Workbook
Name \A: #REF!
Name \B: #REF!
Name \C: #REF!
Name \L: #REF!
Name \M: #REF!
Name \P: #REF!
Name \Y: #REF!
Name _01_30_04: MonthlyOpStats
Name _01_30_04: MonthlyOpStats
Name _1_30_01: MonthlyOpStats
Name _1_30_01: MonthlyOpStats
Name _1_30_02: MonthlyOpStats
Name _1_30_02: MonthlyOpStats
Name _1_31_01: MonthlyOpStats
Name _1_31_01: MonthlyOpStats
Name _1_31_02: MonthlyOpStats
Name _1_31_02: MonthlyOpStats
Name _12_31_05: MonthlyOpStats
Name _12_31_05: MonthlyOpStats
Name _A: #REF!
Name _A___0: #REF!
Name _B: #REF!
Name _B___0: #REF!
Name _C: #REF!
Name _C___0: #REF!
Name _ent1: [1]Inputs!$J$17
Name _ent10: [1]Inputs!$J$476
Name _ent11: [1]Inputs!$J$527
Name _ent12: [1]Inputs!$J$578
Name _ent13: [1]Inputs!$J$629
Name _ent14: [1]Inputs!$J$680
Name _ent15: [1]Inputs!$J$731
Name _ent2: [1]Inputs!$J$68
Name _ent3: [1]Inputs!$J$119
Name _ent4: [1]Inputs!$J$170
Name _ent5: [1]Inputs!$J$221
Name _ent6: [1]Inputs!$J$272
Name _ent7: [1]Inputs!$J$323
Name _ent8: [1]Inputs!$J$374
Name _ent9: [1]Inputs!$J$425
Name _eps1: [1]Inputs!$P$42
Name _eps10: [1]Inputs!$P$501
Name _eps11: [1]Inputs!$P$552
Name _eps12: [1]Inputs!$P$603
Name _eps13: [1]Inputs!$P$654
Name _eps14: [1]Inputs!$P$705
Name _eps15: [1]Inputs!$P$756
Name _eps2: [1]Inputs!$P$93
Name _eps3: [1]Inputs!$P$144
Name _eps4: [1]Inputs!$P$195
Name _eps5: [1]Inputs!$P$246
Name _eps6: [1]Inputs!$P$297
Name _eps7: [1]Inputs!$P$348
Name _eps8: [1]Inputs!$P$399
Name _eps9: [1]Inputs!$P$450
Name _fye1: [1]Inputs!$E$12
Name _fye10: [1]Inputs!$E$471
Name _fye11: [1]Inputs!$E$522
Name _fye12: [1]Inputs!$E$573
Name _fye13: [1]Inputs!$E$624

Sheet Capitalisation
A3: 1Q26 | I3: Exchange rate as at end 1Q26 | J3: =Model!K$204 -> 0.14494854
I4: LTM Average exchange rate 1Q26 | J4: =Model!K$205 -> 0.14097399
B6: Debt Breakdown as on 31-Mar-2026 | C6: RMB millions | D6: Leverage | E6: USD mn | F6: Leverage
B8: Included in non-current liabilities | C8: =SUM(C9:C12) -> 25006.733 | E8: =SUM(E9:E12) -> 3624.6895
B9: Asset-backed securities | C9: 0 | E9: =C9*J3 -> 0
B10: Secured borrowings | C10: 1718.799 | E10: =C10*J3 -> 249.13741
B11: Unsecured borrowings | C11: 18188.172 | E11: =C11*J3 -> 2636.349
B12: Convertible bonds | C12: 5099.762 | E12: =C12*J3 -> 739.20307
B14: Included in current liabilities | C14: =SUM(C15:C18) -> 10360.504 | E14: =SUM(E15:E18) -> 1501.74
B15: Asset-backed securities | C15: 0 | E15: =C15*J3 -> 0
B16: Secured borrowings | C16: 73.134 | E16: =C16*J3 -> 10.600667
B17: Unsecured borrowings | C17: 10287.37 | E17: =C17*J3 -> 1491.1393
B18: Convertible bonds | C18: 0 | E18: =C18*J3 -> 0
B20: Lease Obligations | C20: =SUM(C21:C22) -> 0 | E20: =SUM(E21:E22) -> 0
B21: Short-term | C21: =Model!AK$112 -> 0 | E21: =C21*J3 -> 0
B22: Long-term | C22: =Model!AK$113 -> 0 | E22: =C22*J3 -> 0
B24: Total Loans & Borrowings | C24: =C14+C8+C20 -> 35367.237 | D24: =C24/C29 -> 0.71487752 | E24: =E14+E8+E20 -> 5126.4295 | F24: =E24/E29 -> 0.73503243
B25: Cash and Cash Equivalents | C25: =Model!AK$120 -> 98225.411 | E25: =C25*J3 -> 14237.63
B26: Net debt | C26: =C24-C25 -> -62858.174 | D26: =C26/C29 -> -1.2705515 | E26: =E24-E25 -> -9111.2008 | F26: =E26/E29 -> -1.3063728
B27: Equity | C27: =Model!AK$124 -> 266033.92 | E27: =C27*J3 -> 38561.23
B28: Total Capitalisation | C28: =C26+C27 -> 203175.75 | E28: =E26+E27 -> 29450.029
B29: LTM Adjusted EBITDA | C29: =Model!AK$87 -> 49473.142 | E29: =C29*J4 -> 6974.4263
B30: check | C30: =+C24-Model!AK$119 -> 0
B33: Liquidity at 1Q26 | C33: RMB millions | D33: USD mn
B34: Short-term investments measured at amortized cost | C34: 200 | D34: =C34*J3 -> 28.989709
B35: Short-term investments measured at fair value through profit or loss | C35: 18247.657 | D35: =C35*J3 -> 2644.9713
B36: Term bank deposits | C36: 53443.271 | D36: =C36*J3 -> 7746.5243
B37: Cash and cash equivalents | C37: 26334.483 | D37: =C37*J3 -> 3817.1449
B38: Total liquidity | C38: =SUM(C34:C37) -> 98225.411 | D38: =SUM(D34:D37) -> 14237.63
B39: check | C39: =C38-C25 -> 0
B42: Debt Maturity (from BBG) | C42: RMB mn | D42: USD mn
B43: 2027 | C43: 6419.95 | D43: =C43*J3 -> 930.5624
B44: 2029 | C44: 1000 | D44: =C44*J3 -> 144.94854
B45: 2030 | C45: 4077.19 | D45: =C45*J3 -> 590.98275
B46: 2031+ | C46: =5346.26+2718.13 -> 8064.39 | D46: =C46*J3 -> 1168.9216
B47: Total | C47: =SUM(C43:C46) -> 19561.53 | D47: =SUM(D43:D46) -> 2835.4153
A51: FY25 | I51: Exchange rate as at end | J51: =Model!$K$204 -> 0.14494854
I52: LTM Average exchange rate | J52: =Model!K$205 -> 0.14097399
B54: Debt Breakdown as on 31-Dec-2025 | C54: RMB millions | D54: Leverage (RMB) | E54: USD mn | F54: Leverage (USD)
B56: Included in non-current liabilities | C56: =SUM(C57:C60) -> 22921.433 | E56: =SUM(E57:E60) -> 3322.4283
...

Sheet Model
B2: Xiaomi Corporation | C2: Annual | D2: Annual | E2: Annual | F2: Annual | G2: Annual | H2: Annual | I2: Annual | J2: Annual | K2: LTM | M2: Quarters | N2: Quarters | O2: Quarters | P2: Quarters | Q2: Quarters | R2: Quarters | S2: Quarters | T2: Quarters | U2: Quarters | V2: Quarters | W2: Quarters | X2: Quarters | Y2: Quarters | Z2: Quarters | AA2: Quarters | AB2: Quarters | AC2: Quarters | AD2: Quarters | AE2: Quarters | AF2: Quarters | AG2: Quarters | AH2: Quarters | AI2: Quarters | AJ2: Quarters | AK2: Quarters
B3: (RMB millions) | C3: 43465 | D3: 43830 | E3: 44196 | F3: 44561 | G3: 44926 | H3: 45291 | I3: 45657 | J3: 46022 | K3: =AK3 -> 46112 | M3: 43921 | N3: 44012 | O3: 44104 | P3: 44196 | Q3: 44286 | R3: 44377 | S3: 44469 | T3: 44561 | U3: 44651 | V3: 44742 | W3: 44834 | X3: 44926 | Y3: 45016 | Z3: 45107 | AA3: 45199 | AB3: 45291 | AC3: 45382 | AD3: 45473 | AE3: 45565 | AF3: 45657 | AG3: 45747 | AH3: 45838 | AI3: 45930 | AJ3: 46022 | AK3: 46112
C4: Act | D4: Act | E4: Act | F4: Act | G4: Act | H4: Act | I4: Act | J4: Act | K4: Act | M4: Act | N4: Act | O4: Act | P4: Act | Q4: Act | R4: Act | S4: Act | T4: Act | U4: Act | V4: Act | W4: Act | X4: Act | Y4: Act | Z4: Act | AA4: Act | AB4: Act | AC4: Act | AD4: Act | AE4: Act | AF4: Act | AG4: Act | AH4: Act | AI4: Act | AJ4: Act | AK4: Act
C5: FY | D5: FY | E5: FY | F5: FY | G5: FY | H5: FY | I5: FY | J5: FY | K5: LTM | M5: 1Q | N5: 2Q | O5: 3Q | P5: 4Q | Q5: 1Q | R5: 2Q | S5: 3Q | T5: 4Q | U5: 1Q | V5: 2Q | W5: 3Q | X5: 4Q | Y5: 1Q | Z5: 2Q | AA5: 3Q | AB5: 4Q | AC5: 1Q | AD5: 2Q | AE5: 3Q | AF5: 4Q | AG5: 1Q | AH5: 2Q | AI5: 3Q | AJ5: 4Q | AK5: 1Q
B6: INCOME STATEMENT
B7: Revenue | C7: 174915.42 | D7: 205838.68 | E7: 245865.63 | F7: 328309.15 | G7: 280044.02 | H7: 270970.1 | I7: 365906.35 | J7: 457286.69 | K7: =SUM(AH7:AK7) -> 445134.97 | M7: 49702.167 | N7: 53537.805 | O7: 72162.777 | P7: =E7-SUM(M7:O7) -> 70462.884 | Q7: 76882.163 | R7: 87788.96 | S7: 78062.855 | T7: =F7-SUM(Q7:S7) -> 85575.167 | U7: 73351.502 | V7: 70170.877 | W7: 70474.269 | X7: =G7-SUM(U7:W7) -> 66047.368 | Y7: 59477.134 | Z7: 67354.908 | AA7: 70894.412 | AB7: =H7-SUM(Y7:AA7) -> 73243.646 | AC7: 75506.822 | AD7: 88887.828 | AE7: 92506.541 | AF7: =I7-SUM(AC7:AE7) -> 109005.16 | AG7: 111293.34 | AH7: 115956.09 | AI7: 113120.73 | AJ7: =J7-SUM(AG7:AI7) -> 116916.52 | AK7: 99141.618
B8: % of growth | D8: =(D7/C7)-1 -> 0.17678977 | E8: =(E7/D7)-1 -> 0.19445787 | F8: =(F7/E7)-1 -> 0.33531938 | G8: =(G7/F7)-1 -> -0.14701122 | H8: =(H7/G7)-1 -> -0.032401749 | I8: =(I7/H7)-1 -> 0.35035692 | J8: =(J7/I7)-1 -> 0.24973695 | Q8: =(Q7/M7)-1 -> 0.54685736 | R8: =(R7/N7)-1 -> 0.63975643 | S8: =(S7/O7)-1 -> 0.081760684 | T8: =(T7/P7)-1 -> 0.21447154 | U8: =(U7/Q7)-1 -> -0.045923019 | V8: =(V7/R7)-1 -> -0.20068677 | W8: =(W7/S7)-1 -> -0.097211228 | X8: =(X7/T7)-1 -> -0.22819469 | ... AK8: =(AK7/AG7)-1 -> -0.1091864
B9: Cost of revenues | C9: -152723.49 | D9: -177284.65 | E9: -209113.77 | F9: -270048.2 | G9: -232466.83 | H9: -213493.9 | I9: -289346.16 | J9: -355480.84 | K9: =SUM(AH9:AK9) -> -346924.91 | M9: -42143.71 | N9: -45836.359 | O9: -61997.121 | P9: =E9-SUM(M9:O9) -> -59136.581 | Q9: -62720.932 | R9: -72640.918 | S9: -63770.634 | T9: =F9-SUM(Q9:S9) -> -70915.72 | U9: -60641.756 | V9: -58402.842 | W9: -58752.36 | X9: =G9-SUM(U9:W9) -> -54669.868 | Y9: -47885.567 | Z9: -53193.892 | AA9: -54784.701 | AB9: =H9-SUM(Y9:AA9) -> -57629.74 | AC9: -58677.105 | AD9: -70493.651 | AE9: -73625.131 | AF9: =I9-SUM(AC9:AE9) -> -86550.269 | AG9: -85887.427 | AH9: -89855.133 | AI9: -87184.568 | AJ9: =J9-SUM(AG9:AI9) -> -92553.712 | AK9: -77331.498
B10: Gross Profit | C10: =C7+C9 -> 22191.939 | D10: =D7+D9 -> 28554.033 | E10: =E7+E9 -> 36751.862 | F10: =F7+F9 -> 58260.941 | G10: =G7+G9 -> 47577.19 | H10: =H7+H9 -> 57476.2 | I10: =I7+I9 -> 76560.194 | J10: =J7+J9 -> 101805.85 | K10: =K7+K9 -> 98210.057 | M10: =M7+M9 -> 7558.457 | N10: =N7+N9 -> 7701.446 | O10: =O7+O9 -> 10165.656 | P10: =P7+P9 -> 11326.303 | Q10: =Q7+Q9 -> 14161.231 | R10: =R7+R9 -> 15148.042 | S10: =S7+S9 -> 14292.221 | T10: =T7+T9 -> 14659.447 | ... AK10: =AK7+AK9 -> 21810.12
B11: Gross Profit margin | C11: =C10/C7 -> 0.1268724 | D11: =D10/D7 -> 0.13872044 | E11: =E10/E7 -> 0.14947946 | F11: =F10/F7 -> 0.17745756 | G11: =G10/G7 -> 0.16989183 | H11: =H10/H7 -> 0.2121127 | I11: =I10/I7 -> 0.2092344 | J11: =J10/J7 -> 0.22263024 | K11: =K10/K7 -> 0.22062984 | M11: =M10/M7 -> 0.152075 | N11: =N10/N7 -> 0.14385061 | O11: =O10/O7 -> 0.14087119 | P11: =P10/P7 -> 0.16074141 | Q11: =Q10/Q7 -> 0.18419397 | R11: =R10/R7 -> 0.17255065 | S11: =S10/S7 -> 0.18308607 | T11: =T10/T7 -> 0.17130492 | ... AK11: =AK10/AK7 -> 0.21998955
B12: Operating expenses:
B13: Selling and marketing expenses | C13: -7993.072 | D13: -10378.073 | E13: -14539.4 | F13: -20980.765 | G13: -21323.323 | H13: -19226.5 | I13: -25389.628 | J13: -33214.338 | K13: =SUM(AH13:AK13) -> -34291.004 | M13: -2624.873 | N13: -3223.676 | O13: -3600.582 | P13: =E13-SUM(M13:O13) -> -5090.269 | Q13: -4163.475 | R13: -5680.659 | S13: -4882.314 | T13: =F13-SUM(Q13:S13) -> -6254.317 | U13: -5256.184 | V13: -5332.208 | W13: -4882.576 | X13: =G13-SUM(U13:W13) -> -5852.355 | Y13: -4103.864 | Z13: -4476.758 | AA13: -4736.265 | AB13: =H13-SUM(Y13:AA13) -> -5909.613 | AC13: -5481.047 | AD13: -5899.052 | AE13: -6280.146 | AF13: =I13-SUM(AC13:AE13) -> -7729.383 | AG13: -7199.817 | AH13: -7777.971 | AI13: -8309.653 | AJ13: =J13-SUM(AG13:AI13) -> -9926.897 | AK13: -8276.483
B14: Administrative expenses | C14: -12099.078 | D14: -3103.901 | E14: -3746.449 | F14: -4738.919 | G14: -5113.877 | H14: -5126.8 | I14: -5601.248 | J14: -6653.026 | K14: =SUM(AH14:AK14) -> -6753.317 | M14: -781.533 | N14: -836.426 | O14: -852.715 | P14: =E14-SUM(M14:O14) -> -1275.775 | Q14: -987.652 | R14: -1150.336 | S14: -1274.603 | T14: =F14-SUM(Q14:S14) -> -1326.328 | U14: -1244.573 | V14: -1315.404 | W14: -1255.393 | X14: =G14-SUM(U14:W14) -> -1298.507 | Y14: -1135.173 | Z14: -1143.19 | AA14: -1365.291 | AB14: =H14-SUM(Y14:AA14) -> -1483.146 | AC14: -1523.007 | AD14: -1182.524 | AE14: -1415.369 | AF14: =I14-SUM(AC14:AE14) -> -1480.348 | AG14: -1530.094 | AH14: -1627.144 | AI14: -1848.197 | AJ14: =J14-SUM(AG14:AI14) -> -1647.591 | AK14: -1630.385
B15: Research and development expenses | C15: -5776.826 | D15: -7492.554 | E15: -9256.139 | F15: -13167.088 | G15: -16028.132 | H15: -19097.7 | I15: -24050.484 | J15: -33132.201 | K15: =SUM(AH15:AK15) -> -35374.874 | M15: -1870.984 | N15: -1958.272 | O15: -2321.264 | P15: =E15-SUM(M15:O15) -> -3105.619 | Q15: -3011.991 | R15: -3064.176 | S15: -3237.695 | T15: =F15-SUM(Q15:S15) -> -3853.226 | U15: -3494.539 | V15: -3763.374 | W15: -4069.789 | X15: =G15-SUM(U15:W15) -> -4700.43 | Y15: -4113.36 | Z15: -4554.803 | AA15: -4966.22 | AB15: =H15-SUM(Y15:AA15) -> -5463.317 | AC15: -5159.387 | AD15: -5497.729 | AE15: -5956.784 | AF15: =I15-SUM(AC15:AE15) -> -7436.584 | AG15: -6711.708 | AH15: -7763.377 | AI15: -9059.373 | AJ15: =J15-SUM(AG15:AI15) -> -9597.743 | AK15: -8954.381
B16: Fair value changes on investments | C16: 4430.359 | D16: 3813.012 | E16: 13173.479 | F16: 8132.133 | G16: -1662.01 | H16: 3501.1 | I16: 1050.772 | J16: 13311.733 | K16: =SUM(AH16:AK16) -> 11333.228 | M16: 347.846 | N16: 2366.188 | O16: 3417.924 | P16: =E16-SUM(M16:O16) -> 7041.521 | Q16: 2063.207 | R16: 4165.419 | S16: -1975.634 | T16: =F16-SUM(Q16:S16) -> 3879.141 | U16: -3550.255 | V16: 513.577 | W16: -2390.854 | X16: =G16-SUM(U16:W16) -> 3765.522 | Y16: 3453.259 | Z16: -275.784 | AA16: -299.895 | AB16: =H16-SUM(Y16:AA16) -> 623.52 | AC16: -1226.492 | AD16: -849.41 | AE16: 548.514 | AF16: =I16-SUM(AC16:AE16) -> 2578.16 | AG16: 2827.022 | AH16: 3363.497 | AI16: 5483.157 | AJ16: =J16-SUM(AG16:AI16) -> 1638.057 | AK16: 848.517
B17: Share of net profit /(loss) of investments | C17: -614.92 | D17: -671.822 | E17: 1380.904 | F17: 275.013 | G17: -400.1 | H17: 45.6 | I17: 276.845 | J17: 326.127 | K17: =SUM(AH17:AK17) -> 306.363 | M17: 130.738 | N17: 892.645 | O17: -10.696 | P17: =E17-SUM(M17:O17) -> 368.217 | Q17: 8.989 | R17: -26.193 | S17: 45.116 | T17: =F17-SUM(Q17:S17) -> 247.101 | U17: -201.332 | V17: 62.672 | W17: -264.996 | X17: =G17-SUM(U17:W17) -> 3.556 | Y17: -133.081 | Z17: 74.046 | AA17: 20.633 | AB17: =H17-SUM(Y17:AA17) -> 84.002 | AC17: 155.391 | AD17: 86.385 | AE17: 37.739 | AF17: =I17-SUM(AC17:AE17) -> -2.67 | AG17: 63.531 | AH17: 86.864 | AI17: 25.144 | AJ17: =J17-SUM(AG17:AI17) -> 150.588 | AK17: 43.767
B18: Other operating income/(loss), net | C18: =844.789+213.281 -> 1058.07 | D18: =1265.921-226.399 -> 1039.522 | E18: =642.93-372.458 -> 270.472 | F18: =826.856-2579.507 -> -1752.651 | G18: =1135.56-1368.81 -> -233.25 | H18: =740.1+1696.7 -> 2436.8 | I18: =1666.779-10.334 -> 1656.445 | J18: =2736.94+2719.838 -> 5456.778 | K18: =SUM(AH18:AK18) -> 6657.705 | M18: =73.727-510.19 -> -436.463 | N18: =183.051+288.071 -> 471.122 | O18: =139.291-240.995 -> -101.704 | P18: =E18-SUM(M18:O18) -> 337.517 | Q18: =152.053-64.699 -> 87.354 | R18: =234.612+1099.047 -> 1333.659 | S18: =234.886-472.296 -> -237.41 | T18: =F18-SUM(Q18:S18) -> -2936.254 | U18: =164.927-39.053 -> 125.874 | V18: =186.177-386.447 -> -200.27 | W18: =195.671-414.983 -> -219.312 | X18: =G18-SUM(U18:W18) -> 60.458 | Y18: =164.834+176.027 -> 340.861 | Z18: =184.776+71.223 -> 255.999 | AA18: =128.734+119.806 -> 248.54 | AB18: =H18-SUM(Y18:AA18) -> 1591.4 | AC18: =157.407-69.544 -> 87.863 | AD18: =287.246+549.628 -> 836.874 | AE18: =275.902-50.003 -> 225.899 | AF18: =I18-SUM(AC18:AE18) -> 505.809 | AG18: =(161766+108797)/1000 -> 270.563 | AH18: =299.446+754.446 -> 1053.892 | AI18: =(1686642+1196243)/1000 -> 2882.885 | AJ18: =J18-SUM(AG18:AI18) -> 1249.438 | AK18: =1085.385+386.105 -> 1471.49
B19: Operating profit | C19: =C10+SUM(C13:C18) -> 1196.472 | D19: =D10+SUM(D13:D18) -> 11760.217 | E19: =E10+SUM(E13:E18) -> 24034.729 | F19: =F10+SUM(F13:F18) -> 26028.664 | G19: =G10+SUM(G13:G18) -> 2816.498 | H19: =H10+SUM(H13:H18) -> 20008.7 | I19: =I10+SUM(I13:I18) -> 24502.896 | J19: =J10+SUM(J13:J18) -> 47900.92 | K19: =K10+SUM(K13:K18) -> 40088.158 | M19: =M10+SUM(M13:M18) -> 2323.188 | N19: =N10+SUM(N13:N18) -> 5413.027 | O19: =O10+SUM(O13:O18) -> 6696.619 | P19: =P10+SUM(P13:P18) -> 9601.895 | Q19: =Q10+SUM(Q13:Q18) -> 8157.663 | R19: =R10+SUM(R13:R18) -> 10725.756 | S19: =S10+SUM(S13:S18) -> 2729.681 | T19: =T10+SUM(T13:T18) -> 4415.564 | ... AK19: =AK10+SUM(AK13:AK18) -> 5312.645
B20: Finance exps | C20: 0 | D20: -528.46 | E20: -3364.852 | F20: -2841.457 | G20: -546.483 | H20: -1555.97 | I20: -212.447 | J20: -3634.735 | K20: =SUM(AH20:AK20) -> -3360.646 | M20: -161.045 | N20: -767.025 | O20: -1465.628 | P20: =E20-SUM(M20:O20) -> -971.154 | Q20: 634.009 | R20: -1369.865 | S20: -1260.559 | T20: =F20-SUM(Q20:S20) -> -845.042 | U20: 229.631 | V20: -376.18 | W20: -284.812 | X20: =G20-SUM(U20:W20) -> -115.122 | Y20: -1107.646 | Z20: 63.882 | AA20: -95.602 | AB20: =H20-SUM(Y20:AA20) -> -416.604 | AC20: 519.905 | AD20: -86.211 | AE20: -157.188 | AF20: =I20-SUM(AC20:AE20) -> -488.953 | AG20: 1003.965 | AH20: -512.462 | AI20: -1644.26 | AJ20: =J20-SUM(AG20:AI20) -> -2481.978 | AK20: 1278.054
B21: Finance income | C21: =216.373+12514.279 -> 12730.652 | D21: 930.889 | E21: 963.555 | F21: 1229.826 | G21: 1663.941 | H21: =3558.347 -> 3558.347 | I21: 3836.204 | J21: 5380.68 | K21: =SUM(AH21:AK21) -> 5480.092 | M21: 291.946 | N21: 221.794 | O21: 219.69 | P21: =E21-SUM(M21:O21) -> 230.125 | Q21: 275.208 | R21: 322.651 | S21: 317.991 | T21: =F21-SUM(Q21:S21) -> 313.976 | U21: 265.702 | V21: 379.991 | W21: 455.128 | X21: =G21-SUM(U21:W21) -> 563.12 | Y21: 678.15 | Z21: 851.273 | AA21: 971.589 | AB21: =H21-SUM(Y21:AA21) -> 1057.335 | AC21: 1019.435 | AD21: 876.875 | AE21: 933.119 | AF21: =I21-SUM(AC21:AE21) -> 1006.775 | AG21: -961.404 | AH21: 1478.526 | AI21: 1489.776 | AJ21: =J21-SUM(AG21:AI21) -> 3373.782 | AK21: -861.992
B22: Finance (costs)/income, net | C22: =SUM(C20:C21) -> 12730.652 | D22: =SUM(D20:D21) -> 402.429 | E22: =SUM(E20:E21) -> -2401.297 | F22: =SUM(F20:F21) -> -1611.631 | G22: =SUM(G20:G21) -> 1117.458 | H22: =SUM(H20:H21) -> 2002.377 | I22: =SUM(I20:I21) -> 3623.757 | J22: =SUM(J20:J21) -> 1745.945 | K22: =SUM(K20:K21) -> 2119.446 | M22: =SUM(M20:M21) -> 130.901 | N22: =SUM(N20:N21) -> -545.231 | O22: =SUM(O20:O21) -> -1245.938 | P22: =SUM(P20:P21) -> -741.029 | Q22: =SUM(Q20:Q21) -> 909.217 | R22: =SUM(R20:R21) -> -1047.214 | S22: =SUM(S20:S21) -> -942.568 | T22: =SUM(T20:T21) -> -531.066 | ... AK22: =SUM(AK20:AK21) -> 416.062
B23: Profit before tax | C23: =C19+SUM(C22) -> 13927.124 | D23: =D19+SUM(D22) -> 12162.646 | E23: =E19+SUM(E22) -> 21633.432 | F23: =F19+SUM(F22) -> 24417.033 | G23: =G19+SUM(G22) -> 3933.956 | H23: =H19+SUM(H22) -> 22011.077 | I23: =I19+SUM(I22) -> 28126.653 | J23: =J19+SUM(J22) -> 49646.865 | K23: =K19+SUM(K22) -> 42207.604 | M23: =M19+SUM(M22) -> 2454.089 | N23: =N19+SUM(N22) -> 4867.796 | O23: =O19+SUM(O22) -> 5450.681 | P23: =P19+SUM(P22) -> 8860.866 | Q23: =Q19+SUM(Q22) -> 9066.88 | R23: =R19+SUM(R22) -> 9678.542 | S23: =S19+SUM(S22) -> 1787.113 | T23: =T19+SUM(T22) -> 3884.498 | ... AK23: =AK19+SUM(AK22) -> 5728.707
B24: Current and deferred income tax and social contribution | C24: -449.377 | D24: -2059.696 | E24: -1320.722 | F24: -5133.798 | G24: -1431.388 | H24: -4536.851 | I24: -4548.204 | J24: -8080.426 | K24: =SUM(AH24:AK24) -> -6799.334 | M24: -294.195 | N24: -374.323 | O24: -586.333 | P24: =E24-SUM(M24:O24) -> -65.871 | Q24: -1277.973 | R24: -1415.234 | S24: -998.596 | T24: =F24-SUM(Q24:S24) -> -1441.995 | U24: -114.624 | V24: -371.462 | W24: -283.227 | X24: =G24-SUM(U24:W24) -> -662.075 | Y24: -1254.575 | Z24: -1290.157 | AA24: -1018.128 | AB24: =H24-SUM(Y24:AA24) -> -973.991 | AC24: -1049.166 | AD24: -1609.716 | AE24: -1476.902 | AF24: =I24-SUM(AC24:AE24) -> -412.42 | AG24: -2275.222 | AH24: -2529.62 | AI24: -2698.904 | AJ24: =J24-SUM(AG24:AI24) -> -576.68 | AK24: -994.13
B25: Net profit/loss | C25: =+C23+C24 -> 13477.747 | D25: =+D23+D24 -> 10102.95 | E25: =+E23+E24 -> 20312.71 | F25: =+F23+F24 -> 19283.235 | G25: =+G23+G24 -> 2502.568 | H25: =+H23+H24 -> 17474.226 | I25: =+I23+I24 -> 23578.449 | J25: =+J23+J24 -> 41566.439 | K25: =+K23+K24 -> 35408.27 | M25: =+M23+M24 -> 2159.894 | N25: =+N23+N24 -> 4493.473 | O25: =+O23+O24 -> 4864.348 | P25: =+P23+P24 -> 8794.995 | Q25: =+Q23+Q24 -> 7788.907 | R25: =+R23+R24 -> 8263.308 | S25: =+S23+S24 -> 788.517 | T25: =+T23+T24 -> 2442.503 | ... AK25: =+AK23+AK24 -> 4734.577
B26: % margin | C26: =+C25/C7 -> 0.077052936 | D26: =+D25/D7 -> 0.049081882 | E26: =+E25/E7 -> 0.082617118 | F26: =+F25/F7 -> 0.058734992 | G26: =+G25/G7 -> 0.0089363381 | H26: =+H25/H7 -> 0.064487654 | I26: =+I25/I7 -> 0.06443848 | J26: =+J25/J7 -> 0.090897986 | K26: =+K25/K7 -> 0.07954502 | M26: =+M25/M7 -> 0.043456737 | N26: =+N25/N7 -> 0.083930841 | O26: =+O25/O7 -> 0.067407993 | P26: =+P25/P7 -> 0.12481741 | Q26: =+Q25/Q7 -> 0.10130968 | R26: =+R25/R7 -> 0.094126961 | S26: =+S25/S7 -> 0.010101053 | T26: =+T25/T7 -> 0.028542194 | ... AK26: =+AK25/AK7 -> 0.047755696
B27: Non-controlling interest | C27: 76.139 | D27: -58.786 | E27: 42.794 | F27: 56.086 | G27: -28.538 | H27: 0.977 | I27: 79.677 | J27: 76.95 | K27: =SUM(AH27:AK27) -> 33.918 | M27: 3.621 | N27: 4.655 | O27: 16.248 | P27: =E27-SUM(M27:O27) -> 18.27 | Q27: 3.982 | R27: 5.169 | S27: 3.739 | T27: =F27-SUM(Q27:S27) -> 43.196 | U27: -57.046 | V27: 21.023 | W27: -2.128 | X27: =G27-SUM(U27:W27) -> 9.613 | Y27: -12.299 | Z27: 4.451 | AA27: 4.789 | AB27: =H27-SUM(Y27:AA27) -> 4.036 | AC27: 8.849 | AD27: 28.333 | AE27: 12.112 | AF27: =I27-SUM(AC27:AE27) -> 30.383 | AG27: 31.575 | AH27: 31.242 | AI27: 14.133 | AJ27: =J27-SUM(AG27:AI27) -> 0 | AK27: -11.457
B28: Net profit/loss | C28: =+C25+C27 -> 13553.886 | D28: =+D25+D27 -> 10044.164 | E28: =+E25+E27 -> 20355.504 | F28: =+F25+F27 -> 19339.321 | G28: =+G25+G27 -> 2474.03 | H28: =+H25+H27 -> 17475.203 | I28: =+I25+I27 -> 23658.126 | J28: =+J25+J27 -> 41643.389 | K28: =+K25+K27 -> 35442.188 | M28: =+M25+M27 -> 2163.515 | N28: =+N25+N27 -> 4498.128 | O28: =+O25+O27 -> 4880.596 | P28: =+P25+P27 -> 8813.265 | Q28: =+Q25+Q27 -> 7792.889 | R28: =+R25+R27 -> 8268.477 | S28: =+S25+S27 -> 792.256 | T28: =+T25+T27 -> 2485.699 | ... AK28: =+AK25+AK27 -> 4723.12
B30: % of sales or stated otherwise
B31: =B13 -> Selling and marketing expenses | C31: =-C13/C7 -> 0.045696782 | D31: =-D13/D7 -> 0.050418478 | E31: =-E13/E7 -> 0.059135552 | F31: =-F13/F7 -> 0.063905515 | G31: =-G13/G7 -> 0.076142755 | H31: =-H13/H7 -> 0.070954323 | I31: =-I13/I7 -> 0.069388323 | J31: =-J13/J7 -> 0.072633512 | K31: =-K13/K7 -> 0.077035071 | M31: =-M13/M7 -> 0.052812043 | N31: =-N13/N7 -> 0.060213077 | O31: =-O13/O7 -> 0.04989528 | P31: =-P13/P7 -> 0.072240429 | Q31: =-Q13/Q7 -> 0.054153978 | R31: =-R13/R7 -> 0.064708125 | S31: =-S13/S7 -> 0.06254337 | T31: =-T13/T7 -> 0.073085653 | ... AK31: =-AK13/AK7 -> 0.083481419
B32: =B14 -> Administrative expenses | C32: =-C14/C7 -> 0.069171018 | D32: =-D14/D7 -> 0.015079289 | E32: =-E14/E7 -> 0.01523779 | F32: =-F14/F7 -> 0.014434319 | G32: =-G14/G7 -> 0.018260976 | H32: =-H14/H7 -> 0.018920169 | I32: =-I14/I7 -> 0.015307873 | J32: =-J14/J7 -> 0.014548917 | K32: =-K14/K7 -> 0.015171392 | M32: =-M14/M7 -> 0.015724324 | N32: =-N14/N7 -> 0.015623091 | O32: =-O14/O7 -> 0.011816549 | P32: =-P14/P7 -> 0.018105631 | Q32: =-Q14/Q7 -> 0.012846309 | R32: =-R14/R7 -> 0.013103424 | S32: =-S14/S7 -> 0.016327907 | T32: =-T14/T7 -> 0.015498982 | ... AK32: =-AK14/AK7 -> 0.016445011
B33: =B15 -> Research and development expenses | C33: =-C15/C7 -> 0.033026395 | D33: =-D15/D7 -> 0.036400126 | E33: =-E15/E7 -> 0.037647144 | F33: =-F15/F7 -> 0.040105761 | G33: =-G15/G7 -> 0.057234331 | H33: =-H15/H7 -> 0.070478994 | I33: =-I15/I7 -> 0.065728523 | J33: =-J15/J7 -> 0.072453894 | K33: =-K15/K7 -> 0.079469996 | M33: =-M15/M7 -> 0.037643912 | N33: =-N15/N7 -> 0.036577368 | O33: =-O15/O7 -> 0.032167055 | P33: =-P15/P7 -> 0.044074537 | Q33: =-Q15/Q7 -> 0.03917672 | R33: =-R15/R7 -> 0.034903888 | S33: =-S15/S7 -> 0.041475488 | T33: =-T15/T7 -> 0.045027385 | ... AK33: =-AK15/AK7 -> 0.090319093
B34: =B16 -> Fair value changes on investments | C34: =-C16/C$7 -> -0.025328578 | D34: =-D16/D$7 -> -0.018524273 | E34: =-E16/E$7 -> -0.053579993 | F34: =-F16/F$7 -> -0.024769743 | G34: =-G16/G$7 -> 0.005934817 | H34: =-H16/H$7 -> -0.012920614 | I34: =-I16/I$7 -> -0.0028716965 | J34: =-J16/J$7 -> -0.029110257 | K34: =-K16/K$7 -> -0.025460206 | M34: =-M16/M$7 -> -0.0069986083 | N34: =-N16/N$7 -> -0.044196582 | O34: =-O16/O$7 -> -0.047364086 | P34: =-P16/P$7 -> -0.099932342 | Q34: =-Q16/Q$7 -> -0.026835965 | R34: =-R16/R$7 -> -0.047448096 | S34: =-S16/S$7 -> 0.025308247 | T34: =-T16/T$7 -> -0.045330218 | ... AK34: =-AK16/AK$7 -> -0.0085586358
B35: =B17 -> Share of net profit /(loss) of investments | C35: =-C17/C$7 -> 0.0035155276 | D35: =-D17/D$7 -> 0.0032638277 | E35: =-E17/E$7 -> -0.0056164987 | F35: =-F17/F$7 -> -0.00083766476 | G35: =-G17/G$7 -> 0.001428704 | H35: =-H17/H$7 -> -0.00016828425 | I35: =-I17/I$7 -> -0.0007566007 | J35: =-J17/J$7 -> -0.00071317843 | K35: =-K17/K$7 -> -0.00068824744 | M35: =-M17/M$7 -> -0.0026304286 | N35: =-N17/N$7 -> -0.016673171 | O35: =-O17/O$7 -> 0.00014822046 | P35: =-P17/P$7 -> -0.0052256873 | Q35: =-Q17/Q$7 -> -0.00011691919 | R35: =-R17/R$7 -> 0.00029836326 | S35: =-S17/S$7 -> -0.00057794453 | T35: =-T17/T$7 -> -0.0028875316 | ... AK35: =-AK17/AK$7 -> -0.00044145941
B36: Finance exps as% of debt | C36: =-C20/C109 -> 0 | D36: =-D20/D109 -> 0.02998625 | E36: =-E20/E109 -> 0.19122016 | F36: =-F20/F109 -> 0.10825901 | G36: =-G20/G109 -> 0.023112965 | H36: =-H20/H109 -> 0.055854928 | I36: =-I20/I109 -> 0.0069420277 | J36: =-J20/J109 -> 0.10061924 | K36: =-K20/K109 -> 0.095021446 | P36: =-SUM(M20:P20)/P109 -> 0.19122016 | Q36: =-SUM(N20:Q20)/Q109 -> 0.12234287 | R36: =-SUM(O20:R20)/R109 -> 0.16426855 | S36: =-SUM(P20:S20)/S109 -> 0.11458525 | T36: =-SUM(Q20:T20)/T109 -> 0.10825901 | U36: =-SUM(R20:U20)/U109 -> 0.10923614 | V36: =-SUM(S20:V20)/V109 -> 0.069149912 | W36: =-SUM(T20:W20)/W109 -> 0.049546538 | ... AK36: =-SUM(AH20:AK20)/AK109 -> 0.095021446
B37: Finance income as% of cash and cash equivalents | C37: =C21/C120 -> 0.33287394 | D37: =D21/D120 -> 0.014566468 | E37: =E21/E120 -> 0.010086916 | F37: =F21/F120 -> 0.014271537 | G37: =G21/G120 -> 0.024550236 | H37: =H21/H120 -> 0.033037047 | I37: =I21/I120 -> 0.038164837 | J37: =J21/J120 -> 0.049961471 | K37: =K21/K120 -> 0.055790981 | P37: =SUM(M21:P21)/P120 -> 0.010086916 | Q37: =SUM(N21:Q21)/Q120 -> 0.010018296 | R37: =SUM(O21:R21)/R120 -> 0.011190031 | S37: =SUM(P21:S21)/S120 -> 0.013995212 | T37: =SUM(Q21:T21)/T120 -> 0.014271537 | U37: =SUM(R21:U21)/U120 -> 0.016006616 | V37: =SUM(S21:V21)/V120 -> 0.017058734 | W37: =SUM(T21:W21)/W120 -> 0.021286842 | ... AK37: =SUM(AH21:AK21)/AK120 -> 0.055790981
B38: Tax % of PBT | C38: =-C24/C23 -> 0.032266317 | D38: =-D24/D23 -> 0.16934605 | E38: =-E24/E23 -> 0.061050045 | F38: =-F24/F23 -> 0.21025478 | G38: =-G24/G23 -> 0.3638546 | H38: =-H24/H23 -> 0.20611672 | I38: =-I24/I23 -> 0.16170442 | J38: =-J24/J23 -> 0.16275803 | K38: =-K24/K23 -> 0.16109263 | M38: =-M24/M23 -> 0.11987952 | N38: =-N24/N23 -> 0.07689784 | O38: =-O24/O23 -> 0.1075706 | P38: =-P24/P23 -> 0.0074339235 | Q38: =-Q24/Q23 -> 0.14094959 | R38: =-R24/R23 -> 0.14622388 | S38: =-S24/S23 -> 0.55877608 | T38: =-T24/T23 -> 0.37121785 | ... AK38: =-AK24/AK23 -> 0.1735348
B40: Working capital /sales | C40: =C61/C7 -> -0.02045899 | D40: =D61/D7 -> 0.025716415 | E40: =E61/E7 -> -0.022507562 | F40: =F61/F7 -> -0.057381777 | G40: =G61/G7 -> -0.077189305 | H40: =H61/H7 -> -0.03921691 | I40: =I61/I7 -> 0.14166828 | J40: =J61/J7 -> -0.030358207 | K40: =K61/K7 -> 0 | M40: =M61/M7 -> 0 | N40: =N61/N7 -> 0 | O40: =O61/O7 -> 0 | P40: =P61/P7 -> -0.078535474 | Q40: =Q61/Q7 -> 0 | R40: =R61/R7 -> 0 | S40: =S61/S7 -> 0 | T40: =T61/T7 -> -0.2201452 | ... AK40: =AK61/AK7 -> 0
B41: Capex/sales | C41: =-C65/C7 -> 0.0013504927 | D41: =-D65/D7 -> 0.016213804 | E41: =-E65/E7 -> 0.012049 | F41: =-F65/F7 -> 0.021729361 | G41: =-G65/G7 -> 0.020647597 | H41: =-H65/H7 -> 0.022866239 | I41: =-I65/I7 -> 0.018963374 | J41: =-J65/J7 -> 0.027895802 | K41: =-K65/K7 -> 0 | M41: =-M65/M7 -> 0 | N41: =-N65/N7 -> 0.021010761 | O41: =-O65/O7 -> 0 | P41: =-P65/P7 -> 0.026078481 | Q41: =-Q65/Q7 -> 0 | R41: =-R65/R7 -> 0.020749921 | S41: =-S65/S7 -> 0 | T41: =-T65/T7 -> 0.062077986 | ... AK41: =-AK65/AK7 -> 0
B43: EBITDA | C43: =C3 -> 43465 | D43: =D3 -> 43830 | E43: =E3 -> 44196 | F43: =F3 -> 44561 | G43: =G3 -> 44926 | H43: =H3 -> 45291 | I43: =I3 -> 45657 | J43: =J3 -> 46022 | K43: =K2 -> LTM | M43: =M3 -> 43921 | N43: =N3 -> 44012 | O43: =O3 -> 44104 | P43: =P3 -> 44196 | Q43: =Q3 -> 44286 | R43: =R3 -> 44377 | S43: =S3 -> 44469 | T43: =T3 -> 44561 | ... AK43: =AK3 -> 46112
B44: Operating profit | C44: =C19 -> 1196.472 | D44: =D19 -> 11760.217 | E44: =E19 -> 24034.729 | F44: =F19 -> 26028.664 | G44: =G19 -> 2816.498 | H44: =H19 -> 20008.7 | I44: =I19 -> 24502.896 | J44: =J19 -> 47900.92 | K44: =K19 -> 40088.158 | M44: =M19 -> 2323.188 | N44: =N19 -> 5413.027 | O44: =O19 -> 6696.619 | P44: =P19 -> 9601.895 | Q44: =Q19 -> 8157.663 | R44: =R19 -> 10725.756 | S44: =S19 -> 2729.681 | T44: =T19 -> 4415.564 | ... AK44: =AK19 -> 5312.645
...

Sheet KPIs
B2: Xiaomi Corporation | C2: Annual | D2: Annual | E2: Annual | F2: Annual | G2: Annual | H2: Annual | I2: Annual | J2: Annual | K2: LTM | M2: Quarters | N2: Quarters | O2: Quarters | P2: Quarters | Q2: Quarters | R2: Quarters | S2: Quarters | T2: Quarters | U2: Quarters | V2: Quarters | W2: Quarters | X2: Quarters | Y2: Quarters | Z2: Quarters | AA2: Quarters | AB2: Quarters | AC2: Quarters | AD2: Quarters | AE2: Quarters | AF2: Quarters | AG2: Quarters | AH2: Quarters | AI2: Quarters | AJ2: Quarters | AK2: Quarters
B3: (RMB millions) | C3: 43465 | D3: 43830 | E3: 44196 | F3: 44561 | G3: 44926 | H3: 45291 | I3: 45657 | J3: 46022 | K3: =AK3 -> 46112 | M3: 43921 | N3: 44012 | O3: 44104 | P3: 44196 | Q3: 44286 | R3: 44377 | S3: 44469 | T3: 44561 | U3: 44651 | V3: 44742 | W3: 44834 | X3: 44926 | Y3: 45016 | Z3: 45107 | AA3: 45199 | AB3: 45291 | AC3: 45382 | AD3: 45473 | AE3: 45565 | AF3: 45657 | AG3: 45747 | AH3: 45838 | AI3: 45930 | AJ3: 46022 | AK3: 46112
C4: Act | D4: Act | E4: Act | F4: Act | G4: Act | H4: Act | I4: Act | J4: Act | K4: Act | M4: Act | N4: Act | O4: Act | P4: Act | Q4: Act | R4: Act | S4: Act | T4: Act | U4: Act | V4: Act | W4: Act | X4: Act | Y4: Act | Z4: Act | AA4: Act | AB4: Act | AC4: Act | AD4: Act | AE4: Act | AF4: Act | AG4: Act | AH4: Act | AI4: Act | AJ4: Act | AK4: Act
C5: FY | D5: FY | E5: FY | F5: FY | G5: FY | H5: FY | I5: FY | J5: FY | K5: LTM | M5: 1Q | N5: 2Q | O5: 3Q | P5: 4Q | Q5: 1Q | R5: 2Q | S5: 3Q | T5: 4Q | U5: 1Q | V5: 2Q | W5: 3Q | X5: 4Q | Y5: 1Q | Z5: 2Q | AA5: 3Q | AB5: 4Q | AC5: 1Q | AD5: 2Q | AE5: 3Q | AF5: 4Q | AG5: 1Q | AH5: 2Q | AI5: 3Q | AJ5: 4Q | AK5: 1Q
B8: Revenue by segment
B9: Smartphones | C9: 113800.39 | D9: 122094.9 | E9: 152190.89 | F9: 208868.94 | G9: 167217.18 | H9: 157461.3 | I9: 191759.3 | J9: 186439.78 | K9: =SUM(AH9:AK9) -> 180101.16 | M9: 30324.723 | N9: 31627.549 | O9: 47604.133 | P9: =E9-SUM(M9:O9) -> 42634.486 | Q9: 51490.983 | R9: 59088.963 | S9: 47824.932 | T9: =F9-SUM(Q9:S9) -> 50464.066 | U9: 45762.689 | V9: 42268.105 | W9: 42514.239 | X9: =G9-SUM(U9:W9) -> 36672.144 | Y9: 34984.746 | Z9: 36595.461 | AA9: 41648.925 | AB9: =H9-SUM(Y9:AA9) -> 44232.168 | AC9: 46479.748 | AD9: 46516.4 | AE9: 47452.324 | AF9: =I9-SUM(AC9:AE9) -> 51310.828 | AG9: 50611.952 | AH9: 45520.009 | AI9: 45969.027 | AJ9: =J9-SUM(AG9:AI9) -> 44338.789 | AK9: 44273.331
B10: IoT and lifestyle products | C10: 43816.885 | D10: 62087.998 | E10: 67410.453 | F10: 84980.097 | G10: 79794.877 | H10: 80107.7 | I10: 104103.9 | J10: 123200.19 | K10: =SUM(AH10:AK10) -> 115542.11 | M10: 12984.208 | N10: 15252.868 | O10: 18119.021 | P10: =E10-SUM(M10:O10) -> 21054.356 | Q10: 18243.267 | R10: 20734.693 | S10: 20935.557 | T10: =F10-SUM(Q10:S10) -> 25066.58 | U10: 19477.357 | V10: 19811.608 | W10: 19058.648 | X10: =G10-SUM(U10:W10) -> 21447.264 | Y10: 16833.782 | Z10: 22253.866 | AA10: 20673.297 | AB10: =H10-SUM(Y10:AA10) -> 20346.755 | AC10: 20373.489 | AD10: 26760.3 | AE10: 26102.162 | AF10: =I10-SUM(AC10:AE10) -> 30867.949 | AG10: 32339.234 | AH10: 38712.153 | AI10: 27552.155 | AJ10: =J10-SUM(AG10:AI10) -> 24596.649 | AK10: 24681.157
B11: Internet services | C11: 15955.558 | D11: 19841.569 | E11: 23755.285 | F11: 28211.739 | G11: 28321.444 | H11: 30107.5 | I11: 34115.4 | J11: 37440.346 | K11: =SUM(AH11:AK11) -> 37832.595 | M11: 5900.696 | N11: 5907.621 | O11: 5771.89 | P11: =E11-SUM(M11:O11) -> 6175.078 | Q11: 6570.848 | R11: 7033.487 | S11: 7337.857 | T11: =F11-SUM(Q11:S11) -> 7269.547 | U11: 7112.481 | V11: 6971.121 | W11: 7066.591 | X11: =G11-SUM(U11:W11) -> 7171.251 | Y11: 7028.148 | Z11: 7444.079 | AA11: 7755.534 | AB11: =H11-SUM(Y11:AA11) -> 7879.739 | AC11: 8048.383 | AD11: 8265.6 | AE11: 8462.807 | AF11: =I11-SUM(AC11:AE11) -> 9338.61 | AG11: 9076.097 | AH11: 9097.747 | AI11: 9380.464 | AJ11: =J11-SUM(AG11:AI11) -> 9886.038 | AK11: 9468.346
B12: Smart EV and other new initiatives | I12: 32753.6 | J12: 106069.51 | K12: =SUM(AH12:AK12) -> 107353.87 | AC12: 26.032 | AD12: 6368.8 | AE12: 9697.134 | AF12: =I12-SUM(AC12:AE12) -> 16661.634 | AG12: 18580.065 | AH12: 21263.264 | AI12: 29010.088 | AJ12: =J12-SUM(AG12:AI12) -> 37216.096 | AK12: 19864.417
B13: Others | C13: 1342.596 | D13: 1814.218 | E13: 2509.004 | F13: 6248.365 | G13: 4710.518 | H13: 3293.6 | I13: 3174.2 | J13: 4136.86 | K13: =SUM(AH13:AK13) -> 4305.238 | M13: 492.54 | N13: 749.767 | O13: 667.733 | P13: =E13-SUM(M13:O13) -> 598.964 | Q13: 577.065 | R13: 931.817 | S13: 1964.509 | T13: =F13-SUM(Q13:S13) -> 2774.974 | U13: 998.975 | V13: 1120.043 | W13: 1834.791 | X13: =G13-SUM(U13:W13) -> 756.709 | Y13: 630.458 | Z13: 1061.502 | AA13: 816.656 | AB13: =H13-SUM(Y13:AA13) -> 784.984 | AC13: 579.17 | AD13: =976.7 -> 976.7 | AE13: =792.114 -> 792.114 | AF13: =I13-SUM(AC13:AE13) -> 826.216 | AG13: 685.989 | AH13: =1362.918 -> 1362.918 | AI13: =(1209000)/1000 -> 1209 | AJ13: =J13-SUM(AG13:AI13) -> 878.953 | AK13: 854.367
B14: Net Revenue | C14: =SUM(C9:C13) -> 174915.42 | D14: =SUM(D9:D13) -> 205838.68 | E14: =SUM(E9:E13) -> 245865.63 | F14: =SUM(F9:F13) -> 328309.14 | G14: =SUM(G9:G13) -> 280044.02 | H14: =SUM(H9:H13) -> 270970.1 | I14: =SUM(I9:I13) -> 365906.4 | J14: =SUM(J9:J13) -> 457286.69 | K14: =SUM(K9:K13) -> 445134.97 | M14: =SUM(M9:M13) -> 49702.167 | N14: =SUM(N9:N13) -> 53537.805 | O14: =SUM(O9:O13) -> 72162.777 | P14: =SUM(P9:P13) -> 70462.884 | Q14: =SUM(Q9:Q13) -> 76882.163 | R14: =SUM(R9:R13) -> 87788.96 | S14: =SUM(S9:S13) -> 78062.855 | T14: =SUM(T9:T13) -> 85575.167 | ... AK14: =SUM(AK9:AK13) -> 99141.618
B15: check | C15: =C14-Model!C7 -> 0 | D15: =D14-Model!D7 -> 0 | E15: =E14-Model!E7 -> 0 | F15: =F14-Model!F7 -> 0 | G15: =G14-Model!G7 -> 0 | H15: =H14-Model!H7 -> 0 | I15: =I14-Model!I7 -> 0.05 | J15: =J14-Model!J7 -> 0 | K15: =K14-Model!K7 -> 0 | M15: =M14-Model!M7 -> 0 | N15: =N14-Model!N7 -> 0 | O15: =O14-Model!O7 -> 0 | P15: =P14-Model!P7 -> 0 | Q15: =Q14-Model!Q7 -> 0 | R15: =R14-Model!R7 -> 0 | S15: =S14-Model!S7 -> 0 | T15: =T14-Model!T7 -> 0 | ... AK15: =AK14-Model!AK7 -> 0
B17: Revenue by segment (% Share)
B18: Smartphones | C18: =C9/C$14 -> 0.65060235 | D18: =D9/D$14 -> 0.59315818 | E18: =E9/E$14 -> 0.61900026 | F18: =F9/F$14 -> 0.63619594 | G18: =G9/G$14 -> 0.59711034 | H18: =H9/H$14 -> 0.58110212 | I18: =I9/I$14 -> 0.52406654 | J18: =J9/J$14 -> 0.40770874 | K18: =K9/K$14 -> 0.40459898 | M18: =M9/M$14 -> 0.61012879 | N18: =N9/N$14 -> 0.59075169 | O18: =O9/O$14 -> 0.65967712 | P18: =P9/P$14 -> 0.60506303 | Q18: =Q9/Q$14 -> 0.669739 | R18: =R9/R$14 -> 0.67307966 | S18: =S9/S$14 -> 0.61264646 | T18: =T9/T$14 -> 0.58970456 | ... AK18: =AK9/AK$14 -> 0.44656656
B19: IoT and lifestyle products | C19: =C10/C$14 -> 0.25050326 | D19: =D10/D$14 -> 0.30163426 | E19: =E10/E$14 -> 0.27417599 | F19: =F10/F$14 -> 0.2588417 | G19: =G10/G$14 -> 0.28493691 | H19: =H10/H$14 -> 0.29563299 | I19: =I10/I$14 -> 0.28450965 | J19: =J10/J$14 -> 0.26941565 | K19: =K10/K$14 -> 0.25956647 | M19: =M10/M$14 -> 0.26124028 | N19: =N10/N$14 -> 0.28489902 | O19: =O10/O$14 -> 0.25108542 | P19: =P10/P$14 -> 0.29880066 | Q19: =Q10/Q$14 -> 0.23728868 | R19: =R10/R$14 -> 0.23618793 | S19: =S10/S$14 -> 0.26818846 | T19: =T10/T$14 -> 0.29291886 | ... AK19: =AK10/AK$14 -> 0.2489485
B20: Internet services | C20: =C11/C$14 -> 0.091218702 | D20: =D11/D$14 -> 0.096393782 | E20: =E11/E$14 -> 0.096618973 | F20: =F11/F$14 -> 0.085930409 | G20: =G11/G$14 -> 0.10113212 | H20: =H11/H$14 -> 0.11111004 | I20: =I11/I$14 -> 0.093235319 | J20: =J11/J$14 -> 0.081874997 | K20: =K11/K$14 -> 0.08499129 | M20: =M11/M$14 -> 0.1187211 | N20: =N11/N$14 -> 0.11034485 | O20: =O11/O$14 -> 0.079984311 | P20: =P11/P$14 -> 0.087635896 | Q20: =Q11/Q$14 -> 0.085466482 | R20: =R11/R$14 -> 0.080118126 | S20: =S11/S$14 -> 0.093999342 | T20: =T11/T$14 -> 0.084949259 | ... AK20: =AK11/AK$14 -> 0.095503243
B21: Smart EV and other new initiatives | C21: =C12/C$14 -> 0 | D21: =D12/D$14 -> 0 | E21: =E12/E$14 -> 0 | F21: =F12/F$14 -> 0 | G21: =G12/G$14 -> 0 | H21: =H12/H$14 -> 0 | I21: =I12/I$14 -> 0.089513602 | J21: =J12/J$14 -> 0.23195408 | K21: =K12/K$14 -> 0.24117149 | M21: =M12/M$14 -> 0 | N21: =N12/N$14 -> 0 | O21: =O12/O$14 -> 0 | P21: =P12/P$14 -> 0 | Q21: =Q12/Q$14 -> 0 | R21: =R12/R$14 -> 0 | S21: =S12/S$14 -> 0 | T21: =T12/T$14 -> 0 | ... AK21: =AK12/AK$14 -> 0.20036406
B22: Others | C22: =C13/C$14 -> 0.0076756867 | D22: =D13/D$14 -> 0.0088137855 | E22: =E13/E$14 -> 0.010204777 | F22: =F13/F$14 -> 0.019031955 | G22: =G13/G$14 -> 0.016820634 | H22: =H13/H$14 -> 0.012154847 | I22: =I13/I$14 -> 0.0086748961 | J22: =J13/J$14 -> 0.009046535 | K22: =K13/K$14 -> 0.0096717587 | M22: =M13/M$14 -> 0.0099098295 | N22: =N13/N$14 -> 0.01400444 | O22: =O13/O$14 -> 0.00925315 | P22: =P13/P$14 -> 0.0085004185 | Q22: =Q13/Q$14 -> 0.0075058372 | R22: =R13/R$14 -> 0.010614285 | S22: =S13/S$14 -> 0.025165733 | T22: =T13/T$14 -> 0.032427328 | ... AK22: =AK13/AK$14 -> 0.0086176423
B23: Net Revenue | C23: =SUM(C18:C22) -> 1 | D23: =SUM(D18:D22) -> 1 | E23: =SUM(E18:E22) -> 1 | F23: =SUM(F18:F22) -> 1 | G23: =SUM(G18:G22) -> 1 | H23: =SUM(H18:H22) -> 1 | I23: =SUM(I18:I22) -> 1 | J23: =SUM(J18:J22) -> 1 | K23: =SUM(K18:K22) -> 1 | M23: =SUM(M18:M22) -> 1 | N23: =SUM(N18:N22) -> 1 | O23: =SUM(O18:O22) -> 1 | P23: =SUM(P18:P22) -> 1 | Q23: =SUM(Q18:Q22) -> 1 | R23: =SUM(R18:R22) -> 1 | S23: =SUM(S18:S22) -> 1 | T23: =SUM(T18:T22) -> 1 | ... AK23: =SUM(AK18:AK22) -> 1
B25: Revenue by segment (YoY % Growth)
B26: Smartphones | D26: =D9/C9-1 -> 0.072886493 | E26: =E9/D9-1 -> 0.24649674 | F26: =F9/E9-1 -> 0.37241423 | G26: =G9/F9-1 -> -0.1994158 | H26: =H9/G9-1 -> -0.058342553 | I26: =I9/H9-1 -> 0.2178186 | J26: =J9/I9-1 -> -0.027740626 | Q26: =Q9/M9-1 -> 0.69798692 | R26: =R9/N9-1 -> 0.86827512 | S26: =S9/O9-1 -> 0.0046382317 | T26: =T9/P9-1 -> 0.18364429 | U26: =U9/Q9-1 -> -0.11124849 | V26: =V9/R9-1 -> -0.28467005 | W26: =W9/S9-1 -> -0.11104444 | X26: =X9/T9-1 -> -0.27330184 | ... AK26: =AK9/AG9-1 -> -0.12523961
B27: IoT and lifestyle products | D27: =D10/C10-1 -> 0.41698795 | E27: =E10/D10-1 -> 0.085724378 | F27: =F10/E10-1 -> 0.26063679 | G27: =G10/F10-1 -> -0.061016876 | H27: =H10/G10-1 -> 0.0039203394 | I27: =I10/H10-1 -> 0.29954923 | J27: =J10/I10-1 -> 0.18343492 | Q27: =Q10/M10-1 -> 0.40503502 | R27: =R10/N10-1 -> 0.35939634 | S27: =S10/O10-1 -> 0.15544637 | T27: =T10/P10-1 -> 0.19056503 | U27: =U10/Q10-1 -> 0.067646327 | V27: =V10/R10-1 -> -0.044518865 | W27: =W10/S10-1 -> -0.089651735 | X27: =X10/T10-1 -> -0.14438811 | ... AK27: =AK10/AG10-1 -> -0.23680453
B28: Internet services | D28: =D11/C11-1 -> 0.24355218 | E28: =E11/D11-1 -> 0.19724831 | F28: =F11/E11-1 -> 0.18759842 | G28: =G11/F11-1 -> 0.0038886295 | H28: =H11/G11-1 -> 0.063063734 | I28: =I11/H11-1 -> 0.13311965 | J28: =J11/I11-1 -> 0.097461733 | Q28: =Q11/M11-1 -> 0.11357169 | R28: =R11/N11-1 -> 0.19057858 | S28: =S11/O11-1 -> 0.27130922 | T28: =T11/P11-1 -> 0.1772397 | U28: =U11/Q11-1 -> 0.082429696 | V28: =V11/R11-1 -> -0.0088670101 | W28: =W11/S11-1 -> -0.036968014 | X28: =X11/T11-1 -> -0.013521613 | ... AK28: =AK11/AG11-1 -> 0.043217806
B29: Smart EV and other new initiatives | D29: =D12/C12-1 -> #DIV/0! | E29: =E12/D12-1 -> #DIV/0! | F29: =F12/E12-1 -> #DIV/0! | G29: =G12/F12-1 -> #DIV/0! | H29: =H12/G12-1 -> #DIV/0! | I29: =I12/H12-1 -> #DIV/0! | J29: =J12/I12-1 -> 2.2384078 | Q29: =Q12/M12-1 -> #DIV/0! | R29: =R12/N12-1 -> #DIV/0! | S29: =S12/O12-1 -> #DIV/0! | T29: =T12/P12-1 -> #DIV/0! | U29: =U12/Q12-1 -> #DIV/0! | V29: =V12/R12-1 -> #DIV/0! | W29: =W12/S12-1 -> #DIV/0! | X29: =X12/T12-1 -> #DIV/0! | ... AK29: =AK12/AG12-1 -> 0.069125269
B30: Others | D30: =D13/C13-1 -> 0.35127618 | E30: =E13/D13-1 -> 0.38296721 | F30: =F13/E13-1 -> 1.4903767 | G30: =G13/F13-1 -> -0.2461199 | H30: =H13/G13-1 -> -0.30079877 | I30: =I13/H13-1 -> -0.036252125 | J30: =J13/I13-1 -> 0.30327642 | Q30: =Q13/M13-1 -> 0.17161043 | R30: =R13/N13-1 -> 0.24280877 | S30: =S13/O13-1 -> 1.9420577 | T30: =T13/P13-1 -> 3.6329562 | U30: =U13/Q13-1 -> 0.73113081 | V30: =V13/R13-1 -> 0.20199889 | W30: =W13/S13-1 -> -0.066030749 | X30: =X13/T13-1 -> -0.72730952 | ... AK30: =AK13/AG13-1 -> 0.24545292
B31: Net Revenue | D31: =D14/C14-1 -> 0.17678977 | E31: =E14/D14-1 -> 0.19445787 | F31: =F14/E14-1 -> 0.33531938 | G31: =G14/F14-1 -> -0.14701122 | H31: =H14/G14-1 -> -0.032401749 | I31: =I14/H14-1 -> 0.35035711 | J31: =J14/I14-1 -> 0.24973678 | Q31: =Q14/M14-1 -> 0.54685736 | R31: =R14/N14-1 -> 0.63975643 | S31: =S14/O14-1 -> 0.081760684 | T31: =T14/P14-1 -> 0.21447154 | U31: =U14/Q14-1 -> -0.045923019 | V31: =V14/R14-1 -> -0.20068677 | W31: =W14/S14-1 -> -0.097211228 | X31: =X14/T14-1 -> -0.22819469 | ... AK31: =AK14/AG14-1 -> -0.1091864
B35: Revenue by geography
B36: Mainland China | C36: 104944.8 | D36: 114608.63 | E36: 123484.25 | F36: 164717.7 | G36: 142258.42 | H36: 149189.72 | I36: 212562.45 | J36: 306223.14 | K36: =SUM(AH36:AK36) -> 292725.42 | M36: 24870.044 | N36: 29509.195 | O36: 32393.887 | P36: =E36-SUM(M36:O36) -> 36711.125 | Q36: 39473.714 | R36: 44150.041 | S36: 37161.472 | T36: =F36-SUM(Q36:S36) -> 43932.477 | U36: 35889.645 | V36: 36201.979 | W36: 34904.227 | X36: =G36-SUM(U36:W36) -> 35262.566 | Y36: 32491.984 | Z36: 39585.96 | AA36: 36213.944 | AB36: =H36-SUM(Y36:AA36) -> 40897.832 | AC36: 37634.073 | AD36: 50812.668 | AE36: 52347.842 | AF36: =I36-SUM(AC36:AE36) -> 71767.866 | AG36: 73068.671 | AH36: 79265.167 | AI36: 73058.359 | AJ36: =J36-SUM(AG36:AI36) -> 80830.944 | AK36: 59570.951
B37: Rest of the world | C37: 69970.622 | D37: 91230.049 | E37: 122381.38 | F37: 163591.44 | G37: 137785.6 | H37: 121780.42 | I37: 153343.9 | J37: 151063.55 | K37: =SUM(AH37:AK37) -> 152409.55 | M37: 24832.123 | N37: 24028.61 | O37: 39768.89 | P37: =E37-SUM(M37:O37) -> 33751.759 | Q37: 37408.449 | R37: 43638.919 | S37: 40901.383 | T37: =F37-SUM(Q37:S37) -> 41642.69 | U37: 37461.857 | V37: 33968.898 | W37: 35570.042 | X37: =G37-SUM(U37:W37) -> 30784.802 | Y37: 26985.15 | Z37: 27768.948 | AA37: 34680.468 | AB37: =H37-SUM(Y37:AA37) -> 32345.855 | AC37: 37872.749 | AD37: 38075.16 | AE37: 40158.699 | AF37: =I37-SUM(AC37:AE37) -> 37237.293 | AG37: 38224.666 | AH37: 36690.924 | AI37: 40062.375 | AJ37: =J37-SUM(AG37:AI37) -> 36085.581 | AK37: 39570.667
B38: Net Revenue | C38: =SUM(C36:C37) -> 174915.42 | D38: =SUM(D36:D37) -> 205838.68 | E38: =SUM(E36:E37) -> 245865.63 | F38: =SUM(F36:F37) -> 328309.15 | G38: =SUM(G36:G37) -> 280044.02 | H38: =SUM(H36:H37) -> 270970.14 | I38: =SUM(I36:I37) -> 365906.35 | J38: =SUM(J36:J37) -> 457286.69 | K38: =SUM(K36:K37) -> 445134.97 | M38: =SUM(M36:M37) -> 49702.167 | N38: =SUM(N36:N37) -> 53537.805 | O38: =SUM(O36:O37) -> 72162.777 | P38: =SUM(P36:P37) -> 70462.884 | Q38: =SUM(Q36:Q37) -> 76882.163 | R38: =SUM(R36:R37) -> 87788.96 | S38: =SUM(S36:S37) -> 78062.855 | T38: =SUM(T36:T37) -> 85575.167 | ... AK38: =SUM(AK36:AK37) -> 99141.618
B39: check | C39: =C38-Model!C7 -> 0 | D39: =D38-Model!D7 -> 0 | E39: =E38-Model!E7 -> 0 | F39: =F38-Model!F7 -> 0 | G39: =G38-Model!G7 -> 0 | H39: =H38-Model!H7 -> 0.041 | I39: =I38-Model!I7 -> 0 | J39: =J38-Model!J7 -> 0 | K39: =K38-Model!K7 -> 0 | M39: =M38-Model!M7 -> 0 | N39: =N38-Model!N7 -> 0 | O39: =O38-Model!O7 -> 0 | P39: =P38-Model!P7 -> 0 | Q39: =Q38-Model!Q7 -> 0 | R39: =R38-Model!R7 -> 0 | S39: =S38-Model!S7 -> 0 | T39: =T38-Model!T7 -> 0 | ... AK39: =AK38-Model!AK7 -> 0
B41: Revenue by geography (% Share)
B42: Mainland China | C42: =C36/C$38 -> 0.59997455 | D42: =D36/D$38 -> 0.55678861 | E42: =E36/E$38 -> 0.50224283 | F42: =F36/F$38 -> 0.50171525 | G42: =G36/G$38 -> 0.50798592 | H42: =H36/H$38 -> 0.55057623 | I42: =I36/I$38 -> 0.58092036 | J42: =J36/J$38 -> 0.66965243 | K42: =K36/K$38 -> 0.65761048 | M42: =M36/M$38 -> 0.50038148 | N42: =N36/N$38 -> 0.55118425 | O42: =O36/O$38 -> 0.44890023 | P42: =P36/P$38 -> 0.52099947 | Q42: =Q36/Q$38 -> 0.51343137 | R42: =R36/R$38 -> 0.50291108 | S42: =S36/S$38 -> 0.47604551 | T42: =T36/T$38 -> 0.51337881 | ... AK42: =AK36/AK$38 -> 0.60086725
B43: Rest of the world | C43: =C37/C$38 -> 0.40002545 | D43: =D37/D$38 -> 0.44321139 | E43: =E37/E$38 -> 0.49775717 | F43: =F37/F$38 -> 0.49828475 | G43: =G37/G$38 -> 0.49201408 | H43: =H37/H$38 -> 0.44942377 | I43: =I37/I$38 -> 0.41907964 | J43: =J37/J$38 -> 0.33034757 | K43: =K37/K$38 -> 0.34238952 | M43: =M37/M$38 -> 0.49961852 | N43: =N37/N$38 -> 0.44881575 | O43: =O37/O$38 -> 0.55109977 | P43: =P37/P$38 -> 0.47900053 | Q43: =Q37/Q$38 -> 0.48656863 | R43: =R37/R$38 -> 0.49708892 | S43: =S37/S$38 -> 0.52395449 | T43: =T37/T$38 -> 0.48662119 | ... AK43: =AK37/AK$38 -> 0.39913275
B44: Net Revenue | C44: =SUM(C42:C43) -> 1 | D44: =SUM(D42:D43) -> 1 | E44: =SUM(E42:E43) -> 1 | F44: =SUM(F42:F43) -> 1 | G44: =SUM(G42:G43) -> 1 | H44: =SUM(H42:H43) -> 1 | I44: =SUM(I42:I43) -> 1 | J44: =SUM(J42:J43) -> 1 | K44: =SUM(K42:K43) -> 1 | M44: =SUM(M42:M43) -> 1 | N44: =SUM(N42:N43) -> 1 | O44: =SUM(O42:O43) -> 1 | P44: =SUM(P42:P43) -> 1 | Q44: =SUM(Q42:Q43) -> 1 | R44: =SUM(R42:R43) -> 1 | S44: =SUM(S42:S43) -> 1 | T44: =SUM(T42:T43) -> 1 | ... AK44: =SUM(AK42:AK43) -> 1
B46: Revenue by geography (YoY % Growth)
B47: Mainland China | D47: =D36/C36-1 -> 0.092084884 | E47: =E36/D36-1 -> 0.07744284 | F47: =F36/E36-1 -> 0.3339167 | G47: =G36/F36-1 -> -0.13635017 | H47: =H36/G36-1 -> 0.048723324 | I47: =I36/H36-1 -> 0.42477946 | J47: =J36/I36-1 -> 0.44062671 | Q47: =Q36/M36-1 -> 0.5871992 | R47: =R36/N36-1 -> 0.49614522 | S47: =S36/O36-1 -> 0.14717545 | T47: =T36/P36-1 -> 0.19670746 | U47: =U36/Q36-1 -> -0.090796346 | V47: =V36/R36-1 -> -0.18002389 | W47: =W36/S36-1 -> -0.060741539 | X47: =X36/T36-1 -> -0.19734628 | ... AK47: =AK36/AG36-1 -> -0.1847265
B48: Rest of the world | D48: =D37/C37-1 -> 0.30383361 | E48: =E37/D37-1 -> 0.34145913 | F48: =F37/E37-1 -> 0.33673471 | G48: =G37/F37-1 -> -0.15774567 | H48: =H37/G37-1 -> -0.11616002 | I48: =I37/H37-1 -> 0.25918353 | J48: =J37/I37-1 -> -0.014870856 | Q48: =Q37/M37-1 -> 0.50645392 | R48: =R37/N37-1 -> 0.81612332 | S48: =S37/O37-1 -> 0.028476857 | T48: =T37/P37-1 -> 0.23379318 | U48: =U37/Q37-1 -> 0.0014276989 | V48: =V37/R37-1 -> -0.22159167 | W48: =W37/S37-1 -> -0.13034623 | X48: =X37/T37-1 -> -0.26073935 | ... AK48: =AK37/AG37-1 -> 0.035212891
B49: Net Revenue | D49: =D38/C38-1 -> 0.17678977 | E49: =E38/D38-1 -> 0.19445787 | F49: =F38/E38-1 -> 0.33531938 | G49: =G38/F38-1 -> -0.14701122 | H49: =H38/G38-1 -> -0.032401603 | I49: =I38/H38-1 -> 0.35035672 | J49: =J38/I38-1 -> 0.24973695 | Q49: =Q38/M38-1 -> 0.54685736 | R49: =R38/N38-1 -> 0.63975643 | S49: =S38/O38-1 -> 0.081760684 | T49: =T38/P38-1 -> 0.21447154 | U49: =U38/Q38-1 -> -0.045923019 | V49: =V38/R38-1 -> -0.20068677 | W49: =W38/S38-1 -> -0.097211228 | X49: =X38/T38-1 -> -0.22819469 | ... AK49: =AK38/AG38-1 -> -0.1091864
B52: Cost of revenues by segment
...
