Workbook
Name \A: #REF!
Name \B: #REF!
Name \C: #REF!
Name \L: #REF!
Name \M: #REF!
Name \P: #REF!
Name \Y: #REF!
Name _01_30_04: MonthlyOpStats
Name _01_30_04: MonthlyOpStats
Name _01_30_04: MonthlyOpStats
Name _1_30_01: MonthlyOpStats
Name _1_30_01: MonthlyOpStats
Name _1_30_01: MonthlyOpStats
Name _1_30_02: MonthlyOpStats
Name _1_30_02: MonthlyOpStats
Name _1_30_02: MonthlyOpStats
Name _1_31_01: MonthlyOpStats
Name _1_31_01: MonthlyOpStats
Name _1_31_01: MonthlyOpStats
Name _1_31_02: MonthlyOpStats
Name _1_31_02: MonthlyOpStats
Name _1_31_02: MonthlyOpStats
Name _12_31_05: MonthlyOpStats
Name _12_31_05: MonthlyOpStats
Name _12_31_05: MonthlyOpStats
Name _A: #REF!
Name _A___0: #REF!
Name _B: #REF!
Name _B___0: #REF!
Name _C: #REF!
Name _C___0: #REF!
Name _ent1: [1]Inputs!$J$17
Name _ent10: [1]Inputs!$J$476
Name _ent11: [1]Inputs!$J$527
Name _ent12: [1]Inputs!$J$578
Name _ent13: [1]Inputs!$J$629
Name _ent14: [1]Inputs!$J$680
Name _ent15: [1]Inputs!$J$731
Name _ent2: [1]Inputs!$J$68
Name _ent3: [1]Inputs!$J$119
Name _ent4: [1]Inputs!$J$170
Name _ent5: [1]Inputs!$J$221
Name _ent6: [1]Inputs!$J$272
Name _ent7: [1]Inputs!$J$323
Name _ent8: [1]Inputs!$J$374
Name _ent9: [1]Inputs!$J$425
Name _eps1: [1]Inputs!$P$42
Name _eps10: [1]Inputs!$P$501
Name _eps11: [1]Inputs!$P$552
Name _eps12: [1]Inputs!$P$603
Name _eps13: [1]Inputs!$P$654
Name _eps14: [1]Inputs!$P$705
Name _eps15: [1]Inputs!$P$756
Name _eps2: [1]Inputs!$P$93
Name _eps3: [1]Inputs!$P$144
Name _eps4: [1]Inputs!$P$195
Name _eps5: [1]Inputs!$P$246
Name _eps6: [1]Inputs!$P$297
Name _eps7: [1]Inputs!$P$348
Name _eps8: [1]Inputs!$P$399

Sheet Capitalisation
A3: 1Q26 | I3: Exchange rate at the end | J3: =Model!$BF$382 -> 926.27
I4: LTM Average exchange rate | J4: =Model!$BF$381 -> 886.57
B6: As on 31-Mar-2026 | C6: CLP (m) | D6: USD (m) | E6: Leverage (CLP) | F6: Leverage (USD) | I6: Company Reported | J6: =C6 -> CLP (m) | K6: =D6 -> USD (m) | L6: =E6 -> Leverage (CLP) | M6: =F6 -> Leverage (USD)
B7: Bank Loans | C7: 304625.54 | D7: =C7/$J3 -> 328.87337 | I7: Consolidated Financial debt (excluding banking operations) | J7: =+C17-C14-C9-C10-C15 -> 3554283.8 | K7: =J7/$J3 -> 3837.2006 | L7: =J7/J10 -> 2.7550026 | M7: =K7/K10 -> 2.636923
B8: Bonds payable | C8: 64251.817 | D8: =C8/$J3 -> 69.366186 | I8: Cash & Equivalents (including other financial assets) | J8: =Model!$BF$252+24956.527 -> 1853519.8 | K8: =J8/$J3 -> 2001.0578
B9: Financial lease obligations | C9: 133112.24 | D9: =C9/$J3 -> 143.70782 | I9: Net debt | J9: =+J7-J8 -> 1700764 | K9: =J9/$J3 -> 1836.1428 | L9: =J9/J10 -> 1.3182991 | M9: =K9/K10 -> 1.2617967
B10: Other financial debt | C10: 17709.194 | D10: =C10/$J3 -> 19.118825 | I10: LTM Non-Banking Adjusted EBITDA | J10: =C27-230033 -> 1290119.9 | K10: =J10/J4 -> 1455.1811
B11: Total short-term retail business debt | C11: =SUM(C7:C10) -> 519698.79 | D11: =SUM(D7:D10) -> 561.0662
B12: Bank loans | C12: 241709.94 | D12: =C12/$J3 -> 260.94977
B13: Bonds payable | C13: 2943696.5 | D13: =C13/$J3 -> 3178.0113
B14: Financial lease obligations | C14: 1317997 | D14: =C14/$J3 -> 1422.908 | I14: Exlcudes financial leases
B15: Other financial debt | C15: 1331.322 | D15: =C15/$J3 -> 1.4372937
B16: Total long-term retail business debt | C16: =SUM(C12:C15) -> 4504734.7 | D16: =SUM(D12:D15) -> 4863.3063
B17: Total Retail business Debt | C17: =C16+C11 -> 5024433.5 | D17: =D16+D11 -> 5424.3725 | E17: =+C17/C27 -> 3.3052158 | F17: =+D17/D27 -> 3.163554
B18: Cash & Equivalents | C18: =Model!$BF$252 -> 1828563.3 | D18: =C18/$J3 -> 1974.1148
B19: Net debt | C19: =+C17-C18 -> 3195870.2 | D19: =+D17-D18 -> 3450.2577 | E19: =+C19/C27 -> 2.1023347 | F19: =+D19/D27 -> 2.0122284
B21: Obligations with other banks | C21: =Model!$BF$272 -> 206456.31 | D21: =C21/$J3 -> 222.88999
B22: Debt instruments issued | C22: =Model!$BF$273 -> 330432.82 | D22: =C22/$J3 -> 356.73488
B23: Lease liabilities | C23: =Model!$BF$274 -> 29150.929 | D23: =C23/$J3 -> 31.471309
B24: Banking business debt, total | C24: =C21+C22+C23 -> 566040.06 | D24: =D21+D22+D23 -> 611.09618
B25: Equity | C25: =Model!$BF$272 -> 206456.31 | D25: =C25/$J3 -> 222.88999
B26: Total Capitalisation | C26: =C25+C17+C24 -> 5796929.9 | D26: =D25+D17+D24 -> 6258.3587
B27: LTM Non-Banking Adjusted EBITDA | C27: =Model!$BF$204 -> 1520152.9 | D27: =C27/$J4 -> 1714.6451
B29: Debt check | C29: =C17-Model!$BF$260 -> 0
B31: Market cap | C31: =Model!$BF$289 -> 15288900
B32: EV | C32: =C31+Model!$BF$283 -> 19428264
B33: EV/EBITDA | C33: =C32/C34 -> 9.6413544
B34: LTM Total Adjusted EBITDA (Banking + Retail) | C34: =Model!$BF$223 -> 2015097
B38: Liquidity Table | C38: CLP(m) | D38: USD (m)
B39: RCF | C39: 0 | D39: 0
B40: Cash | C40: =C18 -> 1828563.3 | D40: =D18 -> 1974.1148
B41: Total Liquidity | C41: =C39+C40 -> 1828563.3 | D41: =D39+D40 -> 1974.1148
B45: Debt Maturity Profile - BBG | C45: CLP(m) | D45: USD (m)
B46: 2026 | C46: =24042.48+272083.03 -> 296125.51 | D46: =C46/$J3 -> 319.69675
B47: 2027 | C47: 402521.53 | D47: =C47/$J3 -> 434.56177
B48: 2028 | C48: 212845.65 | D48: =C48/$J3 -> 229.78791
B49: 2029 | C49: 454751.53 | D49: =C49/$J3 -> 490.94922
B50: 2030 | C50: 289817.88 | D50: =C50/$J3 -> 312.88704
B51: 2031 & therafter | C51: =3811977.62+272083.03-SUM(C46:C50) -> 2427998.6 | D51: =C51/$J3 -> 2621.2644
B52: Total debt | C52: =SUM(C46:C51) -> 4084060.7 | D52: =SUM(D46:D51) -> 4409.1471
...

Sheet Model
B2: Falabella | C2: Annual | D2: Annual | E2: Annual | F2: Annual | G2: Annual | H2: Annual | I2: Annual | J2: Annual | K2: Annual | L2: Annual | M2: Annual | N2: Annual | O2: Annual | P2: Annual | R2: Quarterly | S2: Quarterly | T2: Quarterly | U2: Quarterly | V2: Quarterly | W2: Quarterly | X2: Quarterly | Y2: Quarterly | Z2: Quarterly | AA2: Quarterly | AB2: Quarterly | AC2: Quarterly | AD2: Quarterly | AE2: Quarterly | AF2: Quarterly | AG2: Quarterly | AH2: Quarterly | AI2: Quarterly | AJ2: Quarterly | AK2: Quarterly | AL2: Quarterly | AM2: Quarterly | AN2: Quarterly | AO2: Quarterly | AP2: Quarterly | AQ2: Quarterly | AR2: Quarterly | AS2: Quarterly | AT2: Quarterly | AU2: Quarterly | AV2: Quarterly | AW2: Quarterly | AX2: Quarterly | AY2: Quarterly | AZ2: Quarterly | BA2: Quarterly | BB2: Quarterly | BC2: Quarterly | BD2: Quarterly | BE2: Quarterly | BF2: Quarterly | BH2: Quarterly | BI2: Quarterly | BJ2: Quarterly | BK2: Quarterly | BL2: Quarterly | BN2: Half year | BO2: Half year | BP2: Half year | BQ2: Half year | BR2: Half year | BS2: Half year | BT2: Half year | BU2: Half year | BV2: Half year | BW2: Half year | BY2: Half year | BZ2: Half year | CC2: Quarterly | CD2: Half year | CE2: Nine Months
B3: (CLP $) | C3: 41975 | D3: 42341 | E3: 42708 | F3: 43073 | G3: 43073 | H3: 43438 | I3: 43438 | J3: 43803 | K3: 44169 | L3: 44534 | M3: 44899 | N3: 45264 | O3: 45630 | P3: 45995 | R3: 42437 | S3: 42527 | T3: 42622 | U3: 42714 | V3: 42801 | W3: 42892 | X3: 42987 | Y3: 43079 | Z3: 43166 | AA3: 43257 | AB3: 43352 | AC3: 43444 | AD3: 43531 | AE3: 43622 | AF3: 43738 | AG3: 43809 | AH3: 43897 | AI3: 43988 | AJ3: 44104 | AK3: 44175 | AL3: 44262 | AM3: 44348 | AN3: 44469 | AO3: 44540 | AP3: 44651 | AQ3: 44713 | AR3: 44834 | AS3: 44905 | AT3: 45016 | AU3: 45078 | AV3: 45199 | AW3: 45270 | AX3: 45382 | AY3: 45444 | AZ3: 45565 | BA3: 45636 | BB3: 45747 | BC3: 45809 | BD3: 45930 | BE3: 46001 | BF3: 46112 | BH3: 43166 | BI3: 43281 | BJ3: 43373 | BK3: 43444 | BL3: 43531 | BN3: 42530 | BO3: 42896 | BP3: 43261 | BQ3: 43646 | BR3: 44012 | BS3: 44377 | BT3: 44742 | BU3: 45107 | BV3: 45473 | BW3: 45838 | BY3: 43281 | BZ3: 43646 | CC3: 42071 | CD3: 42161 | CE3: 42256
C4: Act | D4: Act | E4: Act | F4: Act | G4: Act | H4: Act | I4: Act | J4: Act | K4: Act | L4: Act | M4: Act | N4: Act | O4: Act | P4: Act | R4: Act | S4: Act | T4: Act | U4: Act | V4: Act | W4: Act | X4: Act | Y4: Act | Z4: Act | AA4: Act | AB4: Act | AC4: Act | AD4: Act | AE4: Act | AF4: Act | AG4: Act | AH4: Act | AI4: Act | AJ4: Act | AK4: Act | AL4: Act | AM4: Act | AN4: Act | AO4: Act | AP4: Act | AQ4: Act | AR4: Restated | AS4: Act | AT4: Act | AU4: Act | AV4: Act | AW4: Act | AX4: Act | AY4: Act | AZ4: Act | BA4: Act | BB4: Act | BC4: Act | BD4: Act | BE4: Act | BF4: Act | BH4: Act | BI4: Act | BJ4: Act | BK4: Act | BL4: Act | BN4: Act | BO4: Act | BP4: Act | BQ4: Act | BR4: Act | BS4: Act | BT4: Act | BU4: Act | BV4: Act | BW4: Act | BY4: Act | BZ4: Act | CD4: Act
C5: FY | D5: FY | E5: FY | F5: FY | G5: FY | H5: FY | I5: FY | J5: FY | K5: FY | L5: FY | M5: FY | N5: FY | O5: FY | P5: FY | R5: Q1 | S5: Q2 | T5: Q3 | U5: Q4 | V5: Q1 | W5: Q2 | X5: Q3 | Y5: Q4 | Z5: Q1 | AA5: Q2 | AB5: Q3 | AC5: Q4 | AD5: Q1 | AE5: Q2 | AF5: Q3 | AG5: Q4 | AH5: Q1 | AI5: Q2 | AJ5: Q3 | AK5: Q4 | AL5: Q1 | AM5: Q2 | AN5: Q3 | AO5: Q4 | AP5: Q1 | AQ5: Q2 | AR5: Q3 | AS5: Q4 | AT5: Q1 | AU5: Q2 | AV5: Q3 | AW5: Q4 | AX5: Q1 | AY5: Q2 | AZ5: Q3 | BA5: Q4 | BB5: Q1 | BC5: Q2 | BD5: Q3 | BE5: Q4 | BF5: Q1 | BH5: Q1 | BI5: Q2 | BJ5: Q3 | BK5: Q4 | BL5: Q1 | BN5: H1 2016 | BO5: H1 2017 | BP5: H1 2018 | BQ5: H1 2019 | BR5: H1 2020 | BS5: H1 2021 | BT5: H1 2022 | BU5: H1 2023 | BV5: H1 2024 | BW5: H1 2025 | BY5: H1 2018 | BZ5: H1 2019 | CC5: Q1 | CD5: H12015 | CE5: 9M2015
B6: INCOME STATEMENT | G6: Restated | I6: Restated | BH6: Restated | BI6: Restated | BJ6: Restated | BK6: Restated | BL6: Restated | BY6: Restated | BZ6: Restated
B7: Non-Banking Business
B8: Revenues | C8: 7038379.8 | D8: 7753209.6 | E8: 7898301.8 | F8: 8242645.3 | G8: 8209851.5 | H8: 8483577.3 | I8: 7976898.4 | J8: 8053582.8 | K8: 8281049.9 | L8: 10335384 | M8: 10460666 | N8: 9355114.7 | O8: 10322104 | P8: 11342386 | R8: 1889596.2 | S8: =BN8-R8 -> 1948787.3 | T8: =5707941.211-S8-R8 -> 1869557.7 | U8: =E8-T8-S8-R8 -> 2190360.6 | V8: 1952033.1 | W8: =BO8-V8 -> 2015162.9 | X8: =5909189.615-W8-V8 -> 1941993.6 | Y8: =F8-X8-W8-V8 -> 2333455.6 | Z8: 2010257.7 | AA8: =BP8-Z8 -> 2106536.8 | AB8: =6121405.241-AA8-Z8 -> 2004610.8 | AC8: =H8-AB8-AA8-Z8 -> 2362172.1 | AD8: 1926900.5 | AE8: =BQ8-AD8 -> 1994081 | AF8: =5802437.766-AE8-AD8 -> 1881456.2 | AG8: =J8-AF8-AE8-AD8 -> 2251145.1 | AH8: 1887698.6 | AI8: =BR8-AH8 -> 1458364.1 | AJ8: =5563468.36-AI8-AH8 -> 2217405.7 | AK8: =K8-AJ8-AI8-AH8 -> 2717581.6 | AL8: 2218078.5 | AM8: =BS8-AL8 -> 2390588.7 | AN8: =7229559.641-AM8-AL8 -> 2620892.4 | AO8: =L8-AN8-AM8-AL8 -> 3105824.1 | AP8: 2546146.6 | AQ8: =BT8-AP8 -> 2619187.9 | AR8: =7657493.231-AQ8-AP8 -> 2492158.7 | AS8: =M8-AR8-AQ8-AP8 -> 2803173.2 | AT8: 2274726.3 | AU8: =BU8-AT8 -> 2219917.4 | AV8: =6701080.263-AU8-AT8 -> 2206436.6 | AW8: =N8-AV8-AU8-AT8 -> 2654034.4 | AX8: 2392525.6 | AY8: =BV8-AX8 -> 2445288.2 | AZ8: =7240767.681-AY8-AX8 -> 2402953.9 | BA8: =O8-AZ8-AY8-AX8 -> 3081336.8 | BB8: 2653179.2 | BC8: =BW8-BB8 -> 2693468.6 | BD8: =7976947.918-BC8-BB8 -> 2630300.1 | BE8: =P8-BD8-BC8-BB8 -> 3365438 | BF8: 2766025.9 | BH8: 1887142.6 | BI8: =BY8-BH8 -> 1980615.5 | BJ8: =5745783.56-BI8-BH8 -> 1878025.5 | BK8: =I8-AB8-AA8-Z8 -> 1855493.2 | BL8: 1926900.5 | BN8: 3838383.5 | BO8: 3967196 | BP8: 4116794.5 | BQ8: 3920981.5 | BR8: 3346062.7 | BS8: 4608667.2 | BT8: 5165334.5 | BU8: 4494643.6 | BV8: 4837813.8 | BW8: 5346647.9 | BY8: 3867758.1 | BZ8: 3920981.5 | CC8: 1817584.6 | CD8: 3673268.5 | CE8: 5515070.3
B9: % growth | C9: =C8/6196082.713-1 -> 0.13594026 | D9: =D8/C8-1 -> 0.1015617 | E9: =E8/D8-1 -> 0.018713826 | F9: =F8/E8-1 -> 0.043597154 | H9: =H8/G8-1 -> 0.033341142 | I9: =I8/G8-1 -> -0.028374826 | J9: =J8/I8-1 -> 0.0096133141 | K9: =K8/J8-1 -> 0.028244214 | L9: =L8/K8-1 -> 0.24807649 | M9: =M8/L8-1 -> 0.012121723 | N9: =N8/M8-1 -> -0.10568655 | O9: =O8/N8-1 -> 0.10336483 | P9: =P8/O8-1 -> 0.098844322 | R9: =R8/CC8-1 -> 0.03961939 | S9: =S8/(CD8-CC8)-1 -> 0.050172034 | T9: =T8/(CE8-CD8)-1 -> 0.015069958 | U9: =U8/(D8-CE8)-1 -> -0.021347506 | V9: =V8/R8-1 -> 0.03304245 | W9: =W8/S8-1 -> 0.034059974 | X9: =X8/T8-1 -> 0.038744925 | Y9: =Y8/U8-1 -> 0.065329461 | Z9: =Z8/V8-1 -> 0.029827656 | AA9: =AA8/W8-1 -> 0.045343174 | AB9: =AB8/X8-1 -> 0.032243758 | AC9: =AC8/Y8-1 -> 0.012306402 | AD9: =AD8/BH8-1 -> 0.021067761 | AE9: =AE8/BI8-1 -> 0.006798665 | AF9: =AF8/BJ8-1 -> 0.0018268096 | AG9: =AG8/AC8-1 -> -0.047002089 | AH9: =AH8/AD8-1 -> -0.020344538 | AI9: =AI8/AE8-1 -> -0.26865353 | AJ9: =AJ8/AF8-1 -> 0.17855818 | AK9: =AK8/AG8-1 -> 0.20719967 | AL9: =AL8/AH8-1 -> 0.17501726 | AM9: =AM8/AI8-1 -> 0.63922628 | AN9: =AN8/AJ8-1 -> 0.18196345 | ... BF9: =BF8/BB8-1 -> 0.042532633 | BH9: =BH8/V8-1 -> -0.033242505 | BI9: =BI8/W8-1 -> -0.017143747 | BJ9: =BJ8/X8-1 -> -0.03293942 | BK9: =BK8/Y8-1 -> -0.20483033 | BL9: =BL8/BH8-1 -> 0.021067761 | BN9: =BN8/CD8-1 -> 0.044950438 | BO9: =BO8/BN8-1 -> 0.033559057 | BP9: =BP8/BO8-1 -> 0.037708864 | BQ9: =BQ8/BY8-1 -> 0.013760791 | BR9: =BR8/BZ8-1 -> -0.14662625 | BS9: =(BS8/BR8)-1 -> 0.37734036 | BT9: =(BT8/BS8)-1 -> 0.12078704 | BU9: =(BU8/BT8)-1 -> -0.12984461 | BV9: =(BV8/BU8)-1 -> 0.076350917 | BW9: =(BW8/BV8)-1 -> 0.10517851 | BY9: =BY8/BO8-1 -> -0.025065037 | BZ9: =BZ8/BY8-1 -> 0.013760791
B10: LFL Sales growth
B11: COGS | C11: -4654988.9 | D11: -5098131.6 | E11: -5180719.9 | F11: -5360352 | G11: -5296643 | H11: -5508545.4 | I11: -5255756.4 | J11: -5433070.2 | K11: -5790733.7 | L11: -7047860.2 | M11: -7264723.3 | N11: -6423567.1 | O11: -6844745.1 | P11: -7370628.6 | R11: -1266353.8 | S11: =BN11-R11 -> -1279016.6 | T11: =-3779644.108-S11-R11 -> -1234273.7 | U11: =E11-T11-S11-R11 -> -1401075.8 | V11: -1281071.7 | W11: =BO11-V11 -> -1305217.1 | X11: =-3867346.306-W11-V11 -> -1281057.5 | Y11: =F11-X11-W11-V11 -> -1493005.7 | Z11: -1308674.8 | AA11: =BP11-Z11 -> -1360544.2 | AB11: =-3986411.625-AA11-Z11 -> -1317192.7 | AC11: =H11-AB11-AA11-Z11 -> -1522133.7 | AD11: -1323019.3 | AE11: =BQ11-AD11 -> -1330915.3 | AF11: =-3931139.953-AE11-AD11 -> -1277205.3 | AG11: =J11-AF11-AE11-AD11 -> -1501930.3 | AH11: -1301030.6 | AI11: =BR11-AH11 -> -1063909.1 | AJ11: =-3978350.803-AI11-AH11 -> -1613411.1 | AK11: =K11-AJ11-AI11-AH11 -> -1812382.9 | AL11: -1534201.3 | AM11: =BS11-AL11 -> -1653372.8 | AN11: =-4980184.977-AM11-AL11 -> -1792610.9 | AO11: =L11-AN11-AM11-AL11 -> -2067675.3 | AP11: -1796600.8 | AQ11: =BT11-AP11 -> -1799463.2 | AR11: =-5332866.394-AQ11-AP11 -> -1736802.4 | AS11: =M11-AR11-AQ11-AP11 -> -1931856.9 | AT11: -1614201.7 | AU11: =BU11-AT11 -> -1519467.2 | AV11: =-4656631.536-AU11-AT11 -> -1522962.6 | AW11: =N11-AV11-AU11-AT11 -> -1766935.6 | AX11: -1617669.2 | AY11: =BV11-AX11 -> -1625083.1 | AZ11: =-4835758.418-AY11-AX11 -> -1593006.1 | BA11: =O11-AZ11-AY11-AX11 -> -2008986.7 | BB11: -1737013 | BC11: =BW11-BB11 -> -1749365.6 | BD11: =-5208708.004-BC11-BB11 -> -1722329.4 | BE11: =P11-BD11-BC11-BB11 -> -2161920.6 | BF11: -1802151.5 | BH11: -1253403.4 | BI11: =BY11-BH11 -> -1297192.1 | BJ11: =-3802885.751-BI11-BH11 -> -1252290.2 | BK11: =I11-Z11-AB11-AA11 -> -1269344.7 | BL11: -1323019.3 | BN11: -2545370.4 | BO11: -2586288.9 | BP11: -2669219 | BQ11: -2653934.6 | BR11: -2364939.7 | BS11: -3187574.1 | BT11: -3596064 | BU11: -3133669 | BV11: -3242752.3 | BW11: -3486378.6 | BY11: -2550595.5 | BZ11: -2653934.6
B12: Gross Profit | C12: =C8+C11 -> 2383390.9 | D12: =D8+D11 -> 2655077.9 | E12: =E8+E11 -> 2717581.8 | F12: =F8+F11 -> 2882293.2 | G12: =G8+G11 -> 2913208.5 | H12: =H8+H11 -> 2975032 | I12: =I8+I11 -> 2721142.1 | J12: =J8+J11 -> 2620512.6 | ... P12: =P8+P11 -> 3971757.3 | R12: =R8+R11 -> 623242.44 | S12: =S8+S11 -> 669770.62 | T12: =T8+T11 -> 635284.05 | U12: =U8+U11 -> 789284.74 | V12: =V8+V11 -> 670961.37 | W12: =W8+W11 -> 709945.8 | X12: =X8+X11 -> 660936.14 | Y12: =Y8+Y11 -> 840449.9 | ... BF12: =BF8+BF11 -> 963874.49 | BH12: =BH8+BH11 -> 633739.29 | BI12: =BI8+BI11 -> 683423.31 | BJ12: =BJ8+BJ11 -> 625735.21 | BK12: =BK8+BK11 -> 586148.44 | BL12: =BL8+BL11 -> 603881.25 | BN12: =BN8+BN11 -> 1293013.1 | BO12: =BO8+BO11 -> 1380907.2 | BP12: =BP8+BP11 -> 1447575.5 | BQ12: =BQ8+BQ11 -> 1267046.9 | BR12: =BR8+BR11 -> 981122.98 | BS12: =BS8+BS11 -> 1421093.1 | BT12: =BT8+BT11 -> 1569270.5 | BU12: =BU8+BU11 -> 1360974.7 | ... BW12: =BW8+BW11 -> 1860269.2 | BY12: =BY8+BY11 -> 1317162.6 | BZ12: =BZ8+BZ11 -> 1267046.9
B13: Gross Profit margin | C13: =C12/C8 -> 0.33862777 | D13: =D12/D8 -> 0.34244888 | E13: =E12/E8 -> 0.34407166 | F13: =F12/F8 -> 0.34968061 | G13: =G12/G8 -> 0.35484303 | H13: =H12/H8 -> 0.3506813 | I13: =I12/I8 -> 0.34112783 | J13: =J12/J8 -> 0.32538469 | ... P13: =P12/P8 -> 0.35016947 | R13: =R12/R8 -> 0.32982837 | S13: =S12/S8 -> 0.34368586 | T13: =T12/T8 -> 0.33980446 | U13: =U12/U8 -> 0.36034466 | V13: =V12/V8 -> 0.34372438 | W13: =W12/W8 -> 0.35230194 | X13: =X12/X8 -> 0.34033899 | Y13: =Y12/Y8 -> 0.36017394 | ... BF13: =BF12/BF8 -> 0.34846907 | BH13: =BH12/BH8 -> 0.33581949 | BI13: =BI12/BI8 -> 0.34505603 | BJ13: =BJ12/BJ8 -> 0.33318782 | BK13: =BK12/BK8 -> 0.315899 | BL13: =BL12/BL8 -> 0.31339514 | BN13: =BN12/BN8 -> 0.33686396 | BO13: =BO12/BO8 -> 0.34808141 | BP13: =BP12/BP8 -> 0.35162686 | BQ13: =BQ12/BQ8 -> 0.32314534 | BR13: =BR12/BR8 -> 0.29321715 | BS13: =BS12/BS8 -> 0.3083523 | BT13: =BT12/BT8 -> 0.3038081 | BU13: =BU12/BU8 -> 0.30279924 | ... BW13: =BW12/BW8 -> 0.34793188 | BY13: =BY12/BY8 -> 0.34054937 | BZ13: =BZ12/BZ8 -> 0.32314534
B14: Distribution costs | C14: =-82780.323 -> -82780.323 | D14: =-82294.591 -> -82294.591 | E14: =-89751.825 -> -89751.825 | F14: -84461.522 | G14: -96735.311 | H14: -115829.43 | I14: -115035.38 | J14: -121283.22 | K14: -191796.6 | L14: -220052.79 | M14: -230005.27 | N14: -186697.56 | O14: -172518.14 | P14: -191975.74 | R14: =-20361.824 -> -20361.824 | S14: =BN14-R14 -> -27489.368 | T14: =-68104.112-S14-R14 -> -20252.92 | U14: =E14-T14-S14-R14 -> -21647.713 | V14: =-21251.85 -> -21251.85 | W14: =BO14-V14 -> -20785.146 | X14: =-61890.621-W14-V14 -> -19853.625 | Y14: =F14-X14-W14-V14 -> -22570.901 | Z14: -27799.856 | AA14: =BP14-Z14 -> -28348.288 | AB14: =-82802.048-AA14-Z14 -> -26653.904 | AC14: =H14-AB14-AA14-Z14 -> -33027.383 | AD14: -31929.885 | AE14: =BQ14-AD14 -> -31961.789 | AF14: =-88044.424-AE14-AD14 -> -24152.75 | AG14: =J14-AF14-AE14-AD14 -> -33238.792 | AH14: -30574.627 | AI14: =BR14-AH14 -> -41142.494 | AJ14: =-133280.501-AI14-AH14 -> -61563.38 | AK14: =K14-AJ14-AI14-AH14 -> -58516.1 | AL14: -45456.562 | AM14: =BS14-AL14 -> -55091.847 | AN14: =-153333.855-AM14-AL14 -> -52785.446 | AO14: =L14-AN14-AM14-AL14 -> -66718.931 | AP14: -55163.396 | AQ14: =BT14-AP14 -> -62389.878 | AR14: =-165930.646-AQ14-AP14 -> -48377.372 | AS14: =M14-AR14-AQ14-AP14 -> -64074.629 | AT14: -51562.236 | AU14: =BU14-AT14 -> -47262.47 | AV14: =-138182.98-AU14-AT14 -> -39358.274 | AW14: =N14-AV14-AU14-AT14 -> -48514.58 | AX14: -37683.197 | AY14: =BV14-AX14 -> -42255.766 | AZ14: =-121728.214-AY14-AX14 -> -41789.251 | BA14: =O14-AZ14-AY14-AX14 -> -50789.924 | BB14: -45055.521 | BC14: =BW14-BB14 -> -46540.207 | BD14: =-134372.666-BC14-BB14 -> -42776.938 | BE14: =P14-BD14-BC14-BB14 -> -57603.074 | BF14: -50077.449 | BH14: -27604.65 | BI14: =BY14-BH14 -> -28128.325 | BJ14: =-82212.746-BI14-BH14 -> -26479.771 | BK14: =I14-Z14-AB14-AA14 -> -32233.328 | BL14: -30390.169 | BN14: =-47851.192 -> -47851.192 | BO14: =-42036.996 -> -42036.996 | BP14: -56148.144 | BQ14: -63891.674 | BR14: -71717.121 | BS14: -100548.41 | BT14: -117553.27 | BU14: -98824.706 | BV14: -79938.963 | BW14: -91595.728 | BY14: -55732.975 | BZ14: -60842.881
B15: Administrative expenses | C15: -1457458.8 | D15: -1683851 | E15: -1716574.7 | F15: -1832012.7 | G15: -1847408.4 | H15: -1946931.2 | I15: -1904010.2 | J15: -1966962.4 | K15: -1988674.1 | L15: -2080380.9 | M15: -2441176 | N15: -2357878.6 | O15: -2469130.4 | P15: -2578530.2 | R15: -412196.86 | S15: =BN15-R15 -> -418926.81 | T15: =-1258480.94-S15-R15 -> -427357.26 | U15: =E15-T15-S15-R15 -> -458093.8 | V15: -432963.4 | W15: =BO15-V15 -> -453020.25 | X15: =-1343869.179-W15-V15 -> -457885.54 | Y15: =F15-X15-W15-V15 -> -488143.5 | Z15: -456051.22 | AA15: =BP15-Z15 -> -483628.67 | AB15: =-1417503.229-AA15-Z15 -> -477823.34 | AC15: =H15-AB15-AA15-Z15 -> -529427.95 | AD15: -456016.55 | AE15: =BQ15-AD15 -> -481909.43 | AF15: =-1418658.106-AE15-AD15 -> -480732.12 | AG15: =J15-AF15-AE15-AD15 -> -548304.29 | AH15: -492657.95 | AI15: =BR15-AH15 -> -475280.44 | AJ15: =-1457406.418-AI15-AH15 -> -489468.02 | AK15: =K15-AJ15-AI15-AH15 -> -531267.7 | AL15: -465395.41 | AM15: =BS15-AL15 -> -474591.6 | AN15: =-1467546.165-AM15-AL15 -> -527559.16 | AO15: =L15-AN15-AM15-AL15 -> -612834.75 | AP15: -558138.01 | AQ15: =BT15-AP15 -> -600623.12 | AR15: =-1786267.314-AQ15-AP15 -> -627506.19 | AS15: =M15-AR15-AQ15-AP15 -> -654908.7 | AT15: -569760.36 | AU15: =BU15-AT15 -> -582137.19 | AV15: =-1742316.662-AU15-AT15 -> -590419.11 | AW15: =N15-AV15-AU15-AT15 -> -615561.92 | AX15: -592391.92 | AY15: =BV15-AX15 -> -594271.86 | AZ15: =-1796310.047-AY15-AX15 -> -609646.27 | BA15: =O15-AZ15-AY15-AX15 -> -672820.31 | BB15: -611779.62 | BC15: =BW15-BB15 -> -622738.27 | BD15: =-1876988.159-BC15-BB15 -> -642470.28 | BE15: =P15-BD15-BC15-BB15 -> -701542 | BF15: -627437.98 | BH15: -445572.49 | BI15: =BY15-BH15 -> -472304.59 | BJ15: =-1384656.917-BI15-BH15 -> -466779.83 | BK15: =I15-Z15-AB15-AA15 -> -486507.01 | BL15: -457556.27 | BN15: -831123.68 | BO15: -885983.64 | BP15: -939679.89 | BQ15: -937925.99 | BR15: -967938.4 | BS15: -939987.01 | BT15: -1158761.1 | BU15: -1151897.5 | BV15: -1186663.8 | BW15: -1234517.9 | BY15: -917877.08 | BZ15: -940974.78
B16: Other gains (losses) | C16: 8506.262 | D16: 33749.211 | E16: 160726.38 | F16: 5689.395 | G16: 3289.726 | H16: 24079.804 | I16: 24657.249 | J16: 20796.536 | K16: -45064.092 | L16: -29055.029 | M16: 9378.916 | N16: =226571.067 -> 226571.07 | O16: 195716.95 | P16: 1367762 | R16: 1161.901 | S16: =BN16-R16 -> -648.153 | T16: =137610.958-S16-R16 -> 137097.21 | U16: =E16-T16-S16-R16 -> 23115.419 | V16: -5889.723 | W16: =BO16-V16 -> 8506.923 | X16: =1355.087-W16-V16 -> -1262.113 | Y16: =F16-X16-W16-V16 -> 4334.308 | Z16: -238.956 | AA16: =BP16-Z16 -> -1554.962 | AB16: =-442.73-AA16-Z16 -> 1351.188 | AC16: =H16-AB16-AA16-Z16 -> 24522.534 | AD16: -573.83 | AE16: =BQ16-AD16 -> 9095.729 | AF16: =12274.805-AE16-AD16 -> 3752.906 | AG16: =J16-AF16-AE16-AD16 -> 8521.731 | AH16: 310.265 | AI16: =BR16-AH16 -> 1451.528 | AJ16: =3924.185-AI16-AH16 -> 2162.392 | AK16: =K16-AJ16-AI16-AH16 -> -48988.277 | AL16: -4290.924 | AM16: =BS16-AL16 -> -1470.839 | AN16: =-1446.131-AM16-AL16 -> 4315.632 | AO16: =L16-AN16-AM16-AL16 -> -27608.898 | AP16: 2016.356 | AQ16: =BT16-AP16 -> 83406.528 | AR16: =98690.059 -AQ16-AP16 -> 13267.175 | AS16: =M16-AR16-AQ16-AP16 -> -89311.143 | AT16: 5337 | AU16: =BU16-AT16 -> 170546.43 | AV16: =180918.5-AU16-AT16 -> 5035.073 | AW16: =N16-AV16-AU16-AT16 -> 45652.567 | AX16: 8961.685 | AY16: =BV16-AX16 -> 114692.51 | AZ16: =130389.576-AY16-AX16 -> 6735.379 | BA16: =O16-AZ16-AY16-AX16 -> 65327.378 | BB16: 8023.633 | BC16: =BW16-BB16 -> 432144.41 | BD16: =454570.425-BC16-BB16 -> 14402.383 | BE16: =P16-BD16-BC16-BB16 -> 913191.61 | BF16: 11524.835 | BH16: -306.15 | BI16: =BY16-BH16 -> -1334.111 | BJ16: =120.767-BI16-BH16 -> 1761.028 | BK16: =I16-Z16-AB16-AA16 -> 25099.979 | BL16: -573.83 | BN16: 513.748 | BO16: 2617.2 | BP16: -1793.918 | BQ16: 8521.899 | BR16: 1761.793 | BS16: -5761.763 | BT16: 85422.884 | BU16: 175883.43 | BV16: 123654.2 | BW16: 440168.04 | BY16: -1640.261 | BZ16: 8521.899
B17: Other expenses | C17: -136398.08 | D17: -142275.8 | E17: -135229.38 | F17: -148468.52 | G17: -149314.64 | H17: -142404.86 | I17: -139868.2 | J17: -141899.29 | K17: -111787.54 | L17: -181917.88 | M17: -230886.7 | N17: =-125990.851 -> -125990.85 | O17: -111299.14 | P17: -117786.3 | R17: -29322.073 | S17: =BN17-R17 -> -34087.158 | T17: =-95111.051-S17-R17 -> -31701.82 | U17: =E17-T17-S17-R17 -> -40118.326 | V17: -27598.993 | W17: =BO17-V17 -> -38226.494 | X17: =-102100.525-W17-V17 -> -36275.038 | Y17: =F17-X17-W17-V17 -> -46367.996 | Z17: -27231.974 | AA17: =BP17-Z17 -> -35553.002 | AB17: =-97523.042-AA17-Z17 -> -34738.066 | AC17: =H17-AB17-AA17-Z17 -> -44881.818 | AD17: -28701.599 | AE17: =BQ17-AD17 -> -35788.598 | AF17: =-96458.229-AE17-AD17 -> -31968.032 | AG17: =J17-AF17-AE17-AD17 -> -45441.061 | AH17: -28787.759 | AI17: =BR17-AH17 -> -19880.297 | AJ17: =-72442.206-AI17-AH17 -> -23774.15 | AK17: =K17-AJ17-AI17-AH17 -> -39345.338 | AL17: -29113.605 | AM17: =BS17-AL17 -> -34335.976 | AN17: =-109012.651-AM17-AL17 -> -45563.07 | AO17: =L17-AN17-AM17-AL17 -> -72905.224 | AP17: -41598.689 | AQ17: =BT17-AP17 -> -55961.568 | AR17: =-144595.497-AQ17-AP17 -> -47035.24 | AS17: =M17-AR17-AQ17-AP17 -> -86291.202 | AT17: -35779.462 | AU17: =BU17-AT17 -> -19855.449 | AV17: =-85427.185-AU17-AT17 -> -29792.274 | AW17: =N17-AV17-AU17-AT17 -> -40563.666 | AX17: -22293.91 | AY17: =BV17-AX17 -> -31062.203 | AZ17: =-76560.98-AY17-AX17 -> -23204.867 | BA17: =O17-AZ17-AY17-AX17 -> -34738.157 | BB17: -24655.229 | BC17: =BW17-BB17 -> -30004.953 | BD17: =-78283.815-BC17-BB17 -> -23623.633 | BE17: =P17-BD17-BC17-BB17 -> -39502.485 | BF17: -36726.588 | BH17: -26612.7 | BI17: =BY17-BH17 -> -34952.231 | BJ17: =-95733.611-BI17-BH17 -> -34168.68 | BK17: =I17-Z17-AB17-AA17 -> -42345.161 | BL17: -28701.599 | BN17: -63409.231 | BO17: -65825.487 | BP17: -62784.976 | BQ17: -64490.197 | BR17: -48668.056 | BS17: -63449.581 | BT17: -97560.257 | BU17: -55634.911 | BV17: -53356.113 | BW17: -54660.182 | BY17: -61564.931 | BZ17: -64490.197
B18: Operating Profit | C18: =C12+C15+C16+C17+C14 -> 715259.96 | D18: =D12+D15+D16+D17+D14 -> 780405.77 | E18: =E12+E15+E16+E17+E14 -> 936752.28 | F18: =F12+F15+F16+F17+F14 -> 823039.89 | G18: =G12+G15+G16+G17+G14 -> 823039.89 | H18: =H12+H15+H16+H17+H14 -> 793946.3 | I18: =I12+I15+I16+I17+I14 -> 586885.49 | J18: =J12+J15+J16+J17+J14 -> 411164.22 | ... P18: =P12+P15+P16+P17+P14 -> 2451227.1 | R18: =R12+R15+R16+R17+R14 -> 162523.58 | S18: =S12+S15+S16+S17+S14 -> 188619.13 | T18: =T12+T15+T16+T17+T14 -> 293069.25 | U18: =U12+U15+U16+U17+U14 -> 292540.32 | V18: =V12+V15+V16+V17+V14 -> 183257.41 | W18: =W12+W15+W16+W17+W14 -> 206420.83 | X18: =X12+X15+X16+X17+X14 -> 145659.83 | Y18: =Y12+Y15+Y16+Y17+Y14 -> 287701.82 | ... BF18: =BF12+BF15+BF16+BF17+BF14 -> 261157.31 | BH18: =BH12+BH15+BH16+BH17+BH14 -> 133643.3 | BI18: =BI12+BI15+BI16+BI17+BI14 -> 146704.05 | BJ18: =BJ12+BJ15+BJ16+BJ17+BJ14 -> 100067.95 | BK18: =BK12+BK15+BK16+BK17+BK14 -> 50162.92 | BL18: =BL12+BL15+BL16+BL17+BL14 -> 86659.384 | BN18: =BN12+BN15+BN16+BN17+BN14 -> 351142.71 | BO18: =BO12+BO15+BO16+BO17+BO14 -> 389678.24 | BP18: =BP12+BP15+BP16+BP17+BP14 -> 387168.58 | BQ18: =BQ12+BQ15+BQ16+BQ17+BQ14 -> 209260.95 | BR18: =BR12+BR15+BR16+BR17+BR14 -> -105438.81 | BS18: =BS12+BS15+BS16+BS17+BS14 -> 311346.35 | BT18: =BT12+BT15+BT16+BT17+BT14 -> 280818.67 | BU18: =BU12+BU15+BU16+BU17+BU14 -> 230500.94 | ... BW18: =BW12+BW15+BW16+BW17+BW14 -> 919663.48 | BY18: =BY12+BY15+BY16+BY17+BY14 -> 280347.35 | BZ18: =BZ12+BZ15+BZ16+BZ17+BZ14 -> 209260.95 | CC18: 150597.11 | CD18: 326170.15 | CE18: 478149.54
B19: Finance Income | C19: 19557.464 | D19: 33868.899 | E19: 15268.092 | F19: 16196.997 | G19: 15113.935 | H19: 37280.766 | I19: 36224.345 | J19: 27400.95 | K19: 67907.001 | L19: 124517.24 | M19: 61815.59 | N19: =46977.32 -> 46977.32 | O19: 102808.23 | P19: 78953.013 | R19: 3935.739 | S19: =BN19-R19 -> 3052.026 | T19: =11523.788-S19-R19 -> 4536.023 | U19: =E19-T19-S19-R19 -> 3744.304 | V19: 3775.812 | W19: =BO19-V19 -> 4040.425 | X19: =10472.948-W19-V19 -> 2656.711 | Y19: =F19-X19-W19-V19 -> 5724.049 | Z19: 3756.24 | AA19: =BP19-Z19 -> 11427.085 | AB19: =28555.698-AA19-Z19 -> 13372.373 | AC19: =H19-AB19-AA19-Z19 -> 8725.068 | AD19: 4412.754 | AE19: =BQ19-AD19 -> 4537.166 | AF19: =16074.752-AE19-AD19 -> 7124.832 | AG19: =J19-AF19-AE19-AD19 -> 11326.198 | AH19: 28072.221 | AI19: =BR19-AH19 -> 25324.658 | AJ19: =63585.194-AI19-AH19 -> 10188.315 | AK19: =K19-AJ19-AI19-AH19 -> 4321.807 | AL19: 22714.385 | AM19: =BS19-AL19 -> 20838.483 | AN19: =123969.821-AM19-AL19 -> 80416.953 | AO19: =L19-AN19-AM19-AL19 -> 547.423 | AP19: 5396.444 | AQ19: =BT19-AP19 -> 22294.042 | AR19: =48978.447-AQ19-AP19 -> 21287.961 | AS19: =M19-AR19-AQ19-AP19 -> 12837.143 | AT19: 24115.573 | AU19: =BU19-AT19 -> 11921.398 | AV19: =39428.427-AU19-AT19 -> 3391.456 | AW19: =N19-AV19-AU19-AT19 -> 7548.893 | AX19: 28765.129 | AY19: =BV19-AX19 -> 17531.415 | AZ19: =60808.515-AY19-AX19 -> 14511.971 | BA19: =O19-AZ19-AY19-AX19 -> 41999.711 | BB19: 20760.631 | BC19: =BW19-BB19 -> 18440.342 | BD19: =59813.362 -BC19-BB19 -> 20612.389 | BE19: =P19-BD19-BC19-BB19 -> 19139.651 | BF19: 23509.426 | BH19: 3671.008 | BI19: =BY19-BH19 -> 11168.309 | BJ19: =27823.269-BI19-BH19 -> 12983.952 | BK19: =I19-Z19-AB19-AA19 -> 7668.647 | BL19: 4412.754 | BN19: 6987.765 | BO19: 7816.237 | BP19: 15183.325 | BQ19: 8949.92 | BR19: 53396.879 | BS19: 43552.868 | BT19: 27690.486 | BU19: 36036.971 | BV19: 46296.544 | BW19: 39200.973 | BY19: 14839.317 | BZ19: 8949.92
B20: Finance costs | C20: -139227.17 | D20: -174032.52 | E20: -207568.52 | F20: -196455.24 | G20: -195372.18 | H20: -181505.28 | I20: -181142.09 | J20: -209910.8 | K20: -254510.95 | L20: -234461.9 | M20: -309849.69 | N20: =-350424.957 -> -350424.96 | O20: -350758.04 | P20: -335429.57 | R20: -54381.979 | S20: =BN20-R20 -> -56068.413 | T20: =-159376.326-S20-R20 -> -48925.934 | U20: =E20-T20-S20-R20 -> -48192.192 | V20: -51801.873 | W20: =BO20-V20 -> -43827.315 | X20: =-145347.459-W20-V20 -> -49718.271 | Y20: =F20-X20-W20-V20 -> -51107.784 | Z20: -50233.337 | AA20: =BP20-Z20 -> -44211.044 | AB20: =-139784.912-AA20-Z20 -> -45340.531 | AC20: =H20-AB20-AA20-Z20 -> -41720.368 | AD20: -54309.432 | AE20: =BQ20-AD20 -> -55575.907 | AF20: =-147869.227-AE20-AD20 -> -37983.888 | AG20: =J20-AF20-AE20-AD20 -> -62041.573 | AH20: -53153.389 | AI20: =BR20-AH20 -> -61728.703 | AJ20: =-176938.059-AI20-AH20 -> -62055.967 | AK20: =K20-AJ20-AI20-AH20 -> -77572.89 | AL20: -47771.875 | AM20: =BS20-AL20 -> -53170.201 | AN20: =-166696.133-AM20-AL20 -> -65754.057 | AO20: =L20-AN20-AM20-AL20 -> -67765.772 | AP20: -108657.84 | AQ20: =BT20-AP20 -> -33336.292 | AR20: =-201891.374-AQ20-AP20 -> -59897.246 | AS20: =M20-AR20-AQ20-AP20 -> -107958.32 | AT20: -96805.603 | AU20: =BU20-AT20 -> -91071.717 | AV20: =-255786.52-AU20-AT20 -> -67909.2 | AW20: =N20-AV20-AU20-AT20 -> -94638.437 | AX20: -90388.715 | AY20: =BV20-AX20 -> -88702.059 | AZ20: =-265136.464-AY20-AX20 -> -86045.69 | BA20: =O20-AZ20-AY20-AX20 -> -85621.578 | BB20: -94038.014 | BC20: =BW20-BB20 -> -84255.246 | BD20: =-246995.032-BC20-BB20 -> -68701.772 | BE20: =P20-BD20-BC20-BB20 -> -88434.542 | BF20: -69394.736 | BH20: -50066.245 | BI20: =BY20-BH20 -> -44102.53 | BJ20: =-139455.425-BI20-BH20 -> -45286.65 | BK20: =I20-Z20-AB20-AA20 -> -41357.182 | BL20: -54309.432 | BN20: -110450.39 | BO20: -95629.188 | BP20: -94444.381 | BQ20: -109885.34 | BR20: -114882.09 | BS20: -100942.08 | BT20: -141994.13 | BU20: -187877.32 | BV20: -179090.77 | BW20: -178293.26 | BY20: -94168.775 | BZ20: -109885.34
B21: Gain on net non-monetary position | C21: =26155.945-40226.654-41114.681 -> -55185.39 | D21: =25272.409-18208.873-33455.45 -> -26391.914 | E21: =21247.989+3637.364-26087.89 -> -1202.537 | F21: =15279.304-466.04-17264.195 -> -2450.931 | G21: =(15279304-466040-17264195)/1000 -> -2450.931 | H21: =(7092186-15793359-22494868)/1000 -> -31196.041 | I21: =(7092186-15580747-22494868)/1000 -> -30983.429 | J21: =336.784-22065.192-21944.001 -> -43672.409 | K21: =3579.174-29085.779-28678.051 -> -54184.656 | L21: =22662.137-41110.07-56003.432 -> -74451.365 | M21: =16815.716-7706.67-153721.901 -> -144612.86 | N21: =19044.549+38739.34-66019.02 -> -8235.131 | O21: =24797.081-2548.839-63021.636 -> -40773.394 | P21: =30301.086+44437.584-(52130.972) -> 22607.698 | R21: =5592.977+16.605-6285.019 -> -675.437 | S21: =BN21-R21 -> 3205.373 | T21: =15431.963+3494.044-20794.127-S21-R21 -> -4398.056 | U21: =E21-T21-S21-R21 -> 665.583 | V21: =4371.96+2316.799-4283.507 -> 2405.252 | W21: =BO21-V21 -> -7059.253 | X21: =9730.899+1077.901-10654.905-W21-V21 -> 4807.896 | Y21: =F21-X21-W21-V21 -> -2604.826 | Z21: =(2394134+617271-6344480)/1000 -> -3333.075 | AA21: =BP21-Z21 -> -10102.457 | AB21: =5436.026-16937.342-18114.625-AA21-Z21 -> -16180.409 | AC21: =H21-AB21-AA21-Z21 -> -1580.1 | AD21: =(887202+510869+66641)/1000 -> 1464.712 | AE21: =BQ21-AD21 -> -10659.281 | AF21: =-613.139-19594.921-14045.294-AE21-AD21 -> -25058.785 | AG21: =J21-AF21-AE21-AD21 -> -9419.055 | AH21: =-(2478.993+13188.965+10124.833) -> -25792.791 | AI21: =BR21-AH21 -> -15743.077 | AJ21: =-3763.851-27819.351-15422.249-AI21-AH21 -> -5469.583 | AK21: =K21-AJ21-AI21-AH21 -> -7179.205 | AL21: =5203.08-15240.587-13628.005 -> -23665.512 | AM21: =BS21-AL21 -> -20556.122 | AN21: =14069.113-45488.032-38445.355-AM21-AL21 -> -25642.64 | AO21: =L21-AN21-AM21-AL21 -> -4587.091 | AP21: =6011.224+33227.037-26964.404 -> 12273.857 | AQ21: =BT21-AP21 -> -54114.182 | AR21: =16553.36+1200.253-133092.133-AQ21-AP21 -> -73498.195 | AS21: =M21-AR21-AQ21-AP21 -> -29274.335 | AT21: =3614.252+3036.816-18730.946 -> -12079.878 | AU21: =BU21-AT21 -> 354.884 | AV21: =12331.587+23367.896-45091.23-AU21-AT21 -> 2333.247 | AW21: =N21-AV21-AU21-AT21 -> 1156.616 | AX21: =5606.295-2032.213-15027.684 -> -11453.602 | AY21: =BV21-AX21 -> -21893.353 | AZ21: =16936.959-4432.88-43684.137-AY21-AX21 -> 2166.897 | BA21: =O21-AZ21-AY21-AX21 -> -9593.336 | BB21: =10036.743+12201.239-18860.288 -> 3377.694 | BC21: =BW21-BB21 -> 5351.218 | BD21: =26648.632+30195.877-42516.403-BC21-BB21 -> 5599.194 | BE21: =P21-BD21-BC21-BB21 -> 8279.592 | BF21: =11864.798-10930.868-5036.057 -> -4102.127 | BH21: =(2394134+640584-6344480)/1000 -> -3309.762 | BI21: =BY21-BH21 -> -10040.852 | BJ21: =5436.026-16592.306-18114.625-BI21-BH21 -> -15920.291 | BK21: =I21-Z21-AB21-AA21 -> -1367.488 | BL21: =(887202+510869+66641)/1000 -> 1464.712 | BN21: =11068.964+6441.022-14980.05 -> 2529.936 | BO21: =7103.763-839.968-10917.796 -> -4654.001 | BP21: =4035.861-5826.501-11644.892 -> -13435.532 | BQ21: =78.625+1243.574-10516.768 -> -9194.569 | BR21: =-5074.5-21441.132-15020.236 -> -41535.868 | BS21: =8117.858-27257.443-25082.049 -> -44221.634 | BT21: =11266.09+31772.34-84878.755 -> -41840.325 | BU21: =6532.513+25848.165-44105.672 -> -11724.994 | BV21: =10117.03-13377.011-30086.974 -> -33346.955 | BW21: =18311.75+24710.672-34293.51 -> 8728.912 | BY21: =4035.861-5741.583-11644.892 -> -13350.614 | BZ21: =78.625+1243.574-10516.768 -> -9194.569
B22: Profit before tax | C22: =C18+C19+C20+C21 -> 540404.86 | D22: =D18+D19+D20+D21 -> 613850.24 | E22: =E18+E19+E20+E21 -> 743249.31 | F22: =F18+F19+F20+F21 -> 640330.71 | G22: =G18+G19+G20+G21 -> 640330.71 | H22: =H18+H19+H20+H21 -> 618525.74 | I22: =I18+I19+I20+I21 -> 410984.31 | J22: =J18+J19+J20+J21 -> 184981.96 | ... P22: =P18+P19+P20+P21 -> 2217358.2 | R22: =R18+R19+R20+R21 -> 111401.9 | S22: =S18+S19+S20+S21 -> 138808.12 | T22: =T18+T19+T20+T21 -> 244281.29 | U22: =U18+U19+U20+U21 -> 248758.01 | V22: =V18+V19+V20+V21 -> 137636.6 | W22: =W18+W19+W20+W21 -> 159574.69 | X22: =X18+X19+X20+X21 -> 103406.17 | Y22: =Y18+Y19+Y20+Y21 -> 239713.26 | ... BF22: =BF18+BF19+BF20+BF21 -> 211169.87 | BH22: =BH18+BH19+BH20+BH21 -> 83938.301 | BI22: =BI18+BI19+BI20+BI21 -> 103728.98 | BJ22: =BJ18+BJ19+BJ20+BJ21 -> 51844.96 | BK22: =BK18+BK19+BK20+BK21 -> 15106.897 | BL22: =BL18+BL19+BL20+BL21 -> 38227.418 | BN22: =BN18+BN19+BN20+BN21 -> 250210.01 | BO22: =BO18+BO19+BO20+BO21 -> 297211.29 | BP22: =BP18+BP19+BP20+BP21 -> 294472 | BQ22: =BQ18+BQ19+BQ20+BQ21 -> 99130.963 | BR22: =BR18+BR19+BR20+BR21 -> -208459.89 | BS22: =BS18+BS19+BS20+BS21 -> 209735.51 | BT22: =BT18+BT19+BT20+BT21 -> 124674.71 | BU22: =BU18+BU19+BU20+BU21 -> 66935.594 | ... BW22: =BW18+BW19+BW20+BW21 -> 789300.11 | BY22: =BY18+BY19+BY20+BY21 -> 187667.28 | BZ22: =BZ18+BZ19+BZ20+BZ21 -> 99130.963
B23: Income tax benefit/(expense) | C23: -101425.82 | D23: -134095.69 | E23: -148580.18 | F23: -159920.61 | G23: -159920.61 | H23: -152653.83 | I23: -101167.1 | J23: -62097.989 | K23: -5243.074 | L23: -137325.97 | M23: 80781.84 | N23: -27913.013 | O23: -200897.07 | P23: -535651.53 | R23: -20399.589 | S23: =BN23-R23 -> -30086.647 | T23: =-71778.793-S23-R23 -> -21292.557 | U23: =E23-T23-S23-R23 -> -76801.383 | V23: -29460.29 | W23: =BO23-V23 -> -40121.705 | X23: =-96767.076-W23-V23 -> -27185.081 | Y23: =F23-X23-W23-V23 -> -63153.537 | Z23: -35758.106 | AA23: =BP23-Z23 -> -28281.048 | AB23: =-89312.595-AA23-Z23 -> -25273.441 | AC23: =H23-AB23-AA23-Z23 -> -63341.235 | AD23: -14400.612 | AE23: =BQ23-AD23 -> -14824.508 | AF23: =-38987.134-AE23-AD23 -> -9762.014 | AG23: =J23-AF23-AE23-AD23 -> -23110.855 | AH23: -2182.474 | AI23: =BR23-AH23 -> 49471.331 | AJ23: =47995.639-AI23-AH23 -> 706.782 | AK23: =K23-AJ23-AI23-AH23 -> -53238.713 | AL23: -22309.986 | AM23: =BS23-AL23 -> -34146.64 | AN23: =-106620.197-AM23-AL23 -> -50163.571 | AO23: =L23-AN23-AM23-AL23 -> -30705.77 | AP23: 17397.789 | AQ23: =BT23-AP23 -> -20172.839 | AR23: =27079.479-AQ23-AP23 -> 29854.529 | AS23: =M23-AR23-AQ23-AP23 -> 53702.361 | AT23: 20643.061 | AU23: =BU23-AT23 -> -30881.21 | AV23: =3355.558-AU23-AT23 -> 13593.707 | AW23: =N23-AV23-AU23-AT23 -> -31268.571 | AX23: -23193.99 | AY23: =BV23-AX23 -> -68739.61 | AZ23: =-113714.95-AY23-AX23 -> -21781.35 | BA23: =O23-AZ23-AY23-AX23 -> -87182.119 | BB23: -43348.541 | BC23: =BW23-BB23 -> -158935.54 | BD23: =-246752.197-BC23-BB23 -> -44468.112 | BE23: =P23-BD23-BC23-BB23 -> -288899.33 | BF23: -62303.524 | BH23: -21746.325 | BI23: =BY23-BH23 -> -15952.798 | BJ23: =-50556.535-BI23-BH23 -> -12857.412 | BK23: =I23-Z23-AB23-AA23 -> -11854.5 | BL23: -14400.612 | BN23: -50486.236 | BO23: -69581.995 | BP23: -64039.154 | BQ23: -29225.12 | BR23: 47288.857 | BS23: -56456.626 | BT23: -2775.05 | BU23: -10238.149 | BV23: -91933.6 | BW23: -202284.08 | BY23: -37699.123 | BZ23: -29225.12
B24: Profit/(loss) from continuing operations | C24: =C22+C23 -> 438979.04 | D24: =D22+D23 -> 479754.55 | E24: =E22+E23 -> 594669.14 | F24: =F22+F23 -> 480410.1 | G24: =G22+G23 -> 480410.1 | H24: =H22+H23 -> 465871.91 | I24: =I22+I23 -> 309817.21 | J24: =J22+J23 -> 122883.97 | ... P24: =P22+P23 -> 1681706.7 | R24: =R22+R23 -> 91002.31 | S24: =S22+S23 -> 108721.47 | T24: =T22+T23 -> 222988.73 | U24: =U22+U23 -> 171956.63 | V24: =V22+V23 -> 108176.31 | W24: =W22+W23 -> 119452.99 | X24: =X22+X23 -> 76221.084 | Y24: =Y22+Y23 -> 176559.72 | ... BF24: =BF22+BF23 -> 148866.35 | BH24: =BH22+BH23 -> 62191.976 | BI24: =BI22+BI23 -> 87776.182 | BJ24: =BJ22+BJ23 -> 38987.548 | BK24: =BK22+BK23 -> 3252.397 | BL24: =BL22+BL23 -> 23826.806 | BN24: =BN22+BN23 -> 199723.78 | BO24: =BO22+BO23 -> 227629.3 | BP24: =BP22+BP23 -> 230432.84 | BQ24: =BQ22+BQ23 -> 69905.843 | BR24: =BR22+BR23 -> -161171.03 | BS24: =BS22+BS23 -> 153278.88 | BT24: =BT22+BT23 -> 121899.66 | BU24: =BU22+BU23 -> 56697.445 | ... BW24: =BW22+BW23 -> 587016.02 | BY24: =BY22+BY23 -> 149968.16 | BZ24: =BZ22+BZ23 -> 69905.843 | CC24: 93668.103 | CD24: 196361.11 | CE24: 279718.66
B25: Loss from discontinued Operations | C25: 0 | D25: 0 | E25: 0 | F25: 0 | G25: 0 | H25: 0 | I25: 0 | J25: 0 | K25: 0 | L25: 0 | M25: 0 | N25: 0 | O25: 0 | P25: 0 | R25: 0 | S25: =BN25-R25 -> 0 | T25: =0-S25-R25 -> 0 | U25: =E25-T25-S25-R25 -> 0 | V25: 0 | W25: =BO25-V25 -> 0 | X25: =0-W25-V25 -> 0 | Y25: =F25-X25-W25-V25 -> 0 | Z25: =G25-Y25-X25-W25 -> 0 | AA25: =H25-Z25-Y25-X25 -> 0 | AB25: =I25-AA25-Z25-Y25 -> 0 | AC25: =J25-AB25-AA25-Z25 -> 0 | AD25: =K25-AC25-AB25-AA25 -> 0 | AE25: =L25-AD25-AC25-AB25 -> 0 | AF25: =M25-AE25-AD25-AC25 -> 0 | ... AH25: =O25-AG25-AF25-AE25 -> 0 | AI25: =Q25-AH25-AG25-AF25 -> 0 | AJ25: =R25-AI25-AH25-AG25 -> 0 | AK25: =S25-AJ25-AI25-AH25 -> 0 | AL25: =T25-AK25-AJ25-AI25 -> 0 | AM25: =U25-AL25-AK25-AJ25 -> 0 | AN25: =V25-AM25-AL25-AK25 -> 0 | AO25: =W25-AN25-AM25-AL25 -> 0 | AP25: =X25-AO25-AN25-AM25 -> 0 | ... BD25: =AL25-BC25-BB25-BA25 -> 0 | BE25: =P25-BD25-BC25-BB25 -> 0 | BF25: =AN25-BE25-BD25-BC25 -> 0 | BH25: =(T25-BG25-AD25-AC25)/1000 -> 0 | BI25: =(U25-BH25-AE25-AD25)/1000 -> 0 | BJ25: =(V25-BI25-AF25-AE25)/1000 -> 0 | BK25: =I25-Z25-AB25-AA25 -> 0 | BL25: =(AB25-BK25-BJ25-BI25)/1000 -> 0 | BN25: 0 | BO25: 0 | BP25: 0 | BQ25: 0 | BR25: 0 | BS25: 0 | BT25: 0 | BU25: 0 | BV25: 0 | BW25: 0 | BY25: 0 | BZ25: 0 | CD25: 0 | CE25: 0
B26: Profit for the year (Non-banking businesses) | C26: =C24+C25 -> 438979.04 | D26: =D24+D25 -> 479754.55 | E26: =E24+E25 -> 594669.14 | F26: =F24+F25 -> 480410.1 | G26: =G24+G25 -> 480410.1 | H26: =H24+H25 -> 465871.91 | I26: =I24+I25 -> 309817.21 | J26: =J24+J25 -> 122883.97 | ... P26: =P24+P25 -> 1681706.7 | R26: =R24+R25 -> 91002.31 | S26: =S24+S25 -> 108721.47 | T26: =T24+T25 -> 222988.73 | U26: =U24+U25 -> 171956.63 | V26: =V24+V25 -> 108176.31 | W26: =W24+W25 -> 119452.99 | X26: =X24+X25 -> 76221.084 | Y26: =Y24+Y25 -> 176559.72 | ... BF26: =BF24+BF25 -> 148866.35 | BH26: =BH24+BH25 -> 62191.976 | BI26: =BI24+BI25 -> 87776.182 | BJ26: =BJ24+BJ25 -> 38987.548 | BK26: =BK24+BK25 -> 3252.397 | BL26: =BL24+BL25 -> 23826.806 | BN26: =BN24+BN25 -> 199723.78 | BO26: =BO24+BO25 -> 227629.3 | BP26: =BP24+BP25 -> 230432.84 | BQ26: =BQ24+BQ25 -> 69905.843 | BR26: =BR24+BR25 -> -161171.03 | BS26: =BS24+BS25 -> 153278.88 | BT26: =BT24+BT25 -> 121899.66 | BU26: =BU24+BU25 -> 56697.445 | ... BW26: =BW24+BW25 -> 587016.02 | BY26: =BY24+BY25 -> 149968.16 | BZ26: =BZ24+BZ25 -> 69905.843 | CC26: =CC24 -> 93668.103 | CD26: =CD24 -> 196361.11 | CE26: =CE24 -> 279718.66
B28: Banking Business Income statement | C28: 41975 | D28: 42341 | E28: 42708 | F28: 43073 | G28: =G3 -> 43073 | H28: =H3 -> 43438 | I28: =I3 -> 43438 | J28: =J3 -> 43803 | K28: =K3 -> 44169 | L28: =L3 -> 44534 | M28: =M3 -> 44899 | N28: =N3 -> 45264 | ... P28: =P3 -> 45995 | R28: 42437 | S28: 42527 | T28: 42622 | U28: 42714 | V28: 42801 | W28: 42892 | X28: 42987 | Y28: 43079 | Z28: =Z3 -> 43166 | AA28: =AA3 -> 43257 | AB28: =AB3 -> 43352 | AC28: =AC3 -> 43444 | AD28: =AD3 -> 43531 | AE28: =AE3 -> 43622 | AF28: =AF3 -> 43738 | AG28: =AG3 -> 43809 | ... BF28: =BF3 -> 46112 | BH28: =BH3 -> 43166 | BI28: =BI3 -> 43281 | BJ28: =BJ3 -> 43373 | BK28: =BK3 -> 43444 | BL28: =BL3 -> 43531 | BN28: 42530 | BO28: 42896 | BP28: =BP3 -> 43261 | BQ28: =BQ3 -> 43646 | BR28: =BR3 -> 44012 | BS28: =BS3 -> 44377 | BT28: =BT3 -> 44742 | BU28: =BU3 -> 45107 | BV28: =BV3 -> 45473 | BW28: =BW3 -> 45838 | BY28: =BY3 -> 43281 | BZ28: =BZ3 -> 43646
B29: Interest and indexation income. | C29: 445605.72 | D29: 485319.46 | E29: 526664.49 | F29: 556942.54 | G29: 580503.51 | H29: 598968.12 | I29: 1030424.2 | J29: 1108746 | K29: 978716.65 | L29: 901241.5 | M29: 1483314.9 | N29: =1478556.46+41291.16 -> 1519847.6 | O29: =1387171.214+35532.885 -> 1422704.1 | P29: =1476334.739+30905.664 -> 1507240.4 | R29: 125539.16 | S29: =BN29-R29 -> 131560.53 | T29: =390560.638-S29-R29 -> 133460.95 | U29: =E29-T29-S29-R29 -> 136103.85 | V29: 138497.89 | W29: =BO29-V29 -> 144720.75 | X29: =419434.845-W29-V29 -> 136216.21 | Y29: =F29-X29-W29-V29 -> 137507.69 | Z29: 142435.81 | AA29: =BP29-Z29 -> 147279.5 | AB29: =442891.404-AA29-Z29 -> 153176.1 | AC29: =H29-AB29-AA29-Z29 -> 156076.72 | AD29: 266179.13 | AE29: =BQ29-AD29 -> 279234.26 | AF29: =824896.564-AE29-AD29 -> 279483.17 | AG29: =J29-AF29-AE29-AD29 -> 283849.4 | AH29: 286649.93 | AI29: =BR29-AH29 -> 254568.62 | AJ29: =762024.745-AI29-AH29 -> 220806.2 | AK29: =K29-AJ29-AI29-AH29 -> 216691.91 | AL29: 208676.1 | AM29: =BS29-AL29 -> 207388.6 | AN29: =634820.562-AM29-AL29 -> 218755.86 | AO29: =L29-AN29-AM29-AL29 -> 266420.94 | AP29: 305465.91 | AQ29: =BT29-AP29 -> 372193.5 | AR29: =999056.02+81079.093-AQ29-AP29 -> 402475.7 | AS29: =M29-AR29-AQ29-AP29 -> 403179.79 | AT29: 383759.86 | AU29: =BU29-AT29 -> 380629.49 | AV29: =1119184.417+28238.115-AU29-AT29 -> 383033.18 | AW29: =N29-AV29-AU29-AT29 -> 372425.09 | AX29: =358719.206+6483.274 -> 365202.48 | AY29: =BV29-AX29 -> 360952.21 | AZ29: =1047503.515+24280.81-AY29-AX29 -> 345629.64 | BA29: =O29-AZ29-AY29-AX29 -> 350919.77 | BB29: =351193.012+10724.148 -> 361917.16 | BC29: =BW29-BB29 -> 374252.51 | BD29: =1090336.069+25066.904-BC29-BB29 -> 379233.31 | BE29: =P29-BD29-BC29-BB29 -> 391837.43 | BF29: =398147.131+2757.304 -> 400904.43 | BH29: 248488.89 | BI29: =BY29-BH29 -> 254822.05 | BJ29: =763849.417-BI29-BH29 -> 260538.48 | BK29: =I29-Z29-AB29-AA29 -> 587532.84 | BL29: 266179.13 | BN29: 257099.68 | BO29: 283218.64 | BP29: 289715.31 | BQ29: 545413.39 | BR29: 541218.55 | BS29: 416064.7 | BT29: =625516.904+52142.513 -> 677659.42 | BU29: =741043.845+23345.502 -> 764389.35 | BV29: =709611.982+16542.708 -> 726154.69 | BW29: =716256.99+19912.678 -> 736169.67 | BY29: 503310.94 | BZ29: 545413.39 | CC29: 109942.16 | CD29: 230671.86 | CE29: 358562.77
B30: Interest and indexation expense. | C30: -129938.79 | D30: -133370.24 | E30: -152144.76 | F30: -131370.91 | G30: -131789.24 | H30: -123592.69 | I30: -159244.9 | J30: -183119.74 | K30: -138045.5 | L30: -115989.49 | M30: -381166.57 | N30: =-448056.203-27366.89 -> -475423.09 | O30: =-338960.1-25650.678 -> -364610.78 | P30: =-20885.941-252735.845 -> -273621.79 | R30: -35992.828 | S30: =BN30-R30 -> -39238.813 | T30: =-114157.895-S30-R30 -> -38926.254 | U30: =E30-T30-S30-R30 -> -37986.863 | V30: -38537.457 | W30: =BO30-V30 -> -34274.04 | X30: =-102584.355-W30-V30 -> -29772.858 | Y30: =F30-X30-W30-V30 -> -28786.551 | Z30: -29437.147 | AA30: =BP30-Z30 -> -29591.539 | AB30: =-91225.111-AA30-Z30 -> -32196.425 | AC30: =H30-AB30-AA30-Z30 -> -32367.575 | AD30: -41645.262 | AE30: =BQ30-AD30 -> -48806.062 | AF30: =-136139.206-AE30-AD30 -> -45687.882 | AG30: =J30-AF30-AE30-AD30 -> -46980.537 | AH30: -43648.425 | AI30: =BR30-AH30 -> -39080.329 | AJ30: =-110440.512-AI30-AH30 -> -27711.758 | AK30: =K30-AJ30-AI30-AH30 -> -27604.987 | AL30: -26209.041 | AM30: =BS30-AL30 -> -21899.59 | AN30: =-73211.454-AM30-AL30 -> -25102.823 | AO30: =L30-AN30-AM30-AL30 -> -42778.032 | AP30: -54524.866 | AQ30: =BT30-AP30 -> -90359.362 | AR30: =-203850.272-57800.755-AQ30-AP30 -> -116766.8 | AS30: =M30-AR30-AQ30-AP30 -> -119515.54 | AT30: -118450.79 | AU30: =BU30-AT30 -> -120324.5 | AV30: =-337323.213-17746.916-AU30-AT30 -> -116294.83 | AW30: =N30-AV30-AU30-AT30 -> -120352.96 | AX30: =-105697.939-4777.198 -> -110475.14 | AY30: =BV30-AX30 -> -97265.334 | AZ30: =-272322.142-17665.879-AY30-AX30 -> -82247.55 | BA30: =O30-AZ30-AY30-AX30 -> -74622.757 | BB30: =-61589.132-7410.802 -> -68999.934 | BC30: =BW30-BB30 -> -68739.387 | BD30: =-189705.754-16890.488-BC30-BB30 -> -68856.921 | BE30: =P30-BD30-BC30-BB30 -> -67025.544 | BF30: =-61842.026-1846.825 -> -63688.851 | BH30: -38033.156 | BI30: =BY30-BH30 -> -38365.003 | BJ30: =-117304.963-BI30-BH30 -> -40906.804 | BK30: =I30-Z30-AB30-AA30 -> -68019.786 | BL30: -41645.262 | BN30: -75231.641 | BO30: -72811.497 | BP30: -59028.686 | BQ30: -90451.324 | BR30: -82728.754 | BS30: -48108.631 | BT30: =-107344.703-37539.525 -> -144884.23 | BU30: =-222714.808-16060.487 -> -238775.29 | BV30: =-195383.341-12357.13 -> -207740.47 | BW30: =-124380.291-13359.03 -> -137739.32 | BY30: -76398.159 | BZ30: -90451.324 | CC30: -26594.406 | CD30: -59257.418 | CE30: -96289.736
B31: Net interest and indexation income | C31: =C29+C30 -> 315666.92 | D31: =D29+D30 -> 351949.21 | E31: =E29+E30 -> 374519.73 | F31: =F29+F30 -> 425571.63 | G31: =G29+G30 -> 448714.27 | H31: =H29+H30 -> 475375.44 | I31: =I29+I30 -> 871179.34 | J31: =J29+J30 -> 925626.22 | ... P31: =P29+P30 -> 1233618.6 | R31: =R29+R30 -> 89546.331 | S31: =S29+S30 -> 92321.713 | T31: =T29+T30 -> 94534.699 | U31: =U29+U30 -> 98116.99 | V31: =V29+V30 -> 99960.428 | W31: =W29+W30 -> 110446.71 | X31: =X29+X30 -> 106443.35 | Y31: =Y29+Y30 -> 108721.14 | ... BF31: =BF29+BF30 -> 337215.58 | BH31: =BH29+BH30 -> 210455.73 | BI31: =BI29+BI30 -> 216457.05 | BJ31: =BJ29+BJ30 -> 219631.67 | BK31: =BK29+BK30 -> 519513.05 | BL31: =BL29+BL30 -> 224533.87 | BN31: =BN29+BN30 -> 181868.04 | BO31: =BO29+BO30 -> 210407.14 | BP31: =BP29+BP30 -> 230686.62 | BQ31: =BQ29+BQ30 -> 454962.07 | BR31: =BR29+BR30 -> 458489.79 | BS31: =BS29+BS30 -> 367956.07 | BT31: =BT29+BT30 -> 532775.19 | BU31: =BU29+BU30 -> 525614.05 | ... BW31: =BW29+BW30 -> 598430.35 | BY31: =BY29+BY30 -> 426912.78 | BZ31: =BZ29+BZ30 -> 454962.07 | CC31: =CC29+CC30 -> 83347.751 | CD31: 171414.44 | CE31: 262273.03
B32: Commission income | C32: 106875.47 | D32: 135915.71 | E32: 163483.78 | F32: 168429.49 | G32: 144686.06 | H32: 151585.28 | I32: 222880.45 | J32: 245043.8 | K32: 206908.36 | L32: 231937.09 | M32: 320766.14 | N32: =348379.315 -> 348379.32 | O32: 382301.65 | P32: 454764.15 | R32: 38535.59 | S32: =BN32-R32 -> 39517.887 | T32: =119569.97-S32-R32 -> 41516.493 | U32: =E32-T32-S32-R32 -> 43913.812 | V32: 41599.49 | W32: =BO32-V32 -> 42259.575 | X32: =125549.462-W32-V32 -> 41690.397 | Y32: =F32-X32-W32-V32 -> 42880.028 | Z32: 35276.679 | AA32: =BP32-Z32 -> 36532.645 | AB32: =110971.977-AA32-Z32 -> 39162.653 | AC32: =H32-AB32-AA32-Z32 -> 40613.299 | AD32: 58843.567 | AE32: =BQ32-AD32 -> 59772.075 | AF32: =180549.699-AE32-AD32 -> 61934.057 | AG32: =J32-AF32-AE32-AD32 -> 64494.1 | AH32: 64062.721 | AI32: =BR32-AH32 -> 44187.028 | AJ32: =155852.771-AI32-AH32 -> 47603.022 | AK32: =K32-AJ32-AI32-AH32 -> 51055.584 | AL32: 51602.325 | AM32: =BS32-AL32 -> 49079.947 | AN32: =160892.025-AM32-AL32 -> 60209.753 | AO32: =L32-AN32-AM32-AL32 -> 71045.061 | AP32: 79105.146 | AQ32: =BT32-AP32 -> 78788.126 | AR32: =236279.208-AQ32-AP32 -> 78385.936 | AS32: =M32-AR32-AQ32-AP32 -> 84486.935 | AT32: 86629.691 | AU32: =BU32-AT32 -> 82615.464 | AV32: =262008.23-AU32-AT32 -> 92763.075 | AW32: =N32-AV32-AU32-AT32 -> 86371.085 | AX32: 92675.791 | AY32: =BV32-AX32 -> 93479.841 | AZ32: =281107.347-AY32-AX32 -> 94951.715 | BA32: =O32-AZ32-AY32-AX32 -> 101194.3 | BB32: 105917.9 | BC32: =BW32-BB32 -> 109541.64 | BD32: =329730.835-BC32-BB32 -> 114271.29 | BE32: =P32-BD32-BC32-BB32 -> 125033.32 | BF32: 168025.38 | BH32: 52257.528 | BI32: =BY32-BH32 -> 54405.129 | BJ32: =163658.025-BI32-BH32 -> 56995.368 | BK32: =I32-Z32-AB32-AA32 -> 111908.47 | BL32: 58843.567 | BN32: 78053.477 | BO32: 83859.065 | BP32: 71809.324 | BQ32: 118615.64 | BR32: 108249.75 | BS32: 100682.27 | BT32: 157893.27 | BU32: 169245.15 | BV32: 186155.63 | BW32: 215459.54 | BY32: 106662.66 | BZ32: 118615.64 | CC32: 29504.036 | CD32: 59034.835 | CE32: 94436.261
B33: Commission expense | C33: -29218.656 | D33: -33607.581 | E33: -40135.723 | F33: -42394.224 | G33: -40914.588 | H33: -46909.811 | I33: -117165.21 | J33: -116057.42 | K33: -86761.814 | L33: -88385.525 | M33: -132047.61 | N33: =-102362.057 -> -102362.06 | O33: -129378.53 | P33: -158985.5 | R33: -8911.877 | S33: =BN33-R33 -> -10127.991 | T33: =-28960.018-S33-R33 -> -9920.15 | U33: =E33-T33-S33-R33 -> -11175.705 | V33: -9574.697 | W33: =BO33-V33 -> -10231.821 | X33: =-30689.635-W33-V33 -> -10883.117 | Y33: =F33-X33-W33-V33 -> -11704.589 | Z33: -10621.517 | AA33: =BP33-Z33 -> -11799.311 | AB33: =-34442.139-AA33-Z33 -> -12021.311 | AC33: =H33-AB33-AA33-Z33 -> -12467.672 | AD33: -28654.613 | AE33: =BQ33-AD33 -> -29033.033 | AF33: =-85214.41-AE33-AD33 -> -27526.764 | AG33: =J33-AF33-AE33-AD33 -> -30843.011 | AH33: -28426.914 | AI33: =BR33-AH33 -> -18950.94 | AJ33: =-65069.443-AI33-AH33 -> -17691.589 | AK33: =K33-AJ33-AI33-AH33 -> -21692.371 | AL33: -18941.513 | AM33: =BS33-AL33 -> -18344.135 | AN33: =-60800.287-AM33-AL33 -> -23514.639 | AO33: =L33-AN33-AM33-AL33 -> -27585.238 | AP33: -27733.485 | AQ33: =BT33-AP33 -> -35335.785 | AR33: =-94678.036-AQ33-AP33 -> -31608.766 | AS33: =M33-AR33-AQ33-AP33 -> -37369.578 | AT33: -22959.826 | AU33: =BU33-AT33 -> -25622.216 | AV33: =-69406.125-AU33-AT33 -> -20824.083 | AW33: =N33-AV33-AU33-AT33 -> -32955.932 | AX33: -31024.919 | AY33: =BV33-AX33 -> -31938.397 | AZ33: =-92550.189-AY33-AX33 -> -29586.873 | BA33: =O33-AZ33-AY33-AX33 -> -36828.343 | BB33: -33351.858 | BC33: =BW33-BB33 -> -38622.078 | BD33: =-111531.895-BC33-BB33 -> -39557.959 | BE33: =P33-BD33-BC33-BB33 -> -47453.608 | BF33: -69336.678 | BH33: -28038.482 | BI33: =BY33-BH33 -> -29920.772 | BJ33: =-86921.328-BI33-BH33 -> -28962.074 | BK33: =I33-Z33-AB33-AA33 -> -82723.068 | BL33: -28654.613 | BN33: -19039.868 | BO33: -19806.518 | BP33: -22420.828 | BQ33: -57687.646 | BR33: -47377.854 | BS33: -37285.648 | BT33: -63069.27 | BU33: -48582.042 | BV33: -62963.316 | BW33: -71973.936 | BY33: -57959.254 | BZ33: -57687.646 | CC33: -7788.427 | CD33: -15607.507 | CE33: -24151.703
B34: Net commission income | C34: =C32+C33 -> 77656.818 | D34: =D32+D33 -> 102308.13 | E34: =E32+E33 -> 123348.06 | F34: =F32+F33 -> 126035.27 | G34: =G32+G33 -> 103771.47 | H34: =H32+H33 -> 104675.47 | I34: =I32+I33 -> 105715.24 | J34: =J32+J33 -> 128986.38 | ... P34: =P32+P33 -> 295778.65 | R34: =R32+R33 -> 29623.713 | S34: =S32+S33 -> 29389.896 | T34: =T32+T33 -> 31596.343 | U34: =U32+U33 -> 32738.107 | V34: =V32+V33 -> 32024.793 | W34: =W32+W33 -> 32027.754 | X34: =X32+X33 -> 30807.28 | Y34: =Y32+Y33 -> 31175.439 | ... BF34: =BF32+BF33 -> 98688.697 | BH34: =BH32+BH33 -> 24219.046 | BI34: =BI32+BI33 -> 24484.357 | BJ34: =BJ32+BJ33 -> 28033.294 | BK34: =BK32+BK33 -> 29185.401 | BL34: =BL32+BL33 -> 30188.954 | BN34: =BN32+BN33 -> 59013.609 | BO34: =BO32+BO33 -> 64052.547 | BP34: =BP32+BP33 -> 49388.496 | BQ34: =BQ32+BQ33 -> 60927.996 | BR34: =BR32+BR33 -> 60871.895 | BS34: =BS32+BS33 -> 63396.624 | BT34: =BT32+BT33 -> 94824.002 | BU34: =BU32+BU33 -> 120663.11 | ... BW34: =BW32+BW33 -> 143485.6 | BY34: =BY32+BY33 -> 48703.403 | BZ34: =BZ32+BZ33 -> 60927.996 | CC34: =CC32+CC33 -> 21715.609 | CD34: 43427.328 | CE34: 70284.558
B35: Net income (loss) on financial transactions | C35: -1118.943 | D35: 2341.646 | E35: 17811.714 | F35: 6562.337 | G35: 5013.585 | H35: 20658.479 | I35: 20883.343 | J35: 17187.95 | K35: 26894.489 | L35: 22555.337 | M35: 30629.556 | N35: =41804.83 -> 41804.83 | O35: 54446.125 | P35: 25039.395 | R35: 6021.91 | S35: =BN35-R35 -> 2617.94 | T35: =11652.355-S35-R35 -> 3012.505 | U35: =E35-T35-S35-R35 -> 6159.359 | V35: 4296.759 | W35: =BO35-V35 -> 2686.591 | X35: =8929.982-W35-V35 -> 1946.632 | Y35: =F35-X35-W35-V35 -> -2367.645 | Z35: 5546.555 | AA35: =BP35-Z35 -> 7303.236 | AB35: =14298.612-AA35-Z35 -> 1448.821 | AC35: =H35-AB35-AA35-Z35 -> 6359.867 | AD35: 3698.05 | AE35: =BQ35-AD35 -> 7159.53 | AF35: =15822.252-AE35-AD35 -> 4964.672 | AG35: =J35-AF35-AE35-AD35 -> 1365.698 | AH35: 13408.596 | AI35: =BR35-AH35 -> 6591.714 | AJ35: =25920.888-AI35-AH35 -> 5920.578 | AK35: =K35-AJ35-AI35-AH35 -> 973.601 | AL35: 10009.511 | AM35: =BS35-AL35 -> 4009.919 | AN35: =15618.634-AM35-AL35 -> 1599.204 | AO35: =L35-AN35-AM35-AL35 -> 6936.703 | AP35: -9603.66 | AQ35: =BT35-AP35 -> 28511.429 | AR35: =33166.304-AQ35-AP35 -> 14258.535 | AS35: =M35-AR35-AQ35-AP35 -> -2536.748 | AT35: -8674.342 | AU35: =BU35-AT35 -> 1972.219 | AV35: =22731.424-AU35-AT35 -> 29433.547 | AW35: =N35-AV35-AU35-AT35 -> 19073.406 | AX35: 17189.688 | AY35: =BV35-AX35 -> 10349.004 | AZ35: =38233.284-AY35-AX35 -> 10694.592 | BA35: =O35-AZ35-AY35-AX35 -> 16212.841 | BB35: 9188.611 | BC35: =BW35-BB35 -> 3084.196 | BD35: =29291.921-BC35-BB35 -> 17019.114 | BE35: =P35-BD35-BC35-BB35 -> -4252.526 | BF35: 9624.05 | BH35: 5546.555 | BI35: =BY35-BH35 -> 7371.723 | BJ35: =14495.739-BI35-BH35 -> 1577.461 | BK35: =I35-Z35-AB35-AA35 -> 6584.731 | BL35: 3698.05 | BN35: 8639.85 | BO35: 6983.35 | BP35: 12849.791 | BQ35: 10857.58 | BR35: 20000.31 | BS35: 14019.43 | BT35: 18907.769 | BU35: -6702.123 | BV35: 27538.692 | BW35: 12272.807 | BY35: 12918.278 | BZ35: 10857.58 | CC35: 1289.56 | CD35: 546.766 | CE35: -1267.961
B36: Net income (loss) on currency exchange | C36: 10760.905 | D36: 8854.487 | E36: -5777.584 | F36: 5549.303 | G36: 5549.303 | H36: -8982.788 | I36: -8667.556 | J36: 4289.403 | K36: -3198.974 | L36: -8379.431 | M36: -22050.715 | N36: =-1097.673 -> -1097.673 | O36: 6850.842 | P36: 15727.808 | R36: -2696.743 | S36: =BN36-R36 -> 1123.335 | T36: =-2088.395-S36-R36 -> -514.987 | U36: =E36-T36-S36-R36 -> -3689.189 | V36: -158.082 | W36: =BO36-V36 -> 78.063 | X36: =199.907-W36-V36 -> 279.926 | Y36: =F36-X36-W36-V36 -> 5349.396 | Z36: -3224.654 | AA36: =BP36-Z36 -> -4789.709 | AB36: =-5964.282-AA36-Z36 -> 2050.081 | AC36: =H36-AB36-AA36-Z36 -> -3018.506 | AD36: 793.506 | AE36: =BQ36-AD36 -> 538.648 | AF36: =-133.397-AE36-AD36 -> -1465.551 | AG36: =J36-AF36-AE36-AD36 -> 4422.8 | AH36: -10592.732 | AI36: =BR36-AH36 -> 2910.554 | AJ36: =-6943.082-AI36-AH36 -> 739.096 | AK36: =K36-AJ36-AI36-AH36 -> 3744.108 | AL36: -3061.392 | AM36: =BS36-AL36 -> -983.435 | AN36: =-4732.17-AM36-AL36 -> -687.343 | AO36: =L36-AN36-AM36-AL36 -> -3647.261 | AP36: 12199.547 | AQ36: =BT36-AP36 -> -29086.052 | AR36: =-28093.323-AQ36-AP36 -> -11206.818 | AS36: =M36-AR36-AQ36-AP36 -> 6042.608 | AT36: 11218.594 | AU36: =BU36-AT36 -> 4778.768 | AV36: =-1173.512-AU36-AT36 -> -17170.874 | AW36: =N36-AV36-AU36-AT36 -> 75.839 | AX36: 2935.271 | AY36: =BV36-AX36 -> -607.479 | AZ36: =11230.372-AY36-AX36 -> 8902.58 | BA36: =O36-AZ36-AY36-AX36 -> -4379.53 | BB36: 4685.951 | BC36: =BW36-BB36 -> 3257.521 | BD36: =2124.971 -BC36-BB36 -> -5818.501 | BE36: =P36-BD36-BC36-BB36 -> 13602.837 | BF36: -717.439 | BH36: -3247.33 | BI36: =BY36-BH36 -> -4733.249 | BJ36: =-6044.816-BI36-BH36 -> 1935.763 | BK36: =I36-Z36-AB36-AA36 -> -2703.274 | BL36: 793.506 | BN36: -1573.408 | BO36: -80.019 | BP36: -8014.363 | BQ36: 1332.154 | BR36: -7682.178 | BS36: -4044.827 | BT36: -16886.505 | BU36: 15997.362 | BV36: 2327.792 | BW36: 7943.472 | BY36: -7980.579 | BZ36: 1332.154 | CC36: 2287.591 | CD36: 4888.707 | CE36: 9751.101
B37: Other operating income (expenses) | C37: 827.146 | D37: 2147.794 | E37: -69.539 | F37: -1278.595 | G37: 1377.03 | H37: 2128.723 | I37: 7139.46 | J37: 3402.024 | K37: 2125.477 | L37: 3320.434 | M37: 17219.311 | N37: =22017.939 -> 22017.939 | O37: 26509.757 | P37: 11324.466 | R37: 72.427 | S37: =BN37-R37 -> 178.833 | T37: =-116.098-S37-R37 -> -367.358 | U37: =E37-T37-S37-R37 -> 46.559 | V37: -329.383 | W37: =BO37-V37 -> -145.967 | X37: =-495.601-W37-V37 -> -20.251 | Y37: =F37-X37-W37-V37 -> -782.994 | Z37: 464.659 | AA37: =BP37-Z37 -> 339.022 | AB37: =1450.885-AA37-Z37 -> 647.204 | AC37: =H37-AB37-AA37-Z37 -> 677.838 | AD37: 302.835 | AE37: =BQ37-AD37 -> 1032.999 | AF37: =2383.321-AE37-AD37 -> 1047.487 | AG37: =J37-AF37-AE37-AD37 -> 1018.703 | AH37: 297.166 | AI37: =BR37-AH37 -> 668.773 | AJ37: =1130.286-AI37-AH37 -> 164.347 | AK37: =K37-AJ37-AI37-AH37 -> 995.191 | AL37: 852.088 | AM37: =BS37-AL37 -> 1461.99 | AN37: =2781.522-AM37-AL37 -> 467.444 | AO37: =L37-AN37-AM37-AL37 -> 538.912 | AP37: 2825.333 | AQ37: =BT37-AP37 -> 3357.532 | AR37: =7175.948-AQ37-AP37 -> 993.083 | AS37: =M37-AR37-AQ37-AP37 -> 10043.363 | AT37: 2422.16 | AU37: =BU37-AT37 -> 5259.712 | AV37: =13285.522-AU37-AT37 -> 5603.65 | AW37: =N37-AV37-AU37-AT37 -> 8732.417 | AX37: 12696.023 | AY37: =BV37-AX37 -> 3200.778 | AZ37: =17410.46-AY37-AX37 -> 1513.659 | BA37: =O37-AZ37-AY37-AX37 -> 9099.297 | BB37: 2772.93 | BC37: =BW37-BB37 -> 3476.33 | BD37: =7930.177 -BC37-BB37 -> 1680.917 | BE37: =P37-BD37-BC37-BB37 -> 3394.289 | BF37: 5150.868 | BH37: 942.56 | BI37: =BY37-BH37 -> 1336.017 | BJ37: =4339.327-BI37-BH37 -> 2060.75 | BK37: =I37-Z37-AB37-AA37 -> 5688.575 | BL37: 302.835 | BN37: 251.26 | BO37: -475.35 | BP37: 803.681 | BQ37: 1335.834 | BR37: 965.939 | BS37: 2314.078 | BT37: 6182.865 | BU37: 7681.872 | BV37: 15896.801 | BW37: 6249.26 | BY37: 2278.577 | BZ37: 1335.834 | CC37: 166.479 | CD37: 916.22 | CE37: 956.979
