Workbook
Name \A: #REF!
Name \B: #REF!
Name \C: #REF!
Name \L: #REF!
Name \M: #REF!
Name \P: #REF!
Name \Y: #REF!
Name _01_30_04: MonthlyOpStats
Name _01_30_04: MonthlyOpStats
Name _1_30_01: MonthlyOpStats
Name _1_30_01: MonthlyOpStats
Name _1_30_02: MonthlyOpStats
Name _1_30_02: MonthlyOpStats
Name _1_31_01: MonthlyOpStats
Name _1_31_01: MonthlyOpStats
Name _1_31_02: MonthlyOpStats
Name _1_31_02: MonthlyOpStats
Name _12_31_05: MonthlyOpStats
Name _12_31_05: MonthlyOpStats
Name _A: #REF!
Name _A___0: #REF!
Name _B: #REF!
Name _B___0: #REF!
Name _C: #REF!
Name _C___0: #REF!
Name _ent1: [1]Inputs!$J$17
Name _ent10: [1]Inputs!$J$476
Name _ent11: [1]Inputs!$J$527
Name _ent12: [1]Inputs!$J$578
Name _ent13: [1]Inputs!$J$629
Name _ent14: [1]Inputs!$J$680
Name _ent15: [1]Inputs!$J$731
Name _ent2: [1]Inputs!$J$68
Name _ent3: [1]Inputs!$J$119
Name _ent4: [1]Inputs!$J$170
Name _ent5: [1]Inputs!$J$221
Name _ent6: [1]Inputs!$J$272
Name _ent7: [1]Inputs!$J$323
Name _ent8: [1]Inputs!$J$374
Name _ent9: [1]Inputs!$J$425
Name _eps1: [1]Inputs!$P$42
Name _eps10: [1]Inputs!$P$501
Name _eps11: [1]Inputs!$P$552
Name _eps12: [1]Inputs!$P$603
Name _eps13: [1]Inputs!$P$654
Name _eps14: [1]Inputs!$P$705
Name _eps15: [1]Inputs!$P$756
Name _eps2: [1]Inputs!$P$93
Name _eps3: [1]Inputs!$P$144
Name _eps4: [1]Inputs!$P$195
Name _eps5: [1]Inputs!$P$246
Name _eps6: [1]Inputs!$P$297
Name _eps7: [1]Inputs!$P$348
Name _eps8: [1]Inputs!$P$399
Name _eps9: [1]Inputs!$P$450
Name _fye1: [1]Inputs!$E$12
Name _fye10: [1]Inputs!$E$471
Name _fye11: [1]Inputs!$E$522
Name _fye12: [1]Inputs!$E$573
Name _fye13: [1]Inputs!$E$624

Sheet Capitalisation
A2: 1Q26 | I2: Exchange rate as at end 1Q26 | J2: =Model!$K$210 -> 0.14494854
I3: LTM Average exchange rate | J3: =Model!$K$211 -> 0.14097399
B5: Debt Breakdown as on 31-Mar-2026 | C5: RMB mn | D5: Leverage | E5: USD mn | F5: Leverage
B6: current liabilities
B7: RMB bank borrowings – unsecured | E7: =C7*$J$2 -> 0
B8: RMB bank borrowings – secured | E8: =C8*$J$2 -> 0
B9: Total bank borrowings | C9: 5380.92 | E9: =C9*$J$2 -> 779.95652
B11: Current portion of long-term convertible bonds | E11: =C11*$J$2 -> 0
B12: Current portion of long-term senior notes | E12: =C12*$J$2 -> 0
B13: Total bonds and notes | C13: 11334.607 | E13: =C13*$J$2 -> 1642.9348
B15: non-current liabilities:
B16: RMB bank borrowings – unsecured | E16: =C16*$J$2 -> 0
B17: RMB bank borrowings – secured | E17: =C17*$J$2 -> 0
B18: Total bank borrowings | C18: 42686.825 | E18: =C18*$J$2 -> 6187.3931
B20: Non-current portion of long-term convertible bonds | E20: =C20*$J$2 -> 0
B21: Non-current portion of long-term senior notes | E21: =C21*$J$2 -> 0
B22: Total bonds and notes | C22: 46703.421 | E22: =C22*$J$2 -> 6769.5928
B24: lease liabilities:
B25: current lease liabilities | C25: 2829.87 | E25: =C25*$J$2 -> 410.18553
B26: non- current lease liabilities | C26: 3868.242 | E26: =C26*$J$2 -> 560.69604
B28: Total Loans & Borrowings | C28: =SUM(C7:C26) -> 112803.88 | D28: =C28/C36 -> -3.8718558 | E28: =SUM(E7:E26) -> 16350.759 | F28: =E28/E36 -> -3.981017
B29: Cash and Cash Equivalents | C29: =Model!AO$122 -> 117029.37 | E29: =C29*J2 -> 16963.237
B30: Short term Investments | C30: =Model!AO$123 -> 63340.786 | E30: =C30*J2 -> 9181.1547
B31: Net debt | C31: =C28-C29-C30 -> -67566.27 | D31: =IF(C31<0,"net cash",C31/C36) -> net cash | E31: =E28-E29-E30 -> -9793.6324 | F31: =IF(E31<0,"net cash",E31/E36) -> net cash
B32: Restricted cash | C32: =Model!AO$126 -> 19868.723 | E32: =C32*J2 -> 2879.9425
B33: Net debt (including restricted cash) | C33: =C31-C32 -> -87434.993 | D33: =IF(C33<0,"net cash",C33/C36) -> net cash | E33: =E31-E32 -> -12673.575 | F33: =IF(E33<0,"net cash",E33/E36) -> net cash
B34: Equity | C34: =Model!AO$128 -> 149881.76 | E34: =C34*J2 -> 21725.143
B35: Total Capitalisation | C35: =C31+C34 -> 82315.491 | E35: =E31+E34 -> 11931.511
B36: LTM Adjusted EBITDA | C36: =Model!AO$89 -> -29134.32 | E36: =C36*J3 -> -4107.1814
B37: check | C37: =+C28-Model!AO$121 -> 0
B40: Liquidity at end-1Q26 | C40: RMB mn | D40: USD mn
B41: Cash and Cash Equivalents | C41: 117029.37 | D41: =C41*J2 -> 16963.237
B42: Short-term treasury investments | C42: 63340.786 | D42: =C42*J2 -> 9181.1547
B43: Restricted cash | C43: 19868.723 | D43: =C43*J2 -> 2879.9425
B44: Total liquidity | C44: =SUM(C41:C43) -> 200238.88 | D44: =SUM(D41:D43) -> 29024.334
B47: Debt Maturity at end-1Q26 (from BBG) | C47: RMB mn | D47: USD mn
B48: 2027 | C48: 137.38 | D48: =C48*J2 -> 19.913031
B49: 2028 | C49: 8248.87 | D49: =C49*J2 -> 1195.6617
B50: 2029 | C50: 8797.46 | D50: =C50*J2 -> 1275.179
B51: 2030 | C51: 10539.09 | D51: =C51*J2 -> 1527.6257
...

Sheet Model
B2: Meituan | C2: Annual | D2: Annual | E2: Annual | F2: Annual | G2: Annual | H2: Annual | I2: Annual | J2: Annual | K2: LTM | M2: Quarters | N2: Quarters | O2: Quarters | P2: Quarters | Q2: Quarters | R2: Quarters | S2: Quarters | T2: Quarters | U2: Quarters | V2: Quarters | W2: Quarters | X2: Quarters | Y2: Quarters | Z2: Quarters | AA2: Quarters | AB2: Quarters | AC2: Quarters | AD2: Quarters | AE2: Quarters | AF2: Quarters | AG2: Quarters | AH2: Quarters | AI2: Quarters | AJ2: Quarters | AK2: Quarters | AL2: Quarters | AM2: Quarters | AN2: Quarters | AO2: Quarters
B3: (RMB million) | C3: 43465 | D3: 43830 | E3: 44196 | F3: 44561 | G3: 44926 | H3: 45291 | I3: 45657 | J3: 46022 | K3: =AO3 -> 46112 | M3: 43555 | N3: 43646 | O3: 43738 | P3: 43830 | Q3: 43921 | R3: 44012 | S3: 44104 | T3: 44196 | U3: 44286 | V3: 44377 | W3: 44469 | X3: 44561 | Y3: 44651 | Z3: 44742 | AA3: 44834 | AB3: 44926 | AC3: 45016 | AD3: 45107 | AE3: 45199 | AF3: 45291 | AG3: 45382 | AH3: 45473 | AI3: 45565 | AJ3: 45657 | AK3: 45747 | AL3: 45838 | AM3: 45930 | AN3: 46022 | AO3: 46112
C4: Act | D4: Act | E4: Act | F4: Act | G4: Act | H4: Act | I4: Act | J4: Act | K4: Act | M4: Act | N4: Act | O4: Act | P4: Act | Q4: Act | R4: Act | S4: Act | T4: Act | U4: Act | V4: Act | W4: Act | X4: Act | Y4: Act | Z4: Act | AA4: Act | AB4: Act | AC4: Act | AD4: Act | AE4: Act | AF4: Act | AG4: Act | AH4: Act | AI4: Act | AJ4: Act | AK4: Act | AL4: Act | AM4: Act | AN4: Act | AO4: Act
C5: FY | D5: FY | E5: FY | F5: FY | G5: FY | H5: FY | I5: FY | J5: FY | K5: LTM | M5: 1Q | N5: 2Q | O5: 3Q | P5: 4Q | Q5: 1Q | R5: 2Q | S5: 3Q | T5: 4Q | U5: 1Q | V5: 2Q | W5: 3Q | X5: 4Q | Y5: 1Q | Z5: 2Q | AA5: 3Q | AB5: 4Q | AC5: 1Q | AD5: 2Q | AE5: 3Q | AF5: 4Q | AG5: 1Q | AH5: 2Q | AI5: 3Q | AJ5: 4Q | AK5: 1Q | AL5: 2Q | AM5: 3Q | AN5: 4Q | AO5: 1Q
B6: INCOME STATEMENT
B7: Revenue | C7: 65227.278 | D7: 97528.531 | E7: 114794.51 | F7: 179128 | G7: 219954.95 | H7: 276744.95 | I7: 337591.58 | J7: 364854.75 | K7: =SUM(AL7:AO7) -> 369687.51 | M7: 19173.512 | N7: 22703.137 | O7: 27493.629 | P7: =D7-SUM(M7:O7) -> 28158.253 | Q7: 16753.887 | R7: 24721.837 | S7: 35401.282 | T7: =E7-SUM(Q7:S7) -> 37917.504 | U7: 37016.262 | V7: 43759.232 | W7: 48829.37 | X7: =F7-SUM(U7:W7) -> 49523.133 | Y7: 46268.754 | Z7: 50938.363 | AA7: 62618.892 | AB7: =G7-SUM(Y7:AA7) -> 60128.939 | AC7: 58617.472 | AD7: 67964.624 | AE7: 76466.907 | AF7: =H7-SUM(AC7:AE7) -> 73695.951 | AG7: 73275.884 | AH7: 82251.077 | AI7: 93577.319 | AJ7: =I7-SUM(AG7:AI7) -> 88487.296 | AK7: 86206.145 | AL7: 91840.48 | AM7: 95488.113 | AN7: =J7-SUM(AK7:AM7) -> 91320.008 | AO7: =91038.906 -> 91038.906
B8: % of growth | D8: =(D7/C7)-1 -> 0.49521081 | E8: =(E7/D7)-1 -> 0.17703516 | F8: =(F7/E7)-1 -> 0.56042303 | G8: =(G7/F7)-1 -> 0.22792055 | H8: =(H7/G7)-1 -> 0.25818926 | I8: =(I7/H7)-1 -> 0.21986533 | J8: =(J7/I7)-1 -> 0.08075785 | Q8: =(Q7/M7)-1 -> -0.12619623 | R8: =(R7/N7)-1 -> 0.088917228 | S8: =(S7/O7)-1 -> 0.28761765 | T8: =(T7/P7)-1 -> 0.34658581 | U8: =(U7/Q7)-1 -> 1.2094134 | V8: =(V7/Q7)-1 -> 1.6118853 | W8: =(W7/S7)-1 -> 0.37931078 | X8: =(X7/T7)-1 -> 0.30607576 | Y8: =(Y7/U7)-1 -> 0.24995749 | Z8: =(Z7/U7)-1 -> 0.3761077 | AA8: =(AA7/W7)-1 -> 0.28240221 | AB8: =(AB7/X7)-1 -> 0.21415862 | AC8: =(AC7/Y7)-1 -> 0.26689109 | AD8: =(AD7/Y7)-1 -> 0.46890975 | AE8: =(AE7/AA7)-1 -> 0.22114756 | AF8: =(AF7/AB7)-1 -> 0.22563199 | AG8: =(AG7/AC7)-1 -> 0.25006899 | AH8: =(AH7/AC7)-1 -> 0.40318363 | AI8: =(AI7/AE7)-1 -> 0.22376231 | AJ8: =(AJ7/AF7)-1 -> 0.2007077 | AK8: =(AK7/AG7)-1 -> 0.17645998 | AL8: =(AL7/AG7)-1 -> 0.25335206 | AM8: =(AM7/AI7)-1 -> 0.020419414 | AN8: =(AN7/AJ7)-1 -> 0.032012641 | AO8: =(AO7/AK7)-1 -> 0.056060516
B9: Cost of revenues | C9: -50122.32 | D9: -65208.143 | E9: -80744.368 | F9: -136653.87 | G9: -158201.97 | H9: -179553.79 | I9: -207806.98 | J9: -253846.12 | K9: =SUM(AL9:AO9) -> -264771.52 | M9: -14104.172 | N9: -14762.502 | O9: -17901.345 | P9: =D9-SUM(M9:O9) -> -18440.124 | Q9: -11557.421 | R9: -16146.879 | S9: -24578.273 | T9: =E9-SUM(Q9:S9) -> -28461.795 | U9: -29816.095 | V9: -31245.861 | W9: -38051.383 | X9: =F9-SUM(U9:W9) -> -37540.53 | Y9: -35528.467 | Z9: -35363.935 | AA9: -44114.024 | AB9: =G9-SUM(Y9:AA9) -> -43195.543 | AC9: -38800.047 | AD9: -42566.619 | AE9: -49484.515 | AF9: =H9-SUM(AC9:AE9) -> -48702.612 | AG9: -47579.144 | AH9: -48361.233 | AI9: -56823.456 | AJ9: =I9-SUM(AG9:AI9) -> -55043.149 | AK9: -54143.437 | AL9: -61426.477 | AM9: -70307.05 | AN9: =J9-SUM(AK9:AM9) -> -67969.156 | AO9: -65068.834
B10: Gross Profit | C10: =C7+C9 -> 15104.958 | D10: =D7+D9 -> 32320.388 | E10: =E7+E9 -> 34050.142 | F10: =F7+F9 -> 42474.128 | G10: =G7+G9 -> 61752.979 | H10: =H7+H9 -> 97191.161 | I10: =I7+I9 -> 129784.59 | J10: =J7+J9 -> 111008.63 | K10: =K7+K9 -> 104915.99 | M10: =M7+M9 -> 5069.34 | N10: =N7+N9 -> 7940.635 | O10: =O7+O9 -> 9592.284 | P10: =P7+P9 -> 9718.129 | Q10: =Q7+Q9 -> 5196.466 | R10: =R7+R9 -> 8574.958 | S10: =S7+S9 -> 10823.009 | T10: =T7+T9 -> 9455.709 | ... AO10: =AO7+AO9 -> 25970.072
B11: Gross Profit margin | C11: =C10/C7 -> 0.23157425 | D11: =D10/D7 -> 0.33139418 | E11: =E10/E7 -> 0.29661821 | F11: =F10/F7 -> 0.23711608 | G11: =G10/G7 -> 0.28075285 | H11: =H10/H7 -> 0.35119398 | I11: =I10/I7 -> 0.38444263 | J11: =J10/J7 -> 0.3042543 | K11: =K10/K7 -> 0.28379642 | M11: =M10/M7 -> 0.26439288 | N11: =N10/N7 -> 0.34975937 | O11: =O10/O7 -> 0.34889116 | P11: =P10/P7 -> 0.34512542 | Q11: =Q10/Q7 -> 0.3101648 | R11: =R10/R7 -> 0.34685764 | S11: =S10/S7 -> 0.30572365 | T11: =T10/T7 -> 0.24937583 | ... AO11: =AO10/AO7 -> 0.28526345
B12: Operating expenses:
B13: Selling and marketing expenses | C13: -15871.901 | D13: -18819.067 | E13: -20882.685 | F13: -40683.166 | G13: -39745.112 | H13: -58616.997 | I13: -63975.235 | J13: -102934.04 | K13: =SUM(AL13:AO13) -> -110703.53 | M13: -3706.112 | N13: -4149.11 | O13: -5614.75 | P13: =D13-SUM(M13:O13) -> -5349.095 | Q13: -3199.439 | R13: -4172.332 | S13: -5835.574 | T13: =E13-SUM(Q13:S13) -> -7675.34 | U13: -7206.408 | V13: -10848.627 | W13: -11388.227 | X13: =F13-SUM(U13:W13) -> -11239.904 | Y13: -9105.728 | Z13: -8986.036 | AA13: -10886.422 | AB13: =G13-SUM(Y13:AA13) -> -10766.926 | AC13: -10433.07 | AD13: -14553.195 | AE13: -16905.422 | AF13: =H13-SUM(AC13:AE13) -> -16725.31 | AG13: -13888.302 | AH13: -14832.448 | AI13: -17953.163 | AJ13: =I13-SUM(AG13:AI13) -> -17301.322 | AK13: -15199.035 | AL13: -22518.913 | AM13: -34266.826 | AN13: =J13-SUM(AK13:AM13) -> -30949.27 | AO13: -22968.519
B14: Research and development expenses | C14: -7071.9 | D14: -8445.664 | E14: -10892.514 | F14: -16675.595 | G14: -20739.865 | H14: -21201.005 | I14: -21053.601 | J14: -25998.265 | K14: =SUM(AL14:AO14) -> -27269.333 | M14: -2036.1 | N14: -2032.33 | O14: -2137.349 | P14: =D14-SUM(M14:O14) -> -2239.885 | Q14: -2296.458 | R14: -2376.737 | S14: -2970.12 | T14: =E14-SUM(Q14:S14) -> -3249.199 | U14: -3477.29 | V14: -3900.794 | W14: -4715.55 | X14: =F14-SUM(U14:W14) -> -4581.961 | Y14: -4879.033 | Z14: -5203.533 | AA14: -5414.371 | AB14: =G14-SUM(Y14:AA14) -> -5242.928 | AC14: -5047.387 | AD14: -5407.176 | AE14: -5321.157 | AF14: =H14-SUM(AC14:AE14) -> -5425.285 | AG14: -5000.153 | AH14: -5339.68 | AI14: -5293.483 | AJ14: =I14-SUM(AG14:AI14) -> -5420.285 | AK14: -5772.03 | AL14: -6260.087 | AM14: -6936.845 | AN14: =J14-SUM(AK14:AM14) -> -7029.303 | AO14: -7043.098
B15: General and administrative expenses | C15: -5546.037 | D15: -4338.954 | E15: -5593.895 | F15: -8612.626 | G15: -9771.81 | H15: -9372.067 | I15: -10729.203 | J15: -11916.432 | K15: =SUM(AL15:AO15) -> -12227.808 | M15: -1012.213 | N15: -1038.298 | O15: -1055.969 | P15: =D15-SUM(M15:O15) -> -1232.474 | Q15: -1069.741 | R15: -1158.092 | S15: -1415.119 | T15: =E15-SUM(Q15:S15) -> -1950.943 | U15: -1737.403 | V15: -2053.024 | W15: -2387.116 | X15: =F15-SUM(U15:W15) -> -2435.083 | Y15: -2312.289 | Z15: -2503.552 | AA15: -2505.272 | AB15: =G15-SUM(Y15:AA15) -> -2450.697 | AC15: -1994.953 | AD15: -2139.048 | AE15: -2537.785 | AF15: =H15-SUM(AC15:AE15) -> -2700.281 | AG15: -2298.323 | AH15: -2694.931 | AI15: -2797.76 | AJ15: =I15-SUM(AG15:AI15) -> -2938.189 | AK15: -2627.017 | AL15: -2678.95 | AM15: -2957.804 | AN15: =J15-SUM(AK15:AM15) -> -3652.661 | AO15: -2938.393
B16: Net provision for impairment losses on financial assets | C16: -285.655 | D16: -645.685 | E16: -467.69 | F16: -259.953 | G16: -468.62 | H16: -1135.405 | I16: -897.505 | J16: -872.035 | K16: =SUM(AL16:AO16) -> -1231.572 | M16: -62.98 | N16: -138.711 | O16: -111.99 | P16: =D16-SUM(M16:O16) -> -332.004 | Q16: -237.542 | R16: -45.676 | S16: -130.285 | T16: =E16-SUM(Q16:S16) -> -54.187 | U16: 33.775 | V16: -104.355 | W16: -136.884 | X16: =F16-SUM(U16:W16) -> -52.489 | Y16: -153.316 | Z16: -50.437 | AA16: -284.035 | AB16: =G16-SUM(Y16:AA16) -> 19.168 | AC16: -255.347 | AD16: -195.264 | AE16: -276.377 | AF16: =H16-SUM(AC16:AE16) -> -408.417 | AG16: -175.386 | AH16: -276.431 | AI16: -275.298 | AJ16: =I16-SUM(AG16:AI16) -> -170.39 | AK16: -121.474 | AL16: -19.219 | AM16: -292.777 | AN16: =J16-SUM(AK16:AM16) -> -438.565 | AO16: -481.011
B17: Fair value changes on other financial investments | C17: 1836.382 | D17: 77.699 | E17: 4955.909 | F17: 815.747 | G17: -1013.057 | H17: 234.227 | I17: 140.921 | J17: 2393.393 | K17: =SUM(AL17:AO17) -> 1981.014 | M17: 165.292 | N17: -323.651 | O17: 163.615 | P17: =D17-SUM(M17:O17) -> 72.443 | Q17: -508.261 | R17: 346.689 | S17: 5779.364 | T17: =E17-SUM(Q17:S17) -> -661.883 | U17: 42.034 | V17: 164.748 | W17: -117.99 | X17: =F17-SUM(U17:W17) -> 726.955 | Y17: -802.894 | Z17: -292.183 | AA17: -105.922 | AB17: =G17-SUM(Y17:AA17) -> 187.942 | AC17: 164.029 | AD17: 103.761 | AE17: 28.089 | AF17: =H17-SUM(AC17:AE17) -> -61.652 | AG17: -517.116 | AH17: -120.037 | AI17: 765.239 | AJ17: =I17-SUM(AG17:AI17) -> 12.835 | AK17: 804.82 | AL17: 481.537 | AM17: -389.928 | AN17: =J17-SUM(AK17:AM17) -> 1496.964 | AO17: 392.441
B18: Other operating income/(loss), net | C18: 748.356 | D18: 2531.143 | E18: 3160.835 | F18: -185.734 | G18: 4165.037 | H18: 6315.473 | I18: 3574.985 | J18: 3277.62 | K18: =SUM(AL18:AO18) -> 2458.179 | M18: 279.131 | N18: 854.043 | O18: 611.223 | P18: =D18-SUM(M18:O18) -> 786.746 | Q18: 399.445 | R18: 1005.835 | S18: 472.408 | T18: =E18-SUM(Q18:S18) -> 1283.147 | U18: 378.118 | V18: 976.976 | W18: -2134.851 | X18: =F18-SUM(U18:W18) -> 594.023 | Y18: 928.731 | Z18: 968.475 | AA18: 1679.376 | AB18: =G18-SUM(Y18:AA18) -> 588.455 | AC18: 1335.024 | AD18: 1505.916 | AE18: 1388.793 | AF18: =H18-SUM(AC18:AE18) -> 2085.74 | AG18: 1391.932 | AH18: 630.572 | AI18: 2485.778 | AJ18: =I18-SUM(AG18:AI18) -> -933.297 | AK18: 1418.138 | AL18: 807.979 | AM18: -96.233 | AN18: =J18-SUM(AK18:AM18) -> 1147.736 | AO18: 598.697
B19: Operating profit | C19: =C10+SUM(C13:C18) -> -11085.797 | D19: =D10+SUM(D13:D18) -> 2679.86 | E19: =E10+SUM(E13:E18) -> 4330.102 | F19: =F10+SUM(F13:F18) -> -23127.199 | G19: =G10+SUM(G13:G18) -> -5820.448 | H19: =H10+SUM(H13:H18) -> 13415.387 | I19: =I10+SUM(I13:I18) -> 36844.956 | J19: =J10+SUM(J13:J18) -> -25041.137 | K19: =K10+SUM(K13:K18) -> -42077.058 | M19: =M10+SUM(M13:M18) -> -1303.642 | N19: =N10+SUM(N13:N18) -> 1112.578 | O19: =O10+SUM(O13:O18) -> 1447.064 | P19: =P10+SUM(P13:P18) -> 1423.86 | Q19: =Q10+SUM(Q13:Q18) -> -1715.53 | R19: =R10+SUM(R13:R18) -> 2174.645 | S19: =S10+SUM(S13:S18) -> 6723.683 | T19: =T10+SUM(T13:T18) -> -2852.696 | ... AO19: =AO10+SUM(AO13:AO18) -> -6469.811
B20: Finance exps | C20: =-44.732 -> -44.732 | D20: -191.042 | E20: -370.016 | F20: -1130.935 | G20: -1628.825 | H20: -1425.157 | I20: -1337.038 | J20: -1886.802 | K20: =SUM(AL20:AO20) -> -2198.659 | M20: -46.821 | N20: -50.115 | O20: -49.011 | P20: =D20-SUM(M20:O20) -> -45.095 | Q20: -48.044 | R20: -60.731 | S20: -111.506 | T20: =E20-SUM(R20:S20) -> -197.779 | U20: -166.052 | V20: -263.269 | W20: -369.942 | X20: =F20-SUM(V20:W20) -> -497.724 | Y20: -330.317 | Z20: -418.612 | AA20: -474.728 | AB20: =G20-SUM(Y20:AA20) -> -405.168 | AC20: -353.479 | AD20: -354.003 | AE20: -350.95 | AF20: =H20-SUM(AC20:AE20) -> -366.725 | AG20: -321.863 | AH20: -285.373 | AI20: -261.651 | AJ20: =I20-SUM(AG20:AI20) -> -468.151 | AK20: -475.12 | AL20: -430.214 | AM20: -413.987 | AN20: =J20-SUM(AK20:AM20) -> -567.481 | AO20: -786.977
B21: Finance income | C21: 294.047 | D21: 166.217 | E21: 213.684 | F21: 546.037 | G21: 657.908 | H21: 818.986 | I21: 1291.807 | J21: 2011.535 | K21: =SUM(AL21:AO21) -> 2002.103 | M21: 52.922 | N21: 21.541 | O21: 38.235 | P21: =D21-SUM(M21:O21) -> 53.519 | Q21: 57.93 | R21: 40.352 | S21: 45.678 | T21: =E21-SUM(Q21:S21) -> 69.724 | U21: 77.855 | V21: 112.118 | W21: 198.89 | X21: =F21-SUM(U21:W21) -> 157.174 | Y21: 110.359 | Z21: 190.412 | AA21: 209.746 | AB21: =G21-SUM(Y21:AA21) -> 147.391 | AC21: 184.419 | AD21: 217.189 | AE21: 201.225 | AF21: =H21-SUM(AC21:AE21) -> 216.153 | AG21: 279.755 | AH21: 344.494 | AI21: 313.088 | AJ21: =I21-SUM(AG21:AI21) -> 354.47 | AK21: 491.358 | AL21: 508.307 | AM21: 513.372 | AN21: =J21-SUM(AK21:AM21) -> 498.498 | AO21: 481.926
B22: Fair value changes of convertible redeemable preferred shares | C22: -104606.06 | H22: 0 | I22: 0 | J22: 0 | K22: =SUM(AL22:AO22) -> 0 | Y22: 0 | Z22: 0 | AA22: 0 | AB22: =G22-SUM(Y22:AA22) -> 0 | AC22: 0 | AD22: 0 | AE22: 0 | AF22: =H22-SUM(AC22:AE22) -> 0 | AG22: 0 | AH22: 0 | AI22: 0 | AJ22: =I22-SUM(AG22:AI22) -> 0 | AK22: 0 | AL22: 0 | AM22: 0 | AN22: =J22-SUM(AK22:AM22) -> 0 | AO22: 0
B23: Share of net profit /(loss) of associates | C23: -48.267 | D23: 107.353 | E23: 264.105 | F23: 145.62 | G23: 35.848 | H23: 1212.652 | I23: 1185.704 | J23: 78.892 | K23: =SUM(AL23:AO23) -> -441.562 | M23: 7.53 | N23: 17.848 | O23: 24.329 | P23: =D23-SUM(M23:O23) -> 57.646 | Q23: 11.128 | R23: 42.881 | S23: 92.698 | T23: =E23-SUM(Q23:S23) -> 117.398 | U23: -2.013 | V23: 38.251 | W23: 273.237 | X23: =F23-SUM(U23:W23) -> -163.855 | Y23: 46.411 | Z23: -400.052 | AA23: 485.362 | AB23: =G23-SUM(Y23:AA23) -> -95.873 | AC23: -49.759 | AD23: 122.406 | AE23: 434.521 | AF23: =H23-SUM(AC23:AE23) -> 705.484 | AG23: 314.197 | AH23: 341.204 | AI23: 213.821 | AJ23: =I23-SUM(AG23:AI23) -> 316.482 | AK23: 18.453 | AL23: 89.223 | AM23: 9.541 | AN23: =J23-SUM(AK23:AM23) -> -38.325 | AO23: -502.001
B24: Profit before tax | C24: =C19+SUM(C20:C23) -> -115490.81 | D24: =D19+SUM(D20:D23) -> 2762.388 | E24: =E19+SUM(E20:E23) -> 4437.875 | F24: =F19+SUM(F20:F23) -> -23566.477 | G24: =G19+SUM(G20:G23) -> -6755.517 | H24: =H19+SUM(H20:H23) -> 14021.868 | I24: =I19+SUM(I20:I23) -> 37985.429 | J24: =J19+SUM(J20:J23) -> -24837.512 | K24: =K19+SUM(K20:K23) -> -42715.176 | M24: =M19+SUM(M20:M23) -> -1290.011 | N24: =N19+SUM(N20:N23) -> 1101.852 | O24: =O19+SUM(O20:O23) -> 1460.617 | P24: =P19+SUM(P20:P23) -> 1489.93 | Q24: =Q19+SUM(Q20:Q23) -> -1694.516 | R24: =R19+SUM(R20:R23) -> 2197.147 | S24: =S19+SUM(S20:S23) -> 6750.553 | T24: =T19+SUM(T20:T23) -> -2863.353 | ... AO24: =AO19+SUM(AO20:AO23) -> -7276.863
B25: Income tax credits/(expenses) / Current and deferred income tax and social contribution | C25: -1.888 | D25: -526.223 | E25: 269.737 | F25: 30.279 | G25: 70.194 | H25: -164.537 | I25: -2177.107 | J25: 1483.318 | K25: =SUM(AL25:AO25) -> 2476.844 | M25: -143.319 | N25: -226.024 | O25: -127.235 | P25: =D25-SUM(M25:O25) -> -29.645 | Q25: 115.238 | R25: 13.034 | S25: -429.552 | T25: =E25-SUM(Q25:S25) -> 571.017 | U25: 10.955 | V25: 8.23 | W25: 6.036 | X25: =F25-SUM(U25:W25) -> 5.058 | Y25: 55.223 | Z25: 5.063 | AA25: 8.209 | AB25: =G25-SUM(Y25:AA25) -> 1.699 | AC25: -8.411 | AD25: -9.972 | AE25: -50.095 | AF25: =H25-SUM(AC25:AE25) -> -96.059 | AG25: -112.502 | AH25: -304.876 | AI25: -1085.48 | AJ25: =I25-SUM(AG25:AI25) -> -674.249 | AK25: -543.921 | AL25: -28.37 | AM25: 1018.336 | AN25: =J25-SUM(AK25:AM25) -> 1037.273 | AO25: 449.605
B26: Net profit/loss | C26: =+C24+C25 -> -115492.7 | D26: =+D24+D25 -> 2236.165 | E26: =+E24+E25 -> 4707.612 | F26: =+F24+F25 -> -23536.198 | G26: =+G24+G25 -> -6685.323 | H26: =+H24+H25 -> 13857.331 | I26: =+I24+I25 -> 35808.322 | J26: =+J24+J25 -> -23354.194 | K26: =+K24+K25 -> -40238.332 | M26: =+M24+M25 -> -1433.33 | N26: =+N24+N25 -> 875.828 | O26: =+O24+O25 -> 1333.382 | P26: =+P24+P25 -> 1460.285 | Q26: =+Q24+Q25 -> -1579.278 | R26: =+R24+R25 -> 2210.181 | S26: =+S24+S25 -> 6321.001 | T26: =+T24+T25 -> -2292.336 | ... AO26: =+AO24+AO25 -> -6827.258
B27: % margin | C27: =+C26/C7 -> -1.7706196 | D27: =+D26/D7 -> 0.022928316 | E27: =+E26/E7 -> 0.041009034 | F27: =+F26/F7 -> -0.13139318 | G27: =+G26/G7 -> -0.030394056 | H27: =+H26/H7 -> 0.05007257 | I27: =+I26/I7 -> 0.10606995 | J27: =+J26/J7 -> -0.064009566 | K27: =+K26/K7 -> -0.10884418 | M27: =+M26/M7 -> -0.074755736 | N27: =+N26/N7 -> 0.0385774 | O27: =+O26/O7 -> 0.048497854 | P27: =+P26/P7 -> 0.051859929 | Q27: =+Q26/Q7 -> -0.094263379 | R27: =+R26/R7 -> 0.089401973 | S27: =+S26/S7 -> 0.17855288 | T27: =+T26/T7 -> -0.060455878 | ... AO27: =+AO26/AO7 -> -0.074992751
B28: Non-controlling interest | C28: 15.524 | D28: 2.604 | E28: 0.701 | F28: -2.181 | G28: -0.787 | H28: -1.503 | I28: -1.143 | J28: -0.821 | K28: =SUM(AL28:AO28) -> -0.924 | M28: 1.553 | N28: 1.587 | O28: 1.82 | P28: =D28-SUM(M28:O28) -> -2.356 | Q28: 0.942 | R28: -0.434 | S28: 0.602 | T28: =E28-SUM(Q28:S28) -> -0.409 | U28: -1.021 | V28: -0.948 | W28: -0.25 | X28: =F28-SUM(U28:W28) -> 0.038 | Y28: 0.077 | Z28: -0.492 | AA28: 0.369 | AB28: =G28-SUM(Y28:AA28) -> -0.741 | AC28: -0.258 | AD28: -0.749 | AE28: -0.211 | AF28: =H28-SUM(AC28:AE28) -> -0.285 | AG28: -0.441 | AH28: =-0.858-AG28 -> -0.417 | AI28: -0.255 | AJ28: =I28-SUM(AG28:AI28) -> -0.03 | AK28: -0.053 | AL28: =-0.532-AK28 -> -0.479 | AM28: -0.366 | AN28: =J28-SUM(AK28:AM28) -> 0.077 | AO28: -0.156
B29: Net profit/loss | C29: =+C26+C28 -> -115477.17 | D29: =+D26+D28 -> 2238.769 | E29: =+E26+E28 -> 4708.313 | F29: =+F26+F28 -> -23538.379 | G29: =+G26+G28 -> -6686.11 | H29: =+H26+H28 -> 13855.828 | I29: =+I26+I28 -> 35807.179 | J29: =+J26+J28 -> -23355.015 | K29: =+K26+K28 -> -40239.256 | M29: =+M26+M28 -> -1431.777 | N29: =+N26+N28 -> 877.415 | O29: =+O26+O28 -> 1335.202 | P29: =+P26+P28 -> 1457.929 | Q29: =+Q26+Q28 -> -1578.336 | R29: =+R26+R28 -> 2209.747 | S29: =+S26+S28 -> 6321.603 | T29: =+T26+T28 -> -2292.745 | ... AO29: =+AO26+AO28 -> -6827.414
B31: As % of sales unless stated otherwise
B32: =B13 -> Selling and marketing expenses | C32: =-C13/C7 -> 0.24333226 | D32: =-D13/D7 -> 0.19295961 | E32: =-E13/E7 -> 0.18191362 | F32: =-F13/F7 -> 0.22711785 | G32: =-G13/G7 -> 0.1806966 | H32: =-H13/H7 -> 0.21180873 | I32: =-I13/I7 -> 0.18950483 | J32: =-J13/J7 -> 0.28212335 | K32: =-K13/K7 -> 0.29945163 | M32: =-M13/M7 -> 0.19329333 | N32: =-N13/N7 -> 0.18275492 | O32: =-O13/O7 -> 0.20422004 | P32: =-P13/P7 -> 0.18996544 | Q32: =-Q13/Q7 -> 0.19096697 | R32: =-R13/R7 -> 0.16877112 | S32: =-S13/S7 -> 0.16484075 | T32: =-T13/T7 -> 0.20242208 | ... AO32: =-AO13/AO7 -> 0.25229344
B33: =B14 -> Research and development expenses | C33: =-C14/C7 -> 0.10841936 | D33: =-D14/D7 -> 0.086596854 | E33: =-E14/E7 -> 0.094887064 | F33: =-F14/F7 -> 0.093093181 | G33: =-G14/G7 -> 0.094291423 | H33: =-H14/H7 -> 0.076608461 | I33: =-I14/I7 -> 0.062364118 | J33: =-J14/J7 -> 0.07125648 | K33: =-K14/K7 -> 0.073763199 | M33: =-M14/M7 -> 0.10619338 | N33: =-N14/N7 -> 0.089517585 | O33: =-O14/O7 -> 0.077739792 | P33: =-P14/P7 -> 0.079546306 | Q33: =-Q14/Q7 -> 0.13707016 | R33: =-R14/R7 -> 0.096139174 | S33: =-S14/S7 -> 0.083898657 | T33: =-T14/T7 -> 0.085691268 | ... AO33: =-AO14/AO7 -> 0.077363605
B34: =B15 -> General and administrative expenses | C34: =-C15/C7 -> 0.085026344 | D34: =-D15/D7 -> 0.044489074 | E34: =-E15/E7 -> 0.048729639 | F34: =-F15/F7 -> 0.048080848 | G34: =-G15/G7 -> 0.044426416 | H34: =-H15/H7 -> 0.033865358 | I34: =-I15/I7 -> 0.031781608 | J34: =-J15/J7 -> 0.032660756 | K34: =-K15/K7 -> 0.033076065 | M34: =-M15/M7 -> 0.052792258 | N34: =-N15/N7 -> 0.04573368 | O34: =-O15/O7 -> 0.038407771 | P34: =-P15/P7 -> 0.043769548 | Q34: =-Q15/Q7 -> 0.063850317 | R34: =-R15/R7 -> 0.046844901 | S34: =-S15/S7 -> 0.039973665 | T34: =-T15/T7 -> 0.051452306 | ... AO34: =-AO15/AO7 -> 0.032276234
B35: =B16 -> Net provision for impairment losses on financial assets | C35: =-C16/C$7 -> 0.0043793794 | D35: =-D16/D$7 -> 0.0066204729 | E35: =-E16/E$7 -> 0.0040741495 | F35: =-F16/F$7 -> 0.0014512137 | G35: =-G16/G$7 -> 0.0021305272 | H35: =-H16/H$7 -> 0.0041027126 | I35: =-I16/I$7 -> 0.0026585527 | J35: =-J16/J$7 -> 0.0023900881 | K35: =-K16/K$7 -> 0.0033313866 | M35: =-M16/M$7 -> 0.0032847399 | N35: =-N16/N$7 -> 0.0061097724 | O35: =-O16/O$7 -> 0.0040733073 | P35: =-P16/P$7 -> 0.011790646 | Q35: =-Q16/Q$7 -> 0.014178322 | R35: =-R16/R$7 -> 0.0018475973 | S35: =-S16/S$7 -> 0.003680234 | T35: =-T16/T$7 -> 0.0014290761 | ... AO35: =-AO16/AO$7 -> 0.0052835762
B36: =B17 -> Fair value changes on other financial investments | C36: =-C17/C$7 -> -0.028153589 | D36: =-D17/D$7 -> -0.00079667969 | E36: =-E17/E$7 -> -0.043172004 | F36: =-F17/F$7 -> -0.0045539894 | G36: =-G17/G$7 -> 0.0046057477 | H36: =-H17/H$7 -> -0.00084636412 | I36: =-I17/I$7 -> -0.00041743044 | J36: =-J17/J$7 -> -0.0065598516 | K36: =-K17/K$7 -> -0.0053586177 | M36: =-M17/M$7 -> -0.0086208515 | N36: =-N17/N$7 -> 0.014255783 | O36: =-O17/O$7 -> -0.0059510151 | P36: =-P17/P$7 -> -0.0025727093 | Q36: =-Q17/Q$7 -> 0.0303369 | R36: =-R17/R$7 -> -0.014023594 | S36: =-S17/S$7 -> -0.16325296 | T36: =-T17/T$7 -> 0.017455869 | ... AO36: =-AO17/AO$7 -> -0.0043106955
B37: =B18 -> Other operating income/(loss), net | C37: =-C18/C7 -> -0.011473053 | D37: =-D18/D7 -> -0.025952847 | E37: =-E18/E7 -> -0.027534723 | F37: =-F18/F7 -> 0.0010368787 | G37: =-G18/G7 -> -0.018935864 | H37: =-H18/H7 -> -0.022820553 | I37: =-I18/I7 -> -0.010589675 | J37: =-J18/J7 -> -0.0089833558 | K37: =-K18/K7 -> -0.0066493429 | M37: =-M18/M7 -> -0.014558157 | N37: =-N18/N7 -> -0.037617841 | O37: =-O18/O7 -> -0.022231441 | P37: =-P18/P7 -> -0.027940157 | Q37: =-Q18/Q7 -> -0.02384193 | R37: =-R18/R7 -> -0.040686095 | S37: =-S18/S7 -> -0.013344375 | T37: =-T18/T7 -> -0.033840492 | ... AO37: =-AO18/AO7 -> -0.0065762763
B38: Finance exps as % of debt | C38: =-C20/C111 -> 0.019705241 | D38: =-D20/D111 -> 0.0475316 | E38: =-E20/E111 -> 0.017306201 | F38: =-F20/F111 -> 0.020854968 | G38: =-G20/G111 -> 0.030896659 | H38: =-H20/H111 -> 0.02612912 | I38: =-I20/I111 -> 0.023981572 | J38: =-J20/J111 -> 0.023501858 | K38: =-K20/K111 -> 0.020721389 | P38: =-SUM(M20:P20)/P111 -> 0.0475316 | Q38: =-SUM(N20:Q20)/Q111 -> 0.047773921 | R38: =-SUM(O20:R20)/R111 -> 0.061040818 | S38: =-SUM(P20:S20)/S111 -> 0.033743085 | T38: =-SUM(Q20:T20)/T111 -> 0.01955329 | U38: =-SUM(R20:U20)/U111 -> 0.059260966 | V38: =-SUM(S20:V20)/V111 -> 0.014846494 | W38: =-SUM(T20:W20)/W111 -> 0.01806914 | ... AO38: =-SUM(AL20:AO20)/AO111 -> 0.020721389
B39: Finance income as% of cash and cash equivalents | C39: =C21/C122 -> 0.017252541 | D39: =D21/D122 -> 0.012407786 | E39: =E21/E122 -> 0.012500849 | F39: =F21/F122 -> 0.0167942 | G39: =G21/G122 -> 0.032636582 | H39: =H21/H122 -> 0.024564848 | I39: =I21/I122 -> 0.018237079 | J39: =J21/J122 -> 0.018839648 | K39: =K21/K122 -> 0.017107697 | P39: =SUM(M21:P21)/P122 -> 0.012407786 | Q39: =SUM(N21:Q21)/Q122 -> 0.012111125 | R39: =SUM(O21:R21)/R122 -> 0.013637261 | S39: =SUM(P21:S21)/S122 -> 0.010029609 | T39: =SUM(Q21:T21)/T122 -> 0.012500849 | U39: =SUM(R21:U21)/U122 -> 0.013129337 | V39: =SUM(S21:V21)/V122 -> 0.0042776876 | W39: =SUM(T21:W21)/W122 -> 0.0090029468 | ... AO39: =SUM(AL21:AO21)/AO122 -> 0.017107697
B40: =B23 -> Share of net profit /(loss) of associates | C40: =-C23/C7 -> 0.00073998182 | D40: =-D23/D7 -> -0.0011007343 | E40: =-E23/E7 -> -0.0023006762 | F40: =-F23/F7 -> -0.00081293825 | G40: =-G23/G7 -> -0.00016297883 | H40: =-H23/H7 -> -0.0043818396 | I40: =-I23/I7 -> -0.003512244 | J40: =-J23/J7 -> -0.00021622852 | K40: =-K23/K7 -> 0.0011944196 | M40: =-M23/M7 -> -0.0003927293 | N40: =-N23/N7 -> -0.00078614687 | O40: =-O23/O7 -> -0.00088489592 | P40: =-P23/P7 -> -0.0020472151 | Q40: =-Q23/Q7 -> -0.00066420407 | R40: =-R23/R7 -> -0.0017345394 | S40: =-S23/S7 -> -0.0026184927 | T40: =-T23/T7 -> -0.0030961426 | ... AO40: =-AO23/AO7 -> 0.005514137
B41: Tax % of PBT | C41: =-C25/C24 -> -1.6347622e-05 | D41: =-D25/D24 -> 0.19049569 | E41: =-E25/E24 -> -0.060780666 | F41: =-F25/F24 -> 0.0012848335 | G41: =-G25/G24 -> 0.010390619 | H41: =-H25/H24 -> 0.011734314 | I41: =-I25/I24 -> 0.057314266 | J41: =-J25/J24 -> 0.059720877 | K41: =-K25/K24 -> 0.057985106 | M41: =-M25/M24 -> -0.11109905 | N41: =-N25/N24 -> 0.205131 | O41: =-O25/O24 -> 0.087110447 | P41: =-P25/P24 -> 0.019896908 | Q41: =-Q25/Q24 -> 0.06800644 | R41: =-R25/R24 -> -0.0059322385 | S41: =-S25/S24 -> 0.06363212 | T41: =-T25/T24 -> 0.1994225 | ... AO41: =-AO25/AO24 -> 0.061785552
B43: Working capital /sales | C43: =C63/C7 -> 0.0004395247 | D43: =D63/D7 -> 0.010377866 | E43: =E63/E7 -> 0.046499262 | F43: =F63/F7 -> 0.022852285 | G43: =G63/G7 -> -0.0036984119 | H43: =H63/H7 -> 0.048692956 | I43: =I63/I7 -> 0.019152045 | J43: =J63/J7 -> -0.0028941079 | K43: =K63/K7 -> 0 | M43: =M63/M7 -> 0 | N43: =N63/N7 -> 0 | O43: =O63/O7 -> 0 | P43: =P63/P7 -> 0.035944631 | Q43: =Q63/Q7 -> 0 | R43: =R63/R7 -> 0 | S43: =S63/S7 -> 0 | T43: =T63/T7 -> 0.14077562 | ... AO43: =AO63/AO7 -> 0
...

Sheet EBITDA
B2: Meituan | C2: Annual | D2: Annual | E2: Annual | G2: Quarters | H2: Quarters | I2: Quarters | J2: Quarters | K2: Quarters | L2: Quarters | M2: Quarters | N2: Quarters | O2: Quarters
B3: (RMB million) | C3: 45291 | D3: 45657 | E3: 46022 | G3: 45382 | H3: 45473 | I3: 45565 | J3: 45657 | K3: 45747 | L3: 45838 | M3: 45930 | N3: 46022 | O3: 46112
C4: Act | D4: Act | E4: Act | G4: Act | H4: Act | I4: Act | J4: Act | K4: Act | L4: Act | M4: Act | N4: Act | O4: Act
C5: FY | D5: FY | E5: FY | G5: 1Q | H5: 2Q | I5: 3Q | J5: 4Q | K5: 1Q | L5: 2Q | M5: 3Q | N5: 4Q | O5: 1Q
B9: Profit for the period | C9: 13857.331 | D9: 35808.322 | E9: -23354.194 | G9: 5368.979 | H9: 11352.338 | I9: 12864.954 | J9: 6222.051 | K9: 10056.88 | L9: 365.296 | M9: -18632.088 | N9: -15144.282 | O9: -6827.258
B10: Adjusted for:
B11: Share-based compensation expenses | C11: 8383.353 | D11: 7582.693 | E11: 6001.867 | G11: 1851.012 | H11: 2069.327 | I11: 1890.022 | J11: 1772.332 | K11: 1707.846 | L11: 1387.416 | M11: 1558.306 | N11: 1348.299 | O11: 1383.006
B12: Foreign exchange (gains)/losses from intercompany balances | C12: 0 | D12: 119.455 | E12: -1512.297 | G12: 0 | H12: 0 | I12: -1548.588 | J12: 1668.043 | K12: -265.904 | L12: -464.206 | M12: -153.975 | N12: -628.212 | O12: -312.006
B13: Net (gains)/losses from investments | C13: 12.486 | D13: -192.795 | E13: -2334.922 | G13: 359.322 | H13: -62.507 | I13: -567.679 | J13: 78.069 | K13: -777.438 | L13: -355.455 | M13: 335.243 | N13: -1537.272 | O13: -389.746
B14: Impairment and expense provision | C14: 817.785 | D14: 202.48 | E14: 2060.775 | G14: 0 | H14: 129.153 | I14: 0 | J14: 73.327 | K14: 0 | L14: 428.137 | M14: 1017.919 | N14: 614.719 | O14: 1094.032
B15: Amortisation of intangible assets resulting from acquisitions | C15: 246.19 | D15: 171.127 | E15: 199.888 | G15: 42.84 | H15: 42.841 | I15: 42.841 | J15: 42.605 | K15: 45.187 | L15: 51.504 | M15: 51.504 | N15: 51.693 | O15: 51.694
B16: Tax effects | C16: -63.727 | D16: 81.167 | E16: 290.882 | G16: -133.759 | H16: 75.104 | I16: 147.711 | J16: -7.889 | K16: 181.933 | L16: 80.343 | M16: -186.543 | N16: 215.149 | O16: 32.375
B17: Adjusted net profit | C17: =SUM(C9:C16) -> 23253.418 | D17: =SUM(D9:D16) -> 43772.449 | E17: =SUM(E9:E16) -> -18648.001 | G17: =SUM(G9:G16) -> 7488.394 | H17: =SUM(H9:H16) -> 13606.256 | I17: =SUM(I9:I16) -> 12829.261 | J17: =SUM(J9:J16) -> 9848.538 | K17: =SUM(K9:K16) -> 10948.504 | L17: =SUM(L9:L16) -> 1493.035 | M17: =SUM(M9:M16) -> -16009.634 | N17: =SUM(N9:N16) -> -15079.906 | O17: =SUM(O9:O16) -> -4967.903
B19: Adjusted for:
B20: Income tax expenses not adjusted for adjusted net profit | C20: 228.264 | D20: 2095.94 | E20: -1774.2 | G20: 246.261 | H20: 229.772 | I20: 937.769 | J20: 682.138 | K20: 361.988 | L20: -51.973 | M20: -831.793 | N20: -1252.422 | O20: -481.98
B21: Share of profits of investments accounted for using the equity method not adjusted for adjusted net profit | C21: -1554.673 | D21: -934.361 | E21: 13.07 | G21: -143.376 | H21: -93.96 | I21: -385.3 | J21: -311.725 | K21: -30.765 | L21: -141.766 | M21: 45.935 | N21: 139.666 | O21: 503.603
B22: Finance income | C22: -818.986 | D22: -1291.807 | E22: -2011.535 | G22: -279.755 | H22: -344.494 | I22: -313.088 | J22: -354.47 | K22: -491.358 | L22: -508.307 | M22: -513.372 | N22: -498.498 | O22: -481.926
B23: Finance costs | C23: 1425.157 | D23: 1337.038 | E23: 1886.802 | G23: 321.863 | H23: 285.373 | I23: 261.651 | J23: 468.151 | K23: 475.12 | L23: 430.214 | M23: 413.987 | N23: 567.481 | O23: 786.977
B24: Certain items in other gains, net | C24: -6405.729 | D24: -4110.082 | E24: -3248.492 | G24: -1404.959 | H24: -695.272 | I24: -963.271 | J24: -1046.58 | K24: -1145.115 | L24: -822.354 | M24: -577.598 | N24: -703.425 | O24: -1212.618
B25: Amortisation of software and others | C25: 62.744 | D25: 68.522 | E25: 62.52 | G25: 14.384 | H25: 18.392 | I25: 17.622 | J25: 18.124 | K25: 14.047 | L25: 15.721 | M25: 16.116 | N25: 16.636 | O25: 17.788
B26: Depreciation of property, plant and equipment | C26: 7687.823 | D26: 8181.701 | E26: 9936.631 | G26: 1827.531 | H26: 1991.201 | I26: 2144.553 | J26: 2218.416 | K26: 2169.265 | L26: 2367.391 | M26: 2614.462 | N26: 2785.513 | O26: 2786.713
B27: Adjusted EBITDA | C27: =SUM(C20:C26,C17) -> 23878.018 | D27: =SUM(D20:D26,D17) -> 49119.4 | E27: =SUM(E20:E26,E17) -> -13783.205 | G27: =SUM(G20:G26,G17) -> 8070.343 | H27: =SUM(H20:H26,H17) -> 14997.268 | I27: =SUM(I20:I26,I17) -> 14529.197 | J27: =SUM(J20:J26,J17) -> 11522.592 | K27: =SUM(K20:K26,K17) -> 12301.686 | L27: =SUM(L20:L26,L17) -> 2781.961 | M27: =SUM(M20:M26,M17) -> -14841.897 | N27: =SUM(N20:N26,N17) -> -14024.955 | O27: =SUM(O20:O26,O17) -> -3049.346

Sheet KPIs
B2: Meituan | C2: Annual | D2: Annual | E2: Annual | F2: Annual | G2: Annual | H2: Annual | I2: Annual | J2: Annual | K2: LTM | M2: Quarters | N2: Quarters | O2: Quarters | P2: Quarters | Q2: Quarters | R2: Quarters | S2: Quarters | T2: Quarters | U2: Quarters | V2: Quarters | W2: Quarters | X2: Quarters | Y2: Quarters | Z2: Quarters | AA2: Quarters | AB2: Quarters | AC2: Quarters | AD2: Quarters | AE2: Quarters | AF2: Quarters | AG2: Quarters | AH2: Quarters | AI2: Quarters | AJ2: Quarters | AK2: Quarters | AL2: Quarters | AM2: Quarters | AN2: Quarters | AO2: Quarters
B3: (RMB million) | C3: 43465 | D3: 43830 | E3: 44196 | F3: 44561 | G3: 44926 | H3: 45291 | I3: 45657 | J3: 46022 | K3: =AO3 -> 46112 | M3: 43555 | N3: 43646 | O3: 43738 | P3: 43830 | Q3: 43921 | R3: 44012 | S3: 44104 | T3: 44196 | U3: 44286 | V3: 44377 | W3: 44469 | X3: 44561 | Y3: 44651 | Z3: 44742 | AA3: 44834 | AB3: 44926 | AC3: 45016 | AD3: 45107 | AE3: 45199 | AF3: 45291 | AG3: 45382 | AH3: 45473 | AI3: 45565 | AJ3: 45657 | AK3: 45747 | AL3: 45838 | AM3: 45930 | AN3: 46022 | AO3: 46112
C4: Act | D4: Act | E4: Act | F4: Act | G4: Act | H4: Act | I4: Act | J4: Act | K4: Act | M4: Act | N4: Act | O4: Act | P4: Act | Q4: Act | R4: Act | S4: Act | T4: Act | U4: Act | V4: Act | W4: Act | X4: Act | Y4: Act | Z4: Act | AA4: Act | AB4: Act | AC4: Act | AD4: Act | AE4: Act | AF4: Act | AG4: Act | AH4: Act | AI4: Act | AJ4: Act | AK4: Act | AL4: Act | AM4: Act | AN4: Act | AO4: Act
C5: FY | D5: FY | E5: FY | F5: FY | G5: FY | H5: FY | I5: FY | J5: FY | K5: LTM | M5: 1Q | N5: 2Q | O5: 3Q | P5: 4Q | Q5: 1Q | R5: 2Q | S5: 3Q | T5: 4Q | U5: 1Q | V5: 2Q | W5: 3Q | X5: 4Q | Y5: 1Q | Z5: 2Q | AA5: 3Q | AB5: 4Q | AC5: 1Q | AD5: 2Q | AE5: 3Q | AF5: 4Q | AG5: 1Q | AH5: 2Q | AI5: 3Q | AJ5: 4Q | AK5: 1Q | AL5: 2Q | AM5: 3Q | AN5: 4Q | AO5: 1Q
B7: Revenue by segment
B8: Food delivery / Core local commerce | C8: 38143.083 | D8: 54843.205 | E8: 66265.319 | F8: 96311.778 | G8: 160759.02 | H8: 206906.93 | I8: 250247.5 | J8: 260826.09 | K8: =SUM(AL8:AO8) -> 260915.65 | M8: 10705.803 | N8: 12844.72 | O8: 15576.972 | P8: 15715.71 | Q8: 9490.423 | R8: 14544.095 | S8: 20692.816 | T8: 21537.985 | U8: 20575.41 | V8: 23125.084 | W8: 26484.643 | X8: 26126.641 | Y8: 24156.722 | Z8: 36779.243 | AA8: 46327.529 | AB8: 43472.664 | AC8: 42885.336 | AD8: 51199.946 | AE8: 57691.008 | AF8: =H8-AC8-AD8-AE8 -> 55130.642 | AG8: 54625.707 | AH8: 60681.858 | AI8: 69373.099 | AJ8: =I8-AG8-AH8-AI8 -> 65566.832 | AK8: 63973.733 | AL8: 65347.283 | AM8: 67446.866 | AN8: =J8-AK8-AL8-AM8 -> 64058.212 | AO8: 64063.286
B9: In-store, hotel & travel | C9: 15840.361 | D9: 22275.472 | E9: 21252.398 | F9: 32530.325 | M9: 4492.102 | N9: 5245.308 | O9: 6181.117 | P9: 6356.945 | Q9: 3094.978 | R9: 4543.982 | S9: 6478.078 | T9: 7135.36 | U9: 6584.391 | V9: 8602.179 | W9: 8621.328 | X9: 8722.427 | Y9: 7621.509 | Z9: 0 | AA9: 0 | AB9: 0 | AC9: 0 | AD9: 0 | AE9: 0 | AF9: =H9-AC9-AD9-AE9 -> 0 | AG9: 0 | AH9: 0 | AI9: 0 | AJ9: =I9-AG9-AH9-AI9 -> 0 | AK9: 0 | AL9: 0 | AM9: 0 | AN9: =J9-AK9-AL9-AM9 -> 0 | AO9: 0
B10: New initiatives and others | C10: 11243.834 | D10: 20409.854 | E10: 27276.793 | F10: 50285.894 | G10: 59195.926 | H10: 69838.022 | I10: 87344.08 | J10: 104028.65 | K10: =SUM(AL10:AO10) -> 108771.86 | M10: 3975.607 | N10: 4613.109 | O10: 5735.54 | P10: 6085.598 | Q10: 4168.486 | R10: 5633.76 | S10: 8230.388 | T10: 9244.159 | U10: 9856.461 | V10: 12031.969 | W10: 13723.399 | X10: 14674.065 | Y10: 14490.523 | Z10: 14159.12 | AA10: 16291.363 | AB10: 16656.275 | AC10: 15732.136 | AD10: 16764.678 | AE10: 18775.899 | AF10: =H10-AC10-AD10-AE10 -> 18565.309 | AG10: 18650.177 | AH10: 21569.219 | AI10: 24204.22 | AJ10: =I10-AG10-AH10-AI10 -> 22920.464 | AK10: 22232.412 | AL10: 26493.197 | AM10: 28041.247 | AN10: =J10-AK10-AL10-AM10 -> 27261.796 | AO10: 26975.62
B11: Total | C11: =SUM(C8:C10) -> 65227.278 | D11: =SUM(D8:D10) -> 97528.531 | E11: =SUM(E8:E10) -> 114794.51 | F11: =SUM(F8:F10) -> 179128 | G11: =SUM(G8:G10) -> 219954.95 | H11: =SUM(H8:H10) -> 276744.95 | I11: =SUM(I8:I10) -> 337591.58 | J11: =SUM(J8:J10) -> 364854.75 | K11: =SUM(K8:K10) -> 369687.51 | M11: =SUM(M8:M10) -> 19173.512 | N11: =SUM(N8:N10) -> 22703.137 | O11: =SUM(O8:O10) -> 27493.629 | P11: =SUM(P8:P10) -> 28158.253 | Q11: =SUM(Q8:Q10) -> 16753.887 | R11: =SUM(R8:R10) -> 24721.837 | S11: =SUM(S8:S10) -> 35401.282 | T11: =SUM(T8:T10) -> 37917.504 | ... AO11: =SUM(AO8:AO10) -> 91038.906
B12: Check | C12: =C11-Model!C7 -> 0 | D12: =D11-Model!D7 -> 0 | E12: =E11-Model!E7 -> 0 | F12: =F11-Model!F7 -> 0 | G12: =G11-Model!G7 -> 0 | H12: =H11-Model!H7 -> 0 | I12: =I11-Model!I7 -> 0 | J12: =J11-Model!J7 -> 0 | K12: =K11-Model!K7 -> 0 | M12: =M11-Model!M7 -> 0 | N12: =N11-Model!N7 -> 0 | O12: =O11-Model!O7 -> 0 | P12: =P11-Model!P7 -> 0 | Q12: =Q11-Model!Q7 -> 0 | R12: =R11-Model!R7 -> 0 | S12: =S11-Model!S7 -> 0 | T12: =T11-Model!T7 -> 0 | ... AO12: =AO11-Model!AO7 -> 0
B14: Operating profit by segment
B15: Food delivery / Core local commerce | D15: 1415.88 | E15: 2833.369 | F15: 6174.641 | G15: 29502.669 | H15: 38698.847 | I15: 52415.162 | J15: -6904.083 | K15: =SUM(AL15:AO15) -> -22425.505 | M15: -154.203 | N15: 756.347 | O15: 330.907 | P15: 482.829 | Q15: -70.881 | R15: 1253.421 | S15: 768.477 | T15: 882.352 | U15: 1115.885 | V15: 2447.076 | W15: 876.103 | X15: 1735.577 | Y15: 1577.143 | Z15: 8260.993 | AA15: 9321.293 | AB15: 7215.242 | AC15: 9445.07 | AD15: 11138.521 | AE15: 10095.831 | AF15: =H15-AC15-AD15-AE15 -> 8019.425 | AG15: 9698.847 | AH15: 15233.585 | AI15: 14582.403 | AJ15: =I15-AG15-AH15-AI15 -> 12900.327 | AK15: 13491.48 | AL15: 3721.13 | AM15: -14071.01 | AN15: =J15-AK15-AL15-AM15 -> -10045.683 | AO15: -2029.942
B16: In-store, hotel & travel | D16: 8403.293 | E16: 8180.933 | F16: 14093.113 | M16: 1592.878 | N16: 2147.499 | O16: 2331.639 | P16: 2331.277 | Q16: 680.179 | R16: 1891.563 | S16: 2787.256 | T16: 2821.935 | U16: 2748.205 | V16: 3663.818 | W16: 3784.074 | X16: 3897.016 | Y16: 3473.546 | Z16: 0 | AA16: 0 | AB16: 0 | AC16: 0 | AD16: 0 | AE16: 0 | AF16: =H16-AC16-AD16-AE16 -> 0 | AG16: 0 | AH16: 0 | AI16: 0 | AJ16: =I16-AG16-AH16-AI16 -> 0 | AK16: 0 | AL16: 0 | AM16: 0 | AN16: =J16-AK16-AL16-AM16 -> 0 | AO16: 0
B17: New initiatives and others | D17: -6749.149 | E17: -10854.996 | F17: -38393.895 | G17: -28379.21 | H17: -20166.484 | I17: -7273.314 | J17: -10082.34 | K17: =SUM(AL17:AO17) -> -9924.888 | M17: -2583.124 | N17: -1645.735 | O17: -1201.845 | P17: -1318.445 | Q17: -1363.717 | R17: -1459.539 | S17: -2028.909 | T17: -6002.831 | U17: -8044.445 | V17: -9238.125 | W17: -10906.087 | X17: -10205.238 | Y17: -9024.754 | Z17: -6789.546 | AA17: -6771.36 | AB17: -6365.02 | AC17: -5028.894 | AD17: -5192.922 | AE17: -5111.976 | AF17: =H17-AC17-AD17-AE17 -> -4832.692 | AG17: -2756.899 | AH17: -1314.359 | AI17: -1026.042 | AJ17: =I17-AG17-AH17-AI17 -> -2176.014 | AK17: -2273.267 | AL17: -1881.318 | AM17: -1277.909 | AN17: =J17-AK17-AL17-AM17 -> -4649.846 | AO17: -2115.815
B18: Unallocated items | D18: -390.164 | E18: 4170.796 | F18: -5001.058 | G18: -6943.907 | H18: -5116.976 | I18: -8296.892 | J18: -8054.714 | K18: =SUM(AL18:AO18) -> -9726.665 | M18: -159.193 | N18: -145.533 | O18: -13.637 | P18: -71.801 | Q18: -961.111 | R18: 489.2 | S18: 5196.859 | T18: -554.152 | U18: -586.652 | V18: -124.474 | W18: -3856.721 | X18: -433.211 | Y18: -1610.177 | Z18: -1964.285 | AA18: -1561.711 | AB18: -1581.812 | AC18: -830.455 | AD18: -1232.6 | AE18: -1625.322 | AF18: =H18-AC18-AD18-AE18 -> -1428.599 | AG18: -1732.556 | AH18: -2662.337 | AI18: 128.815 | AJ18: =I18-AG18-AH18-AI18 -> -4030.814 | AK18: -652.103 | AL18: -1613.462 | AM18: -4410.431 | AN18: =J18-AK18-AL18-AM18 -> -1378.718 | AO18: -2324.054
B19: Total | D19: =SUM(D15:D18) -> 2679.86 | E19: =SUM(E15:E18) -> 4330.102 | F19: =SUM(F15:F18) -> -23127.199 | G19: =SUM(G15:G18) -> -5820.448 | H19: =SUM(H15:H18) -> 13415.387 | I19: =SUM(I15:I18) -> 36844.956 | J19: =SUM(J15:J18) -> -25041.137 | K19: =SUM(K15:K18) -> -42077.058 | M19: =SUM(M15:M18) -> -1303.642 | N19: =SUM(N15:N18) -> 1112.578 | O19: =SUM(O15:O18) -> 1447.064 | P19: =SUM(P15:P18) -> 1423.86 | Q19: =SUM(Q15:Q18) -> -1715.53 | R19: =SUM(R15:R18) -> 2174.645 | S19: =SUM(S15:S18) -> 6723.683 | T19: =SUM(T15:T18) -> -2852.696 | ... AO19: =SUM(AO15:AO18) -> -6469.811
B20: Check | D20: =D19-Model!D19 -> -9.094947e-12 | E20: =E19-Model!E19 -> 9.094947e-12 | F20: =F19-Model!F19 -> 0 | G20: =G19-Model!G19 -> 0 | H20: =H19-Model!H19 -> -1.4551915e-11 | I20: =I19-Model!I19 -> 0 | J20: =J19-Model!J19 -> 0 | K20: =K19-Model!K19 -> 0 | M20: =M19-Model!M19 -> 0 | N20: =N19-Model!N19 -> 0 | O20: =O19-Model!O19 -> 0 | P20: =P19-Model!P19 -> -1.4779289e-11 | Q20: =Q19-Model!Q19 -> 2.2737368e-12 | R20: =R19-Model!R19 -> 0 | S20: =S19-Model!S19 -> 0 | T20: =T19-Model!T19 -> -4.0927262e-12 | ... AO20: =AO19-Model!AO19 -> 0
B22: Revenues:
B23: Delivery services | H23: 82190.98 | I23: 98065.26 | J23: 96067.515 | AG23: 21065.057 | AH23: 23021.272 | AI23: 27784.111 | AJ23: 26194.82 | AK23: 25751.44 | AL23: 23655.555 | AM23: 23021.931 | AN23: =J23-AK23-AL23-AM23 -> 23638.589 | AO23: 25005.93
B24: Commission | H24: 76688.543 | I24: 95340.956 | J24: 105476.79 | AG24: 20657.273 | AH24: 22825.278 | AI24: 26889.908 | AJ24: 24968.497 | AL24: 26471.515 | AM24: 28002.842 | AN24: =J24-AK24-AL24-AM24 -> 51002.43
B25: Online marketing services | H25: 40513.216 | I25: 49240.392 | J25: 51920.379 | AG25: 10390.898 | AH25: 12359.848 | AI25: 13539.14 | AJ25: 12950.506 | AL25: 13649.757 | AM25: 14326.536 | AN25: =J25-AK25-AL25-AM25 -> 23944.086
B26: Merchant services | AK26: 36774.287 | AN26: =J26-AK26-AL26-AM26 -> -36774.287 | AO26: 38058.92
B27: Product sales | AK27: 14308.694 | AN27: =J27-AK27-AL27-AM27 -> -14308.694 | AO27: 20972.102
B28: Other services and sales ((including interest revenue) | H28: 77352.215 | I28: 94944.968 | J28: 111390.07 | AG28: 21162.656 | AH28: 24044.679 | AI28: 25364.16 | AJ28: 24373.473 | AK28: 9371.724 | AL28: 28063.653 | AM28: 30136.804 | AN28: =J28-AK28-AL28-AM28 -> 43817.884 | AO28: 7001.954
B29: Total | H29: =SUM(H23:H28) -> 276744.95 | I29: =SUM(I23:I28) -> 337591.58 | J29: =SUM(J23:J28) -> 364854.75 | AG29: =SUM(AG23:AG28) -> 73275.884 | AH29: =SUM(AH23:AH28) -> 82251.077 | AI29: =SUM(AI23:AI28) -> 93577.319 | AJ29: =SUM(AJ23:AJ28) -> 88487.296 | AK29: =SUM(AK23:AK28) -> 86206.145 | AL29: =SUM(AL23:AL28) -> 91840.48 | AM29: =SUM(AM23:AM28) -> 95488.113 | AN29: =SUM(AN23:AN28) -> 91320.008 | AO29: =SUM(AO23:AO28) -> 91038.906
B30: Check | H30: =H29-Model!H7 -> 0 | I30: =I29-Model!I7 -> 0 | J30: =J29-Model!J7 -> 0 | AG30: =AG29-Model!AG7 -> 0 | AH30: =AH29-Model!AH7 -> 0 | AI30: =AI29-Model!AI7 -> 0 | AJ30: =AJ29-Model!AJ7 -> 0 | AK30: =AK29-Model!AK7 -> 0 | AL30: =AL29-Model!AL7 -> 0 | AM30: =AM29-Model!AM7 -> 0 | AN30: =AN29-Model!AN7 -> 0 | AO30: =AO29-Model!AO7 -> 0
B32: Revenues (% Share)
B33: Delivery services | H33: =H23/H$29 -> 0.29699179 | I33: =I23/I$29 -> 0.29048491 | J33: =J23/J$29 -> 0.26330345 | AG33: =AG23/AG$29 -> 0.28747599 | AH33: =AH23/AH$29 -> 0.27989022 | AI33: =AI23/AI$29 -> 0.29691074 | AJ33: =AJ23/AJ$29 -> 0.29602916 | AK33: =AK23/AK$29 -> 0.29871931 | AL33: =AL23/AL$29 -> 0.25757221 | AM33: =AM23/AM$29 -> 0.24109735 | AN33: =AN23/AN$29 -> 0.25885443 | AO33: =AO23/AO$29 -> 0.27467301
B34: Commission | H34: =H24/H$29 -> 0.27710909 | I34: =I24/I$29 -> 0.28241509 | J34: =J24/J$29 -> 0.28909254 | AG34: =AG24/AG$29 -> 0.28191094 | AH34: =AH24/AH$29 -> 0.27750734 | AI34: =AI24/AI$29 -> 0.28735497 | AJ34: =AJ24/AJ$29 -> 0.28217041 | AL34: =AL24/AL$29 -> 0.28823363 | AM34: =AM24/AM$29 -> 0.29325998 | AN34: =AN24/AN$29 -> 0.55850225
B35: Online marketing services | H35: =H25/H$29 -> 0.14639189 | I35: =I25/I$29 -> 0.14585788 | J35: =J25/J$29 -> 0.14230424 | AG35: =AG25/AG$29 -> 0.14180515 | AH35: =AH25/AH$29 -> 0.15026974 | AI35: =AI25/AI$29 -> 0.14468399 | AJ35: =AJ25/AJ$29 -> 0.14635441 | AL35: =AL25/AL$29 -> 0.14862463 | AM35: =AM25/AM$29 -> 0.15003476 | AN35: =AN25/AN$29 -> 0.26219978
B36: Merchant services | AK36: =AK26/AK$29 -> 0.42658545 | AO36: =AO26/AO$29 -> 0.41805116
B37: Productt sales | AK37: =AK27/AK$29 -> 0.1659823 | AO37: =AO27/AO$29 -> 0.23036417
B38: Other services and sales ((including interest revenue) | H38: =H28/H$29 -> 0.27950723 | I38: =I28/I$29 -> 0.28124211 | J38: =J28/J$29 -> 0.30529976 | AG38: =AG28/AG$29 -> 0.28880792 | AH38: =AH28/AH$29 -> 0.29233269 | AI38: =AI28/AI$29 -> 0.2710503 | AJ38: =AJ28/AJ$29 -> 0.27544601 | AK38: =AK28/AK$29 -> 0.10871295 | AL38: =AL28/AL$29 -> 0.30556954 | AM38: =AM28/AM$29 -> 0.31560791 | AN38: =AN28/AN$29 -> 0.47982786 | AO38: =AO28/AO$29 -> 0.076911667
B39: Total | H39: =SUM(H33:H38) -> 1 | I39: =SUM(I33:I38) -> 1 | J39: =SUM(J33:J38) -> 1 | AG39: =SUM(AG33:AG38) -> 1 | AH39: =SUM(AH33:AH38) -> 1 | AI39: =SUM(AI33:AI38) -> 1 | AJ39: =SUM(AJ33:AJ38) -> 1 | AK39: =SUM(AK33:AK38) -> 1 | AL39: =SUM(AL33:AL38) -> 1 | AM39: =SUM(AM33:AM38) -> 1 | AN39: =SUM(AN33:AN38) -> 1.5593843 | AO39: =SUM(AO33:AO38) -> 1
B41: Revenues (% YoY Growth)
B42: Delivery services | I42: =I23/H23-1 -> 0.19313896 | J42: =J23/I23-1 -> -0.020371587 | AK42: =AK23/AG23-1 -> 0.22247189 | AL42: =AL23/AH23-1 -> 0.02755204 | AM42: =AM23/AI23-1 -> -0.1713994 | AN42: =AN23/AJ23-1 -> -0.097585362 | AO42: =AO23/AK23-1 -> -0.028950226
B43: Commission | I43: =I24/H24-1 -> 0.24322294 | J43: =J24/I24-1 -> 0.10631141 | AK43: =AK24/AG24-1 -> -1 | AL43: =AL24/AH24-1 -> 0.15974557 | AM43: =AM24/AI24-1 -> 0.041388539 | AN43: =AN24/AJ24-1 -> 1.0426712
B44: Online marketing services | I44: =I25/H25-1 -> 0.21541553 | J44: =J25/I25-1 -> 0.054426598 | AK44: =AK25/AG25-1 -> -1 | AL44: =AL25/AH25-1 -> 0.10436285 | AM44: =AM25/AI25-1 -> 0.058157017 | AN44: =AN25/AJ25-1 -> 0.84889193
B45: Merchant services | I45: =IFERROR(I26/H26-1,"NM") -> NM | J45: =IFERROR(J26/I26-1,"NM") -> NM | AO45: =AO26/AK26-1 -> 0.034932914
B46: Productt sales | I46: =IFERROR(I27/H27-1,"NM") -> NM | J46: =IFERROR(J27/I27-1,"NM") -> NM | AO46: =AO27/AK27-1 -> 0.46568946
...
