Workbook
Name \A: #REF!
Name \B: #REF!
Name \C: #REF!
Name \L: #REF!
Name \M: #REF!
Name \P: #REF!
Name \Y: #REF!
Name _01_30_04: MonthlyOpStats
Name _01_30_04: MonthlyOpStats
Name _1_30_01: MonthlyOpStats
Name _1_30_01: MonthlyOpStats
Name _1_30_02: MonthlyOpStats
Name _1_30_02: MonthlyOpStats
Name _1_31_01: MonthlyOpStats
Name _1_31_01: MonthlyOpStats
Name _1_31_02: MonthlyOpStats
Name _1_31_02: MonthlyOpStats
Name _12_31_05: MonthlyOpStats
Name _12_31_05: MonthlyOpStats
Name _A: #REF!
Name _A___0: #REF!
Name _B: #REF!
Name _B___0: #REF!
Name _C: #REF!
Name _C___0: #REF!
Name _ent1: [1]Inputs!$J$17
Name _ent10: [1]Inputs!$J$476
Name _ent11: [1]Inputs!$J$527
Name _ent12: [1]Inputs!$J$578
Name _ent13: [1]Inputs!$J$629
Name _ent14: [1]Inputs!$J$680
Name _ent15: [1]Inputs!$J$731
Name _ent2: [1]Inputs!$J$68
Name _ent3: [1]Inputs!$J$119
Name _ent4: [1]Inputs!$J$170
Name _ent5: [1]Inputs!$J$221
Name _ent6: [1]Inputs!$J$272
Name _ent7: [1]Inputs!$J$323
Name _ent8: [1]Inputs!$J$374
Name _ent9: [1]Inputs!$J$425
Name _eps1: [1]Inputs!$P$42
Name _eps10: [1]Inputs!$P$501
Name _eps11: [1]Inputs!$P$552
Name _eps12: [1]Inputs!$P$603
Name _eps13: [1]Inputs!$P$654
Name _eps14: [1]Inputs!$P$705
Name _eps15: [1]Inputs!$P$756
Name _eps2: [1]Inputs!$P$93
Name _eps3: [1]Inputs!$P$144
Name _eps4: [1]Inputs!$P$195
Name _eps5: [1]Inputs!$P$246
Name _eps6: [1]Inputs!$P$297
Name _eps7: [1]Inputs!$P$348
Name _eps8: [1]Inputs!$P$399
Name _eps9: [1]Inputs!$P$450
Name _fye1: [1]Inputs!$E$12
Name _fye10: [1]Inputs!$E$471
Name _fye11: [1]Inputs!$E$522
Name _fye12: [1]Inputs!$E$573
Name _fye13: [1]Inputs!$E$624

Sheet Capitalisation
A1: 2Q25
H3: Exchange rate as at end 2Q25 | I3: =Model!AG$198 -> 0.1396
H4: LTM Average exchange rate 2Q25 | I4: =Model!AG$199 -> 0.13889972
B5: Debt Breakdown as on 30-Jun-2025 | C5: RMB mn | D5: Leverage | E5: USD mn | F5: Leverage
B6: Long-term borrowings | C6: 202966 | E6: =C6*$I3 -> 28334.054 | H6: Cash and Short term investments breakdown as on 30 Jun 2025 | I6: RMB mn
B7: Long-term notes payable | C7: 119338 | E7: =C7*$I3 -> 16659.585 | H7: =B13 -> Cash and Cash Equivalents | I7: =C13 -> 182057
B8: Long-term lease liability | C8: 13328 | E8: =C8*$I3 -> 1860.5888 | H8: Term Deposits | I8: 169423
B9: Short-term borrowings | C9: 58631 | E9: =C9*$I3 -> 8184.8876 | H9: Financial assets at fair value through profit or loss | I9: 18235
B10: Short-term notes payable | C10: 12880 | E10: =C10*$I3 -> 1798.048 | H10: Financial assets at fair value through other comprehensive income | I10: 6604
B11: Short-term lease liability | C11: 5343 | E11: =C11*$I3 -> 745.8828 | H11: Other financial assets | I11: 4125
B12: Total Loans & Borrowings | C12: =SUM(C6:C11) -> 412486 | D12: =C12/C18 -> 1.3483636 | E12: =SUM(E6:E11) -> 57583.046 | F12: =E12/E18 -> 1.3551616 | H12: Total | I12: =SUM(I7:I11) -> 380444
B13: Cash and Cash Equivalents | C13: =Model!AG$113 -> 182057 | E13: =C13*$I3 -> 25415.157
B14: Investments | C14: =Model!AG$114 -> 191783 | E14: =C14*$I3 -> 26772.907
B15: Net debt | C15: =C12-C13-C14 -> 38646 | D15: =C15/C18 -> 0.1263288 | E15: =E12-E13-E14 -> 5394.9816 | F15: =E15/E18 -> 0.1269657
B16: Equity | C16: =Model!AG$118 -> 1202849 | E16: =C16*$I3 -> 167917.72
B17: Total Capitalisation | C17: =C15+C16 -> 1241495 | E17: =E15+E16 -> 173312.7
B18: LTM Adjusted EBITDA | C18: =Model!AG$80 -> 305916 | E18: =C18*I4 -> 42491.645
B19: check | C19: =+C12-Model!AG$112 -> 0
B23: Liquidity at end 2Q25 | C23: RMB mn | D23: USD mn
B24: Cash and Cash Equivalents | C24: =C13 -> 182057 | D24: =C24*I3 -> 25415.157
B25: Investments | C25: =C14 -> 191783 | D25: =C25*I3 -> 26772.907
B26: Total liquidity | C26: =SUM(C24:C25) -> 373840 | D26: =SUM(D24:D25) -> 52188.064
B28: Debt maturity at end-2Q25 | C28: RMB mn | D28: USD mn
B29: 2025 | C29: 56846.22 | D29: =C29*I3 -> 7935.7323
B30: 2026 | C30: 71132.07 | D30: =C30*I3 -> 9930.037
B31: =B30+1 -> 2027 | C31: 897.04 | D31: =C31*I3 -> 125.22678
B32: 2028 and later | C32: =249621.23-SUM(C29:C31) -> 120745.9 | D32: =C32*I3 -> 16856.128
B33: Total | C33: =SUM(C29:C32) -> 249621.23 | D33: =SUM(D29:D32) -> 34847.124
A36: 1Q25
H38: Exchange rate as at end 1Q25 | I38: =Model!AF$198 -> 0.1375
H39: LTM Average exchange rate 1Q25 | I39: =Model!AF$199 -> 0.13878722
B40: Debt Breakdown as on 30-Mar-2025 | C40: RMB mn | D40: Leverage | E40: USD mn | F40: Leverage
B41: Long-term borrowings | C41: 209079 | E41: =C41*$I38 -> 28748.363 | H41: Cash and Short term investments breakdown as on 30 Mar 2025 | I41: RMB mn
B42: Long-term notes payable | C42: 123240 | E42: =C42*$I38 -> 16945.5 | H42: =B48 -> Cash and Cash Equivalents | I42: =C48 -> 205253
B43: Long-term lease liability | C43: 13405 | E43: =C43*$I38 -> 1843.1875 | H43: Term Deposits | I43: 132549
B44: Short-term borrowings | C44: 44151 | E44: =C44*$I38 -> 6070.7625 | H44: Financial assets at fair value through profit or loss | I44: 30212
B45: Short-term notes payable | C45: 9326 | E45: =C45*$I38 -> 1282.325 | H45: Financial assets at fair value through other comprehensive income | I45: 5444
B46: Short-term lease liability | C46: 5442 | E46: =C46*$I38 -> 748.275 | H46: Other financial assets | I46: 4480
B47: Total Loans & Borrowings | C47: =SUM(C41:C46) -> 404643 | D47: =C47/C53 -> 1.3986388 | E47: =SUM(E41:E46) -> 55638.412 | F47: =E47/E53 -> 1.3856668 | H47: Total | I47: =SUM(I42:I46) -> 377938
B48: Cash and Cash Equivalents | C48: =Model!AF$113 -> 205253 | E48: =C48*$I38 -> 28222.288
...

Sheet Model
B1: Tencent | C1: Annual | D1: Annual | E1: Annual | F1: Annual | G1: Annual | H1: Annual | I1: Annual | J1: LTM | L1: Quarters | M1: Quarters | N1: Quarters | O1: Quarters | P1: Quarters | Q1: Quarters | R1: Quarters | S1: Quarters | T1: Quarters | U1: Quarters | V1: Quarters | W1: Quarters | X1: Quarters | Y1: Quarters | Z1: Quarters | AA1: Quarters | AB1: Quarters | AC1: Quarters | AD1: Quarters | AE1: Quarters | AF1: Quarters | AG1: Quarters
B2: (RMB million) | C2: 43465 | D2: 43830 | E2: 44196 | F2: 44561 | G2: 44926 | H2: 45291 | I2: 45657 | J2: =AG2 -> 45838 | L2: 43921 | M2: 44012 | N2: 44104 | O2: 44196 | P2: 44286 | Q2: 44377 | R2: 44469 | S2: 44561 | T2: 44651 | U2: 44742 | V2: 44834 | W2: 44926 | X2: 45016 | Y2: 45107 | Z2: 45199 | AA2: 45291 | AB2: 45382 | AC2: 45473 | AD2: 45565 | AE2: 45657 | AF2: 45747 | AG2: 45838
C3: Act | D3: Act | E3: Act | F3: Act | G3: Act | H3: Act | I3: Act | J3: Act | L3: Act | M3: Act | N3: Act | O3: Act | P3: Act | Q3: Act | R3: Act | S3: Act | T3: Act | U3: Act | V3: Act | W3: Act | X3: Act | Y3: Act | Z3: Act | AA3: Act | AB3: Act | AC3: Act | AD3: Act | AE3: Act | AF3: Act | AG3: Act
C4: FY | D4: FY | E4: FY | F4: FY | G4: FY | H4: FY | I4: FY | J4: FY | L4: 1Q | M4: 2Q | N4: 3Q | O4: 4Q | P4: 1Q | Q4: 2Q | R4: 3Q | S4: 4Q | T4: 1Q | U4: 2Q | V4: 3Q | W4: 4Q | X4: 1Q | Y4: 2Q | Z4: 3Q | AA4: 4Q | AB4: 1Q | AC4: 2Q | AD4: 3Q | AE4: 4Q | AF4: 1Q | AG4: 2Q
B5: INCOME STATEMENT
B6: Revenue | C6: 312694 | D6: 377289 | E6: 482064 | F6: 560118 | G6: 554552 | H6: 609015 | I6: 660257 | J6: =SUM(AD6:AG6) -> 704165 | L6: 108065 | M6: 114883 | N6: 125447 | O6: =E6-SUM(L6:N6) -> 133669 | P6: 135303 | Q6: 138259 | R6: 142368 | S6: =F6-SUM(P6:R6) -> 144188 | T6: 135471 | U6: 134034 | V6: 140093 | W6: =G6-SUM(T6:V6) -> 144954 | X6: 149986 | Y6: 149208 | Z6: 154625 | AA6: =H6-SUM(X6:Z6) -> 155196 | AB6: 159501 | AC6: 161117 | AD6: 167193 | AE6: =I6-SUM(AB6:AD6) -> 172446 | AF6: 180022 | AG6: 184504
B7: % of growth | D7: =(D6/C6)-1 -> 0.20657576 | E7: =(E6/D6)-1 -> 0.27770489 | F7: =(F6/E6)-1 -> 0.16191626 | G7: =(G6/F6)-1 -> -0.0099371918 | H7: =(H6/G6)-1 -> 0.098210808 | I7: =(I6/H6)-1 -> 0.084139143 | J7: =(J6/H6)-1 -> 0.15623589 | P7: =(P6/L6)-1 -> 0.25205201 | Q7: =(Q6/M6)-1 -> 0.20347658 | R7: =(R6/N6)-1 -> 0.13488565 | S7: =(S6/O6)-1 -> 0.078694387 | T7: =(T6/P6)-1 -> 0.0012416576 | U7: =(U6/Q6)-1 -> -0.030558589 | V7: =(V6/R6)-1 -> -0.015979715 | W7: =(W6/S6)-1 -> 0.0053125087 | ... AG7: =(AG6/AC6)-1 -> 0.14515538
B8: Cost of revenues | C8: -170574 | D8: -209756 | E8: -260532 | F8: -314174 | G8: -315806 | H8: -315906 | I8: -311011 | J8: =SUM(AD8:AG8) -> -319178 | L8: -55271 | M8: -61673 | N8: -68800 | O8: =E8-SUM(L8:N8) -> -74788 | P8: -72668 | Q8: -75514 | R8: -79621 | S8: =F8-SUM(P8:R8) -> -86371 | T8: -78397 | U8: -76167 | V8: -78110 | W8: =G8-SUM(T8:V8) -> -83132 | X8: -81804 | Y8: -78368 | Z8: -78102 | AA8: =H8-SUM(X8:Z8) -> -77632 | AB8: -75631 | AC8: -75222 | AD8: -78365 | AE8: =I8-SUM(AB8:AD8) -> -81793 | AF8: -79529 | AG8: -79491
B9: Gross Profit | C9: =C6+C8 -> 142120 | D9: =D6+D8 -> 167533 | E9: =E6+E8 -> 221532 | F9: =F6+F8 -> 245944 | G9: =G6+G8 -> 238746 | H9: =H6+H8 -> 293109 | I9: =I6+I8 -> 349246 | J9: =J6+J8 -> 384987 | L9: =L6+L8 -> 52794 | M9: =M6+M8 -> 53210 | N9: =N6+N8 -> 56647 | O9: =O6+O8 -> 58881 | P9: =P6+P8 -> 62635 | Q9: =Q6+Q8 -> 62745 | R9: =R6+R8 -> 62747 | S9: =S6+S8 -> 57817 | ... AG9: =AG6+AG8 -> 105013
B10: Gross Profit margin | C10: =C9/C6 -> 0.45450185 | D10: =D9/D6 -> 0.44404422 | E10: =E9/E6 -> 0.45954894 | F10: =F9/F6 -> 0.43909319 | G10: =G9/G6 -> 0.43052049 | H10: =H9/H6 -> 0.48128371 | I10: =I9/I6 -> 0.52895463 | J10: =J9/J6 -> 0.54672839 | L10: =L9/L6 -> 0.48853931 | M10: =M9/M6 -> 0.46316687 | N10: =N9/N6 -> 0.45156122 | O10: =O9/O6 -> 0.44049854 | P10: =P9/P6 -> 0.46292396 | Q10: =Q9/Q6 -> 0.45382217 | R10: =R9/R6 -> 0.44073809 | S10: =S9/S6 -> 0.40098344 | ... AG10: =AG9/AG6 -> 0.56916381
B11: Operating expenses:
B12: Interest income | C12: 4569 | D12: 6314 | E12: 6957 | F12: 6650 | G12: 8592 | H12: 13808 | I12: 16004 | J12: =SUM(AD12:AG12) -> 15775 | L12: 1636 | M12: 1749 | N12: 1864 | O12: =E12-SUM(L12:N12) -> 1708 | P12: 1614 | Q12: 1630 | R12: 1703 | S12: =F12-SUM(P12:R12) -> 1703 | T12: 1737 | U12: 1945 | V12: 2328 | W12: =G12-SUM(T12:V12) -> 2582 | X12: 2963 | Y12: 3419 | Z12: 3509 | AA12: =H12-SUM(X12:Z12) -> 3917 | AB12: 4248 | AC12: 3850 | AD12: 3996 | AE12: =I12-SUM(AB12:AD12) -> 3910 | AF12: 3748 | AG12: 4121
B13: Other gains, net | C13: 16714 | D13: 19689 | E13: 57131 | F13: 149467 | G13: 124293 | H13: =4701-6090 -> -1389 | I13: =8002+4187 -> 12189 | J13: =SUM(AD13:AG13) -> 8742 | L13: 4037 | M13: 8607 | N13: 11551 | O13: =E13-SUM(L13:N13) -> 32936 | P13: 19521 | Q13: 20763 | R13: 22984 | S13: =F13-SUM(P13:R13) -> 86199 | T13: 13133 | U13: 4420 | V13: 20886 | W13: =G13-SUM(T13:V13) -> 85854 | X13: =1520-576 -> 944 | Y13: -230 | Z13: 2644 | AA13: =H13-SUM(X13:Z13) -> -4747 | AB13: =656+1031 -> 1687 | AC13: =-654+1484 -> 830 | AD13: =3066+2974 -> 6040 | AE13: =I13-SUM(AB13:AD13) -> 3632 | AF13: =-1397+1407 -> 10 | AG13: =2638-3578 -> -940
B14: Selling and marketing expenses | C14: -24233 | D14: -21396 | E14: -33758 | F14: -40594 | G14: -29229 | H14: -34211 | I14: -36388 | J14: =SUM(AD14:AG14) -> -36972 | L14: -7049 | M14: -7756 | N14: -8920 | O14: =E14-SUM(L14:N14) -> -10033 | P14: -8530 | Q14: -10013 | R14: -10435 | S14: =F14-SUM(P14:R14) -> -11616 | T14: -8058 | U14: -7932 | V14: -7124 | W14: =G14-SUM(T14:V14) -> -6115 | X14: -7018 | Y14: -8310 | Z14: -7912 | AA14: =H14-SUM(X14:Z14) -> -10971 | AB14: -7536 | AC14: -9156 | AD14: -9411 | AE14: =I14-SUM(AB14:AD14) -> -10285 | AF14: -7866 | AG14: -9410
B15: General and administrative expenses | C15: -41522 | D15: -53446 | E15: -67625 | F15: -89847 | G15: -106696 | H15: -103525 | I15: -112761 | J15: =SUM(AD15:AG15) -> -126046 | L15: -14158 | M15: -16499 | N15: -17189 | O15: =E15-SUM(L15:N15) -> -19779 | P15: -18967 | Q15: -22638 | R15: -23862 | S15: =F15-SUM(P15:R15) -> -24380 | T15: -26669 | U15: -26233 | V15: -26480 | W15: =G15-SUM(T15:V15) -> -27314 | X15: -24642 | Y15: -25419 | Z15: -26289 | AA15: =H15-SUM(X15:Z15) -> -27175 | AB15: -24809 | AC15: -27491 | AD15: -29058 | AE15: =I15-SUM(AB15:AD15) -> -31403 | AF15: -33664 | AG15: -31921
B16: Operating profit | C16: =C9+SUM(C12:C15) -> 97648 | D16: =D9+SUM(D12:D15) -> 118694 | E16: =E9+SUM(E12:E15) -> 184237 | F16: =F9+SUM(F12:F15) -> 271620 | G16: =G9+SUM(G12:G15) -> 235706 | H16: =H9+SUM(H12:H15) -> 167792 | I16: =I9+SUM(I12:I15) -> 228290 | J16: =J9+SUM(J12:J15) -> 246486 | L16: =L9+SUM(L12:L15) -> 37260 | M16: =M9+SUM(M12:M15) -> 39311 | N16: =N9+SUM(N12:N15) -> 43953 | O16: =O9+SUM(O12:O15) -> 63713 | P16: =P9+SUM(P12:P15) -> 56273 | Q16: =Q9+SUM(Q12:Q15) -> 52487 | R16: =R9+SUM(R12:R15) -> 53137 | S16: =S9+SUM(S12:S15) -> 109723 | ... AG16: =AG9+SUM(AG12:AG15) -> 66863
B17: Finance costs, net | C17: -4669 | D17: -7613 | E17: -7887 | F17: -7114 | G17: -9352 | H17: -12268 | I17: -11981 | J17: =SUM(AD17:AG17) -> -13844 | L17: -1684 | M17: -2005 | N17: -1945 | O17: =E17-SUM(L17:N17) -> -2253 | P17: -1367 | Q17: -1942 | R17: -1942 | S17: =F17-SUM(P17:R17) -> -1863 | T17: -1935 | U17: -1809 | V17: -1950 | W17: =G17-SUM(T17:V17) -> -3658 | X17: -2650 | Y17: -3291 | Z17: -2784 | AA17: =H17-SUM(X17:Z17) -> -3543 | AB17: -2826 | AC17: -3112 | AD17: -3531 | AE17: =I17-SUM(AB17:AD17) -> -2512 | AF17: -3860 | AG17: -3941
B18: Share of (loss)/profit of associates and joint ventures | C18: 1487 | D18: -1681 | E18: 3672 | F18: -16444 | G18: -16129 | H18: 5800 | I18: 25176 | J18: =SUM(AD18:AG18) -> 24326 | L18: -281 | M18: -295 | N18: 2630 | O18: =E18-SUM(L18:N18) -> 1618 | P18: 1348 | Q18: -3857 | R18: -5668 | S18: =F18-SUM(P18:R18) -> -8267 | T18: -6280 | U18: -4460 | V18: -3697 | W18: =G18-SUM(T18:V18) -> -1692 | X18: 80 | Y18: 1159 | Z18: 2098 | AA18: =H18-SUM(X18:Z18) -> 2463 | AB18: 2186 | AC18: 7718 | AD18: 6019 | AE18: =I18-SUM(AB18:AD18) -> 9253 | AF18: 4581 | AG18: 4473
B19: Profit before income tax | C19: =C16+SUM(C17:C18) -> 94466 | D19: =D16+SUM(D17:D18) -> 109400 | E19: =E16+SUM(E17:E18) -> 180022 | F19: =F16+SUM(F17:F18) -> 248062 | G19: =G16+SUM(G17:G18) -> 210225 | H19: =H16+SUM(H17:H18) -> 161324 | I19: =I16+SUM(I17:I18) -> 241485 | J19: =J16+SUM(J17:J18) -> 256968 | L19: =L16+SUM(L17:L18) -> 35295 | M19: =M16+SUM(M17:M18) -> 37011 | N19: =N16+SUM(N17:N18) -> 44638 | O19: =O16+SUM(O17:O18) -> 63078 | P19: =P16+SUM(P17:P18) -> 56254 | Q19: =Q16+SUM(Q17:Q18) -> 46688 | R19: =R16+SUM(R17:R18) -> 45527 | S19: =S16+SUM(S17:S18) -> 99593 | ... AG19: =AG16+SUM(AG17:AG18) -> 67395
B20: Income tax expenses | C20: -14482 | D20: -13512 | E20: -19897 | F20: -20252 | G20: -21516 | H20: -43276 | I20: -45018 | J20: =SUM(AD20:AG20) -> -45749 | L20: -5892 | M20: -4557 | N20: -5739 | O20: =E20-SUM(L20:N20) -> -3709 | P20: -7246 | Q20: -3666 | R20: -5452 | S20: =F20-SUM(P20:R20) -> -3888 | T20: -5269 | U20: -4568 | V20: -7104 | W20: =G20-SUM(T20:V20) -> -4575 | X20: -11465 | Y20: -11145 | Z20: -11008 | AA20: =H20-SUM(X20:Z20) -> -9658 | AB20: -14169 | AC20: -10168 | AD20: -8900 | AE20: =I20-SUM(AB20:AD20) -> -11781 | AF20: -13717 | AG20: -11351
B21: Net profit/loss | C21: =+C19+C20 -> 79984 | D21: =+D19+D20 -> 95888 | E21: =+E19+E20 -> 160125 | F21: =+F19+F20 -> 227810 | G21: =+G19+G20 -> 188709 | H21: =+H19+H20 -> 118048 | I21: =+I19+I20 -> 196467 | J21: =+J19+J20 -> 211219 | L21: =+L19+L20 -> 29403 | M21: =+M19+M20 -> 32454 | N21: =+N19+N20 -> 38899 | O21: =+O19+O20 -> 59369 | P21: =+P19+P20 -> 49008 | Q21: =+Q19+Q20 -> 43022 | R21: =+R19+R20 -> 40075 | S21: =+S19+S20 -> 95705 | ... AG21: =+AG19+AG20 -> 56044
B22: % margin | C22: =+C21/C6 -> 0.25579001 | D22: =+D21/D6 -> 0.25415 | E22: =+E21/E6 -> 0.33216544 | F22: =+F21/F6 -> 0.40671787 | G22: =+G21/G6 -> 0.3402909 | H22: =+H21/H6 -> 0.19383431 | I22: =+I21/I6 -> 0.2975614 | J22: =+J21/J6 -> 0.29995669 | L22: =+L21/L6 -> 0.27208624 | M22: =+M21/M6 -> 0.2824961 | N22: =+N21/N6 -> 0.31008314 | O22: =+O21/O6 -> 0.44414935 | P22: =+P21/P6 -> 0.36220926 | Q22: =+Q21/Q6 -> 0.31116962 | R22: =+R21/R6 -> 0.28148882 | S22: =+S21/S6 -> 0.66375149 | ... AG22: =+AG21/AG6 -> 0.30375493
B23: Non-controlling interest | C23: 1265 | D23: 2578 | E23: 278 | F23: 2988 | G23: 466 | H23: 2832 | I23: 2394 | J23: =SUM(AD23:AG23) -> 3216 | L23: 507 | M23: -653 | N23: 357 | O23: =E23-SUM(L23:N23) -> 67 | P23: 1241 | Q23: 435 | R23: 565 | S23: =F23-SUM(P23:R23) -> 747 | T23: 320 | U23: 611 | V23: -1101 | W23: =G23-SUM(T23:V23) -> 636 | X23: 556 | Y23: 852 | Z23: 599 | AA23: =H23-SUM(X23:Z23) -> 825 | AB23: 762 | AC23: 736 | AD23: 753 | AE23: =I23-SUM(AB23:AD23) -> 143 | AF23: 1904 | AG23: 416
B24: Net profit/loss attributable to equity holders of the Company | C24: =+C21-C23 -> 78719 | D24: =+D21-D23 -> 93310 | E24: =+E21-E23 -> 159847 | F24: =+F21-F23 -> 224822 | G24: =+G21-G23 -> 188243 | H24: =+H21-H23 -> 115216 | I24: =+I21-I23 -> 194073 | J24: =+J21-J23 -> 208003 | L24: =+L21-L23 -> 28896 | M24: =+M21-M23 -> 33107 | N24: =+N21-N23 -> 38542 | O24: =+O21-O23 -> 59302 | P24: =+P21-P23 -> 47767 | Q24: =+Q21-Q23 -> 42587 | R24: =+R21-R23 -> 39510 | S24: =+S21-S23 -> 94958 | ... AG24: =+AG21-AG23 -> 55628
B26: % of sales or stated otherwise
B27: =B12 -> Interest income | C27: =-C12/C6 -> -0.014611729 | D27: =-D12/D6 -> -0.016735182 | E27: =-E12/E6 -> -0.014431694 | F27: =-F12/F6 -> -0.011872498 | G27: =-G12/G6 -> -0.015493588 | H27: =-H12/H6 -> -0.022672676 | I27: =-I12/I6 -> -0.024239046 | J27: =-J12/J6 -> -0.02240242 | L27: =-L12/L6 -> -0.015139037 | M27: =-M12/M6 -> -0.015224185 | N27: =-N12/N6 -> -0.014858865 | O27: =-O12/O6 -> -0.012777832 | P27: =-P12/P6 -> -0.011928782 | Q27: =-Q12/Q6 -> -0.011789468 | R27: =-R12/R6 -> -0.011961958 | S27: =-S12/S6 -> -0.011810969 | ... AG27: =-AG12/AG6 -> -0.022335559
B28: =B13 -> Other gains, net | C28: =-C13/C6 -> -0.053451617 | D28: =-D13/D6 -> -0.05218546 | E28: =-E13/E6 -> -0.11851331 | F28: =-F13/F6 -> -0.26684913 | G28: =-G13/G6 -> -0.22413227 | H28: =-H13/H6 -> 0.002280732 | I28: =-I13/I6 -> -0.018460993 | J28: =-J13/J6 -> -0.012414704 | L28: =-L13/L6 -> -0.037357146 | M28: =-M13/M6 -> -0.074919701 | N28: =-N13/N6 -> -0.092078726 | O28: =-O13/O6 -> -0.24639969 | P28: =-P13/P6 -> -0.14427618 | Q28: =-Q13/Q6 -> -0.15017467 | R28: =-R13/R6 -> -0.16144077 | S28: =-S13/S6 -> -0.59782367 | ... AG28: =-AG13/AG6 -> 0.0050947405
B29: =B14 -> Selling and marketing expenses | C29: =-C14/C6 -> 0.07749749 | D29: =-D14/D6 -> 0.056709843 | E29: =-E14/E6 -> 0.070028046 | F29: =-F14/F6 -> 0.072474014 | G29: =-G14/G6 -> 0.052707411 | H29: =-H14/H6 -> 0.056174314 | I29: =-I14/I6 -> 0.055111873 | J29: =-J14/J6 -> 0.05250474 | L29: =-L14/L6 -> 0.06522926 | M29: =-M14/M6 -> 0.067512165 | N29: =-N14/N6 -> 0.071105726 | O29: =-O14/O6 -> 0.07505854 | P29: =-P14/P6 -> 0.063043687 | Q29: =-Q14/Q6 -> 0.072422048 | R29: =-R14/R6 -> 0.073295965 | S29: =-S14/S6 -> 0.080561489 | ... AG29: =-AG14/AG6 -> 0.051001604
B30: =B15 -> General and administrative expenses | C30: =-C15/C6 -> 0.13278797 | D30: =-D15/D6 -> 0.14165799 | E30: =-E15/E6 -> 0.1402822 | F30: =-F15/F6 -> 0.16040727 | G30: =-G15/G6 -> 0.19240035 | H30: =-H15/H6 -> 0.1699876 | I30: =-I15/I6 -> 0.1707835 | J30: =-J15/J6 -> 0.17900066 | L30: =-L15/L6 -> 0.13101374 | M30: =-M15/M6 -> 0.14361568 | N30: =-N15/N6 -> 0.13702201 | O30: =-O15/O6 -> 0.14796999 | P30: =-P15/P6 -> 0.14018167 | Q30: =-Q15/Q6 -> 0.16373618 | R30: =-R15/R6 -> 0.16760789 | S30: =-S15/S6 -> 0.16908481 | ... AG30: =-AG15/AG6 -> 0.1730098
B31: =B17 -> Finance costs, net | C31: =-C17/C6 -> 0.014931531 | D31: =-D17/D6 -> 0.020178166 | E31: =-E17/E6 -> 0.016360898 | F31: =-F17/F6 -> 0.012700895 | G31: =-G17/G6 -> 0.016864063 | H31: =-H17/H6 -> 0.020144003 | I31: =-I17/I6 -> 0.018145964 | J31: =-J17/J6 -> 0.019660165 | L31: =-L17/L6 -> 0.015583214 | M31: =-M17/M6 -> 0.017452539 | N31: =-N17/N6 -> 0.015504556 | O31: =-O17/O6 -> 0.016855067 | P31: =-P17/P6 -> 0.01010325 | Q31: =-Q17/Q6 -> 0.014046102 | R31: =-R17/R6 -> 0.013640706 | S31: =-S17/S6 -> 0.012920631 | ... AG31: =-AG17/AG6 -> 0.021359971
B32: =B18 -> Share of (loss)/profit of associates and joint ventures | C32: =-C18/C6 -> -0.0047554478 | D32: =-D18/D6 -> 0.0044554705 | E32: =-E18/E6 -> -0.0076172458 | F32: =-F18/F6 -> 0.0293581 | G32: =-G18/G6 -> 0.029084739 | H32: =-H18/H6 -> -0.009523575 | I32: =-I18/I6 -> -0.038130607 | J32: =-J18/J6 -> -0.034545881 | L32: =-L18/L6 -> 0.0026002869 | M32: =-M18/M6 -> 0.0025678299 | N32: =-N18/N6 -> -0.020965029 | O32: =-O18/O6 -> -0.012104527 | P32: =-P18/P6 -> -0.0099628242 | Q32: =-Q18/Q6 -> 0.027896918 | R32: =-R18/R6 -> 0.039812317 | S32: =-S18/S6 -> 0.057334868 | ... AG32: =-AG18/AG6 -> -0.024243377
B33: Tax % of PBT | C33: =-C20/C19 -> 0.15330383 | D33: =-D20/D19 -> 0.12351005 | E33: =-E20/E19 -> 0.11052538 | F33: =-F20/F19 -> 0.08164088 | G33: =-G20/G19 -> 0.10234748 | H33: =-H20/H19 -> 0.26825519 | I33: =-I20/I19 -> 0.18642152 | J33: =-J20/J19 -> 0.17803384 | L33: =-L20/L19 -> 0.16693583 | M33: =-M20/M19 -> 0.12312556 | N33: =-N20/N19 -> 0.12856759 | O33: =-O20/O19 -> 0.058800216 | P33: =-P20/P19 -> 0.12880862 | Q33: =-Q20/Q19 -> 0.078521247 | R33: =-R20/R19 -> 0.11975311 | S33: =-S20/S19 -> 0.039038888 | ... AG33: =-AG20/AG19 -> 0.16842496
B34: Working capital /sales | C34: =C54/C6 -> 0.040371737 | D34: =D54/D6 -> 3.7106833e-05 | E34: =E54/E6 -> 0.011218427 | F34: =F54/F6 -> 0.031902206 | G34: =G54/G6 -> -0.0061004198 | H34: =H54/H6 -> 0.014640033 | I34: =I54/I6 -> 0.014909346 | J34: =J54/J6 -> 0 | L34: =L54/L6 -> 0 | M34: =M54/M6 -> 0 | N34: =N54/N6 -> 0 | O34: =O54/O6 -> 0.040458147 | P34: =P54/P6 -> 0 | Q34: =Q54/Q6 -> 0 | R34: =R54/R6 -> 0 | S34: =S54/S6 -> 0.12392848 | ... AG34: =AG54/AG6 -> 0
B35: Capex/sales | C35: =-C58/C6 -> 0.063032869 | D35: =-D58/D6 -> 0.06033041 | E35: =-E58/E6 -> 0.070675263 | F35: =-F58/F6 -> 0.051972977 | G35: =-G58/G6 -> 0.04021805 | H35: =-H58/H6 -> 0.034073052 | I35: =-I58/I6 -> 0.094999371 | J35: =-J58/J6 -> 0 | L35: =-L58/L6 -> 0 | M35: =-M58/M6 -> 0.15313841 | N35: =-N58/N6 -> 0 | O35: =-O58/O6 -> 0.12326717 | P35: =-P58/P6 -> 0 | Q35: =-Q58/Q6 -> 0.11383707 | R35: =-R58/R6 -> 0 | S35: =-S58/S6 -> 0.092740034 | ... AG35: =-AG58/AG6 -> 0.067489052
B37: EBITDA | C37: =C2 -> 43465 | D37: =D2 -> 43830 | E37: =E2 -> 44196 | F37: =F2 -> 44561 | G37: =G2 -> 44926 | H37: =H2 -> 45291 | I37: =I2 -> 45657 | J37: =J1 -> LTM | L37: =L2 -> 43921 | M37: =M2 -> 44012 | N37: =N2 -> 44104 | O37: =O2 -> 44196 | P37: =P2 -> 44286 | Q37: =Q2 -> 44377 | R37: =R2 -> 44469 | S37: =S2 -> 44561 | ... AG37: =AG2 -> 45838
B38: Operating profit | C38: =C16 -> 97648 | D38: =D16 -> 118694 | E38: =E16 -> 184237 | F38: =F16 -> 271620 | G38: =G16 -> 235706 | H38: =H16 -> 167792 | I38: =I16 -> 228290 | J38: =J16 -> 246486 | L38: =L16 -> 37260 | M38: =M16 -> 39311 | N38: =N16 -> 43953 | O38: =O16 -> 63713 | P38: =P16 -> 56273 | Q38: =Q16 -> 52487 | R38: =R16 -> 53137 | S38: =S16 -> 109723 | ... AG38: =AG16 -> 66863
B39: Depreciation, depletion & amortization | C39: =8423+25616 -> 34039 | D39: =12574+3049+28954 -> 44577 | E39: =17685+3773+29073 -> 50531 | F39: =21517+4649+31504 -> 57670 | G39: =21724+6720+32772 -> 61216 | H39: =19908+6397+32703 -> 59008 | I39: =21141+6191+28881 -> 56213 | J39: =SUM(AD39:AG39) -> 59629 | L39: 0 | M39: =4257+899+6415 -> 11571 | N39: 0 | O39: =E39-SUM(L39:N39) -> 38960 | P39: =5303+1055+7859 -> 14217 | Q39: =5374+1089+8010 -> 14473 | R39: =5374+1129+7730 -> 14233 | S39: =F39-SUM(P39:R39) -> 14747 | T39: =5686+1636+8614 -> 15936 | U39: =5589+1673+7664 -> 14926 | V39: =5289+1693+7763 -> 14745 | W39: =G39-SUM(T39:V39) -> 15609 | X39: =5073+1599+9462 -> 16134 | Y39: =4908+1704+8195 -> 14807 | Z39: =4810+1550+7142 -> 13502 | AA39: =H39-SUM(X39:Z39) -> 14565 | AB39: =5091+1550+6928 -> 13569 | AC39: =5056+1497+7101 -> 13654 | AD39: =5183+1549+7306 -> 14038 | AE39: =I39-SUM(AB39:AD39) -> 14952 | AF39: =5295+1495+8064 -> 14854 | AG39: =6076+1575+8134 -> 15785
B40: EBITDA | C40: =SUM(C38:C39) -> 131687 | D40: =SUM(D38:D39) -> 163271 | E40: =SUM(E38:E39) -> 234768 | F40: =SUM(F38:F39) -> 329290 | G40: =SUM(G38:G39) -> 296922 | H40: =SUM(H38:H39) -> 226800 | I40: =SUM(I38:I39) -> 284503 | J40: =SUM(J38:J39) -> 306115 | L40: =SUM(L38:L39) -> 37260 | M40: =SUM(M38:M39) -> 50882 | N40: =SUM(N38:N39) -> 43953 | O40: =SUM(O38:O39) -> 102673 | P40: =SUM(P38:P39) -> 70490 | Q40: =SUM(Q38:Q39) -> 66960 | R40: =SUM(R38:R39) -> 67370 | S40: =SUM(S38:S39) -> 124470 | ... AG40: =SUM(AG38:AG39) -> 82648
B41: % growth | D41: =+D40/C40-1 -> 0.23984144 | E41: =+E40/D40-1 -> 0.43790385 | F41: =+F40/E40-1 -> 0.40261876 | G41: =+G40/F40-1 -> -0.098296335 | H41: =+H40/G40-1 -> -0.23616303 | I41: =+I40/H40-1 -> 0.2544224 | P41: =P40/L40-1 -> 0.89184112 | Q41: =Q40/M40-1 -> 0.31598601 | R41: =R40/N40-1 -> 0.53277364 | S41: =S40/O40-1 -> 0.21229535 | T41: =T40/P40-1 -> -0.24594978 | U41: =U40/Q40-1 -> -0.32806153 | V41: =V40/R40-1 -> -0.015318391 | W41: =W40/S40-1 -> 0.064015425 | ... AG41: =AG40/AC40-1 -> 0.22292918
B42: % margin | C42: =+C40/C6 -> 0.42113696 | D42: =+D40/D6 -> 0.43274784 | E42: =+E40/E6 -> 0.48700587 | F42: =+F40/F6 -> 0.58789398 | G42: =+G40/G6 -> 0.53542679 | H42: =+H40/H6 -> 0.37240462 | I42: =+I40/I6 -> 0.43089736 | J42: =+J40/J6 -> 0.43472056 | L42: =+L40/L6 -> 0.34479249 | M42: =+M40/M6 -> 0.44290278 | N42: =+N40/N6 -> 0.35037107 | O42: =+O40/O6 -> 0.76811377 | P42: =+P40/P6 -> 0.52097884 | Q42: =+Q40/Q6 -> 0.48430844 | R42: =+R40/R6 -> 0.47321027 | S42: =+S40/S6 -> 0.86324798 | ... AG42: =+AG40/AG6 -> 0.44794693
...

Sheet PB_CACHE
A1: H4sIAAAAAAAEAM2Q30rDMBTGu1Wxog+Re0toZ+fcRW+souAuJh3ejDHTcLBhaVLzR+gewxfWpHR64YW3nkDOSeD7nY8vGAVB8OnKd1/nY3c9LZmh9Y2UO7TqWtBowSpFVBejZ1CaSZFPkkmKM5ziJEaF5cYqyAVYowiP0dJWnNFH6FZyByIXlvNjzy+/sdseux2wuATFCGd7UnEoCK3h98/FSrYLeAfev24ZNc6G04aOezK4igrZtESBih6Irku2hyAMoo9R2WkDDS4k59DrNL4H4TbQQ797s26b6Q6Al3S9HlSlUUy8xqjRVCrOqp8MMpz483cA1WxGpnR6lc4vM0iu55tNNB7iPg2H4cgP/9GqN3f2BRsfF+InAgAA

Sheet KPIs
B1: =Model!B1 -> Tencent | C1: Annual | D1: Annual | E1: Annual | F1: Annual | G1: Annual | H1: Annual | I1: Annual | J1: LTM | L1: Quarters | M1: Quarters | N1: Quarters | O1: Quarters | P1: Quarters | Q1: Quarters | R1: Quarters | S1: Quarters | T1: Quarters | U1: Quarters | V1: Quarters | W1: Quarters | X1: Quarters | Y1: Quarters | Z1: Quarters | AA1: Quarters | AB1: Quarters | AC1: Quarters | AD1: Quarters | AE1: Quarters | AF1: Quarters | AG1: Quarters
B2: =Model!B2 -> (RMB million) | C2: 43465 | D2: 43830 | E2: 44196 | F2: 44561 | G2: 44926 | H2: 45291 | I2: 45657 | J2: =AG2 -> 45838 | L2: 43921 | M2: 44012 | N2: 44104 | O2: 44196 | P2: 44286 | Q2: 44377 | R2: 44469 | S2: 44561 | T2: 44651 | U2: 44742 | V2: 44834 | W2: 44926 | X2: 45016 | Y2: 45107 | Z2: 45199 | AA2: 45291 | AB2: 45382 | AC2: 45473 | AD2: 45565 | AE2: 45657 | AF2: 45747 | AG2: 45838
C3: Act | D3: Act | E3: Act | F3: Act | G3: Act | H3: Act | I3: Act | J3: Act | L3: Act | M3: Act | N3: Act | O3: Act | P3: Act | Q3: Act | R3: Act | S3: Act | T3: Act | U3: Act | V3: Act | W3: Act | X3: Act | Y3: Act | Z3: Act | AA3: Act | AB3: Act | AC3: Act | AD3: Act | AE3: Act | AF3: Act | AG3: Act
C4: FY | D4: FY | E4: FY | F4: FY | G4: FY | H4: FY | I4: FY | J4: FY | L4: 1Q | M4: 2Q | N4: 3Q | O4: 4Q | P4: 1Q | Q4: 2Q | R4: 3Q | S4: 4Q | T4: 1Q | U4: 2Q | V4: 3Q | W4: 4Q | X4: 1Q | Y4: 2Q | Z4: 3Q | AA4: 4Q | AB4: 1Q | AC4: 2Q | AD4: 3Q | AE4: 4Q | AF4: 1Q | AG4: 2Q
B5: Revenue
B6: VAS | C6: 176646 | D6: 199991 | E6: 264212 | F6: 291572 | G6: 287565 | H6: 298375 | I6: 319168 | J6: =SUM(AD6:AG6) -> 345218 | L6: 62429 | M6: 65002 | N6: 69802 | O6: =E6-SUM(L6:N6) -> 66979 | P6: 72443 | Q6: 72013 | R6: 75203 | S6: =F6-SUM(P6:R6) -> 71913 | T6: 72738 | U6: 71683 | V6: 72727 | W6: =G6-SUM(T6:V6) -> 70417 | X6: 79337 | Y6: 74211 | Z6: 75748 | AA6: =H6-SUM(X6:Z6) -> 69079 | AB6: 78629 | AC6: 78822 | AD6: 82695 | AE6: =I6-SUM(AB6:AD6) -> 79022 | AF6: 92133 | AG6: 91368
B7: Online Advertising | C7: 58079 | D7: 101355 | E7: 82271 | F7: 88666 | G7: 82729 | H7: 101482 | I7: 121374 | J7: =SUM(AD7:AG7) -> 132612 | L7: 17713 | M7: 18552 | N7: 21351 | O7: =E7-SUM(L7:N7) -> 24655 | P7: 21820 | Q7: 22833 | R7: 22495 | S7: =F7-SUM(P7:R7) -> 21518 | T7: 17988 | U7: 18638 | V7: 21443 | W7: =G7-SUM(T7:V7) -> 24660 | X7: 20964 | Y7: 25003 | Z7: 25721 | AA7: =H7-SUM(X7:Z7) -> 29794 | AB7: 26506 | AC7: 29871 | AD7: 29993 | AE7: =I7-SUM(AB7:AD7) -> 35004 | AF7: 31853 | AG7: 35762
B8: FinTech and Business Services | C8: 73138 | D8: 68377 | E8: 128086 | F8: 172195 | G8: 177064 | H8: 203763 | I8: 211956 | J8: =SUM(AD8:AG8) -> 219657 | L8: 26475 | M8: 29862 | N8: 33255 | O8: =E8-SUM(L8:N8) -> 38494 | P8: 39028 | Q8: 41892 | R8: 43317 | S8: =F8-SUM(P8:R8) -> 47958 | T8: 42768 | U8: 42208 | V8: 44844 | W8: =G8-SUM(T8:V8) -> 47244 | X8: 48701 | Y8: 48635 | Z8: 52048 | AA8: =H8-SUM(X8:Z8) -> 54379 | AB8: 52302 | AC8: 50440 | AD8: 53089 | AE8: =I8-SUM(AB8:AD8) -> 56125 | AF8: 54907 | AG8: 55536
B9: Others | C9: 4831 | D9: 7566 | E9: 7495 | F9: 7685 | G9: 7194 | H9: 5395 | I9: 7759 | J9: =SUM(AD9:AG9) -> 6678 | L9: 1448 | M9: 1467 | N9: 1039 | O9: =E9-SUM(L9:N9) -> 3541 | P9: 2012 | Q9: 1521 | R9: 1353 | S9: =F9-SUM(P9:R9) -> 2799 | T9: 1977 | U9: 1505 | V9: 1079 | W9: =G9-SUM(T9:V9) -> 2633 | X9: 984 | Y9: 1359 | Z9: 1108 | AA9: =H9-SUM(X9:Z9) -> 1944 | AB9: 2064 | AC9: 1984 | AD9: 1416 | AE9: =I9-SUM(AB9:AD9) -> 2295 | AF9: 1129 | AG9: 1838
B10: Total Revenue | C10: =SUM(C6:C9) -> 312694 | D10: =SUM(D6:D9) -> 377289 | E10: =SUM(E6:E9) -> 482064 | F10: =SUM(F6:F9) -> 560118 | G10: =SUM(G6:G9) -> 554552 | H10: =SUM(H6:H9) -> 609015 | I10: =SUM(I6:I9) -> 660257 | J10: =SUM(J6:J9) -> 704165 | L10: =SUM(L6:L9) -> 108065 | M10: =SUM(M6:M9) -> 114883 | N10: =SUM(N6:N9) -> 125447 | O10: =SUM(O6:O9) -> 133669 | P10: =SUM(P6:P9) -> 135303 | Q10: =SUM(Q6:Q9) -> 138259 | R10: =SUM(R6:R9) -> 142368 | S10: =SUM(S6:S9) -> 144188 | ... AG10: =SUM(AG6:AG9) -> 184504
B11: Check | C11: =C10-Model!C6 -> 0 | D11: =D10-Model!D6 -> 0 | E11: =E10-Model!E6 -> 0 | F11: =F10-Model!F6 -> 0 | G11: =G10-Model!G6 -> 0 | H11: =H10-Model!H6 -> 0 | I11: =I10-Model!I6 -> 0 | J11: =J10-Model!J6 -> 0 | L11: =L10-Model!L6 -> 0 | M11: =M10-Model!M6 -> 0 | N11: =N10-Model!N6 -> 0 | O11: =O10-Model!O6 -> 0 | P11: =P10-Model!P6 -> 0 | Q11: =Q10-Model!Q6 -> 0 | R11: =R10-Model!R6 -> 0 | S11: =S10-Model!S6 -> 0 | ... AG11: =AG10-Model!AG6 -> 0
B13: Value Added Services Revenue
B14: Social Networks | C14: 72654 | D14: 85281 | E14: 108111 | F14: 117258 | G14: 116850 | H14: 118500 | I14: 121500 | J14: =SUM(AD14:AG14) -> 125500 | L14: 25100 | M14: 26700 | N14: 28400 | O14: =E14-SUM(L14:N14) -> 27911 | P14: 28800 | Q14: 29000 | R14: 30300 | S14: =F14-SUM(P14:R14) -> 29158 | T14: 29100 | U14: 29200 | V14: 29800 | W14: =G14-SUM(T14:V14) -> 28750 | X14: 31000 | Y14: 29700 | Z14: 29700 | AA14: =H14-SUM(X14:Z14) -> 28100 | AB14: 30500 | AC14: 30300 | AD14: 30900 | AE14: =I14-SUM(AB14:AD14) -> 29800 | AF14: 32600 | AG14: 32200
B15: Domestic Games | C15: 103992 | D15: 114710 | E15: 156101 | F15: =174314-F16 -> 128814 | G15: =170715-G16 -> 123915 | H15: 126700 | I15: 139700 | J15: =SUM(AD15:AG15) -> 153900 | L15: 37300 | M15: 38300 | N15: 31900 | O15: =E15-SUM(L15:N15) -> 48601 | P15: 33500 | Q15: 32100 | R15: 33600 | S15: =F15-SUM(P15:R15) -> 29614 | T15: 33000 | U15: 31800 | V15: 31200 | W15: =G15-SUM(T15:V15) -> 27915 | X15: 35100 | Y15: 31800 | Z15: 32700 | AA15: =H15-SUM(X15:Z15) -> 27100 | AB15: 34500 | AC15: 34600 | AD15: 37300 | AE15: =I15-SUM(AB15:AD15) -> 33300 | AF15: 42900 | AG15: 40400
B16: International Games | F16: 45500 | G16: 46800 | H16: 53200 | I16: 58000 | J16: =SUM(AD16:AG16) -> 65900 | N16: 9500 | O16: =E16-SUM(L16:N16) -> -9500 | P16: 10100 | Q16: 10900 | R16: 11300 | S16: =F16-SUM(P16:R16) -> 13200 | T16: 10600 | U16: 10700 | V16: 11700 | W16: =G16-SUM(T16:V16) -> 13800 | X16: 13200 | Y16: 12700 | Z16: 13300 | AA16: =H16-SUM(X16:Z16) -> 14000 | AB16: 13600 | AC16: 13900 | AD16: 14500 | AE16: =I16-SUM(AB16:AD16) -> 16000 | AF16: 16600 | AG16: 18800
B17: Total VAS Revenue | C17: =SUM(C14:C16) -> 176646 | D17: =SUM(D14:D16) -> 199991 | E17: =SUM(E14:E16) -> 264212 | F17: =SUM(F14:F16) -> 291572 | G17: =SUM(G14:G16) -> 287565 | H17: =SUM(H14:H16) -> 298400 | I17: =SUM(I14:I16) -> 319200 | J17: =SUM(J14:J16) -> 345300 | L17: =SUM(L14:L16) -> 62400 | M17: =SUM(M14:M16) -> 65000 | N17: =SUM(N14:N16) -> 69800 | O17: =SUM(O14:O16) -> 67012 | P17: =SUM(P14:P16) -> 72400 | Q17: =SUM(Q14:Q16) -> 72000 | R17: =SUM(R14:R16) -> 75200 | S17: =SUM(S14:S16) -> 71972 | ... AG17: =SUM(AG14:AG16) -> 91400
B19: Revenue by segment (%)
B20: Social Networks | C20: =C14/C$10 -> 0.23234856 | D20: =D14/D$10 -> 0.22603627 | E20: =E14/E$10 -> 0.2242669 | F20: =F14/F$10 -> 0.20934517 | G20: =G14/G$10 -> 0.21071063 | H20: =H14/H$10 -> 0.19457649 | I20: =I14/I$10 -> 0.18401925 | J20: =J14/J$10 -> 0.17822527 | L20: =L14/L$10 -> 0.23226762 | M20: =M14/M$10 -> 0.23241037 | N20: =N14/N$10 -> 0.22639043 | O20: =O14/O$10 -> 0.20880683 | P20: =P14/P$10 -> 0.21285559 | Q20: =Q14/Q$10 -> 0.20975126 | R20: =R14/R$10 -> 0.21282873 | S20: =S14/S$10 -> 0.2022221 | ... AG20: =AG14/AG$10 -> 0.17452196
B21: Domestic Games | C21: =C15/C$10 -> 0.33256794 | D21: =D15/D$10 -> 0.30403749 | E21: =E15/E$10 -> 0.323818 | F21: =F15/F$10 -> 0.22997654 | G21: =G15/G$10 -> 0.22345064 | H21: =H15/H$10 -> 0.20804085 | I21: =I15/I$10 -> 0.21158428 | J21: =J15/J$10 -> 0.21855673 | L21: =L15/L$10 -> 0.34516263 | M21: =M15/M$10 -> 0.33338266 | N21: =N15/N$10 -> 0.25429066 | O21: =O15/O$10 -> 0.36359216 | P21: =P15/P$10 -> 0.24759244 | Q21: =Q15/Q$10 -> 0.23217295 | R21: =R15/R$10 -> 0.23600809 | S21: =S15/S$10 -> 0.20538464 | ... AG21: =AG15/AG$10 -> 0.21896544
B22: International Games | C22: =C16/C$10 -> 0 | D22: =D16/D$10 -> 0 | E22: =E16/E$10 -> 0 | F22: =F16/F$10 -> 0.081232883 | G22: =G16/G$10 -> 0.084392447 | H22: =H16/H$10 -> 0.08735417 | I22: =I16/I$10 -> 0.087844582 | J22: =J16/J$10 -> 0.09358602 | L22: =L16/L$10 -> 0 | M22: =M16/M$10 -> 0 | N22: =N16/N$10 -> 0.075729192 | O22: =O16/O$10 -> -0.071071079 | P22: =P16/P$10 -> 0.074647273 | Q22: =Q16/Q$10 -> 0.078837544 | R22: =R16/R$10 -> 0.079371769 | S22: =S16/S$10 -> 0.091547147 | ... AG22: =AG16/AG$10 -> 0.10189481
B23: Online Advertising | C23: =C7/C$10 -> 0.18573749 | D23: =D7/D$10 -> 0.26864022 | E23: =E7/E$10 -> 0.17066406 | F23: =F7/F$10 -> 0.15829879 | G23: =G7/G$10 -> 0.14918168 | H23: =H7/H$10 -> 0.16663301 | I23: =I7/I$10 -> 0.18382842 | J23: =J7/J$10 -> 0.18832518 | L23: =L7/L$10 -> 0.16391061 | M23: =M7/M$10 -> 0.16148603 | N23: =N7/N$10 -> 0.17019937 | O23: =O7/O$10 -> 0.18444815 | P23: =P7/P$10 -> 0.16126767 | Q23: =Q7/Q$10 -> 0.16514657 | R23: =R7/R$10 -> 0.15800601 | S23: =S7/S$10 -> 0.14923572 | ... AG23: =AG7/AG$10 -> 0.19382778
B24: FBS | C24: =C8/C$10 -> 0.2338964 | D24: =D8/D$10 -> 0.18123242 | E24: =E8/E$10 -> 0.26570331 | F24: =F8/F$10 -> 0.30742629 | G24: =G8/G$10 -> 0.31929197 | H24: =H8/H$10 -> 0.33457797 | I24: =I8/I$10 -> 0.32102045 | J24: =J8/J$10 -> 0.31193967 | L24: =L8/L$10 -> 0.24499144 | M24: =M8/M$10 -> 0.25993402 | N24: =N8/N$10 -> 0.26509203 | O24: =O8/O$10 -> 0.28798001 | P24: =P8/P$10 -> 0.28844889 | Q24: =Q8/Q$10 -> 0.30299655 | R24: =R8/R$10 -> 0.30426079 | S24: =S8/S$10 -> 0.33260743 | ... AG24: =AG8/AG$10 -> 0.3010016
B25: Others | C25: =C9/C$10 -> 0.015449609 | D25: =D9/D$10 -> 0.020053593 | E25: =E9/E$10 -> 0.015547728 | F25: =F9/F$10 -> 0.013720323 | G25: =G9/G$10 -> 0.012972634 | H25: =H9/H$10 -> 0.0088585667 | I25: =I9/I$10 -> 0.011751485 | J25: =J9/J$10 -> 0.0094835727 | L25: =L9/L$10 -> 0.013399343 | M25: =M9/M$10 -> 0.012769513 | N25: =N9/N$10 -> 0.0082823822 | O25: =O9/O$10 -> 0.026490809 | P25: =P9/P$10 -> 0.014870328 | Q25: =Q9/Q$10 -> 0.011001092 | R25: =R9/R$10 -> 0.0095035401 | S25: =S9/S$10 -> 0.019412156 | ... AG25: =AG9/AG$10 -> 0.0099618436
B27: Capital Expenditure
B28: Operating CAPEX | C28: 19330 | D28: 20538 | E28: 29569 | F28: 26100 | G28: 10200 | H28: 17200 | I28: 63400 | J28: =SUM(AD28:AG28) -> 93900 | L28: 5469 | M28: 8286 | N28: 7800 | O28: =E28-SUM(L28:N28) -> 8014 | P28: 6581 | Q28: 5900 | R28: 5600 | S28: =F28-SUM(P28:R28) -> 8019 | T28: 5200 | U28: 2100 | V28: 1100 | W28: =G28-SUM(T28:V28) -> 1800 | X28: 1000 | Y28: 3000 | Z28: 6600 | AA28: =H28-SUM(X28:Z28) -> 6600 | AB28: 6600 | AC28: 7200 | AD28: 14700 | AE28: =I28-SUM(AB28:AD28) -> 34900 | AF28: 26400 | AG28: 17900
B29: Non-operating CAPEX | C29: 4611 | D29: 11831 | E29: 4391 | F29: 7300 | G29: 7800 | H29: 6700 | I29: 13400 | J29: =SUM(AD29:AG29) -> 6400 | L29: 682 | M29: 1180 | N29: 900 | O29: =E29-SUM(L29:N29) -> 1629 | P29: 1153 | Q29: 1000 | R29: 1500 | S29: =F29-SUM(P29:R29) -> 3647 | T29: 1800 | U29: 900 | V29: 1300 | W29: =G29-SUM(T29:V29) -> 3800 | X29: 3400 | Y29: 1000 | Z29: 1400 | AA29: =H29-SUM(X29:Z29) -> 900 | AB29: 7800 | AC29: 1500 | AD29: 2400 | AE29: =I29-SUM(AB29:AD29) -> 1700 | AF29: 1100 | AG29: 1200
B30: Total CAPEX | C30: =SUM(C28:C29) -> 23941 | D30: =SUM(D28:D29) -> 32369 | E30: =SUM(E28:E29) -> 33960 | F30: =SUM(F28:F29) -> 33400 | G30: =SUM(G28:G29) -> 18000 | H30: =SUM(H28:H29) -> 23900 | I30: =SUM(I28:I29) -> 76800 | J30: =SUM(J28:J29) -> 100300 | L30: =SUM(L28:L29) -> 6151 | M30: =SUM(M28:M29) -> 9466 | N30: =SUM(N28:N29) -> 8700 | O30: =SUM(O28:O29) -> 9643 | P30: =SUM(P28:P29) -> 7734 | Q30: =SUM(Q28:Q29) -> 6900 | R30: =SUM(R28:R29) -> 7100 | S30: =SUM(S28:S29) -> 11666 | ... AG30: =SUM(AG28:AG29) -> 19100
B32: Operating Metrics
B33: Combined MAU of Weixin and WeChat | C33: 1097.6 | D33: 1164.8 | E33: 1225 | F33: 1268.2 | G33: 1313.2 | H33: 1343 | I33: 1385 | J33: =AG33 -> 1411 | L33: 1202.5 | M33: 1206.1 | N33: 1212.8 | O33: =E33 -> 1225 | P33: 1241.6 | Q33: 1251.4 | R33: 1262.6 | S33: =F33 -> 1268.2 | T33: 1288.3 | U33: 1299.1 | V33: 1308.9 | W33: =G33 -> 1313.2 | X33: 1319 | Y33: 1327 | Z33: 1336 | AA33: =H33 -> 1343 | AB33: 1359 | AC33: 1371 | AD33: 1382 | AE33: =I33 -> 1385 | AF33: 1402 | AG33: 1411
B34: Mobile device MAU of QQ | C34: 699.8 | D34: 647 | E34: 594.9 | F34: 552.1 | G34: 572.1 | H34: 554 | I34: 524 | J34: =AG34 -> 532 | L34: 693.5 | M34: 647.6 | N34: 617.4 | O34: =E34 -> 594.9 | P34: 606.4 | Q34: 590.9 | R34: 573.7 | S34: =F34 -> 552.1 | T34: 563.8 | U34: 568.7 | V34: 574.4 | W34: =G34 -> 572.1 | X34: 597 | Y34: 571 | Z34: 558 | AA34: =H34 -> 554 | AB34: 553 | AC34: 571 | AD34: 562 | AE34: =I34 -> 524 | AF34: 534 | AG34: 532
B35: Fee-based VAS registered subscriptions | C35: 160.3 | D35: 180.1 | E35: 219.5 | F35: 236.3 | G35: 233.8 | H35: 244 | I35: 262 | J35: =AG35 -> 264 | L35: 197.4 | M35: 203.4 | N35: 213.4 | O35: =E35 -> 219.5 | P35: 225.7 | Q35: 229.4 | R35: 235.4 | S35: =F35 -> 236.3 | T35: 239.1 | U35: 234.7 | V35: 228.7 | W35: =G35 -> 233.8 | X35: 233 | Y35: 241 | Z35: 243 | AA35: =H35 -> 244 | AB35: 260 | AC35: 263 | AD35: 265 | AE35: =I35 -> 262 | AF35: 268 | AG35: 264
B37: ARPU
B38: Domestic Games
B39: PC Client Games - ARPU range | C39: - | D39: - | E39: - | F39: - | G39: - | H39: - | I39: - | J39: =AG39 -> 465-475 | L39: 410-420 | M39: 410-420 | N39: 445-455 | O39: 435-445 | P39: 390-400 | Q39: 425-435 | R39: 425-435 | S39: 465-575 | T39: 505-515 | U39: 495-505 | V39: 475-485 | W39: 455-465 | X39: 530-540 | Y39: 555-565 | Z39: 505-515 | AA39: 485-495 | AB39: 430-440 | AC39: 450-460 | AD39: 425-435 | AE39: 425-435 | AF39: 485-495 | AG39: 465-475
B40: Mobile Games - ARPU range | C40: - | D40: - | E40: - | F40: - | G40: - | H40: - | I40: - | J40: =AG40 -> 280-290 | L40: 190-200 | M40: 220-230 | N40: 230-240 | O40: 220-230 | P40: 215-225 | Q40: 255-265 | R40: 255-265 | S40: 240-250 | T40: 245-255 | U40: 275-285 | V40: 275-285 | W40: 225-235 | X40: 255-265 | Y40: 285-295 | Z40: 285-295 | AA40: 225-235 | AB40: 235-245 | AC40: 275-285 | AD40: 295-305 | AE40: 275-285 | AF40: 270-280 | AG40: 280-290
B42: Registered monthly subscriptions
B43: Fee-based VAS registered subscriptions | C43: - | D43: - | E43: - | F43: - | G43: - | H43: - | I43: - | J43: =AG43 -> 264 | L43: 197.39976 | M43: 203.42728 | N43: 213.35465 | O43: 219.45812 | P43: 225.7 | Q43: 229.4 | R43: 235.4 | S43: 236 | T43: 239.1 | U43: 235 | V43: 229 | W43: 234 | X43: 226 | Y43: 241 | Z43: 245 | AA43: =AA35 -> 244 | AB43: 260 | AC43: 263 | AD43: 265 | AE43: 262 | AF43: 268 | AG43: 264
B44: Online video subscriptions | C44: - | D44: - | E44: - | F44: - | G44: - | H44: - | I44: - | J44: =AG44 -> 114 | L44: 112 | M44: 114.3 | N44: 120.1 | O44: 123.4 | P44: 125.5 | Q44: 124.5 | R44: 129.3 | S44: 124 | T44: 124 | U44: 122 | V44: 120 | W44: 119 | X44: 113 | Y44: 115 | Z44: 117 | AA44: 117 | AB44: 116 | AC44: 117 | AD44: 116 | AE44: 113 | AF44: 117 | AG44: 114
B45: Online music subscriptions | C45: - | D45: - | E45: - | F45: - | G45: - | H45: - | I45: - | J45: =AG45 -> 124 | L45: 42.7 | M45: 47.1 | N45: 51.7 | O45: 56 | P45: 60.9 | Q45: 66.2 | R45: 71.2 | S45: 76 | T45: 80 | U45: 83 | V45: 85 | W45: 89 | X45: 94 | Y45: 100 | Z45: 103 | AA45: 107 | AB45: 114 | AC45: 117 | AD45: 119 | AE45: 121 | AF45: 123 | AG45: 124
B47: Number of Employees | J47: =AG47 -> 111221 | L47: 64238 | M47: 70756 | N47: 77592 | O47: 85858 | P47: 89228 | Q47: 94182 | R47: 107348 | S47: 112771 | T47: 116213 | U47: 110715 | V47: 108836 | W47: 108436 | X47: 106221 | Y47: 104503 | Z47: 105309 | AA47: 105417 | AB47: 104787 | AC47: 105506 | AD47: 108823 | AE47: 110558 | AF47: 109414 | AG47: 111221
