Workbook
Name IQ_CH: 110000
Name IQ_CQ: 5000
Name IQ_CY: 10000
Name IQ_DAILY: 500000
Name IQ_FH: 100000
Name IQ_FQ: 500
Name IQ_FY: 1000
Name IQ_LTM: 2000
Name IQ_MONTH: 15000
Name IQ_NTM: 6000
Name IQ_WEEK: 50000
Name IQ_YTD: 3000

Sheet Capitalisation
A2: 1Q26 | I2: Exchange rate as at end | J2: =Model!$P$215 -> 0.022495315
I3: LTM Average exchange rate | J3: =Model!$P$216 -> 0.024213722
B5: Debt Breakdown as on 31-Mar-2026 | C5: TRY mn | D5: USD mn | E5: Leverage (TRY) | F5: Leverage (USD) | I5: Company reported | J5: Leverage
B6: Short-term debt | C6: =SUM(C7:C8) -> 17384.16 | D6: =SUM(D7:D8) -> 391.06216 | I6: Net Debt/Ebitda | J6: 1.33
B7: Loans | C7: =Model!BC$111-C8 -> 17384.16 | D7: =C7*$J2 -> 391.06216
B8: Lease Liabilities | C8: =Model!BB$116 -> 0 | D8: =C8*$J2 -> 0
B10: Long-term debt | C10: =SUM(C11:C12) -> 40868.248 | D10: =SUM(D11:D12) -> 919.34413
B11: Loans | C11: =Model!BC$112 -> 40868.248 | D11: =C11*$J2 -> 919.34413
B12: Lease Liabilities | C12: =Model!BB$117 -> 0 | D12: =C12*$J2 -> 0
B13: Total Loans & Borrowings | C13: =C6+C10 -> 58252.408 | D13: =D6+D10 -> 1310.4063 | E13: =C13/C20 -> 3.2252547 | F13: =D13/D20 -> 2.9963638
B14: Cash | C14: =Model!BC$125 -> 17161.084 | D14: =C14*$J2 -> 386.044
B15: Net debt exc investments | C15: =C13-C14 -> 41091.324 | D15: =D13-D14 -> 924.36229 | E15: =C15/C20 -> 2.2750988 | F15: =D15/D20 -> 2.1136389
B16: Short term financial investments | C16: =Model!BC$126 -> 6.614 | D16: =C16*$J2 -> 0.14878402
B17: Net debt | C17: =C15-C16 -> 41084.71 | D17: =D15-D16 -> 924.21351 | E17: =C17/C20 -> 2.2747326 | F17: =D17/D20 -> 2.1132987
B18: Equity | C18: =Model!BC$133 -> 51814.711 | D18: =C18*J2 -> 1165.5883
B19: Total Capitalisation | C19: =C18+C17 -> 92899.421 | D19: =D18+D17 -> 2089.8018
B20: LTM Adjusted EBITDA | C20: =Model!BC$90 -> 18061.336 | D20: =C20*$J3 -> 437.33217
B21: check | C21: =+C13-Model!BC$123 -> 0
B24: Cash and cash equivalents | C24: TL mn | D24: USD mn
B25: Cash on hand | C25: 7.281 | D25: =C25*$J2 -> 0.16378839
B26: Demand deposits | C26: 1646.969 | D26: =C26*$J2 -> 37.049087
B27: Time deposits | C27: 15532.459 | D27: =C27*$J2 -> 349.40756
B28: Impairment provision | C28: -25.625 | D28: =C28*$J2 -> -0.57644246
B29: Total Cash and cash equivalents | C29: =SUM(C25:C28) -> 17161.084 | D29: =SUM(D25:D28) -> 386.044
B30: check | C30: =C29-C14 -> 0
B33: Debt Breakup by currency (including lease liabilities) | C33: =C5 -> TRY mn | D33: =D5 -> USD mn | E33: %age
B34: Local currency | C34: =SUM(C35:C36) -> 0 | D34: =SUM(D35:D36) -> 0 | E34: =C34/$C$98 -> 0
B35: short term | C35: 0 | D35: =C35*$J2 -> 0
B36: long term | C36: 0 | D36: =C36*$J2 -> 0
B37: Foreign currency | C37: =SUM(C38:C39) -> 58252.408 | D37: =SUM(D38:D39) -> 1310.4063 | E37: =C37/$C$40 -> 1
B38: short term | C38: =2493.451+14769.609+31.412+89.688 -> 17384.16 | D38: =C38*$J2 -> 391.06216
B39: long term | C39: =32091.538+8649.593+127.117 -> 40868.248 | D39: =C39*$J2 -> 919.34413
B40: Total Debt | C40: =SUM(C34+C37) -> 58252.408 | D40: =SUM(D34+D37) -> 1310.4063 | E40: =SUM(E34+E37) -> 1
B41: check | C41: =C40-C13-C8 -> 0
B44: Debt Maturity (includes bank loans and issued debt instruments) | C44: =C5 -> TRY mn | D44: =D5 -> USD mn
B45: Short term borrowings | C45: 12203.996 | D45: =C45*J2 -> 274.53274
B47: within 1 year | C47: 5180.164 | D47: =C47*$J2 -> 116.52942
B48: within 1-2 years | C48: 2873.517 | D48: =C48*$J2 -> 64.640671
B49: within 2-3 years | C49: 2604.161 | D49: =C49*$J2 -> 58.581423
B50: within 3-4 years | C50: 2366.548 | D50: =C50*$J2 -> 53.236244
...

Sheet Model
B2: ÜLKER BÝSKÜVÝ SANAYÝ A.Þ. | C2: Annual | D2: Annual | E2: Annual | F2: Annual | G2: Annual | H2: Annual | I2: Annual | J2: Annual | K2: Annual | L2: Annual | M2: Annual | N2: Annual | O2: Annual | P2: LTM | R2: Quarters | S2: Quarters | T2: Quarters | U2: Quarters | V2: Quarters | W2: Quarters | X2: Quarters | Y2: Quarters | Z2: Quarters | AA2: Quarters | AB2: Quarters | AC2: Quarters | AD2: Quarters | AE2: Quarters | AF2: Quarters | AG2: Quarters | AH2: Quarters | AI2: Quarters | AJ2: Quarters | AK2: Quarters | AL2: Quarters | AM2: Quarters | AN2: Quarters | AO2: Quarters | AP2: Quarters | AQ2: Quarters | AR2: Quarters | AS2: Quarters | AT2: Quarters | AU2: Quarters | AV2: Quarters | AW2: Quarters | AX2: Quarters | AY2: Quarters | AZ2: Quarters | BA2: Quarters | BB2: Quarters | BC2: Quarters | BE2: Quarters | BF2: Quarters | BG2: Quarters | BH2: Quarters | BI2: Quarters | BK2: 6M | BL2: 6M | BN2: 9M | BO2: 9M | BQ2: Quarters | BR2: Quarters | BS2: Quarters
B3: (TRY million) | C3: 42735 | D3: 43100 | E3: 43465 | F3: 43830 | G3: 44196 | H3: 44561 | I3: 44926 | J3: 44926 | K3: 45291 | L3: 45291 | M3: 45657 | N3: 45657 | O3: 46022 | P3: =BC3 -> 46112 | R3: 43190 | S3: 43281 | T3: 43373 | U3: 43465 | V3: 43555 | W3: 43646 | X3: 43738 | Y3: 43830 | Z3: 43921 | AA3: 44012 | AB3: 44104 | AC3: 44196 | AD3: 44286 | AE3: 44377 | AF3: 44469 | AG3: 44561 | AH3: 44651 | AI3: 44742 | AJ3: 44834 | AK3: 44926 | AL3: 44926 | AM3: 45016 | AN3: 45016 | AO3: 45107 | AP3: 45107 | AQ3: 45199 | AR3: 45199 | AS3: 45291 | AT3: 45291 | AU3: 45382 | AV3: 45473 | AW3: 45565 | AX3: 45657 | AY3: 45747 | AZ3: 45838 | BA3: 45930 | BB3: 46022 | BC3: 46112 | BE3: 45382 | BF3: 45473 | BG3: 45565 | BH3: 45656 | BI3: 45747 | BK3: 45473 | BL3: 45838 | BN3: 45565 | BO3: 45930 | BQ3: 44104 | BR3: 44286 | BS3: 44377
C4: Act | D4: Act | E4: Act | F4: Act | G4: Act | H4: Act | I4: Act | J4: Restated | K4: Act | L4: Restated | M4: Act | N4: Restated | O4: Act | P4: Act | R4: Act | S4: Act | T4: Act | U4: Act | V4: Act | W4: Act | X4: Act | Y4: Act | Z4: Act | AA4: Act | AB4: Act | AC4: Act | AD4: Act | AE4: Act | AF4: Act | AG4: Act | AH4: Act | AI4: Act | AJ4: Act | AK4: Act | AL4: Restated | AM4: Act | AN4: Restated | AO4: Act | AP4: Restated | AQ4: Act | AR4: Restated | AS4: Act | AT4: Restated | AU4: Act | AV4: Act | AW4: Act | AX4: Act | AY4: Act | AZ4: Act | BA4: Act | BB4: Act | BC4: Act | BE4: Restated | BF4: Restated | BG4: Restated | BH4: Restated | BI4: Restated | BK4: Act | BL4: Act | BN4: Act | BO4: Act | BQ4: Restated | BR4: Restated | BS4: Restated
C5: FY | D5: FY | E5: FY | F5: FY | G5: FY | H5: FY | I5: FY | J5: FY | K5: FY | L5: FY | M5: FY | N5: FY | O5: FY | P5: LTM | R5: 1Q | S5: 2Q | T5: 3Q | U5: 4Q | V5: 1Q | W5: 2Q | X5: 3Q | Y5: 4Q | Z5: 1Q | AA5: 2Q | AB5: 3Q | AC5: 4Q | AD5: 1Q | AE5: 2Q | AF5: 3Q | AG5: 4Q | AH5: 1Q | AI5: 2Q | AJ5: 3Q | AK5: 4Q | AL5: 4Q | AM5: 1Q | AN5: 1Q | AO5: 2Q | AP5: 2Q | AQ5: 3Q | AR5: 3Q | AS5: 4Q | AT5: 4Q | AU5: 1Q | AV5: 2Q | AW5: 3Q | AX5: 4Q | AY5: 1Q | AZ5: 2Q | BA5: 3Q | BB5: 4Q | BC5: 1Q | BE5: 1Q | BF5: 2Q | BG5: 3Q | BH5: 4Q | BI5: 1Q | BK5: 6M | BL5: 6M | BN5: 9M | BO5: 9M | BQ5: 3Q | BR5: 1Q | BS5: 2Q
B6: INCOME STATEMENT
B7: Revenue | C7: 4193.7747 | D7: 4825.648 | E7: 5955.508 | F7: 7803.12 | G7: 9400.861 | H7: 12537.08 | I7: 28196.847 | J7: 51981.208 | K7: 55836.141 | L7: 80615.534 | M7: 84097.908 | N7: 110077.71 | O7: 111904.6 | P7: =SUM(BB7,BC7,AZ7,BA7) -> 118848.7 | R7: 1407.69 | S7: 1312.269 | T7: 1437.674 | U7: =E7-SUM(R7:T7) -> 1797.875 | V7: 1942.36 | W7: 1820.498 | X7: 1893.109 | Y7: =F7-SUM(V7:X7) -> 2147.153 | Z7: 2376.126 | AA7: 2144.641 | AB7: 2228.799 | AC7: =G7-SUM(Z7:AB7) -> 2651.295 | AD7: 2689.678 | AE7: 2542.416 | AF7: 2976.133 | AG7: =H7-SUM(AD7:AF7) -> 4328.853 | AH7: 5886.018 | AI7: 5991.042 | AJ7: 7301.82 | AK7: =I7-SUM(AH7:AJ7) -> 9017.967 | AL7: =J7-SUM(AH7:AJ7) -> 32802.328 | AM7: 10111.756 | AN7: 17346.855 | AO7: 9511.854 | AP7: 16395.693 | AQ7: 12408.578 | AR7: 17809.406 | AS7: =K7-SUM(AM7,AO7,AQ7) -> 23803.953 | AT7: =L7-SUM(AN7,AP7,AR7) -> 29063.58 | AU7: 19600.936 | AV7: 15309.329 | AW7: 18196.405 | AX7: =M7-SUM(AU7,AV7,AW7) -> 30991.238 | AY7: 26962.317 | AZ7: 23057.685 | BA7: 25411.133 | BB7: =O7-SUM(AY7,AZ7,BA7) -> 36473.466 | BC7: 33906.421 | BE7: 27069.643 | BF7: 20675.043 | BG7: 24254.718 | BH7: =N7-SUM(BE7,BF7,BG7) -> 38078.306 | BI7: 35285.011 | BK7: 49370.684 | BL7: 51639.553 | BN7: 77330.367 | BO7: 80925.915 | BQ7: 2291.16 | BR7: 2783.757 | BS7: 2659.067
B8: % growth | D8: =+D7/C7-1 -> 0.15066934 | E8: =+E7/D7-1 -> 0.23413643 | F8: =+F7/E7-1 -> 0.31023584 | G8: =+G7/F7-1 -> 0.20475669 | H8: =+H7/G7-1 -> 0.33360976 | I8: =+I7/H7-1 -> 1.2490761 | J8: =+J7/I7-1 -> 0.84351137 | K8: =+K7/J7-1 -> 0.074160127 | ... M8: =+M7/L7-1 -> 0.043197307 | N8: =+N7/L7-1 -> 0.36546525 | O8: =+O7/N7-1 -> 0.016596375 | V8: =V7/R7-1 -> 0.37982084 | W8: =W7/S7-1 -> 0.38729026 | X8: =X7/T7-1 -> 0.316786 | Y8: =Y7/U7-1 -> 0.19427268 | Z8: =Z7/V7-1 -> 0.22331906 | AA8: =AA7/W7-1 -> 0.17805183 | AB8: =AB7/X7-1 -> 0.17732207 | AC8: =AC7/Y7-1 -> 0.23479556 | ... AK8: =AK7/AG7-1 -> 1.0832232 | AL8: =AL7/AG7-1 -> 6.5776027 | AM8: =AM7/AH7-1 -> 0.71792815 | AN8: =AN7/AI7-1 -> 1.8954654 | AO8: =AO7/AI7-1 -> 0.58767941 | AP8: =AP7/AI7-1 -> 1.7367014 | AQ8: =AQ7/AJ7-1 -> 0.69938152 | AR8: =AR7/AJ7-1 -> 1.4390366 | AS8: =AS7/AK7-1 -> 1.6396141 | AT8: =AT7/AL7-1 -> -0.11397813 | AU8: =AU7/AN7-1 -> 0.12994177 | AV8: =AV7/AP7-1 -> -0.066259108 | AW8: =AW7/AR7-1 -> 0.021730034 | AX8: =AX7/AT7-1 -> 0.066325552 | AY8: =AY7/BE7-1 -> -0.0039648103 | AZ8: =AZ7/BF7-1 -> 0.11524242 | BA8: =BA7/BG7-1 -> 0.04767794 | BB8: =BB7/BH7-1 -> -0.042145782 | BC8: =BC7/BI7-1 -> -0.039070131 | BE8: =BE7/AN7-1 -> 0.56049284 | BF8: =BF7/AP7-1 -> 0.26100452 | BG8: =BG7/AR7-1 -> 0.36190494 | BH8: =BH7/AT7-1 -> 0.31017259 | BI8: =BI7/BE7-1 -> 0.30349008 | BL8: =BL7/BK7-1 -> 0.045955794 | BO8: =BO7/BN7-1 -> 0.046495939 | BQ8: =BQ7/X7-1 -> 0.21026312 | BR8: =BR7/Z7-1 -> 0.17155277 | BS8: =BS7/AA7-1 -> 0.23986579
B9: Cost of sales | C9: -3119.7251 | D9: -3573.677 | E9: -4395.223 | F9: -5663.928 | G9: -6757.398 | H9: -8924.665 | I9: -19788.33 | J9: -40653.018 | K9: -39659.581 | L9: -57260.016 | M9: -59031.548 | N9: -77267.768 | O9: -79559.084 | P9: =SUM(BB9,BC9,AZ9,BA9) -> -86066.846 | R9: -1026.471 | S9: -985.004 | T9: -1052.597 | U9: =E9-SUM(R9:T9) -> -1331.151 | V9: -1404.188 | W9: -1311.332 | X9: -1394.946 | Y9: =F9-SUM(V9:X9) -> -1553.462 | Z9: -1659.845 | AA9: -1557.506 | AB9: -1606.655 | AC9: =G9-SUM(Z9:AB9) -> -1933.392 | AD9: -1916.097 | AE9: -1924.697 | AF9: -2171.949 | AG9: =H9-SUM(AD9:AF9) -> -2911.922 | AH9: -4036.928 | AI9: -4293.332 | AJ9: -5280.918 | AK9: =I9-SUM(AH9:AJ9) -> -6177.152 | AL9: =J9-SUM(AH9:AJ9) -> -27041.84 | AM9: -6640.8 | AN9: -12015.237 | AO9: -6514.881 | AP9: -11910.824 | AQ9: -8222.343 | AR9: -12408.692 | AS9: =K9-SUM(AM9,AO9,AQ9) -> -18281.557 | AT9: =L9-SUM(AN9,AP9,AR9) -> -20925.263 | AU9: -13335.894 | AV9: -10632.082 | AW9: -13265.473 | AX9: =M9-SUM(AU9,AV9,AW9) -> -21798.099 | AY9: -17946.855 | AZ9: -16776.285 | BA9: -17981.12 | BB9: =O9-SUM(AY9,AZ9,BA9) -> -26854.824 | BC9: -24454.617 | BE9: -18417.38 | BF9: -14358.485 | BG9: -17682.081 | BH9: =N9-SUM(BE9,BF9,BG9) -> -26809.822 | BI9: -23486.668 | BK9: -33882.146 | BL9: -35801.158 | BN9: -54106.872 | BO9: -56468.934 | BQ9: -1606.082 | BR9: -1921.419 | BS9: -1947.709
B10: Gross Profit | C10: =C7+C9 -> 1074.0496 | D10: =D7+D9 -> 1251.971 | E10: =E7+E9 -> 1560.285 | F10: =F7+F9 -> 2139.192 | G10: =G7+G9 -> 2643.463 | H10: =H7+H9 -> 3612.415 | I10: =I7+I9 -> 8408.517 | J10: =J7+J9 -> 11328.19 | ... P10: =P7+P9 -> 32781.859 | R10: =R7+R9 -> 381.219 | S10: =S7+S9 -> 327.265 | T10: =T7+T9 -> 385.077 | U10: =U7+U9 -> 466.724 | V10: =V7+V9 -> 538.172 | W10: =W7+W9 -> 509.166 | X10: =X7+X9 -> 498.163 | Y10: =Y7+Y9 -> 593.691 | ... BC10: =BC7+BC9 -> 9451.804 | BE10: =BE7+BE9 -> 8652.263 | BF10: =BF7+BF9 -> 6316.558 | BG10: =BG7+BG9 -> 6572.637 | BH10: =BH7+BH9 -> 11268.484 | BI10: =BI7+BI9 -> 11798.343 | BK10: =BK7+BK9 -> 15488.538 | BL10: =BL7+BL9 -> 15838.395 | BN10: =BN7+BN9 -> 23223.495 | BO10: =BO7+BO9 -> 24456.981 | BQ10: 675.078 | BR10: 862.338 | BS10: 711.358
B11: Gross Profit margin | C11: =C10/C7 -> 0.25610571 | D11: =D10/D7 -> 0.25944101 | E11: =E10/E7 -> 0.26199024 | F11: =F10/F7 -> 0.27414573 | G11: =G10/G7 -> 0.28119371 | H11: =H10/H7 -> 0.28813847 | I11: =I10/I7 -> 0.2982077 | J11: =J10/J7 -> 0.21792856 | ... P11: =P10/P7 -> 0.27582849 | R11: =R10/R7 -> 0.27081176 | S11: =S10/S7 -> 0.24938865 | T11: =T10/T7 -> 0.26784723 | U11: =U10/U7 -> 0.25959758 | V11: =V10/V7 -> 0.27707119 | W11: =W10/W7 -> 0.27968501 | X11: =X10/X7 -> 0.26314544 | Y11: =Y10/Y7 -> 0.27650149 | ... BC11: =BC10/BC7 -> 0.27876148 | BE11: =BE10/BE7 -> 0.31962974 | BF11: =BF10/BF7 -> 0.30551608 | BG11: =BG10/BG7 -> 0.27098386 | BH11: =BH10/BH7 -> 0.29592924 | BI11: =BI10/BI7 -> 0.33437266 | BK11: =BK10/BK7 -> 0.31371933 | BL11: =BL10/BL7 -> 0.30671054 | BN11: =BN10/BN7 -> 0.30031533 | BO11: =BO10/BO7 -> 0.30221445 | BQ11: =BQ10/BQ7 -> 0.29464463 | BR11: =BR10/BR7 -> 0.30977488 | BS11: =BS10/BS7 -> 0.26752165
B12: General Administrative Expenses | C12: -128.28261 | D12: -142.567 | E12: -159.664 | F12: -234.744 | G12: -263.248 | H12: -353.681 | I12: -715.407 | J12: -1238.763 | K12: -1388.277 | L12: -2004.377 | M12: -2275.527 | N12: -2978.49 | O12: -2990.173 | P12: =SUM(BB12,BC12,AZ12,BA12) -> -3258.626 | R12: -34.708 | S12: -39.869 | T12: -39.6 | U12: =E12-SUM(R12:T12) -> -45.487 | V12: -38.613 | W12: -55.972 | X12: -66.617 | Y12: =F12-SUM(V12:X12) -> -73.542 | Z12: -63.816 | AA12: -63.808 | AB12: -66.481 | AC12: =G12-SUM(Z12:AB12) -> -69.143 | AD12: -76.769 | AE12: -80.799 | AF12: -82.105 | AG12: =H12-SUM(AD12:AF12) -> -114.008 | AH12: -132.796 | AI12: -145.579 | AJ12: -194.805 | AK12: =I12-SUM(AH12:AJ12) -> -242.227 | AL12: =J12-SUM(AH12:AJ12) -> -765.583 | AM12: -210.988 | AN12: -358.757 | AO12: -247.964 | AP12: -409.739 | AQ12: -403.85 | AR12: -543.018 | AS12: =K12-SUM(AM12,AO12,AQ12) -> -525.475 | AT12: =L12-SUM(AN12,AP12,AR12) -> -692.863 | AU12: -481.297 | AV12: -400.86 | AW12: -570.708 | AX12: =M12-SUM(AU12,AV12,AW12) -> -822.662 | AY12: -660.35 | AZ12: -644.656 | BA12: -699.259 | BB12: =O12-SUM(AY12,AZ12,BA12) -> -985.908 | BC12: -928.803 | BE12: -664.69 | BF12: -541.355 | BG12: -760.72 | BH12: =N12-SUM(BE12,BF12,BG12) -> -1011.725 | BI12: -864.186 | BK12: -1245.971 | BL12: -1344.671 | BN12: -2100.192 | BO12: -2144.839 | BQ12: -66.977 | BR12: -78.118 | BS12: -82.745
B13: Marketing, Sales and Distribution Expenses | C13: -449.07643 | D13: -478.147 | E13: -598.206 | F13: -752.076 | G13: -921.325 | H13: -1120.598 | I13: -2486.22 | J13: -4389.641 | K13: -5133.098 | L13: -7411.104 | M13: -8600.376 | N13: -11257.232 | O13: -12762.944 | P13: =SUM(BB13,BC13,AZ13,BA13) -> -13621.089 | R13: -152.376 | S13: -118.292 | T13: -145.685 | U13: =E13-SUM(R13:T13) -> -181.853 | V13: -206.804 | W13: -172.846 | X13: -153.876 | Y13: =F13-SUM(V13:X13) -> -218.55 | Z13: -275.631 | AA13: -183.824 | AB13: -210.326 | AC13: =G13-SUM(Z13:AB13) -> -251.544 | AD13: -279.916 | AE13: -227.249 | AF13: -270.405 | AG13: =H13-SUM(AD13:AF13) -> -343.028 | AH13: -537.25 | AI13: -484.019 | AJ13: -640.371 | AK13: =I13-SUM(AH13:AJ13) -> -824.58 | AL13: =J13-SUM(AH13:AJ13) -> -2728.001 | AM13: -991.948 | AN13: -1692.145 | AO13: -906.496 | AP13: -1530.049 | AQ13: -1190.363 | AR13: -1493.086 | AS13: =K13-SUM(AM13,AO13,AQ13) -> -2044.291 | AT13: =L13-SUM(AN13,AP13,AR13) -> -2695.824 | AU13: -2040.865 | AV13: -1639.326 | AW13: -1758.599 | AX13: =M13-SUM(AU13,AV13,AW13) -> -3161.586 | AY13: -3251.343 | AZ13: -2644.952 | BA13: -2699.03 | BB13: =O13-SUM(AY13,AZ13,BA13) -> -4167.619 | BC13: -4109.488 | BE13: -2818.513 | BF13: -2213.887 | BG13: -2344.107 | BH13: =N13-SUM(BE13,BF13,BG13) -> -3880.725 | BI13: -4254.963 | BK13: -5201.7 | BL13: -6091.594 | BN13: -7936.163 | BO13: -9247.76 | BQ13: -211.264 | BR13: -281.943 | BS13: -228.232
B14: Research and Development Expenses | C14: -8.733516 | D14: -13.525 | E14: -12.551 | F14: -19.956 | G14: -24.209 | H14: -39.786 | I14: -88.643 | J14: -164.649 | K14: -238.705 | L14: -344.639 | M14: -415.128 | N14: -543.371 | O14: -628.46 | P14: =SUM(BB14,BC14,AZ14,BA14) -> -655.452 | R14: -3.645 | S14: -3.13 | T14: -3.093 | U14: =E14-SUM(R14:T14) -> -2.683 | V14: -3.836 | W14: -5.253 | X14: -4.451 | Y14: =F14-SUM(V14:X14) -> -6.416 | Z14: -5.682 | AA14: -5.494 | AB14: -5.577 | AC14: =G14-SUM(Z14:AB14) -> -7.456 | AD14: -8.865 | AE14: -9.745 | AF14: -8.31 | AG14: =H14-SUM(AD14:AF14) -> -12.866 | AH14: -12.484 | AI14: -17.23 | AJ14: -20.831 | AK14: =I14-SUM(AH14:AJ14) -> -38.098 | AL14: =J14-SUM(AH14:AJ14) -> -114.104 | AM14: -39.884 | AN14: -69.459 | AO14: -39.268 | AP14: -68.888 | AQ14: -53.429 | AR14: -81.514 | AS14: =K14-SUM(AM14,AO14,AQ14) -> -106.124 | AT14: =L14-SUM(AN14,AP14,AR14) -> -124.778 | AU14: -77.614 | AV14: -68.641 | AW14: -79.388 | AX14: =M14-SUM(AU14,AV14,AW14) -> -189.485 | AY14: -140.298 | AZ14: -133.675 | BA14: -149.267 | BB14: =O14-SUM(AY14,AZ14,BA14) -> -205.22 | BC14: -167.29 | BE14: -107.188 | BF14: -92.699 | BG14: -105.819 | BH14: =N14-SUM(BE14,BF14,BG14) -> -237.665 | BI14: -183.605 | BK14: -206.325 | BL14: -282.4 | BN14: -327.627 | BO14: -452.859 | BQ14: -5.586 | BR14: -8.865 | BS14: -9.895
B15: Other Operating Income | C15: 37.216977 | D15: 58.773 | E15: 114.557 | F15: 87.331 | G15: 229.896 | H15: 895.987 | I15: 1118.931 | J15: 2401.751 | K15: 2745.639 | L15: 3964.12 | M15: 2078.007 | N15: 2719.952 | O15: 3025.401 | P15: =SUM(BB15,BC15,AZ15,BA15) -> 2731.399 | R15: 22.558 | S15: 26.499 | T15: 71.551 | U15: =E15-SUM(R15:T15) -> -6.051 | V15: 31.776 | W15: 16.379 | X15: 9.607 | Y15: =F15-SUM(V15:X15) -> 29.569 | Z15: 54.783 | AA15: 42.459 | AB15: 74.744 | AC15: =G15-SUM(Z15:AB15) -> 57.91 | AD15: 102.224 | AE15: 44.229 | AF15: 13.302 | AG15: =H15-SUM(AD15:AF15) -> 736.232 | AH15: 422.51 | AI15: 257.552 | AJ15: 365.348 | AK15: =I15-SUM(AH15:AJ15) -> 73.521 | AL15: =J15-SUM(AH15:AJ15) -> 1356.341 | AM15: 228.209 | AN15: 403.661 | AO15: 1094.885 | AP15: 1890.503 | AQ15: 359.176 | AR15: 587.727 | AS15: =K15-SUM(AM15,AO15,AQ15) -> 1063.369 | AT15: =L15-SUM(AN15,AP15,AR15) -> 1082.229 | AU15: 1351.312 | AV15: 3.224 | AW15: 134.745 | AX15: =M15-SUM(AU15,AV15,AW15) -> 588.726 | AY15: 1131.685 | AZ15: 427.797 | BA15: 670.322 | BB15: =O15-SUM(AY15,AZ15,BA15) -> 795.597 | BC15: 837.683 | BE15: 1866.214 | BF15: 4.354 | BG15: 179.607 | BH15: =N15-SUM(BE15,BF15,BG15) -> 669.777 | BI15: 1481.012 | BK15: 1982.666 | BL15: 1627.459 | BN15: 2311.06 | BO15: 2419.912 | BQ15: 96.87 | BR15: 126.614 | BS15: 60.538
B16: Other Operating Expenses | C16: -16.492653 | D16: -60.193 | E16: -125.337 | F16: -66.029 | G16: -171.839 | H16: -564.347 | I16: -378.281 | J16: -878.881 | K16: -1169.204 | L16: -1688.082 | M16: -1575.129 | N16: -2061.723 | O16: -2253.736 | P16: =SUM(BB16,BC16,AZ16,BA16) -> -2019.794 | R16: -24.283 | S16: -23.9 | T16: -46.863 | U16: =E16-SUM(R16:T16) -> -30.291 | V16: -24.314 | W16: -13.374 | X16: -22.614 | Y16: =F16-SUM(V16:X16) -> -5.727 | Z16: -28.728 | AA16: -33.077 | AB16: -26.978 | AC16: =G16-SUM(Z16:AB16) -> -83.056 | AD16: -44.882 | AE16: -46.506 | AF16: -7.361 | AG16: =H16-SUM(AD16:AF16) -> -465.598 | AH16: -254.476 | AI16: -23.315 | AJ16: 15.629 | AK16: =I16-SUM(AH16:AJ16) -> -116.119 | AL16: =J16-SUM(AH16:AJ16) -> -616.719 | AM16: -207.595 | AN16: -360.722 | AO16: -71.401 | AP16: -120.225 | AQ16: -441.924 | AR16: -692.11 | AS16: =K16-SUM(AM16,AO16,AQ16) -> -448.284 | AT16: =L16-SUM(AN16,AP16,AR16) -> -515.025 | AU16: -827.271 | AV16: -1.957 | AW16: -215.61 | AX16: =M16-SUM(AU16,AV16,AW16) -> -530.291 | AY16: -720.551 | AZ16: -365.573 | BA16: -465.097 | BB16: =O16-SUM(AY16,AZ16,BA16) -> -702.515 | BC16: -486.609 | BE16: -1142.493 | BF16: -2.644 | BG16: -287.395 | BH16: =N16-SUM(BE16,BF16,BG16) -> -629.191 | BI16: -942.97 | BK16: -1213.763 | BL16: -1129.405 | BN16: -1592.246 | BO16: -1679.257 | BQ16: -55.232 | BR16: -122.723 | BS16: -97.753
B17: Income from Investment Activities | C17: 444.15896 | D17: 680.495 | E17: 1709.158 | F17: 1131.907 | G17: 2503.149 | H17: 6096.145 | I17: 3880.982 | J17: 7811.62 | K17: 7623.622 | L17: 11006.892 | M17: 6108.366 | N17: 7995.382 | O17: 11057.857 | P17: =SUM(BB17,BC17,AZ17,BA17) -> 9274.288 | R17: 315.845 | S17: 646.472 | T17: 1603.173 | U17: =E17-SUM(R17:T17) -> -856.332 | V17: 553.322 | W17: 143.209 | X17: 264.157 | Y17: =F17-SUM(V17:X17) -> 171.219 | Z17: 725.238 | AA17: 319.477 | AB17: 1205.45 | AC17: =G17-SUM(Z17:AB17) -> 252.984 | AD17: 1448.855 | AE17: 782.121 | AF17: -105.996 | AG17: =H17-SUM(AD17:AF17) -> 3971.165 | AH17: 1082.949 | AI17: 1304.375 | AJ17: 1307.218 | AK17: =I17-SUM(AH17:AJ17) -> 186.44 | AL17: =J17-SUM(AH17:AJ17) -> 4117.078 | AM17: 524.086 | AN17: 894.346 | AO17: 3165.844 | AP17: 5580.905 | AQ17: 987.608 | AR17: 1503.336 | AS17: =K17-SUM(AM17,AO17,AQ17) -> 2946.084 | AT17: =L17-SUM(AN17,AP17,AR17) -> 3028.305 | AU17: 1328.192 | AV17: 628.042 | AW17: 2095.632 | AX17: =M17-SUM(AU17,AV17,AW17) -> 2056.5 | AY17: 3389.556 | AZ17: 3099.07 | BA17: 2660.832 | BB17: =O17-SUM(AY17,AZ17,BA17) -> 1908.399 | BC17: 1605.987 | BE17: 1834.284 | BF17: 848.163 | BG17: 2793.352 | BH17: =N17-SUM(BE17,BF17,BG17) -> 2519.583 | BI17: 4435.84 | BK17: 2792.627 | BL17: 6692.227 | BN17: 5795.548 | BO17: 9855.269 | BQ17: 1219.779 | BR17: 1480.763 | BS17: 852.646
B18: Expenses from Investment Activities | C18: -113.22476 | D18: -97.632 | E18: -13.599 | F18: -11.246 | G18: -683.929 | H18: -130.934 | I18: -1607.231 | J18: -3247.512 | K18: -418.788 | L18: -604.641 | M18: -263.15 | N18: -344.443 | O18: -679.996 | P18: =SUM(BB18,BC18,AZ18,BA18) -> -379.206 | R18: -8.281 | S18: 0.197 | T18: -282.82 | U18: =E18-SUM(R18:T18) -> 277.305 | V18: -25.055 | W18: 14.794 | X18: -293.818 | Y18: =F18-SUM(V18:X18) -> 292.833 | Z18: -672.328 | AA18: 429.124 | AB18: 128.596 | AC18: =G18-SUM(Z18:AB18) -> -569.321 | AD18: -0.209 | AE18: -0.026 | AF18: -15.004 | AG18: =H18-SUM(AD18:AF18) -> -115.695 | AH18: -739.621 | AI18: -758.821 | AJ18: -404.992 | AK18: =I18-SUM(AH18:AJ18) -> 296.203 | AL18: =J18-SUM(AH18:AJ18) -> -1344.078 | AM18: -35.677 | AN18: -61.499 | AO18: -140.029 | AP18: -247.106 | AQ18: -126.715 | AR18: -235.781 | AS18: =K18-SUM(AM18,AO18,AQ18) -> -116.367 | AT18: =L18-SUM(AN18,AP18,AR18) -> -60.255 | AU18: -3.78 | AV18: -5.44 | AW18: -111.09 | AX18: =M18-SUM(AU18,AV18,AW18) -> -142.84 | AY18: -575.094 | AZ18: -7.31 | BA18: -75.809 | BB18: =O18-SUM(AY18,AZ18,BA18) -> -21.783 | BC18: -274.304 | BE18: -5.22 | BF18: -7.347 | BG18: -148.076 | BH18: =N18-SUM(BE18,BF18,BG18) -> -183.8 | BI18: -752.613 | BK18: -12.881 | BL18: -616.948 | BN18: -161.924 | BO18: -739.055 | BQ18: 129.387 | BR18: -1.36 | BS18: -0.411
B19: Operating profit | C19: =C10+SUM(C12:C18) -> 839.61561 | D19: =D10+SUM(D12:D18) -> 1199.175 | E19: =E10+SUM(E12:E18) -> 2474.643 | F19: =F10+SUM(F12:F18) -> 2274.379 | G19: =G10+SUM(G12:G18) -> 3311.958 | H19: =H10+SUM(H12:H18) -> 8395.201 | I19: =I10+SUM(I12:I18) -> 8132.648 | J19: =J10+SUM(J12:J18) -> 11622.115 | ... P19: =P10+SUM(P12:P18) -> 24853.379 | R19: =R10+SUM(R12:R18) -> 496.329 | S19: =S10+SUM(S12:S18) -> 815.242 | T19: =T10+SUM(T12:T18) -> 1541.74 | U19: =U10+SUM(U12:U18) -> -378.668 | V19: =V10+SUM(V12:V18) -> 824.648 | W19: =W10+SUM(W12:W18) -> 436.103 | X19: =X10+SUM(X12:X18) -> 230.551 | Y19: =Y10+SUM(Y12:Y18) -> 783.077 | ... BC19: =BC10+SUM(BC12:BC18) -> 5928.98 | BE19: =BE10+SUM(BE12:BE18) -> 7614.657 | BF19: =BF10+SUM(BF12:BF18) -> 4311.143 | BG19: =BG10+SUM(BG12:BG18) -> 5899.479 | BH19: =BH10+SUM(BH12:BH18) -> 8514.738 | BI19: =BI10+SUM(BI12:BI18) -> 10716.858 | BK19: =BK10+SUM(BK12:BK18) -> 12383.191 | BL19: =BL10+SUM(BL12:BL18) -> 14693.063 | BN19: =BN10+SUM(BN12:BN18) -> 19211.951 | BO19: =BO10+SUM(BO12:BO18) -> 22468.392 | BQ19: =BQ10+SUM(BQ12:BQ18) -> 1782.055 | BR19: =BR10+SUM(BR12:BR18) -> 1976.706 | BS19: =BS10+SUM(BS12:BS18) -> 1205.506
B20: % margin | C20: =+C19/C7 -> 0.20020522 | D20: =+D19/D7 -> 0.24850031 | E20: =+E19/E7 -> 0.41552173 | F20: =+F19/F7 -> 0.29147046 | G20: =+G19/G7 -> 0.35230369 | H20: =+H19/H7 -> 0.66962969 | I20: =+I19/I7 -> 0.28842402 | J20: =+J19/J7 -> 0.22358301 | ... P20: =+P19/P7 -> 0.20911779 | R20: =+R19/R7 -> 0.35258402 | S20: =+S19/S7 -> 0.6212461 | T20: =+T19/T7 -> 1.072385 | U20: =+U19/U7 -> -0.21061976 | V20: =+V19/V7 -> 0.42455981 | W20: =+W19/W7 -> 0.23955149 | X20: =+X19/X7 -> 0.12178432 | Y20: =+Y19/Y7 -> 0.3647048 | ... BC20: =+BC19/BC7 -> 0.17486304 | BE20: =+BE19/BE7 -> 0.28129876 | BF20: =+BF19/BF7 -> 0.20851918 | BG20: =+BG19/BG7 -> 0.24323016 | BH20: =+BH19/BH7 -> 0.22361126 | BI20: =+BI19/BI7 -> 0.30372268 | BK20: =+BK19/BK7 -> 0.25082073 | BL20: =+BL19/BL7 -> 0.28453118 | BN20: =+BN19/BN7 -> 0.24843993 | BO20: =+BO19/BO7 -> 0.27764149 | BQ20: =+BQ19/BQ7 -> 0.77779596 | BR20: =+BR19/BR7 -> 0.71008569 | BS20: =+BS19/BS7 -> 0.45335676
B22: Financial expenses | C22: -638.08148 | D22: -703.282 | E22: -2786.405 | F22: -1466.132 | G22: -2372.753 | H22: -8910.373 | I22: -8244.096 | J22: -16430.234 | K22: -18214.12 | L22: -26297.323 | M22: -13130.716 | N22: -17187.1 | O22: -23361.989 | P22: =SUM(BB22,BC22,AZ22,BA22) -> -21862.787 | R22: -305.709 | S22: -524.765 | T22: -1648.729 | U22: =E22-SUM(R22:T22) -> -307.202 | V22: -322.38 | W22: -357.923 | X22: -327.458 | Y22: =F22-SUM(V22:X22) -> -458.371 | Z22: -528.393 | AA22: -592.053 | AB22: -1293.026 | AC22: =G22-SUM(Z22:AB22) -> 40.719 | AD22: -1250.912 | AE22: -703.441 | AF22: -737.17 | AG22: =H22-SUM(AD22:AF22) -> -6218.85 | AH22: -2025.085 | AI22: -2412.951 | AJ22: -2581.142 | AK22: =I22-SUM(AH22:AJ22) -> -1224.918 | AL22: =J22-SUM(AH22:AJ22) -> -9411.056 | AM22: -1465.264 | AN22: -2516.935 | AO22: -7679.675 | AP22: -13292.655 | AQ22: -1709.954 | AR22: -2913.875 | AS22: =K22-SUM(AM22,AO22,AQ22) -> -7359.227 | AT22: =L22-SUM(AN22,AP22,AR22) -> -7573.858 | AU22: -3215.358 | AV22: -2349.95 | AW22: -3822.647 | AX22: =M22-SUM(AU22,AV22,AW22) -> -3742.761 | AY22: -5439.054 | AZ22: -5874.143 | BA22: -5540.338 | BB22: =O22-SUM(AY22,AZ22,BA22) -> -6508.454 | BC22: -3939.852 | BE22: -4440.533 | BF22: -3173.576 | BG22: -5095.36 | BH22: =N22-SUM(BE22,BF22,BG22) -> -4477.631 | BI22: -7117.974 | BK22: -7880.839 | BL22: -11639.906 | BN22: -13567.607 | BO22: -18053.747 | BQ22: -1444.391 | BR22: -1387.968 | BS22: -795.49
B23: Financial income | C23: 135.02642 | D23: 27.859 | E23: 1285.301 | F23: 554.695 | G23: 555.442 | H23: 444.638 | I23: 193.054 | J23: =339.665 -> 339.665 | K23: =318.356 -> 318.356 | L23: 459.638 | M23: 260.297 | N23: 340.709 | O23: 5.6 | P23: =SUM(BB23,BC23,AZ23,BA23) -> 7.022 | R23: 5.318 | S23: 12.531 | T23: 420.94 | U23: =E23-SUM(R23:T23) -> 846.512 | V23: 2.005 | W23: 82.614 | X23: 438.376 | Y23: =F23-SUM(V23:X23) -> 31.7 | Z23: 7.697 | AA23: 182.141 | AB23: 37.439 | AC23: =G23-SUM(Z23:AB23) -> 328.165 | AD23: 1.711 | AE23: 0.733 | AF23: 448.195 | AG23: =H23-SUM(AD23:AF23) -> -6.001 | AH23: 28.219 | AI23: -21.663 | AJ23: 102.225 | AK23: =I23-SUM(AH23:AJ23) -> 84.273 | AL23: =J23-SUM(AH23:AJ23) -> 230.884 | AM23: 129.071 | AN23: 226.139 | AO23: 17.357 | AP23: 12.768 | AQ23: -24.31 | AR23: -59.976 | AS23: =K23-SUM(AM23,AO23,AQ23) -> 196.238 | AT23: =L23-SUM(AN23,AP23,AR23) -> 280.707 | AU23: 13.946 | AV23: 35.637 | AW23: 19.397 | AX23: =M23-SUM(AU23,AV23,AW23) -> 191.317 | AY23: 1.204 | AZ23: 1.255 | BA23: 1.335 | BB23: =O23-SUM(AY23,AZ23,BA23) -> 1.806 | BC23: 2.626 | BE23: 19.26 | BF23: 48.127 | BG23: 25.855 | BH23: =N23-SUM(BE23,BF23,BG23) -> 247.467 | BI23: 1.576 | BK23: 68.544 | BL23: 2.531 | BN23: 99.543 | BO23: 4.056 | BQ23: 34.263 | BR23: 18.892 | BS23: -13.61
B24: Net monetary gain | C24: 0 | D24: 0 | E24: 0 | F24: 0 | G24: 0 | H24: 0 | I24: 0 | J24: 5841.449 | K24: 4475.153 | L24: 6461.171 | M24: 3712.173 | N24: 4858.948 | O24: 2922.25 | P24: =SUM(BB24,BC24,AZ24,BA24) -> 3310.261 | AH24: 0 | AI24: 0 | AJ24: 0 | AK24: =I24-SUM(AH24:AJ24) -> 0 | AL24: =J24-SUM(AH24:AJ24) -> 5841.449 | AM24: 0 | AN24: 1427.8 | AO24: 0 | AP24: 1058.281 | AQ24: 0 | AR24: 3265.006 | AS24: =K24-SUM(AM24,AO24,AQ24) -> 4475.153 | AT24: =L24-SUM(AN24,AP24,AR24) -> 710.084 | AU24: 1316.188 | AV24: 853.582 | AW24: 630.206 | AX24: =M24-SUM(AU24,AV24,AW24) -> 912.197 | AY24: 706.992 | AZ24: 819.253 | BA24: 765.224 | BB24: =O24-SUM(AY24,AZ24,BA24) -> 630.781 | BC24: 1095.003 | BE24: 1817.706 | BF24: 1152.751 | BG24: 840.027 | BH24: =N24-SUM(BE24,BF24,BG24) -> 1048.464 | BI24: 925.225 | BK24: 3079.642 | BL24: 1568.712 | BN24: 4150.778 | BO24: 2451.658
U25: =E25-SUM(R25:T25) -> 0 | Y25: =F25-SUM(V25:X25) -> 0 | AC25: =R25-SUM(Z25:AB25) -> 0 | AG25: =V25-SUM(AD25:AF25) -> 0
B26: Profit before tax | C26: =+C19+C22+C23+C24 -> 336.56055 | D26: =+D19+D22+D23+D24 -> 523.752 | E26: =+E19+E22+E23+E24 -> 973.539 | F26: =+F19+F22+F23+F24 -> 1362.942 | G26: =+G19+G22+G23+G24 -> 1494.647 | H26: =+H19+H22+H23+H24 -> -70.534 | I26: =+I19+I22+I23+I24 -> 81.606 | J26: =+J19+J22+J23+J24 -> 1372.995 | ... P26: =+P19+P22+P23+P24 -> 6307.875 | R26: =+R19+R22+R23 -> 195.938 | S26: =+S19+S22+S23 -> 303.008 | T26: =+T19+T22+T23 -> 313.951 | U26: =+U19+U22+U23 -> 160.642 | V26: =+V19+V22+V23 -> 504.273 | W26: =+W19+W22+W23 -> 160.794 | X26: =+X19+X22+X23 -> 341.469 | Y26: =+Y19+Y22+Y23 -> 356.406 | Z26: =+Z19+Z22+Z23+Z24 -> -70.579 | AA26: =+AA19+AA22+AA23+AA24 -> 682.08 | AB26: =+AB19+AB22+AB23+AB24 -> 465.985 | AC26: =+AC19+AC22+AC23+AC24 -> 417.161 | AD26: =+AD19+AD22+AD23+AD24 -> 664.818 | AE26: =+AE19+AE22+AE23+AE24 -> 377.036 | AF26: =+AF19+AF22+AF23+AF24 -> 39.33 | AG26: =+AG19+AG22+AG23+AG24 -> -1151.718 | ... BC26: =+BC19+BC22+BC23+BC24 -> 3086.757 | BE26: =+BE19+BE22+BE23+BE24 -> 5011.09 | BF26: =+BF19+BF22+BF23+BF24 -> 2338.445 | BG26: =+BG19+BG22+BG23+BG24 -> 1670.001 | BH26: =+BH19+BH22+BH23+BH24 -> 5333.038 | BI26: =+BI19+BI22+BI23+BI24 -> 4525.685 | BK26: =+BK19+BK22+BK23+BK24 -> 7650.538 | BL26: =+BL19+BL22+BL23+BL24 -> 4624.4 | BN26: =+BN19+BN22+BN23+BN24 -> 9894.665 | BO26: =+BO19+BO22+BO23+BO24 -> 6870.359 | BQ26: =+BQ19+BQ22+BQ23 -> 371.927 | BR26: =+BR19+BR22+BR23 -> 607.63 | BS26: =+BS19+BS22+BS23 -> 396.406
B27: Current Tax (Expense)/Income | C27: -59.825029 | D27: -68.079 | E27: -118.197 | F27: -232.123 | G27: -349.929 | H27: -450.711 | I27: -680.294 | J27: -1300.719 | K27: -1297.001 | L27: -1872.594 | M27: -628.228 | N27: -822.302 | O27: -1092.526 | P27: =SUM(BB27,BC27,AZ27,BA27) -> -1936.424 | R27: -33.208 | S27: -38.206 | T27: -52.428 | U27: =E27-SUM(R27:T27) -> 5.645 | V27: -108.769 | W27: -6.824 | X27: -82.959 | Y27: =F27-SUM(V27:X27) -> -33.571 | Z27: -67.338 | AA27: -134.062 | AB27: -97.953 | AC27: =G27-SUM(Z27:AB27) -> -50.576 | AD27: -133.122 | AE27: -147.481 | AF27: -16.48 | AG27: =H27-SUM(AD27:AF27) -> -153.628 | AH27: -190.297 | AI27: -173.977 | AJ27: -203.894 | AK27: =I27-SUM(AH27:AJ27) -> -112.126 | AL27: =J27-SUM(AH27:AJ27) -> -732.551 | AM27: -283.647 | AN27: -489.114 | AO27: -243.223 | AP27: -417.827 | AQ27: -317.871 | AR27: -484.03 | AS27: =K27-SUM(AM27,AO27,AQ27) -> -452.26 | AT27: =L27-SUM(AN27,AP27,AR27) -> -481.623 | AU27: -204.028 | AV27: -236.149 | AW27: 25.373 | AX27: =M27-SUM(AU27,AV27,AW27) -> -213.424 | AY27: -287.036 | AZ27: -23.193 | BA27: -664.908 | BB27: =O27-SUM(AY27,AZ27,BA27) -> -117.389 | BC27: -1130.934 | BE27: -281.77 | BF27: -318.915 | BG27: 33.821 | BH27: =N27-SUM(BE27,BF27,BG27) -> -255.438 | BI27: -375.638 | BK27: -617.611 | BL27: -327.47 | BN27: -630.138 | BO27: -1016.953 | BQ27: -96.689 | BR27: -133.122 | BS27: -159.466
B28: Deferred Tax Income/(Expenses) | C28: 7.560895 | D28: -10.676 | E28: -67.721 | F28: -28.394 | G28: 58.867 | H28: 358.826 | I28: 798.208 | J28: 1357.23 | K28: 742.627 | L28: 1072.196 | M28: -2320.843 | N28: -3037.805 | O28: -380.589 | P28: =SUM(BB28,BC28,AZ28,BA28) -> 90.843 | R28: -10.453 | S28: -29.118 | T28: -4.828 | U28: =E28-SUM(R28:T28) -> -23.322 | V28: 3.942 | W28: -8.036 | X28: 14.256 | Y28: =F28-SUM(V28:X28) -> -38.556 | Z28: 93.774 | AA28: -8.544 | AB28: 5.45 | AC28: =G28-SUM(Z28:AB28) -> -31.813 | AD28: 9.428 | AE28: 3.041 | AF28: 10.354 | AG28: =H28-SUM(AD28:AF28) -> 336.003 | AH28: 178.185 | AI28: 223.283 | AJ28: 134.611 | AK28: =I28-SUM(AH28:AJ28) -> 262.129 | AL28: =J28-SUM(AH28:AJ28) -> 821.151 | AM28: 36.124 | AN28: -244.719 | AO28: 662.195 | AP28: 983.963 | AQ28: 371.466 | AR28: -863.989 | AS28: =K28-SUM(AM28,AO28,AQ28) -> -327.158 | AT28: =L28-SUM(AN28,AP28,AR28) -> 1196.941 | AU28: -943.384 | AV28: -160.934 | AW28: -769.271 | AX28: =M28-SUM(AU28,AV28,AW28) -> -447.254 | AY28: -592.128 | AZ28: -179.097 | BA28: -131.037 | BB28: =O28-SUM(AY28,AZ28,BA28) -> 521.673 | BC28: -120.696 | BE28: -1302.849 | BF28: -217.339 | BG28: -1025.392 | BH28: =N28-SUM(BE28,BF28,BG28) -> -492.225 | BI28: -774.905 | BK28: -1598.447 | BL28: -806.792 | BN28: -2743.792 | BO28: -998.374 | BQ28: 23.104 | BR28: 18.468 | BS28: 10.123
B29: Net profit/loss | C29: =+C26+C27+C28 -> 284.29642 | D29: =+D26+D27+D28 -> 444.997 | E29: =+E26+E27+E28 -> 787.621 | F29: =+F26+F27+F28 -> 1102.425 | G29: =+G26+G27+G28 -> 1203.585 | H29: =+H26+H27+H28 -> -162.419 | I29: =+I26+I27+I28 -> 199.52 | J29: =+J26+J27+J28 -> 1429.506 | ... P29: =+P26+P27+P28 -> 4462.294 | R29: =+R26+R27+R28 -> 152.277 | S29: =+S26+S27+S28 -> 235.684 | T29: =+T26+T27+T28 -> 256.695 | U29: =+U26+U27+U28 -> 142.965 | V29: =+V26+V27+V28 -> 399.446 | W29: =+W26+W27+W28 -> 145.934 | X29: =+X26+X27+X28 -> 272.766 | Y29: =+Y26+Y27+Y28 -> 284.279 | ... BC29: =+BC26+BC27+BC28 -> 1835.127 | BE29: =+BE26+BE27+BE28 -> 3426.471 | BF29: =+BF26+BF27+BF28 -> 1802.191 | BG29: =+BG26+BG27+BG28 -> 678.43 | BH29: =+BH26+BH27+BH28 -> 4585.375 | BI29: =+BI26+BI27+BI28 -> 3375.142 | BK29: =+BK26+BK27+BK28 -> 5434.48 | BL29: =+BL26+BL27+BL28 -> 3490.138 | BN29: =+BN26+BN27+BN28 -> 6520.735 | BO29: =+BO26+BO27+BO28 -> 4855.032 | BQ29: =+BQ26+BQ27+BQ28 -> 298.342 | BR29: =+BR26+BR27+BR28 -> 492.976 | BS29: =+BS26+BS27+BS28 -> 247.063
B30: % margin | C30: =+C29/C7 -> 0.067790102 | D30: =+D29/D7 -> 0.092214973 | E30: =+E29/E7 -> 0.13225085 | F30: =+F29/F7 -> 0.14128003 | G30: =+G29/G7 -> 0.12802923 | H30: =+H29/H7 -> -0.01295509 | I30: =+I29/I7 -> 0.0070759685 | J30: =+J29/J7 -> 0.027500438 | ... P30: =+P29/P7 -> 0.037546004 | R30: =+R29/R7 -> 0.1081751 | S30: =+S29/S7 -> 0.17960037 | T30: =+T29/T7 -> 0.17854882 | U30: =+U29/U7 -> 0.079518876 | V30: =+V29/V7 -> 0.20564983 | W30: =+W29/W7 -> 0.080161582 | X30: =+X29/X7 -> 0.14408362 | Y30: =+Y29/Y7 -> 0.13239811 | ... BC30: =+BC29/BC7 -> 0.054123288 | BE30: =+BE29/BE7 -> 0.12657984 | BF30: =+BF29/BF7 -> 0.087167461 | BG30: =+BG29/BG7 -> 0.027971053 | BH30: =+BH29/BH7 -> 0.12041962 | BI30: =+BI29/BI7 -> 0.095653704 | BK30: =+BK29/BK7 -> 0.11007504 | BL30: =+BL29/BL7 -> 0.067586526 | BN30: =+BN29/BN7 -> 0.084323084 | BO30: =+BO29/BO7 -> 0.059993539 | BQ30: =+BQ29/BQ7 -> 0.13021439 | BR30: =+BR29/BR7 -> 0.17709017 | BS30: =+BS29/BS7 -> 0.092913417
B31: Attributable to:
B32: Controlling interests | C32: 272.66325 | D32: 397.259 | E32: 700.779 | F32: 996.503 | G32: 1016.415 | H32: -464.332 | I32: -353.101 | J32: =J29-J33 -> 984.793 | K32: =K29-K33 -> 3378.878 | L32: =L29-L33 -> 4878.383 | M32: =M29-M33 -> 7400.518 | N32: 9686.71 | O32: 4874.523 | P32: =SUM(BB32,BC32,AZ32,BA32) -> 4046.843 | R32: 133.177 | S32: 218.046 | T32: 220.839 | U32: =E32-SUM(R32:T32) -> 128.717 | V32: 365.476 | W32: 121.733 | X32: 253.514 | Y32: =F32-SUM(V32:X32) -> 255.78 | Z32: -98.292 | AA32: 35.031 | AB32: 323.224 | AC32: =G32-SUM(Z32:AB32) -> 756.452 | AD32: 479.294 | AE32: 26.012 | AF32: 2.457 | AG32: =H32-SUM(AD32:AF32) -> -972.095 | AH32: -470.705 | AI32: -648.635 | AJ32: -217.078 | AK32: =I32-SUM(AH32:AJ32) -> 983.317 | AL32: =J32-SUM(AH32:AJ32) -> 2321.211 | AM32: 895.647 | AN32: 2225.853 | AO32: -1692.398 | AP32: -2471.381 | AQ32: 1456.056 | AR32: 3052.403 | AS32: =K32-SUM(AM32,AO32,AQ32) -> 2719.573 | AT32: =L32-SUM(AN32,AP32,AR32) -> 2071.508 | AU32: 2167.307 | AV32: 1260.349 | AW32: 470.48 | AX32: =M32-SUM(AU32,AV32,AW32) -> 3502.382 | AY32: 2413.368 | AZ32: 721.581 | BA32: 1067.466 | BB32: =O32-SUM(AY32,AZ32,BA32) -> 672.108 | BC32: 1585.688 | BE32: 2993.134 | BF32: 1702.084 | BG32: 627.122 | BH32: =N32-SUM(BE32,BF32,BG32) -> 4364.37 | BI32: 3158.323 | BK32: 4875.008 | BL32: 3279.913 | BN32: 5867.97 | BO32: 4593.516 | BQ32: 248.084 | BR32: 431.148 | BS32: 221.05
B33: Non-controlling interests | C33: 11.633166 | D33: 47.738 | E33: 86.842 | F33: 105.922 | G33: 187.17 | H33: 301.913 | I33: 552.621 | J33: 444.713 | K33: 843.886 | L33: 1218.392 | M33: 615.588 | N33: 805.757 | O33: 331.689 | P33: =SUM(BB33,BC33,AZ33,BA33) -> 415.451 | R33: 19.1 | S33: 17.638 | T33: 35.856 | U33: =E33-SUM(R33:T33) -> 14.248 | V33: 33.97 | W33: 24.201 | X33: 19.252 | Y33: =F33-SUM(V33:X33) -> 28.499 | Z33: 54.149 | AA33: 504.443 | AB33: 50.258 | AC33: =G33-SUM(Z33:AB33) -> -421.68 | AD33: 61.83 | AE33: 206.584 | AF33: 30.747 | AG33: =H33-SUM(AD33:AF33) -> 2.752 | AH33: 139.649 | AI33: 94 | AJ33: 116.976 | AK33: =I33-SUM(AH33:AJ33) -> 201.996 | AL33: =J33-SUM(AH33:AJ33) -> 94.088 | AM33: 257.796 | AN33: 264.361 | AO33: 301.596 | AP33: 396.181 | AQ33: 180.013 | AR33: 337.001 | AS33: =K33-SUM(AM33,AO33,AQ33) -> 104.481 | AT33: =L33-SUM(AN33,AP33,AR33) -> 220.849 | AU33: 313.776 | AV33: 74.126 | AW33: 38.492 | AX33: =M33-SUM(AU33,AV33,AW33) -> 189.194 | AY33: 165.677 | AZ33: 34.595 | BA33: 35.515 | BB33: =O33-SUM(AY33,AZ33,BA33) -> 95.902 | BC33: 249.439 | BE33: 433.337 | BF33: 100.107 | BG33: 51.308 | BH33: =N33-SUM(BE33,BF33,BG33) -> 221.005 | BI33: 216.819 | BK33: 559.472 | BL33: 210.225 | BN33: 652.765 | BO33: 261.516 | BQ33: 50.258 | BR33: 61.828 | BS33: 26.013
B35: Check | C35: =+C29-C32-C33 -> -2.6645353e-13 | D35: =+D29-D32-D33 -> 1.7053026e-13 | E35: =+E29-E32-E33 -> -6.9633188e-13 | F35: =+F29-F32-F33 -> 0 | G35: =+G29-G32-G33 -> 3.126388e-13 | H35: =+H29-H32-H33 -> -5.6843419e-13 | I35: =+I29-I32-I33 -> 0 | J35: =+J29-J32-J33 -> 0 | ... P35: =+P29-P32-P33 -> -2.228262e-11 | R35: =+R29-R32-R33 -> 7.8159701e-14 | S35: =+S29-S32-S33 -> 0 | T35: =+T29-T32-T33 -> 0 | U35: =+U29-U32-U33 -> -7.1054274e-14 | V35: =+V29-V32-V33 -> -1.9895197e-13 | W35: =+W29-W32-W33 -> -1.2079227e-13 | X35: =+X29-X32-X33 -> -4.6185278e-14 | Y35: =+Y29-Y32-Y33 -> -3.126388e-13 | ... BC35: =+BC29-BC32-BC33 -> 3.2684966e-12 | BE35: =+BE29-BE32-BE33 -> -4.5474735e-13 | BF35: =+BF29-BF32-BF33 -> 6.5369932e-13 | BG35: =+BG29-BG32-BG33 -> 2.3803182e-12 | BH35: =+BH29-BH32-BH33 -> 8.2991392e-12 | BI35: =+BI29-BI32-BI33 -> -9.3791641e-13 | BK35: =+BK29-BK32-BK33 -> 0 | BL35: =+BL29-BL32-BL33 -> -4.1779913e-12 | BN35: =+BN29-BN32-BN33 -> -6.9348971e-12 | BO35: =+BO29-BO32-BO33 -> -5.8548721e-12 | BQ35: =+BQ29-BQ32-BQ33 -> -7.8159701e-14 | BR35: =+BR29-BR32-BR33 -> 8.5265128e-14 | BS35: =+BS29-BS32-BS33 -> -1.9539925e-13
B37: As % of sales unless stated otherwise
B38: =B9 -> Cost of sales | C38: =-C9/C7 -> 0.74389429 | D38: =-D9/D7 -> 0.74055899 | E38: =-E9/E7 -> 0.73800976 | F38: =-F9/F7 -> 0.72585427 | G38: =-G9/G7 -> 0.71880629 | H38: =-H9/H7 -> 0.71186153 | I38: =-I9/I7 -> 0.7017923 | J38: =-J9/J7 -> 0.78207144 | ... P38: =-P9/P7 -> 0.72417151 | R38: =-R9/R7 -> 0.72918824 | S38: =-S9/S7 -> 0.75061135 | T38: =-T9/T7 -> 0.73215277 | U38: =-U9/U7 -> 0.74040242 | V38: =-V9/V7 -> 0.72292881 | W38: =-W9/W7 -> 0.72031499 | X38: =-X9/X7 -> 0.73685456 | Y38: =-Y9/Y7 -> 0.72349851 | ... BC38: =-BC9/BC7 -> 0.72123852 | BE38: =-BE9/BE7 -> 0.68037026 | BF38: =-BF9/BF7 -> 0.69448392 | BG38: =-BG9/BG7 -> 0.72901614 | BH38: =-BH9/BH7 -> 0.70407076 | BI38: =-BI9/BI7 -> 0.66562734 | BK38: =-BK9/BK7 -> 0.68628067 | BL38: =-BL9/BL7 -> 0.69328946 | BN38: =-BN9/BN7 -> 0.69968467 | BO38: =-BO9/BO7 -> 0.69778555
B39: =B12 -> General Administrative Expenses | C39: =-C12/C7 -> 0.030588817 | D39: =-D12/D7 -> 0.029543597 | E39: =-E12/E7 -> 0.026809468 | F39: =-F12/F7 -> 0.030083351 | G39: =-G12/G7 -> 0.028002541 | H39: =-H12/H7 -> 0.028210795 | I39: =-I12/I7 -> 0.025371879 | J39: =-J12/J7 -> 0.023830978 | ... P39: =-P12/P7 -> 0.027418271 | R39: =-R12/R7 -> 0.024655997 | S39: =-S12/S7 -> 0.030381728 | T39: =-T12/T7 -> 0.027544492 | U39: =-U12/U7 -> 0.025300424 | V39: =-V12/V7 -> 0.019879425 | W39: =-W12/W7 -> 0.030745433 | X39: =-X12/X7 -> 0.035189205 | Y39: =-Y12/Y7 -> 0.034250936 | ... BC39: =-BC12/BC7 -> 0.02739313 | BE39: =-BE12/BE7 -> 0.024554812 | BF39: =-BF12/BF7 -> 0.026183984 | BG39: =-BG12/BG7 -> 0.031363795 | BH39: =-BH12/BH7 -> 0.026569591 | BI39: =-BI12/BI7 -> 0.024491589 | BK39: =-BK12/BK7 -> 0.025237062 | BL39: =-BL12/BL7 -> 0.026039555 | BN39: =-BN12/BN7 -> 0.027158697 | BO39: =-BO12/BO7 -> 0.026503735
B40: =B13 -> Marketing, Sales and Distribution Expenses | C40: =-C13/C7 -> 0.10708168 | D40: =-D13/D7 -> 0.099084517 | E40: =-E13/E7 -> 0.10044584 | F40: =-F13/F7 -> 0.096381447 | G40: =-G13/G7 -> 0.098004321 | H40: =-H13/H7 -> 0.089382695 | I40: =-I13/I7 -> 0.088173688 | J40: =-J13/J7 -> 0.084446691 | ... P40: =-P13/P7 -> 0.11460864 | R40: =-R13/R7 -> 0.10824542 | S40: =-S13/S7 -> 0.090143103 | T40: =-T13/T7 -> 0.10133382 | U40: =-U13/U7 -> 0.10114886 | V40: =-V13/V7 -> 0.10647048 | W40: =-W13/W7 -> 0.09494435 | X40: =-X13/X7 -> 0.081282166 | Y40: =-Y13/Y7 -> 0.10178595 | ... BC40: =-BC13/BC7 -> 0.12120088 | BE40: =-BE13/BE7 -> 0.1041208 | BF40: =-BF13/BF7 -> 0.10708016 | BG40: =-BG13/BG7 -> 0.096645403 | BH40: =-BH13/BH7 -> 0.10191433 | BI40: =-BI13/BI7 -> 0.1205884 | BK40: =-BK13/BK7 -> 0.1053601 | BL40: =-BL13/BL7 -> 0.11796372 | BN40: =-BN13/BN7 -> 0.10262673 | BO40: =-BO13/BO7 -> 0.1142744
B41: =+B14 -> Research and Development Expenses | C41: =C14/C7 -> -0.0020824953 | D41: =D14/D7 -> -0.0028027324 | E41: =E14/E7 -> -0.0021074609 | F41: =F14/F7 -> -0.0025574386 | G41: =G14/G7 -> -0.0025751897 | H41: =H14/H7 -> -0.0031734662 | I41: =I14/I7 -> -0.0031437203 | J41: =J14/J7 -> -0.0031674716 | ... P41: =P14/P7 -> -0.0055150117 | R41: =R14/R7 -> -0.0025893485 | S41: =S14/S7 -> -0.0023851817 | T41: =T14/T7 -> -0.0021513918 | U41: =U14/U7 -> -0.0014923173 | V41: =V14/V7 -> -0.0019749171 | W41: =W14/W7 -> -0.0028854742 | X41: =X14/X7 -> -0.0023511589 | Y41: =Y14/Y7 -> -0.0029881429 | ... BC41: =BC14/BC7 -> -0.0049338737 | BE41: =BE14/BE7 -> -0.0039597124 | BF41: =BF14/BF7 -> -0.0044836182 | BG41: =BG14/BG7 -> -0.0043628213 | BH41: =BH14/BH7 -> -0.0062414804 | BI41: =BI14/BI7 -> -0.0052034843 | BK41: =BK14/BK7 -> -0.0041790995 | BL41: =BL14/BL7 -> -0.0054686763 | BN41: =BN14/BN7 -> -0.0042367185 | BO41: =BO14/BO7 -> -0.0055959701
B42: Financial income as a % of cash | C42: =C23/C127 -> 0.058986839 | D42: =D23/D127 -> 0.008731904 | E42: =E23/E127 -> 0.38032699 | F42: =F23/F127 -> 0.10908332 | G42: =G23/G127 -> 0.074418185 | H42: =H23/H127 -> 0.047202974 | I42: =I23/I127 -> 0.020395906 | J42: =J23/J127 -> 0.02177856 | ... P42: =P23/P127 -> 0.00040902397 | R42: =(SUM(F23:R23)/R127) -> 1.0002644 | S42: =(SUM(P23:S23)/S127) -> 0.0080442698 | T42: =(SUM(P23:T23)/T127) -> 0.1104332 | U42: =(SUM(R23:U23)/U127) -> 0.38032699 | V42: =(SUM(S23:V23)/V127) -> 0.33465657 | W42: =(SUM(T23:W23)/W127) -> 0.32824475 | X42: =(SUM(U23:X23)/X127) -> 0.3588269 | Y42: =(SUM(V23:Y23)/Y127) -> 0.10908332 | Z42: =(SUM(W23:Z23)/Z127) -> 0.11119705 | AA42: =(SUM(X23:AA23)/AA127) -> 0.10057015 | AB42: =(SUM(Y23:AB23)/AB127) -> 0.043842324 | ... AK42: =(SUM(AH23:AK23)/AK127) -> 0.020395906 | AL42: =(SUM(AH23:AJ23,AL23)/AL127) -> 0.02177856 | AM42: =(SUM(AI23:AM23)/AM127) -> 0.053198823 | AN42: =(SUM(AJ23:AN23)/AN127) -> 0.046487476 | AO42: =(SUM(AO23,AM23,AK23,AJ23)/AO127) -> 0.037996702 | AP42: =(SUM(AP23,AN23,AL23,AJ23)/AP127) -> 0.065283941 | AQ42: =(SUM(AQ23,AO23,AM23,AK23)/AQ127) -> 0.021307044 | AR42: =(SUM(AR23,AP23,AN23,AL23)/AR127) -> 0.042307786 | AS42: =(SUM(AS23,AQ23,AO23,AM23)/AS127) -> 0.027299859 | AT42: =(SUM(AT23,AR23,AP23,AN23)/AT127) -> 0.03941516 | AU42: =(SUM(AT23:AU23,AR23,AP23)/AU127) -> 0.019534483 | AV42: =(SUM(AT23:AV23,AR23)/AV127) -> 0.016157916 | AW42: =(SUM(AT23:AW23)/AW127) -> 0.014986057 | AX42: =(SUM(AX23,AV23,AW23,AU23)/AX127) -> 0.0098921139 | AY42: =(SUM(AX23,AY23,AV23,AW23)/AY127) -> 0.010339479 | AZ42: =(SUM(AX23,AY23,AZ23,AW23)/AZ127) -> 0.0077807723 | BA42: =(SUM(AX23:BA23)/BA127) -> 0.006596825 | BB42: =(SUM(BB23,AZ23,BA23,AY23)/BB127) -> 0.00024008468 | BC42: =(SUM(BB23,BC23,AZ23,BA23)/BC127) -> 0.00040902397 | BH42: =(SUM(BH23,BF23,BG23,BE23)/BH127) -> 0.0098921198 | BI42: =(SUM(BI23,BG23,BH23,BF23)/BI127) -> 0.013491588
B43: Financial expenses as a % of debt | C43: =C22/C123 -> -0.21608975 | D43: =D22/D123 -> -0.16315922 | E43: =E22/E123 -> -0.5311735 | F43: =F22/F123 -> -0.2494411 | G43: =G22/G123 -> -0.25408966 | H43: =H22/H123 -> -0.49105209 | I43: =I22/I123 -> -0.34726508 | J43: =J22/J123 -> -0.42002583 | ... P43: =P22/P123 -> -0.3753113 | R43: =(SUM(F22:R22)/R123) -> -33.523896 | S43: =(SUM(P22:S22)/S123) -> -4.7287016 | T43: =(SUM(P22:T22)/T123) -> -3.9421733 | U43: =(SUM(R22:U22)/U123) -> -0.5311735 | V43: =(SUM(S22:V22)/V123) -> -0.50439512 | W43: =(SUM(T22:W22)/W123) -> -0.44808116 | X43: =(SUM(U22:X22)/X123) -> -0.22852813 | Y43: =(SUM(V22:Y22)/Y123) -> -0.2494411 | Z43: =(SUM(W22:Z22)/Z123) -> -0.26259544 | AA43: =(SUM(X22:AA22)/AA123) -> -0.26565083 | AB43: =(SUM(Y22:AB22)/AB123) -> -0.34162717 | ... AK43: =(SUM(AH22:AK22)/AK123) -> -0.34726508 | AL43: =(SUM(AH22:AJ22,AL22)/AL123) -> -0.42002583 | AM43: =(SUM(AI22:AM22)/AM123) -> -0.67837772 | AN43: =(SUM(AJ22:AN22)/AN123) -> -0.68250402 | AO43: =(SUM(AO22,AM22,AK22,AJ22)/AO123) -> -0.45278249 | AP43: =(SUM(AP22,AN22,AL22,AJ22)/AP123) -> -0.97198391 | AQ43: =(SUM(AQ22,AO22,AM22,AK22)/AQ123) -> -0.42279153 | AR43: =(SUM(AR22,AP22,AN22,AL22)/AR123) -> -0.98470391 | AS43: =(SUM(AS22,AQ22,AO22,AM22)/AS123) -> -0.59599955 | AT43: =(SUM(AT22,AR22,AP22,AN22)/AT123) -> -0.86049684 | AU43: =(SUM(AT22:AU22,AR22,AP22)/AU123) -> -0.78677202 | AV43: =(SUM(AT22:AV22,AR22)/AV123) -> -0.42531193 | AW43: =(SUM(AT22:AW22)/AW123) -> -0.35680647 | AX43: =(SUM(AX22,AV22,AW22,AU22)/AX123) -> -0.27350322 | AY43: =(SUM(AX22:AY22,AV22,AW22)/AY123) -> -0.27705461 | AZ43: =(SUM(AX22:AZ22,AW22)/AZ123) -> -0.28916335 | BA43: =(SUM(AX22:BA22)/BA123) -> -0.30079352 | BB43: =(SUM(BB22,AZ22,BA22,AY22)/BB123) -> -0.40739095 | BC43: =(SUM(BB22:BC22,AZ22,BA22)/BC123) -> -0.3753113 | BH43: =(SUM(BH22,BF22,BG22,BE22)/BH123) -> -0.27350322 | BI43: =(SUM(BI22,BG22,BH22,BF22)/BI123) -> -0.35843526
B44: Tax % of PBT | C44: =-(C28+C27)/C26 -> 0.15528895 | D44: =-(D28+D27)/D26 -> 0.15036697 | E44: =-(E28+E27)/E26 -> 0.19097129 | F44: =-(F28+F27)/F26 -> 0.19114313 | G44: =-(G28+G27)/G26 -> 0.19473628 | H44: =-(H28+H27)/H26 -> -1.3027051 | I44: =-(I28+I27)/I26 -> -1.4449183 | J44: =-(J28+J27)/J26 -> -0.041158926 | ... P44: =-(P28+P27)/P26 -> 0.29258364 | R44: =-(R28+R27)/R26 -> 0.22283069 | S44: =-(S28+S27)/S26 -> 0.22218555 | T44: =-(T28+T27)/T26 -> 0.18237241 | U44: =-(U28+U27)/U26 -> 0.11003972 | V44: =-(V28+V27)/V26 -> 0.20787748 | W44: =-(W28+W27)/W26 -> 0.092416384 | X44: =-(X28+X27)/X26 -> 0.20119835 | Y44: =-(Y28+Y27)/Y26 -> 0.20237314 | ... BC44: =-(BC28+BC27)/BC26 -> 0.40548381 | BE44: =-(BE28+BE27)/BE26 -> 0.31622242 | BF44: =-(BF28+BF27)/BF26 -> 0.22932077 | BG44: =-(BG28+BG27)/BG26 -> 0.59375473 | BH44: =-(BH28+BH27)/BH26 -> 0.14019458 | BI44: =-(BI28+BI27)/BI26 -> 0.25422516 | BK44: =-(BK28+BK27)/BK26 -> 0.28966041 | BL44: =-(BL28+BL27)/BL26 -> 0.24527766 | BN44: =-(BN28+BN27)/BN26 -> 0.34098476 | BO44: =-(BO28+BO27)/BO26 -> 0.29333649
...

Sheet KPIs
B2: ÜLKER BÝSKÜVÝ SANAYÝ A.Þ. | C2: Annual | D2: Annual | E2: Annual | F2: Annual | G2: Annual | H2: Annual | I2: Annual | J2: Annual | K2: Annual | L2: Annual | M2: Annual | N2: Annual | O2: Annual | P2: LTM | R2: Quarters | S2: Quarters | T2: Quarters | U2: Quarters | V2: Quarters | W2: Quarters | X2: Quarters | Y2: Quarters | Z2: Quarters | AA2: Quarters | AB2: Quarters | AC2: Quarters | AD2: Quarters | AE2: Quarters | AF2: Quarters | AG2: Quarters | AH2: Quarters | AI2: Quarters | AJ2: Quarters | AK2: Quarters | AL2: Quarters | AM2: Quarters | AN2: Quarters | AO2: Quarters | AP2: Quarters | AQ2: Quarters | AR2: Quarters | AS2: Quarters | AT2: Quarters | AU2: Quarters | AV2: Quarters | AW2: Quarters | AX2: Quarters | AY2: Quarters | BA2: Quarters | BB2: Quarters | BC2: Quarters | BD2: Quarters | BE2: Quarters | BG2: Semi - Annually | BH2: Semi - Annually | BJ2: 9M | BK2: 9M
B3: (TL million) | C3: 42735 | D3: 43100 | E3: 43465 | F3: 43830 | G3: 44196 | H3: 44561 | I3: 44926 | J3: 44926 | K3: 45291 | L3: 45291 | M3: 45657 | N3: 45657 | O3: 46022 | P3: =AY3 -> 46112 | R3: 43190 | S3: 43281 | T3: 43373 | U3: 43465 | V3: 43555 | W3: 43646 | X3: 43738 | Y3: 43830 | Z3: 43921 | AA3: 44012 | AB3: 44104 | AC3: 44196 | AD3: 44286 | AE3: 44377 | AF3: 44469 | AG3: 44561 | AH3: 44651 | AI3: 44742 | AJ3: 44834 | AK3: 44926 | AL3: 45016 | AM3: 45016 | AN3: 45107 | AO3: 45199 | AP3: 45291 | AQ3: 45382 | AR3: 45473 | AS3: 45565 | AT3: 45657 | AU3: 45747 | AV3: 45838 | AW3: 45930 | AX3: 46021 | AY3: 46112 | BA3: 45382 | BB3: 45473 | BC3: 45565 | BD3: 45656 | BE3: 45747 | BG3: 45473 | BH3: 45838 | BJ3: 45565 | BK3: 45930
C4: Act | D4: Act | E4: Act | F4: Act | G4: Act | H4: Act | I4: Act | J4: Restated | K4: Act | L4: Restated | M4: Act | N4: Restated | O4: Act | P4: Act | R4: Act | S4: Act | T4: Act | U4: Act | V4: Act | W4: Act | X4: Act | Y4: Act | Z4: Act | AA4: Act | AB4: Act | AC4: Act | AD4: Act | AE4: Act | AF4: Act | AG4: Act | AH4: Act | AI4: Act | AJ4: Act | AK4: Act | AL4: Act | AM4: Restated | AN4: Act | AO4: Act | AP4: Act | AQ4: Act | AR4: Act | AS4: Act | AT4: Act | AU4: Act | AV4: Act | AW4: Act | AX4: Act | AY4: Act | BA4: Restated | BB4: Restated | BC4: Restated | BD4: Restated | BE4: Restated | BG4: Act | BH4: Act | BJ4: Act | BK4: Act
C5: FY | D5: FY | E5: FY | F5: FY | G5: FY | H5: FY | I5: FY | J5: FY | K5: FY | L5: FY | M5: FY | N5: FY | O5: FY | P5: LTM | R5: 1Q | S5: 2Q | T5: 3Q | U5: 4Q | V5: 1Q | W5: 2Q | X5: 3Q | Y5: 4Q | Z5: 1Q | AA5: 2Q | AB5: 3Q | AC5: 4Q | AD5: 1Q | AE5: 2Q | AF5: 3Q | AG5: 4Q | AH5: 1Q | AI5: 2Q | AJ5: 3Q | AK5: 4Q | AL5: 1Q | AM5: 1Q | AN5: 2Q | AO5: 3Q | AP5: 4Q | AQ5: 1Q | AR5: 2Q | AS5: 3Q | AT5: 4Q | AU5: 1Q | AV5: 2Q | AW5: 3Q | AX5: 4Q | AY5: 1Q | BA5: 1Q | BB5: 2Q | BC5: 3Q | BD5: 4Q | BE5: 1Q | BG5: 1H | BH5: 1H | BJ5: 9M | BK5: 9M
B8: Revenue by business segment
B9: Domestic | D9: 3173.193 | E9: 3709.288 | F9: 4728.447 | G9: 5606.929 | H9: 7386.841 | I9: 17482.255 | J9: =33287.39 -> 33287.39 | K9: 38076.576 | L9: 92193.212 | M9: 76189.509 | N9: 99726.223 | O9: 103118.66 | P9: =SUM(AV9:AY9) -> 110717 | R9: 930.381 | S9: =1807.14-R9 -> 876.759 | T9: =2700.129-S9-R9 -> 892.989 | U9: =+E9-SUM(R9:T9) -> 1009.159 | V9: 1202.223 | W9: =2320.967-V9 -> 1118.744 | X9: =3499.827-V9-W9 -> 1178.86 | Y9: =+F9-SUM(V9:X9) -> 1228.62 | Z9: 1474.956 | AA9: =2736.219-Z9 -> 1261.263 | AB9: =4047.242-Z9-AA9 -> 1311.023 | AC9: =+G9-SUM(Z9:AB9) -> 1559.687 | AD9: 1681.246 | AE9: =3169.435-AD9 -> 1488.189 | AF9: =5148.731-AD9-AE9 -> 1979.296 | AG9: =+H9-SUM(AD9:AF9) -> 2238.11 | AH9: 3506.874 | AI9: =7089.243-AH9 -> 3582.369 | AJ9: =11813.999-AH9-AI9 -> 4724.756 | AK9: =+I9-SUM(AH9:AJ9) -> 5668.256 | AL9: 6659.227 | AM9: 11477.348 | AN9: =12859.019-AL9 -> 6199.792 | AO9: =20920.052-AL9-AN9 -> 8061.033 | AP9: =+K9-SUM(AL9:AO9) -> 5679.176 | AQ9: 13416.966 | AR9: =25336.366-AQ9 -> 11919.4 | AS9: =40904.033-AQ9-AR9 -> 15567.667 | AU9: 25559.447 | AV9: 21132.488 | AW9: 23096.503 | AX9: =O9-SUM(AU9:AW9) -> 33330.223 | AY9: 33157.781 | BA9: 25188.647 | BB9: 18884.78 | BC9: 22027.66 | BD9: =N9-SUM(BA9:BC9) -> 33625.136 | BE9: 33449.106 | BG9: 45586.436 | BH9: 48227.219 | BJ9: 71035.079 | BK9: 74942.876
B10: Foreign | D10: 1652.455 | E10: 2246.22 | F10: 3074.673 | G10: 3793.932 | H10: 5150.239 | I10: 10714.592 | J10: 18693.818 | K10: 17759.565 | L10: 15975.816 | M10: 15607.316 | N10: 20428.779 | O10: 21326.493 | P10: =SUM(AV10:AY10) -> 22652.167 | R10: 477.309 | S10: =912.819-R10 -> 435.51 | T10: =1457.504-S10-R10 -> 544.685 | U10: =+E10-SUM(R10:T10) -> 788.716 | V10: 740.137 | W10: =1441.891-V10 -> 701.754 | X10: =2156.14-V10-W10 -> 714.249 | Y10: =+F10-SUM(V10:X10) -> 918.533 | Z10: 901.17 | AA10: =1784.548-Z10 -> 883.378 | AB10: =2702.324-Z10-AA10 -> 917.776 | AC10: =+G10-SUM(Z10:AB10) -> 1091.608 | AD10: 1102.511 | AE10: =2062.659-AD10 -> 960.148 | AF10: =3270.226-AD10-AE10 -> 1207.567 | AG10: =+H10-SUM(AD10:AF10) -> 1880.013 | AH10: 2379.144 | AI10: =4787.817-AH10 -> 2408.673 | AJ10: =7364.881-AH10-AI10 -> 2577.064 | AK10: =+I10-SUM(AH10:AJ10) -> 3349.711 | AL10: 3452.529 | AM10: 5869.507 | AN10: =6764.591-AL10 -> 3312.062 | AO10: =11112.136-AL10-AN10 -> 4347.545 | AP10: =+K10-SUM(AL10:AO10) -> 777.922 | AQ10: 6183.97 | AR10: =11221.335-AQ10 -> 5037.365 | AS10: =17110.852-AQ10-AR10 -> 5889.517 | AU10: 3920.202 | AV10: 4460.924 | AW10: 5405.227 | AX10: =O10-SUM(AU10:AW10) -> 7540.14 | AY10: 5245.876 | BA10: 4563.131 | BB10: 3856.679 | BC10: 4391.578 | BD10: =N10-SUM(BA10:BC10) -> 7617.391 | BE10: 5130.285 | BG10: 8693.905 | BH10: 8616.602 | BJ10: 13737.906 | BK10: 14668.452
B11: Sales returns and discounts (-) | L11: -27553.494 | M11: -7698.917 | N11: -10077.292 | O11: -12540.553 | P11: =SUM(AV11:AY11) -> -14520.457 | AU11: -2517.332 | AV11: -2535.727 | AW11: -3090.597 | AX11: =O11-SUM(AU11:AW11) -> -4396.897 | AY11: -4497.236 | BA11: -2682.135 | BB11: -2066.416 | BC11: -2164.52 | BD11: =N11-SUM(BA11:BC11) -> -3164.221 | BE11: -3294.38 | BG11: -4909.657 | BH11: -5204.268 | BJ11: -7442.618 | BK11: -8685.413
B12: Total | D12: =SUM(D9:D11) -> 4825.648 | E12: =SUM(E9:E11) -> 5955.508 | F12: =SUM(F9:F11) -> 7803.12 | G12: =SUM(G9:G11) -> 9400.861 | H12: =SUM(H9:H11) -> 12537.08 | I12: =SUM(I9:I11) -> 28196.847 | J12: =SUM(J9:J11) -> 51981.208 | K12: =SUM(K9:K11) -> 55836.141 | ... P12: =SUM(P9:P11) -> 118848.71 | R12: =SUM(R9:R10) -> 1407.69 | S12: =SUM(S9:S10) -> 1312.269 | T12: =SUM(T9:T10) -> 1437.674 | U12: =SUM(U9:U10) -> 1797.875 | V12: =SUM(V9:V10) -> 1942.36 | W12: =SUM(W9:W10) -> 1820.498 | X12: =SUM(X9:X10) -> 1893.109 | Y12: =SUM(Y9:Y10) -> 2147.153 | Z12: =SUM(Z9:Z10) -> 2376.126 | AA12: =SUM(AA9:AA11) -> 2144.641 | AB12: =SUM(AB9:AB11) -> 2228.799 | AC12: =SUM(AC9:AC11) -> 2651.295 | AD12: =SUM(AD9:AD11) -> 2783.757 | AE12: =SUM(AE9:AE11) -> 2448.337 | AF12: =SUM(AF9:AF11) -> 3186.863 | AG12: =SUM(AG9:AG11) -> 4118.123 | AH12: =SUM(AH9:AH11) -> 5886.018 | ... AY12: =SUM(AY9:AY11) -> 33906.421 | BA12: =SUM(BA9:BA11) -> 27069.643 | BB12: =SUM(BB9:BB11) -> 20675.043 | BC12: =SUM(BC9:BC11) -> 24254.718 | BD12: =SUM(BD9:BD11) -> 38078.306 | BE12: =SUM(BE9:BE11) -> 35285.011 | BG12: =SUM(BG9:BG11) -> 49370.684 | BH12: =SUM(BH9:BH11) -> 51639.553 | BJ12: =SUM(BJ9:BJ11) -> 77330.367 | BK12: =SUM(BK9:BK11) -> 80925.915
B13: Check | D13: =+D12-Model!D7 -> 0 | E13: =+E12-Model!E7 -> 0 | F13: =+F12-Model!F7 -> 0 | G13: =+G12-Model!G7 -> 0 | H13: =+H12-Model!H7 -> 0 | I13: =+I12-Model!I7 -> 0 | J13: =+J12-Model!J7 -> 0 | K13: =+K12-Model!K7 -> 0 | ... P13: =+P12-Model!P7 -> 0 | R13: =+R12-Model!R7 -> 0 | S13: =+S12-Model!S7 -> 0 | T13: =+T12-Model!T7 -> 0 | U13: =+U12-Model!U7 -> 0 | V13: =+V12-Model!V7 -> 0 | W13: =+W12-Model!W7 -> 0 | X13: =+X12-Model!X7 -> 0 | Y13: =+Y12-Model!Y7 -> 0 | ... AC13: =+AC12-Model!AC7 -> 0 | AD13: =+AD12-Model!BR7 -> 0 | AE13: =+AE12-Model!AE7 -> -94.079 | AF13: =((+AF12-Model!AF7)-(8418.957-SUM(Model!AD7:AF7))) -> -1.3642421e-12 | AG13: =((+AG12-Model!AG7))+(8418.957-SUM(Model!AD7:AF7)) -> 0 | AH13: =+AH12-Model!AH7 -> 0 | AI13: =+AI12-Model!AI7 -> 0 | AJ13: =((+AJ12-Model!AJ7)-(19178.88-SUM(Model!AH7:AJ7))) -> 0 | AK13: =+AK12-Model!AK7 -> 0 | AL13: =+AL12-Model!AM7 -> 0 | AM13: =+AM12-Model!AN7 -> 0 | AN13: =+AN12-Model!AO7 -> 0 | AO13: =+AO12-Model!AQ7 -> 0 | AP13: =+AP12-Model!AS7 -> -17346.855 | AQ13: =+AQ12-Model!AU7 -> 0 | AR13: =+AR12-Model!AV7 -> 1647.436 | AS13: =+AS12-Model!AW7 -> 3260.779 | AU13: =+AU12-Model!AY7 -> 0 | AV13: =+AV12-Model!AZ7 -> 0 | AW13: =+AW12-Model!BA7 -> 0 | AX13: =+AX12-Model!BB7 -> 0 | AY13: =+AY12-Model!BC7 -> 0 | BA13: =BA12-Model!BE7 -> 0 | BB13: =BB12-Model!BF7 -> 0 | BC13: =BC12-Model!BG7 -> 0 | BD13: =BD12-Model!BH7 -> 0 | BE13: =BE12-Model!BI7 -> 0 | BG13: =BG12-Model!BK7 -> 0 | BH13: =BH12-Model!BL7 -> 0 | BJ13: =BJ12-Model!BN7 -> 0 | BK13: =BK12-Model!BO7 -> 0
B15: % of Revenue by business segment
B16: =+B9 -> Domestic | D16: =+D9/D$12 -> 0.65756827 | E16: =+E9/E$12 -> 0.62283318 | F16: =+F9/F$12 -> 0.60596877 | G16: =+G9/G$12 -> 0.59642718 | H16: =+H9/H$12 -> 0.58919948 | I16: =+I9/I$12 -> 0.62000744 | J16: =+J9/J$12 -> 0.64037354 | K16: =+K9/K$12 -> 0.68193423 | ... P16: =+P9/P$12 -> 0.93157931 | R16: =+R9/R$12 -> 0.66092748 | S16: =+S9/S$12 -> 0.66812445 | T16: =+T9/T$12 -> 0.62113455 | U16: =+U9/U$12 -> 0.56130654 | V16: =+V9/V$12 -> 0.61894963 | W16: =+W9/W$12 -> 0.61452635 | X16: =+X9/X$12 -> 0.62271111 | Y16: =+Y9/Y$12 -> 0.57220887 | ... AY16: =+AY9/AY$12 -> 0.97792041 | BA16: =+BA9/BA$12 -> 0.93051271 | BB16: =+BB9/BB$12 -> 0.91340947 | BC16: =+BC9/BC$12 -> 0.90818042 | BD16: =+BD9/BD$12 -> 0.88305231 | BE16: =+BE9/BE$12 -> 0.94796927 | BG16: =+BG9/BG$12 -> 0.9233503 | BH16: =+BH9/BH$12 -> 0.93392015 | BJ16: =+BJ9/BJ$12 -> 0.91859229 | BK16: =+BK9/BK$12 -> 0.9260677
B17: =+B10 -> Foreign | D17: =+D10/D$12 -> 0.34243173 | E17: =+E10/E$12 -> 0.37716682 | F17: =+F10/F$12 -> 0.39403123 | G17: =+G10/G$12 -> 0.40357282 | H17: =+H10/H$12 -> 0.41080052 | I17: =+I10/I$12 -> 0.37999256 | J17: =+J10/J$12 -> 0.35962646 | K17: =+K10/K$12 -> 0.31806577 | ... P17: =+P10/P$12 -> 0.19059667 | R17: =+R10/R$12 -> 0.33907252 | S17: =+S10/S$12 -> 0.33187555 | T17: =+T10/T$12 -> 0.37886545 | U17: =+U10/U$12 -> 0.43869346 | V17: =+V10/V$12 -> 0.38105037 | W17: =+W10/W$12 -> 0.38547365 | X17: =+X10/X$12 -> 0.37728889 | Y17: =+Y10/Y$12 -> 0.42779113 | ... AY17: =+AY10/AY$12 -> 0.1547163 | BA17: =+BA10/BA$12 -> 0.16857005 | BB17: =+BB10/BB$12 -> 0.18653789 | BC17: =+BC10/BC$12 -> 0.18106077 | BD17: =+BD10/BD$12 -> 0.20004543 | BE17: =+BE10/BE$12 -> 0.14539559 | BG17: =+BG10/BG$12 -> 0.17609448 | BH17: =+BH10/BH$12 -> 0.16686051 | BJ17: =+BJ10/BJ$12 -> 0.17765215 | BK17: =+BK10/BK$12 -> 0.18125778
B18: Sales returns and discounts (-) | D18: =+D11/D$12 -> 0 | E18: =+E11/E$12 -> 0 | F18: =+F11/F$12 -> 0 | G18: =+G11/G$12 -> 0 | H18: =+H11/H$12 -> 0 | I18: =+I11/I$12 -> 0 | J18: =+J11/J$12 -> 0 | K18: =+K11/K$12 -> 0 | ... P18: =+P11/P$12 -> -0.12217598 | R18: =+R11/R$12 -> 0 | S18: =+S11/S$12 -> 0 | T18: =+T11/T$12 -> 0 | U18: =+U11/U$12 -> 0 | V18: =+V11/V$12 -> 0 | W18: =+W11/W$12 -> 0 | X18: =+X11/X$12 -> 0 | Y18: =+Y11/Y$12 -> 0 | ... AY18: =+AY11/AY$12 -> -0.13263671 | BA18: =+BA11/BA$12 -> -0.099082762 | BB18: =+BB11/BB$12 -> -0.099947362 | BC18: =+BC11/BC$12 -> -0.089241194 | BD18: =+BD11/BD$12 -> -0.083097735 | BE18: =+BE11/BE$12 -> -0.093364857 | BG18: =+BG11/BG$12 -> -0.099444784 | BH18: =+BH11/BH$12 -> -0.10078066 | BJ18: =+BJ11/BJ$12 -> -0.096244442 | BK18: =+BK11/BK$12 -> -0.10732548
B19: Total | D19: =SUM(D16:D18) -> 1 | E19: =SUM(E16:E18) -> 1 | F19: =SUM(F16:F18) -> 1 | G19: =SUM(G16:G18) -> 1 | H19: =SUM(H16:H18) -> 1 | I19: =SUM(I16:I18) -> 1 | J19: =SUM(J16:J18) -> 1 | K19: =SUM(K16:K18) -> 1 | ... P19: =SUM(P16:P18) -> 1 | R19: =SUM(R16:R18) -> 1 | S19: =SUM(S16:S18) -> 1 | T19: =SUM(T16:T18) -> 1 | U19: =SUM(U16:U18) -> 1 | V19: =SUM(V16:V18) -> 1 | W19: =SUM(W16:W18) -> 1 | X19: =SUM(X16:X18) -> 1 | Y19: =SUM(Y16:Y18) -> 1 | ... AY19: =SUM(AY16:AY18) -> 1 | BA19: =SUM(BA16:BA18) -> 1 | BB19: =SUM(BB16:BB18) -> 1 | BC19: =SUM(BC16:BC18) -> 1 | BD19: =SUM(BD16:BD18) -> 1 | BE19: =SUM(BE16:BE18) -> 1 | BG19: =SUM(BG16:BG18) -> 1 | BH19: =SUM(BH16:BH18) -> 1 | BJ19: =SUM(BJ16:BJ18) -> 1 | BK19: =SUM(BK16:BK18) -> 1
B21: EBITDA by business segment
