Workbook
Name IQ_CH: 110000
Name IQ_CQ: 5000
Name IQ_CY: 10000
Name IQ_DAILY: 500000
Name IQ_FH: 100000
Name IQ_FQ: 500
Name IQ_FY: 1000
Name IQ_LTM: 2000
Name IQ_MONTH: 15000
Name IQ_NTM: 6000
Name IQ_WEEK: 50000
Name IQ_YTD: 3000

Sheet Capitalization
A2: 1Q26 | I2: Exchange rate as at end | J2: =Model!$R$216 -> 0.24697456
I3: LTM Average exchange rate | J3: =Model!$R$217 -> 0.2404492
C5: Amount outstanding as on 31-Mar-2026 | D5: MYR (mn) | E5: USD (mn) | F5: Leverage (RM) | G5: Leverage (USD) | I5: Company reported | J5: =F5 -> Leverage (RM)
I6: Group Borrowings | J6: 15098
C7: Short-term debt | I7: Group Cash | J7: 3624
C8: Secured | D8: =Model!$BM$108 -> 91.315 | E8: =+D8*J2 -> 22.552482 | I8: Net debt / EBITDA | J8: 2.51x
C9: Unsecured | D9: =Model!$BM$109 -> 4621.096 | E9: =+D9*J2 -> 1141.2932
C10: Lease liabilities | D10: =Model!$BM$110 -> 325.305 | E10: =+D10*J2 -> 80.34206
C11: Long-term debt
C12: Secured | D12: =Model!$BM$113 -> 3653.265 | E12: =+D12*J2 -> 902.26352
C13: Unsecured | D13: =Model!$BM$114 -> 6732.13 | E13: =+D13*J2 -> 1662.6649
C14: Lease liabilities | D14: =Model!$BM$115 -> 1471.271 | E14: =+D14*J2 -> 363.36651
C15: Total Loans & Borrows | D15: =SUM(D8:D14) -> 16894.382 | E15: =SUM(E8:E14) -> 4172.4826 | F15: =+D15/D20 -> 3.8730008 | G15: =+E15/E20 -> 3.9781072
C16: Cash & Equivalents | D16: =Model!$BM$123 -> 2413.057 | E16: =+D16*J2 -> 595.96369
C17: Net debt | D17: =+D15-D16 -> 14481.325 | E17: =+E15-E16 -> 3576.5189 | F17: =+D17/D20 -> 3.3198127 | G17: =+E17/E20 -> 3.4099065
C18: Equity | D18: =Model!$BM$131 -> 23762.062 | E18: =+D18*J2 -> 5868.6248
C19: Total Capitalisation | D19: =D15+D18 -> 40656.444 | E19: =E15+E18 -> 10041.107 | F19: =D19/D20 -> 9.3204025 | G19: =E19/E20 -> 9.5733416
C20: LTM Adjusted EBITDA | D20: =Model!$BM$90 -> 4362.091 | E20: =D20*J3 -> 1048.8613
C21: check | D21: =+D15-Model!$BM$116 -> 0
C24: Liquidity Table at end-1Q26 | D24: =D5 -> MYR (mn) | E24: USD (mn)
C25: Deposits, cash and bank balances | D25: 3623.942 | E25: =D25*J2 -> 895.02149
C26: Less:
C27: Deposits pledged and restricted cash | D27: -173.115 | E27: =D27*J2 -> -42.755001
C28: Deposits maturing more than three (3) months | D28: -918.252 | E28: =D28*J2 -> -226.78489
C29: Bank overdraft | D29: -119.518 | E29: =D29*J2 -> -29.517906
C30: Total | D30: =SUM(D25:D29) -> 2413.057 | E30: =SUM(E25:E29) -> 595.96369
C33: Foreign currency borrowings and debt securities by currency at end-1Q26 | D33: =D5 -> MYR (mn) | E33: USD (mn)
C34: USD | D34: 6971.698 | E34: =D34*J2 -> 1721.8321
C35: IDR | D35: 1945.09 | E35: =D35*J2 -> 480.38775
C36: BDT | D36: 118.83 | E36: =D36*J2 -> 29.347987
C37: LKR | D37: 748.527 | E37: =D37*J2 -> 184.86713
C38: PHP | D38: 1717.941 | E38: =D38*J2 -> 424.28773
C39: Others | D39: 14.596 | E39: =D39*J2 -> 3.6048407
C40: Total debt | D40: =SUM(D34:D39) -> 11516.682 | E40: =SUM(E34:E39) -> 2844.3275
C43: Debt maturity at end-1Q26 (from BBG) | D43: =D5 -> MYR (mn) | E43: USD (mn)
C44: 2027 | D44: 1531.7 | E44: =D44*J2 -> 378.29094
C45: 2028 | D45: 29.5 | E45: =D45*J2 -> 7.2857496
C46: 2029 | D46: 396.55 | E46: =D46*J2 -> 97.937762
C47: 2030 | D47: 1989.65 | E47: =D47*J2 -> 491.39294
C48: 2031+ | D48: =15056.88-SUM(D44:D47) -> 11109.48 | E48: =D48*J2 -> 2743.759
...

Sheet Model
B2: Axiata | C2: Annual | D2: Annual | E2: Annual | F2: Annual | G2: Annual | H2: Annual | I2: Annual | J2: Annual | K2: Annual | L2: Annual | M2: Annual | N2: Annual | O2: Annual | P2: Annual | Q2: Annual | R2: LTM | T2: Quarterly | U2: Quarterly | V2: Quarterly | W2: Quarterly | X2: Quarterly | Y2: Quarterly | Z2: Quarterly | AA2: Quarterly | AB2: Quarterly | AC2: Quarterly | AD2: Quarterly | AE2: Quarterly | AF2: Quarterly | AG2: Quarterly | AH2: Quarterly | AI2: Quarterly | AJ2: Quarterly | AK2: Quarterly | AL2: Quarterly | AM2: Quarterly | AN2: Quarterly | AO2: Quarterly | AP2: Quarterly | AQ2: Quarterly | AR2: Quarterly | AS2: Quarterly | AT2: Quarterly | AU2: Quarterly | AV2: Quarterly | AW2: Quarterly | AX2: Quarterly | AY2: Quarterly | AZ2: Quarterly | BA2: Quarterly | BB2: Quarterly | BC2: Quarterly | BD2: Quarterly | BE2: Quarterly | BF2: Quarterly | BG2: Quarterly | BH2: Quarterly | BI2: Quarterly | BJ2: Quarterly | BK2: Quarterly | BL2: Quarterly | BM2: Quarterly | BO2: Quarterly | BP2: Quarterly | BQ2: Quarterly | BR2: Quarterly | BS2: Quarterly | BT2: Quarterly | BV2: 6M | BW2: 6M | BY2: 9M | BZ2: 9M | CB2: Quarterly | CC2: Quarterly
B3: (MYR millions) | C3: 42707 | D3: 43073 | E3: 43438 | F3: 43803 | G3: 44169 | H3: 44561 | I3: 44926 | J3: 44561 | K3: 44926 | L3: 44926 | M3: 45291 | N3: 45291 | O3: 45657 | P3: 45657 | Q3: 46022 | R3: =BM3 -> 46112 | T3: 43190 | U3: 43281 | V3: 43373 | W3: 43465 | X3: 43555 | Y3: 43646 | Z3: 43738 | AA3: 43830 | AB3: 43921 | AC3: 44012 | AD3: 44104 | AE3: 44196 | AF3: 44286 | AG3: 44377 | AH3: 44469 | AI3: 44561 | AJ3: 44286 | AK3: 44377 | AL3: 44469 | AM3: 44561 | AN3: 44651 | AO3: 44742 | AP3: 44834 | AQ3: 44926 | AR3: 44651 | AS3: 44742 | AT3: 44834 | AU3: 44926 | AV3: 44834 | AW3: 44926 | AX3: 45016 | AY3: 45016 | AZ3: 45107 | BA3: 45107 | BB3: 45199 | BC3: 45199 | BD3: 45291 | BE3: 45382 | BF3: 45473 | BG3: 45565 | BH3: 45657 | BI3: 45747 | BJ3: 45838 | BK3: 45930 | BL3: 46022 | BM3: 46112 | BO3: 45291 | BP3: 45382 | BQ3: 45473 | BR3: 45565 | BS3: 45657 | BT3: 45747 | BV3: 45473 | BW3: 45838 | BY3: 45565 | BZ3: 45930 | CB3: 45657 | CC3: 46022
C4: Act | D4: Act | E4: Act | F4: Act | G4: Act | H4: Act | I4: Act | J4: Act | K4: Act | L4: Act | M4: Act | N4: Act | O4: Act | P4: Act | Q4: Act | R4: Act | T4: Act | U4: Act | V4: Act | W4: Act | X4: Act | Y4: Act | Z4: Act | AA4: Act | AB4: Act | AC4: Act | AD4: Act | AE4: Act | AF4: Act | AG4: Act | AH4: Act | AI4: Act | AJ4: restated | AK4: restated | AL4: restated | AM4: restated | AN4: Act | AO4: Act | AP4: Act | AQ4: Act | AR4: Restated | AS4: Restated | AT4: Restated | AU4: Restated | AV4: Restated** | AW4: Restated | AX4: Act | AY4: Restated | AZ4: Act | BA4: Restated | BB4: Act | BC4: Restated | BE4: Act | BF4: Act | BG4: Act | BH4: Act | BI4: Act | BJ4: Act | BK4: Act | BL4: Act | BM4: Act | BO4: Act | BP4: Act | BQ4: Act | BR4: Act | BS4: Act | BT4: Act | BV4: Act | BW4: Act | BY4: Act | BZ4: Act | CB4: Act | CC4: Act
C5: FY | D5: FY | E5: FY | F5: FY | G5: FY | H5: FY | I5: FY | J5: FY | K5: FY | L5: FY | M5: FY | N5: FY | O5: FY | P5: FY | Q5: FY | R5: LTM | T5: Q1 | U5: Q2 | V5: Q3 | W5: Q4 | X5: Q1 | Y5: Q2 | Z5: Q3 | AA5: Q4 | AB5: Q1 | AC5: Q2 | AD5: Q3 | AE5: Q4 | AF5: Q1 | AG5: Q2 | AH5: Q3 | AI5: Q4 | AJ5: Q1 | AK5: Q2 | AL5: Q3 | AM5: Q4 | AN5: Q1 | AO5: Q2 | AP5: Q3 | AQ5: Q4 | AR5: Q1 | AS5: Q2 | AT5: Q3 | AU5: Q4 | AV5: Q3 | AW5: Q4 | AX5: Q1 | AY5: Q1 | AZ5: Q2 | BA5: Q2 | BB5: Q3 | BC5: Q3 | BD5: Q4 | BE5: Q1 | BF5: Q2 | BG5: Q3 | BH5: Q4 | BI5: Q1 | BJ5: Q2 | BK5: Q3 | BL5: Q4 | BM5: Q1 | BO5: Q4 | BP5: Q1 | BQ5: Q2 | BR5: Q3 | BS5: Q4 | BT5: Q1 | BV5: 6M | BW5: 6M | BY5: 9M | BZ5: 9M | CB5: Q4 | CC5: Q4
B6: INCOME STATEMENT | J6: Restated | K6: Restated | L6: Restated** | N6: Restated | P6: Restated | BO6: Restated | BP6: Restated | BQ6: Restated | BR6: Restated | BS6: Restated | BT6: Restated | BV6: Restated | BY6: Restated | CB6: Restated | CC6: Restated
B7: Operating revenue | C7: 21565.392 | D7: 24402.401 | E7: 23885.781 | F7: 24583.312 | G7: 24203.171 | H7: 25900.661 | I7: 27522 | J7: 19994.368 | K7: 21725.735 | L7: 20020.28 | M7: 22002.269 | N7: 22318.326 | O7: 22334.617 | P7: 12541.918 | Q7: 11757.997 | R7: =SUM(BJ7:BM7) -> 9468.961 | T7: 5748.249 | U7: 5867.065 | V7: 6003.472 | W7: =E7-V7-U7-T7 -> 6266.995 | X7: 5949.437 | Y7: 6153.614 | Z7: 6213.254 | AA7: =F7-Z7-Y7-X7 -> 6267.007 | AB7: 6036.584 | AC7: 5792.414 | AD7: 6111.657 | AE7: =G7-AD7-AC7-AB7 -> 6262.516 | AF7: 6064.019 | AG7: 6390.064 | AH7: 6542.963 | AI7: =H7-AH7-AG7-AF7 -> 6903.615 | AM7: 5336.465 | AN7: 6469.951 | AO7: 6704.257 | AP7: 7260.318 | AQ7: =I7-SUM(AN7:AP7) -> 7087.474 | AR7: 4983.89 | AS7: 5197.605 | AT7: 5709 | AU7: 5835 | AV7: 5367.383 | AW7: =L7-AR7-AS7-AV7 -> 4471.402 | AX7: 5378.716 | AY7: 4997.228 | AZ7: 5994.526 | BA7: 5592.159 | BB7: 6010 | BC7: 5695.697 | BD7: =M7-AZ7-AX7-BC7 -> 4933.33 | BE7: 5662.084 | BF7: 5755.766 | BG7: 5321.643 | BH7: =O7-SUM(BE7:BG7) -> 5595.124 | BI7: 5088.897 | BJ7: 2966.419 | BK7: 2920.48 | BL7: =Q7-SUM(BI7:BK7) -> 782.201 | BM7: 2799.861 | BO7: =N7-SUM(AY7,BA7,BC7) -> 6033.242 | BP7: 5739.043 | BQ7: 3319.636 | BR7: 3064.998 | BS7: =P7-SUM(BP7:BR7) -> 418.241 | BT7: 2891.857 | BV7: 6508.744 | BW7: 5858.276 | BY7: 9573.74 | BZ7: 8778.756 | CB7: =P7-BY7 -> 2968.178 | CC7: =Q7-BZ7 -> 2979.241
B8: % y-o-y growth | D8: =D7/C7-1 -> 0.13155379 | E8: =E7/D7-1 -> -0.021170868 | F8: =F7/E7-1 -> 0.029202771 | G8: =G7/E7-1 -> 0.013287822 | H8: =H7/F7-1 -> 0.053587124 | I8: =I7/H7-1 -> 0.062598364 | J8: =J7/G7-1 -> -0.17389469 | K8: =K7/J7-1 -> 0.086592735 | L8: =L7/J7-1 -> 0.0012959649 | M8: =M7/L7-1 -> 0.098999065 | N8: =N7/L7-1 -> 0.11478591 | O8: =O7/N7-1 -> 0.00072993826 | P8: =P7/N7-1 -> -0.43804396 | Q8: =Q7/P7-1 -> -0.062504076 | X8: =X7/T7-1 -> 0.034999876 | Y8: =Y7/U7-1 -> 0.048840263 | Z8: =Z7/V7-1 -> 0.034943446 | AA8: =AA7/W7-1 -> 1.9147933e-06 | AB8: =AB7/X7-1 -> 0.014647941 | AC8: =AC7/Y7-1 -> -0.058697214 | AD8: =AD7/Z7-1 -> -0.016351657 | AE8: =AE7/AA7-1 -> -0.00071661002 | ... AI8: =AI7/AE7-1 -> 0.10237084 | AM8: =AM7/AE7-1 -> -0.14787204 | AN8: =AN7/AF7-1 -> 0.066941083 | AO8: =AO7/AG7-1 -> 0.049168991 | AP8: =AP7/AH7-1 -> 0.10963764 | AQ8: =AQ7/AI7-1 -> 0.026632279 | AR8: =AR7/AF7-1 -> -0.17812098 | AS8: =AS7/AG7-1 -> -0.18661143 | AT8: =AT7/AH7-1 -> -0.12745953 | AU8: =AU7/AM7-1 -> 0.093420457 | AV8: =AV7/AH7-1 -> -0.17967089 | AW8: =AW7/AM7-1 -> -0.16210413 | AX8: =AX7/AR7-1 -> 0.079220448 | AY8: =AY7/AS7-1 -> -0.038551795 | AZ8: =AZ7/AS7-1 -> 0.15332466 | BA8: =BA7/AS7-1 -> 0.075910732 | BB8: =BB7/AT7-1 -> 0.052723769 | BC8: =BC7/AV7-1 -> 0.061168357 | BD8: =BD7/AW7-1 -> 0.1033072 | BE8: =BE7/AW7-1 -> 0.26628829 | BF8: =BF7/AX7-1 -> 0.070100373 | BG8: =BG7/BC7-1 -> -0.065673086 | BH8: =BH7/BO7-1 -> -0.072617342 | BI8: =BI7/BP7-1 -> -0.11328474 | BJ8: =BJ7/BQ7-1 -> -0.10640233 | BK8: =BK7/BR7-1 -> -0.047151091 | BL8: =BL7/BS7-1 -> 0.87021598 | BM8: =BM7/BT7-1 -> -0.031812085 | BO8: =BO7/AW7-1 -> 0.34929537 | BP8: =BP7/AY7-1 -> 0.1484453 | BQ8: =BQ7/BA7-1 -> -0.40637668 | BR8: =BR7/BC7-1 -> -0.46187482 | BS8: =BS7/BO7-1 -> -0.93067724 | BT8: =BT7/BP7-1 -> -0.49610815 | BW8: =BW7/BV7-1 -> -0.099937561 | BZ8: =BZ7/BY7-1 -> -0.083037977 | CC8: =CC7/CB7-1 -> 0.0037272023
B9: Depreciation, impairment and amortisation | C9: -5666.505 | D9: -5986.213 | E9: -7644.816 | F9: -7084.236 | G9: -8484.994 | H9: -8094.868 | I9: -7070.912 | J9: -6317.817 | K9: -7070.912 | L9: -7878.003 | M9: -7199.986 | N9: -8202.382 | O9: -7341.195 | P9: -3752.309 | Q9: -3893.444 | R9: =SUM(BJ9:BM9) -> -3007.488 | T9: -1393.211 | U9: -1489.038 | V9: -1511.446 | W9: =E9-V9-U9-T9 -> -3251.121 | X9: -1643.04 | Y9: -1706.761 | Z9: -1846.046 | AA9: =F9-Z9-Y9-X9 -> -1888.389 | AB9: -1848.469 | AC9: -1842.228 | AD9: -1762.142 | AE9: =G9-AD9-AC9-AB9 -> -3032.155 | AF9: -1974.973 | AG9: -1903.392 | AH9: -1983.974 | AI9: =H9-AH9-AG9-AF9 -> -2232.529 | AM9: -1636.167 | AN9: -1860.543 | AO9: -1879.377 | AP9: -2101.416 | AQ9: =I9-SUM(AN9:AP9) -> -1229.576 | AR9: -1608.352 | AS9: -1626.464 | AT9: -1680.506 | AU9: =K9-AR9-AS9-AT9 -> -2155.59 | AV9: -1680.506 | AW9: =L9-AR9-AS9-AV9 -> -2962.681 | AX9: -1812.906 | AY9: -1636.184 | AZ9: -2697.068 | BA9: -1814.368 | BB9: -1859.536 | BC9: -1859.536 | BD9: =M9-AZ9-AX9-BC9 -> -830.476 | BE9: -1916.817 | BF9: -1879.054 | BG9: -1818.854 | BH9: =O9-SUM(BE9:BG9) -> -1726.47 | BI9: -1658.463 | BJ9: -1133.367 | BK9: -1019.063 | BL9: =Q9-SUM(BI9:BK9) -> -82.551 | BM9: -772.507 | BO9: =N9-SUM(AY9,BA9,BC9) -> -2892.294 | BP9: -1897.248 | BQ9: -972.917 | BR9: -944.656 | BS9: =P9-SUM(BP9:BR9) -> 62.512 | BT9: -825.975 | BV9: -1956.151 | BW9: -1959.341 | BY9: -2900.808 | BZ9: -2978.404 | CB9: =P9-BY9 -> -851.501 | CC9: =Q9-BZ9 -> -915.04
B10: Impairment of goodwill | F10: 0 | G10: 0 | H10: 0 | I10: -4145.544 | J10: -340.029 | K10: -4145.544 | L10: 0 | M10: 0 | N10: 0 | O10: 0 | P10: 0 | Q10: 0 | R10: =SUM(BJ10:BM10) -> 0 | AB10: 0 | AC10: 0 | AD10: 0 | AE10: =G10-AD10-AC10-AB10 -> 0 | AF10: 0 | AG10: 0 | AH10: 0 | AI10: =H10-AH10-AG10-AF10 -> 0 | AM10: -338.44 | AN10: 0 | AO10: 0 | AP10: 0 | AQ10: =I10-SUM(AN10:AP10) -> -4145.544 | AR10: 0 | AS10: 0 | AT10: 0 | AU10: =K10-AR10-AS10-AT10 -> -4145.544 | AV10: 0 | AW10: =L10-AR10-AS10-AV10 -> 0 | AX10: 0 | AY10: 0 | AZ10: 0 | BA10: 0 | BB10: 0 | BC10: 0 | BD10: =M10-AZ10-AX10-BC10 -> 0 | BE10: 0 | BF10: 0 | BG10: 0 | BH10: =O10-SUM(BE10:BG10) -> 0 | BI10: 0 | BJ10: 0 | BK10: 0 | BL10: =Q10-SUM(BI10:BK10) -> 0 | BM10: 0 | BO10: =N10-SUM(AY10,BA10,BC10) -> 0 | BP10: 0 | BQ10: 0 | BR10: 0 | BS10: =P10-SUM(BP10:BR10) -> 0 | BT10: 0 | BV10: 0 | BW10: 0 | BY10: 0 | BZ10: 0 | CB10: =P10-BY10 -> 0 | CC10: =Q10-BZ10 -> 0
B11: Foreign exchange gains / (losses) | C11: -85.342 | D11: -191.563 | E11: 8.389 | F11: 5.421 | G11: -196.083 | H11: 58.239 | I11: -420.48 | J11: 58.05 | K11: -420.48 | L11: -388.816 | M11: 143.947 | N11: 47.984 | O11: -311.622 | P11: -195.976 | Q11: -274.503 | R11: =SUM(BJ11:BM11) -> -272.908 | T11: -106.444 | U11: 87.727 | V11: 38.593 | W11: =E11-V11-U11-T11 -> -11.487 | X11: 14.577 | Y11: 5.728 | Z11: 6.295 | AA11: =F11-Z11-Y11-X11 -> -21.179 | AB11: 65.594 | AC11: -6.237 | AD11: -116.412 | AE11: =G11-AD11-AC11-AB11 -> -139.028 | AF11: 72.199 | AG11: 0.011 | AH11: -4.807 | AI11: =H11-AH11-AG11-AF11 -> -9.164 | AM11: -9.858 | AN11: -241.227 | AO11: -175.399 | AP11: 77.356 | AQ11: =I11-SUM(AN11:AP11) -> -81.21 | AR11: -241.187 | AS11: -175.938 | AT11: 62.868 | AU11: =K11-AR11-AS11-AT11 -> -66.223 | AV11: 62.868 | AW11: =L11-AR11-AS11-AV11 -> -34.559 | AX11: 5.831 | AY11: 7.331 | AZ11: 161.552 | BA11: 193.448 | BB11: -12.171 | BC11: -12.171 | BD11: =M11-AZ11-AX11-BC11 -> -11.265 | BE11: 87.886 | BF11: -53.866 | BG11: -368.639 | BH11: =O11-SUM(BE11:BG11) -> 22.997 | BI11: -22.418 | BJ11: -181.799 | BK11: -0.389 | BL11: =Q11-SUM(BI11:BK11) -> -69.897 | BM11: -20.823 | BO11: =N11-SUM(AY11,BA11,BC11) -> -140.624 | BP11: 58.64 | BQ11: -50.578 | BR11: -378.359 | BS11: =P11-SUM(BP11:BR11) -> 174.321 | BT11: -22.145 | BV11: 41.09 | BW11: -203.944 | BY11: -337.268 | BZ11: -204.332 | CB11: =P11-BY11 -> 141.292 | CC11: =Q11-BZ11 -> -70.171
B12: Domestic interconnect and international outpayment | C12: -2096.123 | D12: -2700.723 | E12: -2408.317 | F12: -1980.257 | G12: -1822.171 | H12: -2199.93 | I12: -2148.369 | J12: -1972.088 | K12: -2148.369 | L12: -2227.676 | M12: -2479.354 | N12: -2497.542 | O12: -1953.594 | P12: -1513.718 | Q12: -1206.774 | R12: =SUM(BJ12:BM12) -> -1112.971 | T12: -602.404 | U12: -611.211 | V12: -600.128 | W12: =E12-V12-U12-T12 -> -594.574 | X12: -530.672 | Y12: -502.143 | Z12: -447.204 | AA12: =F12-Z12-Y12-X12 -> -500.238 | AB12: -416.564 | AC12: -417.555 | AD12: -460.999 | AE12: =G12-AD12-AC12-AB12 -> -527.053 | AF12: -417.174 | AG12: -528.876 | AH12: -573.079 | AI12: =H12-AH12-AG12-AF12 -> -680.801 | AM12: -612.062 | AN12: -525.369 | AO12: -538.513 | AP12: -668.257 | AQ12: =I12-SUM(AN12:AP12) -> -416.23 | AR12: -449.868 | AS12: -460.123 | AT12: -568.587 | AU12: =K12-AR12-AS12-AT12 -> -669.791 | AV12: -568.587 | AW12: =L12-AR12-AS12-AV12 -> -749.098 | AX12: -568.686 | AY12: -550.526 | AZ12: -638.854 | BA12: -624.037 | BB12: -666.2 | BC12: -666.2 | BD12: =M12-AZ12-AX12-BC12 -> -605.614 | BE12: -564.354 | BF12: -531.242 | BG12: -421.033 | BH12: =O12-SUM(BE12:BG12) -> -436.965 | BI12: -385.679 | BJ12: -331.558 | BK12: -300.323 | BL12: =Q12-SUM(BI12:BK12) -> -189.214 | BM12: -291.876 | BO12: =N12-SUM(AY12,BA12,BC12) -> -656.779 | BP12: -571.187 | BQ12: -374.752 | BR12: -357.617 | BS12: =P12-SUM(BP12:BR12) -> -210.162 | BT12: -330.493 | BV12: -808.575 | BW12: -662.051 | BY12: -1166.191 | BZ12: -962.374 | CB12: =P12-BY12 -> -347.527 | CC12: =Q12-BZ12 -> -244.4
B13: Marketing, Advertising and promotion | C13: -1817.599 | D13: -2108.755 | E13: -2147.698 | F13: -2001.47 | G13: -1892.272 | H13: -2192.658 | I13: -1862.175 | J13: -1858.864 | K13: -1862.175 | L13: -1757.81 | M13: -1774.327 | N13: -1774.327 | O13: -1537.456 | P13: -1007.41 | Q13: -866.55 | R13: =SUM(BJ13:BM13) -> -759.666 | T13: -550.88 | U13: -565.847 | V13: -506.784 | W13: =E13-V13-U13-T13 -> -524.187 | X13: -488.979 | Y13: -516.257 | Z13: -475.962 | AA13: =F13-Z13-Y13-X13 -> -520.272 | AB13: -497.362 | AC13: -412.348 | AD13: -440.084 | AE13: =G13-AD13-AC13-AB13 -> -542.478 | AF13: -482.756 | AG13: -567.573 | AH13: -566.023 | AI13: =H13-AH13-AG13-AF13 -> -576.306 | AM13: -503.799 | AN13: -537.348 | AO13: -534.164 | AP13: -529.778 | AQ13: =I13-SUM(AN13:AP13) -> -260.885 | AR13: -476.45 | AS13: -449.12 | AT13: -414.772 | AU13: =K13-AR13-AS13-AT13 -> -521.833 | AV13: -414.772 | AW13: =L13-AR13-AS13-AV13 -> -417.468 | AX13: -426.414 | AY13: -405.831 | AZ13: -471.13 | BA13: -450.452 | BB13: -461.877 | BC13: -461.877 | BD13: =M13-AZ13-AX13-BC13 -> -414.906 | BE13: -431.577 | BF13: -436.283 | BG13: -342.545 | BH13: =O13-SUM(BE13:BG13) -> -327.051 | BI13: -304.204 | BJ13: -215.964 | BK13: -214.027 | BL13: =Q13-SUM(BI13:BK13) -> -132.355 | BM13: -197.32 | BO13: =N13-SUM(AY13,BA13,BC13) -> -456.167 | BP13: -431.577 | BQ13: -294.253 | BR13: -215.615 | BS13: =P13-SUM(BP13:BR13) -> -65.965 | BT13: -213.264 | BV13: -583.817 | BW13: -429.227 | BY13: -799.433 | BZ13: -643.254 | CB13: =P13-BY13 -> -207.977 | CC13: =Q13-BZ13 -> -223.296
B14: Other operating costs | C14: -8074.312 | D14: -8455.866 | E14: -8927.499 | F14: -7406.798 | G14: -7305.59 | H14: -7963.233 | I14: -6328.825 | J14: -5685.331 | K14: -6328.825 | L14: -5747.014 | M14: -6128.716 | N14: -6135.272 | O14: -5958.757 | P14: -2949.727 | Q14: -2885.284 | R14: =SUM(BJ14:BM14) -> -2015.33 | T14: -2143.009 | U14: -2121.201 | V14: -2200.231 | W14: =E14-V14-U14-T14 -> -2463.058 | X14: -2005.522 | Y14: -1832.29 | Z14: -1942.82 | AA14: =F14-Z14-Y14-X14 -> -1626.166 | AB14: -1892.56 | AC14: -1870.242 | AD14: -1846.424 | AE14: =G14-AD14-AC14-AB14 -> -1696.364 | AF14: -1924.25 | AG14: -1930.334 | AH14: -1978.687 | AI14: =H14-AH14-AG14-AF14 -> -2129.962 | AM14: -1552.268 | AN14: -1983.515 | AO14: -2089.265 | AP14: -2223.552 | AQ14: =I14-SUM(AN14:AP14) -> -32.493 | AR14: -1417.339 | AS14: -1548.441 | AT14: -1623.2 | AU14: =K14-AR14-AS14-AT14 -> -1739.845 | AV14: -1623.2 | AW14: =L14-AR14-AS14-AV14 -> -1158.034 | AX14: -1507.643 | AY14: -1419.337 | AZ14: -1647.272 | BA14: -1530.464 | BB14: -1528.728 | BC14: -1528.728 | BD14: =M14-AZ14-AX14-BC14 -> -1445.073 | BE14: -1497.033 | BF14: -1513.985 | BG14: -1507.974 | BH14: =O14-SUM(BE14:BG14) -> -1439.765 | BI14: -1516.152 | BJ14: -638.985 | BK14: -687.212 | BL14: =Q14-SUM(BI14:BK14) -> -42.935 | BM14: -646.198 | BO14: =N14-SUM(AY14,BA14,BC14) -> -1656.743 | BP14: -1498.416 | BQ14: -783.627 | BR14: -746.352 | BS14: =P14-SUM(BP14:BR14) -> 78.668 | BT14: -797.215 | BV14: -1515.986 | BW14: -1436.201 | BY14: -2262.338 | BZ14: -2123.414 | CB14: =P14-BY14 -> -687.389 | CC14: =Q14-BZ14 -> -761.87
B15: Staff costs | C15: -1564.71 | D15: -1906.939 | E15: -2068.133 | F15: -2220.2 | G15: -2227.532 | H15: -2071.006 | I15: -1662.47 | J15: -1536.728 | K15: -1662.47 | L15: -1570.643 | M15: -1719.19 | N15: -1731.332 | O15: -1614.394 | P15: -1280.392 | Q15: -1305.327 | R15: =SUM(BJ15:BM15) -> -1187.499 | T15: -415.546 | U15: -525.638 | V15: -525.312 | W15: =E15-V15-U15-T15 -> -601.637 | X15: -502.496 | Y15: -632.397 | Z15: -545.591 | AA15: =F15-Z15-Y15-X15 -> -539.716 | AB15: -650.213 | AC15: -508.519 | AD15: -524.512 | AE15: =G15-AD15-AC15-AB15 -> -544.288 | AF15: -519.665 | AG15: -520.293 | AH15: -551.819 | AI15: =H15-AH15-AG15-AF15 -> -479.229 | AM15: -341.127 | AN15: -499.448 | AO15: -543.211 | AP15: -608.348 | AQ15: =I15-SUM(AN15:AP15) -> -11.463 | AR15: -374.89 | AS15: -395.351 | AT15: -420.163 | AU15: =K15-AR15-AS15-AT15 -> -472.066 | AV15: -420.163 | AW15: =L15-AR15-AS15-AV15 -> -380.239 | AX15: -432.436 | AY15: -410.339 | AZ15: -474.699 | BA15: -450.56 | BB15: -464.415 | BC15: -464.415 | BD15: =M15-AZ15-AX15-BC15 -> -347.64 | BE15: -409.489 | BF15: -423.423 | BG15: -384.29 | BH15: =O15-SUM(BE15:BG15) -> -397.192 | BI15: -401.625 | BJ15: -335.825 | BK15: -340.352 | BL15: =Q15-SUM(BI15:BK15) -> -227.525 | BM15: -283.797 | BO15: =N15-SUM(AY15,BA15,BC15) -> -406.018 | BP15: -412.804 | BQ15: -337.287 | BR15: -309.464 | BS15: =P15-SUM(BP15:BR15) -> -220.837 | BT15: -313.157 | BV15: -665.861 | BW15: -648.983 | BY15: -975.325 | BZ15: -989.335 | CB15: =P15-BY15 -> -305.067 | CC15: =Q15-BZ15 -> -315.992
B16: Impairment on receivables, net / provision for impairment on financial assets | C16: 0 | D16: 0 | E16: 0 | F16: -355.437 | G16: -298.731 | H16: -69.817 | I16: -127.251 | J16: -39.098 | K16: -127.251 | L16: -97.223 | M16: -271.81 | N16: -270.509 | O16: -141.172 | P16: -102.354 | Q16: -33.619 | R16: =SUM(BJ16:BM16) -> -31.404 | T16: 0 | U16: 0 | V16: 0 | W16: =E16-V16-U16-T16 -> 0 | X16: 0 | Y16: 0 | Z16: 0 | AA16: =F16-Z16-Y16-X16 -> -355.437 | AB16: -75.992 | AC16: 0 | AD16: 0 | AE16: =G16-AD16-AC16-AB16 -> -222.739 | AF16: -28.319 | AG16: -32.12 | AH16: -13.969 | AI16: =H16-AH16-AG16-AF16 -> 4.591 | AM16: -5.354 | AN16: -25.808 | AO16: 11.532 | AP16: -26.776 | AQ16: =I16-SUM(AN16:AP16) -> -86.199 | AR16: -19.064 | AS16: -14.9 | AT16: -32.893 | AU16: =K16-AR16-AS16-AT16 -> -60.394 | AV16: -32.893 | AW16: =L16-AR16-AS16-AV16 -> -30.366 | AX16: -26.806 | AY16: -27.921 | AZ16: -33.798 | BA16: -33.461 | BB16: -36.469 | BC16: -36.469 | BD16: =M16-AZ16-AX16-BC16 -> -174.737 | BE16: -22.762 | BF16: -25.634 | BG16: -31.013 | BH16: =O16-SUM(BE16:BG16) -> -61.763 | BI16: -27.021 | BJ16: -4.039 | BK16: -16.146 | BL16: =Q16-SUM(BI16:BK16) -> 13.587 | BM16: -24.806 | BO16: =N16-SUM(AY16,BA16,BC16) -> -172.658 | BP16: -21.513 | BQ16: -16.706 | BR16: -22.098 | BS16: =P16-SUM(BP16:BR16) -> -42.037 | BT16: -18.559 | BV16: -28.755 | BW16: -22.599 | BY16: -50.853 | BZ16: -38.744 | CB16: =P16-BY16 -> -51.501 | CC16: =Q16-BZ16 -> 5.125
B17: Other gains/(losses) - net | C17: -68.161 | D17: -57.655 | E17: -25.242 | F17: -22.601 | G17: 2.693 | H17: 52.034 | I17: 28.225 | J17: 17.026 | K17: 28.225 | L17: 5.348 | M17: -5.342 | N17: -5.342 | O17: -0.852 | P17: -0.852 | Q17: 6.075 | R17: =SUM(BJ17:BM17) -> 5.252 | T17: 20.262 | U17: 49.509 | V17: 27.674 | W17: =E17-V17-U17-T17 -> -122.687 | X17: -22.709 | Y17: -0.089 | Z17: -0.122 | AA17: =F17-Z17-Y17-X17 -> 0.319 | AB17: 0.566 | AC17: 0.61 | AD17: 0.778 | AE17: =G17-AD17-AC17-AB17 -> 0.739 | AF17: 16.202 | AG17: 6.495 | AH17: 41.723 | AI17: =H17-AH17-AG17-AF17 -> -12.386 | AM17: -12.383 | AN17: 11.509 | AO17: 8.756 | AP17: 5.016 | AQ17: =I17-SUM(AN17:AP17) -> 2.944 | AR17: 11.511 | AS17: 8.756 | AT17: -2.315 | AU17: =K17-AR17-AS17-AT17 -> 10.273 | AV17: -2.315 | AW17: =L17-AR17-AS17-AV17 -> -12.604 | AX17: 6.31 | AY17: -1.247 | AZ17: 6.801 | BA17: 1.58 | BB17: 0.132 | BC17: 0.132 | BD17: =M17-AZ17-AX17-BC17 -> -18.585 | BE17: 2.463 | BF17: -0.829 | BG17: 2.007 | BH17: =O17-SUM(BE17:BG17) -> -4.493 | BI17: 2.525 | BJ17: 1.214 | BK17: 1.862 | BL17: =Q17-SUM(BI17:BK17) -> 0.474 | BM17: 1.702 | BO17: =N17-SUM(AY17,BA17,BC17) -> -5.807 | BP17: 2.463 | BQ17: -0.829 | BR17: 2.007 | BS17: =P17-SUM(BP17:BR17) -> -4.493 | BT17: 2.525 | BV17: 1.634 | BW17: 3.74 | BY17: 3.642 | BZ17: 5.601 | CB17: =P17-BY17 -> -4.494 | CC17: =Q17-BZ17 -> 0.474
B18: Other operating income (expenses)- net | C18: 534.566 | D18: 5.37 | E18: -3057.592 | F18: 714.392 | G18: 516.393 | H18: 398.655 | I18: -33.426 | J18: 107.224 | K18: -33.426 | L18: -0.104 | M18: 91.067 | N18: 96.547 | O18: 80.506 | P18: -6.461 | Q18: -2.545 | R18: =SUM(BJ18:BM18) -> -21.78 | T18: 57.774 | U18: -3273.839 | V18: 103.168 | W18: =E18-V18-U18-T18 -> 55.305 | X18: 460.57 | Y18: 145.435 | Z18: 36.168 | AA18: =F18-Z18-Y18-X18 -> 72.219 | AB18: 414.556 | AC18: 10.989 | AD18: 43.671 | AE18: =G18-AD18-AC18-AB18 -> 47.177 | AF18: 69.565 | AG18: 34.565 | AH18: 135.243 | AI18: =H18-AH18-AG18-AF18 -> 159.282 | AM18: 25.195 | AN18: 46.035 | AO18: 22.599 | AP18: -29.547 | AQ18: =I18-SUM(AN18:AP18) -> -72.513 | AR18: 30.184 | AS18: -2.4 | AT18: -82.776 | AU18: =K18-AR18-AS18-AT18 -> 21.566 | AV18: -82.776 | AW18: =L18-AR18-AS18-AV18 -> 54.888 | AX18: 10.993 | AY18: 10.402 | AZ18: -407.09 | BA18: -9.845 | BB18: 26.571 | BC18: 26.571 | BD18: =M18-AZ18-AX18-BC18 -> 460.593 | BE18: 26.161 | BF18: -6.682 | BG18: 12.569 | BH18: =O18-SUM(BE18:BG18) -> 48.458 | BI18: 14.794 | BJ18: 5.903 | BK18: -45.964 | BL18: =Q18-SUM(BI18:BK18) -> 22.722 | BM18: -4.441 | BO18: =N18-SUM(AY18,BA18,BC18) -> 69.419 | BP18: 29.894 | BQ18: -38.019 | BR18: -9.311 | BS18: =P18-SUM(BP18:BR18) -> 10.975 | BT18: 8.492 | BV18: -49.523 | BW18: 14.394 | BY18: -58.829 | BZ18: -31.569 | CB18: =P18-BY18 -> 52.368 | CC18: =Q18-BZ18 -> 29.024
B19: Operating Profit | C19: =C7+SUM(C9:C18) -> 2727.206 | D19: =D7+SUM(D9:D18) -> 3000.057 | E19: =E7+SUM(E9:E18) -> -2385.127 | F19: =F7+SUM(F9:F18) -> 4232.126 | G19: =G7+SUM(G9:G18) -> 2494.884 | H19: =H7+SUM(H9:H18) -> 3818.077 | I19: =I7+SUM(I9:I18) -> 3750.773 | J19: =J7+SUM(J9:J18) -> 2426.713 | ... R19: =R7+SUM(R9:R18) -> 1065.167 | T19: =T7+SUM(T9:T18) -> 614.791 | U19: =U7+SUM(U9:U18) -> -2582.473 | V19: =V7+SUM(V9:V18) -> 829.006 | W19: =W7+SUM(W9:W18) -> -1246.451 | X19: =X7+SUM(X9:X18) -> 1231.166 | Y19: =Y7+SUM(Y9:Y18) -> 1114.84 | Z19: =Z7+SUM(Z9:Z18) -> 997.972 | AA19: =AA7+SUM(AA9:AA18) -> 888.148 | ... AI19: =AI7+SUM(AI9:AI18) -> 947.111 | AM19: =AM7+SUM(AM9:AM18) -> 350.202 | AN19: =AN7+SUM(AN9:AN18) -> 854.237 | AO19: =AO7+SUM(AO9:AO18) -> 987.215 | AP19: =AP7+SUM(AP9:AP18) -> 1155.016 | AQ19: =AQ7+SUM(AQ9:AQ18) -> 754.305 | AR19: =AR7+SUM(AR9:AR18) -> 438.435 | AS19: =AS7+SUM(AS9:AS18) -> 533.624 | AT19: =AT7+SUM(AT9:AT18) -> 946.656 | ... BM19: =BM7+SUM(BM9:BM18) -> 559.795 | BO19: =BO7+SUM(BO9:BO18) -> -284.429 | BP19: =BP7+SUM(BP9:BP18) -> 997.295 | BQ19: =BQ7+SUM(BQ9:BQ18) -> 450.668 | BR19: =BR7+SUM(BR9:BR18) -> 83.533 | BS19: =BS7+SUM(BS9:BS18) -> 201.223 | BT19: =BT7+SUM(BT9:BT18) -> 382.066 | BV19: =BV7+SUM(BV9:BV18) -> 942.8 | BW19: =BW7+SUM(BW9:BW18) -> 514.064 | BY19: =BY7+SUM(BY9:BY18) -> 1026.337 | BZ19: =BZ7+SUM(BZ9:BZ18) -> 812.931 | CB19: =CB7+SUM(CB9:CB18) -> 706.382 | CC19: =CC7+SUM(CC9:CC18) -> 483.095
B20: Finance Income | C20: 183.394 | D20: 241.807 | E20: 221.459 | F20: 230.468 | G20: 177.183 | H20: 150.982 | I20: 255.274 | J20: 179.684 | K20: 255.274 | L20: 223.805 | M20: 248.363 | N20: 287.17 | O20: 265.646 | P20: 176.326 | Q20: 169.717 | R20: =SUM(BJ20:BM20) -> 138.061 | T20: 61.299 | U20: 53.411 | V20: 50.768 | W20: =E20-V20-U20-T20 -> 55.981 | X20: 56.381 | Y20: 55.022 | Z20: 65.886 | AA20: =F20-Z20-Y20-X20 -> 53.179 | AB20: 42.137 | AC20: 48.1 | AD20: 46.917 | AE20: =G20-AD20-AC20-AB20 -> 40.029 | AF20: 34.469 | AG20: 37.003 | AH20: 39.153 | AI20: =H20-AH20-AG20-AF20 -> 40.357 | AM20: 48.56 | AN20: 36.735 | AO20: 43.721 | AP20: 58.39 | AQ20: =I20-SUM(AN20:AP20) -> 116.428 | AR20: 44.836 | AS20: 51.611 | AT20: 57.349 | AU20: =K20-AR20-AS20-AT20 -> 101.478 | AV20: 57.349 | AW20: =L20-AR20-AS20-AV20 -> 70.009 | AX20: 83.871 | AY20: 69.662 | AZ20: 76.942 | BA20: 62.383 | BB20: 69.595 | BC20: 69.595 | BD20: =M20-AZ20-AX20-BC20 -> 17.955 | BE20: 57.936 | BF20: 41.635 | BG20: 55.01 | BH20: =O20-SUM(BE20:BG20) -> 111.065 | BI20: 66.343 | BJ20: 49.339 | BK20: 43.11 | BL20: =Q20-SUM(BI20:BK20) -> 10.925 | BM20: 34.687 | BO20: =N20-SUM(AY20,BA20,BC20) -> 85.53 | BP20: 72.159 | BQ20: 36.79 | BR20: 47.809 | BS20: =P20-SUM(BP20:BR20) -> 19.568 | BT20: 36.851 | BV20: 89.993 | BW20: 86.191 | BY20: 137.802 | BZ20: 129.302 | CB20: =P20-BY20 -> 38.524 | CC20: =Q20-BZ20 -> 40.415
B21: Finance cost excluding net foreign exchange gains / (losses) on financing activities | C21: -1201.184 | D21: -1253.369 | E21: -1272.385 | F21: -1738.473 | G21: -1693.067 | H21: -1565.069 | I21: -1827.015 | J21: -1411.448 | K21: -1827.015 | L21: -1702.229 | M21: -2287.869 | N21: -2296.617 | O21: -2345.021 | P21: -1419.573 | Q21: -1248.83 | R21: =SUM(BJ21:BM21) -> -985.55 | T21: -302.522 | U21: -314.951 | V21: -323.633 | W21: =E21-V21-U21-T21 -> -331.279 | X21: -408.922 | Y21: -464.566 | Z21: -435.309 | AA21: =F21-Z21-Y21-X21 -> -429.676 | AB21: -426.235 | AC21: -427.087 | AD21: -429.448 | AE21: =G21-AD21-AC21-AB21 -> -410.297 | AF21: -362.309 | AG21: -376.835 | AH21: -379.092 | AI21: =H21-AH21-AG21-AF21 -> -446.833 | AM21: -412.488 | AN21: -403.26 | AO21: -434.955 | AP21: -522.555 | AQ21: =I21-SUM(AN21:AP21) -> -466.245 | AR21: -368.691 | AS21: -400.709 | AT21: -461.635 | AU21: =K21-AR21-AS21-AT21 -> -595.98 | AV21: -461.635 | AW21: =L21-AR21-AS21-AV21 -> -471.194 | AX21: -536.918 | AY21: -509.642 | AZ21: -721.369 | BA21: -623.026 | BB21: -586.882 | BC21: -586.882 | BD21: =M21-AZ21-AX21-BC21 -> -442.7 | BE21: -602.031 | BF21: -602.966 | BG21: -562.216 | BH21: =O21-SUM(BE21:BG21) -> -577.808 | BI21: -526.709 | BJ21: -313.785 | BK21: -313.992 | BL21: =Q21-SUM(BI21:BK21) -> -94.344 | BM21: -263.429 | BO21: =N21-SUM(AY21,BA21,BC21) -> -577.067 | BP21: -604.321 | BQ21: -370.852 | BR21: -342.787 | BS21: =P21-SUM(BP21:BR21) -> -101.613 | BT21: -309.683 | BV21: -739.738 | BW21: -623.468 | BY21: -1082.526 | BZ21: -937.46 | CB21: =P21-BY21 -> -337.047 | CC21: =Q21-BZ21 -> -311.37
B22: Net foreign exchange gains/ (losses) on financing activities | C22: -599.72 | D22: 352 | E22: -208.689 | F22: 59.085 | G22: 173.395 | H22: -234.355 | I22: -564.533 | J22: -234.355 | K22: -564.533 | L22: -622.879 | M22: -357.443 | N22: -357.443 | O22: 330.737 | P22: 330.737 | Q22: 531.033 | R22: =SUM(BJ22:BM22) -> 606.499 | T22: 125.023 | U22: -202.014 | V22: -164.841 | W22: =E22-V22-U22-T22 -> 33.143 | X22: 115.433 | Y22: -48.264 | Z22: -55.538 | AA22: =F22-Z22-Y22-X22 -> 47.454 | AB22: -165.313 | AC22: 35.004 | AD22: 94.321 | AE22: =G22-AD22-AC22-AB22 -> 209.383 | AF22: -186.736 | AG22: -4.752 | AH22: -47.122 | AI22: =H22-AH22-AG22-AF22 -> 4.255 | AM22: 4.256 | AN22: -235.657 | AO22: -300.255 | AP22: -424.006 | AQ22: =I22-SUM(AN22:AP22) -> 395.385 | AR22: -235.657 | AS22: -300.255 | AT22: -424.006 | AU22: =K22-AR22-AS22-AT22 -> 395.385 | AV22: -424.006 | AW22: =L22-AR22-AS22-AV22 -> 337.039 | AX22: -19.402 | AY22: -19.402 | AZ22: -459.478 | BA22: -459.478 | BB22: -75.192 | BC22: -75.192 | BD22: =M22-AZ22-AX22-BC22 -> 196.629 | BE22: -196.601 | BF22: -18.36 | BG22: 1034.989 | BH22: =O22-SUM(BE22:BG22) -> -489.291 | BI22: 50.865 | BJ22: 306.708 | BK22: -5.966 | BL22: =Q22-SUM(BI22:BK22) -> 179.426 | BM22: 126.331 | BO22: =N22-SUM(AY22,BA22,BC22) -> 196.629 | BP22: -196.601 | BQ22: -18.36 | BR22: 1034.989 | BS22: =P22-SUM(BP22:BR22) -> -489.291 | BT22: 50.865 | BV22: -214.961 | BW22: 357.574 | BY22: 820.027 | BZ22: 351.607 | CB22: =P22-BY22 -> -489.29 | CC22: =Q22-BZ22 -> 179.426
B23: Joint ventures - share of tax (net taxes) | C23: -95.842 | D23: -48.989 | E23: 1.678 | F23: -2.819 | G23: -1.039 | H23: -7.706 | I23: -9.709 | J23: -7.706 | K23: -9.709 | L23: -9.709 | M23: 0.903 | N23: 0.903 | O23: 0.066 | P23: 0.066 | Q23: 0.008 | R23: =SUM(BJ23:BM23) -> 0.495 | T23: 0 | U23: 0.17 | V23: 1.082 | W23: =E23-V23-U23-T23 -> 0.426 | X23: -2.236 | Y23: -0.583 | Z23: 0 | AA23: =F23-Z23-Y23-X23 -> 0 | AB23: -1.936 | AC23: -2.037 | AD23: 2.358 | AE23: =G23-AD23-AC23-AB23 -> 0.576 | AF23: -0.188 | AG23: -1.529 | AH23: -4.802 | AI23: =H23-AH23-AG23-AF23 -> -1.187 | AM23: -1.187 | AN23: -1.986 | AO23: -2.334 | AP23: -3.621 | AQ23: =I23-SUM(AN23:AP23) -> -1.768 | AR23: -1.986 | AS23: -2.334 | AT23: -3.621 | AU23: =K23-AR23-AS23-AT23 -> -1.768 | AV23: -3.621 | AW23: =L23-AR23-AS23-AV23 -> -1.768 | AX23: 1.231 | AY23: 1.231 | AZ23: -0.812 | BA23: -0.812 | BB23: -0.57 | BC23: -0.57 | BD23: =M23-AZ23-AX23-BC23 -> 1.054 | BE23: 0.104 | BF23: 0.89 | BG23: -1.223 | BH23: =O23-SUM(BE23:BG23) -> 0.295 | BI23: -0.848 | BJ23: 0.2 | BK23: -0.191 | BL23: =Q23-SUM(BI23:BK23) -> 0.847 | BM23: -0.361 | BO23: =N23-SUM(AY23,BA23,BC23) -> 1.054 | BP23: 0.104 | BQ23: 0.89 | BR23: -1.223 | BS23: =P23-SUM(BP23:BR23) -> 0.295 | BT23: -0.848 | BV23: 0.994 | BW23: -0.648 | BY23: -0.23 | BZ23: -0.839 | CB23: =P23-BY23 -> 0.296 | CC23: =Q23-BZ23 -> 0.847
B24: Associates - share of tax (net of tax) | C24: 131.124 | D24: -352.67 | E24: -26.364 | F24: -0.647 | G24: 19.761 | H24: 11.689 | I24: -56.817 | J24: -1.663 | K24: -56.817 | L24: -56.817 | M24: 530.743 | N24: 530.743 | O24: 450.865 | P24: 454.179 | Q24: 19.342 | R24: =SUM(BJ24:BM24) -> 4.626 | T24: -86.074 | U24: 46.569 | V24: 3.069 | W24: =E24-V24-U24-T24 -> 10.072 | X24: 1.082 | Y24: -2.515 | Z24: 0.778 | AA24: =F24-Z24-Y24-X24 -> 0.008 | AB24: 7.903 | AC24: 4.946 | AD24: 4.792 | AE24: =G24-AD24-AC24-AB24 -> 2.12 | AF24: 1.884 | AG24: 2.161 | AH24: 2.576 | AI24: =H24-AH24-AG24-AF24 -> 5.068 | AM24: -0.336 | AN24: 3.151 | AO24: -6.643 | AP24: 5.36 | AQ24: =I24-SUM(AN24:AP24) -> -58.685 | AR24: -0.799 | AS24: -10.78 | AT24: 0.08 | AU24: =K24-AR24-AS24-AT24 -> -45.318 | AV24: 0.08 | AW24: =L24-AR24-AS24-AV24 -> -45.318 | AX24: 113.294 | AY24: 113.294 | AZ24: 107.114 | BA24: 107.114 | BB24: 143.658 | BC24: 143.658 | BD24: =M24-AZ24-AX24-BC24 -> 166.677 | BE24: 106.25 | BF24: 144.813 | BG24: 138.666 | BH24: =O24-SUM(BE24:BG24) -> 61.136 | BI24: 76.229 | BJ24: 51.363 | BK24: -27.719 | BL24: =Q24-SUM(BI24:BK24) -> -80.531 | BM24: 61.513 | BO24: =N24-SUM(AY24,BA24,BC24) -> 166.677 | BP24: 106.25 | BQ24: 145.109 | BR24: 140.263 | BS24: =P24-SUM(BP24:BR24) -> 62.557 | BT24: 81.242 | BV24: 255.239 | BW24: 132.605 | BY24: 395.502 | BZ24: 104.885 | CB24: =P24-BY24 -> 58.677 | CC24: =Q24-BZ24 -> -85.543
B25: Associates - gain/ (loss) on dilution of equity interest | C25: -5.398 | D25: -2.595 | E25: -403.712 | F25: 0 | G25: 0 | H25: 0 | I25: 0 | J25: 0 | K25: 0 | L25: 0 | M25: 0.11 | N25: 0.11 | O25: 0 | P25: 0 | Q25: 53.178 | R25: =SUM(BJ25:BM25) -> 53.178 | T25: -357.604 | U25: -45.384 | V25: 0 | W25: =E25-V25-U25-T25 -> -0.724 | X25: 0 | Y25: 0 | Z25: 0 | AA25: =F25-Z25-Y25-X25 -> 0 | AB25: 0 | AC25: 0 | AD25: 0 | AE25: =G25-AD25-AC25-AB25 -> 0 | AF25: 0 | AG25: 0 | AH25: 0 | AI25: =H25-AH25-AG25-AF25 -> 0 | AM25: 0 | AN25: 0 | AO25: 0 | AP25: 0 | AQ25: =I25-SUM(AN25:AP25) -> 0 | AR25: 0 | AS25: 0 | AT25: 0 | AU25: =K25-AR25-AS25-AT25 -> 0 | AV25: 0 | AW25: =L25-AR25-AS25-AV25 -> 0 | AX25: 0 | AY25: 0 | AZ25: 0 | BA25: 0 | BB25: 0 | BC25: 0 | BD25: =M25-AZ25-AX25-BC25 -> 0.11 | BE25: 0 | BF25: 0 | BG25: 0 | BH25: =O25-SUM(BE25:BG25) -> 0 | BI25: 0 | BJ25: 0 | BK25: 0 | BL25: =Q25-SUM(BI25:BK25) -> 53.178 | BM25: 0 | BO25: =N25-SUM(AY25,BA25,BC25) -> 0.11 | BP25: 0 | BQ25: 0 | BR25: 0 | BS25: =P25-SUM(BP25:BR25) -> 0 | BT25: 0 | BV25: 0 | BW25: 0 | BY25: 0 | BZ25: 0 | CB25: =P25-BY25 -> 0 | CC25: =Q25-BZ25 -> 53.178
B26: Gain on early redemption of debt | N26: 0 | O26: 306.101 | P26: 306.101 | Q26: 175.129 | R26: =SUM(BJ26:BM26) -> 175.129 | BE26: 0 | BF26: 0 | BG26: 306.101 | BH26: =O26-SUM(BE26:BG26) -> 0 | BI26: 0 | BJ26: 0 | BK26: 175.129 | BL26: =Q26-SUM(BI26:BK26) -> 0 | BM26: 0 | BO26: =N26-SUM(AY26,BA26,BC26) -> 0 | BP26: 0 | BQ26: 0 | BR26: 306.101 | BS26: =P26-SUM(BP26:BR26) -> 0 | BT26: 0 | BV26: 0 | BW26: 0 | BY26: 306.101 | BZ26: 175.129 | CB26: =P26-BY26 -> 0 | CC26: =Q26-BZ26 -> 0
B27: Profit before tax | C27: =SUM(C19,C20,C21,C22,C23,C24,C25,C26) -> 1139.58 | D27: =SUM(D19,D20,D21,D22,D23,D24,D25,D26) -> 1936.241 | E27: =SUM(E19,E20,E21,E22,E23,E24,E25,E26) -> -4073.14 | F27: =SUM(F19,F20,F21,F22,F23,F24,F25,F26) -> 2779.74 | G27: =SUM(G19,G20,G21,G22,G23,G24,G25,G26) -> 1171.117 | H27: =SUM(H19,H20,H21,H22,H23,H24,H25,H26) -> 2173.618 | I27: =SUM(I19,I20,I21,I22,I23,I24,I25,I26) -> 1547.973 | J27: =SUM(J19,J20,J21,J22,J23,J24,J25,J26) -> 951.225 | ... R27: =SUM(R19,R20,R21,R22,R23,R24,R25,R26) -> 1057.605 | T27: =SUM(T19,T20,T21,T22,T23,T24,T25) -> 54.913 | U27: =SUM(U19,U20,U21,U22,U23,U24,U25) -> -3044.672 | V27: =SUM(V19,V20,V21,V22,V23,V24,V25) -> 395.451 | W27: =SUM(W19,W20,W21,W22,W23,W24,W25) -> -1478.832 | X27: =SUM(X19,X20,X21,X22,X23,X24,X25) -> 992.904 | Y27: =SUM(Y19,Y20,Y21,Y22,Y23,Y24,Y25) -> 653.934 | Z27: =SUM(Z19,Z20,Z21,Z22,Z23,Z24,Z25) -> 573.789 | AA27: =SUM(AA19,AA20,AA21,AA22,AA23,AA24,AA25) -> 559.113 | ... AI27: =SUM(AI19,AI20,AI21,AI22,AI23,AI24,AI25) -> 548.771 | AM27: =SUM(AM19,AM20,AM21,AM22,AM23,AM24,AM25) -> -10.993 | AN27: =SUM(AN19,AN20,AN21,AN22,AN23,AN24,AN25) -> 253.22 | AO27: =SUM(AO19,AO20,AO21,AO22,AO23,AO24,AO25) -> 286.749 | AP27: =SUM(AP19,AP20,AP21,AP22,AP23,AP24,AP25) -> 268.584 | AQ27: =SUM(AQ19,AQ20,AQ21,AQ22,AQ23,AQ24,AQ25) -> 739.42 | AR27: =SUM(AR19,AR20,AR21,AR22,AR23,AR24,AR25) -> -123.862 | AS27: =SUM(AS19,AS20,AS21,AS22,AS23,AS24,AS25) -> -128.843 | AT27: =SUM(AT19,AT20,AT21,AT22,AT23,AT24,AT25) -> 114.823 | ... AW27: =SUM(AW19,AW20,AW21,AW22,AW23,AW24,AW25) -> -1329.991 | AX27: =SUM(AX19,AX20,AX21,AX22,AX23,AX24,AX25,AX26) -> 269.035 | AY27: =SUM(AY19,AY20,AY21,AY22,AY23,AY24,AY25,AY26) -> 218.719 | AZ27: =SUM(AZ19,AZ20,AZ21,AZ22,AZ23,AZ24,AZ25,AZ26) -> -1204.635 | BA27: =SUM(BA19,BA20,BA21,BA22,BA23,BA24,BA25,BA26) -> -39.819 | BB27: =SUM(BB19,BB20,BB21,BB22,BB23,BB24,BB25,BB26) -> 557.916 | BC27: =SUM(BC19,BC20,BC21,BC22,BC23,BC24,BC25,BC26) -> 243.613 | BD27: =SUM(BD19,BD20,BD21,BD22,BD23,BD24,BD25,BD26) -> 1485.352 | BE27: =SUM(BE19,BE20,BE21,BE22,BE23,BE24,BE25,BE26) -> 302.22 | ... BM27: =SUM(BM19,BM20,BM21,BM22,BM23,BM24,BM25,BM26) -> 518.536 | BO27: =SUM(BO19,BO20,BO21,BO22,BO23,BO24,BO25,BO26) -> -411.496 | BP27: =SUM(BP19,BP20,BP21,BP22,BP23,BP24,BP25,BP26) -> 374.886 | BQ27: =SUM(BQ19,BQ20,BQ21,BQ22,BQ23,BQ24,BQ25,BQ26) -> 244.245 | BR27: =SUM(BR19,BR20,BR21,BR22,BR23,BR24,BR25,BR26) -> 1268.685 | BS27: =SUM(BS19,BS20,BS21,BS22,BS23,BS24,BS25,BS26) -> -307.261 | BT27: =SUM(BT19,BT20,BT21,BT22,BT23,BT24,BT25,BT26) -> 240.493 | BV27: =SUM(BV19,BV20,BV21,BV22,BV23,BV24,BV25,BV26) -> 334.327 | BW27: =SUM(BW19,BW20,BW21,BW22,BW23,BW24,BW25,BW26) -> 466.318 | BY27: =SUM(BY19,BY20,BY21,BY22,BY23,BY24,BY25,BY26) -> 1603.013 | BZ27: =SUM(BZ19,BZ20,BZ21,BZ22,BZ23,BZ24,BZ25,BZ26) -> 635.555 | CB27: =SUM(CB19,CB20,CB21,CB22,CB23,CB24,CB25,CB26) -> -22.458 | CC27: =SUM(CC19,CC20,CC21,CC22,CC23,CC24,CC25,CC26) -> 360.048
B28: Income tax benefit/(expense) | C28: -482.422 | D28: -773.749 | E28: -901.552 | F28: -964.644 | G28: -547.072 | H28: -896.737 | I28: -614.666 | J28: -643.69 | K28: -614.666 | L28: -604.86 | M28: -651.168 | N28: -665.744 | O28: -965.616 | P28: -775.566 | Q28: -656.33 | R28: =SUM(BJ28:BM28) -> -639.04 | T28: -136.032 | U28: -259.477 | V28: -196.104 | W28: =E28-V28-U28-T28 -> -309.939 | X28: -193.078 | Y28: -349.972 | Z28: -266.624 | AA28: =F28-Z28-Y28-X28 -> -154.97 | AB28: -194.396 | AC28: -249.326 | AD28: -256.804 | AE28: =G28-AD28-AC28-AB28 -> 153.454 | AF28: -174.578 | AG28: -189.727 | AH28: -195.162 | AI28: =H28-AH28-AG28-AF28 -> -337.27 | AM28: -223.538 | AN28: -262.511 | AO28: -300.1 | AP28: -274.964 | AQ28: =I28-SUM(AN28:AP28) -> 222.909 | AR28: -146.152 | AS28: -178.311 | AT28: -145.071 | AU28: =K28-AR28-AS28-AT28 -> -145.132 | AV28: -145.071 | AW28: =L28-AR28-AS28-AV28 -> -135.326 | AX28: -127.101 | AY28: -116.358 | AZ28: 80.818 | BA28: -153.766 | BB28: -135.622 | BC28: -135.622 | BD28: =M28-AZ28-AX28-BC28 -> -469.263 | BE28: -167.262 | BF28: -249.265 | BG28: -289.505 | BH28: =O28-SUM(BE28:BG28) -> -259.584 | BI28: -148.042 | BJ28: -260.396 | BK28: -155.687 | BL28: =Q28-SUM(BI28:BK28) -> -92.205 | BM28: -130.752 | BO28: =N28-SUM(AY28,BA28,BC28) -> -259.998 | BP28: -173.207 | BQ28: -195.61 | BR28: -253.157 | BS28: =P28-SUM(BP28:BR28) -> -153.592 | BT28: -123.277 | BV28: -325.701 | BW28: -383.673 | BY28: -578.859 | BZ28: -539.36 | CB28: =P28-BY28 -> -196.707 | CC28: =Q28-BZ28 -> -116.97
B29: Profit / (Loss) for the financial period from continuing operations | C29: =+C27+C28 -> 657.158 | D29: =+D27+D28 -> 1162.492 | E29: =+E27+E28 -> -4974.692 | F29: =+F27+F28 -> 1815.096 | G29: =+G27+G28 -> 624.045 | H29: =+H27+H28 -> 1276.881 | I29: =+I27+I28 -> 933.307 | J29: =+J27+J28 -> 307.535 | ... R29: =+R27+R28 -> 418.565 | T29: =+T27+T28 -> -81.119 | U29: =+U27+U28 -> -3304.149 | V29: =+V27+V28 -> 199.347 | W29: =+W27+W28 -> -1788.771 | X29: =+X27+X28 -> 799.826 | Y29: =+Y27+Y28 -> 303.962 | Z29: =+Z27+Z28 -> 307.165 | AA29: =+AA27+AA28 -> 404.143 | ... AI29: =+AI27+AI28 -> 211.501 | AM29: =+AM27+AM28 -> -234.531 | AN29: =+AN27+AN28 -> -9.291 | AO29: =+AO27+AO28 -> -13.351 | AP29: =+AP27+AP28 -> -6.38 | AQ29: =+AQ27+AQ28 -> 962.329 | AR29: =+AR27+AR28 -> -270.014 | AS29: =+AS27+AS28 -> -307.154 | AT29: =+AT27+AT28 -> -30.248 | ... BM29: =+BM27+BM28 -> 387.784 | BO29: =+BO27+BO28 -> -671.494 | BP29: =+BP27+BP28 -> 201.679 | BQ29: =+BQ27+BQ28 -> 48.635 | BR29: =+BR27+BR28 -> 1015.528 | BS29: =+BS27+BS28 -> -460.853 | BT29: =+BT27+BT28 -> 117.216 | BV29: =+BV27+BV28 -> 8.626 | BW29: =+BW27+BW28 -> 82.645 | BY29: =+BY27+BY28 -> 1024.154 | BZ29: =+BZ27+BZ28 -> 96.195 | CB29: =+CB27+CB28 -> -219.165 | CC29: =+CC27+CC28 -> 243.078
B30: Gain on disposal of group of subsidiares - net | K30: 13472.081 | L30: 0 | M30: 0 | N30: 0 | O30: 0 | P30: 0 | Q30: 0 | R30: =SUM(BJ30:BM30) -> 0 | AP30: 0 | AQ30: =I30-SUM(AN30:AP30) -> 0 | AR30: 0 | AS30: 0 | AT30: 0 | AU30: =K30-AR30-AS30-AT30 -> 13472.081 | AV30: 0 | AW30: =L30-AR30-AS30-AV30 -> 0 | AZ30: 402 | BA30: 0 | BB30: 0 | BC30: 0 | BD30: =M30-AZ30-AX30-BC30 -> -402 | BF30: 0 | BG30: 0 | BH30: =O30-SUM(BE30:BG30) -> 0 | BI30: 0 | BJ30: 0 | BK30: 0 | BL30: =Q30-SUM(BI30:BK30) -> 0 | BM30: 0 | BO30: =N30-SUM(AY30,BA30,BC30) -> 0 | BP30: 0 | BQ30: 0 | BR30: 0 | BS30: =P30-SUM(BP30:BR30) -> 0 | BT30: 0 | BV30: 0 | BW30: 0 | BY30: 0 | BZ30: 0 | CB30: =P30-BY30 -> 0 | CC30: =Q30-BZ30 -> 0
B31: Profit for the financial period from discontinued operations | J31: 969.346 | K31: 1424.208 | L31: 12433.764 | M31: -2599.355 | N31: -1802.431 | O31: 0 | P31: 793.87 | Q31: 292.335 | R31: =SUM(BJ31:BM31) -> 292.335 | AN31: 0 | AO31: 0 | AP31: 0 | AQ31: =I31-SUM(AN31:AP31) -> 0 | AR31: 260.723 | AS31: 293.803 | AT31: 365.485 | AU31: =K31-AR31-AS31-AT31 -> 504.197 | AV31: 365.485 | AW31: =L31-AR31-AS31-AV31 -> 11513.753 | AX31: 0 | AY31: 39.573 | AZ31: 0 | BA31: -528.232 | BB31: -1022.85 | BC31: -1022.85 | BD31: =M31-AZ31-AX31-BC31 -> -1576.505 | BE31: 66.721 | BF31: 53.949 | BG31: 44.702 | BH31: =O31-SUM(BE31:BG31) -> -165.372 | BI31: 0 | BJ31: 238.467 | BK31: 6.519 | BL31: =Q31-SUM(BI31:BK31) -> 47.349 | BM31: 0 | BO31: =N31-SUM(AY31,BA31,BC31) -> -290.922 | BP31: 0 | BQ31: 206.829 | BR31: 172.867 | BS31: =P31-SUM(BP31:BR31) -> 414.174 | BT31: 191.276 | BV31: 448.517 | BW31: 429.742 | BY31: 621.384 | BZ31: 436.261 | CB31: =P31-BY31 -> 172.486 | CC31: =Q31-BZ31 -> -143.926
B32: Profit / (Loss) for the financial period | C32: =+C29+C31+C30 -> 657.158 | D32: =+D29+D31+D30 -> 1162.492 | E32: =+E29+E31+E30 -> -4974.692 | F32: =+F29+F31+F30 -> 1815.096 | G32: =+G29+G31+G30 -> 624.045 | H32: =+H29+H31+H30 -> 1276.881 | I32: =+I29+I31+I30 -> 933.307 | J32: =+J29+J31+J30 -> 1276.881 | ... R32: =+R29+R31+R30 -> 710.9 | T32: =+T29+T31+T30 -> -81.119 | U32: =+U29+U31+U30 -> -3304.149 | V32: =+V29+V31+V30 -> 199.347 | W32: =+W29+W31+W30 -> -1788.771 | X32: =+X29+X31+X30 -> 799.826 | Y32: =+Y29+Y31+Y30 -> 303.962 | Z32: =+Z29+Z31+Z30 -> 307.165 | AA32: =+AA29+AA31+AA30 -> 404.143 | ... AI32: =+AI29+AI31+AI30 -> 211.501 | AM32: =+AM29+AM31+AM30 -> -234.531 | AN32: =+AN29+AN31+AN30 -> -9.291 | AO32: =+AO29+AO31+AO30 -> -13.351 | AP32: =+AP29+AP31+AP30 -> -6.38 | AQ32: =+AQ29+AQ31+AQ30 -> 962.329 | AR32: =+AR29+AR31+AR30 -> -9.291 | AS32: =+AS29+AS31+AS30 -> -13.351 | AT32: =+AT29+AT31+AT30 -> 335.237 | ... BM32: =+BM29+BM31+BM30 -> 387.784 | BO32: =+BO29+BO31+BO30 -> -962.416 | BP32: =+BP29+BP31+BP30 -> 201.679 | BQ32: =+BQ29+BQ31+BQ30 -> 255.464 | BR32: =+BR29+BR31+BR30 -> 1188.395 | BS32: =+BS29+BS31+BS30 -> -46.679 | BT32: =+BT29+BT31+BT30 -> 308.492 | BV32: =+BV29+BV31+BV30 -> 457.143 | BW32: =+BW29+BW31+BW30 -> 512.387 | BY32: =+BY29+BY31+BY30 -> 1645.538 | BZ32: =+BZ29+BZ31+BZ30 -> 532.456 | CB32: =+CB29+CB31+CB30 -> -46.679 | CC32: =+CC29+CC31+CC30 -> 99.152
B34: % of Net sales unless stated otherwise
B35: =B9 -> Depreciation, impairment and amortisation | C35: =-C9/C7 -> 0.26275919 | D35: =-D9/D7 -> 0.24531246 | E35: =-E9/E7 -> 0.32005719 | F35: =-F9/F7 -> 0.28817256 | G35: =-G9/G7 -> 0.35057365 | H35: =-H9/H7 -> 0.31253519 | I35: =-I9/I7 -> 0.25691854 | J35: =-J9/J7 -> 0.31597983 | ... R35: =-R9/R7 -> 0.31761542 | T35: =-T9/T7 -> 0.24237137 | U35: =-U9/U7 -> 0.25379606 | V35: =-V9/V7 -> 0.25176198 | W35: =-W9/W7 -> 0.51876872 | X35: =-X9/X7 -> 0.27616731 | Y35: =-Y9/Y7 -> 0.27735913 | Z35: =-Z9/Z7 -> 0.2971142 | AA35: =-AA9/AA7 -> 0.30132231 | ... AI35: =-AI9/AI7 -> 0.3233855 | AM35: =-AM9/AM7 -> 0.30660128 | AN35: =-AN9/AN7 -> 0.28756678 | AO35: =-AO9/AO7 -> 0.28032592 | AP35: =-AP9/AP7 -> 0.28943856 | AQ35: =-AQ9/AQ7 -> 0.17348579 | AR35: =-AR9/AR7 -> 0.32271017 | AS35: =-AS9/AS7 -> 0.31292566 | AT35: =-AT9/AT7 -> 0.29436083 | ... BM35: =-BM9/BM7 -> 0.27590905 | BO35: =-BO9/BO7 -> 0.479393 | BP35: =-BP9/BP7 -> 0.33058613 | BQ35: =-BQ9/BQ7 -> 0.29307942 | BR35: =-BR9/BR7 -> 0.30820771 | BS35: =-BS9/BS7 -> -0.14946406 | BT35: =-BT9/BT7 -> 0.28562097 | BV35: =-BV9/BV7 -> 0.30054201 | BW35: =-BW9/BW7 -> 0.33445693 | BY35: =-BY9/BY7 -> 0.30299632 | BZ35: =-BZ9/BZ7 -> 0.33927404
B36: =B13 -> Marketing, Advertising and promotion | C36: =-C13/C7 -> 0.084283142 | D36: =-D13/D7 -> 0.086415882 | E36: =-E13/E7 -> 0.089915335 | F36: =-F13/F7 -> 0.081415799 | G36: =-G13/G7 -> 0.078182813 | H36: =-H13/H7 -> 0.08465645 | I36: =-I13/I7 -> 0.067661325 | J36: =-J13/J7 -> 0.09296938 | ... R36: =-R13/R7 -> 0.080226965 | T36: =-T13/T7 -> 0.095834401 | U36: =-U13/U7 -> 0.096444645 | V36: =-V13/V7 -> 0.084415152 | W36: =-W13/W7 -> 0.083642479 | X36: =-X13/X7 -> 0.082189121 | Y36: =-Y13/Y7 -> 0.083894927 | Z36: =-Z13/Z7 -> 0.076604304 | AA36: =-AA13/AA7 -> 0.083017619 | ... AI36: =-AI13/AI7 -> 0.083478873 | AM36: =-AM13/AM7 -> 0.094406878 | AN36: =-AN13/AN7 -> 0.08305287 | AO36: =-AO13/AO7 -> 0.079675347 | AP36: =-AP13/AP7 -> 0.07296898 | AQ36: =-AQ13/AQ7 -> 0.036809306 | AR36: =-AR13/AR7 -> 0.095598017 | AS36: =-AS13/AS7 -> 0.086409029 | AT36: =-AT13/AT7 -> 0.072652303 | ... BM36: =-BM13/BM7 -> 0.070474927 | BO36: =-BO13/BO7 -> 0.075608935 | BP36: =-BP13/BP7 -> 0.075200168 | BQ36: =-BQ13/BQ7 -> 0.08864014 | BR36: =-BR13/BR7 -> 0.070347517 | BS36: =-BS13/BS7 -> 0.15772007 | BT36: =-BT13/BT7 -> 0.073746385 | BV36: =-BV13/BV7 -> 0.089697336 | BW36: =-BW13/BW7 -> 0.073268484 | BY36: =-BY13/BY7 -> 0.083502685 | BZ36: =-BZ13/BZ7 -> 0.073273935
B37: =B14 -> Other operating costs | C37: =-C14/C7 -> 0.37441063 | D37: =-D14/D7 -> 0.34651779 | E37: =-E14/E7 -> 0.37375789 | F37: =-F14/F7 -> 0.30129374 | G37: =-G14/G7 -> 0.30184433 | H37: =-H14/H7 -> 0.30745289 | I37: =-I14/I7 -> 0.22995513 | J37: =-J14/J7 -> 0.28434662 | ... R37: =-R14/R7 -> 0.21283539 | T37: =-T14/T7 -> 0.37281075 | U37: =-U14/U7 -> 0.3615438 | V37: =-V14/V7 -> 0.36649309 | W37: =-W14/W7 -> 0.39302058 | X37: =-X14/X7 -> 0.33709442 | Y37: =-Y14/Y7 -> 0.29775836 | Z37: =-Z14/Z7 -> 0.31268961 | AA37: =-AA14/AA7 -> 0.25948048 | ... AI37: =-AI14/AI7 -> 0.3085285 | AM37: =-AM14/AM7 -> 0.29087945 | AN37: =-AN14/AN7 -> 0.30657342 | AO37: =-AO14/AO7 -> 0.31163259 | AP37: =-AP14/AP7 -> 0.30626097 | AQ37: =-AQ14/AQ7 -> 0.0045845671 | AR37: =-AR14/AR7 -> 0.28438409 | AS37: =-AS14/AS7 -> 0.29791433 | AT37: =-AT14/AT7 -> 0.284323 | ... BM37: =-BM14/BM7 -> 0.23079646 | BO37: =-BO14/BO7 -> 0.27460244 | BP37: =-BP14/BP7 -> 0.26109161 | BQ37: =-BQ14/BQ7 -> 0.23605811 | BR37: =-BR14/BR7 -> 0.24350815 | BS37: =-BS14/BS7 -> -0.18809251 | BT37: =-BT14/BT7 -> 0.2756758 | BV37: =-BV14/BV7 -> 0.23291529 | BW37: =-BW14/BW7 -> 0.24515762 | BY37: =-BY14/BY7 -> 0.23630661 | BZ37: =-BZ14/BZ7 -> 0.24188097
B38: =B15 -> Staff costs | C38: =-C15/C7 -> 0.072556529 | D38: =-D15/D7 -> 0.078145548 | E38: =-E15/E7 -> 0.086584274 | F38: =-F15/F7 -> 0.090313299 | G38: =-G15/G7 -> 0.092034717 | H38: =-H15/H7 -> 0.079959581 | I38: =-I15/I7 -> 0.06040513 | J38: =-J15/J7 -> 0.076858043 | ... R38: =-R15/R7 -> 0.12540964 | T38: =-T15/T7 -> 0.072290884 | U38: =-U15/U7 -> 0.089591303 | V38: =-V15/V7 -> 0.087501366 | W38: =-W15/W7 -> 0.096000874 | X38: =-X15/X7 -> 0.084461101 | Y38: =-Y15/Y7 -> 0.10276839 | Z38: =-Z15/Z7 -> 0.087810831 | AA38: =-AA15/AA7 -> 0.086120217 | ... AI38: =-AI15/AI7 -> 0.06941711 | AM38: =-AM15/AM7 -> 0.063923777 | AN38: =-AN15/AN7 -> 0.07719502 | AO38: =-AO15/AO7 -> 0.081024788 | AP38: =-AP15/AP7 -> 0.08379082 | AQ38: =-AQ15/AQ7 -> 0.0016173604 | AR38: =-AR15/AR7 -> 0.07522036 | AS38: =-AS15/AS7 -> 0.076064072 | AT38: =-AT15/AT7 -> 0.073596602 | ... BM38: =-BM15/BM7 -> 0.1013611 | BO38: =-BO15/BO7 -> 0.06729682 | BP38: =-BP15/BP7 -> 0.071929066 | BQ38: =-BQ15/BQ7 -> 0.10160361 | BR38: =-BR15/BR7 -> 0.10096711 | BS38: =-BS15/BS7 -> 0.52801375 | BT38: =-BT15/BT7 -> 0.10828924 | BV38: =-BV15/BV7 -> 0.10230253 | BW38: =-BW15/BW7 -> 0.11078054 | BY38: =-BY15/BY7 -> 0.10187502 | BZ38: =-BZ15/BZ7 -> 0.11269649
B39: =B19 -> Operating Profit | C39: =C19/C7 -> 0.12646216 | D39: =D19/D7 -> 0.12294106 | E39: =E19/E7 -> -0.099855517 | F39: =F19/F7 -> 0.17215443 | G39: =G19/G7 -> 0.10308087 | H39: =H19/H7 -> 0.14741234 | I39: =I19/I7 -> 0.13628272 | J39: =J19/J7 -> 0.12136983 | ... R39: =R19/R7 -> 0.11249038 | T39: =T19/T7 -> 0.10695274 | U39: =U19/U7 -> -0.44016438 | V39: =V19/V7 -> 0.13808776 | W39: =W19/W7 -> -0.19889133 | X39: =X19/X7 -> 0.20693824 | Y39: =Y19/Y7 -> 0.18116833 | Z39: =Z19/Z7 -> 0.16061986 | AA39: =AA19/AA7 -> 0.14171805 | ... AI39: =AI19/AI7 -> 0.13719059 | AM39: =AM19/AM7 -> 0.065624341 | AN39: =AN19/AN7 -> 0.13203145 | AO39: =AO19/AO7 -> 0.14725196 | AP39: =AP19/AP7 -> 0.15908614 | AQ39: =AQ19/AQ7 -> 0.1064279 | AR39: =AR19/AR7 -> 0.087970441 | AS39: =AS19/AS7 -> 0.10266729 | AT39: =AT19/AT7 -> 0.16581818 | ... BM39: =BM19/BM7 -> 0.19993671 | BO39: =BO19/BO7 -> -0.047143642 | BP39: =BP19/BP7 -> 0.17377375 | BQ39: =BQ19/BQ7 -> 0.13575826 | BR39: =BR19/BR7 -> 0.027253851 | BS39: =BS19/BS7 -> 0.48111735 | BT39: =BT19/BT7 -> 0.13211787 | BV39: =BV19/BV7 -> 0.1448513 | BW39: =BW19/BW7 -> 0.087750048 | BY39: =BY19/BY7 -> 0.10720335 | BZ39: =BZ19/BZ7 -> 0.092602073
B40: Finance Income as a % of cash at end of period | C40: =C20/C123 -> 0.88719571 | D40: =D20/D123 -> 3.6282842 | E40: =E20/E123 -> 0.043667805 | F40: =F20/F123 -> 0.054470009 | G40: =G20/G123 -> 0.024628405 | H40: =H20/H123 -> 0.021663707 | I40: =I20/I123 -> 0.034254658 | J40: =J20/J123 -> 0.025782024 | ... R40: =R20/R123 -> 0.057214148 | T40: =SUM(T20:T20)/T123 -> 0.010726253 | U40: =SUM(T20:U20)/U123 -> 0.018399493 | V40: =SUM(T20:V20)/V123 -> 0.027494315 | W40: =SUM(T20:W20)/W123 -> 0.043667805 | X40: =SUM(X20:X20)/X123 -> 0.0083525205 | Y40: =SUM(X20:Y20)/Y123 -> 0.020561066 | Z40: =SUM(X20:Z20)/Z123 -> 0.035587638 | AA40: =SUM(X20:AA20)/AA123 -> 0.054470009 | AB40: =SUM(Y20:AB20)/AB123 -> 0.036263691 | AC40: =SUM(Z20:AC20)/AC123 -> 0.035434178 | AD40: =SUM(AA20:AD20)/AD123 -> 0.017243391 | AE40: =SUM(AB20:AE20)/AE123 -> 0.024628405 | AF40: =SUM(AC20:AF20)/AF123 -> 0.025871273 | AG40: =SUM(AD20:AG20)/AG123 -> 0.022625338 | AH40: =SUM(AE20:AH20)/AH123 -> 0.020579076 | AI40: =SUM(AF20:AI20)/AI123 -> 0.021663707 | AM40: =SUM(AJ20:AM20)/AM123 -> 0.0069676492 | AN40: =SUM(AC20:AN20)/AN123 -> 0.064221567 | AO40: =SUM(AD20:AO20)/AO123 -> 0.055713426 | AP40: =SUM(AE20:AP20)/AP123 -> 0.048882648 | AQ40: =SUM(AF20:AQ20)/AQ123 -> 0.061030761 | AR40: =SUM(AG20:AR20)/AR123 -> 0.080454971 | AS40: =SUM(AH20:AS20)/AS123 -> 0.072847084 | AT40: =SUM(AI20:AT20)/AT123 -> 0.064328302 | AU40: =SUM(AR20:AU20)/AU123 -> 0.034254658 | AV40: =SUM(AK20:AV20)/AV123 -> 0.079631862 | AW40: =SUM(AT20:AW20)/AW123 -> 0.038399956 | AX40: =SUM(AS20:AX20)/AX123 -> 0.077294882 | AY40: =SUM(AT20:AY20)/AY123 -> 0.080603772 | AZ40: =SUM(AT20:AZ20)/AZ123 -> 0.082395475 | BA40: =SUM(AU20:BA20)/BA123 -> 0.083198283 | BB40: =SUM(AU20:BB20)/BB123 -> 0.10450888 | BC40: =SUM(AV20:BC20)/BC123 -> 0.098873641 | BD40: =SUM(AZ20:BD20)/BD123 -> 0.064280439 | BE40: =SUM(BC20:BE20,BA20)/BE123 -> 0.047141846 | BF40: =SUM(BC20:BF20)/BF123 -> 0.036142382 | BG40: =SUM(BD20:BG20)/BG123 -> 0.038017366 | BH40: =SUM(BE20:BH20)/BH123 -> 0.054654723 | BI40: =SUM(BG20:BI20,BF20)/BI123 -> 0.055325012 | BJ40: =SUM(BG20:BJ20)/BJ123 -> 0.057902444 | BK40: =SUM(BH20:BK20)/BK123 -> 0.073408084 | BL40: =SUM(BI20:BL20)/BL123 -> 0.045296749 | BM40: =SUM(BK20:BM20,BJ20)/BM123 -> 0.057214148 | BS40: =SUM(BP20:BS20)/BS123 -> 0.036277786
B41: Finance costs as a % of debt at end of period | C41: =-C21/C116 -> 0.053961834 | D41: =-D21/D116 -> 0.065334118 | E41: =-E21/E116 -> 0.066543824 | F41: =-F21/F116 -> 0.067732996 | G41: =-G21/G116 -> 0.061849377 | H41: =-H21/H116 -> 0.053558836 | I41: =-I21/I116 -> 0.050922894 | J41: =-J21/J116 -> 0.048301712 | ... R41: =-R21/R116 -> 0.05833596 | T41: =-SUM(T21:T21)/T116 -> 0.016663456 | U41: =-SUM(T21:U21)/U116 -> 0.033068803 | V41: =-SUM(T21:V21)/V116 -> 0.048336515 | W41: =-SUM(T21:W21)/W116 -> 0.066543824 | X41: =-SUM(X21:X21)/X116 -> 0.015470524 | Y41: =-SUM(X21:Y21)/Y116 -> 0.034107767 | Z41: =-SUM(X21:Z21)/Z116 -> 0.050928559 | AA41: =-SUM(X21:AA21)/AA116 -> 0.067732996 | AB41: =-SUM(Y21:AB21)/AB116 -> 0.066390319 | AC41: =-SUM(Z21:AC21)/AC116 -> 0.064025304 | AD41: =-SUM(AA21:AD21)/AD116 -> 0.05598681 | AE41: =-SUM(AB21:AE21)/AE116 -> 0.061849377 | AF41: =-SUM(AC21:AF21)/AF116 -> 0.060400719 | AG41: =-SUM(AD21:AG21)/AG116 -> 0.057787878 | AH41: =-SUM(AE21:AH21)/AH116 -> 0.055168036 | AI41: =-SUM(AF21:AI21)/AI116 -> 0.053558836 | AM41: =-SUM(AJ21:AM21)/AM116 -> 0.014115913 | AN41: =-SUM(AC21:AN21)/AN116 -> 0.12646823 | AO41: =-SUM(AD21:AO21)/AO116 -> 0.10195929 | AP41: =-SUM(AE21:AP21)/AP116 -> 0.095661442 | AQ41: =-SUM(AF21:AQ21)/AQ116 -> 0.10604172 | AR41: =-SUM(AG21:AR21)/AR116 -> 0.13213021 | AS41: =-SUM(AH21:AS21)/AS116 -> 0.10696062 | AT41: =-SUM(AI21:AT21)/AT116 -> 0.099967711 | AU41: =-SUM(AR21:AU21)/AU116 -> 0.050920827 | AV41: =-SUM(AK21:AV21)/AV116 -> 0.11555431 | AW41: =-SUM(AT21:AW21)/AW116 -> 0.055475765 | AX41: =-SUM(AS21:AX21)/AX116 -> 0.079857174 | AY41: =-SUM(AT21:AY21)/AY116 -> 0.082828099 | AZ41: =-SUM(AT21:AZ21)/AZ116 -> 0.099519752 | BA41: =-SUM(AU21:BA21)/BA116 -> 0.1037933 | BB41: =-SUM(AU21:BB21)/BB116 -> 0.12264685 | BC41: =-SUM(AV21:BC21)/BC116 -> 0.12239925 | BD41: =-SUM(AZ21:BD21)/BD116 -> 0.080144175 | BE41: =-SUM(BC21:BE21,BA21)/BE116 -> 0.060374751 | BF41: =-SUM(BC21:BF21)/BF116 -> 0.060006763 | BG41: =-SUM(BD21:BG21)/BG116 -> 0.067376156 | BH41: =-SUM(BE21:BH21)/BH116 -> 0.068515834 | BI41: =-SUM(BG21:BI21,BF21)/BI116 -> 0.068653311 | BJ41: =-SUM(BG21:BJ21)/BJ116 -> 0.10214488 | BK41: =-SUM(BH21:BK21)/BK116 -> 0.099105269 | BL41: =-SUM(BI21:BL21)/BL116 -> 0.074094475 | BM41: =-SUM(BK21:BM21,BJ21)/BM116 -> 0.05833596 | BS41: =-SUM(BP21:BS21)/BS116 -> 0.041476485
B42: =B27 -> Profit before tax | C42: =C27/C7 -> 0.052843 | D42: =D27/D7 -> 0.079346332 | E42: =E27/E7 -> -0.17052572 | F42: =F27/F7 -> 0.11307427 | G42: =G27/G7 -> 0.048386924 | H42: =H27/H7 -> 0.083921333 | I42: =I27/I7 -> 0.056244931 | J42: =J27/J7 -> 0.047574647 | ... R42: =R27/R7 -> 0.11169177 | T42: =T27/T7 -> 0.0095529961 | U42: =U27/U7 -> -0.51894295 | V42: =V27/V7 -> 0.065870383 | W42: =W27/W7 -> -0.23597147 | X42: =X27/X7 -> 0.16689041 | Y42: =Y27/Y7 -> 0.10626828 | Z42: =Z27/Z7 -> 0.092349194 | AA42: =AA27/AA7 -> 0.089215314 | ... AI42: =AI27/AI7 -> 0.079490383 | AM42: =AM27/AM7 -> -0.0020599779 | AN42: =AN27/AN7 -> 0.039137854 | AO42: =AO27/AO7 -> 0.042771183 | AP42: =AP27/AP7 -> 0.036993421 | AQ42: =AQ27/AQ7 -> 0.10432772 | AR42: =AR27/AR7 -> -0.024852475 | AS42: =AS27/AS7 -> -0.024788917 | AT42: =AT27/AT7 -> 0.020112629 | ... BM42: =BM27/BM7 -> 0.18520062 | BO42: =BO27/BO7 -> -0.068204789 | BP42: =BP27/BP7 -> 0.065322041 | BQ42: =BQ27/BQ7 -> 0.073575838 | BR42: =BR27/BR7 -> 0.41392686 | BS42: =BS27/BS7 -> -0.7346506 | BT42: =BT27/BT7 -> 0.083162134 | BV42: =BV27/BV7 -> 0.051365824 | BW42: =BW27/BW7 -> 0.079599869 | BY42: =BY27/BY7 -> 0.16743853 | BZ42: =BZ27/BZ7 -> 0.072396932
...

Sheet KPI
B2: Axiata | C2: Annual | D2: Annual | E2: Annual | F2: Annual | G2: Annual | H2: Annual | I2: Annual | J2: Annual | K2: Annual | L2: Annual | M2: Annual | N2: Annual | O2: Annual | Q2: Quarterly | R2: Quarterly | S2: Quarterly | T2: Quarterly | U2: Quarterly | V2: Quarterly | W2: Quarterly | X2: Quarterly | Y2: Quarterly | Z2: Quarterly | AA2: Quarterly | AB2: Quarterly | AC2: Quarterly | AD2: Quarterly | AE2: Quarterly | AF2: Quarterly | AG2: Quarterly | AH2: Quarterly | AI2: Quarterly | AJ2: Quarterly | AK2: Quarterly | AL2: Quarterly | AM2: Quarterly | AN2: Quarterly | AO2: Quarterly | AP2: Quarterly | AQ2: Quarterly | AR2: Quarterly | AS2: Quarterly | AT2: Quarterly | AU2: Quarterly | AV2: Quarterly | AW2: Quarterly | AY2: Quarterly | AZ2: Quarterly | BA2: Quarterly | BC2: 6M | BD2: 6M | BF2: 9M | BG2: 9M
B3: (MYR millions) | C3: 42735 | D3: =EDATE(C3,12) -> 43100 | E3: =EDATE(D3,12) -> 43465 | F3: =EDATE(E3,12) -> 43830 | G3: =EDATE(F3,12) -> 44196 | H3: =EDATE(G3,12) -> 44561 | I3: 44561 | J3: =EDATE(H3,12) -> 44926 | K3: 44926 | L3: =EDATE(J3,12) -> 45291 | M3: =EDATE(K3,12) -> 45291 | N3: 45657 | O3: 46022 | Q3: 43160 | R3: 43252 | S3: 43344 | T3: 43435 | U3: 43525 | V3: 43617 | W3: 43709 | X3: 43800 | Y3: 43891 | Z3: 43983 | AA3: 44075 | AB3: 44166 | AC3: 44256 | AD3: 44348 | AE3: 44440 | AF3: 44531 | AG3: 44621 | AH3: 44713 | AI3: 44805 | AJ3: 44896 | AK3: 44986 | AL3: 45078 | AM3: 45199 | AN3: 45261 | AO3: 45352 | AP3: 45444 | AQ3: 45565 | AR3: 45627 | AS3: 45717 | AT3: 45809 | AU3: 45901 | AV3: 45992 | AW3: 46082 | AY3: 45261 | AZ3: 45382 | BA3: 45747 | BC3: 45444 | BD3: 45809 | BF3: 45536 | BG3: 45901
C4: Act | D4: Act | E4: Act | F4: Act | G4: Act | H4: Act | I4: Act | J4: Act | K4: Act | L4: Act | M4: Act | N4: Act | O4: Act | Q4: Act | R4: Act | S4: Act | T4: Act | U4: Act | V4: Act | W4: Act | X4: Act | Y4: Act | Z4: Act | AA4: Act | AB4: Act | AC4: Act | AD4: Act | AE4: Act | AF4: Act | AG4: Act | AH4: Act | AI4: Act | AJ4: Act | AK4: Act | AL4: Act | AM4: Act | AN4: Act | AO4: Act | AP4: Act | AQ4: Act | AR4: Act | AS4: Act | AT4: Act | AU4: Act | AV4: Act | AW4: Act | AY4: Act | AZ4: Act | BA4: Act | BC4: Act | BD4: Act | BF4: Act | BG4: Act
C5: FY | D5: FY | E5: FY | F5: FY | G5: FY | H5: FY | I5: FY | J5: FY | K5: FY | L5: FY | M5: FY | N5: FY | O5: FY | Q5: Q1 | R5: Q2 | S5: Q3 | T5: Q4 | U5: Q1 | V5: Q2 | W5: Q3 | X5: Q4 | Y5: Q1 | Z5: Q2 | AA5: Q3 | AB5: Q4 | AC5: Q1 | AD5: Q2 | AE5: Q3 | AF5: Q4 | AG5: Q1 | AH5: Q2 | AI5: Q3 | AJ5: Q4 | AK5: Q1 | AL5: Q2 | AM5: Q3 | AN5: Q4 | AO5: Q1 | AP5: Q2 | AQ5: Q3 | AR5: Q4 | AS5: Q1 | AT5: Q2 | AU5: Q3 | AV5: Q4 | AW5: Q1 | AY5: Q4 | AZ5: Q1 | BA5: Q1 | BC5: 6M | BD5: 6M | BF5: 9M | BG5: 9M
I6: Restated | K6: Restated | M6: Restated and reclassified | AY6: Restated and reclassified | AZ6: Restated | BA6: Restated | BC6: Restated | BD6: Act | BF6: Restated | BG6: Act
B8: Revenue by segment
B9: Mobile
B10: Malaysia | C10: 6576.648 | D10: 6549.138 | E10: 7284.632 | F10: 6651.37 | G10: 6174.047 | H10: 6603.94 | Q10: 1789.977 | R10: =3588.746-Q10 -> 1798.769 | S10: =5388.829-R10-Q10 -> 1800.083 | T10: =+E10-Q10-R10-S10 -> 1895.803 | U10: 1651.508 | V10: =3303.106-U10 -> 1651.598 | W10: =4924.836-V10-U10 -> 1621.73 | X10: =+F10-U10-V10-W10 -> 1726.534 | Y10: 1538.068 | Z10: =2974.814-Y10 -> 1436.746 | AA10: =4546.506-Z10-Y10 -> 1571.692 | AB10: =+G10-Y10-Z10-AA10 -> 1627.541 | AC10: 1636.484 | AD10: =3260.898-AC10 -> 1624.414 | AE10: =4859.306-AD10-AC10 -> 1598.408 | AF10: =+H10-AC10-AD10-AE10 -> 1744.634
