Workbook
Name \A: #REF!
Name \B: #REF!
Name \C: #REF!
Name \L: #REF!
Name \M: #REF!
Name \P: #REF!
Name \Y: #REF!
Name _01_30_04: MonthlyOpStats
Name _01_30_04: MonthlyOpStats
Name _1_30_01: MonthlyOpStats
Name _1_30_01: MonthlyOpStats
Name _1_30_02: MonthlyOpStats
Name _1_30_02: MonthlyOpStats
Name _1_31_01: MonthlyOpStats
Name _1_31_01: MonthlyOpStats
Name _1_31_02: MonthlyOpStats
Name _1_31_02: MonthlyOpStats
Name _12_31_05: MonthlyOpStats
Name _12_31_05: MonthlyOpStats
Name _A: #REF!
Name _A___0: #REF!
Name _B: #REF!
Name _B___0: #REF!
Name _C: #REF!
Name _C___0: #REF!
Name _ent1: [1]Inputs!$J$17
Name _ent10: [1]Inputs!$J$476
Name _ent11: [1]Inputs!$J$527
Name _ent12: [1]Inputs!$J$578
Name _ent13: [1]Inputs!$J$629
Name _ent14: [1]Inputs!$J$680
Name _ent15: [1]Inputs!$J$731
Name _ent2: [1]Inputs!$J$68
Name _ent3: [1]Inputs!$J$119
Name _ent4: [1]Inputs!$J$170
Name _ent5: [1]Inputs!$J$221
Name _ent6: [1]Inputs!$J$272
Name _ent7: [1]Inputs!$J$323
Name _ent8: [1]Inputs!$J$374
Name _ent9: [1]Inputs!$J$425
Name _eps1: [1]Inputs!$P$42
Name _eps10: [1]Inputs!$P$501
Name _eps11: [1]Inputs!$P$552
Name _eps12: [1]Inputs!$P$603
Name _eps13: [1]Inputs!$P$654
Name _eps14: [1]Inputs!$P$705
Name _eps15: [1]Inputs!$P$756
Name _eps2: [1]Inputs!$P$93
Name _eps3: [1]Inputs!$P$144
Name _eps4: [1]Inputs!$P$195
Name _eps5: [1]Inputs!$P$246
Name _eps6: [1]Inputs!$P$297
Name _eps7: [1]Inputs!$P$348
Name _eps8: [1]Inputs!$P$399
Name _eps9: [1]Inputs!$P$450
Name _fye1: [1]Inputs!$E$12
Name _fye10: [1]Inputs!$E$471
Name _fye11: [1]Inputs!$E$522
Name _fye12: [1]Inputs!$E$573
Name _fye13: [1]Inputs!$E$624

Sheet Capitalisation
A3: 2Q26
B5: Debt Breakdown as on 30 Jun 2026 | C5: USD mn | D5: Leverage | G5: Company reported | H5: USD mm
G6: Total debentures and lease liabilities | H6: 4353
B7: Current portion | C7: =SUM(C8) -> 830.109 | G7: Debt to Equity | H7: 0.26
B8: Debentures | C8: =Model!$AG$106 -> 830.109 | G8: Debt to EBITDA | H8: 0.61
B10: Non Current portion | C10: =SUM(C11) -> 2449.44
B11: Debentures | C11: =Model!$AG$107 -> 2449.44
B13: Leases | C13: =SUM(C14:C15) -> 1073.788
B14: Current | C14: =Model!$AG$111 -> 410
B15: Non curremt | C15: =Model!$AG$112 -> 663.788
B17: Total Loans & Borrowings | C17: =C13+C7+C10 -> 4353.337 | D17: =C17/C23 -> 0.64801087
B18: Cash and Cash Equivalents | C18: =Model!$AG$119 -> 2498.089
B19: Investments | C19: =Model!$AG$120 -> 98.813
B20: Net debt | C20: =C17-C18-C19 -> 1756.435 | D20: =C20/C23 -> 0.26145207
B21: Equity | C21: =Model!$AG$124 -> 17067.98
B22: Total Capitalisation | C22: =C20+C21 -> 18824.415
B23: LTM Adjusted EBITDA | C23: =Model!$AG$90 -> 6718
B24: check | C24: =+C17-Model!$AG$118 -> 0
B26: Liquidity at the end | C26: USD mn
B27: Cash and Cash Equivalents | C27: =C18 -> 2498.089
B28: Investments | C28: =C19 -> 98.813
B29: Total debt | C29: =SUM(C27:C28) -> 2596.902
B33: Debt Maturity Profile
A65: 1Q26
B67: Debt Breakdown as on 31-Mar-2026 | C67: USD mn | D67: Leverage | G67: Company reported | H67: USD mm
G68: Total debentures and lease liabilities | H68: 3943
B69: Current portion | C69: =SUM(C70) -> 228.105 | G69: Debt to Equity | H69: 0.24
B70: Debentures | C70: =Model!$AF$106 -> 228.105 | G70: Debt to EBITDA | H70: 0.64
B72: Non Current portion | C72: =SUM(C73) -> 2603.826
B73: Debentures | C73: =Model!$AF$107 -> 2603.826
B75: Leases | C75: =SUM(C76:C77) -> 1111.113
B76: Current | C76: =Model!$AF$111 -> 433
B77: Non curremt | C77: =Model!$AF$112 -> 678.113
B79: Total Loans & Borrowings | C79: =C75+C69+C72 -> 3943.044 | D79: =C79/C85 -> 0.64000065
B80: Cash and Cash Equivalents | C80: =Model!$AF$119 -> 2460.358
B81: Investments | C81: =Model!$AF$120 -> 71.839
B82: Net debt | C82: =C79-C80-C81 -> 1410.847 | D82: =C82/C85 -> 0.22899643
B83: Equity | C83: =Model!$AF$124 -> 16226.257
B84: Total Capitalisation | C84: =C82+C83 -> 17637.104
B85: LTM Adjusted EBITDA | C85: =Model!$AF$90 -> 6161
...

Sheet Model
B2: PTT EP | C2: Annual | D2: Annual | E2: Annual | F2: Annual | G2: Annual | H2: Annual | I2: Annual | J2: LTM | L2: Quarters | M2: Quarters | N2: Quarters | O2: Quarters | P2: Quarters | Q2: Quarters | R2: Quarters | S2: Quarters | T2: Quarters | U2: Quarters | V2: Quarters | W2: Quarters | X2: Quarters | Y2: Quarters | Z2: Quarters | AA2: Quarters | AB2: Quarters | AC2: Quarters | AD2: Quarters | AE2: Quarters | AF2: Quarters | AG2: Quarters
B3: (USD million) | C3: 43830 | D3: 44196 | E3: 44561 | F3: 44926 | G3: 45291 | H3: 45657 | I3: 46022 | J3: =AG3 -> 46203 | L3: 44286 | M3: 44377 | N3: 44469 | O3: 44561 | P3: 44651 | Q3: 44742 | R3: 44834 | S3: 44926 | T3: 45016 | U3: 45107 | V3: 45199 | W3: 45291 | X3: 45382 | Y3: 45473 | Z3: 45565 | AA3: 45657 | AB3: 45747 | AC3: 45838 | AD3: 45930 | AE3: 46022 | AF3: 46112 | AG3: 46203
C4: Act | D4: Act | E4: Act | F4: Act | G4: Act | H4: Act | I4: Act | J4: Act | L4: Act | M4: Act | N4: Act | O4: Act | P4: Act | Q4: Act | R4: Act | S4: Act | T4: Act | U4: Act | V4: Act | W4: Act | X4: Act | Y4: Act | Z4: Act | AA4: Act | AB4: Act | AC4: Act | AD4: Act | AE4: Act | AF4: Act | AG4: Act
C5: FY | D5: FY | E5: FY | F5: FY | G5: FY | H5: FY | I5: FY | J5: LTM | L5: 1Q | M5: 2Q | N5: 3Q | O5: 4Q | P5: 1Q | Q5: 2Q | R5: 3Q | S5: 4Q | T5: 1Q | U5: 2Q | V5: 3Q | W5: 4Q | X5: 1Q | Y5: 2Q | Z5: 3Q | AA5: 4Q | AB5: 1Q | AC5: 2Q | AD5: 3Q | AE5: 4Q | AF5: 1Q | AG5: 2Q
B6: INCOME STATEMENT
B7: Total Revenues | C7: =C8+C9 -> 6162.8123 | D7: =D8+D9 -> 5135.52 | E7: =E8+E9 -> 6824.007 | F7: =F8+F9 -> 9421.487 | G7: =G8+G9 -> 8639.146 | H7: =H8+H9 -> 8842.301 | I7: =I8+I9 -> 8562.19 | J7: =J8+J9 -> 9669.379 | L7: =L8+L9 -> 1411.727 | M7: =M8+M9 -> 1748.699 | N7: =N8+N9 -> 1770.325 | O7: =O8+O9 -> 1893.256 | P7: =P8+P9 -> 2060.633 | Q7: =Q8+Q9 -> 2415.255 | R7: =R8+R9 -> 2431.326 | S7: =S8+S9 -> 2514.273 | ... AG7: =AG8+AG9 -> 2949.73
B8: Revenue from sales | C8: 6046.4162 | D8: 5043.17 | E8: 6730.86 | F8: 9270.564 | G8: 8511.079 | H8: 8698.463 | I8: 8437.335 | J8: =SUM(AD8:AG8) -> 9553.838 | L8: 1391.318 | M8: 1728.895 | N8: 1743.639 | O8: =E8-SUM(L8:N8) -> 1867.008 | P8: 2030.275 | Q8: 2382.536 | R8: 2388.305 | S8: =F8-SUM(P8:R8) -> 2469.448 | T8: 2193.048 | U8: 1923.876 | V8: 2192.607 | W8: =G8-SUM(T8:V8) -> 2201.548 | X8: 2093.482 | Y8: 2257.467 | Z8: 2133.415 | AA8: =H8-SUM(X8:Z8) -> 2214.099 | AB8: 2063.802 | AC8: =4184.017-AB8 -> 2120.215 | AD8: 2093.213 | AE8: =I8-SUM(AB8:AD8) -> 2160.105 | AF8: 2376.871 | AG8: =5300.52-AF8 -> 2923.649
B9: Revenue from pipeline transportation | C9: 116.39614 | D9: 92.35 | E9: 93.147 | F9: 150.923 | G9: 128.067 | H9: 143.838 | I9: 124.855 | J9: =SUM(AD9:AG9) -> 115.541 | L9: 20.409 | M9: 19.804 | N9: 26.686 | O9: =E9-SUM(L9:N9) -> 26.248 | P9: 30.358 | Q9: 32.719 | R9: 43.021 | S9: =F9-SUM(P9:R9) -> 44.825 | T9: 34.181 | U9: 33.595 | V9: 30.801 | W9: =G9-SUM(T9:V9) -> 29.49 | X9: 29.417 | Y9: 40.881 | Z9: 40.044 | AA9: =H9-SUM(X9:Z9) -> 33.496 | AB9: 31.985 | AC9: =62.61-AB9 -> 30.625 | AD9: 33.522 | AE9: =I9-SUM(AB9:AD9) -> 28.723 | AF9: 27.215 | AG9: =53.296-AF9 -> 26.081
B10: % of growth | D10: =(D7/C7)-1 -> -0.16669213 | E10: =(E7/D7)-1 -> 0.32878598 | F10: =(F7/E7)-1 -> 0.38063853 | G10: =(G7/F7)-1 -> -0.083037954 | H10: =(H7/G7)-1 -> 0.023515635 | I10: =(I7/H7)-1 -> -0.031678519 | P10: =(P7/L7)-1 -> 0.45965403 | Q10: =(Q7/M7)-1 -> 0.38117252 | R10: =(R7/N7)-1 -> 0.37337833 | S10: =(S7/O7)-1 -> 0.32801533 | T10: =(T7/P7)-1 -> 0.080847002 | U10: =(U7/Q7)-1 -> -0.18953858 | V10: =(V7/R7)-1 -> -0.085516299 | W10: =(W7/S7)-1 -> -0.11265085 | ... AG10: =(AG7/AC7)-1 -> 0.37143163
B11: Operating expenses:
B12: Operating expenses | C12: -750.68233 | D12: -795.112 | E12: -861.495 | F12: -1110.01 | G12: -1224.841 | H12: -1401.808 | I12: -1530.354 | J12: =SUM(AD12:AG12) -> -1722.637 | L12: -174.202 | M12: -192.455 | N12: -219.801 | O12: =E12-SUM(L12:N12) -> -275.037 | P12: -196.719 | Q12: -291.598 | R12: -300.286 | S12: =F12-SUM(P12:R12) -> -321.407 | T12: -360.053 | U12: -247.249 | V12: -337.237 | W12: =G12-SUM(T12:V12) -> -280.302 | X12: -299.61 | Y12: -309.718 | Z12: -367.986 | AA12: =H12-SUM(X12:Z12) -> -424.494 | AB12: -356.128 | AC12: =-734.836-AB12 -> -378.708 | AD12: -369.789 | AE12: =I12-SUM(AB12:AD12) -> -425.729 | AF12: -424.43 | AG12: =-927.119-AF12 -> -502.689
B13: Exploration expenses | C13: -128.09799 | D13: -104.314 | E13: -226.252 | F13: -71.683 | G13: -94.044 | H13: -124.794 | I13: -133.45 | J13: =SUM(AD13:AG13) -> -137.235 | L13: -148.805 | M13: -7.464 | N13: -50.285 | O13: =E13-SUM(L13:N13) -> -19.698 | P13: -6.122 | Q13: -16.553 | R13: -41.497 | S13: =F13-SUM(P13:R13) -> -7.511 | T13: -10.842 | U13: -5.625 | V13: -15.426 | W13: =G13-SUM(T13:V13) -> -62.151 | X13: -46.299 | Y13: -26.601 | Z13: -45.837 | AA13: =H13-SUM(X13:Z13) -> -6.057 | AB13: -8.454 | AC13: =-48.96-AB13 -> -40.506 | AD13: -35.782 | AE13: =I13-SUM(AB13:AD13) -> -48.708 | AF13: -6.761 | AG13: =-52.745-AF13 -> -45.984
B14: Administrative expenses | C14: -383.77651 | D14: -314.117 | E14: -355.039 | F14: -578.363 | G14: -486.938 | H14: -516.071 | I14: -618.145 | J14: =SUM(AD14:AG14) -> -684.189 | L14: -74.945 | M14: -82.935 | N14: -71.625 | O14: =E14-SUM(L14:N14) -> -125.534 | P14: -92.609 | Q14: -112.4 | R14: -80.444 | S14: =F14-SUM(P14:R14) -> -292.91 | T14: -100.293 | U14: -105.718 | V14: -113.153 | W14: =G14-SUM(T14:V14) -> -167.774 | X14: -105.356 | Y14: -111.533 | Z14: -129.436 | AA14: =H14-SUM(X14:Z14) -> -169.746 | AB14: -125.502 | AC14: =-251.496-AB14 -> -125.994 | AD14: -166.273 | AE14: =I14-SUM(AB14:AD14) -> -200.376 | AF14: -152.818 | AG14: =-317.54-AF14 -> -164.722
B15: Petroleum royalties | C15: -546.33421 | D15: -410.154 | E15: -530.215 | F15: -687.723 | G15: -450.155 | H15: -396.387 | I15: -362.676 | J15: =SUM(AD15:AG15) -> -406.894 | L15: -117.6 | M15: -137.964 | N15: -131.997 | O15: =E15-SUM(L15:N15) -> -142.654 | P15: -164.209 | Q15: -178.681 | R15: -170.824 | S15: =F15-SUM(P15:R15) -> -174.009 | T15: -140.516 | U15: -93.562 | V15: -106.837 | W15: =G15-SUM(T15:V15) -> -109.24 | X15: -103.908 | Y15: -104.226 | Z15: -93.523 | AA15: =H15-SUM(X15:Z15) -> -94.73 | AB15: -95.097 | AC15: =-183.889-AB15 -> -88.792 | AD15: -87.983 | AE15: =I15-SUM(AB15:AD15) -> -90.804 | AF15: -104.388 | AG15: =-228.107-AF15 -> -123.719
B16: Depreciation, depletion and amortisation | C16: -2026.0556 | D16: -2086.083 | E16: -2202.064 | F16: -2363.135 | G16: -2334.711 | H16: -2688.941 | I16: -2897.044 | J16: =SUM(AD16:AG16) -> -2879.629 | L16: -546.659 | M16: -629.714 | N16: -605.821 | O16: =E16-SUM(L16:N16) -> -419.87 | P16: -516.759 | Q16: -565.33 | R16: -631.112 | S16: =F16-SUM(P16:R16) -> -649.934 | T16: -491.624 | U16: -559.716 | V16: -629.444 | W16: =G16-SUM(T16:V16) -> -653.927 | X16: -623.245 | Y16: -716.25 | Z16: -722.533 | AA16: =H16-SUM(X16:Z16) -> -626.913 | AB16: -680.711 | AC16: =-1435.575-AB16 -> -754.864 | AD16: -736.682 | AE16: =I16-SUM(AB16:AD16) -> -724.787 | AF16: -668.858 | AG16: =-1418.16-AF16 -> -749.302
B17: Gain/(Loss) on foreign exchange rate | C17: 108.59753 | D17: 26.062 | E17: -37.592 | F17: -91.064 | G17: 48.129 | H17: 6.49 | I17: 51.425 | J17: =SUM(AD17:AG17) -> 38.053 | L17: -4.462 | M17: -1.753 | N17: -36.323 | O17: =E17-SUM(L17:N17) -> 4.946 | P17: -4.824 | Q17: -44.217 | R17: -86.591 | S17: =F17-SUM(P17:R17) -> 44.568 | T17: 18.966 | U17: 8.798 | V17: -4.905 | W17: =G17-SUM(T17:V17) -> 25.27 | X17: -2.063 | Y17: 0.799 | Z17: 0 | AA17: =H17-SUM(X17:Z17) -> 7.754 | AB17: 0 | AC17: =1.814-AB17 -> 1.814 | AD17: 0 | AE17: =I17-SUM(AB17:AD17) -> 49.611 | AF17: 23.191 | AG17: =-11.558-AF17 -> -34.749
B18: Loss on remeasuring of financial instruments | C18: -109.39972 | D18: 0 | E18: -234.29 | F18: -184.486 | G18: -55.588 | H18: 0 | I18: 0 | J18: =SUM(AD18:AG18) -> -152.523 | L18: -98.359 | M18: -124.35 | N18: -5.052 | O18: =E18-SUM(L18:N18) -> -6.529 | P18: -245.612 | Q18: 0 | R18: 0 | S18: =F18-SUM(P18:R18) -> 61.126 | T18: -41.765 | U18: 0 | V18: -19.904 | W18: =G18-SUM(T18:V18) -> 6.081 | X18: -11.832 | Y18: 0 | Z18: -31.036 | AA18: =H18-SUM(X18:Z18) -> 42.868 | AB18: 0 | AC18: =0-AB18 -> 0 | AD18: -17.577 | AE18: =I18-SUM(AB18:AD18) -> 17.577 | AF18: -276.41 | AG18: =-152.523-AF18 -> 123.887
B19: Impairment loss on assets and goodwill | C19: 0 | D19: -91.576 | E19: 0 | F19: 0 | G19: 0 | H19: 0 | I19: 0 | J19: =SUM(AD19:AG19) -> 0 | L19: 0 | M19: 0 | N19: 0 | O19: =E19-SUM(L19:N19) -> 0 | P19: 0 | Q19: 0 | R19: 0 | S19: =F19-SUM(P19:R19) -> 0 | T19: 0 | U19: 0 | V19: 0 | W19: =G19-SUM(T19:V19) -> 0 | X19: 0 | Y19: 0 | Z19: 0 | AA19: =H19-SUM(X19:Z19) -> 0 | AB19: 0 | AC19: =0-AB19 -> 0 | AD19: 0 | AE19: =I19-SUM(AB19:AD19) -> 0 | AF19: 0 | AG19: =0-AF19 -> 0
B20: Impairment loss on assets held-for-sale | C20: 0 | D20: 0 | E20: -183 | F20: -300.08 | G20: -120 | H20: 0 | I20: 0 | J20: =SUM(AD20:AG20) -> 0 | L20: 0 | M20: 0 | N20: 0 | O20: =E20-SUM(L20:N20) -> -183 | P20: 0 | Q20: 0 | R20: -94.996 | S20: =F20-SUM(P20:R20) -> -205.084 | T20: 0 | U20: 0 | V20: 0 | W20: =G20-SUM(T20:V20) -> -120 | X20: 0 | Y20: 0 | Z20: 0 | AA20: =H20-SUM(X20:Z20) -> 0 | AB20: 0 | AC20: =0-AB20 -> 0 | AD20: 0 | AE20: =I20-SUM(AB20:AD20) -> 0 | AF20: 0 | AG20: =0-AF20 -> 0
B21: Gain on debt modification | C21: 0 | D21: 22.307 | E21: 0 | F21: 0 | G21: 0 | H21: 0 | I21: 0 | J21: =SUM(AD21:AG21) -> 0 | L21: 0 | M21: 0 | N21: 0 | O21: =E21-SUM(L21:N21) -> 0 | P21: 0 | Q21: 0 | R21: 0 | S21: =F21-SUM(P21:R21) -> 0 | T21: 0 | U21: 0 | V21: 0 | W21: =G21-SUM(T21:V21) -> 0 | X21: 0 | Y21: 0 | Z21: 22.741 | AA21: =H21-SUM(X21:Z21) -> -22.741 | AB21: -8.202 | AC21: =0-AB21 -> 8.202 | AD21: 34.656 | AE21: =I21-SUM(AB21:AD21) -> -34.656 | AF21: 0 | AG21: =0-AF21 -> 0
B22: Gain on remeasuring of financial instruments | C22: 0 | D22: 99.331 | E22: 0 | F22: 0 | G22: 0 | H22: 0 | I22: 0 | J22: =SUM(AD22:AG22) -> -6.573 | L22: 0 | M22: 0 | N22: 0 | O22: =E22-SUM(L22:N22) -> 0 | P22: 0 | Q22: 8.724 | R22: 152.519 | S22: =F22-SUM(P22:R22) -> -161.243 | T22: 0 | U22: 28.538 | V22: 0 | W22: =G22-SUM(T22:V22) -> -28.538 | X22: 0 | Y22: 13.964 | Z22: 0 | AA22: =H22-SUM(X22:Z22) -> -13.964 | AB22: 4.609 | AC22: =6.573-AB22 -> 1.964 | AD22: 0 | AE22: =I22-SUM(AB22:AD22) -> -6.573 | AF22: 0 | AG22: =0-AF22 -> 0
B23: Other operating income/(loss), net | C23: 55.390651 | D23: =37.012-20.341 -> 16.671 | E23: 131.594 | F23: 195.134 | G23: =144.545+73.239 -> 217.784 | H23: =174.592+11.089 -> 185.681 | I23: =(17076+161400)/1000 -> 178.476 | J23: =SUM(AD23:AG23) -> 188.303 | L23: 11.675 | M23: 14.392 | N23: 10.459 | O23: =E23-SUM(L23:N23) -> 95.068 | P23: 18.173 | Q23: 39.519 | R23: 21.835 | S23: =F23-SUM(P23:R23) -> 115.607 | T23: 33.373 | U23: 41.488 | V23: 31.442 | W23: =G23-SUM(T23:V23) -> 111.481 | X23: 29.487 | Y23: 32.171 | Z23: 50.93 | AA23: =H23-SUM(X23:Z23) -> 73.093 | AB23: 30.623 | AC23: =72.194-AB23 -> 41.571 | AD23: 33.209 | AE23: =I23-SUM(AB23:AD23) -> 73.073 | AF23: 35.631 | AG23: =82.021-AF23 -> 46.39
B24: Operating profit | C24: =C7+SUM(C12:C23) -> 2382.4541 | D24: =D7+SUM(D12:D23) -> 1498.535 | E24: =E7+SUM(E12:E23) -> 2325.654 | F24: =F7+SUM(F12:F23) -> 4230.077 | G24: =G7+SUM(G12:G23) -> 4138.782 | H24: =H7+SUM(H12:H23) -> 3906.471 | I24: =I7+SUM(I12:I23) -> 3250.422 | J24: =J7+SUM(J12:J23) -> 3906.055 | L24: =L7+SUM(L12:L23) -> 258.37 | M24: =M7+SUM(M12:M23) -> 586.456 | N24: =N7+SUM(N12:N23) -> 659.88 | O24: =O7+SUM(O12:O23) -> 820.948 | P24: =P7+SUM(P12:P23) -> 851.952 | Q24: =Q7+SUM(Q12:Q23) -> 1254.719 | R24: =R7+SUM(R12:R23) -> 1199.93 | S24: =S7+SUM(S12:S23) -> 923.476 | ... AG24: =AG7+SUM(AG12:AG23) -> 1498.842
B25: Finance exps | C25: -234.97874 | D25: -254.476 | E25: -202.226 | F25: -233.583 | G25: -294.457 | H25: -334.466 | I25: -397.662 | J25: =SUM(AD25:AG25) -> -389.98 | L25: -48.02 | M25: -51.372 | N25: -52.008 | O25: =E25-SUM(L25:N25) -> -50.826 | P25: -51.968 | Q25: -63.694 | R25: -62.335 | S25: =F25-SUM(P25:R25) -> -55.586 | T25: -77.159 | U25: -75.596 | V25: -75.458 | W25: =G25-SUM(T25:V25) -> -66.244 | X25: -84.854 | Y25: -87.501 | Z25: -84.507 | AA25: =H25-SUM(X25:Z25) -> -77.604 | AB25: -96.744 | AC25: =-193.895-AB25 -> -97.151 | AD25: -98.579 | AE25: =I25-SUM(AB25:AD25) -> -105.188 | AF25: -91.919 | AG25: =-186.213-AF25 -> -94.294
B26: Finance income | C26: 86.234821 | D26: 36.729 | E26: 16.75 | F26: 44.031 | G26: 152.274 | H26: 238.34 | I26: 178.192 | J26: =SUM(AD26:AG26) -> 133.267 | L26: 5.131 | M26: 4.726 | N26: 3.465 | O26: =E26-SUM(L26:N26) -> 3.428 | P26: 4.264 | Q26: 5.587 | R26: 11.402 | S26: =F26-SUM(P26:R26) -> 22.778 | T26: 34.787 | U26: 37.334 | V26: 36.906 | W26: =G26-SUM(T26:V26) -> 43.247 | X26: 56.7 | Y26: 66.399 | Z26: 59.846 | AA26: =H26-SUM(X26:Z26) -> 55.395 | AB26: 54.049 | AC26: =103.79-AB26 -> 49.741 | AD26: 39.804 | AE26: =I26-SUM(AB26:AD26) -> 34.598 | AF26: 28.37 | AG26: =58.865-AF26 -> 30.495
B27: Gain from a bargain purchase | C27: 0 | D27: 0 | E27: 341.874 | F27: 0 | G27: 0 | H27: 0 | I27: 0 | J27: =SUM(AD27:AG27) -> 0 | L27: 349.971 | M27: 0 | N27: 0 | O27: =E27-SUM(L27:N27) -> -8.097 | P27: 0 | Q27: 0 | R27: 0 | S27: =F27-SUM(P27:R27) -> 0 | T27: 0 | U27: 0 | V27: 0 | W27: =G27-SUM(T27:V27) -> 0 | X27: 0 | Y27: 0 | Z27: 0 | AA27: =H27-SUM(X27:Z27) -> 0 | AB27: 0 | AC27: =0-AB27 -> 0 | AD27: 0 | AE27: =I27-SUM(AB27:AD27) -> 0 | AF27: 0 | AG27: =0-AF27 -> 0
B28: Share of net profit /(loss) of associates | C28: 12.351839 | D28: 41.636 | E28: 15.174 | F28: 19.556 | G28: 42.566 | H28: 37.752 | I28: 130.224 | J28: =SUM(AD28:AG28) -> 152.513 | L28: 2.179 | M28: 2.795 | N28: 6.895 | O28: =E28-SUM(L28:N28) -> 3.305 | P28: 10.567 | Q28: 12.964 | R28: -17.485 | S28: =F28-SUM(P28:R28) -> 13.51 | T28: 12.42 | U28: 9.623 | V28: 9.096 | W28: =G28-SUM(T28:V28) -> 11.427 | X28: 10.181 | Y28: 5.475 | Z28: 1.019 | AA28: =H28-SUM(X28:Z28) -> 21.077 | AB28: 13.758 | AC28: =18.535-AB28 -> 4.777 | AD28: 4.868 | AE28: =I28-SUM(AB28:AD28) -> 106.821 | AF28: 24.791 | AG28: =40.824-AF28 -> 16.033
B29: Profit before tax | C29: =C24+SUM(C25:C28) -> 2246.062 | D29: =D24+SUM(D25:D28) -> 1322.424 | E29: =E24+SUM(E25:E28) -> 2497.226 | F29: =F24+SUM(F25:F28) -> 4060.081 | G29: =G24+SUM(G25:G28) -> 4039.165 | H29: =H24+SUM(H25:H28) -> 3848.097 | I29: =I24+SUM(I25:I28) -> 3161.176 | J29: =J24+SUM(J25:J28) -> 3801.855 | L29: =L24+SUM(L25:L28) -> 567.631 | M29: =M24+SUM(M25:M28) -> 542.605 | N29: =N24+SUM(N25:N28) -> 618.232 | O29: =O24+SUM(O25:O28) -> 768.758 | P29: =P24+SUM(P25:P28) -> 814.815 | Q29: =Q24+SUM(Q25:Q28) -> 1209.576 | R29: =R24+SUM(R25:R28) -> 1131.512 | S29: =S24+SUM(S25:S28) -> 904.178 | ... AG29: =AG24+SUM(AG25:AG28) -> 1451.076
B30: Income taxes | C30: -676.99805 | D30: -602.88 | E30: -1286.688 | F30: -2061.501 | G30: -1831.388 | H30: -1621.179 | I30: -1331.232 | J30: =SUM(AD30:AG30) -> -1657.999 | L30: -191.611 | M30: -320.957 | N30: -326.179 | O30: =E30-SUM(L30:N30) -> -447.941 | P30: -496.785 | Q30: -609.835 | R30: -467.916 | S30: =F30-SUM(P30:R30) -> -486.965 | T30: -535.276 | U30: -385.423 | V30: -484.442 | W30: =G30-SUM(T30:V30) -> -426.247 | X30: -418.589 | Y30: -408.277 | Z30: -321.662 | AA30: =H30-SUM(X30:Z30) -> -472.651 | AB30: -340.537 | AC30: =-705.767-AB30 -> -365.23 | AD30: -334.071 | AE30: =I30-SUM(AB30:AD30) -> -291.394 | AF30: =(-414661)/1000 -> -414.661 | AG30: =-1032.534-AF30 -> -617.873
B31: Net profit/loss | C31: =+C29+C30 -> 1569.064 | D31: =+D29+D30 -> 719.544 | E31: =+E29+E30 -> 1210.538 | F31: =+F29+F30 -> 1998.58 | G31: =+G29+G30 -> 2207.777 | H31: =+H29+H30 -> 2226.918 | I31: =+I29+I30 -> 1829.944 | J31: =+J29+J30 -> 2143.856 | L31: =+L29+L30 -> 376.02 | M31: =+M29+M30 -> 221.648 | N31: =+N29+N30 -> 292.053 | O31: =+O29+O30 -> 320.817 | P31: =+P29+P30 -> 318.03 | Q31: =+Q29+Q30 -> 599.741 | R31: =+R29+R30 -> 663.596 | S31: =+S29+S30 -> 417.213 | ... AG31: =+AG29+AG30 -> 833.203
B32: % margin | C32: =+C31/C7 -> 0.25460195 | D32: =+D31/D7 -> 0.14011123 | E32: =+E31/E7 -> 0.17739401 | F32: =+F31/F7 -> 0.21213 | G32: =+G31/G7 -> 0.25555501 | H32: =+H31/H7 -> 0.25184825 | I32: =+I31/I7 -> 0.21372383 | J32: =+J31/J7 -> 0.221716 | L32: =+L31/L7 -> 0.26635461 | M32: =+M31/M7 -> 0.12675023 | N32: =+N31/N7 -> 0.1649714 | O32: =+O31/O7 -> 0.16945252 | P32: =+P31/P7 -> 0.15433607 | Q32: =+Q31/Q7 -> 0.24831374 | R32: =+R31/R7 -> 0.27293584 | S32: =+S31/S7 -> 0.16593783 | ... AG32: =+AG31/AG7 -> 0.28246755
B34: As % of sales unless stated otherwise
B35: =B12 -> Operating expenses | C35: =-C12/C7 -> 0.1218084 | D35: =-D12/D7 -> 0.154826 | E35: =-E12/E7 -> 0.12624474 | F35: =-F12/F7 -> 0.11781686 | G35: =-G12/G7 -> 0.14177802 | H35: =-H12/H7 -> 0.1585343 | I35: =-I12/I7 -> 0.17873395 | J35: =-J12/J7 -> 0.17815384 | L35: =-L12/L7 -> 0.12339638 | M35: =-M12/M7 -> 0.1100561 | N35: =-N12/N7 -> 0.12415856 | O35: =-O12/O7 -> 0.14527195 | P35: =-P12/P7 -> 0.095465325 | Q35: =-Q12/Q7 -> 0.12073177 | R35: =-R12/R7 -> 0.12350709 | S35: =-S12/S7 -> 0.12783298 | ... AG35: =-AG12/AG7 -> 0.17041865
B36: =B13 -> Exploration expenses | C36: =-C13/C7 -> 0.020785639 | D36: =-D13/D7 -> 0.020312257 | E36: =-E13/E7 -> 0.0331553 | F36: =-F13/F7 -> 0.0076084593 | G36: =-G13/G7 -> 0.010885798 | H36: =-H13/H7 -> 0.014113295 | I36: =-I13/I7 -> 0.015585966 | J36: =-J13/J7 -> 0.014192742 | L36: =-L13/L7 -> 0.10540636 | M36: =-M13/M7 -> 0.004268316 | N36: =-N13/N7 -> 0.028404389 | O36: =-O13/O7 -> 0.010404298 | P36: =-P13/P7 -> 0.0029709317 | Q36: =-Q13/Q7 -> 0.0068535206 | R36: =-R13/R7 -> 0.017067641 | S36: =-S13/S7 -> 0.0029873447 | ... AG36: =-AG13/AG7 -> 0.015589223
B37: =B15 -> Petroleum royalties | C37: =-C15/C7 -> 0.088650146 | D37: =-D15/D7 -> 0.079866109 | E37: =-E15/E7 -> 0.077698484 | F37: =-F15/F7 -> 0.072995165 | G37: =-G15/G7 -> 0.052106423 | H37: =-H15/H7 -> 0.04482849 | I37: =-I15/I7 -> 0.042357855 | J37: =-J15/J7 -> 0.042080676 | L37: =-L15/L7 -> 0.083302225 | M37: =-M15/M7 -> 0.078895224 | N37: =-N15/N7 -> 0.074560886 | O37: =-O15/O7 -> 0.0753485 | P37: =-P15/P7 -> 0.07968862 | Q37: =-Q15/Q7 -> 0.07398018 | R37: =-R15/R7 -> 0.070259603 | S37: =-S15/S7 -> 0.069208475 | ... AG37: =-AG15/AG7 -> 0.041942483
B38: =B23 -> Other operating income/(loss), net | C38: =-C23/C7 -> -0.0089878855 | D38: =-D23/D7 -> -0.0032462146 | E38: =-E23/E7 -> -0.019283978 | F38: =-F23/F7 -> -0.020711593 | G38: =-G23/G7 -> -0.025208973 | H38: =-H23/H7 -> -0.020999172 | I38: =-I23/I7 -> -0.020844667 | J38: =-J23/J7 -> -0.019474157 | L38: =-L23/L7 -> -0.0082700125 | M38: =-M23/M7 -> -0.0082301185 | N38: =-N23/N7 -> -0.0059079548 | O38: =-O23/O7 -> -0.050214023 | P38: =-P23/P7 -> -0.0088191347 | Q38: =-Q23/Q7 -> -0.016362247 | R38: =-R23/R7 -> -0.0089806961 | S38: =-S23/S7 -> -0.045980289 | ... AG38: =-AG23/AG7 -> -0.015726863
B39: Finance exps as % of debt | C39: =-C25/C118 -> 0.068273994 | D39: =-D25/D118 -> 0.064718223 | E39: =-E25/E118 -> 0.04939914 | F39: =-F25/F118 -> 0.060939645 | G39: =-G25/G118 -> 0.080593088 | H39: =-H25/H118 -> 0.088925792 | I39: =-I25/I118 -> 0.099067599 | J39: =-J25/J118 -> 0.089581854 | O39: =-SUM(L25:O25)/O118 -> 0.04939914 | P39: =-SUM(M25:P25)/P118 -> 0.05034977 | Q39: =-SUM(N25:Q25)/Q118 -> 0.051495118 | R39: =-SUM(O25:R25)/R118 -> 0.053541992 | S39: =-SUM(P25:S25)/S118 -> 0.060939645 | T39: =-SUM(Q25:T25)/T118 -> 0.067229375 | U39: =-SUM(R25:U25)/U118 -> 0.073937636 | V39: =-SUM(S25:V25)/V118 -> 0.07880648 | ... AG39: =-SUM(AD25:AG25)/AG118 -> 0.089581854
B40: Finance income as % of cash and cash equivalents | C40: =C26/C119 -> 0.030548341 | D40: =D26/D119 -> 0.0099160287 | E40: =E26/E119 -> 0.0065450422 | F40: =F26/F119 -> 0.012440877 | G40: =G26/G119 -> 0.037888916 | H40: =H26/H119 -> 0.060520603 | I40: =I26/I119 -> 0.077012973 | J40: =J26/J119 -> 0.053347579 | O40: =SUM(L26:O26)/O119 -> 0.0065450422 | P40: =SUM(M26:P26)/P119 -> 0.0047468591 | Q40: =SUM(N26:Q26)/Q119 -> 0.005966386 | R40: =SUM(O26:R26)/R119 -> 0.0071829446 | S40: =SUM(P26:S26)/S119 -> 0.012440877 | T40: =SUM(Q26:T26)/T119 -> 0.017576895 | U40: =SUM(R26:U26)/U119 -> 0.034686395 | V40: =SUM(S26:V26)/V119 -> 0.043411629 | ... AG40: =SUM(AD26:AG26)/AG119 -> 0.053347579
B41: =B28 -> Share of net profit /(loss) of associates | C41: =-C28/C7 -> -0.0020042536 | D41: =-D28/D7 -> -0.0081074555 | E41: =-E28/E7 -> -0.0022236202 | F41: =-F28/F7 -> -0.0020756808 | G41: =-G28/G7 -> -0.0049271074 | H41: =-H28/H7 -> -0.0042694769 | I41: =-I28/I7 -> -0.015209193 | J41: =-J28/J7 -> -0.015772781 | L41: =-L28/L7 -> -0.0015434996 | M41: =-M28/M7 -> -0.0015983311 | N41: =-N28/N7 -> -0.0038947651 | O41: =-O28/O7 -> -0.0017456699 | P41: =-P28/P7 -> -0.0051280359 | Q41: =-Q28/Q7 -> -0.0053675492 | R41: =-R28/R7 -> 0.007191549 | S41: =-S28/S7 -> -0.0053733226 | ... AG41: =-AG28/AG7 -> -0.0054354127
B42: Tax % of PBT | C42: =-C30/C29 -> 0.30141556 | D42: =-D30/D29 -> 0.45589009 | E42: =-E30/E29 -> 0.51524692 | F42: =-F30/F29 -> 0.50774874 | G42: =-G30/G29 -> 0.45340757 | H42: =-H30/H29 -> 0.42129369 | I42: =-I30/I29 -> 0.42111923 | J42: =-J30/J29 -> 0.43610264 | L42: =-L30/L29 -> 0.33756261 | M42: =-M30/M29 -> 0.59151132 | N42: =-N30/N29 -> 0.52759967 | O42: =-O30/O29 -> 0.58268142 | P42: =-P30/P29 -> 0.60969054 | Q42: =-Q30/Q29 -> 0.50417254 | R42: =-R30/R29 -> 0.41353163 | S42: =-S30/S29 -> 0.53857205 | ... AG42: =-AG30/AG29 -> 0.42580333
...

Sheet KPIs
B2: PTT EP | C2: Annual | D2: Annual | E2: Annual | F2: Annual | G2: Annual | H2: Annual | I2: Annual | J2: LTM | L2: Quarters | M2: Quarters | N2: Quarters | O2: Quarters | P2: Quarters | Q2: Quarters | R2: Quarters | S2: Quarters | T2: Quarters | U2: Quarters | V2: Quarters | W2: Quarters | X2: Quarters | Y2: Quarters | Z2: Quarters | AA2: Quarters | AB2: Quarters | AC2: Quarters | AD2: Quarters | AE2: Quarters | AF2: Quarters | AG2: Quarters
B3: (USD million) | C3: 43830 | D3: 44196 | E3: 44561 | F3: 44926 | G3: 45291 | H3: 45657 | I3: 46022 | J3: =AG3 -> 46203 | L3: 44286 | M3: 44377 | N3: 44469 | O3: 44561 | P3: 44651 | Q3: 44742 | R3: 44834 | S3: 44926 | T3: 45016 | U3: 45107 | V3: 45199 | W3: 45291 | X3: 45382 | Y3: 45473 | Z3: 45565 | AA3: 45657 | AB3: 45747 | AC3: 45838 | AD3: 45930 | AE3: 46022 | AF3: 46112 | AG3: 46203
C4: Act | D4: Act | E4: Act | F4: Act | G4: Act | H4: Act | I4: Act | J4: Act | L4: Act | M4: Act | N4: Act | O4: Act | P4: Act | Q4: Act | R4: Act | S4: Act | T4: Act | U4: Act | V4: Act | W4: Act | X4: Act | Y4: Act | Z4: Act | AA4: Act | AB4: Act | AC4: Act | AD4: Act | AE4: Act | AF4: Act | AG4: Act
C5: FY | D5: FY | E5: FY | F5: FY | G5: FY | H5: FY | I5: FY | J5: LTM | L5: 1Q | M5: 2Q | N5: 3Q | O5: 4Q | P5: 1Q | Q5: 2Q | R5: 3Q | S5: 4Q | T5: 1Q | U5: 2Q | V5: 3Q | W5: 4Q | X5: 1Q | Y5: 2Q | Z5: 3Q | AA5: 4Q | AB5: 1Q | AC5: 2Q | AD5: 3Q | AE5: 4Q | AF5: 1Q | AG5: 2Q
B7: Exploration and Production | C7: =SUM(C10:C16) -> 1634 | D7: =SUM(D10:D16) -> 868 | E7: =SUM(E10:E16) -> 1698 | F7: =SUM(F10:F16) -> 2489 | G7: =SUM(G10:G16) -> 2513 | H7: =SUM(H10:H16) -> 2399 | I7: =SUM(I10:I16) -> 2057 | J7: =SUM(J10:J16) -> 2559 | L7: =SUM(L10:L16) -> 539 | M7: =SUM(M10:M16) -> 394.5 | N7: =SUM(N10:N16) -> 365.5 | O7: =SUM(O10:O16) -> 399 | P7: =SUM(P10:P16) -> 631 | Q7: =SUM(Q10:Q16) -> 682 | R7: =SUM(R10:R16) -> 610 | S7: =SUM(S10:S16) -> 566 | ... AG7: =SUM(AG10:AG16) -> 812
B9: Southeast Asia | C9: =SUM(C10:C11) -> 1660 | D9: =SUM(D10:D11) -> 944 | E9: =SUM(E10:E11) -> 1576 | F9: =SUM(F10:F11) -> 2626 | G9: =SUM(G10:G11) -> 2277 | H9: =SUM(H10:H11) -> 2100 | I9: =SUM(I10:I11) -> 1767 | J9: =SUM(J10:J11) -> 2215 | L9: =SUM(L10:L11) -> 324 | M9: =SUM(M10:M11) -> 382 | N9: =SUM(N10:N11) -> 324 | O9: =SUM(O10:O11) -> 546 | P9: =SUM(P10:P11) -> 584 | Q9: =SUM(Q10:Q11) -> 632 | R9: =SUM(R10:R11) -> 682 | S9: =SUM(S10:S11) -> 728 | ... AG9: =SUM(AG10:AG11) -> 724
B10: Thailand | C10: 1236 | D10: 799 | E10: 1220 | F10: 1843 | G10: 1608 | H10: 1530 | I10: 1214 | J10: =SUM(AD10:AG10) -> 1674 | L10: 270 | M10: 307 | N10: 271 | O10: =E10-SUM(L10:N10) -> 372 | P10: 418 | Q10: 480 | R10: 421 | S10: =F10-SUM(P10:R10) -> 524 | T10: 413 | U10: 413 | V10: 384 | W10: =G10-SUM(T10:V10) -> 398 | X10: 394 | Y10: 404 | Z10: 362 | AA10: =H10-SUM(X10:Z10) -> 370 | AB10: 318 | AC10: 282 | AD10: 302 | AE10: =I10-SUM(AB10:AD10) -> 312 | AF10: 498 | AG10: 562
B11: Other Southeast Asia | C11: 424 | D11: 145 | E11: 356 | F11: 783 | G11: 669 | H11: 570 | I11: 553 | J11: =SUM(AD11:AG11) -> 541 | L11: 54 | M11: 75 | N11: 53 | O11: =E11-SUM(L11:N11) -> 174 | P11: 166 | Q11: 152 | R11: 261 | S11: =F11-SUM(P11:R11) -> 204 | T11: 163 | U11: 163 | V11: 173 | W11: =G11-SUM(T11:V11) -> 170 | X11: 97 | Y11: 176 | Z11: 194 | AA11: =H11-SUM(X11:Z11) -> 103 | AB11: 155 | AC11: 136 | AD11: 141 | AE11: =I11-SUM(AB11:AD11) -> 121 | AF11: 117 | AG11: 162
B12: Middle East | C12: 0 | D12: -13 | E12: 426 | F12: 292 | G12: 223 | H12: 204 | I12: 142 | J12: =SUM(AD12:AG12) -> 48 | L12: 351 | M12: 6 | N12: 32 | O12: =E12-SUM(L12:N12) -> 37 | P12: 54 | Q12: 56 | R12: 64 | S12: =F12-SUM(P12:R12) -> 118 | T12: 69 | U12: 69 | V12: 39 | W12: =G12-SUM(T12:V12) -> 46 | X12: 57 | Y12: 57 | Z12: 34 | AA12: =H12-SUM(X12:Z12) -> 56 | AB12: 31 | AC12: 63 | AD12: 16 | AE12: =I12-SUM(AB12:AD12) -> 32
B13: Australia | C13: -15 | D13: -28 | E13: 5 | F13: -164 | G13: 22 | H13: 0 | I13: 0 | J13: =SUM(AD13:AG13) -> 0 | L13: -1 | M13: -0.5 | N13: -0.5 | O13: =E13-SUM(L13:N13) -> 7 | P13: -1 | Q13: -1 | R13: -31 | S13: =F13-SUM(P13:R13) -> -131 | T13: 1 | U13: 1 | V13: -1 | W13: =G13-SUM(T13:V13) -> 21 | X13: 0 | Y13: -30 | Z13: -23 | AA13: =H13-SUM(X13:Z13) -> 53
B14: America | C14: -10 | D14: -56 | E14: -175 | F14: -110 | G14: -8 | H14: 0 | I14: 0 | J14: =SUM(AD14:AG14) -> 0 | L14: -146 | M14: -2 | N14: -2 | O14: =E14-SUM(L14:N14) -> -25 | P14: -7 | Q14: -4 | R14: -96 | S14: =F14-SUM(P14:R14) -> -3 | T14: -2 | U14: -2 | V14: -3 | W14: =G14-SUM(T14:V14) -> -1 | X14: -2 | Y14: -2 | Z14: 0 | AA14: =H14-SUM(X14:Z14) -> 4
B15: Africa | C15: 14 | D15: 23 | E15: -147 | F15: -167 | G15: -6 | H15: 144 | I15: 180 | J15: =SUM(AD15:AG15) -> 139 | L15: 7 | M15: 6 | N15: 9 | O15: =E15-SUM(L15:N15) -> -169 | P15: -3 | Q15: -6 | R15: -10 | S15: =F15-SUM(P15:R15) -> -148 | T15: 19 | U15: 19 | V15: 33 | W15: =G15-SUM(T15:V15) -> -77 | X15: 23 | Y15: 56 | Z15: 23 | AA15: =H15-SUM(X15:Z15) -> 42 | AB15: 13 | AC15: 28 | AD15: 16 | AE15: =I15-SUM(AB15:AD15) -> 123
B16: Others | C16: -15 | D16: -2 | E16: 13 | F16: 12 | G16: 5 | H16: -49 | I16: -32 | J16: =SUM(AD16:AG16) -> 157 | L16: 4 | M16: 3 | N16: 3 | O16: =E16-SUM(L16:N16) -> 3 | P16: 4 | Q16: 5 | R16: 1 | S16: =F16-SUM(P16:R16) -> 2 | T16: 1 | U16: 1 | V16: 1 | W16: =G16-SUM(T16:V16) -> 2 | X16: 4 | Y16: 2 | Z16: 0 | AA16: =H16-SUM(X16:Z16) -> -55 | AB16: 1 | AC16: -37 | AD16: 3 | AE16: =I16-SUM(AB16:AD16) -> 1 | AF16: 65 | AG16: 88
B17: Head office and others | C17: -65 | D17: -148 | E17: -487 | F17: -490 | G17: -305 | H17: -172 | I17: -227 | J17: =SUM(AD17:AG17) -> -437 | L17: -163 | M17: -173 | N17: -74 | O17: =E17-SUM(L17:N17) -> -77 | P17: -313 | Q17: -82 | R17: 54 | S17: =F17-SUM(P17:R17) -> -149 | T17: -95 | U17: -95 | V17: -16 | W17: =G17-SUM(T17:V17) -> -99 | X17: -49 | Y17: -10 | Z17: -79 | AA17: =H17-SUM(X17:Z17) -> -34 | AB17: -30 | AC17: -64 | AD17: -85 | AE17: =I17-SUM(AB17:AD17) -> -48 | AF17: -304 | AG17: 0
B19: Total | C19: =C17+C7 -> 1569 | D19: =D17+D7 -> 720 | E19: =E17+E7 -> 1211 | F19: =F17+F7 -> 1999 | G19: =G17+G7 -> 2208 | H19: =H17+H7 -> 2227 | I19: =I17+I7 -> 1830 | J19: =J17+J7 -> 2122 | L19: =L17+L7 -> 376 | M19: =M17+M7 -> 221.5 | N19: =N17+N7 -> 291.5 | O19: =O17+O7 -> 322 | P19: =P17+P7 -> 318 | Q19: =Q17+Q7 -> 600 | R19: =R17+R7 -> 664 | S19: =S17+S7 -> 417 | ... AG19: =AG17+AG7 -> 812
B21: Average Sales Volume (Barrels of Oil Equivalent per Day)
B22: By product type
B23: Gas | C23: 248537 | D23: 236314 | E23: 296838 | F23: 339421 | G23: 331083 | H23: 354391 | I23: 369255 | J23: =AVERAGE(AD23:AG23) -> 400111.25 | L23: 270982 | M23: 317243 | N23: 300319 | O23: =E23 -> 296838 | P23: 310757 | Q23: 336924 | R23: 347908 | S23: =F23 -> 339421 | T23: 332351 | U23: 323336 | V23: 328265 | W23: 340325 | X23: 345454 | Y23: 373464 | Z23: 343138 | AA23: 355616 | AB23: 354884 | AC23: 356674 | AD23: 378417 | AE23: 386598 | AF23: 412304 | AG23: 423126
B24: Liquid | C24: 102114 | D24: 117738 | E24: 119303 | F24: 128709 | G24: 130924 | H24: 134403 | I24: 140651 | J24: =AVERAGE(AD24:AG24) -> 143956.5 | L24: 111895 | M24: 125883 | N24: 116848 | O24: =E24 -> 119303 | P24: 116611 | Q24: 128535 | R24: 130415 | S24: =F24 -> 128709 | T24: 128466 | U24: 121532 | V24: 139187 | W24: 134354 | X24: 127594 | Y24: 133245 | Z24: 131940 | AA24: 144749 | AB24: 129334 | AC24: 148098 | AD24: 132080 | AE24: 152925 | AF24: 141065 | AG24: 149756
B25: Total | C25: =SUM(C23:C24) -> 350651 | D25: =SUM(D23:D24) -> 354052 | E25: =SUM(E23:E24) -> 416141 | F25: =SUM(F23:F24) -> 468130 | G25: =SUM(G23:G24) -> 462007 | H25: =SUM(H23:H24) -> 488794 | I25: =SUM(I23:I24) -> 509906 | J25: =SUM(J23:J24) -> 544067.75 | L25: =SUM(L23:L24) -> 382877 | M25: =SUM(M23:M24) -> 443126 | N25: =SUM(N23:N24) -> 417167 | O25: =SUM(O23:O24) -> 416141 | P25: =SUM(P23:P24) -> 427368 | Q25: =SUM(Q23:Q24) -> 465459 | R25: =SUM(R23:R24) -> 478323 | S25: =SUM(S23:S24) -> 468130 | ... AG25: =SUM(AG23:AG24) -> 572882
B27: By geographical region
B28: Thailand | C28: 273981 | D28: 249481 | E28: 264382 | F28: 295362 | G28: 306750 | H28: 334205 | I28: 353491 | J28: =AVERAGE(AD28:AG28) -> 379139.5 | L28: 274242 | M28: 272819 | N28: 255150 | O28: =E28 -> 264382 | P28: 264424 | Q28: 290086 | R28: 302056 | S28: =F28 -> 295362 | T28: 314421 | U28: 295986 | V28: 301386 | W28: 315258 | X28: 320221 | Y28: 349190 | Z28: 328333 | AA28: 339087 | AB28: 330645 | AC28: 348042 | AD28: 360342 | AE28: 374380 | AF28: 385519 | AG28: 396317
B29: Other Southeast Asia | C29: 70560 | D29: 85248 | E29: 95766 | F29: 98715 | G29: 93653 | H29: 88624 | I29: 89160 | J29: =AVERAGE(AD29:AG29) -> 93036.25 | L29: 85215 | M29: 102239 | N29: 97468 | O29: =E29 -> 95766 | P29: 97600 | Q29: 98166 | R29: 101076 | S29: =F29 -> 98715 | T29: 88779 | U29: 91316 | V29: 99326 | W29: 95058 | X29: 90056 | Y29: 88675 | Z29: 88933 | AA29: 86850 | AB29: 100429 | AC29: 82192 | AD29: 86703 | AE29: 87487 | AF29: 97587 | AG29: 100368
B30: Rest of the World | C30: 6110 | D30: 19323 | E30: 55993 | F30: 74053 | G30: 61604 | H30: 65965 | I30: 67255 | J30: =AVERAGE(AD30:AG30) -> 71892 | L30: 23420 | M30: 68068 | N30: 64549 | O30: =E30 -> 55993 | P30: 65344 | Q30: 77207 | R30: 75191 | S30: =F30 -> 74053 | T30: 57617 | U30: 57566 | V30: 66740 | W30: 64363 | X30: 62771 | Y30: 68844 | Z30: 57812 | AA30: 74428 | AB30: 53144 | AC30: 74538 | AD30: 63452 | AE30: 77656 | AF30: 70263 | AG30: 76197
B31: Total | C31: =SUM(C28:C30) -> 350651 | D31: =SUM(D28:D30) -> 354052 | E31: =SUM(E28:E30) -> 416141 | F31: =SUM(F28:F30) -> 468130 | G31: =SUM(G28:G30) -> 462007 | H31: =SUM(H28:H30) -> 488794 | I31: =SUM(I28:I30) -> 509906 | J31: =SUM(J28:J30) -> 544067.75 | L31: =SUM(L28:L30) -> 382877 | M31: =SUM(M28:M30) -> 443126 | N31: =SUM(N28:N30) -> 417167 | O31: =SUM(O28:O30) -> 416141 | P31: =SUM(P28:P30) -> 427368 | Q31: =SUM(Q28:Q30) -> 465459 | R31: =SUM(R28:R30) -> 478323 | S31: =SUM(S28:S30) -> 468130 | ... AG31: =SUM(AG28:AG30) -> 572882
B33: By geographical region (% Share)
B34: Thailand | C34: =C28/C$31 -> 0.78134955 | D34: =D28/D$31 -> 0.70464508 | E34: =E28/E$31 -> 0.63531832 | F34: =F28/F$31 -> 0.63094012 | G34: =G28/G$31 -> 0.66395098 | H34: =H28/H$31 -> 0.68373384 | I34: =I28/I$31 -> 0.69324738 | J34: =J28/J$31 -> 0.69686082 | L34: =L28/L$31 -> 0.71626658 | M34: =M28/M$31 -> 0.61566913 | N34: =N28/N$31 -> 0.61162556 | O34: =O28/O$31 -> 0.63531832 | P34: =P28/P$31 -> 0.61872672 | Q34: =Q28/Q$31 -> 0.62322568 | R34: =R28/R$31 -> 0.6314896 | S34: =S28/S$31 -> 0.63094012 | ... AG34: =AG28/AG$31 -> 0.69179517
B35: Other Southeast Asia | C35: =C29/C$31 -> 0.20122572 | D35: =D29/D$31 -> 0.24077819 | E35: =E29/E$31 -> 0.23012873 | F35: =F29/F$31 -> 0.21087091 | G35: =G29/G$31 -> 0.20270905 | H35: =H29/H$31 -> 0.18131155 | I35: =I29/I$31 -> 0.17485576 | J35: =J29/J$31 -> 0.17100122 | L35: =L29/L$31 -> 0.22256495 | M35: =M29/M$31 -> 0.23072219 | N35: =N29/N$31 -> 0.23364264 | O35: =O29/O$31 -> 0.23012873 | P35: =P29/P$31 -> 0.22837461 | Q35: =Q29/Q$31 -> 0.2109015 | R35: =R29/R$31 -> 0.21131328 | S35: =S29/S$31 -> 0.21087091 | ... AG35: =AG29/AG$31 -> 0.17519838
B36: Rest of the World | C36: =C30/C$31 -> 0.017424733 | D36: =D30/D$31 -> 0.054576729 | E36: =E30/E$31 -> 0.13455295 | F36: =F30/F$31 -> 0.15818896 | G36: =G30/G$31 -> 0.13333997 | H36: =H30/H$31 -> 0.1349546 | I36: =I30/I$31 -> 0.13189686 | J36: =J30/J$31 -> 0.13213796 | L36: =L30/L$31 -> 0.061168469 | M36: =M30/M$31 -> 0.15360868 | N36: =N30/N$31 -> 0.1547318 | O36: =O30/O$31 -> 0.13455295 | P36: =P30/P$31 -> 0.15289867 | Q36: =Q30/Q$31 -> 0.16587283 | R36: =R30/R$31 -> 0.15719712 | S36: =S30/S$31 -> 0.15818896 | ... AG36: =AG30/AG$31 -> 0.13300645
B37: Total | C37: =SUM(C34:C36) -> 1 | D37: =SUM(D34:D36) -> 1 | E37: =SUM(E34:E36) -> 1 | F37: =SUM(F34:F36) -> 1 | G37: =SUM(G34:G36) -> 1 | H37: =SUM(H34:H36) -> 1 | I37: =SUM(I34:I36) -> 1 | J37: =SUM(J34:J36) -> 1 | L37: =SUM(L34:L36) -> 1 | M37: =SUM(M34:M36) -> 1 | N37: =SUM(N34:N36) -> 1 | O37: =SUM(O34:O36) -> 1 | P37: =SUM(P34:P36) -> 1 | Q37: =SUM(Q34:Q36) -> 1 | R37: =SUM(R34:R36) -> 1 | S37: =SUM(S34:S36) -> 1 | ... AG37: =SUM(AG34:AG36) -> 1
B39: By geographical region (YoY % Growth)
B40: Thailand | D40: =D28/C28-1 -> -0.089422259 | E40: =E28/D28-1 -> 0.059727995 | F40: =F28/E28-1 -> 0.11717893 | G40: =G28/F28-1 -> 0.038556077 | H40: =H28/G28-1 -> 0.089502852 | I40: =I28/H28-1 -> 0.057707096 | P40: =P28/L28-1 -> -0.035800497 | Q40: =Q28/M28-1 -> 0.063291046 | R40: =R28/N28-1 -> 0.18383696 | S40: =S28/O28-1 -> 0.11717893 | T40: =T28/P28-1 -> 0.1890789 | U40: =U28/Q28-1 -> 0.020338796 | V40: =V28/R28-1 -> -0.0022181317 | W40: =W28/S28-1 -> 0.067361407 | ... AG40: =AG28/AC28-1 -> 0.13870452
B41: Other Southeast Asia | D41: =D29/C29-1 -> 0.20816327 | E41: =E29/D29-1 -> 0.12338119 | F41: =F29/E29-1 -> 0.03079381 | G41: =G29/F29-1 -> -0.051278934 | H41: =H29/G29-1 -> -0.053698226 | I41: =I29/H29-1 -> 0.0060480231 | P41: =P29/L29-1 -> 0.14533826 | Q41: =Q29/M29-1 -> -0.039838027 | R41: =R29/N29-1 -> 0.037017277 | S41: =S29/O29-1 -> 0.03079381 | T41: =T29/P29-1 -> -0.090379098 | U41: =U29/Q29-1 -> -0.069779761 | V41: =V29/R29-1 -> -0.017313705 | W41: =W29/S29-1 -> -0.037046042 | ... AG41: =AG29/AC29-1 -> 0.22114074
B42: Rest of the World | D42: =D30/C30-1 -> 2.1625205 | E42: =E30/D30-1 -> 1.8977384 | F42: =F30/E30-1 -> 0.32254032 | G42: =G30/F30-1 -> -0.16810933 | H42: =H30/G30-1 -> 0.070790858 | I42: =I30/H30-1 -> 0.019555825 | P42: =P30/L30-1 -> 1.7900939 | Q42: =Q30/M30-1 -> 0.1342628 | R42: =R30/N30-1 -> 0.164867 | S42: =S30/O30-1 -> 0.32254032 | T42: =T30/P30-1 -> -0.1182511 | U42: =U30/Q30-1 -> -0.25439403 | V42: =V30/R30-1 -> -0.11239377 | W42: =W30/S30-1 -> -0.13085223 | ... AG42: =AG30/AC30-1 -> 0.022257104
B43: Total | D43: =D31/C31-1 -> 0.0096991025 | E43: =E31/D31-1 -> 0.1753669 | F43: =F31/E31-1 -> 0.12493121 | G43: =G31/F31-1 -> -0.0130797 | H43: =H31/G31-1 -> 0.057979641 | I43: =I31/H31-1 -> 0.04319202 | P43: =P31/L31-1 -> 0.11620181 | Q43: =Q31/M31-1 -> 0.050398758 | R43: =R31/N31-1 -> 0.14659836 | S43: =S31/O31-1 -> 0.12493121 | T43: =T31/P31-1 -> 0.078267442 | U43: =U31/Q31-1 -> -0.044238053 | V43: =V31/R31-1 -> -0.02272732 | W43: =W31/S31-1 -> 0.013989704 | ... AG43: =AG31/AC31-1 -> 0.13493221
B46: Product price table
B47: Gas ($/MMBTU) | C47: 6.27 | D47: 6.27 | E47: 5.69 | F47: 6.27 | G47: 6 | H47: 5.87 | I47: 5.81 | J47: =AVERAGE(AD47:AG47) -> 5.8275 | L47: 5.61 | M47: 5.59 | N47: 5.76 | O47: 5.81 | P47: 6.07 | Q47: 6.1 | R47: 6.18 | S47: 6.27 | T47: 6.52 | U47: 5.87 | V47: 5.75 | W47: 5.86 | X47: 5.9 | Y47: 5.8 | Z47: 5.93 | AA47: 5.86 | AB47: 5.95 | AC47: 5.79 | AD47: 5.8 | AE47: 5.74 | AF47: 5.81 | AG47: 5.96
B48: Liquid ($/BBL) | C48: 41.55 | D48: 41.55 | E48: 66.7 | F48: 94.89 | G48: 79.09 | H48: 77.2 | I48: 67.13 | J48: =AVERAGE(AD48:AG48) -> 251.6975 | L48: 56.59 | M48: 63.98 | N48: 69.16 | O48: 76.17 | P48: 91.19 | Q48: 105.47 | R48: 97.94 | S48: 94.89 | T48: 78.14 | U48: 73.66 | V48: 81.89 | W48: 81.95 | X48: 79.36 | Y48: 81.15 | Z48: 76.91 | AA48: 71.98 | AB48: 73.37 | AC48: 66.32 | AD48: 67.03 | AE48: 762.78 | AF48: 77.47 | AG48: 99.51
B49: Weighted Avg. ($/BOE) | C49: 38.92 | D49: 38.92 | E49: 43.49 | F49: 53.39 | G49: 48.21 | H49: 46.78 | I49: 43.82 | J49: =AG49 -> 52.89 | L49: 40.38 | M49: 42.19 | N49: 44.25 | O49: 46.87 | P49: 51.35 | Q49: 55.61 | R49: 53.68 | S49: 46.87 | T49: 50.01 | U49: 55.61 | V49: 53.68 | W49: 48.41 | X49: 47.24 | Y49: 55.61 | Z49: 53.68 | AA49: 45.83 | AB49: 45.74 | AC49: 44.01 | AD49: 43.17 | AE49: 42.55 | AF49: 46.02 | AG49: 52.89
B50: Avg. Dubai ($/BBL) | C50: 42.27 | D50: 42.27 | E50: 69.39 | F50: 96.38 | G50: 82.09 | H50: 79.58 | I50: 69.36 | J50: =AVERAGE(AD50:AG50) -> 79.4175 | L50: 60.01 | M50: 67.02 | N50: 71.68 | O50: 78.27 | P50: 96.21 | Q50: 108.22 | R50: 96.68 | S50: 96.38 | T50: 80.23 | U50: 77.59 | V50: 86.63 | W50: 83.75 | X50: 81.22 | Y50: 85.34 | Z50: 78.43 | AA50: 73.62 | AB50: 76.94 | AC50: 66.95 | AD50: 70.11 | AE50: 63.82 | AF50: 87.87 | AG50: 95.87
...
