Workbook
Name \A: #REF!
Name \B: #REF!
Name \C: #REF!
Name \L: #REF!
Name \M: #REF!
Name \P: #REF!
Name \Y: #REF!
Name _01_30_04: MonthlyOpStats
Name _01_30_04: MonthlyOpStats
Name _1_30_01: MonthlyOpStats
Name _1_30_01: MonthlyOpStats
Name _1_30_02: MonthlyOpStats
Name _1_30_02: MonthlyOpStats
Name _1_31_01: MonthlyOpStats
Name _1_31_01: MonthlyOpStats
Name _1_31_02: MonthlyOpStats
Name _1_31_02: MonthlyOpStats
Name _12_31_05: MonthlyOpStats
Name _12_31_05: MonthlyOpStats
Name _A: #REF!
Name _A___0: #REF!
Name _B: #REF!
Name _B___0: #REF!
Name _C: #REF!
Name _C___0: #REF!
Name _ent1: [1]Inputs!$J$17
Name _ent10: [1]Inputs!$J$476
Name _ent11: [1]Inputs!$J$527
Name _ent12: [1]Inputs!$J$578
Name _ent13: [1]Inputs!$J$629
Name _ent14: [1]Inputs!$J$680
Name _ent15: [1]Inputs!$J$731
Name _ent2: [1]Inputs!$J$68
Name _ent3: [1]Inputs!$J$119
Name _ent4: [1]Inputs!$J$170
Name _ent5: [1]Inputs!$J$221
Name _ent6: [1]Inputs!$J$272
Name _ent7: [1]Inputs!$J$323
Name _ent8: [1]Inputs!$J$374
Name _ent9: [1]Inputs!$J$425
Name _eps1: [1]Inputs!$P$42
Name _eps10: [1]Inputs!$P$501
Name _eps11: [1]Inputs!$P$552
Name _eps12: [1]Inputs!$P$603
Name _eps13: [1]Inputs!$P$654
Name _eps14: [1]Inputs!$P$705
Name _eps15: [1]Inputs!$P$756
Name _eps2: [1]Inputs!$P$93
Name _eps3: [1]Inputs!$P$144
Name _eps4: [1]Inputs!$P$195
Name _eps5: [1]Inputs!$P$246
Name _eps6: [1]Inputs!$P$297
Name _eps7: [1]Inputs!$P$348
Name _eps8: [1]Inputs!$P$399
Name _eps9: [1]Inputs!$P$450
Name _fye1: [1]Inputs!$E$12
Name _fye10: [1]Inputs!$E$471
Name _fye11: [1]Inputs!$E$522
Name _fye12: [1]Inputs!$E$573
Name _fye13: [1]Inputs!$E$624

Sheet Capitalisation
A3: 1Q26 | I3: Exchange rate as at end | J3: =Model!$I$203 -> 0.0010795988
I4: LTM Average exchange rate | J4: =Model!$I$204 -> 0.0010682761
B6: Debt Breakdown as on 31-Mar-2026 | C6: CLP millions | D6: Leverage | E6: USD mn | F6: Leverage | I6: Company Reported | J6: CLP millions
I7: Total Financial Debt | J7: 1247190
B8: Included in non-current liabilities | C8: =SUM(C9:C10) -> 1046265.7 | E8: =SUM(E9:E10) -> 1129.5472 | I8: Net Financial Debt | J8: 635620
B9: Bank borrowings | C9: 40280.382 | E9: =C9*J3 -> 43.486653 | I9: Net Financial Debt / EBITDA | J9: 1.69x
B10: Bonds payable | C10: 1005985.3 | E10: =C10*J3 -> 1086.0605
B12: Included in current liabilities | C12: =SUM(C13:C14) -> 120403.68 | E12: =SUM(E13:E14) -> 129.98767
B13: Bank borrowings | C13: 85852.526 | E13: =C13*J3 -> 92.686286
B14: Bonds payable | C14: 34551.156 | E14: =C14*J3 -> 37.301387
B16: Lease Obligations | C16: =SUM(C17:C18) -> 56851.904 | E16: =SUM(E17:E18) -> 61.377249
B17: Short-term | C17: =Model!$AE$111 -> 11649.606 | E17: =C17*J3 -> 12.576901
B18: Long-term | C18: =Model!$AE$112 -> 45202.298 | E18: =C18*J3 -> 48.800348
B20: Total Loans & Borrowings | C20: =C12+C8+C16 -> 1223521.2 | D20: =C20/C25 -> 3.2514735 | E20: =E12+E8+E16 -> 1320.9121 | F20: =E20/E25 -> 3.285936
B21: Cash and Cash Equivalents | C21: =Model!AE$119 -> 611569.36 | E21: =C21*J3 -> 660.24957
B22: Net debt | C22: =C20-C21 -> 611951.88 | D22: =C22/C25 -> 1.626245 | E22: =E20-E21 -> 660.66253 | F22: =E22/E25 -> 1.6434817
B23: Equity | C23: =Model!AE$123 -> 1739768.3 | E23: =C23*J3 -> 1878.2518
B24: Total Capitalisation | C24: =C22+C23 -> 2351720.2 | E24: =E22+E23 -> 2538.9144
B25: LTM Adjusted EBITDA | C25: =Model!AE$86 -> 376297.47 | E25: =C25*J4 -> 401.9896
B26: check | C26: =+C20-Model!AE$118 -> 0
B29: Liquidity at 1Q26 | C29: CLP millions | D29: USD mn
B30: Cash and Cash Equivalents | C30: =C21 -> 611569.36 | D30: =C30*J3 -> 660.24957
B31: Total liquidity | C31: =SUM(C30:C30) -> 611569.36 | D31: =SUM(D30:D30) -> 660.24957
B34: Debt Maturity | C34: CLP millions | D34: USD mn
B35: 1 year | C35: =C13+C14 -> 120403.68 | D35: =C35*$J3 -> 129.98767
B36: >1-3 years | C36: =33144.521+14984.664 -> 48129.185 | D36: =C36*$J3 -> 51.960211
B37: >3-5 years | C37: =3687.815+80599.741 -> 84287.556 | D37: =C37*$J3 -> 90.996746
B38: More than 5 years | C38: =3448.046+910400.872 -> 913848.92 | D38: =C38*$J3 -> 986.59021
B39: Total | C39: =SUM(C35:C38) -> 1166669.3 | D39: =SUM(D35:D38) -> 1259.5348
B40: check | C40: =C39-C8-C12 -> 0
B43: Bank Borrowings
B44: Company | C44: Creditor name | D44: Interest rate | E44: CLP millions | F44: USD mn
B45: Current:
B46: Viña San Pedro Tarapacá S.A | C46: Banco Itaú | D46: 0.0143 | E46: 59736.308 | F46: =E46*$J3 -> 64.491248
B47: Cervecería Kunstmann S.A. | C47: Banco Itaú | D47: 0.0546 | E47: 2020.93 | F47: =E47*$J3 -> 2.1817936
B48: Cervecería Kunstmann S.A. | C48: Banco del Estado de Chile | D48: 0.062 | E48: 2035.133 | F48: =E48*$J3 -> 2.1971272
B49: Cervecería Kunstmann S.A. | C49: Banco del Estado de Chile | D49: 0.0627 | E49: 1017.765 | F49: =E49*$J3 -> 1.0987779
B50: Cervecería Kunstmann S.A. | C50: Banco del Estado de Chile | D50: 0.06074 | E50: 43.836 | F50: =E50*$J3 -> 0.047325294
B51: Cervecería Kunstmann S.A. | C51: Banco Itaú | D51: 0.0614 | E51: 3005.961 | F51: =E51*$J3 -> 3.245232
B52: Cervecería Kunstmann S.A. | C52: Banco del Estado de Chile | D52: 0.0633 | E52: 98.021 | F52: =E52*$J3 -> 0.10582336
...

Sheet Model
B2: Compañía Cervecerías Unidas S.A. | C2: Annual | D2: Annual | E2: Annual | F2: Annual | G2: Annual | H2: Annual | I2: LTM | K2: Quarters | L2: Quarters | M2: Quarters | N2: Quarters | O2: Quarters | P2: Quarters | Q2: Quarters | R2: Quarters | S2: Quarters | T2: Quarters | U2: Quarters | V2: Quarters | W2: Quarters | X2: Quarters | Y2: Quarters | Z2: Quarters | AA2: Quarters | AB2: Quarters | AC2: Quarters | AD2: Quarters | AE2: Quarters
B3: (CLP millions) | C3: 44196 | D3: 44561 | E3: 44926 | F3: 45291 | G3: 45657 | H3: 46022 | I3: =AE3 -> 46112 | K3: 44286 | L3: 44377 | M3: 44469 | N3: 44561 | O3: 44651 | P3: 44742 | Q3: 44834 | R3: 44926 | S3: 45016 | T3: 45107 | U3: 45199 | V3: 45291 | W3: 45382 | X3: 45473 | Y3: 45565 | Z3: 45657 | AA3: 45747 | AB3: 45838 | AC3: 45930 | AD3: 46022 | AE3: 46112
C4: Act | D4: Act | E4: Act | F4: Act | G4: Act | H4: Act | I4: Act | K4: Act | L4: Act | M4: Act | N4: Act | O4: Act | P4: Act | Q4: Act | R4: Act | S4: Act | T4: Act | U4: Act | V4: Act | W4: Act | X4: Act | Y4: Act | Z4: Act | AA4: Act | AB4: Act | AC4: Act | AD4: Act | AE4: Act
C5: FY | D5: FY | E5: FY | F5: FY | G5: FY | H5: FY | I5: LTM | K5: 1Q | L5: 2Q | M5: 3Q | N5: 4Q | O5: 1Q | P5: 2Q | Q5: 3Q | R5: 4Q | S5: 1Q | T5: 2Q | U5: 3Q | V5: 4Q | W5: 1Q | X5: 2Q | Y5: 3Q | Z5: 4Q | AA5: 1Q | AB5: 2Q | AC5: 3Q | AD5: 4Q | AE5: 1Q
B6: INCOME STATEMENT
B7: Revenue | C7: 1857593.7 | D7: 2484712.3 | E7: 2711434.9 | F7: 2565556.1 | G7: 2904566.5 | H7: 2909625.4 | I7: =AE7+AB7+AC7+AD7 -> 2911470.1 | K7: 569639.46 | L7: 469994.59 | M7: 622729.63 | N7: =D7-SUM(K7:M7) -> 822348.61 | O7: 700464.93 | P7: 558502.88 | Q7: 684105.54 | R7: =E7-SUM(O7:Q7) -> 768361.6 | S7: 732030.76 | T7: 574241.7 | U7: 686676.91 | V7: =F7-SUM(S7:U7) -> 572606.7 | W7: =746023.982 -> 746023.98 | X7: 524641.48 | Y7: 665823.27 | Z7: =G7-SUM(W7:Y7) -> 968077.72 | AA7: 817670.59 | AB7: 579913.9 | AC7: 658627.85 | AD7: =H7-SUM(AA7:AC7) -> 853413.1 | AE7: 819515.28
B8: % of growth | D8: =(D7/C7)-1 -> 0.3375973 | E8: =(E7/D7)-1 -> 0.091247051 | F8: =(F7/E7)-1 -> -0.053801358 | G8: =(G7/F7)-1 -> 0.13213915 | H8: =(H7/G7)-1 -> 0.0017417381 | O8: =(O7/K7)-1 -> 0.22966365 | P8: =(P7/L7)-1 -> 0.1883177 | Q8: =(Q7/M7)-1 -> 0.09855948 | R8: =(R7/N7)-1 -> -0.065649788 | S8: =(S7/O7)-1 -> 0.04506411 | T8: =(T7/P7)-1 -> 0.028180372 | U8: =(U7/Q7)-1 -> 0.0037587344 | V8: =(V7/R7)-1 -> -0.25476924 | ... AE8: =(AE7/AA7)-1 -> 0.0022560283
B9: Cost of sales | C9: -984035.92 | D9: -1291559.8 | E9: -1514925.3 | F9: -1378612 | G9: -1590957.8 | H9: -1618034.2 | I9: =AE9+AB9+AC9+AD9 -> -1614537.9 | K9: -280270.89 | L9: -249566.84 | M9: -330148.4 | N9: =D9-SUM(K9:M9) -> -431573.67 | O9: -376740.25 | P9: -333194.47 | Q9: -391714.49 | R9: =E9-SUM(O9:Q9) -> -413276.09 | S9: -377085.58 | T9: -324826.38 | U9: -368362.24 | V9: =F9-SUM(S9:U9) -> -308337.77 | W9: =-(393897.326) -> -393897.33 | X9: -314528.12 | Y9: -377538.5 | Z9: =G9-SUM(W9:Y9) -> -504993.83 | AA9: -435489.18 | AB9: -343082.28 | AC9: -378691.84 | AD9: =H9-SUM(AA9:AC9) -> -460770.92 | AE9: -431992.86
B10: Gross Profit | C10: =C7+C9 -> 873557.76 | D10: =D7+D9 -> 1193152.5 | E10: =E7+E9 -> 1196509.6 | F10: =F7+F9 -> 1186944.1 | G10: =G7+G9 -> 1313608.7 | H10: =H7+H9 -> 1291591.2 | I10: =I7+I9 -> 1296932.2 | K10: =K7+K9 -> 289368.56 | L10: =L7+L9 -> 220427.75 | M10: =M7+M9 -> 292581.23 | N10: =N7+N9 -> 390774.94 | O10: =O7+O9 -> 323724.68 | P10: =P7+P9 -> 225308.41 | Q10: =Q7+Q9 -> 292391.04 | R10: =R7+R9 -> 355085.51 | ... AE10: =AE7+AE9 -> 387522.42
B11: Gross Profit margin | C11: =C10/C7 -> 0.4702631 | D11: =D10/D7 -> 0.48019744 | E11: =E10/E7 -> 0.44128281 | F11: =F10/F7 -> 0.46264594 | G11: =G10/G7 -> 0.45225637 | H11: =H10/H7 -> 0.44390292 | I11: =I10/I7 -> 0.44545614 | K11: =K10/K7 -> 0.50798546 | L11: =L10/L7 -> 0.46900061 | M11: =M10/M7 -> 0.4698367 | N11: =N10/N7 -> 0.47519378 | O11: =O10/O7 -> 0.46215687 | P11: =P10/P7 -> 0.40341494 | Q11: =Q10/Q7 -> 0.42740634 | R11: =R10/R7 -> 0.46213334 | ... AE11: =AE10/AE7 -> 0.47286784
B12: Operating expenses:
B13: Other income | C13: 19295.892 | D13: 11808.439 | E13: 5284.666 | F13: 4419.789 | G13: 40211.51 | H13: 11829.734 | I13: =AE13+AB13+AC13+AD13 -> 9378.399 | K13: 4561.577 | L13: 567.084 | M13: 4108.153 | N13: =D13-SUM(K13:M13) -> 2571.625 | O13: 814.593 | P13: 1114.213 | Q13: 1548.689 | R13: =E13-SUM(O13:Q13) -> 1807.171 | S13: 801.632 | T13: 847.974 | U13: 1159.522 | V13: =F13-SUM(S13:U13) -> 1610.661 | W13: =1064.779 -> 1064.779 | X13: 32676.846 | Y13: 1268.001 | Z13: =G13-SUM(W13:Y13) -> 5201.884 | AA13: 4875.644 | AB13: 1387.728 | AC13: 1115.279 | AD13: =H13-SUM(AA13:AC13) -> 4451.083 | AE13: 2424.309
B14: Distribution costs | C14: -337101.55 | D14: -438601.94 | E14: -504184.25 | F14: -470120.81 | G14: -536420.14 | H14: -547393.15 | I14: =AE14+AB14+AC14+AD14 -> -550250.65 | K14: -95679.199 | L14: -85926.112 | M14: -111353.57 | N14: =D14-SUM(K14:M14) -> -145643.06 | O14: -122682.67 | P14: -108715.38 | Q14: -132334.85 | R14: =E14-SUM(O14:Q14) -> -140451.36 | S14: -138549.18 | T14: -116809.79 | U14: -122158.33 | V14: =F14-SUM(S14:U14) -> -92603.519 | W14: =(-134752.73) -> -134752.73 | X14: -112936.63 | Y14: -126083.58 | Z14: =G14-SUM(W14:Y14) -> -162647.2 | AA14: -148691.25 | AB14: -121478.43 | AC14: -124892.65 | AD14: =H14-SUM(AA14:AC14) -> -152330.83 | AE14: -151548.75
B15: Administrative expenses | C15: -138811.67 | D15: -161390.78 | E15: -187421.8 | F15: -197256.57 | G15: -214915.09 | H15: -205911.74 | I15: =AE15+AB15+AC15+AD15 -> -211725.68 | K15: -32461.71 | L15: -34744.59 | M15: -41787.512 | N15: =D15-SUM(K15:M15) -> -52396.967 | O15: -35449.088 | P15: -45691.984 | Q15: -54960.501 | R15: =E15-SUM(O15:Q15) -> -51320.223 | S15: -32358.416 | T15: -52476.442 | U15: -62630.221 | V15: =F15-SUM(S15:U15) -> -49791.492 | W15: =-(42611.167) -> -42611.167 | X15: -56689.94 | Y15: -57729.046 | Z15: =G15-SUM(W15:Y15) -> -57884.936 | AA15: -52433.131 | AB15: -54706.522 | AC15: -44928.956 | AD15: =H15-SUM(AA15:AC15) -> -53843.13 | AE15: -58247.067
B16: Other expenses by function | C16: -230349.57 | D16: -284087.36 | E16: -278757.1 | F16: -270703.33 | G16: -339783.07 | H16: -329266.8 | I16: =AE16+AB16+AC16+AD16 -> -323585.04 | K16: -66040.26 | L16: -65654.567 | M16: -72084.366 | N16: =D16-SUM(K16:M16) -> -80308.165 | O16: -60512.679 | P16: -73686.271 | Q16: -73113.137 | R16: =E16-SUM(O16:Q16) -> -71445.018 | S16: -80616.94 | T16: -68025.521 | U16: -83614.081 | V16: =F16-SUM(S16:U16) -> -38446.792 | W16: =(-86913.343) -> -86913.343 | X16: -70719.768 | Y16: -72111.628 | Z16: =G16-SUM(W16:Y16) -> -110038.33 | AA16: -94049.42 | AB16: -79374.07 | AC16: -74837.454 | AD16: =H16-SUM(AA16:AC16) -> -81005.853 | AE16: -88367.661
B17: Other gains (losses) | C17: -11410.085 | D17: 9590.45 | E17: -12669.54 | F17: -13316.208 | G17: -94.937 | H17: -27672.922 | I17: =AE17+AB17+AC17+AD17 -> -14296.718 | K17: -1040.928 | L17: 1738.588 | M17: 7304.058 | N17: =D17-SUM(K17:M17) -> 1588.732 | O17: -8991.582 | P17: 13516.855 | Q17: 1328.953 | R17: =E17-SUM(O17:Q17) -> -18523.766 | S17: -7452.796 | T17: -2873.551 | U17: 5063.367 | V17: =F17-SUM(S17:U17) -> -8053.228 | W17: =1064.348 -> 1064.348 | X17: -5256.413 | Y17: -4311.792 | Z17: =G17-SUM(W17:Y17) -> 8408.92 | AA17: -7444.459 | AB17: -9465.32 | AC17: 4187.269 | AD17: =H17-SUM(AA17:AC17) -> -14950.412 | AE17: 5931.745
B18: Operating profit | C18: =C10+SUM(C13:C17) -> 175180.78 | D18: =D10+SUM(D13:D17) -> 330471.3 | E18: =E10+SUM(E13:E17) -> 218761.62 | F18: =F10+SUM(F13:F17) -> 239966.97 | G18: =G10+SUM(G13:G17) -> 262606.95 | H18: =H10+SUM(H13:H17) -> 193176.34 | I18: =I10+SUM(I13:I17) -> 206452.55 | K18: 94146.466 | L18: 35841.066 | M18: 74659.845 | N18: =N10+SUM(N14:N17) -> 114015.48 | O18: =O10+SUM(O14:O17) -> 96088.659 | P18: =P10+SUM(P14:P17) -> 10731.635 | Q18: =Q10+SUM(Q14:Q17) -> 33311.509 | R18: =R10+SUM(R14:R17) -> 73345.147 | S18: =S10+SUM(S14:S17) -> 95967.851 | T18: =T10+SUM(T14:T17) -> 9230.02 | U18: =U10+SUM(U13:U17) -> 56134.93 | V18: =V10+SUM(V13:V17) -> 76984.56 | W18: =W10+SUM(W13:W17) -> 89978.543 | X18: =X10+SUM(X13:X17) -> -2812.544 | Y18: =Y10+SUM(Y13:Y17) -> 29316.724 | Z18: =Z10+SUM(Z13:Z17) -> 146124.23 | AA18: =AA10+SUM(AA13:AA17) -> 84438.794 | AB18: =AB10+SUM(AB13:AB17) -> -26804.989 | ... AE18: =AE10+SUM(AE13:AE17) -> 97715
B19: Finance income | C19: 3451.143 | D19: 14263.669 | E19: 22870.538 | F19: 39402.492 | G19: 38102.053 | H19: 27522.243 | I19: =AE19+AB19+AC19+AD19 -> 23045.073 | K19: 3352.77 | L19: 3464.805 | M19: 2689.372 | N19: =D19-SUM(K19:M19) -> 4756.722 | O19: 6348.294 | P19: 6505.17 | Q19: 4680.264 | R19: =E19-SUM(O19:Q19) -> 5336.81 | S19: 10393.133 | T19: 13458.819 | U19: 10560.575 | V19: =F19-SUM(S19:U19) -> 4989.965 | W19: =12703.221 -> 12703.221 | X19: 9103.863 | Y19: 7834.17 | Z19: =G19-SUM(W19:Y19) -> 8460.799 | AA19: 9495.959 | AB19: 7982.055 | AC19: 5392.814 | AD19: =H19-SUM(AA19:AC19) -> 4651.415 | AE19: 5018.789
B20: Finance exps | C20: -28714.063 | D20: -35660.493 | E20: -75930.875 | F20: -77023.048 | G20: -97165.278 | H20: -79947.714 | I20: =AE20+AB20+AC20+AD20 -> -77524.639 | K20: -7168.197 | L20: -6941.675 | M20: -8903.459 | N20: =D20-SUM(K20:M20) -> -12647.162 | O20: -12718.817 | P20: -17018.053 | Q20: -23375.161 | R20: =E20-SUM(O20:Q20) -> -22818.844 | S20: -20451.345 | T20: -19000.454 | U20: -21375.537 | V20: =F20-SUM(S20:U20) -> -16195.712 | W20: =-19368.518 -> -19368.518 | X20: -21389.854 | Y20: -27687.403 | Z20: =G20-SUM(W20:Y20) -> -28719.503 | AA20: -20752.884 | AB20: -18154.517 | AC20: -20330.452 | AD20: =H20-SUM(AA20:AC20) -> -20709.861 | AE20: -18329.809
B21: Share of profit of equity-accounted investees | C21: -8437.209 | D21: 226.026 | E21: -10978.068 | F21: -19217.758 | G21: -9494.703 | H21: -14352.591 | I21: =AE21+AB21+AC21+AD21 -> -15194.615 | K21: -596.475 | L21: -1752.132 | M21: -1013.287 | N21: =D21-SUM(K21:M21) -> 3587.92 | O21: -564.64 | P21: -3837.066 | Q21: -3495.437 | R21: =E21-SUM(O21:Q21) -> -3080.925 | S21: -3818.77 | T21: -6179.91 | U21: -11709.227 | V21: =F21-SUM(S21:U21) -> 2490.149 | W21: =(-3317.839) -> -3317.839 | X21: -2577.643 | Y21: -530.841 | Z21: =G21-SUM(W21:Y21) -> -3068.38 | AA21: -1517.971 | AB21: -6064.957 | AC21: -5357.183 | AD21: =H21-SUM(AA21:AC21) -> -1412.48 | AE21: -2359.995
B22: Gains (losses) on exchange differences | C22: 2551.823 | D22: -10149.345 | E22: -20173.381 | F22: -65944.57 | G22: -17797.269 | H22: 1473.55 | I22: =AE22+AB22+AC22+AD22 -> 7.988 | K22: -1387.312 | L22: -1378.951 | M22: -4483.454 | N22: =D22-SUM(K22:M22) -> -2899.628 | O22: 1594.225 | P22: -11430.455 | Q22: -8095.775 | R22: =E22-SUM(O22:Q22) -> -2241.376 | S22: -4327.369 | T22: -7117.365 | U22: -24484.632 | V22: =F22-SUM(S22:U22) -> -30015.204 | W22: =(-8467.435) -> -8467.435 | X22: 1.628 | Y22: 4573.011 | Z22: =G22-SUM(W22:Y22) -> -13904.473 | AA22: -444.237 | AB22: 1916.962 | AC22: -9350.023 | AD22: =H22-SUM(AA22:AC22) -> 9350.848 | AE22: -1909.799
B23: Result as per adjustment units | C23: -429.198 | D23: 2529.298 | E23: 1198.565 | F23: -14025.895 | G23: -10722.033 | H23: -17631.014 | I23: =AE23+AB23+AC23+AD23 -> -14480.093 | K23: 67.942 | L23: 729.558 | M23: 551.589 | N23: =D23-SUM(K23:M23) -> 1180.209 | O23: -3591.675 | P23: -1480.671 | Q23: 4641.027 | R23: =E23-SUM(O23:Q23) -> 1629.884 | S23: -1656.078 | T23: -3533.385 | U23: -692.545 | V23: =F23-SUM(S23:U23) -> -8143.887 | W23: =(-1879.441) -> -1879.441 | X23: -3395.306 | Y23: 54.079 | Z23: =G23-SUM(W23:Y23) -> -5501.365 | AA23: -6017.421 | AB23: -6474.768 | AC23: -2553.246 | AD23: =H23-SUM(AA23:AC23) -> -2585.579 | AE23: -2866.5
B24: Other expenses | C24: 0 | D24: 0 | E24: 0 | F24: 0 | G24: 0 | H24: 0 | I24: =AE24+AB24+AC24+AD24 -> 0 | K24: 0 | L24: 0 | M24: 0 | N24: =D24-SUM(K24:M24) -> 0 | O24: 0 | P24: 0 | Q24: 0 | R24: =E24-SUM(O24:Q24) -> 0 | U24: 0 | V24: =F24-SUM(S24:U24) -> 0 | W24: 0 | Y24: 0 | Z24: =G24-SUM(W24:Y24) -> 0 | AA24: 0 | AB24: 0 | AC24: 0 | AD24: =H24-SUM(AA24:AC24) -> 0 | AE24: 0
B25: Profit before tax | C25: =C18+SUM(C19:C24) -> 143603.28 | D25: =D18+SUM(D19:D24) -> 301680.45 | E25: =E18+SUM(E19:E24) -> 135748.39 | F25: =F18+SUM(F19:F24) -> 103158.19 | G25: =G18+SUM(G19:G24) -> 165529.72 | H25: =H18+SUM(H19:H24) -> 110240.82 | I25: =I18+SUM(I19:I24) -> 122306.26 | K25: 92976.771 | L25: 30529.755 | M25: 67608.759 | N25: =N18+SUM(N19:N24) -> 107993.54 | O25: =O18+SUM(O19:O24) -> 87156.046 | P25: =P18+SUM(P19:P24) -> -16529.44 | Q25: =Q18+SUM(Q19:Q24) -> 7666.427 | R25: =R18+SUM(R19:R24) -> 52170.696 | S25: =S18+SUM(S19:S24) -> 76107.422 | T25: =T18+SUM(T19:T24) -> -13142.275 | U25: =U18+SUM(U19:U24) -> 8433.564 | ... AE25: =AE18+SUM(AE19:AE24) -> 77267.686
B26: Income tax (expense)/benefit | C26: -35408.42 | D26: -82629.773 | E26: -263.943 | F26: 15267.255 | G26: 11015.074 | H26: 27051.867 | I26: =AE26+AB26+AC26+AD26 -> 12546.153 | K26: -23531.533 | L26: -7973.321 | M26: -20856.945 | N26: =D26-SUM(K26:M26) -> -30267.974 | O26: -17564.609 | P26: 8020.38 | Q26: 10185.069 | R26: =E26-SUM(O26:Q26) -> -904.783 | S26: -15347.635 | T26: 8695.389 | U26: 4226.575 | V26: =F26-SUM(S26:U26) -> 17692.926 | W26: =(-14620.924) -> -14620.924 | X26: 27900.465 | Y26: 18994.161 | Z26: =G26-SUM(W26:Y26) -> -21258.628 | AA26: -3714.274 | AB26: 36387.682 | AC26: 12304.256 | AD26: =H26-SUM(AA26:AC26) -> -17925.797 | AE26: -18219.988
B27: Net profit/loss | C27: =+C25+C26 -> 108194.86 | D27: =+D25+D26 -> 219050.68 | E27: =+E25+E26 -> 135484.45 | F27: =+F25+F26 -> 118425.44 | G27: =+G25+G26 -> 176544.8 | H27: =+H25+H26 -> 137292.68 | I27: =+I25+I26 -> 134852.42 | K27: 69445.238 | L27: 22556.434 | M27: 46751.814 | N27: =+N25+N26 -> 77725.57 | O27: =+O25+O26 -> 69591.437 | P27: =+P25+P26 -> -8509.06 | Q27: =+Q25+Q26 -> 17851.496 | R27: =+R25+R26 -> 51265.913 | S27: =+S25+S26 -> 60759.787 | T27: =+T25+T26 -> -4446.886 | U27: =+U25+U26 -> 12660.139 | ... AE27: =+AE25+AE26 -> 59047.698
B28: % margin | C28: =+C27/C7 -> 0.05824463 | D28: =+D27/D7 -> 0.088159375 | E28: =+E27/E7 -> 0.049967805 | F28: =+F27/F7 -> 0.046159756 | G28: =+G27/G7 -> 0.060781807 | H28: =+H27/H7 -> 0.04718569 | I28: =+I27/I7 -> 0.046317637 | K28: 0.12191086 | L28: 0.047992966 | M28: 0.075075622 | N28: =+N27/N7 -> 0.09451657 | O28: =+O27/O7 -> 0.099350351 | P28: =+P27/P7 -> -0.015235481 | Q28: =+Q27/Q7 -> 0.026094652 | R28: =+R27/R7 -> 0.066721076 | S28: =+S27/S7 -> 0.083001686 | T28: =+T27/T7 -> -0.0077439273 | U28: =+U27/U7 -> 0.018436821 | ... AE28: =+AE27/AE7 -> 0.072051979
B29: Non-controlling interest | C29: -12042.584 | D29: -19887.95 | E29: -17316.101 | F29: -12772.715 | G29: -15600.659 | H29: -20140.477 | I29: =AE29+AB29+AC29+AD29 -> -21621.842 | K29: -5061.367 | L29: -3588.571 | M29: -4583.744 | N29: =D29-SUM(K29:M29) -> -6654.268 | O29: -5861.566 | P29: -3060.295 | Q29: -2174.103 | R29: =E29-SUM(O29:Q29) -> -6220.137 | S29: -3193.432 | T29: -344.586 | U29: -3161.322 | V29: =F29-SUM(S29:U29) -> -6073.375 | W29: =-2824.874 -> -2824.874 | X29: -1790.357 | Y29: 3005.456 | Z29: =G29-SUM(W29:Y29) -> -13990.884 | AA29: -3710.358 | AB29: -5.49 | AC29: -5189.17 | AD29: =H29-SUM(AA29:AC29) -> -11235.459 | AE29: -5191.723
B30: Net profit/loss | C30: =+C27+C29 -> 96152.272 | D30: =+D27+D29 -> 199162.73 | E30: =+E27+E29 -> 118168.35 | F30: =+F27+F29 -> 105652.73 | G30: =+G27+G29 -> 160944.14 | H30: =+H27+H29 -> 117152.21 | I30: =+I27+I29 -> 113230.57 | K30: 64383.871 | L30: 18967.863 | M30: 42168.07 | N30: =+N27+N29 -> 71071.302 | O30: =+O27+O29 -> 63729.871 | P30: =+P27+P29 -> -11569.355 | Q30: =+Q27+Q29 -> 15677.393 | R30: =+R27+R29 -> 45045.776 | S30: =+S27+S29 -> 57566.355 | T30: =+T27+T29 -> -4791.472 | U30: =+U27+U29 -> 9498.817 | ... AE30: =+AE27+AE29 -> 53855.975
B32: % of sales or stated otherwise
B33: =B14 -> Distribution costs | C33: =-C14/C7 -> 0.18147217 | D33: =-D14/D7 -> 0.17652021 | E33: =-E14/E7 -> 0.18594739 | F33: =-F14/F7 -> 0.18324324 | G33: =-G14/G7 -> 0.18468166 | H33: =-H14/H7 -> 0.18813183 | I33: =-I14/I7 -> 0.18899409 | K33: =-K14/K7 -> 0.16796449 | L33: =-L14/L7 -> 0.18282362 | M33: =-M14/M7 -> 0.17881527 | N33: =-N14/N7 -> 0.17710623 | O33: =-O14/O7 -> 0.17514463 | P33: =-P14/P7 -> 0.19465499 | Q33: =-Q14/Q7 -> 0.19344215 | R33: =-R14/R7 -> 0.18279331 | ... AE33: =-AE14/AE7 -> 0.18492486
B34: =B15 -> Administrative expenses | C34: =-C15/C7 -> 0.074726604 | D34: =-D15/D7 -> 0.064953508 | E34: =-E15/E7 -> 0.069122734 | F34: =-F15/F7 -> 0.076886478 | G34: =-G15/G7 -> 0.07399214 | H34: =-H15/H7 -> 0.070769157 | I34: =-I15/I7 -> 0.072721225 | K34: =-K15/K7 -> 0.056986414 | L34: =-L15/L7 -> 0.073925511 | M34: =-M15/M7 -> 0.06710378 | N34: =-N15/N7 -> 0.063716247 | O34: =-O15/O7 -> 0.050607941 | P34: =-P15/P7 -> 0.081811545 | Q34: =-Q15/Q7 -> 0.080339214 | R34: =-R15/R7 -> 0.066791759 | ... AE34: =-AE15/AE7 -> 0.071075023
B35: =B16 -> Other expenses by function | C35: =-C16/C7 -> 0.12400428 | D35: =-D16/D7 -> 0.11433411 | E35: =-E16/E7 -> 0.10280796 | F35: =-F16/F7 -> 0.10551449 | G35: =-G16/G7 -> 0.11698237 | H35: =-H16/H7 -> 0.11316467 | I35: =-I16/I7 -> 0.11114146 | K35: =-K16/K7 -> 0.11593344 | L35: =-L16/L7 -> 0.13969218 | M35: =-M16/M7 -> 0.11575548 | N35: =-N16/N7 -> 0.097657081 | O35: =-O16/O7 -> 0.086389306 | P35: =-P16/P7 -> 0.13193535 | Q35: =-Q16/Q7 -> 0.10687406 | R35: =-R16/R7 -> 0.092983588 | ... AE35: =-AE16/AE7 -> 0.10782918
B36: Finance exps as % of debt | C36: =-C20/C108 -> 0.062650334 | D36: =-D20/D108 -> 0.066223149 | E36: =-E20/E108 -> 0.056999551 | F36: =-F20/F108 -> 0.059797792 | G36: =-G20/G108 -> 0.071165523 | H36: =-H20/H108 -> 0.066730309 | I36: =-I20/I108 -> 0.066449538 | N36: =-SUM(K20:N20)/N108 -> 0.066223149 | O36: =-SUM(L20:O20)/O108 -> 0.040440843 | P36: =-SUM(M20:P20)/P108 -> 0.042637557 | Q36: =-SUM(N20:Q20)/Q108 -> 0.050224194 | R36: =-SUM(O20:R20)/R108 -> 0.056999551 | S36: =-SUM(P20:S20)/S108 -> 0.066731718 | T36: =-SUM(Q20:T20)/T108 -> 0.066015632 | U36: =-SUM(R20:U20)/U108 -> 0.063494599 | ... AE36: =-SUM(AB20:AE20)/AE108 -> 0.066449538
B37: Finance income as % of cash and cash equivalents | C37: =C19/C119 -> 0.0087064547 | D37: =D19/D119 -> 0.053710019 | E37: =E19/E119 -> 0.038303869 | F37: =F19/F119 -> 0.063742192 | G37: =G19/G119 -> 0.053883218 | H37: =H19/H119 -> 0.0530114 | I37: =I19/I119 -> 0.037681863 | N37: =SUM(K19:N19)/N119 -> 0.053710019 | O37: =SUM(L19:O19)/O119 -> 0.023257784 | P37: =SUM(M19:P19)/P119 -> 0.031521093 | Q37: =SUM(N19:Q19)/Q119 -> 0.035076323 | R37: =SUM(O19:R19)/R119 -> 0.038303869 | S37: =SUM(P19:S19)/S119 -> 0.047029408 | T37: =SUM(Q19:T19)/T119 -> 0.057306499 | U37: =SUM(R19:U19)/U119 -> 0.063444044 | ... AE37: =SUM(AB19:AE19)/AE119 -> 0.037681863
B38: Tax % of PBT | C38: =-C26/C25 -> 0.24657112 | D38: =-D26/D25 -> 0.27389833 | E38: =-E26/E25 -> 0.0019443545 | F38: =-F26/F25 -> -0.14799848 | G38: =-G26/G25 -> -0.066544387 | H38: =-H26/H25 -> -0.24538885 | I38: =-I26/I25 -> -0.10257981 | K38: =-K26/K25 -> 0.25309045 | L38: =-L26/L25 -> 0.26116557 | M38: =-M26/M25 -> 0.30849472 | N38: =-N26/N25 -> 0.28027577 | O38: =-O26/O25 -> 0.20153059 | P38: =-P26/P25 -> 0.48521789 | Q38: =-Q26/Q25 -> -1.3285288 | R38: =-R26/R25 -> 0.017342744 | ... AE38: =-AE26/AE25 -> 0.23580346
B40: Working capital /sales | C40: =C60/C7 -> 0.46370505 | D40: =D60/D7 -> 0.43894697 | E40: =E60/E7 -> 0.31097275 | F40: =F60/F7 -> 0.41309329 | G40: =G60/G7 -> 0.39827044 | H40: =H60/H7 -> 0.4032648 | I40: =I60/I7 -> 0.41410095 | K40: =K60/K7 -> 0.5909214 | L40: =L60/L7 -> 0.44365836 | M40: =M60/M7 -> 0.38111731 | N40: =N60/N7 -> 0.37477381 | O40: =O60/O7 -> 0.44609453 | P40: =P60/P7 -> 0.23257376 | Q40: =Q60/Q7 -> 0.25032778 | R40: =R60/R7 -> 0.29877219 | ... AE40: =AE60/AE7 -> 0.55988574
B41: Capex/sales | C41: =-C64/C7 -> 0.062780923 | D41: =-D64/D7 -> 0.068225266 | E41: =-E64/E7 -> 0.068261659 | F41: =-F64/F7 -> 0.048008726 | G41: =-G64/G7 -> 0.034596397 | H41: =-H64/H7 -> 0.047924791 | I41: =-I64/I7 -> 0.052186982 | K41: =-K64/K7 -> 0.049412573 | L41: =-L64/L7 -> 0.086456551 | M41: =-M64/M7 -> 0.057544596 | N41: =-N64/N7 -> 0.078925126 | O41: =-O64/O7 -> 0.038880676 | P41: =-P64/P7 -> 0.084083471 | Q41: =-Q64/Q7 -> 0.082327388 | R41: =-R64/R7 -> 0.071022571 | ... AE41: =-AE64/AE7 -> 0.046654361
B43: EBITDA | C43: =C3 -> 44196 | D43: =D3 -> 44561 | E43: =E3 -> 44926 | F43: =F3 -> 45291 | G43: =G3 -> 45657 | H43: =H3 -> 46022 | I43: =I3 -> 46112 | K43: =K3 -> 44286 | L43: =L3 -> 44377 | M43: =M3 -> 44469 | N43: =N3 -> 44561 | O43: =O3 -> 44651 | P43: =P3 -> 44742 | Q43: =Q3 -> 44834 | R43: =R3 -> 44926 | ... AE43: =AE3 -> 46112
B44: Operating profit | C44: =C18 -> 175180.78 | D44: =D18 -> 330471.3 | E44: =E18 -> 218761.62 | F44: =F18 -> 239966.97 | G44: =G18 -> 262606.95 | H44: =H18 -> 193176.34 | I44: =I18 -> 206452.55 | K44: =K18 -> 94146.466 | L44: =L18 -> 35841.066 | M44: =M18 -> 74659.845 | N44: =N18 -> 114015.48 | O44: =O18 -> 96088.659 | P44: =P18 -> 10731.635 | Q44: =Q18 -> 33311.509 | R44: =R18 -> 73345.147 | ... AE44: =AE18 -> 97715
...

Sheet Adjusted EBITDA
B2: Compañía Cervecerías Unidas S.A. | C2: Annual | D2: Annual | E2: Annual | F2: Annual | G2: LTM | I2: Annual | J2: Annual | K2: Annual | L2: Annual | M2: Annual | N2: Annual | O2: Annual | P2: Annual | Q2: Annual
B3: (CLP millions) | C3: 44926 | D3: 45291 | E3: 45657 | F3: 46022 | G3: =Q3 -> 46112 | I3: 45382 | J3: 45473 | K3: 45565 | L3: 45657 | M3: 45747 | N3: 45838 | O3: 45565 | P3: 46022 | Q3: 46112
C4: Act | D4: Act | E4: Act | F4: Act | G4: Act | I4: Act | J4: Act | K4: Act | L4: Act | M4: Act | N4: Act | O4: Act | P4: Act | Q4: Act
C5: FY | D5: FY | E5: FY | F5: FY | G5: LTM | I5: 1Q | J5: 2Q | K5: 3Q | L5: 4Q | M5: 1Q | N5: 2Q | O5: 3Q | P5: 4Q | Q5: 1Q
B7: Profit (loss) for the year | C7: =Model!E27 -> 135484.45 | D7: =Model!F27 -> 118425.44 | E7: =Model!G27 -> 176544.8 | F7: =Model!H27 -> 137292.68 | G7: =Model!I27 -> 134852.42 | I7: =Model!W27 -> 55027.607 | J7: =Model!X27 -> 6830.609 | K7: =Model!Y27 -> 32553.901 | L7: =Model!Z27 -> 82132.68 | M7: =Model!AA27 -> 61487.966 | N7: =Model!AB27 -> -11212.532 | O7: =Model!AC27 -> 20685.663 | P7: =Model!AD27 -> 66331.587 | Q7: =Model!AE27 -> 59047.698
B8: Other gains (losses) | C8: =-Model!E17 -> 12669.54 | D8: =-Model!F17 -> 13316.208 | E8: =-Model!G17 -> 94.937 | F8: =-Model!H17 -> 27672.922 | G8: =-Model!I17 -> 14296.718 | I8: =-Model!W17 -> -1064.348 | J8: =-Model!X17 -> 5256.413 | K8: =-Model!Y17 -> 4311.792 | L8: =-Model!Z17 -> -8408.92 | M8: =-Model!AA17 -> 7444.459 | N8: =-Model!AB17 -> 9465.32 | O8: =-Model!AC17 -> -4187.269 | P8: =-Model!AD17 -> 14950.412 | Q8: =-Model!AE17 -> -5931.745
B9: Financial income | C9: =-Model!E19 -> -22870.538 | D9: =-Model!F19 -> -39402.492 | E9: =-Model!G19 -> -38102.053 | F9: =-Model!H19 -> -27522.243 | G9: =-Model!I19 -> -23045.073 | I9: =-Model!W19 -> -12703.221 | J9: =-Model!X19 -> -9103.863 | K9: =-Model!Y19 -> -7834.17 | L9: =-Model!Z19 -> -8460.799 | M9: =-Model!AA19 -> -9495.959 | N9: =-Model!AB19 -> -7982.055 | O9: =-Model!AC19 -> -5392.814 | P9: =-Model!AD19 -> -4651.415 | Q9: =-Model!AE19 -> -5018.789
B10: Financial costs | C10: =-Model!E20 -> 75930.875 | D10: =-Model!F20 -> 77023.048 | E10: =-Model!G20 -> 97165.278 | F10: =-Model!H20 -> 79947.714 | G10: =-Model!I20 -> 77524.639 | I10: =-Model!W20 -> 19368.518 | J10: =-Model!X20 -> 21389.854 | K10: =-Model!Y20 -> 27687.403 | L10: =-Model!Z20 -> 28719.503 | M10: =-Model!AA20 -> 20752.884 | N10: =-Model!AB20 -> 18154.517 | O10: =-Model!AC20 -> 20330.452 | P10: =-Model!AD20 -> 20709.861 | Q10: =-Model!AE20 -> 18329.809
B11: Share in profit (loss) of associates and joint ventures accounted for using the equity method | C11: =-Model!E21 -> 10978.068 | D11: =-Model!F21 -> 19217.758 | E11: =-Model!G21 -> 9494.703 | F11: =-Model!H21 -> 14352.591 | G11: =-Model!I21 -> 15194.615 | I11: =-Model!W21 -> 3317.839 | J11: =-Model!X21 -> 2577.643 | K11: =-Model!Y21 -> 530.841 | L11: =-Model!Z21 -> 3068.38 | M11: =-Model!AA21 -> 1517.971 | N11: =-Model!AB21 -> 6064.957 | O11: =-Model!AC21 -> 5357.183 | P11: =-Model!AD21 -> 1412.48 | Q11: =-Model!AE21 -> 2359.995
B12: Foreign currency exchange gains (losses) | C12: =-Model!E22 -> 20173.381 | D12: =-Model!F22 -> 65944.57 | E12: =-Model!G22 -> 17797.269 | F12: =-Model!H22 -> -1473.55 | G12: =-Model!I22 -> -7.988 | I12: =-Model!W22 -> 8467.435 | J12: =-Model!X22 -> -1.628 | K12: =-Model!Y22 -> -4573.011 | L12: =-Model!Z22 -> 13904.473 | M12: =-Model!AA22 -> 444.237 | N12: =-Model!AB22 -> -1916.962 | O12: =-Model!AC22 -> 9350.023 | P12: =-Model!AD22 -> -9350.848 | Q12: =-Model!AE22 -> 1909.799
B13: Result by adjustment units | C13: =-Model!E23 -> -1198.565 | D13: =-Model!F23 -> 14025.895 | E13: =-Model!G23 -> 10722.033 | F13: =-Model!H23 -> 17631.014 | G13: =-Model!I23 -> 14480.093 | I13: =-Model!W23 -> 1879.441 | J13: =-Model!X23 -> 3395.306 | K13: =-Model!Y23 -> -54.079 | L13: =-Model!Z23 -> 5501.365 | M13: =-Model!AA23 -> 6017.421 | N13: =-Model!AB23 -> 6474.768 | O13: =-Model!AC23 -> 2553.246 | P13: =-Model!AD23 -> 2585.579 | Q13: =-Model!AE23 -> 2866.5
B14: Income taxes | C14: =-Model!E26 -> 263.943 | D14: =-Model!F26 -> -15267.255 | E14: =-Model!G26 -> -11015.074 | F14: =-Model!H26 -> -27051.867 | G14: =-Model!I26 -> -12546.153 | I14: =-Model!W26 -> 14620.924 | J14: =-Model!X26 -> -27900.465 | K14: =-Model!Y26 -> -18994.161 | L14: =-Model!Z26 -> 21258.628 | M14: =-Model!AA26 -> 3714.274 | N14: =-Model!AB26 -> -36387.682 | O14: =-Model!AC26 -> -12304.256 | P14: =-Model!AD26 -> 17925.797 | Q14: =-Model!AE26 -> 18219.988
B15: Adjusted operating result | C15: =SUM(C7:C14) -> 231431.16 | D15: =SUM(D7:D14) -> 253283.17 | E15: =SUM(E7:E14) -> 262701.89 | F15: =SUM(F7:F14) -> 220849.26 | G15: =SUM(G7:G14) -> 220749.27 | I15: =SUM(I7:I14) -> 88914.195 | J15: =SUM(J7:J14) -> 2443.869 | K15: =SUM(K7:K14) -> 33628.516 | L15: =SUM(L7:L14) -> 137715.31 | M15: =SUM(M7:M14) -> 91883.253 | N15: =SUM(N7:N14) -> -17339.669 | O15: =SUM(O7:O14) -> 36392.228 | P15: =SUM(P7:P14) -> 109913.45 | Q15: =SUM(Q7:Q14) -> 91783.255
B16: Depreciation and amortization | C16: =Model!E45 -> 126497.49 | D16: =Model!F45 -> 126119.2 | E16: =Model!G45 -> 153234.22 | F16: =Model!H45 -> 155358.69 | G16: =Model!I45 -> 155548.16 | I16: =Model!W45 -> 35249.053 | J16: =Model!X45 -> 36277.691 | K16: =Model!Y45 -> 36802.182 | L16: =Model!Z45 -> 44905.298 | M16: =Model!AA45 -> 39670.795 | N16: =Model!AB45 -> 37156.952 | O16: =Model!AC45 -> 37243.232 | P16: =Model!AD45 -> 41287.714 | Q16: =Model!AE45 -> 39860.26
B17: ROADA | C17: =SUM(C15:C16) -> 357928.65 | D17: =SUM(D15:D16) -> 379402.37 | E17: =SUM(E15:E16) -> 415936.11 | F17: =SUM(F15:F16) -> 376207.96 | G17: =SUM(G15:G16) -> 376297.42 | I17: =SUM(I15:I16) -> 124163.25 | J17: =SUM(J15:J16) -> 38721.56 | K17: =SUM(K15:K16) -> 70430.698 | L17: =SUM(L15:L16) -> 182620.61 | M17: =SUM(M15:M16) -> 131554.05 | N17: =SUM(N15:N16) -> 19817.283 | O17: =SUM(O15:O16) -> 73635.46 | P17: =SUM(P15:P16) -> 151201.17 | Q17: =SUM(Q15:Q16) -> 131643.51
B18: check | C18: =C17-Model!E51 -> 0 | D18: =D17-Model!F51 -> 0 | E18: =E17-Model!G51 -> 0 | F18: =F17-Model!H51 -> 0 | G18: =G17-Model!I51 -> -0.048 | I18: =I17-Model!W51 -> 0 | J18: =J17-Model!X51 -> -0.44 | K18: =K17-Model!Y51 -> 0 | L18: =L17-Model!Z51 -> 0.44 | M18: =M17-Model!AA51 -> 0.048 | N18: =N17-Model!AB51 -> -6.184564e-11 | O18: =O17-Model!AC51 -> 0.46 | P18: =P17-Model!AD51 -> -0.508 | Q18: =Q17-Model!AE51 -> 0

Sheet KPIs
B2: Compañía Cervecerías Unidas S.A. | C2: Annual | D2: Annual | E2: Annual | F2: Annual | G2: Annual | H2: Annual | I2: LTM | K2: Quarters | L2: Quarters | M2: Quarters | N2: Quarters | O2: Quarters | P2: Quarters | Q2: Quarters | R2: Quarters | S2: Quarters | T2: Quarters | U2: Quarters | V2: Quarters | W2: Quarters | X2: Quarters | Y2: Quarters | Z2: Quarters | AA2: Quarters | AB2: Quarters | AC2: Quarters | AD2: Quarters | AE2: Quarters
B3: (CLP millions) | C3: 44196 | D3: 44561 | E3: 44926 | F3: 45291 | G3: 45657 | H3: 46022 | I3: =AE3 -> 46112 | K3: 44286 | L3: 44377 | M3: 44469 | N3: 44561 | O3: 44651 | P3: 44742 | Q3: 44834 | R3: 44926 | S3: 45016 | T3: 45107 | U3: 45199 | V3: 45291 | W3: 45382 | X3: 45473 | Y3: 45565 | Z3: 45657 | AA3: 45747 | AB3: 45838 | AC3: 45930 | AD3: 46022 | AE3: 46112
C4: Act | D4: Act | E4: Act | F4: Act | G4: Act | H4: Act | I4: Act | K4: Act | L4: Act | M4: Act | N4: Act | O4: Act | P4: Act | Q4: Act | R4: Act | S4: Act | T4: Act | U4: Act | V4: Act | W4: Act | X4: Act | Y4: Act | Z4: Act | AA4: Act | AB4: Act | AC4: Act | AD4: Act | AE4: Act
C5: FY | D5: FY | E5: FY | F5: FY | G5: FY | H5: FY | I5: LTM | K5: 1Q | L5: 2Q | M5: 3Q | N5: 4Q | O5: 1Q | P5: 2Q | Q5: 3Q | R5: 4Q | S5: 1Q | T5: 2Q | U5: 3Q | V5: 4Q | W5: 1Q | X5: 2Q | Y5: 3Q | Z5: 4Q | AA5: 1Q | AB5: 2Q | AC5: 3Q | AD5: 4Q | AE5: 1Q
B7: Volume by segment
B8: Chile | C8: 20483.028 | D8: 23897.316 | E8: 23387.927 | F8: 22781.417 | G8: 22707 | H8: 22966 | I8: =SUM(AB8:AE8) -> 23216 | K8: 6249.0652 | L8: 4752.3672 | M8: 5549.36 | N8: =D8-SUM(K8:M8) -> 7346.5238 | O8: 6729.0794 | P8: 4601.0906 | Q8: 5285.4316 | R8: =E8-SUM(O8:Q8) -> 6772.3255 | S8: 6645.1367 | T8: 4817.7771 | U8: 5038.5182 | V8: =F8-SUM(S8:U8) -> 6279.9847 | W8: 6587.9264 | X8: 4414 | Y8: 5127 | Z8: =G8-SUM(W8:Y8) -> 6578.0736 | AA8: 6463 | AB8: 4557 | AC8: 5096 | AD8: =H8-SUM(AA8:AC8) -> 6850 | AE8: 6713
B9: Interntional Business | C9: 8783.4653 | D9: 9424.2216 | E9: 9526.5548 | F9: 9095.3138 | G9: 9780 | H9: 12029 | I9: =SUM(AB9:AE9) -> 11973 | K9: 2461.7703 | L9: 1629.1315 | M9: 2316.5858 | N9: =D9-SUM(K9:M9) -> 3016.734 | O9: 2655.7975 | P9: 1601.8377 | Q9: 2285.9536 | R9: =E9-SUM(O9:Q9) -> 2982.966 | S9: 2440.6785 | T9: 1731.8667 | U9: 2187.2273 | V9: =F9-SUM(S9:U9) -> 2735.5412 | W9: 2081.5159 | X9: 1260 | Y9: 2517 | Z9: =G9-SUM(W9:Y9) -> 3921.4841 | AA9: 3382 | AB9: 2256 | AC9: 2650 | AD9: =H9-SUM(AA9:AC9) -> 3741 | AE9: 3326
B10: Wine | C10: 1532.9779 | D10: 1582.6787 | E10: 1573.3503 | F10: 1346.983 | G10: 1361 | H10: 1321 | I10: =SUM(AB10:AE10) -> 1304 | K10: 352.69224 | L10: 413.31011 | M10: 434.23146 | N10: =D10-SUM(K10:M10) -> 382.44485 | O10: 352.18244 | P10: 411.0761 | Q10: 436.74294 | R10: =E10-SUM(O10:Q10) -> 373.3488 | S10: 289.40475 | T10: 355.8627 | U10: 361.32585 | V10: =F10-SUM(S10:U10) -> 340.38974 | W10: 297.18898 | X10: 356 | Y10: 368 | Z10: =G10-SUM(W10:Y10) -> 339.81102 | AA10: 286 | AB10: 371 | AC10: 357 | AD10: =H10-SUM(AA10:AC10) -> 307 | AE10: 269
B11: Other/Eliminations | C11: -112.53026 | D11: -206.09447 | E11: -166.99954 | F11: -86.682108 | G11: -75 | H11: -67 | I11: =SUM(AB11:AE11) -> -61 | K11: -21.548217 | L11: -36.083045 | M11: -87.352718 | N11: =D11-SUM(K11:M11) -> -61.110496 | O11: -44.790978 | P11: -46.532536 | Q11: -44.379951 | R11: =E11-SUM(O11:Q11) -> -31.296077 | S11: -12.933892 | T11: -22.557995 | U11: -27.751202 | V11: =F11-SUM(S11:U11) -> -23.439017 | W11: -14.875382 | X11: -21 | Y11: =Y12-SUM(Y8:Y10) -> -21 | Z11: =G11-SUM(W11:Y11) -> -18.124618 | AA11: -18 | AB11: -18 | AC11: -17 | AD11: =H11-SUM(AA11:AC11) -> -14 | AE11: -12
B12: Total | C12: =SUM(C8:C11) -> 30686.941 | D12: =SUM(D8:D11) -> 34698.122 | E12: =SUM(E8:E11) -> 34320.833 | F12: =SUM(F8:F11) -> 33137.031 | G12: =SUM(G8:G11) -> 33773 | H12: =SUM(H8:H11) -> 36249 | I12: =SUM(I8:I11) -> 36432 | K12: =SUM(K8:K11) -> 9041.9795 | L12: =SUM(L8:L11) -> 6758.7258 | M12: =SUM(M8:M11) -> 8212.8245 | N12: =SUM(N8:N11) -> 10684.592 | O12: =SUM(O8:O11) -> 9692.2683 | P12: =SUM(P8:P11) -> 6567.4719 | Q12: =SUM(Q8:Q11) -> 7963.7482 | R12: =SUM(R8:R11) -> 10097.344 | ... X12: =SUM(X8:X11) -> 6009 | Y12: 7991 | Z12: =SUM(Z8:Z11) -> 10821.244 | AA12: =SUM(AA8:AA11) -> 10113 | AB12: =SUM(AB8:AB11) -> 7166 | AC12: =SUM(AC8:AC11) -> 8086 | AD12: =SUM(AD8:AD11) -> 10884 | AE12: =SUM(AE8:AE11) -> 10296
B15: Revenue by segment
B16: Chile | C16: 1242762.9 | D16: 1578151.9 | E16: 1673349.4 | F16: 1758971.2 | G16: 1829243.7 | H16: 1914527.6 | I16: =SUM(AB16:AE16) -> 1934647.8 | K16: 393220.48 | L16: 316435.84 | M16: 378830.11 | N16: =D16-SUM(K16:M16) -> 489665.48 | O16: 458484.32 | P16: 328283.18 | Q16: 379318.88 | R16: =E16-SUM(O16:Q16) -> 507262.97 | S16: 487817.87 | T16: 376377.67 | U16: 398549.51 | V16: =F16-SUM(S16:U16) -> 496226.19 | W16: 501876.69 | X16: 355612.75 | Y16: 426414.32 | Z16: =G16-SUM(W16:Y16) -> 545339.9 | AA16: 515794.59 | AB16: 389247 | AC16: 434113.76 | AD16: =H16-SUM(AA16:AC16) -> 575372.27 | AE16: 535914.74
B17: Interntional Business | C17: 402828.83 | D17: 677906.8 | E17: 782563.35 | F17: 586484.36 | G17: 850118.28 | H17: 780295.79 | I17: =SUM(AB17:AE17) -> 763245.66 | K17: 124661.8 | L17: 95899.854 | M17: 185198.93 | N17: =D17-SUM(K17:M17) -> 272146.2 | O17: 188548.22 | P17: 163888.84 | Q17: 232995.39 | R17: =E17-SUM(O17:Q17) -> 197130.91 | S17: 197386.87 | T17: 142511.78 | U17: 227378.59 | V17: =F17-SUM(S17:U17) -> 19207.123 | W17: 194253.75 | X17: 111001.54 | Y17: 177834.13 | Z17: =G17-SUM(W17:Y17) -> 367028.85 | AA17: 256029.91 | AB17: 128328 | AC17: 161979.26 | AD17: =H17-SUM(AA17:AC17) -> 233958.61 | AE17: 238979.79
B18: Wine | C18: 235210.37 | D18: 261620.06 | E18: 296349.89 | F18: 252825.5 | G18: 282637.92 | H18: 276488.98 | I18: =SUM(AB18:AE18) -> 272184.61 | K18: 56402.916 | L18: 64781.743 | M18: 70846.894 | N18: =D18-SUM(K18:M18) -> 69588.512 | O18: 64005.599 | P18: 75617.508 | Q18: 84892.705 | R18: =E18-SUM(O18:Q18) -> 71834.081 | S18: 52646.744 | T18: 64369.292 | U18: 72379.599 | V18: =F18-SUM(S18:U18) -> 63429.861 | W18: 58765.21 | X18: 72124.558 | Y18: 74774.164 | Z18: =G18-SUM(W18:Y18) -> 76973.991 | AA18: 60021.512 | AB18: 76444 | AC18: 75990.644 | AD18: =H18-SUM(AA18:AC18) -> 64032.826 | AE18: 55717.137
B19: Other/Eliminations | C19: -23208.385 | D19: -32966.495 | E19: -40827.654 | F19: -32725.024 | G19: -57433.404 | H19: -61686.943 | I19: =SUM(AB19:AE19) -> -58607.907 | K19: -4645.7401 | L19: -7122.854 | M19: -12146.316 | N19: =D19-SUM(K19:M19) -> -9051.5842 | O19: -10573.213 | P19: -9286.6365 | Q19: -13101.438 | R19: =E19-SUM(O19:Q19) -> -7866.3664 | S19: -5820.7235 | T19: -9017.0366 | U19: -11630.788 | V19: =F19-SUM(S19:U19) -> -6256.4757 | W19: -8871.6675 | X19: -14097.371 | Y19: -13199.343 | Z19: =G19-SUM(W19:Y19) -> -21265.023 | AA19: -14175.427 | AB19: -14104 | AC19: -13455.815 | AD19: =H19-SUM(AA19:AC19) -> -19951.701 | AE19: -11096.391
B20: Total | C20: =SUM(C16:C19) -> 1857593.7 | D20: =SUM(D16:D19) -> 2484712.3 | E20: =SUM(E16:E19) -> 2711434.9 | F20: =SUM(F16:F19) -> 2565556.1 | G20: =SUM(G16:G19) -> 2904566.5 | H20: =SUM(H16:H19) -> 2909625.4 | I20: =SUM(I16:I19) -> 2911470.1 | K20: =SUM(K16:K19) -> 569639.46 | L20: =SUM(L16:L19) -> 469994.59 | M20: =SUM(M16:M19) -> 622729.63 | N20: =SUM(N16:N19) -> 822348.61 | O20: =SUM(O16:O19) -> 700464.93 | P20: =SUM(P16:P19) -> 558502.88 | Q20: =SUM(Q16:Q19) -> 684105.54 | R20: =SUM(R16:R19) -> 768361.6 | ... AE20: =SUM(AE16:AE19) -> 819515.28
B21: Check | C21: =C20-Model!C7 -> -7.2000083e-05 | D21: =D20-Model!D7 -> 7.8819226e-05 | E21: =E20-Model!E7 -> 0.00025487412 | F21: =F20-Model!F7 -> 0.00038081966 | G21: =G20-Model!G7 -> 0 | H21: =H20-Model!H7 -> 0 | I21: =I20-Model!I7 -> 0 | K21: =K20-Model!K7 -> -2.0000036e-05 | L21: =L20-Model!L7 -> -0.00065585802 | M21: =M20-Model!M7 -> -0.00016058912 | N21: =N20-Model!N7 -> 0.00091526622 | O21: =O20-Model!O7 -> 0.00017039687 | P21: =P20-Model!P7 -> 0.00058699504 | Q21: =Q20-Model!Q7 -> 0.00027804589 | R21: =R20-Model!R7 -> -0.00078056392 | ... AE21: =AE20-Model!AE7 -> 0
B24: Revenue by segment (% Share)
B25: Chile | C25: =C16/C$20 -> 0.6690176 | D25: =D16/D$20 -> 0.63514473 | E25: =E16/E$20 -> 0.61714531 | F25: =F16/F$20 -> 0.68561013 | G25: =G16/G$20 -> 0.629782 | H25: =H16/H$20 -> 0.65799797 | I25: =I16/I$20 -> 0.66449171 | K25: =K16/K$20 -> 0.69029712 | L25: =L16/L$20 -> 0.6732755 | M25: =M16/M$20 -> 0.60833803 | N25: =N16/N$20 -> 0.59544757 | O25: =O16/O$20 -> 0.65454287 | P25: =P16/P$20 -> 0.58779137 | Q25: =Q16/Q$20 -> 0.55447422 | R25: =R16/R$20 -> 0.66018783 | ... AE25: =AE16/AE$20 -> 0.65394113
B26: Interntional Business | C26: =C17/C$20 -> 0.21685519 | D26: =D17/D$20 -> 0.2728311 | E26: =E17/E$20 -> 0.28861594 | F26: =F17/F$20 -> 0.22859932 | G26: =G17/G$20 -> 0.29268336 | H26: =H17/H$20 -> 0.2681774 | I26: =I17/I$20 -> 0.26215129 | K26: =K17/K$20 -> 0.21884334 | L26: =L17/L$20 -> 0.20404459 | M26: =M17/M$20 -> 0.29739862 | N26: =N17/N$20 -> 0.33093776 | O26: =O17/O$20 -> 0.26917582 | P26: =P17/P$20 -> 0.29344314 | Q26: =Q17/Q$20 -> 0.34058398 | R26: =R17/R$20 -> 0.25656007 | ... AE26: =AE17/AE$20 -> 0.29161114
B27: Wine | C27: =C18/C$20 -> 0.126621 | D27: =D18/D$20 -> 0.1052919 | E27: =E18/E$20 -> 0.10929633 | F27: =F18/F$20 -> 0.098546081 | G27: =G18/G$20 -> 0.097308128 | H27: =H18/H$20 -> 0.095025627 | I27: =I18/I$20 -> 0.093486999 | K27: =K18/K$20 -> 0.099015114 | L27: =L18/L$20 -> 0.13783508 | M27: =M18/M$20 -> 0.11376831 | N27: =N18/N$20 -> 0.084621669 | O27: =O18/O$20 -> 0.09137588 | P27: =P18/P$20 -> 0.13539323 | Q27: =Q18/Q$20 -> 0.124093 | R27: =R18/R$20 -> 0.093489942 | ... AE27: =AE18/AE$20 -> 0.067987917
B28: Other/Eliminations | C28: =C19/C$20 -> -0.01249379 | D28: =D19/D$20 -> -0.013267731 | E28: =E19/E$20 -> -0.015057582 | F28: =F19/F$20 -> -0.012755529 | G28: =G19/G$20 -> -0.019773486 | H28: =H19/H$20 -> -0.021200991 | I28: =I19/I$20 -> -0.020130005 | K28: =K19/K$20 -> -0.00815558 | L28: =L19/L$20 -> -0.015155183 | M28: =M19/M$20 -> -0.01950496 | N28: =N19/N$20 -> -0.011006992 | O28: =O19/O$20 -> -0.015094564 | P28: =P19/P$20 -> -0.016627732 | Q28: =Q19/Q$20 -> -0.019151195 | R28: =R19/R$20 -> -0.010237844 | ... AE28: =AE19/AE$20 -> -0.013540188
B29: Total | C29: =SUM(C25:C28) -> 1 | D29: =SUM(D25:D28) -> 1 | E29: =SUM(E25:E28) -> 1 | F29: =SUM(F25:F28) -> 1 | G29: =SUM(G25:G28) -> 1 | H29: =SUM(H25:H28) -> 1 | I29: =SUM(I25:I28) -> 1 | K29: =SUM(K25:K28) -> 1 | L29: =SUM(L25:L28) -> 1 | M29: =SUM(M25:M28) -> 1 | N29: =SUM(N25:N28) -> 1 | O29: =SUM(O25:O28) -> 1 | P29: =SUM(P25:P28) -> 1 | Q29: =SUM(Q25:Q28) -> 1 | R29: =SUM(R25:R28) -> 1 | ... AE29: =SUM(AE25:AE28) -> 1
B32: Revenue by segment (% YoY Growth)
B33: Chile | D33: =D16/C16-1 -> 0.26987372 | E33: =E16/D16-1 -> 0.060322104 | F33: =F16/E16-1 -> 0.051167963 | G33: =G16/F16-1 -> 0.039950865 | H33: =H16/G16-1 -> 0.046622529 | I33: =I16/H16-1 -> 0.0105092 | O33: =O16/K16-1 -> 0.16597266 | P33: =P16/L16-1 -> 0.037439924 | Q33: =Q16/M16-1 -> 0.0012902069 | R33: =R16/N16-1 -> 0.035937788 | S33: =S16/O16-1 -> 0.063979388 | T33: =T16/P16-1 -> 0.14650307 | U33: =U16/Q16-1 -> 0.050697776 | V33: =V16/R16-1 -> -0.021757521 | ... AE33: =AE16/AA16-1 -> 0.039008073
B34: Interntional Business | D34: =D17/C17-1 -> 0.68286566 | E34: =E17/D17-1 -> 0.15438192 | F34: =F17/E17-1 -> -0.25055989 | G34: =G17/F17-1 -> 0.44951568 | H34: =H17/G17-1 -> -0.08213268 | I34: =I17/H17-1 -> -0.02185085 | O34: =O17/K17-1 -> 0.51247788 | P34: =P17/L17-1 -> 0.70895815 | Q34: =Q17/M17-1 -> 0.25808167 | R34: =R17/N17-1 -> -0.27564336 | S34: =S17/O17-1 -> 0.046877392 | T34: =T17/P17-1 -> -0.13043632 | U34: =U17/Q17-1 -> -0.024106903 | V34: =V17/R17-1 -> -0.90256666 | ... AE34: =AE17/AA17-1 -> -0.066594273
B35: Wine | D35: =D18/C18-1 -> 0.11228117 | E35: =E18/D18-1 -> 0.1327491 | F35: =F18/E18-1 -> -0.14686828 | G35: =G18/F18-1 -> 0.11791701 | H35: =H18/G18-1 -> -0.021755541 | I35: =I18/H18-1 -> -0.01556798 | O35: =O18/K18-1 -> 0.13479238 | P35: =P18/L18-1 -> 0.16726571 | Q35: =Q18/M18-1 -> 0.19825584 | R35: =R18/N18-1 -> 0.032269258 | S35: =S18/O18-1 -> -0.17746659 | T35: =T18/P18-1 -> -0.14875148 | U35: =U18/Q18-1 -> -0.14739907 | V35: =V18/R18-1 -> -0.11699489 | ... AE35: =AE18/AA18-1 -> -0.071713872
B36: Other/Eliminations | D36: =D19/C19-1 -> 0.4204562 | E36: =E19/D19-1 -> 0.23845906 | F36: =F19/E19-1 -> -0.19845936 | G36: =G19/F19-1 -> 0.75503018 | H36: =H19/G19-1 -> 0.074060367 | I36: =I19/H19-1 -> -0.049913902 | O36: =O19/K19-1 -> 1.2758941 | P36: =P19/L19-1 -> 0.30378027 | Q36: =Q19/M19-1 -> 0.078634705 | R36: =R19/N19-1 -> -0.13094037 | S36: =S19/O19-1 -> -0.44948392 | T36: =T19/P19-1 -> -0.029030948 | U36: =U19/Q19-1 -> -0.11225107 | V36: =V19/R19-1 -> -0.20465494 | ... AE36: =AE19/AA19-1 -> -0.2172094
B37: Total | D37: =D20/C20-1 -> 0.3375973 | E37: =E20/D20-1 -> 0.091247051 | F37: =F20/E20-1 -> -0.053801357 | G37: =G20/F20-1 -> 0.13213915 | H37: =H20/G20-1 -> 0.0017417381 | I37: =I20/H20-1 -> 0.000633995 | O37: =O20/K20-1 -> 0.22966365 | P37: =P20/L20-1 -> 0.1883177 | Q37: =Q20/M20-1 -> 0.09855948 | R37: =R20/N20-1 -> -0.06564979 | S37: =S20/O20-1 -> 0.045064111 | T37: =T20/P20-1 -> 0.028180372 | U37: =U20/Q20-1 -> 0.0037587342 | V37: =V20/R20-1 -> -0.25476924 | ... AE37: =AE20/AA20-1 -> 0.0022560283
B40: EBITDA by segment
B41: Chile | C41: 244767.95 | D41: 334616.9 | E41: 227005.81 | F41: 283409.47 | G41: 290079.5 | H41: 312773.52 | I41: =SUM(AB41:AE41) -> 325730.75 | K41: 103945.9 | L41: 57934.894 | M41: 77634.79 | N41: =D41-SUM(K41:M41) -> 95101.317 | O41: 93444.911 | P41: 23711.452 | Q41: 37946.77 | R41: =E41-SUM(O41:Q41) -> 71902.682 | S41: 99760.923 | T41: 44105.783 | U41: 52618.074 | V41: =F41-SUM(S41:U41) -> 86924.69 | W41: 96733.379 | X41: 26587 | Y41: 59879.873 | Z41: =G41-SUM(W41:Y41) -> 106879.25 | AA41: 94399.941 | AB41: 42305 | AC41: 62756.235 | AD41: =H41-SUM(AA41:AC41) -> 113312.35 | AE41: 107357.17
B42: Interntional Business | C42: 24201.159 | D42: 90853.77 | E42: 101832.73 | F42: 85563.786 | G42: 78445.523 | H42: 55306.066 | I42: =SUM(AB42:AE42) -> 48811.582 | K42: 16706.271 | L42: -2223.2097 | M42: 16932.532 | N42: =D42-SUM(K42:M42) -> 59438.177 | O42: 33195.75 | P42: 1072.1762 | Q42: 19810.136 | R42: =E42-SUM(O42:Q42) -> 47754.672 | S42: 35807.11 | T42: 1875.4248 | U42: 25785.434 | V42: =F42-SUM(S42:U42) -> 22095.817 | W42: 26097.706 | X42: -24373 | Y42: 3953.738 | Z42: =G42-SUM(W42:Y42) -> 72767.079 | AA42: 34983.112 | AB42: -26892 | AC42: 6845.212 | AD42: =H42-SUM(AA42:AC42) -> 40369.742 | AE42: 28488.628
B43: Wine | C43: 43104.576 | D43: 45690.839 | E43: 51374.741 | F43: 32184.35 | G43: 41829.076 | H43: 35599.733 | I43: =SUM(AB43:AE43) -> 32295.95 | K43: 10179.583 | L43: 10808.991 | M43: 13404.368 | N43: =D43-SUM(K43:M43) -> 11297.897 | O43: 11469.427 | P43: 11788.401 | Q43: 14733.421 | R43: =E43-SUM(O43:Q43) -> 13383.492 | S43: 3496.4511 | T43: 6542.8742 | U43: 11606.13 | V43: =F43-SUM(S43:U43) -> 10538.895 | W43: 6666.9653 | X43: 10419 | Y43: 12521.319 | Z43: =G43-SUM(W43:Y43) -> 12221.792 | AA43: 6591.924 | AB43: 11285 | AC43: 11024.322 | AD43: =H43-SUM(AA43:AC43) -> 6698.487 | AE43: 3288.141
B44: Other/Eliminations | C44: -15668.846 | D44: -26163.923 | E44: -22284.642 | F44: -21755.234 | G44: 5582.014 | H44: -27471.364 | I44: =SUM(AB44:AE44) -> -30540.857 | K44: -4284.3604 | L44: -4945.091 | M44: -6499.4163 | N44: =D44-SUM(K44:M44) -> -10435.055 | O44: -2984.3032 | P44: -4101.1463 | Q44: -4883.6709 | R44: =E44-SUM(O44:Q44) -> -10315.521 | S44: -3687.7775 | T44: -5398.2414 | U44: -3665.7825 | V44: =F44-SUM(S44:U44) -> -9003.433 | W44: -5334.7994 | X44: 26089 | Y44: -5924.232 | Z44: =G44-SUM(W44:Y44) -> -9247.9546 | AA44: -4420.929 | AB44: -6881 | AC44: -6990.309 | AD44: =H44-SUM(AA44:AC44) -> -9179.126 | AE44: -7490.422
B45: Total | C45: =SUM(C41:C44) -> 296404.84 | D45: =SUM(D41:D44) -> 444997.59 | E45: =SUM(E41:E44) -> 357928.65 | F45: =SUM(F41:F44) -> 379402.37 | G45: =SUM(G41:G44) -> 415936.11 | H45: =SUM(H41:H44) -> 376207.96 | I45: =SUM(AB45:AE45) -> 376297.43 | K45: =SUM(K41:K44) -> 126547.39 | L45: =SUM(L41:L44) -> 61575.584 | M45: =SUM(M41:M44) -> 101472.27 | N45: =SUM(N41:N44) -> 155402.34 | O45: =SUM(O41:O44) -> 135125.78 | P45: =SUM(P41:P44) -> 32470.883 | Q45: =SUM(Q41:Q44) -> 67606.655 | R45: =SUM(R41:R44) -> 122725.32 | ... AE45: =SUM(AE41:AE44) -> 131643.52
B46: Check | C46: =C45-Model!C51 -> -0.00021999999 | D46: =D45-Model!D51 -> -0.0010331731 | E46: =E45-Model!E51 -> -0.0016961747 | F46: =F45-Model!F51 -> -0.0015146816 | G46: =G45-Model!G51 -> 0 | H46: =H45-Model!H51 -> 0 | I46: =I45-Model!I51 -> -0.048 | K46: =K45-Model!K51 -> -0.000711 | L46: =L45-Model!L51 -> -0.0017437525 | M46: =M45-Model!M51 -> 0.001019279 | N46: =N45-Model!N51 -> 0.00040230041 | O46: =O45-Model!O51 -> -0.00039269918 | P46: =P45-Model!P51 -> 0.0010080301 | Q46: =Q45-Model!Q51 -> -0.00063764671 | R46: =R45-Model!R51 -> -0.0016738589 | ... AE46: =AE45-Model!AE51 -> 0
