Workbook
Name \A: #REF!
Name \B: #REF!
Name \C: #REF!
Name \L: #REF!
Name \M: #REF!
Name \P: #REF!
Name \Y: #REF!
Name _01_30_04: MonthlyOpStats
Name _1_30_01: MonthlyOpStats
Name _1_30_02: MonthlyOpStats
Name _1_31_01: MonthlyOpStats
Name _1_31_02: MonthlyOpStats
Name _12_31_05: MonthlyOpStats
Name _A: #REF!
Name _A___0: #REF!
Name _B: #REF!
Name _B___0: #REF!
Name _C: #REF!
Name _C___0: #REF!
Name _ent1: [1]Inputs!$J$17
Name _ent10: [1]Inputs!$J$476
Name _ent11: [1]Inputs!$J$527
Name _ent12: [1]Inputs!$J$578
Name _ent13: [1]Inputs!$J$629
Name _ent14: [1]Inputs!$J$680
Name _ent15: [1]Inputs!$J$731
Name _ent2: [1]Inputs!$J$68
Name _ent3: [1]Inputs!$J$119
Name _ent4: [1]Inputs!$J$170
Name _ent5: [1]Inputs!$J$221
Name _ent6: [1]Inputs!$J$272
Name _ent7: [1]Inputs!$J$323
Name _ent8: [1]Inputs!$J$374
Name _ent9: [1]Inputs!$J$425
Name _eps1: [1]Inputs!$P$42
Name _eps10: [1]Inputs!$P$501
Name _eps11: [1]Inputs!$P$552
Name _eps12: [1]Inputs!$P$603
Name _eps13: [1]Inputs!$P$654
Name _eps14: [1]Inputs!$P$705
Name _eps15: [1]Inputs!$P$756
Name _eps2: [1]Inputs!$P$93
Name _eps3: [1]Inputs!$P$144
Name _eps4: [1]Inputs!$P$195
Name _eps5: [1]Inputs!$P$246
Name _eps6: [1]Inputs!$P$297
Name _eps7: [1]Inputs!$P$348
Name _eps8: [1]Inputs!$P$399
Name _eps9: [1]Inputs!$P$450
Name _fye1: [1]Inputs!$E$12
Name _fye10: [1]Inputs!$E$471
Name _fye11: [1]Inputs!$E$522
Name _fye12: [1]Inputs!$E$573
Name _fye13: [1]Inputs!$E$624
Name _fye14: [1]Inputs!$E$675
Name _fye15: [1]Inputs!$E$726
Name _fye2: [1]Inputs!$E$63
Name _fye3: [1]Inputs!$E$114
Name _fye4: [1]Inputs!$E$165
Name _fye5: [1]Inputs!$E$216

Sheet Capital Structure
AR2: Exchange rate at end of period | AS2: 72.49 | AT2: 69.77 | AU2: 69.16 | AV2: 69.02 | AW2: 71.77 | AX2: 70.8675 | AY2: 75.3245 | AZ2: 75.5087 | BA2: 73.7637 | BB2: 73.01 | BC2: 73.2065 | BD2: 74.3716 | BE2: 74.2236 | BF2: 74.467 | BG2: 74.36 | BH2: 78.92 | BI2: 81.461 | BJ2: 82.717 | BK2: 82.08 | BL2: 82.1 | BM2: 83.04 | BN2: 83.238 | BO2: 83.35 | BP2: 83.355 | BQ2: 83.755 | BR2: 85.554 | BS2: 85.45 | BT2: 85.7 | BU2: 88.841 | BV2: ='Model '!BY208 -> 89.871 | BW2: ='Model '!BZ208 -> 93.485
AS3: Amount in USD
C4: 40603 | D4: 40969 | E4: 41334 | F4: 41699 | G4: 42064 | H4: 42430 | I4: 42795 | J4: 43070 | K4: 43190 | L4: 43281 | M4: 43373 | N4: 43465 | O4: 43555 | P4: 43646 | Q4: 43738 | R4: 43830 | S4: 43921 | T4: 44012 | U4: 44104 | V4: 44196 | W4: 44286 | X4: 44377 | Y4: 44469 | Z4: 44561 | AA4: 44651 | AB4: 44742 | AC4: 44834 | AD4: 44926 | AE4: 45016 | AF4: 45107 | AG4: 45199 | AH4: 45290 | AI4: 45382 | AJ4: 45473 | AK4: 45565 | AL4: 45656 | AM4: 45746 | AN4: 45838 | AO4: 45930 | AP4: 46021 | AQ4: 46112 | AS4: 43373 | AT4: 43464 | AU4: 43555 | AV4: =P4 -> 43646 | AW4: =Q4 -> 43738 | AX4: =R4 -> 43830 | AY4: =S4 -> 43921 | AZ4: =T4 -> 44012 | BA4: =U4 -> 44104 | BB4: =V4 -> 44196 | BC4: =W4 -> 44286 | ... BW4: =AQ4 -> 46112
B5: Amounts in millions of INR unless stated | C5: FY11 | D5: FY12 | E5: FY13 | F5: FY14 | G5: FY15 | H5: FY16 | I5: FY17 | J5: 3Q18 | K5: 4Q18 | L5: 1Q19 | M5: 2Q19 | N5: 3Q19 | O5: 4Q19 | P5: 1Q20 | Q5: 2Q20 | R5: 3Q20 | S5: 4Q20 | T5: 1Q21 | U5: 2Q21 | V5: 3Q21 | W5: 4Q21 | X5: 1Q22 | Y5: 2Q22 | Z5: 3Q22 | AA5: 4Q22 | AB5: 1Q23 | AC5: 2Q23 | AD5: 3Q23 | AE5: 4Q23 | AF5: 1Q24 | AG5: 2Q24 | AH5: 3Q24 | AI5: 4Q24 | AJ5: 1Q25 | AK5: 2Q25 | AL5: 3Q25 | AM5: 4Q25 | AN5: 1Q26 | AO5: 2Q26 | AP5: 3Q26 | AQ5: 4Q26 | AS5: 2Q19 | AT5: 3Q19 | AU5: 4Q19 | AV5: =P5 -> 1Q20 | AW5: =Q5 -> 2Q20 | AX5: =R5 -> 3Q20 | AY5: =S5 -> 4Q20 | AZ5: =T5 -> 1Q21 | BA5: =U5 -> 2Q21 | BB5: =V5 -> 3Q21 | BC5: =W5 -> 4Q21 | ... BW5: =AQ5 -> 4Q26
B6: Secured debt | C6: 0 | D6: 0 | E6: 0 | F6: 0 | G6: 0 | H6: 43977 | I6: 12038 | J6: 12038 | K6: 21925 | L6: 21925 | M6: 21925 | N6: 21925 | O6: 3095 | P6: 3095 | Q6: 3095 | R6: 3095 | S6: 3095 | T6: 3095 | U6: 3095 | V6: 3095 | W6: 3095 | X6: 3095 | Y6: 3095 | Z6: 3095 | AA6: 3095 | AB6: 3095 | AC6: 3095 | AD6: 3095 | AE6: 3095 | AF6: 3095 | AG6: 3095 | AH6: 3095 | AI6: 3095 | AJ6: 3095 | AK6: 3095 | AL6: 3095 | AM6: 3095 | AN6: 3095 | AO6: 3095 | AP6: 3095 | AQ6: 3095 | AS6: =M6/$AS$2 -> 302.45551 | AT6: =N6/$AT$2 -> 314.24681 | AU6: =O6/AU$2 -> 44.751301 | AV6: =P6/AV$2 -> 44.842075 | AW6: =Q6/AW$2 -> 43.123868 | AX6: =R6/AX$2 -> 43.673052 | AY6: =S6/AY$2 -> 41.088889 | AZ6: =T6/AZ$2 -> 40.988654 | BA6: =U6/BA$2 -> 41.958307 | BB6: =V6/BB$2 -> 42.391453 | ... BW6: =AQ6/BW$2 -> 33.106916
B7: Lease Obligation | C7: 0 | D7: 0 | E7: 0 | F7: 0 | G7: 0 | H7: 57871 | I7: 56547 | J7: 48389.606 | K7: 48831 | L7: 50118 | M7: 52304.93 | N7: 49293.865 | O7: 47553.013 | P7: 281967.47 | Q7: 299807.14 | R7: 301529.25 | S7: 306078.13 | T7: 306132.55 | U7: 304383 | V7: 324529 | W7: 329953 | X7: 331104 | Y7: 348981 | Z7: 352346.29 | AA7: 367634 | AB7: 478105.47 | AC7: 523642.47 | AD7: 549018.04 | AE7: 604755 | AF7: 589108 | AG7: 595564.62 | AH7: 597143 | AI7: 636758 | AJ7: 674544 | AK7: 792003 | AL7: 629333 | AM7: 653298 | AN7: 660901 | AO7: 680618 | AP7: ='Model '!$BY$118 -> 701294 | AQ7: ='Model '!$BZ$118 -> 737403 | AS7: =M7/$AS$2 -> 721.54683 | AT7: =N7/$AT$2 -> 706.51949 | AU7: =O7/AU$2 -> 687.57971 | AV7: =P7/AV$2 -> 4085.3009 | AW7: =Q7/AW$2 -> 4177.3323 | AX7: =R7/AX$2 -> 4254.8312 | AY7: =S7/AY$2 -> 4063.4604 | AZ7: =T7/AZ$2 -> 4054.2685 | BA7: =U7/BA$2 -> 4126.4606 | BB7: =V7/BB$2 -> 4444.9938 | ... BW7: =AQ7/BW$2 -> 7887.9285
B8: Total Secured debt | C8: =SUM(C6:C7) -> 0 | D8: =SUM(D6:D7) -> 0 | E8: =SUM(E6:E7) -> 0 | F8: =SUM(F6:F7) -> 0 | G8: =SUM(G6:G7) -> 0 | H8: =SUM(H6:H7) -> 101848 | I8: =SUM(I6:I7) -> 68585 | J8: =SUM(J6:J7) -> 60427.606 | ... AQ8: =SUM(AQ6:AQ7) -> 740498 | AS8: =SUM(AS6:AS7) -> 1024.0023 | AT8: =SUM(AT6:AT7) -> 1020.7663 | AU8: =SUM(AU6:AU7) -> 732.33101 | AV8: =SUM(AV6:AV7) -> 4130.143 | AW8: =SUM(AW6:AW7) -> 4220.4562 | AX8: =SUM(AX6:AX7) -> 4298.5043 | AY8: =SUM(AY6:AY7) -> 4104.5493 | AZ8: =SUM(AZ6:AZ7) -> 4095.2572 | ... BW8: =SUM(BW6:BW7) -> 7921.0355
B10: Unsecured debt
B11: 1.5% Senior USD bond due 2025 | R11: 70867.5 | S11: 75324.5 | T11: 75508.7 | U11: 73763.7 | V11: 73010 | W11: 73206.5 | X11: 74371.6 | Y11: 74223.6 | Z11: 74467 | AA11: 74360 | AB11: 78920 | AC11: 81461 | AD11: 82717 | AE11: 82080 | AF11: 75917.87 | AG11: 65354.141 | AH11: 48087.425 | AI11: 48152.128 | AJ11: 48155.017 | AK11: 48386.101 | AL11: 49425.401 | AM11: 0 | AN11: 0 | AO11: 0 | AP11: 0 | AQ11: 0 | AX11: =R11/AX$2 -> 1000 | AY11: =S11/AY$2 -> 1000 | AZ11: =T11/AZ$2 -> 1000 | BA11: =U11/BA$2 -> 1000 | BB11: =V11/BB$2 -> 1000 | BC11: =W11/BC$2 -> 1000 | BD11: =X11/BD$2 -> 1000 | BE11: =Y11/BE$2 -> 1000 | ... BW11: =AQ11/BW$2 -> 0
B12: 4.375% Senior USD Bonds due 2025 | J12: 63880 | K12: 65180 | L12: 68470 | M12: 72490 | N12: 69770 | O12: 69160 | P12: 69020 | Q12: 71770 | R12: 70867.5 | S12: 75324.5 | T12: 75508.7 | U12: 73763.7 | V12: 73010 | W12: 73206.5 | X12: 74371.6 | Y12: 74223.6 | Z12: 74467 | AA12: 74360 | AB12: 78920 | AC12: 81461 | AD12: 82717 | AE12: 82080 | AF12: 82100 | AG12: 83040 | AH12: 83238 | AI12: 83350 | AJ12: 83355 | AK12: 83755 | AL12: 85554 | AM12: 85450 | AN12: 0 | AO12: 0 | AP12: 0 | AQ12: 0 | AS12: =M12/$AS$2 -> 1000 | AT12: =N12/$AT$2 -> 1000 | AU12: =O12/AU$2 -> 1000 | AV12: =P12/AV$2 -> 1000 | AW12: =Q12/AW$2 -> 1000 | AX12: =R12/AX$2 -> 1000 | AY12: =S12/AY$2 -> 1000 | AZ12: =T12/AZ$2 -> 1000 | BA12: =U12/BA$2 -> 1000 | BB12: =V12/BB$2 -> 1000 | ... BW12: =AQ12/BW$2 -> 0
B13: 5.125% Senior USD Bonds due 2023 | J13: 95820 | K13: 97770 | L13: 102705 | M13: 108735 | N13: 104655 | O13: 103740 | P13: 103530 | Q13: 107655 | R13: 106301.25 | S13: 112986.75 | T13: 38125.853 | U13: 37244.767 | V13: 36864.209 | W13: 36963.426 | X13: 37551.708 | Y13: 37476.98 | Z13: 37599.878 | AA13: 37545.851 | AB13: 39848.286 | AC13: 41131.288 | AD13: 41765.468 | AE13: 41443.834 | AF13: 0 | AG13: 0 | AH13: 0 | AI13: 0 | AJ13: 0 | AK13: 0 | AL13: 0 | AM13: 0 | AN13: 0 | AO13: 0 | AP13: 0 | AQ13: 0 | AS13: =M13/$AS$2 -> 1500 | AT13: =N13/$AT$2 -> 1500 | AU13: =O13/AU$2 -> 1500 | AV13: =P13/AV$2 -> 1500 | AW13: =Q13/AW$2 -> 1500 | AX13: =R13/AX$2 -> 1500 | AY13: =S13/AY$2 -> 1500 | AZ13: =T13/AZ$2 -> 504.92 | BA13: =U13/BA$2 -> 504.92 | BB13: =V13/BB$2 -> 504.92 | ... BW13: =AQ13/BW$2 -> 0
B14: 5.350% Senior USD Bonds due 2024 | J14: 63880 | K14: 65180 | L14: 68470 | M14: 72490 | N14: 69770 | O14: 69160 | P14: 69020 | Q14: 71770 | R14: 70867.5 | S14: 75324.5 | T14: 75508.7 | U14: 73763.7 | V14: 73010 | W14: 73206.5 | X14: 74371.6 | Y14: 74223.6 | Z14: 74467 | AA14: 74360 | AB14: 78920 | AC14: 81461 | AD14: 82717 | AE14: 82080 | AF14: 45155 | AG14: 45672 | AH14: 45780.9 | AI14: 45842.5 | AJ14: 45845.25 | AK14: 46065.25 | AL14: 47054.7 | AM14: 0 | AN14: 0 | AO14: 0 | AP14: 0 | AQ14: 0 | AS14: =M14/$AS$2 -> 1000 | AT14: =N14/$AT$2 -> 1000 | AU14: =O14/AU$2 -> 1000 | AV14: =P14/AV$2 -> 1000 | AW14: =Q14/AW$2 -> 1000 | AX14: =R14/AX$2 -> 1000 | AY14: =S14/AY$2 -> 1000 | AZ14: =T14/AZ$2 -> 1000 | BA14: =U14/BA$2 -> 1000 | BB14: =V14/BB$2 -> 1000 | ... BW14: =AQ14/BW$2 -> 0
B15: 3.375% Senior EUR Bonds due 2021 | J15: 47910 | K15: 48885 | L15: 51352.5 | M15: 74664.7 | N15: 71863.1 | O15: 71234.8 | P15: 71090.6 | Q15: 73923.1 | R15: 72993.525 | S15: 77584.235 | T15: 66651.529 | U15: 65368.653 | V15: 64700.732 | W15: 75402.695 | X15: 65647.811 | Y15: 65776.212 | Z15: 65991.911 | AA15: 65897.088 | AB15: 69662.684 | AC15: 71905.625 | AD15: 73302.978 | AE15: 72738.475 | AF15: 0 | AG15: 0 | AH15: 0 | AI15: 0 | AJ15: 0 | AK15: 0 | AL15: 0 | AM15: 0 | AN15: 0 | AO15: 0 | AP15: 0 | AQ15: 0 | AS15: =M15/$AS$2 -> 1030 | AT15: =N15/$AT$2 -> 1030 | AU15: =O15/AU$2 -> 1030 | AV15: =P15/AV$2 -> 1030 | AW15: =Q15/AW$2 -> 1030 | AX15: =R15/AX$2 -> 1030 | AY15: =S15/AY$2 -> 1030 | AZ15: =T15/AZ$2 -> 882.7 | BA15: =U15/BA$2 -> 886.19 | BB15: =V15/BB$2 -> 886.19 | ... BW15: =AQ15/BW$2 -> 0
B16: 3.25% Senior EUR Bonds due 2031 | AF16: 61575 | AG16: 62280 | AH16: 62428.5 | AI16: 62512.5 | AJ16: 62516.25 | AK16: 62816.25 | AL16: 64165.5 | AM16: 64087.5 | AN16: 64275 | AO16: 66630.75 | AP16: =750*$BV$2 -> 67403.25 | AQ16: =750*$BW$2 -> 70113.75 | BL16: =AF16/BL$2 -> 750 | BM16: =AG16/BM$2 -> 750 | BN16: =AH16/BN$2 -> 750 | BO16: =AI16/BO$2 -> 750 | BP16: =AJ16/BP$2 -> 750 | BQ16: =AK16/BQ$2 -> 750 | BR16: =AL16/BR$2 -> 750 | BS16: =AM16/BS$2 -> 750 | ... BW16: =AQ16/BW$2 -> 750
B17: 4.00% Senior EUR Bonds due 2018 | J17: 63880 | K17: 65180 | L17: 68470 | M17: 100036.2 | AI17: 0 | AJ17: 0 | AK17: 0 | AL17: 0 | AM17: 0 | AN17: 0 | AO17: 0 | AP17: 0 | AQ17: 0 | AS17: =M17/$AS$2 -> 1380 | AT17: =N17/$AT$2 -> 0 | AU17: =O17/AU$2 -> 0 | AV17: =P17/AV$2 -> 0 | AW17: =Q17/AW$2 -> 0 | AX17: =R17/AX$2 -> 0 | AY17: =S17/AY$2 -> 0 | AZ17: =T17/AZ$2 -> 0 | BA17: =U17/BA$2 -> 0 | BB17: =V17/BB$2 -> 0 | ... BW17: =AQ17/BW$2 -> 0
B18: 3.00% Senior CHF Bonds due 2020 | J18: 22358 | K18: 22813 | L18: 23964.5 | M18: 28695.166 | N18: 27618.454 | O18: 27376.986 | P18: 27321.567 | Q18: 28410.155 | R18: 28052.9 | S18: 29817.203 | T18: 0 | U18: 0 | V18: 0 | W18: 0 | X18: 0 | Y18: 0 | Z18: 0 | AA18: 0 | AB18: 0 | AC18: 0 | AD18: 0 | AE18: 0 | AF18: 0 | AG18: 0 | AH18: 0 | AI18: 0 | AJ18: 0 | AK18: 0 | AL18: 0 | AM18: 0 | AN18: 0 | AO18: 0 | AP18: 0 | AQ18: 0 | AS18: =M18/$AS$2 -> 395.85 | AT18: =N18/$AT$2 -> 395.85 | AU18: =O18/AU$2 -> 395.85 | AV18: =P18/AV$2 -> 395.85 | AW18: =Q18/AW$2 -> 395.85 | AX18: =R18/AX$2 -> 395.85 | AY18: =S18/AY$2 -> 395.85 | AZ18: =T18/AZ$2 -> 0 | BA18: =U18/BA$2 -> 0 | BB18: =V18/BB$2 -> 0 | ... BW18: =AQ18/BW$2 -> 0
B19: 8.250% subordinated INR bonds due 2020 | K19: 15000 | L19: 15000 | M19: 15000 | N19: 15000 | O19: 15000 | P19: 15000 | Q19: 15000 | R19: 15000 | S19: 15000 | T19: 14976.74 | U19: 0 | V19: 0 | W19: 0 | X19: 0 | Y19: 0 | Z19: 0 | AA19: 0 | AB19: 0 | AC19: 0 | AD19: 0 | AE19: 0 | AF19: 0 | AG19: 0 | AH19: 0 | AI19: 0 | AJ19: 0 | AK19: 0 | AL19: 0 | AM19: 0 | AN19: 0 | AO19: 0 | AP19: 0 | AQ19: 0 | AS19: =M19/$AS$2 -> 206.92509 | AT19: =N19/$AT$2 -> 214.99212 | AU19: =O19/AU$2 -> 216.88837 | AV19: =P19/AV$2 -> 217.32831 | AW19: =Q19/AW$2 -> 209.00098 | AX19: =R19/AX$2 -> 211.66261 | AY19: =S19/AY$2 -> 199.13839 | AZ19: =T19/AZ$2 -> 198.34456 | BA19: =U19/BA$2 -> 0 | BB19: =V19/BB$2 -> 0 | ... BW19: =AQ19/BW$2 -> 0
B20: 8.350% subordinated INR bonds due 2021 | K20: 15000 | L20: 15000 | M20: 15000 | N20: 15000 | O20: 15000 | P20: 15000 | Q20: 15000 | R20: 15000 | S20: 15000 | T20: 15000 | U20: 15000 | V20: 15000 | W20: 15000 | X20: 15000 | Y20: 15000 | Z20: 15000 | AA20: 15000 | AB20: 15000 | AC20: 15000 | AD20: 15000 | AE20: 15000 | AF20: 0 | AG20: 0 | AH20: 0 | AI20: 0 | AJ20: 0 | AK20: 0 | AL20: 0 | AM20: 0 | AN20: 0 | AO20: 0 | AP20: 0 | AQ20: 0 | AS20: =M20/$AS$2 -> 206.92509 | AT20: =N20/$AT$2 -> 214.99212 | AU20: =O20/AU$2 -> 216.88837 | AV20: =P20/AV$2 -> 217.32831 | AW20: =Q20/AW$2 -> 209.00098 | AX20: =R20/AX$2 -> 211.66261 | AY20: =S20/AY$2 -> 199.13839 | AZ20: =T20/AZ$2 -> 198.65261 | BA20: =U20/BA$2 -> 203.35206 | BB20: =V20/BB$2 -> 205.45131 | ... BW20: =AQ20/BW$2 -> 0
B21: 5.65% Subordinated USD Bond - perpetual | Q21: 53827.5 | R21: 53150.625 | S21: 56493.375 | T21: 75508.7 | U21: 73763.7 | V21: 73010 | W21: 54904.875 | X21: 74371.6 | Y21: 74223.6 | Z21: 74467 | AA21: 74360 | AB21: 78920 | AC21: 81461 | AD21: 82717 | AE21: 82080 | AF21: 82100 | AG21: 83040 | AH21: 83238 | AI21: 83350 | AJ21: 83355 | AK21: 83755 | AL21: 85554 | AM21: 0 | AN21: 0 | AO21: 0 | AP21: 0 | AQ21: 0 | AW21: 1 | AX21: =R21/AX$2 -> 750 | AY21: =S21/AY$2 -> 750 | AZ21: =T21/AZ$2 -> 1000 | BA21: =U21/BA$2 -> 1000 | BB21: =V21/BB$2 -> 1000 | BC21: =W21/BC$2 -> 750 | BD21: =X21/BD$2 -> 1000 | BE21: =Y21/BE$2 -> 1000 | ... BW21: =AQ21/BW$2 -> 0
B22: 3.975% Subordinated USD Bond - perpetual | AF22: 41050 | AG22: 41520 | AH22: 41619 | AI22: 41675 | AJ22: 41677.5 | AK22: 41877.5 | AL22: 42777 | AM22: 42725 | AN22: 42850 | AO22: 44420.5 | AP22: =500*$BV$2 -> 44935.5 | AQ22: =500*$BW$2 -> 46742.5 | BL22: =AF22/BL$2 -> 500 | BM22: =AG22/BM$2 -> 500 | BN22: =AH22/BN$2 -> 500 | BO22: =AI22/BO$2 -> 500 | BP22: =AJ22/BP$2 -> 500 | BQ22: =AK22/BQ$2 -> 500 | BR22: =AL22/BR$2 -> 500 | BS22: =AM22/BS$2 -> 500 | ... BW22: =AQ22/BW$2 -> 500
B23: DoT Obligations / Spectrum Debt | C23: 0 | D23: 0 | E23: 0 | F23: 0 | G23: 143143.33 | H23: 350025.16 | I23: 439229.05 | J23: =917139-446768 -> 470371 | K23: 0 | L23: 0 | M23: 0 | N23: 0 | O23: 0 | AI23: 0 | AJ23: 0 | AK23: 0 | AL23: 0 | AM23: 0 | AN23: 0 | AO23: 0 | AP23: 0 | AQ23: 0 | AS23: =M23/$AS$2 -> 0 | AT23: =N23/$AT$2 -> 0 | AU23: =O23/AU$2 -> 0 | AV23: =P23/AV$2 -> 0 | AW23: =Q23/AW$2 -> 0 | AX23: =R23/AX$2 -> 0 | AY23: =S23/AY$2 -> 0 | AZ23: =T23/AZ$2 -> 0 | BA23: =U23/BA$2 -> 0 | BB23: =V23/BB$2 -> 0 | ... BW23: =AQ23/BW$2 -> 0
B24: Other unsecured debt | C24: 616707 | D24: 690232 | E24: 667363 | F24: 759984 | G24: 663695.67 | H24: 552652.83 | I24: 566466.95 | J24: 173879 | K24: 675912 | L24: 717464 | M24: 723122.93 | N24: 770881.45 | O24: 835802.28 | P24: 642734.66 | Q24: 625533.17 | R24: 653879.14 | S24: 637172.12 | T24: 857839.48 | U24: 947348.17 | V24: 915867.06 | W24: 890851.5 | X24: 1085266.3 | Y24: 1109022 | Z24: 985437.31 | AA24: 983029.06 | AB24: 1015645.7 | AC24: 1279857.7 | AD24: 1290213.7 | AE24: 1276424.7 | AF24: 1269218.1 | AG24: 1194012 | AH24: 1220414.2 | AI24: 1144873.9 | AJ24: 1047161.8 | AK24: 1094797.8 | AL24: 1040385.4 | AM24: 1288775.5 | AN24: 1263525 | AO24: 1286387.8 | AP24: ='Model '!BY$122-AP23-AP18-AP17-AP15-AP14-AP13-AP12-AP19-AP20-AP21-AP11-AP16-AP22 -> 1163314.2 | AQ24: ='Model '!BZ$122-AQ23-AQ18-AQ17-AQ15-AQ14-AQ13-AQ12-AQ19-AQ20-AQ21-AQ11-AQ16-AQ22 -> 1097751.8 | AS24: =M24/$AS$2 -> 9975.4854 | AT24: =N24/$AT$2 -> 11048.896 | AU24: =O24/AU$2 -> 12085.053 | AV24: =P24/AV$2 -> 9312.2958 | AW24: =Q24/AW$2 -> 8715.8029 | AX24: =R24/AX$2 -> 9226.7844 | AY24: =S24/AY$2 -> 8459.0289 | AZ24: =T24/AZ$2 -> 11360.803 | BA24: =U24/BA$2 -> 12843.013 | BB24: =V24/BB$2 -> 12544.406 | ... BW24: =AQ24/BW$2 -> 11742.544
B25: Total debt | C25: =C24+C8+C23+C12+C13+C14+C15+C17+C18+C19+C20 -> 616707 | D25: =D24+D8+D23+D12+D13+D14+D15+D17+D18+D19+D20 -> 690232 | E25: =E24+E8+E23+E12+E13+E14+E15+E17+E18+E19+E20 -> 667363 | F25: =F24+F8+F23+F12+F13+F14+F15+F17+F18+F19+F20 -> 759984 | G25: =G24+G8+G23+G12+G13+G14+G15+G17+G18+G19+G20 -> 806839 | H25: =H24+H8+H23+H12+H13+H14+H15+H17+H18+H19+H20 -> 1004526 | I25: =I24+I8+I23+I12+I13+I14+I15+I17+I18+I19+I20 -> 1074281 | J25: =J24+J8+J23+J12+J13+J14+J15+J17+J18+J19+J20 -> 1062405.6 | ... P25: =P24+P8+P23+P12+P13+P14+P15+P17+P18+P19+P20 -> 1297779.3 | Q25: =Q24+Q8+Q23+Q12+Q13+Q14+Q15+Q17+Q18+Q19+Q20+Q21 -> 1365791.1 | R25: =R24+R8+R23+R12+R13+R14+R15+R17+R18+R19+R20+R21+R11 -> 1461604.2 | S25: =S24+S8+S23+S12+S13+S14+S15+S17+S18+S19+S20+S21+S11 -> 1479200.3 | T25: =T24+T8+T23+T12+T13+T14+T15+T17+T18+T19+T20 -> 1452838.5 | U25: =U24+U8+U23+U12+U13+U14+U15+U17+U18+U19+U20+U21 -> 1593730.7 | V25: =V24+V8+V23+V12+V13+V14+V15+V17+V18+V19+V20+V21 -> 1579086 | W25: =W24+W8+W23+W12+W13+W14+W15+W17+W18+W19+W20+W21+W11 -> 1625790 | X25: =X24+X8+X23+X12+X13+X14+X15+X17+X18+X19+X20 -> 1686408 | Y25: =Y24+Y8+Y23+Y12+Y13+Y14+Y15+Y17+Y18+Y19+Y20+Y21 -> 1802022 | Z25: =Z24+Z8+Z23+Z12+Z13+Z14+Z15+Z17+Z18+Z19+Z20+Z21 -> 1682871.4 | AA25: =AA24+AA8+AA23+AA12+AA13+AA14+AA15+AA17+AA18+AA19+AA20+AA21 -> 1695281 | AB25: =AB24+AB8+AB23+AB12+AB13+AB14+AB15+AB17+AB18+AB19+AB20 -> 1779197.2 | AC25: =AC24+AC8+AC23+AC12+AC13+AC14+AC15+AC17+AC18+AC19+AC20+AC21 -> 2179015 | AD25: =AD24+AD8+AD23+AD12+AD13+AD14+AD15+AD17+AD18+AD19+AD20+AD21 -> 2220546.2 | AE25: =AE24+AE8+AE23+AE12+AE13+AE14+AE15+AE17+AE18+AE19+AE20+AE21 -> 2259697 | AF25: =AF24+AF8+AF23+AF12+AF13+AF14+AF15+AF17+AF18+AF19+AF20+AF21+AF16+AF22+AF11 -> 2249319 | AG25: =AG24+AG8+AG23+AG12+AG13+AG14+AG15+AG17+AG18+AG19+AG20+AG21+AG16+AG22+AG11 -> 2173577.8 | AH25: =AH24+AH8+AH23+AH12+AH13+AH14+AH15+AH17+AH18+AH19+AH20+AH21+AH16+AH22+AH11 -> 2185044 | AI25: =AI24+AI8+AI23+AI12+AI13+AI14+AI15+AI17+AI18+AI19+AI20+AI21+AI16+AI22+AI11 -> 2149609 | AJ25: =AJ24+AJ8+AJ23+AJ12+AJ13+AJ14+AJ15+AJ17+AJ18+AJ19+AJ20+AJ21+AJ16+AJ22+AJ11 -> 2089704.8 | AK25: =AK24+AK8+AK23+AK12+AK13+AK14+AK15+AK17+AK18+AK19+AK20+AK21+AK16+AK22+AK11 -> 2256550.9 | AL25: =AL24+AL8+AL23+AL12+AL13+AL14+AL15+AL17+AL18+AL19+AL20+AL21+AL16+AL22+AL11 -> 2047344 | AM25: =AM24+AM8+AM23+AM12+AM13+AM14+AM15+AM17+AM18+AM19+AM20+AM21+AM16+AM22+AM11 -> 2137431 | ... AQ25: =AQ24+AQ8+AQ23+AQ12+AQ13+AQ14+AQ15+AQ17+AQ18+AQ19+AQ20+AQ21+AQ16+AQ22+AQ11 -> 1955106 | AS25: =AS24+AS8+AS23+AS12+AS13+AS14+AS15+AS17+AS18+AS19+AS20 -> 17719.188 | AT25: =AT24+AT8+AT23+AT12+AT13+AT14+AT15+AT17+AT18+AT19+AT20 -> 17425.496 | AU25: =AU24+AU8+AU23+AU12+AU13+AU14+AU15+AU17+AU18+AU19+AU20 -> 18177.011 | AV25: =AV24+AV8+AV23+AV12+AV13+AV14+AV15+AV17+AV18+AV19+AV20 -> 18802.945 | AW25: =AW24+AW8+AW23+AW12+AW13+AW14+AW15+AW17+AW18+AW19+AW20+AW21+AW11 -> 18281.111 | AX25: =AX24+AX8+AX23+AX12+AX13+AX14+AX15+AX17+AX18+AX19+AX20+AX21+AX11 -> 20624.464 | AY25: =AY24+AY8+AY23+AY12+AY13+AY14+AY15+AY17+AY18+AY19+AY20+AY21+AY11 -> 19637.705 | AZ25: =AZ24+AZ8+AZ23+AZ12+AZ13+AZ14+AZ15+AZ17+AZ18+AZ19+AZ20+AZ21+AZ11 -> 21240.678 | BA25: =BA24+BA8+BA23+BA12+BA13+BA14+BA15+BA17+BA18+BA19+BA20+BA21+BA11 -> 22605.894 | BB25: =BB24+BB8+BB23+BB12+BB13+BB14+BB15+BB17+BB18+BB19+BB20+BB21+BB11 -> 22628.352 | BC25: =BC24+BC8+BC23+BC12+BC13+BC14+BC15+BC17+BC18+BC19+BC20+BC21+BC11 -> 22208.274 | BD25: =BD24+BD8+BD23+BD12+BD13+BD14+BD15+BD17+BD18+BD19+BD20+BD21+BD11 -> 24675.43 | ... BK25: =BK24+BK8+BK23+BK12+BK13+BK14+BK15+BK17+BK18+BK19+BK20+BK21+BK11 -> 28530.422 | BL25: =BL24+BL8+BL23+BL12+BL13+BL14+BL15+BL17+BL18+BL19+BL20+BL21+BL11+BL16+BL22 -> 27397.308 | BM25: =BM24+BM8+BM23+BM12+BM13+BM14+BM15+BM17+BM18+BM19+BM20+BM21+BM11+BM16+BM22 -> 26175.07 | BN25: =BN24+BN8+BN23+BN12+BN13+BN14+BN15+BN17+BN18+BN19+BN20+BN21+BN11+BN16+BN22 -> 26250.559 | BO25: =BO24+BO8+BO23+BO12+BO13+BO14+BO15+BO17+BO18+BO19+BO20+BO21+BO11+BO16+BO22 -> 25790.15 | BP25: =BP24+BP8+BP23+BP12+BP13+BP14+BP15+BP17+BP18+BP19+BP20+BP21+BP11+BP16+BP22 -> 25069.94 | BQ25: =BQ24+BQ8+BQ23+BQ12+BQ13+BQ14+BQ15+BQ17+BQ18+BQ19+BQ20+BQ21+BQ11+BQ16+BQ22 -> 26942.283 | BR25: =BR24+BR8+BR23+BR12+BR13+BR14+BR15+BR17+BR18+BR19+BR20+BR21+BR11+BR16+BR22 -> 23930.43 | BS25: =BS24+BS8+BS23+BS12+BS13+BS14+BS15+BS17+BS18+BS19+BS20+BS21+BS11+BS16+BS22 -> 25013.821 | ... BW25: =BW24+BW8+BW23+BW12+BW13+BW14+BW15+BW17+BW18+BW19+BW20+BW21+BW11+BW16+BW22 -> 20913.58
B26: Cash & Equivalents | C26: 17195 | D26: 39838 | E26: 83796 | F26: 154568 | G26: 138422 | H26: 111547 | I26: 103733 | J26: 96877 | K26: 120593 | L26: 123793 | M26: 100117 | N26: 102809 | O26: 127222.85 | P26: 131321.27 | Q26: 184726.07 | R26: 312410.7 | S26: 290610 | T26: 287434 | U26: 215313.87 | V26: 104704 | W26: 140713 | X26: 90187 | Y26: 139629 | Z26: 91451.101 | AA26: 92208 | AB26: 106002.17 | AC26: 82596.571 | AD26: 123235.19 | AE26: 128434 | AF26: 172029 | AG26: 103420.17 | AH26: 164342 | AI26: 103147 | AJ26: 63902.835 | AK26: 54165.906 | AL26: 81257 | AM26: 99047 | AN26: 118852 | AO26: 134021 | AP26: ='Model '!BY$128 -> 153836 | AQ26: ='Model '!BZ$128 -> 307218 | AS26: =M26/$AS$2 -> 1381.1146 | AT26: =N26/$AT$2 -> 1473.5416 | AU26: =O26/AU$2 -> 1839.5438 | AV26: =P26/AV$2 -> 1902.6553 | AW26: =Q26/AW$2 -> 2573.862 | AX26: =R26/AX$2 -> 4408.3776 | AY26: =S26/AY$2 -> 3858.1073 | AZ26: =T26/AZ$2 -> 3806.6342 | BA26: =U26/BA$2 -> 2918.9679 | BB26: =V26/BB$2 -> 1434.1049 | ... BW26: =AQ26/BW$2 -> 3286.2812
B27: Net debt | C27: =C25-C26 -> 599512 | D27: =D25-D26 -> 650394 | E27: =E25-E26 -> 583567 | F27: =F25-F26 -> 605416 | G27: =G25-G26 -> 668417 | H27: =H25-H26 -> 892979 | I27: =I25-I26 -> 970548 | J27: =J25-J26 -> 965528.61 | ... AQ27: =AQ25-AQ26 -> 1647888 | AS27: =AS25-AS26 -> 16338.073 | AT27: =AT25-AT26 -> 15951.954 | AU27: =AU25-AU26 -> 16337.467 | AV27: =AV25-AV26 -> 16900.29 | AW27: =AW25-AW26 -> 15707.249 | AX27: =AX25-AX26 -> 16216.086 | AY27: =AY25-AY26 -> 15779.598 | AZ27: =AZ25-AZ26 -> 17434.043 | ... BW27: =BW25-BW26 -> 17627.298
B28: Shareholders Equity | C28: 516231 | D28: 533808 | E28: 544102.68 | F28: 639662 | G28: 668088.74 | H28: 722674 | I28: 743313 | J28: 799768.57 | K28: 783483 | L28: 784887 | M28: 763996 | N28: 832059 | O28: 849480 | P28: 1040449 | Q28: 870149 | R28: 911205 | S28: 1021295 | T28: 858446 | U28: 842970 | V28: 778411 | W28: 812266 | X28: 820943 | Y28: 835516 | Z28: 887636 | AA28: 919350 | AB28: 946108 | AC28: 1005595 | AD28: 1021997.9 | AE28: 1064443 | AF28: 1030533 | AG28: 1034092 | AH28: 1035469 | AI28: 1055639 | AJ28: 1120335 | AK28: 1103030 | AL28: 1514323 | AM28: 1534677 | AN28: 1607482 | AO28: 1603540 | AP28: ='Model '!BY$133 -> 1690131 | AQ28: ='Model '!BZ$133 -> 1959634 | AS28: =M28/$AS$2 -> 10539.33 | AT28: =N28/$AT$2 -> 11925.742 | AU28: =O28/AU$2 -> 12282.822 | AV28: =P28/AV$2 -> 15074.602 | AW28: =Q28/AW$2 -> 12124.133 | AX28: =R28/AX$2 -> 12857.869 | AY28: =S28/AY$2 -> 13558.603 | AZ28: =T28/AZ$2 -> 11368.836 | BA28: =U28/BA$2 -> 11427.979 | BB28: =V28/BB$2 -> 10661.704 | ... BW28: =AQ28/BW$2 -> 20962.015
B29: Total capitalisation | C29: =C27+C28 -> 1115743 | D29: =D27+D28 -> 1184202 | E29: =E27+E28 -> 1127669.7 | F29: =F27+F28 -> 1245078 | G29: =G27+G28 -> 1336505.7 | H29: =H27+H28 -> 1615653 | I29: =I27+I28 -> 1713861 | J29: =J27+J28 -> 1765297.2 | ... AQ29: =AQ27+AQ28 -> 3607522 | AS29: =AS27+AS28 -> 26877.403 | AT29: =AT27+AT28 -> 27877.696 | AU29: =AU27+AU28 -> 28620.29 | AV29: =AV27+AV28 -> 31974.892 | AW29: =AW27+AW28 -> 27831.382 | AX29: =AX27+AX28 -> 29073.955 | AY29: =AY27+AY28 -> 29338.201 | AZ29: =AZ27+AZ28 -> 28802.879 | ... BW29: =BW27+BW28 -> 38589.314
B30: LTM EBITDA | C30: 200718 | D30: 222533 | E30: 233340 | F30: 278430 | G30: 314517 | H30: 341682 | I30: 356208 | J30: 314066.81 | K30: 304479 | L30: 294618.39 | M30: 278014.62 | N30: 265212.62 | O30: 262937 | P30: 339705.61 | Q30: 357450.12 | R30: 374003.89 | S30: 371053 | T30: 425568 | U30: 473932 | V30: 487108 | W30: 461387 | X30: 527576 | Y30: 560708 | Z30: 535853 | AA30: 581103 | AB30: 664176 | AC30: 708848 | AD30: 689248 | AE30: 717330 | AF30: 748747 | AG30: 768185 | AH30: 782620.64 | AI30: 790458 | AJ30: 792439 | AK30: 815999 | AL30: 864356.36 | AM30: 942490 | AN30: 1024716 | AO30: 1103696 | AP30: ='Model '!BY$100 -> 1166337 | AQ30: ='Model '!BZ$100 -> 1212676
B31: Debt Check | C31: 0 | D31: 0 | E31: 0 | F31: 0 | G31: 0 | H31: 0 | I31: 0 | J31: 0 | K31: 0 | L31: 0 | M31: 0 | N31: 0 | O31: 0 | P31: 0 | Q31: 0 | R31: 0 | S31: 0 | T31: 0 | U31: 0 | V31: 0 | W31: 0 | X31: 0 | Y31: 0 | Z31: 0 | AA31: 0 | AB31: 0 | AC31: 0 | AD31: 0 | AE31: 0 | AF31: 0 | AG31: 0 | AH31: 0 | AI31: 0 | AJ31: 0 | AK31: 0 | AL31: 0 | AM31: 0 | AN31: 0 | AO31: 0 | AP31: =AP25-'Model '!BY$124 -> 0
B33: Secured Net Leverage | C33: =(C8-C26)/C30 -> -0.085667454 | D33: =(D8-D26)/D30 -> -0.17902064 | E33: =(E8-E26)/E30 -> -0.35911545 | F33: =(F8-F26)/F30 -> -0.55514133 | G33: =(G8-G26)/G30 -> -0.44010976 | H33: =(H8-H26)/H30 -> -0.028386043 | I33: =(I8-I26)/I30 -> -0.098672686 | J33: =(J8-J26)/J30 -> -0.11605618 | ... AQ33: =(AQ8-AQ26)/AQ30 -> 0.35729247
B34: Gross Leverage ( Total debt/ EBITDA) | C34: =C25/C30 -> 3.0725047 | D34: =D25/D30 -> 3.1017063 | E34: =E25/E30 -> 2.8600454 | F34: =F25/F30 -> 2.7295335 | G34: =G25/G30 -> 2.5653272 | H34: =H25/H30 -> 2.9399442 | I34: =I25/I30 -> 3.0158812 | J34: =J25/J30 -> 3.3827376 | ... AQ34: =AQ25/AQ30 -> 1.6122245
B35: Net Leverage ( Net debt/ EBITDA) | C35: =C27/C30 -> 2.9868373 | D35: =D27/D30 -> 2.9226856 | E35: =E27/E30 -> 2.50093 | F35: =F27/F30 -> 2.1743921 | G35: =G27/G30 -> 2.1252174 | H35: =H27/H30 -> 2.6134798 | I35: =I27/I30 -> 2.7246665 | J35: =J27/J30 -> 3.0742777 | ... AQ35: =AQ27/AQ30 -> 1.3588856
B38: Market Cap | C38: 1357238 | D38: 1283186 | E38: 1107929.4 | F38: 1320141.4 | G38: 1572177.4 | H38: 1402288 | I38: 1399289.9 | J38: 2117222.9 | K38: 1593763.4 | L38: 1429670.1 | M38: 1353319.8 | N38: 1224803 | O38: 1331533.9 | P38: 1778657.7 | Q38: 1467245.7 | R38: 2339165.6 | S38: 3184000 | T38: 3054294 | U38: 2296513.8 | V38: 3267610 | W38: 2841025.7 | X38: 2867946.4 | Y38: 3780162.2 | Z38: 4021230 | AA38: 4303000 | AB38: 4050000 | AC38: 4820000 | AD38: 4536000 | AE38: 4320000 | AF38: 5062740 | AG38: 5420642.3 | AH38: 6560410 | AI38: 7273000 | AJ38: 8757000 | AK38: 9798000 | AL38: 10033000 | AM38: 10980575 | AN38: 11567616 | AO38: 11989648 | AP38: ='Model '!BY$132 -> 12178531 | AQ38: ='Model '!BZ$132 -> 11417638
B39: EV | C39: =C38+C27 -> 1956750 | D39: =D38+D27 -> 1933580 | E39: =E38+E27 -> 1691496.4 | F39: =F38+F27 -> 1925557.4 | G39: =G38+G27 -> 2240594.4 | H39: =H38+H27 -> 2295267 | I39: =I38+I27 -> 2369837.9 | J39: =J38+J27 -> 3082751.5 | ... AQ39: =AQ38+AQ27 -> 13065526
B41: EV/EBITDA | C41: =C39/C30 -> 9.748752 | D41: =D39/D30 -> 8.6889585 | E41: =E39/E30 -> 7.2490632 | F41: =F39/F30 -> 6.9157684 | G41: =G39/G30 -> 7.1239214 | H41: =H39/H30 -> 6.7175532 | I41: =I39/I30 -> 6.6529609 | J41: =J39/J30 -> 9.8155915 | ... AQ41: =AQ39/AQ30 -> 10.774127
I43: Liquidity Table as of end-3Q24 | J43: INR mn | K43: USD mn | M43: Debt maturity profile | N43: INR mn | O43: USD mn
M44: 2024 | N44: =O44*BL$2 -> 279547.22 | O44: 3404.96
I45: Cash | J45: =AH26 -> 164342 | K45: =BN26 -> 1974.3627 | M45: 2025 | N45: =O45*BL$2 -> 130774.63 | O45: 1592.87
I46: Available RCF | M46: 2030 | N46: =O46*BL$2 -> 15927.4 | O46: 194
I47: Total liquidity | J47: =SUM(J45:J46) -> 164342 | K47: =SUM(K45:K46) -> 1974.3627 | M47: 2031 | N47: =O47*BL$2 -> 209948.58 | O47: 2557.23
...

Sheet Model 
B2: Bharti Airtel | D2: Annual | E2: Annual | F2: Annual | G2: Annual | H2: Annual | I2: Annual | J2: Annual | K2: Annual | L2: Annual | M2: Annual | N2: Annual | O2: Annual | P2: Annual | Q2: Annual | R2: Annual | S2: Annual | T2: Annual | U2: LTM | W2: Quarter | X2: Quarter | Y2: Quarter | Z2: Quarter | AA2: Quarter | AB2: Quarter | AC2: Quarter | AD2: Quarter | AE2: Quarter | AF2: Quarter | AG2: Quarter | AH2: Quarter | AI2: Quarter | AJ2: Quarter | AK2: Quarter | AL2: Quarter | AM2: Quarter | AN2: Quarter | AO2: Quarter | AP2: Quarter | AQ2: Quarter | AR2: Quarter | AS2: Quarter | AT2: Quarter | AU2: Quarter | AV2: Quarter | AW2: Quarter | AX2: Quarter | AY2: Quarter | AZ2: Quarter | BA2: Quarter | BB2: Quarter | BC2: Quarter | BD2: Quarter | BE2: Quarter | BF2: Quarter | BG2: Quarter | BH2: Quarter | BI2: Quarter | BJ2: Quarter | BK2: Quarter | BL2: Quarter | BM2: Quarter | BN2: Quarter | BO2: Quarter | BP2: Quarter | BQ2: Quarter | BR2: Quarter | BS2: Quarter | BT2: Quarter | BU2: Quarter | BV2: Quarter | BW2: Quarter | BX2: Quarter | BY2: Quarter | BZ2: Quarter | CB2: Quarter | CC2: Quarter | CD2: Quarter | CE2: Quarter | CF2: Quarter | CH2: Annual
B3: (INR millions) | D3: 40612 | E3: 40979 | F3: 41346 | G3: 41713 | H3: 42080 | I3: 42460 | J3: 42825 | K3: 43190 | L3: 43190 | M3: 43555 | N3: 43921 | O3: 44286 | P3: 44651 | Q3: 45016 | R3: 45382 | S3: 45747 | T3: 46112 | U3: =BZ3 -> 46112 | W3: 41068 | X3: 41161 | Y3: 41253 | Z3: 41343 | AA3: 41433 | AB3: 41526 | AC3: 41618 | AD3: 41708 | AE3: 41798 | AF3: 41891 | AG3: 41983 | AH3: 42073 | AI3: 42163 | AJ3: 42256 | AK3: 42348 | AL3: 42439 | AM3: 42529 | AN3: 42622 | AO3: 42714 | AP3: 42804 | AQ3: 42916 | AR3: 43008 | AS3: 43100 | AT3: 43190 | AU3: 43281 | AV3: 43373 | AW3: 43465 | AX3: 43555 | AY3: 43646 | AZ3: 43738 | BA3: 43830 | BB3: 43921 | BC3: 44012 | BD3: 44104 | BE3: 44196 | BF3: 44286 | BG3: 44377 | BH3: 44469 | BI3: 44561 | BJ3: 44651 | BK3: 44742 | BL3: 44834 | BM3: 44926 | BN3: 45016 | BO3: 45107 | BP3: 45199 | BQ3: 45290 | BR3: 45382 | BS3: 45473 | BT3: 45565 | BU3: 45656 | BV3: 45747 | BW3: 45838 | BX3: 45930 | BY3: 46021 | BZ3: 46112 | CB3: 43646 | CC3: 43830 | CD3: 43921 | CE3: 44012 | CF3: 44104 | CH3: 43921
D4: Act | E4: Act | F4: Act | G4: Act | H4: Act | I4: Act | J4: Act | K4: Act | L4: Act | M4: Act | N4: Act | O4: Act | P4: Act | Q4: Act | R4: Act | S4: Act | T4: Act | U4: Act | W4: Act | X4: Act | Y4: Act | Z4: Act | AA4: Act | AB4: Act | AC4: Act | AD4: Act | AE4: Act | AF4: Act | AG4: Act | AH4: Act | AI4: Act | AJ4: Act | AK4: Act | AL4: Act | AM4: Act | AN4: Act | AO4: Act | AP4: Act | AQ4: Act | AR4: Act | AS4: Act | AT4: Act | AU4: Act | AV4: Act | AW4: Act | AX4: Act | AY4: Act | AZ4: Act | BA4: Act | BB4: Act | BC4: Act | BD4: Act | BE4: Act | BF4: Act | BG4: Act | BH4: Act | BI4: Act | BJ4: Act | BK4: Act | BL4: Act | BM4: Act | BN4: Act | BO4: Act | BP4: Act | BQ4: Act | BR4: Act | BS4: Act | BT4: Act | BU4: Act | BV4: Act | BW4: Act | BX4: Act | BY4: Act | BZ4: Act | CB4: Act | CC4: Act | CD4: Act | CE4: Act | CF4: Act | CH4: Act
D5: FY 11 | E5: FY 12 | F5: FY 13 | G5: FY 14 | H5: FY 15 | I5: FY 16 | J5: FY 17 | K5: FY 18 | L5: FY 18 | M5: FY 19 | N5: FY 20 | O5: FY 21 | P5: FY 22 | Q5: FY 23 | R5: FY 24 | S5: FY 25 | T5: FY 26 | U5: LTM | W5: 1Q | X5: 2Q | Y5: 3Q | Z5: 4Q | AA5: 1Q | AB5: 2Q | AC5: 3Q | AD5: 4Q | AE5: 1Q | AF5: 2Q | AG5: 3Q | AH5: 4Q | AI5: 1Q | AJ5: 2Q | AK5: 3Q | AL5: 4Q | AM5: 1Q | AN5: 2Q | AO5: 3Q | AP5: 4Q | AQ5: 1Q | AR5: 2Q | AS5: 3Q | AT5: 4Q | AU5: 1Q | AV5: 2Q | AW5: 3Q | AX5: 4Q | AY5: 1Q | AZ5: 2Q | BA5: 3Q | BB5: 4Q | BC5: 1Q | BD5: 2Q | BE5: 3Q | BF5: 4Q | BG5: 1Q | BH5: 2Q | BI5: 3Q | BJ5: 4Q | BK5: 1Q | BL5: 2Q | BM5: 3Q | BN5: 4Q | BO5: 1Q | BP5: 2Q | BQ5: 3Q | BR5: 4Q | BS5: 1Q | BT5: 2Q | BU5: 3Q | BV5: 4Q | BW5: 1Q | BX5: 2Q | BY5: 3Q | BZ5: 4Q | CB5: Q1 20 | CC5: Q3 20 | CD5: Q4 20 | CE5: Q1 21 | CF5: Q2 21 | CH5: FY 20
B6: INCOME STATEMENT | L6: Restated | AU6: Restated | AV6: Restated | AW6: Restated | CB6: Restated | CC6: Restated | CD6: Restated | CE6: Restated | CF6: Restated | CH6: Restated
B7: Revenue from operations | D7: 595383 | E7: 683267 | F7: 769044.92 | G7: 857460.94 | H7: 920394 | I7: 965321 | J7: 954683 | K7: 836879 | L7: 826388 | M7: 807802 | N7: 875390 | O7: 1006158 | P7: 1165469 | Q7: 1391448 | R7: 1499824 | S7: 1729852 | T7: 2109728 | U7: =SUM(BW7:BZ7) -> 2109728 | W7: 185601 | X7: 193998.74 | Y7: 193624.42 | Z7: =F7-SUM(W7:Y7) -> 195820.75 | AA7: 202639.24 | AB7: 213243.7 | AC7: 219385 | AD7: =G7-SUM(AA7:AC7) -> 222193 | AE7: 229616 | AF7: 228452 | AG7: 232171 | AH7: =H7-SUM(AE7:AG7) -> 230155 | AI7: 236709 | AJ7: 238357 | AK7: 240659 | AL7: =I7-SUM(AI7:AK7) -> 249596 | AM7: 255465 | AN7: 246515 | AO7: 233357 | AP7: =J7-SUM(AM7:AO7) -> 219346 | AQ7: 219581 | AR7: 217769 | AS7: 203186 | AT7: =+K7-AS7-AR7-AQ7 -> 196343 | AU7: 197992.29 | AV7: 201477.59 | AW7: 202310.66 | AX7: =M7-AW7-AV7-AU7 -> 206021.47 | AY7: 207379 | AZ7: 211313 | BA7: 219471 | BB7: =N7-BA7-AZ7-AY7 -> 237227 | BC7: 239387 | BD7: 257850 | BE7: 265178 | BF7: =O7-BE7-BD7-BC7 -> 243743 | BG7: 268536 | BH7: 283264 | BI7: 298666 | BJ7: =P7-BI7-BH7-BG7 -> 315003 | BK7: 328046 | BL7: 345268 | BM7: 358044 | BN7: =Q7-BM7-BL7-BK7 -> 360090 | BO7: 374400 | BP7: 370438 | BQ7: 378995 | BR7: =R7-BQ7-BP7-BO7 -> 375991 | BS7: 385064 | BT7: 414733 | BU7: 451293 | BV7: =S7-BU7-BT7-BS7 -> 478762 | BW7: 494626 | BX7: 521454 | BY7: 539816 | BZ7: =T7-SUM(BW7:BY7) -> 553832 | CB7: 207379 | CC7: 213436 | CD7: 230187 | CE7: 232903 | CF7: 250604 | CH7: 846765
B8: % growth | E8: =E7/D7-1 -> 0.14760919 | F8: =F7/E7-1 -> 0.12554084 | G8: =G7/F7-1 -> 0.11496861 | H8: =H7/G7-1 -> 0.073394669 | I8: =I7/H7-1 -> 0.048812791 | J8: =J7/I7-1 -> -0.011020168 | K8: =K7/J7-1 -> -0.12339593 | L8: =L7/J7-1 -> -0.13438492 | M8: =M7/L7-1 -> -0.022490646 | N8: =N7/M7-1 -> 0.083669018 | O8: =O7/N7-1 -> 0.14938256 | P8: =P7/O7-1 -> 0.15833597 | Q8: =Q7/P7-1 -> 0.19389533 | R8: =R7/Q7-1 -> 0.077887208 | S8: =S7/R7-1 -> 0.15337 | T8: =T7/S7-1 -> 0.21960029 | AE8: =AE7/AA7-1 -> 0.13312703 | AF8: =AF7/AB7-1 -> 0.071318882 | AG8: =AG7/AC7-1 -> 0.058281104 | AH8: =AH7/AD7-1 -> 0.035833712 | AI8: =AI7/AE7-1 -> 0.030890704 | AJ8: =AJ7/AF7-1 -> 0.043357029 | AK8: =AK7/AG7-1 -> 0.03655926 | AL8: =AL7/AH7-1 -> 0.084469162 | ... BB8: =BB7/AX7-1 -> 0.15146738 | BC8: =BC7/CB7-1 -> 0.15434543 | BD8: =BD7/AZ7-1 -> 0.22022781 | BE8: =BE7/BA7-1 -> 0.20825986 | BF8: =BF7/BB7-1 -> 0.027467362 | BG8: =BG7/CE7-1 -> 0.15299502 | BH8: =BH7/CF7-1 -> 0.13032513 | BI8: =BI7/BE7-1 -> 0.12628499 | BJ8: =BJ7/BF7-1 -> 0.29235711 | BK8: =BK7/BG7-1 -> 0.22160902 | BL8: =BL7/BH7-1 -> 0.21889121 | BM8: =BM7/BI7-1 -> 0.19881071 | BN8: =BN7/BJ7-1 -> 0.14313197 | BO8: =BO7/BK7-1 -> 0.14130335 | BP8: =BP7/BL7-1 -> 0.072899892 | ... BZ8: =BZ7/BV7-1 -> 0.15680025 | CB8: =CB7/AU7-1 -> 0.047409481 | CC8: =CC7/AY7-1 -> 0.029207393 | CD8: =CD7/AX7-1 -> 0.11729619 | CE8: =CE7/AW7-1 -> 0.15121469 | CF8: =CF7/AV7-1 -> 0.24383066 | CH8: =CH7/M7-1 -> 0.048233354
B9: Other income | D9: 635 | E9: 550 | F9: 425 | G9: 1174 | H9: 957 | I9: 871 | J9: 1206 | K9: 2488 | L9: 2488 | M9: 2912 | N9: 3248 | O9: 6428 | P9: 5343 | Q9: 9366 | R9: 14354 | S9: 15737 | T9: 28173 | U9: =SUM(BW9:BZ9) -> 28173 | W9: 102 | X9: 86 | Y9: 134 | Z9: =F9-SUM(W9:Y9) -> 103 | AA9: 356 | AB9: 184 | AC9: 222 | AD9: =G9-SUM(AA9:AC9) -> 412 | AE9: 439 | AF9: 165 | AG9: 110 | AH9: =H9-SUM(AE9:AG9) -> 243 | AI9: 99 | AJ9: 162 | AK9: 375 | AL9: =I9-SUM(AI9:AK9) -> 235 | AM9: 264 | AN9: 200 | AO9: 282 | AP9: 460 | AQ9: 486 | AR9: 553 | AS9: 696 | AT9: =+K9-AS9-AR9-AQ9 -> 753 | AU9: 997 | AV9: 813 | AW9: 675 | AX9: =M9-AW9-AV9-AU9 -> 427 | AY9: 746 | AZ9: 677 | BA9: 745 | BB9: =N9-BA9-AZ9-AY9 -> 1080 | BC9: =4805-4063 -> 742 | BD9: =1489-346 -> 1143 | BE9: =492-556 -> -64 | BF9: =O9-BE9-BD9-BC9 -> 4607 | BG9: =2098-1438 -> 660 | BH9: =1088-804 -> 284 | BI9: =1971-79 -> 1892 | BJ9: =P9-BI9-BH9-BG9 -> 2507 | BK9: 1922 | BL9: =2019 -> 2019 | BM9: 2576 | BN9: =Q9-BM9-BL9-BK9 -> 2849 | BO9: 3483 | BP9: 3304 | BQ9: 4398 | BR9: =R9-BQ9-BP9-BO9 -> 3169 | BS9: 3635 | BT9: 2547 | BU9: 4697 | BV9: =S9-BU9-BT9-BS9 -> 4858 | BW9: =5088 -> 5088 | BX9: 7277 | BY9: 7023 | BZ9: =T9-SUM(BW9:BY9) -> 8785 | CB9: =2945-2113 -> 832 | CC9: =3067-2970 -> 97 | CD9: =8198-4314 -> 3884 | CE9: =4066-3372 -> 694 | CF9: =1031-54 -> 977 | CH9: 15357
B10: Total income from operations | D10: =D7+D9 -> 596018 | E10: =E7+E9 -> 683817 | F10: =F7+F9 -> 769469.92 | G10: =G7+G9 -> 858634.94 | H10: =H7+H9 -> 921351 | I10: =I7+I9 -> 966192 | J10: =J7+J9 -> 955889 | K10: =K7+K9 -> 839367 | ... U10: =U7+U9 -> 2137901 | W10: =W7+W9 -> 185703 | X10: =X7+X9 -> 194084.74 | Y10: =Y7+Y9 -> 193758.42 | Z10: =Z7+Z9 -> 195923.75 | AA10: =AA7+AA9 -> 202995.24 | AB10: =AB7+AB9 -> 213427.7 | AC10: =AC7+AC9 -> 219607 | AD10: =AD7+AD9 -> 222605 | ... BZ10: =BZ7+BZ9 -> 562617 | CB10: =CB7+CB9 -> 208211 | CC10: =CC7+CC9 -> 213533 | CD10: =CD7+CD9 -> 234071 | CE10: =CE7+CE9 -> 233597 | CF10: =CF7+CF9 -> 251581 | CH10: =CH7+CH9 -> 862122
B11: % growth | E11: =E10/D10-1 -> 0.14730931 | F11: =F10/E10-1 -> 0.12525707 | G11: =G10/F10-1 -> 0.1158785 | H11: =H10/G10-1 -> 0.073041591 | I11: =I10/H10-1 -> 0.048668748 | J11: =J10/I10-1 -> -0.010663512 | K11: =K10/J10-1 -> -0.12189909 | L11: =L10/J10-1 -> -0.13287421 | M11: =M10/L10-1 -> -0.021911601 | N11: =N10/M10-1 -> 0.083782937 | O11: =O10/N10-1 -> 0.15244959 | P11: =P10/O10-1 -> 0.15625932 | Q11: =Q10/P10-1 -> 0.19644657 | R11: =R10/Q10-1 -> 0.080927232 | S11: =S10/R10-1 -> 0.15282946 | T11: =T10/S10-1 -> 0.22474477 | AQ11: =AQ10/AM10-1 -> -0.13945231 | AR11: =AR10/AN10-1 -> -0.11508421 | AS11: =AS10/AO10-1 -> -0.12736315 | AT11: =AT10/AP10-1 -> -0.10331838 | AU11: =AU10/AQ10-1 -> -0.095778612 | AV11: =AV10/AR10-1 -> -0.073430129 | AW11: =AW10/AS10-1 -> -0.0043963819 | AX11: =AX10/AT10-1 -> 0.047451331 | ... BB11: =BB10/AX10-1 -> 0.15431712 | BC11: =BC10/CB10-1 -> 0.15329642 | BD11: =BD10/AZ10-1 -> 0.22172272 | BE11: =BE10/BA10-1 -> 0.20388164 | BF11: =BF10/BB10-1 -> 0.042143118 | BG11: =BG10/CE10-1 -> 0.15239494 | BH11: =BH10/CF10-1 -> 0.12706444 | BI11: =BI10/BE10-1 -> 0.13369343 | BJ11: =BJ10/BF10-1 -> 0.27847795 | BK11: =BK10/BG10-1 -> 0.22575373 | BL11: =BL10/BH10-1 -> 0.22479086 | BM11: =BM10/BI10-1 -> 0.19983497 | BN11: =BN10/BJ10-1 -> 0.14307896 | BO11: =BO10/BK10-1 -> 0.14521105 | BP11: =BP10/BL10-1 -> 0.076176189 | ... BZ11: =BZ10/BV10-1 -> 0.16334519 | CB11: =CB10/AU10-1 -> 0.046342754 | CC11: =CC10/AY10-1 -> 0.025984384 | CD11: =CD10/AX10-1 -> 0.13379868 | CE11: =CE10/AW10-1 -> 0.15080545 | CF11: =CF10/AV10-1 -> 0.24366142 | CH11: =CH10/M10-1 -> 0.063410771
B12: Expenses
B13: Network operating expenses | I13: 201567 | J13: 209154 | K13: 197520 | L13: 197520 | M13: 223900 | N13: 197685 | O13: 219819 | P13: 250205 | Q13: 285433 | R13: 300188 | S13: 335043 | T13: 397500 | U13: =SUM(BW13:BZ13) -> 397500 | AM13: 53957.992 | AN13: 50933.404 | AO13: 52634.744 | AP13: =J13-SUM(AM13:AO13) -> 51627.86 | AQ13: 51612 | AR13: 50472 | AS13: 47365 | AT13: =+K13-AS13-AR13-AQ13 -> 48071 | AU13: 50677 | AV13: 56289.452 | AW13: 57539 | AX13: =M13-AW13-AV13-AU13 -> 59394.548 | AY13: 45957 | AZ13: 49688.872 | BA13: 49344.621 | BB13: =N13-BA13-AZ13-AY13 -> 52694.507 | BC13: 51036 | BD13: 54564 | BE13: 55479 | BF13: =O13-BE13-BD13-BC13 -> 58740 | BG13: 57973 | BH13: 61788 | BI13: 64986 | BJ13: =P13-BI13-BH13-BG13 -> 65458 | BK13: 66828 | BL13: 71303 | BM13: 73284 | BN13: =Q13-BM13-BL13-BK13 -> 74018 | BO13: 74036 | BP13: 74240 | BQ13: 75926 | BR13: =R13-BQ13-BP13-BO13 -> 75986 | BS13: 77606 | BT13: 80115 | BU13: 86267 | BV13: =S13-BU13-BT13-BS13 -> 91055 | BW13: 95456 | BX13: 101178 | BY13: 98786 | BZ13: =T13-SUM(BW13:BY13) -> 102080 | CB13: 46636 | CC13: 49849 | CD13: 51510 | CE13: 50963 | CF13: 54198 | CH13: 196305
B14: Access Charges | I14: 109423 | J14: 102786 | K14: 90446 | L14: 90446 | M14: 93521 | N14: 107395 | O14: 103521 | P14: 67611 | Q14: 76207 | R14: 75185 | S14: 71713 | T14: 55416 | U14: =SUM(BW14:BZ14) -> 55416 | AM14: 27041.285 | AN14: 28597.715 | AO14: 24386 | AP14: =J14-SUM(AM14:AO14) -> 22761 | AQ14: 25016 | AR14: 25603 | AS14: 19539 | AT14: =+K14-AS14-AR14-AQ14 -> 20288 | AU14: 21355 | AV14: 23294 | AW14: 24462 | AX14: =M14-AW14-AV14-AU14 -> 24410 | AY14: 25627 | AZ14: 26389 | BA14: 27109 | BB14: =N14-BA14-AZ14-AY14 -> 28270 | BC14: 28011 | BD14: 29229 | BE14: 30632 | BF14: =O14-BE14-BD14-BC14 -> 15649 | BG14: 16166 | BH14: 16708 | BI14: 17232 | BJ14: =P14-BI14-BH14-BG14 -> 17505 | BK14: 18698 | BL14: 19310 | BM14: 19352 | BN14: =Q14-BM14-BL14-BK14 -> 18847 | BO14: 19972 | BP14: 18144 | BQ14: 18568 | BR14: =R14-BQ14-BP14-BO14 -> 18501 | BS14: 19084 | BT14: 18211 | BU14: 19636 | BV14: =S14-BU14-BT14-BS14 -> 14782 | BW14: 12571 | BX14: 13215 | BY14: 14691 | BZ14: =T14-SUM(BW14:BY14) -> 14939 | CB14: 25627 | CC14: 27109 | CD14: 28270 | CE14: 28011 | CF14: 29229 | CH14: 107395
B15: License fee / spectrum charges (revenue share) | I15: 94928 | J15: 92760 | K15: 75558 | L15: 75558 | M15: 69426 | N15: 72561 | O15: 91084 | P15: 110636 | Q15: 117517 | R15: 120358 | S15: 138290 | T15: 153729 | U15: =SUM(BW15:BZ15) -> 153729 | AM15: 25498.85 | AN15: 24143.15 | AO15: 22268 | AP15: =J15-SUM(AM15:AO15) -> 20850 | AQ15: 20820 | AR15: 19720 | AS15: 17542 | AT15: =+K15-AS15-AR15-AQ15 -> 17476 | AU15: 16972 | AV15: 17697 | AW15: 17469 | AX15: =M15-AW15-AV15-AU15 -> 17288 | AY15: 17930 | AZ15: 16764 | BA15: 17666 | BB15: =N15-BA15-AZ15-AY15 -> 20201 | BC15: 20768 | BD15: 22355 | BE15: 22952 | BF15: =O15-BE15-BD15-BC15 -> 25009 | BG15: 26455 | BH15: 26794 | BI15: 27298 | BJ15: =P15-BI15-BH15-BG15 -> 30089 | BK15: 31306 | BL15: 29511 | BM15: 28421 | BN15: =Q15-BM15-BL15-BK15 -> 28279 | BO15: 29403 | BP15: 29643 | BQ15: 30205 | BR15: =R15-BQ15-BP15-BO15 -> 31107 | BS15: 31564 | BT15: 34658 | BU15: 35698 | BV15: =S15-BU15-BT15-BS15 -> 36370 | BW15: 37200 | BX15: 38249 | BY15: 38462 | BZ15: =T15-SUM(BW15:BY15) -> 39818 | CB15: 18391 | CC15: 17875 | CD15: 20569 | CE15: 20766 | CF15: 22354 | CH15: 73826
B16: Employee benefits | I16: 49108 | J16: 43032 | K16: 39771 | L16: 39771 | M16: 37975 | N16: 38072 | O16: 41146 | P16: 44333 | Q16: 48308 | R16: 53231 | S16: 63089 | T16: 75813 | U16: =SUM(BW16:BZ16) -> 75813 | AM16: 11144.376 | AN16: 10857.624 | AO16: 10532 | AP16: =J16-SUM(AM16:AO16) -> 10498 | AQ16: 10147 | AR16: 10089 | AS16: 9586 | AU16: 9656 | AV16: 9360 | AW16: 9530 | AX16: =M16-AW16-AV16-AU16 -> 9429 | AY16: 8641 | AZ16: 9464 | BA16: 9651 | BB16: =N16-BA16-AZ16-AY16 -> 10316 | BC16: 11566 | BD16: 11008 | BE16: 10260 | BF16: =O16-BE16-BD16-BC16 -> 8312 | BG16: 10345 | BH16: 11010 | BI16: 11336 | BJ16: =P16-BI16-BH16-BG16 -> 11642 | BK16: 11235 | BL16: 12086 | BM16: 12353 | BN16: =Q16-BM16-BL16-BK16 -> 12634 | BO16: 12572 | BP16: 13790 | BQ16: 13230 | BR16: =R16-BQ16-BP16-BO16 -> 13639 | BS16: 13728 | BT16: 14966 | BU16: 16082 | BV16: =S16-BU16-BT16-BS16 -> 18313 | BW16: 17380 | BX16: 18571 | BY16: 19581 | BZ16: =T16-SUM(BW16:BY16) -> 20281 | CB16: 8641 | CC16: 8914 | CD16: 9520 | CE16: 10725 | CF16: 10172 | CH16: 35137
B17: Sales and marketing expenses | I17: 82410 | J17: 66732 | K17: 55766 | L17: 45275 | M17: 41277 | N17: 34325 | O17: 38009 | P17: 53035 | Q17: 72454 | R17: 81326 | S17: 114601 | T17: 131073 | U17: =SUM(BW17:BZ17) -> 131073 | AM17: 19904.247 | AN17: 18012.026 | AO17: 16549.928 | AP17: =J17-SUM(AM17:AO17) -> 12265.799 | AQ17: 15365 | AR17: 14104 | AS17: 15902 | AT17: =+K17-AS17-AR17-AQ17 -> 10395 | AU17: 10144.288 | AV17: 10207.507 | AW17: 10560.657 | AX17: =M17-AW17-AV17-AU17 -> 10364.548 | AY17: 8364 | AZ17: 7580.9178 | BA17: 9003 | BB17: =N17-BA17-AZ17-AY17 -> 9377.0822 | BC17: 7301 | BD17: 8744 | BE17: 10524 | BF17: =O17-BE17-BD17-BC17 -> 11440 | BG17: 10613 | BH17: 12670 | BI17: 14425 | BJ17: =P17-BI17-BH17-BG17 -> 15327 | BK17: 15669 | BL17: 17823 | BM17: 19118 | BN17: =Q17-BM17-BL17-BK17 -> 19844 | BO17: 20596 | BP17: 19590 | BQ17: 20473 | BR17: =R17-BQ17-BP17-BO17 -> 20667 | BS17: 27157 | BT17: 28824 | BU17: 29261 | BV17: =S17-BU17-BT17-BS17 -> 29359 | BW17: 29659 | BX17: 31824 | BY17: 34269 | BZ17: =T17-SUM(BW17:BY17) -> 35321 | CB17: 8386 | CC17: 8979 | CD17: 9335 | CE17: 7278 | CF17: 8722 | CH17: 34236
B18: Other expenses | I18: 88043 | J18: 86921 | K18: 77027 | L18: 77027 | M18: 83514 | N18: 59257 | O18: 58862 | P18: 64310 | Q18: 78794 | R18: 86618 | S18: 75524 | T18: 99452 | U18: =SUM(BW18:BZ18) -> 99452 | AM18: 22438.19 | AN18: 19568.142 | AO18: 22171.328 | AP18: =J18-SUM(AM18:AO18) -> 22743.341 | AQ18: 19036.82 | AR18: 18561 | AS18: 18564 | AT18: =+K18-AS18-AR18-AQ18 -> 20865.18 | AU18: 21929.751 | AV18: 22314.036 | AW18: 20570.176 | AX18: =M18-AW18-AV18-AU18 -> 18700.037 | AY18: 17972 | AZ18: 12823.362 | BA18: 14028 | BB18: =N18-BA18-AZ18-AY18 -> 14433.638 | BC18: 16626 | BD18: 15530 | BE18: 14801 | BF18: =O18-BE18-BD18-BC18 -> 11905 | BG18: 17181 | BH18: 16189 | BI18: 16361 | BJ18: =P18-BI18-BH18-BG18 -> 14579 | BK18: 19016 | BL18: 19297 | BM18: 20984 | BN18: =Q18-BM18-BL18-BK18 -> 19497 | BO18: 21836 | BP18: 19894 | BQ18: 22445 | BR18: =R18-BQ18-BP18-BO18 -> 22443 | BS18: 18849 | BT18: 19497 | BU18: 18383 | BV18: =S18-BU18-BT18-BS18 -> 18795 | BW18: 23973 | BX18: 22803 | BY18: 26199 | BZ18: =T18-SUM(BW18:BY18) -> 26477 | CB18: 17357 | CC18: 13546 | CD18: 14808 | CE18: 15989 | CF18: 15232 | CH18: 57332
B19: Profit from operating activities before D&A and exceptional items | D19: 200718 | E19: =103442+133681 -> 237123 | F19: =84431+148147 -> 232578 | G19: =121934+156496 -> 278430 | H19: 313883 | I19: =I10-SUM(I13:I18) -> 340713 | J19: =J10-SUM(J13:J18) -> 354504 | K19: =K10-SUM(K13:K18) -> 303279 | L19: =L10-SUM(L13:L18) -> 303279 | M19: =M10-SUM(M13:M18) -> 261101 | N19: =N10-SUM(N13:N18) -> 369343 | O19: =O10-SUM(O13:O18) -> 460145 | P19: =P10-SUM(P13:P18) -> 580682 | ... U19: =U10-SUM(U13:U18) -> 1224918 | W19: =18955+35901 -> 54856 | X19: =22478+36891 -> 59369 | Y19: =20399+37350 -> 57749 | Z19: =F19-SUM(W19:Y19) -> 60604 | AA19: =26979+38470 -> 65449 | AB19: =29335+39394 -> 68729 | AC19: =31818+39188 -> 71006 | AD19: =G19-SUM(AA19:AC19) -> 73246 | AE19: =36913+40365 -> 77278 | AF19: =38523+38530 -> 77053 | AG19: =39842+38015 -> 77857 | AH19: =H19-SUM(AE19:AG19) -> 81695 | AI19: =42158+40404 -> 82562 | AJ19: =40112+42390 -> 82502 | AK19: =40971+43541 -> 84512 | AL19: =I19-SUM(AI19:AK19) -> 91137 | AM19: =AM10-SUM(AM13:AM18) -> 95744.06 | AN19: =AN10-SUM(AN13:AN18) -> 94602.94 | AO19: =AO10-SUM(AO13:AO18) -> 85097 | AP19: =AP10-SUM(AP13:AP18) -> 79060 | AQ19: =AQ10-SUM(AQ13:AQ18) -> 78070.18 | AR19: =AR10-SUM(AR13:AR18) -> 79773 | AS19: =AS10-SUM(AS13:AS18) -> 75384 | AT19: =AT10-SUM(AT13:AT18) -> 80000.82 | ... BZ19: =BZ10-SUM(BZ13:BZ18) -> 323701 | CB19: =CB10-SUM(CB13:CB18) -> 83173 | CC19: =CC10-SUM(CC13:CC18) -> 87261 | CD19: =CD10-SUM(CD13:CD18) -> 100059 | CE19: =CE10-SUM(CE13:CE18) -> 99865 | CF19: =CF10-SUM(CF13:CF18) -> 111674 | CH19: =CH10-SUM(CH13:CH18) -> 357891
B20: % margin | D20: =D19/D10 -> 0.336765 | E20: =E19/E10 -> 0.34676383 | F20: =F19/F10 -> 0.30225743 | G20: =G19/G10 -> 0.32427052 | H20: =H19/H10 -> 0.3406769 | I20: =I19/I10 -> 0.35263488 | J20: =J19/J10 -> 0.37086314 | K20: =K19/K10 -> 0.36131871 | ... U20: =U19/U10 -> 0.57295357 | W20: =W19/W10 -> 0.29539641 | X20: =X19/X10 -> 0.30589215 | Y20: =Y19/Y10 -> 0.2980464 | Z20: =Z19/Z10 -> 0.30932442 | AA20: =AA19/AA10 -> 0.32241643 | AB20: =AB19/AB10 -> 0.32202475 | AC20: =AC19/AC10 -> 0.32333213 | AD20: =AD19/AD10 -> 0.32904023 | ... BZ20: =BZ19/BZ10 -> 0.57534877 | CB20: =CB19/CB10 -> 0.39946497 | CC20: =CC19/CC10 -> 0.40865346 | CD20: =CD19/CD10 -> 0.42747286 | CE20: =CE19/CE10 -> 0.42750977 | CF20: =CF19/CF10 -> 0.44388885 | CH20: =CH19/CH10 -> 0.41512802
B21: Share of results of joint ventures and associates | D21: 57 | E21: 74 | F21: -3506 | G21: -5211 | H21: -7223 | I21: -10666 | J21: -10449 | K21: -10609 | L21: -10609 | M21: -3556 | N21: -6524 | O21: 928 | P21: -24232 | Q21: -7521 | R21: -27094 | S21: -37030 | T21: -3645 | U21: =SUM(BW21:BZ21) -> -3645 | W21: -706 | X21: -982 | Y21: -943 | Z21: =F21-SUM(W21:Y21) -> -875 | AA21: -822 | AB21: -1652 | AC21: -1064 | AD21: =G21-SUM(AA21:AC21) -> -1673 | AE21: -1578 | AF21: -1709 | AG21: -1800 | AH21: =H21-SUM(AE21:AG21) -> -2136 | AI21: -2126 | AJ21: -2404 | AK21: -2463 | AL21: =I21-SUM(AI21:AK21) -> -3673 | AM21: -2548 | AN21: -2697 | AO21: -2696 | AP21: =J21-SUM(AM21:AO21) -> -2508 | AQ21: -2855 | AR21: -3662 | AS21: -2256 | AT21: =+K21-AS21-AR21-AQ21 -> -1836 | AU21: -1653 | AV21: -1633 | AW21: 98 | AX21: =M21-AW21-AV21-AU21 -> -368 | AY21: -931 | AZ21: -3155 | BA21: -1523 | BB21: =N21-BA21-AZ21-AY21 -> -915 | BC21: -1666 | BD21: 423 | BE21: 2206 | BF21: =O21-BE21-BD21-BC21 -> -35 | BG21: -4947 | BH21: -5988 | BI21: -6161 | BJ21: =P21-BI21-BH21-BG21 -> -7136 | BK21: -1628 | BL21: -3567 | BM21: 3684 | BN21: =Q21-BM21-BL21-BK21 -> -6010 | BO21: -5899 | BP21: -5860 | BQ21: -7032 | BR21: =R21-BQ21-BP21-BO21 -> -8303 | BS21: -9117 | BT21: -10739 | BU21: -16597 | BV21: =S21-BU21-BT21-BS21 -> -577 | BW21: -828 | BX21: -810 | BY21: -1163 | BZ21: =T21-SUM(BW21:BY21) -> -844 | CB21: -931 | CC21: 2015 | CD21: 1243 | CE21: 1070 | CF21: 2926 | CH21: 6627
B22: Depreciation and amortisation | D22: =D65+D66 -> 102066 | E22: =E65+E66 -> 133681 | F22: =F65+F66 -> 148148 | G22: =G65+G66 -> 156496 | H22: =H65+H66 -> 155311 | I22: =I65+I66 -> 174498 | J22: =J65+J66 -> 197730 | K22: =K65+K66 -> 192431 | L22: 192431 | M22: 213475 | N22: 276896 | O22: 294044 | P22: 330907 | Q22: 364318 | R22: 395376 | S22: 455703 | T22: 527108 | U22: =SUM(BW22:BZ22) -> 527108 | W22: 35901 | X22: 36891 | Y22: 37350 | Z22: =F22-SUM(W22:Y22) -> 38006 | AA22: 38470 | AB22: 39394 | AC22: 39188 | AD22: =G22-SUM(AA22:AC22) -> 39444 | AE22: 40365 | AF22: 38530 | AG22: 38015 | AH22: =H22-SUM(AE22:AG22) -> 38401 | AI22: 40404 | AJ22: 42390 | AK22: 43541 | AL22: =I22-SUM(AI22:AK22) -> 48163 | AM22: 50402 | AN22: 49560 | AO22: 48350 | AP22: =J22-SUM(AM22:AO22) -> 49418 | AQ22: 48192 | AR22: 46873 | AS22: 48375 | AT22: =+K22-AS22-AR22-AQ22 -> 48991 | AU22: 51452 | AV22: 52366 | AW22: 54723 | AX22: =M22-AW22-AV22-AU22 -> 54934 | AY22: 67587 | AZ22: 69351 | BA22: 69408 | BB22: =N22-BA22-AZ22-AY22 -> 70550 | BC22: 72268 | BD22: 74211 | BE22: 75031 | BF22: =O22-BE22-BD22-BC22 -> 72534 | BG22: 77137 | BH22: 82472 | BI22: 85472 | BJ22: =P22-BI22-BH22-BG22 -> 85826 | BK22: 87814 | BL22: 89468 | BM22: 92977 | BN22: =Q22-BM22-BL22-BK22 -> 94059 | BO22: 96538 | BP22: 97343 | BQ22: 100743 | BR22: =R22-BQ22-BP22-BO22 -> 100752 | BS22: 105401 | BT22: 110000 | BU22: 117042 | BV22: =S22-BU22-BT22-BS22 -> 123260 | BW22: 124651 | BX22: 131821 | BY22: 134201 | BZ22: =T22-SUM(BW22:BY22) -> 136435 | CB22: 67587 | CC22: 68178 | CD22: 68615 | CE22: 71131 | CF22: 72862 | CH22: 270944
B23: Finance costs | D23: 25349 | E23: 40828 | F23: 45187 | G23: 60060 | H23: 73252 | I23: 85461 | J23: 105540 | K23: 95703 | L23: 93255 | M23: 110134 | N23: 139918 | O23: 150910 | P23: 166162 | Q23: 192999 | R23: 226477 | S23: 217539 | T23: 215553 | U23: =SUM(BW23:BZ23) -> 215553 | W23: 9929 | X23: 12681 | Y23: 13177 | Z23: =F23-SUM(W23:Y23) -> 9400 | AA23: 15889 | AB23: 16957 | AC23: 13160 | AD23: =G23-SUM(AA23:AC23) -> 14054 | AE23: 15727 | AF23: 12383 | AG23: 18669 | AH23: =H23-SUM(AE23:AG23) -> 26473 | AI23: 24441 | AJ23: 29735 | AK23: 19026 | AL23: =I23-SUM(AI23:AK23) -> 12259 | AM23: 25136 | AN23: 24626 | AO23: 33061 | AP23: =J23-SUM(AM23:AO23) -> 22717 | AQ23: 22039 | AR23: 24916 | AS23: 24846 | AT23: =+K23-AS23-AR23-AQ23 -> 23902 | AU23: 25498 | AV23: 33034 | AW23: 28381 | AX23: =M23-AW23-AV23-AU23 -> 23221 | AY23: 37840 | AZ23: 31872 | BA23: 32816 | BB23: =N23-BA23-AZ23-AY23 -> 37390 | BC23: 34562 | BD23: 37604 | BE23: 39719 | BF23: =O23-BE23-BD23-BC23 -> 39025 | BG23: 42257 | BH23: 39641 | BI23: 43671 | BJ23: =P23-BI23-BH23-BG23 -> 40593 | BK23: 45109 | BL23: 49403 | BM23: 46856 | BN23: =Q23-BM23-BL23-BK23 -> 51631 | BO23: 56137 | BP23: 51858 | BQ23: 66449 | BR23: =R23-BQ23-BP23-BO23 -> 52033 | BS23: 51523 | BT23: 54237 | BU23: 56755 | BV23: =S23-BU23-BT23-BS23 -> 55024 | BW23: 54608 | BX23: 48657 | BY23: 56232 | BZ23: =T23-SUM(BW23:BY23) -> 56056 | CB23: 33928 | CC23: 32893 | CD23: 41471 | CE23: 34671 | CF23: 37914 | CH23: 140732
B24: Finance Income | D24: -3536 | E24: -2643 | F24: -5103 | G24: -11680 | H24: -24788 | I24: -16326 | J24: -28566 | K24: -14988 | L24: -12540 | M24: -14240 | N24: -16098 | O24: 0 | P24: 0 | Q24: 0 | R24: 0 | S24: 0 | T24: 0 | U24: =SUM(BW24:BZ24) -> 0 | W24: -2562 | X24: -3431 | Y24: -867 | Z24: =F24-SUM(W24:Y24) -> 1757 | AA24: -4213 | AB24: -846 | AC24: -2478 | AD24: =G24-SUM(AA24:AC24) -> -4143 | AE24: -6162 | AF24: -3325 | AG24: -8219 | AH24: =H24-SUM(AE24:AG24) -> -7082 | AI24: -5250 | AJ24: -11110 | AK24: -5115 | AL24: =I24-SUM(AI24:AK24) -> 5149 | AM24: -5737 | AN24: -5569 | AO24: -13705 | AP24: =J24-SUM(AM24:AO24) -> -3555 | AQ24: -3765 | AR24: -1650 | AS24: -3964 | AT24: =+K24-AS24-AR24-AQ24 -> -5609 | AU24: -4232 | AV24: -3177 | AW24: -8933 | AX24: =M24-AW24-AV24-AU24 -> 2102 | AY24: -6025 | AZ24: -2789 | BA24: -2970 | BB24: =N24-BA24-AZ24-AY24 -> -4314 | BC24: -4063 | BD24: -346 | BE24: -556 | BF24: =O24-BE24-BD24-BC24 -> 4965 | BG24: -1438 | BH24: -804 | BI24: -79 | BJ24: =P24-BI24-BH24-BG24 -> 2321 | BK24: 0 | BL24: 0 | BM24: 0 | BN24: =Q24-BM24-BL24-BK24 -> 0 | BO24: 0 | BP24: 0 | BQ24: 0 | BR24: =R24-BQ24-BP24-BO24 -> 0 | BS24: 0 | BT24: 0 | BU24: 0 | BV24: =S24-BU24-BT24-BS24 -> 0 | BW24: 0 | BX24: 0 | BY24: 0 | BZ24: =T24-SUM(BW24:BY24) -> 0 | CB24: -2113 | CC24: -2970 | CD24: -4314 | CE24: -3372 | CF24: -54 | CH24: 0
B25: Net foreign exchange and derivative (gain)/loss | D25: 0 | E25: 0 | F25: 0 | G25: 0 | H25: 0 | I25: 0 | J25: 0 | K25: 0 | L25: 0 | M25: 0 | N25: 0 | O25: 0 | P25: 0 | Q25: 0 | R25: 0 | S25: 0 | T25: 0 | U25: =SUM(BW25:BZ25) -> 0 | W25: 0 | X25: 0 | Y25: 0 | Z25: =F25-SUM(W25:Y25) -> 0 | AA25: 0 | AB25: 0 | AC25: 0 | AD25: =G25-SUM(AA25:AC25) -> 0 | AE25: 0 | AF25: 0 | AG25: 0 | AH25: =H25-SUM(AE25:AG25) -> 0 | AI25: 0 | AJ25: 0 | AK25: 0 | AL25: =I25-SUM(AI25:AK25) -> 0 | AM25: 0 | AN25: 0 | AO25: 0 | AP25: =J25-SUM(AM25:AO25) -> 0 | AQ25: 0 | AR25: 0 | AS25: 0 | AT25: =+K25-AS25-AR25-AQ25 -> 0 | AU25: 0 | AV25: 0 | AW25: 0 | AX25: =M25-AW25-AV25-AU25 -> 0 | AY25: 0 | AZ25: 0 | BA25: 0 | BB25: =N25-BA25-AZ25-AY25 -> 0 | BC25: 0 | BD25: 0 | BE25: 0 | BF25: =O25-BE25-BD25-BC25 -> 0 | BG25: 0 | BH25: 0 | BI25: 0 | BJ25: =P25-BI25-BH25-BG25 -> 0 | BK25: 0 | BL25: 0 | BM25: 0 | BN25: =Q25-BM25-BL25-BK25 -> 0 | BO25: 0 | BP25: 0 | BQ25: 0 | BR25: =R25-BQ25-BP25-BO25 -> 0 | BS25: 0 | BT25: 0 | BU25: 0 | BV25: =S25-BU25-BT25-BS25 -> 0 | BW25: 0 | BX25: 0 | BY25: 0 | BZ25: =T25-SUM(BW25:BY25) -> 0 | CB25: 0 | CC25: 0 | CD25: 0 | CE25: 0 | CF25: 0 | CH25: 0
B26: Non-operating income / expenses, (net) | D26: 0 | E26: 0 | F26: 0 | G26: 660 | H26: 1669 | I26: 1024 | J26: 1319 | K26: 141 | L26: 141 | M26: 1894 | N26: 1272 | O26: 0 | P26: 0 | Q26: 0 | R26: 0 | S26: 0 | T26: 0 | U26: =SUM(BW26:BZ26) -> 0 | W26: 0 | X26: 0 | Y26: 0 | Z26: =F26-SUM(W26:Y26) -> 0 | AA26: 0 | AB26: 408 | AC26: 72 | AD26: =G26-SUM(AA26:AC26) -> 180 | AE26: 78 | AF26: 1206 | AG26: 73 | AH26: =H26-SUM(AE26:AG26) -> 312 | AI26: 85 | AJ26: 858 | AK26: 60 | AL26: =I26-SUM(AI26:AK26) -> 21 | AM26: 25 | AN26: 1329 | AO26: -509 | AP26: =J26-SUM(AM26:AO26) -> 474 | AQ26: -357 | AR26: 308 | AS26: 2 | AT26: =+K26-AS26-AR26-AQ26 -> 188 | AU26: 40 | AV26: 1074 | AW26: 721 | AX26: =M26-AW26-AV26-AU26 -> 59 | AY26: 461 | AZ26: 231 | BA26: 211 | BB26: =N26-BA26-AZ26-AY26 -> 369 | BC26: 0 | BD26: 0 | BE26: 0 | BF26: =O26-BE26-BD26-BC26 -> 0 | BG26: 0 | BH26: 0 | BI26: 0 | BJ26: =P26-BI26-BH26-BG26 -> 0 | BK26: 0 | BL26: 0 | BM26: 0 | BN26: =Q26-BM26-BL26-BK26 -> 0 | BO26: 0 | BP26: 0 | BQ26: 0 | BR26: =R26-BQ26-BP26-BO26 -> 0 | BS26: 0 | BT26: 0 | BU26: 0 | BV26: =S26-BU26-BT26-BS26 -> 0 | BW26: 0 | BX26: 0 | BY26: 0 | BZ26: =T26-SUM(BW26:BY26) -> 0 | CB26: 0 | CC26: 0 | CD26: 0 | CE26: 0 | CF26: 0 | CH26: 0
B27: Exceptional items | D27: 0 | E27: 0 | F27: 0 | G27: -538 | H27: 7960 | I27: -21741 | J27: 11697 | K27: 7931 | L27: 7931 | M27: -29288 | N27: 402344 | O27: 159145 | P27: -16986 | Q27: 6698 | R27: 75723 | S27: -72868 | T27: 34175 | U27: =SUM(BW27:BZ27) -> 34175 | W27: 0 | X27: 0 | Y27: 0 | Z27: =F27-SUM(W27:Y27) -> 0 | AA27: -2252 | AB27: 819 | AC27: -674 | AD27: =G27-SUM(AA27:AC27) -> 1569 | AE27: 1820 | AF27: 1750 | AG27: 2921 | AH27: =H27-SUM(AE27:AG27) -> 1469 | AI27: -14314 | AJ27: -6596 | AK27: 3405 | AL27: =I27-SUM(AI27:AK27) -> -4236 | AM27: 3536 | AN27: 66 | AO27: 2040 | AP27: =J27-SUM(AM27:AO27) -> 6055 | AQ27: 503 | AR27: 1786 | AS27: 2395 | AT27: =+K27-AS27-AR27-AQ27 -> 3247 | AU27: 3621 | AV27: 1449 | AW27: -14137 | AX27: =M27-AW27-AV27-AU27 -> -20221 | AY27: 14694 | AZ27: 307110 | BA27: 10500 | BB27: =N27-BA27-AZ27-AY27 -> 70040 | BC27: 117457 | BD27: 493 | BE27: 45599 | BF27: =O27-BE27-BD27-BC27 -> -4404 | BG27: -305 | BH27: -7221 | BI27: -398 | BJ27: =P27-BI27-BH27-BG27 -> -9062 | BK27: 0 | BL27: 0 | BM27: 6698 | BN27: =Q27-BM27-BL27-BK27 -> 0 | BO27: 34163 | BP27: 15703 | BQ27: 1302 | BR27: =R27-BQ27-BP27-BO27 -> 24555 | BS27: -7350 | BT27: 8537 | BU27: -75456 | BV27: =S27-BU27-BT27-BS27 -> 1401 | BW27: 0 | BX27: 0 | BY27: 2568 | BZ27: =T27-SUM(BW27:BY27) -> 31607 | CB27: 14694 | CC27: 10500 | CD27: 68588 | CE27: 117457 | CF27: 493 | CH27: 400892
B28: Profit before tax | D28: =D19-SUM(D21:D27) -> 76782 | E28: =E19-SUM(E21:E27) -> 65183 | F28: =F19-SUM(F21:F27) -> 47852 | G28: =G19-SUM(G21:G27) -> 78643 | H28: =H19-SUM(H21:H27) -> 107702 | I28: =I19-SUM(I21:I27) -> 128463 | J28: =J19-SUM(J21:J27) -> 77233 | K28: =K19-SUM(K21:K27) -> 32670 | ... U28: =U19-SUM(U21:U27) -> 451727 | W28: =W19-SUM(W21:W27) -> 12294 | X28: =X19-SUM(X21:X27) -> 14210 | Y28: =Y19-SUM(Y21:Y27) -> 9032 | Z28: =Z19-SUM(Z21:Z27) -> 12316 | AA28: =AA19-SUM(AA21:AA27) -> 18377 | AB28: =AB19-SUM(AB21:AB27) -> 13649 | AC28: =AC19-SUM(AC21:AC27) -> 22802 | AD28: =AD19-SUM(AD21:AD27) -> 23815 | ... BZ28: =BZ19-SUM(BZ21:BZ27) -> 100447 | CB28: =CB19-SUM(CB21:CB27) -> -29992 | CC28: =CC19-SUM(CC21:CC27) -> -23355 | CD28: =CD19-SUM(CD21:CD27) -> -75544 | CE28: =CE19-SUM(CE21:CE27) -> -121092 | CF28: =CF19-SUM(CF21:CF27) -> -2467 | CH28: =CH19-SUM(CH21:CH27) -> -461304
B29: Income Tax Expense | D29: -17790 | E29: -22602 | F29: -25184 | G29: -48449 | H29: -54047 | I29: -59533 | J29: -34819 | K29: =-18230+7395 -> -10835 | L29: =-18230+7395 -> -10835 | M29: =-19391+53584 -> 34193 | N29: =-23738+145561 -> 121823 | O29: =-20584-68741 -> -89325 | P29: =-30331-11448 -> -41779 | Q29: -42733 | R29: -41210 | S29: =-41121+31949 -> -9172 | T29: =-78812-34687 -> -113499 | U29: =SUM(BW29:BZ29) -> -113499 | W29: -4543 | X29: -7195 | Y29: -6192 | Z29: =F29-SUM(W29:Y29) -> -7254 | AA29: -9684 | AB29: -8634 | AC29: -16569 | AD29: =G29-SUM(AA29:AC29) -> -13562 | AE29: -15326 | AF29: -14765 | AG29: -13145 | AH29: =H29-SUM(AE29:AG29) -> -10811 | AI29: -21781 | AJ29: -13326 | AK29: -13499 | AL29: =I29-SUM(AI29:AK29) -> -10927 | AM29: -10089 | AN29: -11136 | AO29: -11841 | AP29: =J29-SUM(AM29:AO29) -> -1753 | AQ29: -8136 | AR29: -5341 | AS29: -379 | AT29: =+K29-AS29-AR29-AQ29 -> 3021 | AU29: =-7176+18443 -> 11267 | AV29: =-3850+26326 -> 22476 | AW29: =-5331+7155 -> 1824 | AX29: =M29-AW29-AV29-AU29 -> -1374 | AY29: =-7763+13833 -> 6070 | AZ29: =-4281+89320 -> 85039 | BA29: =-7309+17688 -> 10379 | BB29: =N29-BA29-AZ29-AY29 -> 20335 | BC29: =-5086-33089 -> -38175 | BD29: =-6494+977 -> -5517 | BE29: =-5594-37473 -> -43067 | BF29: =O29-BE29-BD29-BC29 -> -2566 | BG29: =-7274-1071 -> -8345 | BH29: =-7370-2938 -> -10308 | BI29: =-7922-1986 -> -9908 | BJ29: =P29-BI29-BH29-BG29 -> -13218 | BK29: -11233 | BL29: =-7953-4911 -> -12864 | BM29: =-6511-4245 -> -10756 | BN29: =Q29-BM29-BL29-BK29 -> -7880 | BO29: =5997-9324 -> -3327 | BP29: =-17574-891 -> -18465 | BQ29: =-7506-4814 -> -12320 | BR29: =R29-BQ29-BP29-BO29 -> -7098 | BS29: =-7883-5195 -> -13078 | BT29: -17440 | BU29: =-11336+3763 -> -7573 | BV29: =S29-BU29-BT29-BS29 -> 28919 | BW29: =-18657-12169 -> -30826 | BX29: =-18514-18201 -> -36715 | BY29: =-20153-17832 -> -37985 | BZ29: =T29-SUM(BW29:BY29) -> -7973 | CB29: =-7763+13833 -> 6070 | CC29: =17623-5986 -> 11637 | CD29: =-3021+24541 -> 21520 | CE29: =-3583-33439 -> -37022 | CF29: =-4949+814 -> -4135 | CH29: =-17932+143056 -> 125124
