Workbook
Name \A: #REF!
Name \B: #REF!
Name \C: #REF!
Name \L: #REF!
Name \M: #REF!
Name \P: #REF!
Name \Y: #REF!
Name _01_30_04: MonthlyOpStats
Name _01_30_04: MonthlyOpStats
Name _01_30_04: MonthlyOpStats
Name _01_30_04: MonthlyOpStats
Name _1_30_01: MonthlyOpStats
Name _1_30_01: MonthlyOpStats
Name _1_30_01: MonthlyOpStats
Name _1_30_01: MonthlyOpStats
Name _1_30_02: MonthlyOpStats
Name _1_30_02: MonthlyOpStats
Name _1_30_02: MonthlyOpStats
Name _1_30_02: MonthlyOpStats
Name _1_31_01: MonthlyOpStats
Name _1_31_01: MonthlyOpStats
Name _1_31_01: MonthlyOpStats
Name _1_31_01: MonthlyOpStats
Name _1_31_02: MonthlyOpStats
Name _1_31_02: MonthlyOpStats
Name _1_31_02: MonthlyOpStats
Name _1_31_02: MonthlyOpStats
Name _12_31_05: MonthlyOpStats
Name _12_31_05: MonthlyOpStats
Name _12_31_05: MonthlyOpStats
Name _12_31_05: MonthlyOpStats
Name _A: #REF!
Name _A___0: #REF!
Name _B: #REF!
Name _B___0: #REF!
Name _C: #REF!
Name _C___0: #REF!
Name _ent1: [1]Inputs!$J$17
Name _ent10: [1]Inputs!$J$476
Name _ent11: [1]Inputs!$J$527
Name _ent12: [1]Inputs!$J$578
Name _ent13: [1]Inputs!$J$629
Name _ent14: [1]Inputs!$J$680
Name _ent15: [1]Inputs!$J$731
Name _ent2: [1]Inputs!$J$68
Name _ent3: [1]Inputs!$J$119
Name _ent4: [1]Inputs!$J$170
Name _ent5: [1]Inputs!$J$221
Name _ent6: [1]Inputs!$J$272
Name _ent7: [1]Inputs!$J$323
Name _ent8: [1]Inputs!$J$374
Name _ent9: [1]Inputs!$J$425
Name _eps1: [1]Inputs!$P$42
Name _eps10: [1]Inputs!$P$501
Name _eps11: [1]Inputs!$P$552
Name _eps12: [1]Inputs!$P$603
Name _eps13: [1]Inputs!$P$654
Name _eps14: [1]Inputs!$P$705
Name _eps15: [1]Inputs!$P$756
Name _eps2: [1]Inputs!$P$93

Sheet Capitalisation
B3: 1Q26 | I3: Exchange rate as at end | J3: =Model!$O$208 -> 0.0010795988
I4: LTM Average exchange rate | J4: =Model!$O$207 -> 0.0010741488
C6: Amount outstanding as on 31-Mar-2026 | D6: Ch$ (mn) | E6: USD (mn) | F6: Leverage (Ch$) | G6: Leverage (USD) | I6: Company Reported | J6: Ch$ (mn)
I7: Net debt | J7: =1335.7*1000 -> 1335700
C8: Short-term debt | I8: Net debt to EBITDA | J8: 2.34
C9: Interest bearing borrowings (Loans) | D9: =Model!$BE$107 -> 14561.932 | E9: =+D9*$J3 -> 15.721045
C10: Liabilities with bondholders | D10: =Model!$BE$108 -> 8921.722 | E10: =+D10*$J3 -> 9.6318806
C11: Liabilities for leases current | D11: =Model!$BE$110 -> 148848.49 | E11: =+D11*$J3 -> 160.69666
C12: Long-term debt
C13: Interest bearing borrowings (Loans) | D13: =Model!$BE$112 -> 170467.77 | E13: =+D13*$J3 -> 184.0368
C14: Liabilities with bondholders | D14: =Model!$BE$113 -> 1403972.5 | E14: =+D14*$J3 -> 1515.727
C15: Liabilities for leases non-current | D15: =Model!$BE$115 -> 522425.65 | E15: =+D15*$J3 -> 564.01012
C16: Total Loans & Borrows | D16: =SUM(D9:D15) -> 2269198 | E16: =SUM(E9:E15) -> 2449.8235 | F16: =+D16/D21 -> 2.6528389 | G16: =+E16/E21 -> 2.6662989
C17: Cash & Equivalents | D17: =Model!$BE$118 -> 215586.38 | E17: =+D17*$J3 -> 232.7468
C18: Net debt | D18: =+D16-D17 -> 2053611.7 | E18: =+E16-E17 -> 2217.0767 | F18: =+D18/D21 -> 2.4008045 | G18: =+E18/E21 -> 2.4129858
C19: Equity | D19: =Model!$BE$125 -> 1969186.8 | E19: =+D19*$J3 -> 2125.9317
C20: Total Capitalisation | D20: =D16+D19 -> 4238384.8 | E20: =E16+E19 -> 4575.7552 | F20: =D20/D21 -> 4.9549452 | G20: =E20/E21 -> 4.9800858
C21: LTM Adjusted EBITDA | D21: =Model!$BE$84 -> 855384.79 | E21: =+D21*J4 -> 918.81052
C22: check | D22: =D16-Model!$BE$121 -> 0
C25: Liquidity Table at end-1Q26 | D25: =D6 -> Ch$ (mn) | E25: =E6 -> USD (mn)
C26: Cash and cash equivalents | D26: =D17 -> 215586.38 | E26: =D26*$J3 -> 232.7468
C27: Total | D27: =SUM(D26:D26) -> 215586.38 | E27: =SUM(E26:E26) -> 232.7468
C30: Debt Maturity Profile at end-1Q26 | D30: =D25 -> Ch$ (mn) | E30: =E25 -> USD (mn)
C31: Less than 1 year | D31: =14561.932+7915.943+1005.779 -> 23483.654 | E31: =D31*$J3 -> 25.352925
C32: Year 1-2 | D32: 0 | E32: =D32*$J3 -> 0
C33: Year 2-3 | D33: 248006.15 | E33: =D33*$J3 -> 267.74715
C34: Year 3-4 | D34: 0 | E34: =D34*$J3 -> 0
C35: Year 4-5 | D35: =170467.765+39692.799 -> 210160.56 | E35: =D35*$J3 -> 226.8891
C36: Over 5 years | D36: 1116273.5 | E36: =D36*$J3 -> 1205.1276
C37: Total debt (excluding leases) | D37: =SUM(D31:D36) -> 1597923.9 | E37: =SUM(E31:E36) -> 1725.1167
C38: check | D38: =D37-D9-D10-D13-D14 -> 0
C41: Lease liabilities Maturity Profile at end-1Q26 | D41: (Ch$ millions) | E41: (USD millions)
C42: Less than 1 year | D42: 148848.49 | E42: =D42*$J3 -> 160.69666
C43: Year 1-2 | D43: 129322.58 | E43: =D43*$J3 -> 139.61651
C44: Year 2-3 | D44: 115938.55 | E44: =D44*$J3 -> 125.16712
C45: Year 3-4 | D45: 95222.316 | E45: =D45*$J3 -> 102.8019
C46: Year 4-5 | D46: 52805.087 | E46: =D46*$J3 -> 57.00831
C47: Over 5 years | D47: 129137.12 | E47: =D47*$J3 -> 139.41628
C48: Total debt | D48: =SUM(D42:D47) -> 671274.14 | E48: =SUM(E42:E47) -> 724.70677
C49: check | D49: =D48-D11-D15 -> 0
...

Sheet Model
B2: ENTEL | C2: Annual | D2: Annual | E2: Annual | F2: Annual | G2: Annual | H2: Annual | I2: Annual | J2: Annual | K2: Annual | L2: Annual | M2: Annual | N2: Annual | O2: LTM | Q2: Quarterly | R2: Quarterly | S2: Quarterly | T2: Quartdrly | U2: Quarterly | V2: Quarterly | W2: Quarterly | X2: Quarterly | Y2: Quarterly | Z2: Quarterly | AA2: Quarterly | AB2: Quarterly | AC2: Quarterly | AD2: Quarterly | AE2: Quarterly | AF2: Quarterly | AG2: Quarterly | AH2: Quarterly | AI2: Quarterly | AJ2: Quarterly | AK2: Quarterly | AL2: Quarterly | AM2: Quarterly | AN2: Quarterly | AO2: Quarterly | AP2: Quarterly | AQ2: Quarterly | AR2: Quarterly | AS2: Quarterly | AT2: Quarterly | AU2: Quarterly | AV2: Quarterly | AW2: Quarterly | AX2: Quarterly | AY2: Quarterly | AZ2: Quarterly | BA2: Quarterly | BB2: Quarterly | BC2: Quarterly | BD2: Quarterly | BE2: Quarterly
B3: (Ch$ millions) | C3: 41974 | D3: 42340 | E3: 42707 | F3: 43073 | G3: 43438 | H3: 43803 | I3: 44169 | J3: 44534 | K3: 44926 | L3: 45291 | M3: 45657 | N3: 46022 | O3: =BE3 -> 46112 | Q3: 42437 | R3: 42527 | S3: 42622 | T3: 42714 | U3: 42801 | V3: 42892 | W3: 42987 | X3: 43079 | Y3: 43190 | Z3: 43281 | AA3: 43373 | AB3: 43465 | AC3: 43555 | AD3: 43646 | AE3: 43738 | AF3: 43830 | AG3: 43921 | AH3: 44012 | AI3: 44104 | AJ3: 44196 | AK3: 44286 | AL3: 44377 | AM3: 44469 | AN3: 44560 | AO3: 44651 | AP3: 44742 | AQ3: 44834 | AR3: 44926 | AS3: 45016 | AT3: 45107 | AU3: 45199 | AV3: 45291 | AW3: 45382 | AX3: 45473 | AY3: 45565 | AZ3: 45657 | BA3: 45747 | BB3: 45838 | BC3: 45930 | BD3: 46022 | BE3: 46112
C4: Act | D4: Act | E4: Act | F4: Act | G4: Act | H4: Act | I4: Act | J4: Act | K4: Act | L4: Act | M4: Act | N4: Act | O4: Act | Q4: Act | R4: Act | S4: Act | T4: Act | U4: Act | V4: Act | W4: Act | X4: Act | Y4: Act | Z4: Act | AA4: Act | AB4: Act | AC4: Act | AD4: Act | AE4: Act | AF4: Act | AG4: Act | AH4: Act | AI4: Act | AJ4: Act | AK4: Act | AL4: Act | AM4: Act | AN4: Act | AO4: Act | AP4: Act | AQ4: Act | AR4: Act | AS4: Act | AT4: Act | AU4: Act | AV4: Act | AW4: Act | AX4: Act | AY4: Act | AZ4: Act | BA4: Act | BB4: Act | BC4: Act | BD4: Act | BE4: Act
C5: FY | D5: FY | E5: FY | F5: FY | G5: FY | H5: FY | I5: FY | J5: FY | K5: FY | L5: FY | M5: FY | N5: FY | O5: LTM | Q5: Q1 | R5: Q2 | S5: Q3 | T5: Q4 | U5: Q1 | V5: Q2 | W5: Q3 | X5: Q4 | Y5: Q1 | Z5: Q2 | AA5: Q3 | AB5: Q4 | AC5: Q1 | AD5: Q2 | AE5: Q3 | AF5: Q4 | AG5: Q1 | AH5: Q2 | AI5: Q3 | AJ5: Q4 | AK5: Q1 | AL5: Q2 | AM5: Q3 | AN5: Q4 | AO5: Q1 | AP5: Q2 | AQ5: Q3 | AR5: Q4 | AS5: Q1 | AT5: Q2 | AU5: Q3 | AV5: Q4 | AW5: Q1 | AX5: Q2 | AY5: Q3 | AZ5: Q4 | BA5: Q1 | BB5: Q2 | BC5: Q3 | BD5: Q4 | BE5: Q1
B6: INCOME STATEMENT
B7: Revenues | C7: 1657770.4 | D7: 1784612.7 | E7: 1867697.1 | F7: 1943071.2 | G7: 1913174.3 | H7: 1978792 | I7: 2092644.2 | J7: 2408809.6 | K7: 2540682.9 | L7: 2473692.3 | M7: 2703236.7 | N7: 2954930.3 | O7: =SUM(BB7:BE7) -> 3002583.4 | Q7: 459463.63 | R7: =916299.774-Q7 -> 456836.15 | S7: =1384201.053-R7-Q7 -> 467901.28 | T7: =E7-S7-R7-Q7 -> 483496.02 | U7: 473615.34 | V7: =952346.117-U7 -> 478730.78 | W7: =1432252.759-V7-U7 -> 479906.64 | X7: =F7-W7-V7-U7 -> 510818.44 | Y7: 461181.57 | Z7: =926857.408-Y7 -> 465675.84 | AA7: =1408181.843-Z7-Y7 -> 481324.44 | AB7: =G7-AA7-Z7-Y7 -> 504992.44 | AC7: 471553.29 | AD7: 482669.9 | AE7: 496056.71 | AF7: =H7-AE7-AD7-AC7 -> 528512.09 | AG7: 513442.28 | AH7: 457638.94 | AI7: 534454.77 | AJ7: =I7-AI7-AH7-AG7 -> 587108.25 | AK7: 557729.51 | AL7: 591680.99 | AM7: 608206.88 | AN7: =J7-AM7-AL7-AK7 -> 651192.23 | AO7: 640785.58 | AP7: 646628.75 | AQ7: 622782.23 | AR7: =K7-AO7-AP7-AQ7 -> 630486.35 | AS7: 601409.66 | AT7: 607222.76 | AU7: 603807.07 | AV7: =L7-AS7-AT7-AU7 -> 661252.82 | AW7: 649744.56 | AX7: 660664.46 | AY7: 659565.95 | AZ7: =M7-AW7-AX7-AY7 -> 733261.76 | BA7: 707083.93 | BB7: =1412720.853-BA7 -> 705636.93 | BC7: 730437.04 | BD7: =N7-BA7-BB7-BC7 -> 811772.39 | BE7: 754737.08
B8: % y-o-y growth | D8: =D7/C7-1 -> 0.076513787 | E8: =E7/D7-1 -> 0.046555989 | F8: =F7/E7-1 -> 0.04035672 | G8: =G7/F7-1 -> -0.015386423 | H8: =H7/G7-1 -> 0.034297819 | I8: =I7/H7-1 -> 0.057536237 | J8: =J7/I7-1 -> 0.15108415 | K8: =K7/J7-1 -> 0.054746256 | ... N8: =N7/M7-1 -> 0.093108216 | U8: =U7/Q7-1 -> 0.030800503 | V8: =V7/R7-1 -> 0.047926663 | W8: =W7/S7-1 -> 0.025657897 | X8: =X7/T7-1 -> 0.056510128 | Y8: =Y7/U7-1 -> -0.026252883 | Z8: =Z7/V7-1 -> -0.027269901 | AA8: =AA7/W7-1 -> 0.00295431 | AB8: =AB7/X7-1 -> -0.011405227 | ... BE8: =BE7/BA7-1 -> 0.067393909
B9: Other income | C9: 4299.76 | D9: 8284.735 | E9: 19214.192 | F9: 11974.824 | G9: 9874.347 | H9: 11475.402 | I9: 13254.828 | J9: 30500.293 | K9: 52062.685 | L9: 48125.237 | M9: 64957.031 | N9: 77576.278 | O9: =SUM(BB9:BE9) -> 81218.768 | Q9: 1821.463 | R9: =3760.468-Q9 -> 1939.005 | S9: =6011.072-R9-Q9 -> 2250.604 | T9: =E9-S9-R9-Q9 -> 13203.12 | U9: 3735.191 | V9: =6370.919-U9 -> 2635.728 | W9: =9113.878-V9-U9 -> 2742.959 | X9: =F9-W9-V9-U9 -> 2860.946 | Y9: 2432.787 | Z9: =5301.876-Y9 -> 2869.089 | AA9: =7461.375-Z9-Y9 -> 2159.499 | AB9: =G9-AA9-Z9-Y9 -> 2412.972 | AC9: 3249.484 | AD9: 2802.708 | AE9: 2712.27 | AF9: =H9-AE9-AD9-AC9 -> 2710.94 | AG9: 3526.614 | AH9: 3893.964 | AI9: 2856.609 | AJ9: =I9-AI9-AH9-AG9 -> 2977.641 | AK9: 6730.949 | AL9: 6747.994 | AM9: 8478.316 | AN9: =J9-AM9-AL9-AK9 -> 8543.034 | AO9: 9547.493 | AP9: 16613.511 | AQ9: 13210.508 | AR9: =K9-AO9-AP9-AQ9 -> 12691.173 | AS9: 12412.806 | AT9: 10381.294 | AU9: 14140.534 | AV9: =L9-AS9-AT9-AU9 -> 11190.603 | AW9: 15015.756 | AX9: 19267.787 | AY9: 14488.232 | AZ9: =M9-AW9-AX9-AY9 -> 16185.256 | BA9: 17224.497 | BB9: =34236.661-BA9 -> 17012.164 | BC9: 17565.94 | BD9: =N9-BA9-BB9-BC9 -> 25773.677 | BE9: 20866.987
B10: Salaries and Expenses / Employee Benefits Expenses | C10: -222224.88 | D10: -247005.73 | E10: -245606.06 | F10: -249163.56 | G10: -260153.63 | H10: -260168.14 | I10: -256582.14 | J10: -257334.49 | K10: -296125.85 | L10: -301943.15 | M10: -323940.67 | N10: -350441.87 | O10: =SUM(BB10:BE10) -> -352609.42 | Q10: -60587.981 | R10: =-121638.494-Q10 -> -61050.513 | S10: =-183842.004-R10-Q10 -> -62203.51 | T10: =E10-S10-R10-Q10 -> -61764.055 | U10: -64682.209 | V10: =-126399.286-U10 -> -61717.077 | W10: =-187449.049-V10-U10 -> -61049.763 | X10: =F10-W10-V10-U10 -> -61714.509 | Y10: -62514.423 | Z10: =-132921.69-Y10 -> -70407.267 | AA10: =-199812.093-Z10-Y10 -> -66890.403 | AB10: =G10-AA10-Z10-Y10 -> -60341.534 | AC10: -60638.208 | AD10: -69113.453 | AE10: -62648.176 | AF10: =H10-AE10-AD10-AC10 -> -67768.301 | AG10: -64271.068 | AH10: -63243.043 | AI10: -65576.948 | AJ10: =I10-AI10-AH10-AG10 -> -63491.076 | AK10: -64370.446 | AL10: -63447.64 | AM10: -61902.616 | AN10: =J10-AM10-AL10-AK10 -> -67613.785 | AO10: -73170.807 | AP10: -71226.364 | AQ10: -78205.358 | AR10: =K10-AO10-AP10-AQ10 -> -73523.323 | AS10: -83977.997 | AT10: -71676.127 | AU10: -71810 | AV10: =L10-AS10-AT10-AU10 -> -74479.023 | AW10: -77056.052 | AX10: -77702.524 | AY10: -85387.053 | AZ10: =M10-AW10-AX10-AY10 -> -83795.041 | BA10: -88567.207 | BB10: =-170273.897-BA10 -> -81706.69 | BC10: -87719.734 | BD10: =N10-BA10-BB10-BC10 -> -92448.235 | BE10: -90734.76
B11: Depreciation and amortization expenses | C11: -239635.27 | D11: -273625.47 | E11: -299584.31 | F11: -315867.65 | G11: -331565.83 | H11: -422651.52 | I11: -467435.7 | J11: -466882.18 | K11: -518018.76 | L11: -504142.39 | M11: -544468.26 | N11: -570766.45 | O11: =SUM(BB11:BE11) -> -577039.63 | Q11: -73266.158 | R11: =-147348.536-Q11 -> -74082.378 | S11: =-222514.129-R11-Q11 -> -75165.593 | T11: =E11-S11-R11-Q11 -> -77070.185 | U11: -77803.059 | V11: =-156844.167-U11 -> -79041.108 | W11: =-235710.501-V11-U11 -> -78866.334 | X11: =F11-W11-V11-U11 -> -80157.151 | Y11: -81303.266 | Z11: =-163860.322-Y11 -> -82557.056 | AA11: =-247607.981-Z11-Y11 -> -83747.659 | AB11: =G11-AA11-Z11-Y11 -> -83957.847 | AC11: -101130.35 | AD11: -103801.07 | AE11: -107265 | AF11: =H11-AE11-AD11-AC11 -> -110455.09 | AG11: -115515.19 | AH11: -116506.96 | AI11: -116989.27 | AJ11: =I11-AI11-AH11-AG11 -> -118424.28 | AK11: -114882.64 | AL11: -114555.78 | AM11: -116826.47 | AN11: =J11-AM11-AL11-AK11 -> -120617.3 | AO11: -123409.77 | AP11: -138669.03 | AQ11: -127929.62 | AR11: =K11-AO11-AP11-AQ11 -> -128010.34 | AS11: -123770.5 | AT11: -124236.54 | AU11: -127476.87 | AV11: =L11-AS11-AT11-AU11 -> -128658.49 | AW11: -132760.02 | AX11: -139544.61 | AY11: -139744.07 | AZ11: =M11-AW11-AX11-AY11 -> -132419.55 | BA11: -139408.61 | BB11: =-280948.855-BA11 -> -141540.25 | BC11: -139017.99 | BD11: =N11-BA11-BB11-BC11 -> -150799.61 | BE11: -145681.78
B12: Impairment losses (reversals), Net | D12: -53796.077 | E12: -58901.242 | F12: -52089.5 | G12: -68584.398 | H12: -70132.193 | I12: -79684.088 | J12: -98585.66 | K12: -106577.97 | L12: -122085.65 | M12: -91587.508 | N12: -89695.735 | O12: =SUM(BB12:BE12) -> -88741.266 | Q12: -14397.242 | R12: =-25060.834-Q12 -> -10663.592 | S12: =-39164.733-R12-Q12 -> -14103.899 | T12: =E12-S12-R12-Q12 -> -19736.509 | U12: -11569.119 | V12: =-24323.843-U12 -> -12754.724 | W12: =-36739.808-V12-U12 -> -12415.965 | X12: =F12-W12-V12-U12 -> -15349.692 | Y12: -19552.524 | Z12: =-37733.019-Y12 -> -18180.495 | AA12: =-52556.869-Z12-Y12 -> -14823.85 | AB12: =G12-AA12-Z12-Y12 -> -16027.529 | AC12: -14484.416 | AD12: -15851.207 | AE12: -18695.275 | AF12: =H12-AE12-AD12-AC12 -> -21101.295 | AG12: -18307.127 | AH12: -23134.682 | AI12: -17233.733 | AJ12: =I12-AI12-AH12-AG12 -> -21008.546 | AK12: -19896.875 | AL12: -22872.512 | AM12: -23589.972 | AN12: =J12-AM12-AL12-AK12 -> -32226.301 | AO12: -27789.105 | AP12: -25952.236 | AQ12: -28648.557 | AR12: =K12-AO12-AP12-AQ12 -> -24188.069 | AS12: -55592.447 | AT12: -21322.947 | AU12: -21708.639 | AV12: =L12-AS12-AT12-AU12 -> -23461.619 | AW12: -22258.555 | AX12: -21931.153 | AY12: -20617.08 | AZ12: =M12-AW12-AX12-AY12 -> -26780.72 | BA12: -22782.496 | BB12: =-44683.182-BA12 -> -21900.686 | BC12: -22915.503 | BD12: =N12-BA12-BB12-BC12 -> -22097.05 | BE12: -21828.027
B13: Other expenses | C13: -1024171.9 | D13: -1137592.9 | E13: -1168814.9 | F13: -1220664.5 | G13: -1171742.7 | H13: -1100674.4 | I13: -1131313.5 | J13: -1342942.4 | K13: -1459378.3 | L13: -1395401.4 | M13: -1573911.2 | N13: -1771543.5 | O13: =SUM(BB13:BE13) -> -1802036.4 | Q13: -278000.77 | R13: =-567454.367-Q13 -> -289453.59 | S13: =-856123.189-R13-Q13 -> -288668.82 | T13: =E13-S13-R13-Q13 -> -312691.67 | U13: -291753.2 | V13: =-600966.078-U13 -> -309212.88 | W13: =-899434.203-V13-U13 -> -298468.13 | X13: =F13-W13-V13-U13 -> -321230.34 | Y13: -283190.07 | Z13: =-570100.181-Y13 -> -286910.11 | AA13: =-865812.941-Z13-Y13 -> -295712.76 | AB13: =G13-AA13-Z13-Y13 -> -305929.76 | AC13: -262815.12 | AD13: -263786.01 | AE13: -270708.18 | AF13: =H13-AE13-AD13-AC13 -> -303365.12 | AG13: -276511.41 | AH13: -227174.53 | AI13: -296649.36 | AJ13: =I13-AI13-AH13-AG13 -> -330978.17 | AK13: -308125.44 | AL13: -318886.29 | AM13: -335253.03 | AN13: =J13-AM13-AL13-AK13 -> -380677.62 | AO13: -360282.34 | AP13: -367199.45 | AQ13: -357200.58 | AR13: =K13-AO13-AP13-AQ13 -> -374695.95 | AS13: -343565.86 | AT13: -334024.95 | AU13: -335885.75 | AV13: =L13-AS13-AT13-AU13 -> -381924.83 | AW13: -380732.04 | AX13: -383573.39 | AY13: -375359.64 | AZ13: =M13-AW13-AX13-AY13 -> -434246.17 | BA13: -423133.58 | BB13: =-843243.564-BA13 -> -420109.98 | BC13: -427235.42 | BD13: =N13-BA13-BB13-BC13 -> -501064.53 | BE13: -453626.47
B14: Other gains (losses) | C14: 5981.586 | D14: -33.432 | E14: 390.536 | F14: 124.569 | G14: -89 | H14: 207275.45 | I14: 41585.368 | J14: 20809.511 | K14: 544963.98 | L14: 51324.376 | M14: -3433.485 | N14: -205.502 | O14: =SUM(BB14:BE14) -> -533.823 | Q14: 25.257 | R14: =250.944-Q14 -> 225.687 | S14: =268.965-R14-Q14 -> 18.021 | T14: =E14-S14-R14-Q14 -> 121.571 | U14: -325.238 | V14: =-341.523-U14 -> -16.285 | W14: =27.174-V14-U14 -> 368.697 | X14: =F14-W14-V14-U14 -> 97.395 | Y14: -75.017 | Z14: =-80.968-Y14 -> -5.951 | AA14: =-124.264-Z14-Y14 -> -43.296 | AB14: =G14-AA14-Z14-Y14 -> 35.264 | AC14: -18.014 | AD14: -33.814 | AE14: -281.206 | AF14: =H14-AE14-AD14-AC14 -> 207608.49 | AG14: 13736.444 | AH14: 14560.646 | AI14: 5728.474 | AJ14: =I14-AI14-AH14-AG14 -> 7559.804 | AK14: 4298.592 | AL14: 10024.151 | AM14: 6660.594 | AN14: =J14-AM14-AL14-AK14 -> -173.826 | AO14: -392.27 | AP14: 486325.08 | AQ14: 59602.71 | AR14: =K14-AO14-AP14-AQ14 -> -571.538 | AS14: -484.16 | AT14: 118.857 | AU14: -509.306 | AV14: =L14-AS14-AT14-AU14 -> 52198.985 | AW14: -116.948 | AX14: 490.644 | AY14: -609.822 | AZ14: =M14-AW14-AX14-AY14 -> -3197.359 | BA14: 306.804 | BB14: =675.27-BA14 -> 368.466 | BC14: -449.802 | BD14: =N14-BA14-BB14-BC14 -> -430.97 | BE14: -21.517
B15: Operating Profit | C15: =C7+SUM(C9:C14) -> 182019.64 | D15: =D7+SUM(D9:D14) -> 80843.799 | E15: =E7+SUM(E9:E14) -> 114395.32 | F15: =F7+SUM(F9:F14) -> 117385.34 | G15: =G7+SUM(G9:G14) -> 90913.071 | H15: =H7+SUM(H9:H14) -> 343916.57 | I15: =I7+SUM(I9:I14) -> 212469.04 | J15: =J7+SUM(J9:J14) -> 294374.69 | ... O15: =O7+SUM(O9:O14) -> 262841.65 | Q15: =Q7+SUM(Q9:Q14) -> 35058.193 | R15: =R7+SUM(R9:R14) -> 23750.762 | S15: =S7+SUM(S9:S14) -> 30028.08 | T15: =T7+SUM(T9:T14) -> 25558.286 | U15: =U7+SUM(U9:U14) -> 31217.703 | V15: =V7+SUM(V9:V14) -> 18624.436 | W15: =W7+SUM(W9:W14) -> 32218.111 | X15: =X7+SUM(X9:X14) -> 35325.086 | ... BE15: =BE7+SUM(BE9:BE14) -> 63711.506
B16: Finance Income | C16: 10818.705 | D16: 12183.865 | E16: 5952.92 | F16: 5225.532 | G16: 1889.772 | H16: 8746.947 | I16: 10894.534 | J16: 4919.952 | K16: 26563.887 | L16: 26535.094 | M16: 48118.158 | N16: 28768.371 | O16: =SUM(BB16:BE16) -> 26993.533 | Q16: 6119.225 | R16: =9473.433-Q16 -> 3354.208 | S16: =7842.692-R16-Q16 -> -1630.741 | T16: =E16-S16-R16-Q16 -> -1889.772 | U16: 2528.653 | V16: =5048.04-U16 -> 2519.387 | W16: =4953.604-V16-U16 -> -94.436 | X16: =F16-W16-V16-U16 -> 271.928 | Y16: 835.356 | Z16: =1402.952-Y16 -> 567.596 | AA16: =1687.118-Z16-Y16 -> 284.166 | AB16: =G16-AA16-Z16-Y16 -> 202.654 | AC16: 3186.538 | AD16: 4354.644 | AE16: 517.6 | AF16: =H16-AE16-AD16-AC16 -> 688.165 | AG16: 4796.556 | AH16: 3554.087 | AI16: 1444.183 | AJ16: =I16-AI16-AH16-AG16 -> 1099.708 | AK16: 644.156 | AL16: 460.657 | AM16: 1479.932 | AN16: =J16-AM16-AL16-AK16 -> 2335.207 | AO16: 3384.097 | AP16: 8608.77 | AQ16: 8591.226 | AR16: =K16-AO16-AP16-AQ16 -> 5979.794 | AS16: 5825.119 | AT16: 4203.163 | AU16: 6803.021 | AV16: =L16-AS16-AT16-AU16 -> 9703.791 | AW16: 11361.421 | AX16: 8768.153 | AY16: 5351.549 | AZ16: =M16-AW16-AX16-AY16 -> 22637.035 | BA16: 5102.986 | BB16: =7564.088-BA16 -> 2461.102 | BC16: 6263.529 | BD16: =N16-BA16-BB16-BC16 -> 14940.754 | BE16: 3328.148
B17: Financial expenses | C17: -55252.785 | D17: -70978.326 | E17: -82221.963 | F17: -80035.968 | G17: -77711.185 | H17: -97558.997 | I17: -102535.94 | J17: -113951.13 | K17: -113696.38 | L17: -113270.2 | M17: -111986.5 | N17: -165362.52 | O17: =SUM(BB17:BE17) -> -138918.41 | Q17: -18462.272 | R17: =-37632.325-Q17 -> -19170.053 | S17: =-56930.486-R17-Q17 -> -19298.161 | T17: =E17-S17-R17-Q17 -> -25291.477 | U17: -18449.335 | V17: =-40529.797-U17 -> -22080.462 | W17: =-60237.471-V17-U17 -> -19707.674 | X17: =F17-W17-V17-U17 -> -19798.497 | Y17: -21373.738 | Z17: =-42191.821-Y17 -> -20818.083 | AA17: =-61902.072-Z17-Y17 -> -19710.251 | AB17: =G17-AA17-Z17-Y17 -> -15809.113 | AC17: -22786.558 | AD17: -24444.595 | AE17: -24471.645 | AF17: =H17-AE17-AD17-AC17 -> -25856.199 | AG17: -27204.418 | AH17: -26018.812 | AI17: -24679.518 | AJ17: =I17-AI17-AH17-AG17 -> -24633.19 | AK17: -23329.043 | AL17: -22877.109 | AM17: -41353.92 | AN17: =J17-AM17-AL17-AK17 -> -26391.061 | AO17: -24603.053 | AP17: -30773.087 | AQ17: -29217.044 | AR17: =K17-AO17-AP17-AQ17 -> -29103.199 | AS17: -27587.608 | AT17: -28198.521 | AU17: -28353.268 | AV17: =L17-AS17-AT17-AU17 -> -29130.803 | AW17: -27500.891 | AX17: -27692.341 | AY17: -27330.747 | AZ17: =M17-AW17-AX17-AY17 -> -29462.518 | BA17: -52370.305 | BB17: =-93066.125-BA17 -> -40695.82 | BC17: -16715.392 | BD17: =N17-BA17-BB17-BC17 -> -55581.004 | BE17: -25926.197
B18: Foreign currency translation differences | C18: -11243.068 | D18: -12945.839 | E18: -16051.379 | F18: -6973.571 | G18: -994.222 | H18: 4551.31 | I18: -115.094 | J18: 250.185 | K18: -350.491 | L18: -3187.775 | M18: -2897.341 | N18: 753.395 | O18: =SUM(BB18:BE18) -> -37.313 | Q18: -5943.731 | R18: =-9364.382-Q18 -> -3420.651 | S18: =-13744.459-R18-Q18 -> -4380.077 | T18: =E18-S18-R18-Q18 -> -2306.92 | U18: -1659.109 | V18: =-4111.661-U18 -> -2452.552 | W18: =-5895.437-V18-U18 -> -1783.776 | X18: =F18-W18-V18-U18 -> -1078.134 | Y18: -1176.139 | Z18: =-473.89-Y18 -> 702.249 | AA18: =-983.773-Z18-Y18 -> -509.883 | AB18: =G18-AA18-Z18-Y18 -> -10.449 | AC18: 1969.702 | AD18: 51.292 | AE18: 2081.58 | AF18: =H18-AE18-AD18-AC18 -> 448.736 | AG18: -635.473 | AH18: -24.416 | AI18: -722.503 | AJ18: =I18-AI18-AH18-AG18 -> 1267.298 | AK18: -602.037 | AL18: -1581.046 | AM18: 739.708 | AN18: =J18-AM18-AL18-AK18 -> 1693.56 | AO18: 2569.758 | AP18: -2760.954 | AQ18: -2817.641 | AR18: =K18-AO18-AP18-AQ18 -> 2658.346 | AS18: 191.191 | AT18: -1189.346 | AU18: -2525.323 | AV18: =L18-AS18-AT18-AU18 -> 335.703 | AW18: -1343.755 | AX18: -1544.142 | AY18: 442.993 | AZ18: =M18-AW18-AX18-AY18 -> -452.437 | BA18: 20.189 | BB18: =895.96-BA18 -> 875.771 | BC18: -863.595 | BD18: =N18-BA18-BB18-BC18 -> 721.03 | BE18: -770.519
B19: Results from inflation-adjusted units | C19: -22635.632 | D19: -22985.872 | E19: -15934.835 | F19: -9600.405 | G19: -16368.412 | H19: -19445.992 | I19: -26758.482 | J19: -66963.329 | K19: -130374.24 | L19: -39051.828 | M19: -32919.657 | N19: -24859.269 | O19: =SUM(BB19:BE19) -> -17398.975 | Q19: -3977.408 | R19: =-9499.781-Q19 -> -5522.373 | S19: =-13185.375-R19-Q19 -> -3685.594 | T19: =E19-S19-R19-Q19 -> -2749.46 | U19: -2766.358 | V19: =-7173.524-U19 -> -4407.166 | W19: =-7063.271-V19-U19 -> 110.253 | X19: =F19-W19-V19-U19 -> -2537.134 | Y19: -3444.75 | Z19: =-7426.083-Y19 -> -3981.333 | AA19: =-11862.017-Z19-Y19 -> -4435.934 | AB19: =G19-AA19-Z19-Y19 -> -4506.395 | AC19: 29.344 | AD19: -7543.41 | AE19: -3406.778 | AF19: =H19-AE19-AD19-AC19 -> -8525.148 | AG19: -10321.723 | AH19: -3890.407 | AI19: -152.219 | AJ19: =I19-AI19-AH19-AG19 -> -12394.133 | AK19: -12030.81 | AL19: -9283.999 | AM19: -12972.845 | AN19: =J19-AM19-AL19-AK19 -> -32675.675 | AO19: -26497.446 | AP19: -45863.712 | AQ19: -34966.079 | AR19: =K19-AO19-AP19-AQ19 -> -23047.008 | AS19: -11742.475 | AT19: -13578.407 | AU19: -126.653 | AV19: =L19-AS19-AT19-AU19 -> -13604.293 | AW19: -5147.068 | AX19: -11048.467 | AY19: -7258.756 | AZ19: =M19-AW19-AX19-AY19 -> -9465.366 | BA19: -9520.27 | BB19: =-16946.774-BA19 -> -7426.504 | BC19: -3732.227 | BD19: =N19-BA19-BB19-BC19 -> -4180.268 | BE19: -2059.976
B20: Profit before tax | C20: =SUM(C15,C16,C17,C18,C19) -> 103706.86 | D20: =SUM(D15,D16,D17,D18,D19) -> -13882.373 | E20: =SUM(E15,E16,E17,E18,E19) -> 6140.064 | F20: =SUM(F15,F16,F17,F18,F19) -> 26000.924 | G20: =SUM(G15,G16,G17,G18,G19) -> -2270.976 | H20: =SUM(H15,H16,H17,H18,H19) -> 240209.84 | I20: =SUM(I15,I16,I17,I18,I19) -> 93954.056 | J20: =SUM(J15,J16,J17,J18,J19) -> 118630.36 | ... O20: =SUM(O15,O16,O17,O18,O19) -> 133480.48 | Q20: =SUM(Q15,Q16,Q17,Q18,Q19) -> 12794.007 | R20: =SUM(R15,R16,R17,R18,R19) -> -1008.107 | S20: =SUM(S15,S16,S17,S18,S19) -> 1033.507 | T20: =SUM(T15,T16,T17,T18,T19) -> -6679.343 | U20: =SUM(U15,U16,U17,U18,U19) -> 10871.554 | V20: =SUM(V15,V16,V17,V18,V19) -> -7796.357 | W20: =SUM(W15,W16,W17,W18,W19) -> 10742.478 | X20: =SUM(X15,X16,X17,X18,X19) -> 12183.249 | ... BE20: =SUM(BE15,BE16,BE17,BE18,BE19) -> 38282.962
B21: Income tax benefit/(expense) | C21: 8013.985 | D21: 12780.376 | E21: 28018.036 | F21: 17408.617 | G21: -21343.116 | H21: -86057.731 | I21: -9487.808 | J21: -43655.049 | K21: -82964.112 | L21: -31710.265 | M21: -63495.128 | N21: 102243.01 | O21: =SUM(BB21:BE21) -> 62679.768 | Q21: 11174.927 | R21: =20979.756-Q21 -> 9804.829 | S21: =29402.861-R21-Q21 -> 8423.105 | T21: =E21-S21-R21-Q21 -> -1384.825 | U21: 3254.391 | V21: =8408.878-U21 -> 5154.487 | W21: =15330.006-V21-U21 -> 6921.128 | X21: =F21-W21-V21-U21 -> 2078.611 | Y21: 8203.185 | Z21: =-2388.757-Y21 -> -10591.942 | AA21: =-5550.49-Z21-Y21 -> -3161.733 | AB21: =G21-AA21-Z21-Y21 -> -15792.626 | AC21: -7977.813 | AD21: -928.308 | AE21: -28643.649 | AF21: =H21-AE21-AD21-AC21 -> -48507.961 | AG21: -45200.064 | AH21: 2864.235 | AI21: 4783.213 | AJ21: =I21-AI21-AH21-AG21 -> 28064.808 | AK21: -8842.548 | AL21: -10736.441 | AM21: -31470.177 | AN21: =J21-AM21-AL21-AK21 -> 7394.117 | AO21: 32165.322 | AP21: -167083.23 | AQ21: -2399.995 | AR21: =K21-AO21-AP21-AQ21 -> 54353.796 | AS21: 29914.65 | AT21: -5353.759 | AU21: -48449.803 | AV21: =L21-AS21-AT21-AU21 -> -7821.353 | AW21: -49637.925 | AX21: 17931.563 | AY21: 17658.1 | AZ21: =M21-AW21-AX21-AY21 -> -49446.866 | BA21: 29045.018 | BB21: =34640.927-BA21 -> 5595.909 | BC21: -24920.226 | BD21: =N21-BA21-BB21-BC21 -> 92522.308 | BE21: -10518.223
B22: Income from Continuing Operations | C22: =SUM(C20,C21) -> 111720.84 | D22: =SUM(D20,D21) -> -1101.997 | E22: =SUM(E20,E21) -> 34158.1 | F22: =SUM(F20,F21) -> 43409.541 | G22: =SUM(G20,G21) -> -23614.092 | H22: =SUM(H20,H21) -> 154152.11 | I22: =SUM(I20,I21) -> 84466.248 | J22: =SUM(J20,J21) -> 74975.311 | ... O22: =SUM(O20,O21) -> 196160.25 | Q22: =SUM(Q20,Q21) -> 23968.934 | R22: =SUM(R20,R21) -> 8796.722 | S22: =SUM(S20,S21) -> 9456.612 | T22: =SUM(T20,T21) -> -8064.168 | U22: =SUM(U20,U21) -> 14125.945 | V22: =SUM(V20,V21) -> -2641.87 | W22: =SUM(W20,W21) -> 17663.606 | X22: =SUM(X20,X21) -> 14261.86 | ... BE22: =SUM(BE20,BE21) -> 27764.739
B23: Discontinued Operations | C23: 0 | D23: 0 | E23: 0 | F23: 0 | G23: 0 | H23: 0 | I23: 0 | J23: 0 | K23: 0 | L23: 0 | M23: 0 | N23: 0 | O23: =SUM(BB23:BE23) -> 0 | Q23: 0 | R23: 0 | S23: 0 | T23: =E23-S23-R23-Q23 -> 0 | U23: 0 | V23: 0 | W23: 0 | X23: =F23-W23-V23-U23 -> 0 | Y23: 0 | Z23: 0 | AA23: 0 | AB23: =G23-AA23-Z23-Y23 -> 0 | AC23: 0 | AD23: 0 | AE23: 0 | AF23: =H23-AE23-AD23-AC23 -> 0 | AG23: 0 | AH23: 0 | AI23: 0 | AJ23: =I23-AI23-AH23-AG23 -> 0 | AK23: 0 | AL23: 0 | AM23: 0 | AN23: =J23-AM23-AL23-AK23 -> 0 | AO23: 0 | AP23: 0 | AQ23: 0 | AR23: =K23-AO23-AP23-AQ23 -> 0 | AS23: 0 | AT23: 0 | AU23: 0 | AV23: =L23-AS23-AT23-AU23 -> 0 | AW23: 0 | AX23: 0 | AY23: 0 | AZ23: =M23-AW23-AX23-AY23 -> 0 | BA23: 0 | BB23: =0-BA23 -> 0 | BC23: 0 | BD23: =N23-BA23-BB23-BC23 -> 0 | BE23: 0
B24: Net income | C24: =C22+C23 -> 111720.84 | D24: =D22+D23 -> -1101.997 | E24: =E22+E23 -> 34158.1 | F24: =F22+F23 -> 43409.541 | G24: =G22+G23 -> -23614.092 | H24: =H22+H23 -> 154152.11 | I24: =I22+I23 -> 84466.248 | J24: =J22+J23 -> 74975.311 | ... O24: =O22+O23 -> 196160.25 | Q24: =Q22+Q23 -> 23968.934 | R24: =R22+R23 -> 8796.722 | S24: =S22+S23 -> 9456.612 | T24: =T22+T23 -> -8064.168 | U24: =U22+U23 -> 14125.945 | V24: =V22+V23 -> -2641.87 | W24: =W22+W23 -> 17663.606 | X24: =X22+X23 -> 14261.86 | ... BE24: =BE22+BE23 -> 27764.739
B26: As % of Revenues unless stated otherwise
B27: =B10 -> Salaries and Expenses / Employee Benefits Expenses | C27: =-C10/C7 -> 0.13405046 | D27: =-D10/D7 -> 0.1384086 | E27: =-E10/E7 -> 0.13150209 | F27: =-F10/F7 -> 0.12823182 | G27: =-G10/G7 -> 0.1359801 | H27: =-H10/H7 -> 0.13147827 | I27: =-I10/I7 -> 0.12261145 | J27: =-J10/J7 -> 0.10683056 | ... O27: =-O10/O7 -> 0.11743534 | Q27: =-Q10/Q7 -> 0.13186676 | R27: =-R10/R7 -> 0.13363766 | S27: =-S10/S7 -> 0.13294153 | T27: =-T10/T7 -> 0.1277447 | U27: =-U10/U7 -> 0.13657119 | V27: =-V10/V7 -> 0.12891813 | W27: =-W10/W7 -> 0.12721175 | X27: =-X10/X7 -> 0.12081496 | ... BE27: =-BE10/BE7 -> 0.12022036
B28: =B11 -> Depreciation and amortization expenses | C28: =-C11/C7 -> 0.14455275 | D28: =-D11/D7 -> 0.15332485 | E28: =-E11/E7 -> 0.16040305 | F28: =-F11/F7 -> 0.16256103 | G28: =-G11/G7 -> 0.17330665 | H28: =-H11/H7 -> 0.21359068 | I28: =-I11/I7 -> 0.22337084 | J28: =-J11/J7 -> 0.19382278 | ... O28: =-O11/O7 -> 0.19218105 | Q28: =-Q11/Q7 -> 0.15946019 | R28: =-R11/R7 -> 0.162164 | S28: =-S11/S7 -> 0.16064413 | T28: =-T11/T7 -> 0.1594019 | U28: =-U11/U7 -> 0.16427479 | V28: =-V11/V7 -> 0.16510555 | W28: =-W11/W7 -> 0.16433683 | X28: =-X11/X7 -> 0.15691906 | ... BE28: =-BE11/BE7 -> 0.19302322
B29: =B12 -> Impairment losses (reversals), Net | C29: =-C12/C7 -> 0 | D29: =-D12/D7 -> 0.030144399 | E29: =-E12/E7 -> 0.031536828 | F29: =-F12/F7 -> 0.026807818 | G29: =-G12/G7 -> 0.035848484 | H29: =-H12/H7 -> 0.035441923 | I29: =-I12/I7 -> 0.038078182 | J29: =-J12/J7 -> 0.040927129 | ... O29: =-O12/O7 -> 0.029554971 | Q29: =-Q12/Q7 -> 0.031334889 | R29: =-R12/R7 -> 0.023342269 | S29: =-S12/S7 -> 0.030142895 | T29: =-T12/T7 -> 0.040820417 | U29: =-U12/U7 -> 0.024427247 | V29: =-V12/V7 -> 0.026642791 | W29: =-W12/W7 -> 0.025871626 | X29: =-X12/X7 -> 0.030049213 | ... BE29: =-BE12/BE7 -> 0.028921366
B30: =B13 -> Other expenses | C30: =-C13/C7 -> 0.61780084 | D30: =-D13/D7 -> 0.63744526 | E30: =-E13/E7 -> 0.62580537 | F30: =-F13/F7 -> 0.62821401 | G30: =-G13/G7 -> 0.61245999 | H30: =-H13/H7 -> 0.55623554 | I30: =-I13/I7 -> 0.54061433 | J30: =-J13/J7 -> 0.55751288 | ... O30: =-O13/O7 -> 0.60016198 | Q30: =-Q13/Q7 -> 0.60505502 | R30: =-R13/R7 -> 0.63360484 | S30: =-S13/S7 -> 0.61694386 | T30: =-T13/T7 -> 0.64673061 | U30: =-U13/U7 -> 0.61601299 | V30: =-V13/V7 -> 0.64590139 | W30: =-W13/W7 -> 0.62192956 | X30: =-X13/X7 -> 0.62885424 | ... BE30: =-BE13/BE7 -> 0.60103907
B31: =B15 -> Operating Profit | C31: =C15/C7 -> 0.10979786 | D31: =D15/D7 -> 0.045300474 | E31: =E15/E7 -> 0.061249398 | F31: =F15/F7 -> 0.060412267 | G31: =G15/G7 -> 0.047519493 | H31: =H15/H7 -> 0.17380127 | I31: =I15/I7 -> 0.10153137 | J31: =J15/J7 -> 0.12220754 | ... O31: =O15/O7 -> 0.087538501 | Q31: =Q15/Q7 -> 0.076302434 | R31: =R15/R7 -> 0.051989673 | S31: =S15/S7 -> 0.064176102 | T31: =T15/T7 -> 0.05286142 | U31: =U15/U7 -> 0.065913623 | V31: =V15/V7 -> 0.038903778 | W31: =W15/W7 -> 0.067134122 | X31: =X15/X7 -> 0.069153898 | ... BE31: =BE15/BE7 -> 0.084415498
B32: Finance Income as a % of cash at end of period | C32: =C16/C118 -> 0.028551469 | D32: =D16/D118 -> 0.089264007 | E32: =E16/E118 -> 0.053671092 | F32: =F16/F118 -> 0.035878193 | G32: =G16/G118 -> 0.025976872 | H32: =H16/H118 -> 0.019550105 | I32: =I16/I118 -> 0.053805153 | J32: =J16/J118 -> 0.045301436 | ... O32: =O16/O118 -> 0.12520983 | T32: =SUM(Q16:T16)/T118 -> 0.053671092 | U32: =SUM(R16:U16)/U118 -> 0.030126738 | V32: =SUM(S16:V16)/V118 -> 0.014129165 | W32: =SUM(T16:W16)/W118 -> 0.022288379 | X32: =SUM(U16:X16)/X118 -> 0.035878193 | Y32: =SUM(V16:Y16)/Y118 -> 0.07116953 | Z32: =SUM(W16:Z16)/Z118 -> 0.048754874 | AA32: =SUM(X16:AA16)/AA118 -> 0.21489915 | ... BE32: =SUM(BB16:BE16)/BE118 -> 0.12520983
B33: Finance costs as a % of debt including leases at end of period | C33: =-C17/C116 -> 0.038065864 | D33: =-D17/D116 -> 0.042415867 | E33: =-E17/E116 -> 0.051581876 | F33: =-F17/F116 -> 0.050506168 | G33: =-G17/G116 -> 0.042991844 | H33: =-H17/H116 -> 0.039196339 | I33: =-I17/I116 -> 0.043195758 | J33: =-J17/J116 -> 0.041924574 | ... O33: =-O17/O116 -> 0.061219167 | T33: =-SUM(Q17:T17)/T116 -> 0.051581876 | U33: =-SUM(R17:U17)/U116 -> 0.051816578 | V33: =-SUM(S17:V17)/V116 -> 0.050552252 | W33: =-SUM(T17:W17)/W116 -> 0.052332811 | X33: =-SUM(U17:X17)/X116 -> 0.050506168 | Y33: =-SUM(V17:Y17)/Y116 -> 0.052972583 | Z33: =-SUM(W17:Z17)/Z116 -> 0.049183176 | AA33: =-SUM(X17:AA17)/AA116 -> 0.048477946 | ... BE33: =-SUM(BB17:BE17)/BE116 -> 0.061219167
B34: =B20 -> Profit before tax | C34: =C20/C7 -> 0.062558037 | D34: =D20/D7 -> -0.0077789278 | E34: =E20/E7 -> 0.0032875053 | F34: =F20/F7 -> 0.013381354 | G34: =G20/G7 -> -0.0011870199 | H34: =H20/H7 -> 0.12139216 | I34: =I20/I7 -> 0.044897291 | J34: =J20/J7 -> 0.049248542 | ... O34: =O20/O7 -> 0.044455213 | Q34: =Q20/Q7 -> 0.027845527 | R34: =R20/R7 -> -0.0022067146 | S34: =S20/S7 -> 0.0022088142 | T34: =T20/T7 -> -0.013814681 | U34: =U20/U7 -> 0.022954396 | V34: =V20/V7 -> -0.016285473 | W34: =W20/W7 -> 0.022384516 | X34: =X20/X7 -> 0.023850449 | ... BE34: =BE20/BE7 -> 0.050723574
B35: Income tax benefit/(expense) as a % of Profit before tax | C35: =-C21/C20 -> -0.077275361 | D35: =-D21/D20 -> 0.92061897 | E35: =-E21/E20 -> -4.5631505 | F35: =-F21/F20 -> -0.6695384 | G35: =-G21/G20 -> -9.3982129 | H35: =-H21/H20 -> 0.35826064 | I35: =-I21/I20 -> 0.10098348 | J35: =-J21/J20 -> 0.36799222 | ... O35: =-O21/O20 -> -0.46958001 | Q35: =-Q21/Q20 -> -0.87345012 | R35: =-R21/R20 -> 9.7259805 | S35: =-S21/S20 -> -8.1500222 | T35: =-T21/T20 -> -0.20732952 | U35: =-U21/U20 -> -0.2993492 | V35: =-V21/V20 -> 0.66114045 | W35: =-W21/W20 -> -0.64427667 | X35: =-X21/X20 -> -0.17061221 | ... BE35: =-BE21/BE20 -> 0.27474946
B37: capex/sales | C37: =-C63/C7 -> 0.33260349 | D37: =-D63/D7 -> 0.2931655 | E37: =-E63/E7 -> 0.24318154 | F37: =-F63/F7 -> 0.25584701 | G37: =-G63/G7 -> 0.26546149 | H37: =-H63/H7 -> -0.0064757044 | I37: =-I63/I7 -> 0.13939777 | J37: =-J63/J7 -> 0.10812001 | ... O37: =-O63/O7 -> 0.16451557 | Q37: =-Q63/Q7 -> 0.23118316 | R37: =-R63/R7 -> 0.23778357 | S37: =-S63/S7 -> 0.23813522 | T37: =-T63/T7 -> 0.26456741 | U37: =-U63/U7 -> 0.24741341 | V37: =-V63/V7 -> 0.23029247 | W37: =-W63/W7 -> 0.28192044 | X37: =-X63/X7 -> 0.26312007 | ... BE37: =-BE63/BE7 -> 0.14393768
B38: D/A/sales | C38: =C42/C7 -> 0.14681209 | D38: =D42/D7 -> 0.15451056 | E38: =E42/E7 -> 0.16618616 | F38: =F42/F7 -> 0.16454228 | G38: =G42/G7 -> 0.17563349 | H38: =H42/H7 -> 0.2155328 | I38: =I42/I7 -> 0.22543863 | J38: =J42/J7 -> 0.19847047 | ... O38: =O42/O7 -> 0.19734444 | Q38: =Q42/Q7 -> 0.16100167 | R38: =R42/R7 -> 0.1637665 | S38: =S42/S7 -> 0.16215239 | T38: =T42/T7 -> 0.17730288 | U38: =U42/U7 -> 0.16628905 | V38: =V42/V7 -> 0.16709855 | W38: =W42/W7 -> 0.16636322 | X38: =X42/X7 -> 0.15881627 | ... BE38: =BE42/BE7 -> 0.19843412
B40: EBITDA | C40: =+C3 -> 41974 | D40: =+D3 -> 42340 | E40: =+E3 -> 42707 | F40: =+F3 -> 43073 | G40: =G3 -> 43438 | H40: =H3 -> 43803 | I40: =I3 -> 44169 | J40: =J3 -> 44534 | K40: =K3 -> 44926 | L40: =L3 -> 45291 | M40: =M3 -> 45657 | N40: =N3 -> 46022 | O40: =+O3 -> 46112 | Q40: =+Q3 -> 42437 | R40: =+R3 -> 42527 | S40: =+S3 -> 42622 | T40: =+T3 -> 42714 | U40: =+U3 -> 42801 | V40: =+V3 -> 42892 | W40: =+W3 -> 42987 | X40: =+X3 -> 43079 | Y40: =+Y3 -> 43190 | Z40: =Z3 -> 43281 | AA40: =AA3 -> 43373 | AB40: =AB3 -> 43465 | AC40: =+AC3 -> 43555 | AD40: =+AD3 -> 43646 | AE40: =+AE3 -> 43738 | AF40: =+AF3 -> 43830 | AG40: =+AG3 -> 43921 | AH40: =+AH3 -> 44012 | AI40: =+AI3 -> 44104 | AJ40: =+AJ3 -> 44196 | ... BE40: =+BE3 -> 46112
B41: Operating profit | C41: =C15 -> 182019.64 | D41: =D15 -> 80843.799 | E41: =E15 -> 114395.32 | F41: =F15 -> 117385.34 | G41: =G15 -> 90913.071 | H41: =H15 -> 343916.57 | I41: =I15 -> 212469.04 | J41: =J15 -> 294374.69 | ... O41: =O15 -> 262841.65 | Q41: =Q15 -> 35058.193 | R41: =R15 -> 23750.762 | S41: =S15 -> 30028.08 | T41: =T15 -> 25558.286 | U41: =U15 -> 31217.703 | V41: =V15 -> 18624.436 | W41: =W15 -> 32218.111 | X41: =X15 -> 35325.086 | ... BE41: =BE15 -> 63711.506
B42: Depreciation & amortisation | C42: 243380.73 | D42: 275741.49 | E42: 310385.41 | F42: 319717.36 | G42: 336017.48 | H42: 426494.59 | I42: 471762.85 | J42: 478077.57 | K42: 524404.22 | L42: 512992.83 | M42: 557760.31 | N42: 585619.61 | O42: =SUM(BB42:BE42) -> 592543.14 | Q42: 73974.41 | R42: =148788.867-Q42 -> 74814.457 | S42: =224660.177-SUM(Q42:R42) -> 75871.31 | T42: =E42-SUM(Q42:S42) -> 85725.236 | U42: 78757.047 | V42: =158752.268-U42 -> 79995.221 | W42: =238591.082-SUM(U42:V42) -> 79838.814 | X42: =F42-SUM(U42:W42) -> 81126.281 | Y42: 82362.655 | Z42: =166100.984-Y42 -> 83738.329 | AA42: =250942.805-SUM(Y42:Z42) -> 84841.821 | AB42: =G42-SUM(Y42:AA42) -> 85074.677 | AC42: 102088.16 | AD42: =206851.644-AC42 -> 104763.48 | AE42: =315077.947-SUM(AC42:AD42) -> 108226.3 | AF42: =H42-SUM(AC42:AE42) -> 111416.64 | AG42: 116596.81 | AH42: =234183.773-AG42 -> 117586.96 | AI42: =352256.697-SUM(AG42:AH42) -> 118072.92 | AJ42: =I42-SUM(AG42:AI42) -> 119506.16 | AK42: 116113.26 | AL42: =231725.243-AK42 -> 115611.98 | AM42: =349893.458-SUM(AK42:AL42) -> 118168.21 | AN42: =J42-SUM(AK42:AM42) -> 128184.11 | AO42: 124298.24 | AP42: =264572.517-AO42 -> 140274.28 | AQ42: =391141.616-SUM(AO42:AP42) -> 126569.1 | AR42: =K42-SUM(AO42:AQ42) -> 133262.6 | AS42: 125691.76 | AT42: =252462.754-AS42 -> 126770.99 | AU42: =382058.243-SUM(AS42:AT42) -> 129595.49 | AV42: =L42-SUM(AS42:AU42) -> 130934.59 | AW42: 135933.67 | AX42: =278199.116-AW42 -> 142265.44 | AY42: =420571.122-SUM(AW42:AX42) -> 142372.01 | AZ42: =M42-SUM(AW42:AY42) -> 137189.19 | BA42: 142842.06 | BB42: =287730.669-BA42 -> 144888.61 | BC42: =430692.527-SUM(BA42:BB42) -> 142961.86 | BD42: =N42-SUM(BA42:BC42) -> 154927.08 | BE42: 149765.59
B43: EBITDA | C43: =SUM(C41:C42) -> 425400.36 | D43: =SUM(D41:D42) -> 356585.29 | E43: =SUM(E41:E42) -> 424780.73 | F43: =SUM(F41:F42) -> 437102.7 | G43: =SUM(G41:G42) -> 426930.55 | H43: =SUM(H41:H42) -> 770411.16 | I43: =SUM(I41:I42) -> 684231.89 | J43: =SUM(J41:J42) -> 772452.26 | ... O43: =SUM(O41:O42) -> 855384.79 | Q43: =SUM(Q41:Q42) -> 109032.6 | R43: =SUM(R41:R42) -> 98565.219 | S43: =SUM(S41:S42) -> 105899.39 | T43: =SUM(T41:T42) -> 111283.52 | U43: =SUM(U41:U42) -> 109974.75 | V43: =SUM(V41:V42) -> 98619.657 | W43: =SUM(W41:W42) -> 112056.93 | X43: =SUM(X41:X42) -> 116451.37 | ... BE43: =SUM(BE41:BE42) -> 213477.1
B44: % growth | D44: =+D43/C43-1 -> -0.16176543 | E44: =+E43/D43-1 -> 0.1912458 | F44: =+F43/E43-1 -> 0.029007825 | G44: =+G43/F43-1 -> -0.023271753 | H44: =+H43/G43-1 -> 0.80453507 | I44: =+I43/H43-1 -> -0.1118614 | J44: =+J43/I43-1 -> 0.12893344 | K44: =+K43/J43-1 -> 0.65966619 | ... N44: =+N43/M43-1 -> 0.059421035 | U44: =+U43/Q43-1 -> 0.0086409659 | V44: =+V43/R43-1 -> 0.00055230436 | W44: =+W43/S43-1 -> 0.058145141 | X44: =+X43/T43-1 -> 0.046438546 | Y44: =+Y43/U43-1 -> -0.096686139 | Z44: =+Z43/V43-1 -> -0.044588322 | AA44: =+AA43/W43-1 -> -0.044166284 | AB44: =+AB43/X43-1 -> 0.084218084 | ... BE44: =+BE43/BA43-1 -> 0.10286807
...

Sheet KPIS
B2: ENTEL | C2: Annual | D2: Annual | E2: Annual | F2: Annual | G2: Annual | H2: Annual | I2: Annual | J2: Annual | K2: Annual | L2: Annual | M2: Annual | N2: Annual | O2: Annual | P2: LTM | R2: Quarterly | S2: Quarterly | T2: Quarterly | U2: Quarterly | V2: Quarterly | W2: Quarterly | X2: Quarterly | Y2: Quarterly | Z2: Quarterly | AA2: Quarterly | AB2: Quarterly | AC2: Quarterly | AD2: Quarterly | AE2: Quarterly | AF2: Quarterly | AG2: Quarterly | AH2: Quarterly | AI2: Quarterly | AJ2: Quarterly | AK2: Quarterly | AL2: Quarterly | AM2: Quarterly | AN2: Quarterly | AO2: Quarterly | AP2: Quarterly | AQ2: Quarterly | AR2: Quarterly | AS2: Quarterly | AT2: Quarterly | AU2: Quarterly | AV2: Quarterly | AW2: Quarterly | AX2: Quarterly | AY2: Quarterly | AZ2: Quarterly | BA2: Quarterly | BB2: Quarterly | BC2: Quarterly | BD2: Quarterly | BE2: Quarterly | BF2: Quarterly
B3: (Ch$ millions) | C3: 41975 | D3: 42340 | E3: 42707 | F3: 43073 | G3: 43438 | H3: 43438 | I3: 43803 | J3: 44169 | K3: 44534 | L3: 44926 | M3: 45291 | N3: 45657 | O3: 46022 | P3: =BF3 -> 46112 | R3: 42437 | S3: 42527 | T3: 42622 | U3: 42714 | V3: 42801 | W3: 42892 | X3: 42987 | Y3: 43079 | Z3: 43190 | AA3: 43281 | AB3: 43373 | AC3: 43465 | AD3: 43555 | AE3: 43646 | AF3: 43738 | AG3: 43830 | AH3: 43921 | AI3: 44012 | AJ3: 44104 | AK3: 44196 | AL3: 44286 | AM3: 44377 | AN3: 44469 | AO3: 44561 | AP3: 44651 | AQ3: 44742 | AR3: 44834 | AS3: 44926 | AT3: 45016 | AU3: 45107 | AV3: 45199 | AW3: 45291 | AX3: 45382 | AY3: 45473 | AZ3: 45565 | BA3: 45657 | BB3: 45747 | BC3: 45838 | BD3: 45930 | BE3: 46022 | BF3: 46112
C4: Act | D4: Act | E4: Act | F4: Act | G4: Act | H4: Act | I4: Act | J4: Act | K4: Act | L4: Act | M4: Act | N4: Act | O4: Act | P4: Act | R4: Act | S4: Act | T4: Act | U4: Act | V4: Act | W4: Act | X4: Act | Y4: Act | Z4: Act | AA4: Act | AB4: Act | AC4: Act | AD4: Act | AE4: Act | AF4: Act | AG4: Act | AH4: Act | AI4: Act | AJ4: Act | AK4: Act | AL4: Act | AM4: Act | AN4: Act | AO4: Act | AP4: Act | AQ4: Act | AR4: Act | AS4: Act | AT4: Act | AU4: Act | AV4: Act | AW4: Act | AX4: Act | AY4: Act | AZ4: Act | BA4: Act | BB4: Act | BC4: Act | BD4: Act | BE4: Act | BF4: Act
C5: FY | D5: FY | E5: FY | F5: FY | G5: FY | H5: FY | I5: FY | J5: FY | K5: FY | L5: FY | M5: FY | N5: FY | O5: FY | P5: LTM | R5: Q1 | S5: Q2 | T5: Q3 | U5: Q4 | V5: Q1 | W5: Q2 | X5: Q3 | Y5: Q4 | Z5: Q1 | AA5: Q2 | AB5: Q3 | AC5: Q4 | AD5: Q1 | AE5: Q2 | AF5: Q3 | AG5: Q4 | AH5: Q1 | AI5: Q2 | AJ5: Q3 | AK5: Q4 | AL5: Q1 | AM5: Q2 | AN5: Q3 | AO5: Q4 | AP5: Q1 | AQ5: Q2 | AR5: Q3 | AS5: Q4 | AT5: Q1 | AU5: Q2 | AV5: Q3 | AW5: Q4 | AX5: Q1 | AY5: Q2 | AZ5: Q3 | BA5: Q4 | BB5: Q1 | BC5: Q2 | BD5: Q3 | BE5: Q4 | BF5: Q1
B7: Revenue by Segments
B8: Consumer | C8: 895081.71 | D8: 906619.38 | E8: 884434.6 | F8: 890684.32 | G8: 861262.83 | H8: 861262.83 | I8: 839092.67 | J8: 908564.8 | K8: 1069417.6 | L8: 1099807 | R8: 223641.22 | S8: =440677.368-R8 -> 217036.15 | T8: =658075.657-S8-R8 -> 217398.29 | U8: =E8-T8-S8-R8 -> 226358.94 | V8: 219034.59 | W8: =441203.792-V8 -> 222169.21 | X8: =659693.959-W8-V8 -> 218490.17 | Y8: =F8-X8-W8-V8 -> 230990.37 | Z8: 211645.11 | AA8: =425601.906-Z8 -> 213956.79 | AB8: =636162.288-AA8-Z8 -> 210560.38 | AC8: =H8-AB8-AA8-Z8 -> 225100.54 | AD8: 211447.79 | AE8: =413194.65-AD8 -> 201746.87 | AF8: =623214.391-AE8-AD8 -> 210019.74 | AG8: =I8-AF8-AE8-AD8 -> 215878.28 | AH8: 220500.89 | AI8: =420918.194-AH8 -> 200417.31 | AJ8: =653739.997-AH8-AI8 -> 232821.8 | AK8: =J8-AJ8-AI8-AH8 -> 254824.8 | AL8: 255744.43 | AM8: =521914.035-AL8 -> 266169.6 | AN8: =789686.56-AL8-AM8 -> 267772.53 | AO8: =K8-AN8-AM8-AL8 -> 279731.02 | AP8: 274822.06 | AQ8: =557472.167-AP8 -> 282650.11 | AR8: =821812.028-AP8-AQ8 -> 264339.86 | AS8: =L8-AP8-AQ8-AR8 -> 277994.97 | AT8: 267004.43
B9: Enterprise | C9: 296488.16 | D9: 307623.23 | E9: 303206.99 | F9: 293852.41 | G9: 281417.26 | H9: 281417.26 | I9: 258420.2 | J9: 248479.52 | K9: 266250.06 | L9: 265312.75 | R9: 76228.235 | S9: =151926.211-R9 -> 75697.976 | T9: =227221.075-S9-R9 -> 75294.864 | U9: =E9-T9-S9-R9 -> 75985.917 | V9: 74063.989 | W9: =149383.766-V9 -> 75319.777 | X9: =220788.305-W9-V9 -> 71404.539 | Y9: =F9-X9-W9-V9 -> 73064.103 | Z9: 73557.885 | AA9: =145612.934-Z9 -> 72055.049 | AB9: =213564.798-AA9-Z9 -> 67951.864 | AC9: =H9-AB9-AA9-Z9 -> 67852.462 | AD9: 65617.039 | AE9: =131531.307-AD9 -> 65914.268 | AF9: =195916.296-AE9-AD9 -> 64384.989 | AG9: =I9-AF9-AE9-AD9 -> 62503.904 | AH9: 61819.66 | AI9: =121424.285-AH9 -> 59604.625 | AJ9: =182397.994-AH9-AI9 -> 60973.709 | AK9: =J9-AJ9-AI9-AH9 -> 66081.531 | AL9: 63054.947 | AM9: =130964.334-AL9 -> 67909.387 | AN9: =198257.805-AL9-AM9 -> 67293.471 | AO9: =K9-AN9-AM9-AL9 -> 67992.259 | AP9: 63232.006 | AQ9: =129157.404-AP9 -> 65925.398 | AR9: =195203.759-AP9-AQ9 -> 66046.355 | AS9: =L9-AP9-AQ9-AR9 -> 70108.992 | AT9: 68887.652
B10: Corporate | C10: 211283.22 | D10: 220809.19 | E10: 223098.13 | F10: 226748.23 | G10: 224806.88 | H10: 224806.88 | I10: 227171.9 | J10: 236482.64 | K10: 250489.34 | L10: 252230.41 | R10: 54634.605 | S10: =109105.483-R10 -> 54470.878 | T10: =165253.832-S10-R10 -> 56148.349 | U10: =E10-T10-S10-R10 -> 57844.295 | V10: 57302.623 | W10: =111965.88-V10 -> 54663.257 | X10: =169637.433-W10-V10 -> 57671.553 | Y10: =F10-X10-W10-V10 -> 57110.794 | Z10: 53879.743 | AA10: =107835.737-Z10 -> 53955.994 | AB10: =164763.317-AA10-Z10 -> 56927.58 | AC10: =H10-AB10-AA10-Z10 -> 60043.564 | AD10: 54013.314 | AE10: =112125.32-AD10 -> 58112.006 | AF10: =169297.151-AE10-AD10 -> 57171.831 | AG10: =I10-AF10-AE10-AD10 -> 57874.749 | AH10: 53517.622 | AI10: =110884.785-AH10 -> 57367.163 | AJ10: =172022.101-AH10-AI10 -> 61137.316 | AK10: =J10-AJ10-AI10-AH10 -> 64460.541 | AL10: 53821.3 | AM10: =115750.386-AL10 -> 61929.086 | AN10: =182596.577-AL10-AM10 -> 66846.191 | AO10: =K10-AN10-AM10-AL10 -> 67892.765 | AP10: 61187.217 | AQ10: =120606.572-AP10 -> 59419.355 | AR10: =182406.406-AP10-AQ10 -> 61799.834 | AS10: =L10-AP10-AQ10-AR10 -> 69824.007 | AT10: 61938.237
B11: M. Serv.Peru | C11: 157552.71 | D11: 245329.15 | E11: 357503.12 | F11: 470592.48 | G11: 489053.02 | H11: 513507.4 | I11: 706075.74 | J11: 680167.74 | K11: 803030.91 | L11: 931642.21 | R11: 81205.092 | S11: =165931.915-R11 -> 84726.823 | T11: =258143.36-S11-R11 -> 92211.445 | U11: =E11-T11-S11-R11 -> 99359.757 | V11: 104826.2 | W11: =216133.498-V11 -> 111307.3 | X11: =336376.699-W11-V11 -> 120243.2 | Y11: =F11-X11-W11-V11 -> 134215.78 | Z11: 110263.73 | AA11: =223731.28-Z11 -> 113467.55 | AB11: =351884.754-AA11-Z11 -> 128153.47 | AC11: =H11-AB11-AA11-Z11 -> 161622.65 | AD11: 135105.93 | AE11: =284362.522-AD11 -> 149256.59 | AF11: =442462.785-AE11-AD11 -> 158100.26 | AG11: =I11-AF11-AE11-AD11 -> 263612.95 | AH11: 172827.85 | AI11: =311215.676-AH11 -> 138387.82 | AJ11: =485298.351-AH11-AI11 -> 174082.68 | AK11: =J11-AJ11-AI11-AH11 -> 194869.39 | AL11: 178622.67 | AM11: =370058.286-AL11 -> 191435.62 | AN11: =572030.287-AL11-AM11 -> 201972 | AO11: =K11-AN11-AM11-AL11 -> 231000.62 | AP11: 236412.59 | AQ11: =478148.667-AP11 -> 241736.08 | AR11: =703047.342-AP11-AQ11 -> 224898.67 | AS11: =L11-AP11-AQ11-AR11 -> 228594.87 | AT11: 203282.11
B12: Other businesses | C12: 433833.29 | D12: 550595.88 | E12: 691718.68 | F12: 787552.79 | G12: 875725.2 | H12: 851270.81 | I12: 965676.63 | J12: 934634.36 | K12: 956928.75 | L12: 1146092.8 | R12: 146657.24 | S12: =304552.99-R12 -> 157895.75 | T12: =483823.735-S12-R12 -> 179270.75 | U12: =E12-T12-S12-R12 -> 207894.94 | V12: 184112.83 | W12: =376737.385-V12 -> 192624.55 | X12: =574697.108-W12-V12 -> 197959.72 | Y12: =F12-X12-W12-V12 -> 212855.68 | Z12: 205020.86 | AA12: =423276.832-Z12 -> 218255.97 | AB12: =644243.208-AA12-Z12 -> 220966.38 | AC12: =H12-AB12-AA12-Z12 -> 207027.6 | AD12: 199264.82 | AE12: =400609.626-AD12 -> 201344.81 | AF12: =616086.195-AE12-AD12 -> 215476.57 | AG12: =I12-AF12-AE12-AD12 -> 349590.43 | AH12: 217437.98 | AI12: =452471.234-AH12 -> 235033.26 | AJ12: =693779.017-AH12-AI12 -> 241307.78 | AK12: =J12-AJ12-AI12-AH12 -> 240855.34 | AL12: 231398.51 | AM12: =475486.58-AL12 -> 244088.07 | AN12: =713083.937-AL12-AM12 -> 237597.36 | AO12: =K12-AN12-AM12-AL12 -> 243844.81 | AP12: 251639.61 | AQ12: =517640.049-AP12 -> 266000.44 | AR12: =870171.263-AP12-AQ12 -> 352531.21 | AS12: =L12-AP12-AQ12-AR12 -> 275921.51 | AT12: 306268.15
B13: Withdrawals | C13: -336468.72 | D13: -446364.16 | E13: -592264.44 | F13: -726359.03 | G13: -819090.9 | H13: -809305.56 | I13: -798893.3 | J13: -860844.64 | K13: -885997.24 | L13: -1106564.7 | R13: -122902.77 | S13: =-255894.193-R13 -> -132991.43 | T13: =-408316.606-S13-R13 -> -152422.41 | U13: =E13-T13-S13-R13 -> -183947.84 | V13: -165724.89 | W13: =-343078.204-V13 -> -177353.32 | X13: =-528940.745-W13-V13 -> -185862.54 | Y13: =F13-X13-W13-V13 -> -197418.29 | Z13: -193185.76 | AA13: =-399201.281-Z13 -> -206015.52 | AB13: =-602436.522-AA13-Z13 -> -203235.24 | AC13: =H13-AB13-AA13-Z13 -> -206869.03 | AD13: -190664.12 | AE13: =-381599.87-AD13 -> -190935.75 | AF13: =-588265.489-AE13-AD13 -> -206665.62 | AG13: =I13-AF13-AE13-AD13 -> -210627.81 | AH13: -195398.66 | AI13: =-410115.288-AH13 -> -214716.62 | AJ13: =-637398.726-AH13-AI13 -> -227283.44 | AK13: =J13-AJ13-AI13-AH13 -> -223445.91 | AL13: -213882.81 | AM13: =-436961.443-AL13 -> -223078.63 | AN13: =-655097.2-AL13-AM13 -> -218135.76 | AO13: =K13-AN13-AM13-AL13 -> -230900.04 | AP13: -237352.67 | AQ13: =-489290.186-AP13 -> -251937.51 | AR13: =-822245.791-AP13-AQ13 -> -332955.6 | AS13: =L13-AP13-AQ13-AR13 -> -284318.93 | AT13: -294042.27
B14: Un-Assigned | L14: 549189.18 | AQ14: =485773.466-AP14 -> 485773.47 | AR14: =544708.577-AP14-AQ14 -> 58935.111 | AS14: =L14-AP14-AQ14-AR14 -> 4480.605
B15: Total Revenue | C15: =SUM(C8:C13) -> 1657770.4 | D15: =SUM(D8:D13) -> 1784612.7 | E15: =SUM(E8:E13) -> 1867697.1 | F15: =SUM(F8:F13) -> 1943071.2 | G15: =SUM(G8:G13) -> 1913174.3 | H15: =SUM(H8:H13) -> 1922959.6 | I15: =SUM(I8:I13) -> 2197543.8 | J15: =SUM(J8:J13) -> 2147484.4 | K15: =SUM(K8:K13) -> 2460119.4 | L15: =SUM(L8:L14) -> 3137709.6 | R15: =SUM(R8:R13) -> 459463.63 | S15: =SUM(S8:S13) -> 456836.15 | T15: =SUM(T8:T13) -> 467901.28 | U15: =SUM(U8:U13) -> 483496.02 | V15: =SUM(V8:V13) -> 473615.34 | W15: =SUM(W8:W13) -> 478730.78 | X15: =SUM(X8:X13) -> 479906.64 | Y15: =SUM(Y8:Y13) -> 510818.44 | ... AP15: =SUM(AP8:AP13) -> 649940.8 | AQ15: =SUM(AQ8:AQ14) -> 1149567.3 | AR15: =SUM(AR8:AR14) -> 695595.45 | AS15: =SUM(AS8:AS14) -> 642606.03 | AT15: =SUM(AT8:AT13) -> 613338.3
B17: check | C17: =C15-Model!C7 -> 0 | D17: =D15-Model!D7 -> 0 | E17: =E15-Model!E7 -> 0 | F17: =F15-Model!F7 -> 0 | G17: =G15-Model!G7 -> 0 | H17: =H15-(Model!G7+Model!G9+Model!G14) -> 0 | I17: =I15-(Model!H7+Model!H9+Model!H14) -> 1 | J17: =J15-(Model!I7+Model!I9+Model!I14) -> 0 | K17: =K15-(Model!J7+Model!J9+Model!J14) -> 0 | L17: =L15-(Model!K7+Model!K9+Model!K14) -> 0.044 | R17: =R15-Model!Q7 -> 0 | S17: =S15-Model!R7 -> 0 | T17: =T15-Model!S7 -> 0 | U17: =U15-Model!T7 -> 0 | V17: =V15-Model!U7 -> 0 | W17: =W15-Model!V7 -> 0 | X17: =X15-Model!W7 -> 0 | Y17: =Y15-Model!X7 -> 0 | ... AB17: =AB15-Model!AA7 -> 0 | AD17: =AD15-(Model!AC7+Model!AC9+Model!AC14) -> 0 | AE17: =AE15-(Model!AD7+Model!AD9+Model!AD14) -> 0 | AF17: =AF15-(Model!AE7+Model!AE9+Model!AE14) -> 0 | AG17: =AG15-(Model!AF7+Model!AF9+Model!AF14) -> 1 | AH17: =AH15-(Model!AG7+Model!AG9+Model!AG14) -> 0 | AI17: =AI15-(Model!AH7+Model!AH9+Model!AH14) -> 0 | AJ17: =AJ15-(Model!AI7+Model!AI9+Model!AI14) -> 0 | AK17: =AK15-(Model!AJ7+Model!AJ9+Model!AJ14) -> 0 | ... AT17: =AT15-(Model!AS7+Model!AS9+Model!AS14) -> 0
B19: Revenue by Segments
B20: Consumer | M20: 1069314 | N20: 1174516 | O20: 1259066.9 | P20: =SUM(BC20:BF20) -> 1291499.1 | AQ20: 557472.17 | AR20: =821812.028-AQ20 -> 264339.86 | AS20: =1099806.956-AR20-AQ20-AP20 -> 277994.93 | AT20: 267004.43 | AU20: 528132.27 | AV20: =785819.121-AU20 -> 257686.85 | AW20: =1069313.998-AV20-AU20-AT20 -> 16490.449 | AX20: 275362.65 | AY20: =561627.796-AX20 -> 286265.14 | AZ20: =850184.207-AY20-AX20 -> 288556.41 | BA20: =N20-(AZ20+AY20+AX20) -> 324331.79 | BB20: 305177.14 | BC20: =603697.209-BB20 -> 298520.07 | BD20: =913447.031-BC20-BB20 -> 309749.82 | BE20: =O20-(BD20+BC20+BB20) -> 345619.92 | BF20: 337609.26
B21: B2B'Enterprise | M21: 425230.36 | N21: 454475.62 | O21: 471205.43 | P21: =SUM(BC21:BF21) -> 474783.26 | AQ21: 197227.38 | AR21: =298696.858-AQ21 -> 101469.48 | AS21: =409101.469-AR21-AQ21-AP21 -> 110404.61 | AT21: 103643.74 | AU21: 210945.58 | AV21: =311684.315-AU21 -> 100738.74 | AW21: =425230.358-AV21-AU21-AT21 -> 9902.305 | AX21: 107373.44 | AY21: =218317.691-AX21 -> 110944.25 | AZ21: =328985.203-AY21-AX21 -> 110667.51 | BA21: =N21-(AZ21+AY21+AX21) -> 125490.42 | BB21: 114922.49 | BC21: =232731.801-BB21 -> 117809.31 | BD21: =351039.001-BC21-BB21 -> 118307.2 | BE21: =O21-(BD21+BC21+BB21) -> 120166.43 | BF21: 118500.32
B22: Digital Business | M22: 121639.04 | N22: 127797.15 | O22: 136124.7 | P22: =SUM(BC22:BF22) -> 134910.05 | AQ22: 52536.599 | AR22: =78913.308-AQ22 -> 26376.709 | AS22: =108441.696-AR22-AQ22-AP22 -> 29528.388 | AT22: 27182.152 | AU22: 59656.763 | AV22: =88574.627-AU22 -> 28917.864 | AW22: =121639.036-AV22-AU22-AT22 -> 5882.257 | AX22: 30061.328 | AY22: =61330.209-AX22 -> 31268.881 | AZ22: =92899.209-AY22-AX22 -> 31569 | BA22: =N22-(AZ22+AY22+AX22) -> 34897.938 | BB22: 31665.012 | BC22: =63589.388-BB22 -> 31924.376 | BD22: =96069.253-BC22-BB22 -> 32479.865 | BE22: =O22-(BD22+BC22+BB22) -> 40055.446 | BF22: 30450.363
B23: M. Serv.Peru | M23: 848160.32 | N23: 956750.19 | O23: 1087917.5 | P23: =SUM(BC23:BF23) -> 1107143 | AQ23: 474140.88 | AR23: =703047.342-AQ23 -> 228906.46 | AS23: =931590.085-AR23-AQ23-AP23 -> 228542.74 | AT23: 203282.11 | AU23: 404276.06 | AV23: =620406.788-AU23 -> 216130.72 | AW23: =848160.321-AV23-AU23-AT23 -> 24471.418 | AX23: 234775.24 | AY23: =466234.522-AX23 -> 231459.28 | AZ23: =704668.514-AY23-AX23 -> 238433.99 | BA23: =N23-(AZ23+AY23+AX23) -> 252081.68 | BB23: 256299.7 | BC23: =513806.726-BB23 -> 257507.02 | BD23: =786777.496-BC23-BB23 -> 272970.77 | BE23: =O23-(BD23+BC23+BB23) -> 301139.97 | BF23: 275525.25
B24: Other businesses | M24: 1248089.6 | N24: 1242740 | O24: 1353541.6 | P24: =SUM(BC24:BF24) -> 1367744.8 | AQ24: 482444.25 | AR24: =870171.263-AQ24 -> 387727.01 | AS24: =1158491.777-AR24-AQ24-AP24 -> 288320.51 | AT24: 306268.15 | AU24: 615537.35 | AV24: =931413.902-AU24 -> 315876.55 | AW24: =1248089.636-AV24-AU24-AT24 -> 10407.588 | AX24: 304515.51 | AY24: =620990.349-AX24 -> 316474.84 | AZ24: =931185.302-AY24-AX24 -> 310194.95 | BA24: =N24-(AZ24+AY24+AX24) -> 311554.73 | BB24: 323318.58 | BC24: =662202.271-BB24 -> 338883.69 | BD24: =1001147.473-BC24-BB24 -> 338945.2 | BE24: =O24-(BD24+BC24+BB24) -> 352394.11 | BF24: 337521.75
B25: Un-Assigned | M25: 52251.177 | N25: 4227.887 | O25: 0 | P25: =SUM(BC25:BF25) -> -1411.434 | AQ25: 489781.26 | AR25: =549080.439-AQ25 -> 59299.184 | AS25: =536842.311-AR25-AQ25-AP25 -> -12238.128 | AT25: 0 | AU25: 0 | AV25: =0-AU25 -> 0 | AW25: =52251.177-AV25-AU25-AT25 -> 52251.177 | AX25: 0 | AY25: =0-AX25 -> 0 | AZ25: =0-AY25-AX25 -> 0 | BA25: =N25-(AZ25+AY25+AX25) -> 4227.887 | BB25: 1411.434 | BC25: =1411.434-BB25 -> 0 | BD25: =1411.434 -BC25-BB25 -> 0 | BE25: =O25-(BD25+BC25+BB25) -> -1411.434 | BF25: 0
B26: Withdrawals | M26: -1191542.6 | N26: -1195746.6 | O26: -1275555.1 | P26: =SUM(BC26:BF26) -> -1291400.3 | AQ26: -454094.39 | AR26: =-826617.654-AQ26 -> -372523.26 | AS26: =-1106564.722-AR26-AQ26-AP26 -> -279947.07 | AT26: -294042.27 | AU26: -587486.8 | AV26: =-889399.237-AU26 -> -301912.43 | AW26: =-1191542.603-AV26-AU26-AT26 -> -8101.092 | AX26: -287444.81 | AY26: =-583434.31-AX26 -> -295989.5 | AZ26: =-889411.817-AY26-AX26 -> -305977.51 | BA26: =N26-(AZ26+AY26+AX26) -> -306334.79 | BB26: -308179.14 | BC26: =-629806.045-BB26 -> -321626.91 | BD26: =-954705.731-BC26-BB26 -> -324899.69 | BE26: =O26-(BD26+BC26+BB26) -> -320849.35 | BF26: -324024.4
B27: Total Revenue | C27: =SUM(C20:C25) -> 0 | D27: =SUM(D20:D25) -> 0 | E27: =SUM(E20:E25) -> 0 | F27: =SUM(F20:F25) -> 0 | G27: =SUM(G20:G25) -> 0 | H27: =SUM(H20:H25) -> 0 | I27: =SUM(I20:I25) -> 0 | J27: =SUM(J20:J25) -> 0 | K27: =SUM(K20:K25) -> 0 | L27: =SUM(L20:L26) -> 0 | M27: =SUM(M20:M26) -> 2573141.9 | N27: =SUM(N20:N26) -> 2764760.3 | O27: =SUM(O20:O26) -> 3032301.1 | P27: =SUM(P20:P26) -> 3083268.4 | R27: =SUM(R20:R25) -> 0 | S27: =SUM(S20:S25) -> 0 | T27: =SUM(T20:T25) -> 0 | U27: =SUM(U20:U25) -> 0 | V27: =SUM(V20:V25) -> 0 | W27: =SUM(W20:W25) -> 0 | X27: =SUM(X20:X25) -> 0 | Y27: =SUM(Y20:Y25) -> 0 | ... AP27: =SUM(AP20:AP25) -> 0 | AQ27: =SUM(AQ20:AQ26) -> 1799508.1 | AR27: =SUM(AR20:AR26) -> 695595.45 | AS27: =SUM(AS20:AS26) -> 642605.99 | AT27: =SUM(AT20:AT26) -> 613338.3 | AU27: =SUM(AU20:AU26) -> 1231061.2 | AV27: =SUM(AV20:AV26) -> 617438.3 | AW27: =SUM(AW20:AW26) -> 111304.1 | AX27: =SUM(AX20:AX26) -> 664643.37 | ... BF27: =SUM(BF20:BF26) -> 775582.55
B28: check | M28: =M27-(Model!L7+Model!L9+Model!L14) -> 0 | N28: =N27-(Model!M7+Model!M9+Model!M14) -> 0 | O28: =O27-(Model!N7+Model!N9+Model!N14) -> 0 | P28: =P27-(Model!O7+Model!O9+Model!O14) -> 0 | AY28: =AY27-(Model!AX7+Model!AX9+Model!AX14) -> 0 | AZ28: =AZ27-(Model!AY7+Model!AY9+Model!AY14) -> 0 | BA28: =BA27-(Model!AZ7+Model!AZ9+Model!AZ14) -> 0 | BB28: =BB27-(Model!BA7+Model!BA9+Model!BA14) -> 0 | BC28: =BC27-(Model!BB7+Model!BB9+Model!BB14) -> 0 | BD28: =BD27-(Model!BC7+Model!BC9+Model!BC14) -> 0 | BE28: =BE27-(Model!BD7+Model!BD9+Model!BD14) -> 0 | BF28: =BF27-(Model!BE7+Model!BE9+Model!BE14) -> 0
B30: Revenue by Segments (Share %)
B31: Consumer | M31: =M20/M$27 -> 0.41556744 | N31: =N20/N$27 -> 0.42481658 | O31: =O20/O$27 -> 0.41521832 | P31: =P20/P$27 -> 0.41887339 | AQ31: =AQ20/AQ$27 -> 0.30979141 | AR31: =AR20/AR$27 -> 0.38001954 | AS31: =AS20/AS$27 -> 0.43260557 | AT31: =AT20/AT$27 -> 0.43532978 | AU31: =AU20/AU$27 -> 0.42900569 | AV31: =AV20/AV$27 -> 0.41734834 | AW31: =AW20/AW$27 -> 0.1481567 | AX31: =AX20/AX$27 -> 0.41430136 | ... BF31: =BF20/BF$27 -> 0.43529765
B32: B2B'Enterprise | M32: =M21/M$27 -> 0.16525725 | N32: =N21/N$27 -> 0.16438157 | O32: =O21/O$27 -> 0.15539533 | P32: =P21/P$27 -> 0.153987 | AQ32: =AQ21/AQ$27 -> 0.10960071 | AR32: =AR21/AR$27 -> 0.14587427 | AS32: =AS21/AS$27 -> 0.17180763 | AT32: =AT21/AT$27 -> 0.16898299 | AU32: =AU21/AU$27 -> 0.17135263 | AV32: =AV21/AV$27 -> 0.16315596 | AW32: =AW21/AW$27 -> 0.088966218 | AX32: =AX21/AX$27 -> 0.16155046 | ... BF32: =BF21/BF$27 -> 0.1527888
B33: Digital Business | M33: =M22/M$27 -> 0.047272572 | N33: =N22/N$27 -> 0.046223591 | O33: =O22/O$27 -> 0.044891552 | P33: =P22/P$27 -> 0.043755533 | AQ33: =AQ22/AQ$27 -> 0.029194977 | AR33: =AR22/AR$27 -> 0.037919611 | AS33: =AS22/AS$27 -> 0.045951 | AT33: =AT22/AT$27 -> 0.044318367 | AU33: =AU22/AU$27 -> 0.048459624 | AV33: =AV22/AV$27 -> 0.046835229 | AW33: =AW22/AW$27 -> 0.052848519 | AX33: =AX22/AX$27 -> 0.045229261 | ... BF33: =BF22/BF$27 -> 0.039261279
B34: M. Serv.Peru | M34: =M23/M$27 -> 0.3296205 | N34: =N23/N$27 -> 0.34605177 | O34: =O23/O$27 -> 0.35877621 | P34: =P23/P$27 -> 0.35908098 | AQ34: =AQ23/AQ$27 -> 0.2634836 | AR34: =AR23/AR$27 -> 0.32907988 | AS34: =AS23/AS$27 -> 0.35564988 | AT34: =AT23/AT$27 -> 0.33143554 | AU34: =AU23/AU$27 -> 0.32839639 | AV34: =AV23/AV$27 -> 0.35004425 | AW34: =AW23/AW$27 -> 0.21986088 | AX34: =AX23/AX$27 -> 0.35323491 | ... BF34: =BF23/BF$27 -> 0.35524942
B35: Other businesses | M35: =M24/M$27 -> 0.485045 | N35: =N24/N$27 -> 0.44949287 | O35: =O24/O$27 -> 0.44637441 | P35: =P24/P$27 -> 0.44360224 | AQ35: =AQ24/AQ$27 -> 0.26809784 | AR35: =AR24/AR$27 -> 0.55740303 | AS35: =AS24/AS$27 -> 0.44867387 | AT35: =AT24/AT$27 -> 0.49934619 | AU35: =AU24/AU$27 -> 0.50000548 | AV35: =AV24/AV$27 -> 0.51159209 | AW35: =AW24/AW$27 -> 0.09350588 | AX35: =AX24/AX$27 -> 0.45816376 | ... BF35: =BF24/BF$27 -> 0.43518482
B36: Un-Assigned | M36: =M25/M$27 -> 0.020306372 | N36: =N25/N$27 -> 0.0015292056 | O36: =O25/O$27 -> 0 | P36: =P25/P$27 -> -0.00045777202 | AQ36: =AQ25/AQ$27 -> 0.27217507 | AR36: =AR25/AR$27 -> 0.085249529 | AS36: =AS25/AS$27 -> -0.019044528 | AT36: =AT25/AT$27 -> 0 | AU36: =AU25/AU$27 -> 0 | AV36: =AV25/AV$27 -> 0 | AW36: =AW25/AW$27 -> 0.46944521 | AX36: =AX25/AX$27 -> 0 | ... BF36: =BF25/BF$27 -> 0
B37: Withdrawals | M37: =M26/M$27 -> -0.46306913 | N37: =N26/N$27 -> -0.43249558 | O37: =O26/O$27 -> -0.42065582 | P37: =P26/P$27 -> -0.41884137 | AQ37: =AQ26/AQ$27 -> -0.25234362 | AR37: =AR26/AR$27 -> -0.53554586 | AS37: =AS26/AS$27 -> -0.43564342 | AT37: =AT26/AT$27 -> -0.47941286 | AU37: =AU26/AU$27 -> -0.47721981 | AV37: =AV26/AV$27 -> -0.48897587 | AW37: =AW26/AW$27 -> -0.072783409 | AX37: =AX26/AX$27 -> -0.43247976 | ... BF37: =BF26/BF$27 -> -0.41778197
B38: Total Revenue | M38: =SUM(M31:M37) -> 1 | N38: =SUM(N31:N37) -> 1 | O38: =SUM(O31:O37) -> 1 | P38: =SUM(P31:P37) -> 1 | AQ38: =SUM(AQ31:AQ37) -> 1 | AR38: =SUM(AR31:AR37) -> 1 | AS38: =SUM(AS31:AS37) -> 1 | AT38: =SUM(AT31:AT37) -> 1 | AU38: =SUM(AU31:AU37) -> 1 | AV38: =SUM(AV31:AV37) -> 1 | AW38: =SUM(AW31:AW37) -> 1 | AX38: =SUM(AX31:AX37) -> 1 | ... BF38: =SUM(BF31:BF37) -> 1
