Workbook
Name IQ_CH: 110000
Name IQ_CQ: 5000
Name IQ_CY: 10000
Name IQ_DAILY: 500000
Name IQ_FH: 100000
Name IQ_FQ: 500
Name IQ_FY: 1000
Name IQ_LTM: 2000
Name IQ_MONTH: 15000
Name IQ_NTM: 6000
Name IQ_WEEK: 50000
Name IQ_YTD: 3000

Sheet Capitalization
A3: 2Q26 | I3: Exchange rate as at end | J3: =1/Model!$AV$202 -> 0.016299919
I4: LTM Average exchange rate | J4: =1/AVERAGE(Model!$AS$201:$AV$201) -> 0.016968134
B6: Debt Breakdown as on 30-Jun-2026 | C6: PHP (mn) | D6: USD (mn) | E6: Leverage (PHP) | F6: Leverage (USD) | I6: Company reported | J6: =C6 -> PHP (mn)
B7: Interest-bearing financial liabilities | I7: Net debt | J7: 287339
B8: Long -term | C8: 267008 | D8: =C8*$J3 -> 4352.2086 | I8: Net debt to EBITDA | J8: 2.6x
B9: Short term | C9: 30917 | D9: =C9*$J3 -> 503.94458
B11: Lease Liabilites
B12: Long -term | C12: 52905 | D12: =C12*$J3 -> 862.34719
B13: Short tem | C13: 10187 | D13: =C13*$J3 -> 166.04727
B15: Total loan and borrowing | C15: =SUM(C8,C9,C12,C13) -> 361017 | D15: =SUM(D8,D9,D12,D13) -> 5884.5477 | E15: =C15/C20 -> 3.2306061 | F15: =D15/D20 -> 3.1033829
B16: Total cash and cash equivalents | C16: =Model!AV$119 -> 11906 | D16: =C16*$J3 -> 194.06683
B17: Net debt | C17: =C15-C16 -> 349111 | D17: =D15-D16 -> 5690.4808 | E17: =C17/C20 -> 3.1240638 | F17: =D17/D20 -> 3.0010362
B18: Equity | C18: =Model!AV$126 -> 114267 | D18: =C18*$J3 -> 1862.5428
B19: Total Capitalisation | C19: =C17+C18 -> 463378 | D19: =D17+D18 -> 7553.0236
B20: LTM Adjusted EBITDA | C20: =Model!AV$84 -> 111749 | D20: =C20*$J4 -> 1896.172
B21: check | C21: =C15-Model!AV$123 -> 0
B24: =B6 -> Debt Breakdown as on 30-Jun-2026 | C24: =C6 -> PHP (mn) | D24: =D6 -> USD (mn) | E24: =E6 -> Leverage (PHP) | F24: =F6 -> Leverage (USD)
B25: U.S. Dollar Debts
B26: Fixed Rate Notes
B27: 2.5000% to 3.4500% in 2026 and 2025 | C27: 36291 | D27: =C27*$J3 -> 591.54034
B28: Term Loans
B29: Unsecured Term Loans : SOFR + 1.31161 % in 2026 and 2025 | C29: 3849 | D29: =C29*$J3 -> 62.738386
B31: Philippine Peso Debts
B32: Term Loans
B33: Unsecured Term Loans : 4.0000% to 5.3500%; PHP BVAL + 0.4000% to 0.9000% in 2026; 4.0000% to 5.3500%; PHP BVAL + 0.4000% to 1.1250% (floor rate 4.5000% to 4.6250%) in 2025 | C33: 257485 | D33: =C33*$J3 -> 4196.9845
B34: Total Long term debt | C34: =SUM(C27,C29,C33) -> 297625 | D34: =SUM(D27,D29,D33) -> 4851.2632
B35: Less portion maturing within one year | C35: 30617 | D35: =C35*$J3 -> 499.0546
B36: Non current portion of long-term debt | C36: =+C34-C35 -> 267008 | D36: =+D34-D35 -> 4352.2086
B38: Long-term debt maturing within one year | C38: =C35 -> 30617 | D38: =D35 -> 499.0546
B39: Short-term debt | C39: 300 | D39: =C39*$J3 -> 4.8899756
B40: Total Debt | C40: =+C36+C38+C39 -> 297925 | D40: =+D36+D38+D39 -> 4856.1532
B42: Current portion of lease liabilities | C42: =C13 -> 10187 | D42: =C42*$J3 -> 166.04727
B43: Noncurrent portion of lease liabilities | C43: =C12 -> 52905 | D43: =C43*$J3 -> 862.34719
B44: Total Debt (including lease liabilities) | C44: =C40+C42+C43 -> 361017 | D44: =D40+D42+D43 -> 5884.5477 | E44: =C44/C49 -> 3.2306061 | F44: =D44/D49 -> 3.1033829
B45: Cash & Cash Equivalents | C45: =Model!AV$119 -> 11906 | D45: =C45*$J3 -> 194.06683
B46: Net debt | C46: =C44-C45 -> 349111 | D46: =D44-D45 -> 5690.4808 | E46: =C46/C49 -> 3.1240638 | F46: =D46/D49 -> 3.0010362
B47: Equity | C47: =Model!AV$126 -> 114267 | D47: =C47*$J3 -> 1862.5428
B48: Total Capitalisation | C48: =C46+C47 -> 463378 | D48: =D46+D47 -> 7553.0236
B49: LTM Adjusted EBITDA | C49: =Model!AV$84 -> 111749 | D49: =C49*J4 -> 1896.172
B50: check | C50: =C44-Model!AV$123 -> 0
...

Sheet Model
B2: PLDT INC. | C2: Annual | D2: Annual | E2: Annual | F2: Annual | G2: Annual | H2: Annual | I2: Annual | J2: Annual | K2: Annual | L2: Annual | M2: LTM | O2: Quarter | P2: Quarter | Q2: Quarter | R2: Quarter | S2: Quarter | T2: Quarter | U2: Quarter | V2: Quarter | W2: Quarter | X2: Quarter | Y2: Quarter | Z2: Quarter | AA2: Quarter | AB2: Quarter | AC2: Quarter | AD2: Quarter | AE2: Quarter | AF2: Quarter | AG2: Quarter | AH2: Quarter | AI2: Quarter | AJ2: Quarter | AK2: Quarter | AL2: Quarter | AM2: Quarter | AN2: Quarter | AO2: Quarter | AP2: Quarter | AQ2: Quarter | AR2: Quarter | AS2: Quarter | AT2: Quarter | AU2: Quarter | AV2: Quarter | AY2: Quarter
B3: (PHP millions) | C3: 42735 | D3: 43100 | E3: 43465 | F3: 43830 | G3: 44196 | H3: 44561 | I3: 44926 | J3: 45291 | K3: 45657 | L3: 46022 | M3: =AV3 -> 46203 | O3: 43190 | P3: 43281 | Q3: 43373 | R3: 43465 | S3: 43555 | T3: 43646 | U3: 43738 | V3: 43830 | W3: 43921 | X3: 44012 | Y3: 44104 | Z3: 44196 | AA3: 44286 | AB3: 44348 | AC3: 44469 | AD3: 44561 | AE3: 44651 | AF3: 44742 | AG3: 44834 | AH3: 44926 | AI3: 45016 | AJ3: 45107 | AK3: 45199 | AL3: 45291 | AM3: 45382 | AN3: 45473 | AO3: 45565 | AP3: 45657 | AQ3: 45747 | AR3: 45838 | AS3: 45930 | AT3: 46022 | AU3: 46112 | AV3: 46203 | AY3: 44104
C4: Act | D4: Act | E4: Act | F4: Act | G4: Act | H4: Act | I4: Act | J4: Act | K4: Act | L4: Act | M4: Act | O4: Act | P4: Act | Q4: Act | R4: Act | S4: Act | T4: Act | U4: Act | V4: Act | W4: Act | X4: Act | Y4: Act | Z4: Act | AA4: Act | AB4: Act | AC4: Act | AD4: Act | AE4: Restated | AF4: Restated | AG4: Restated | AH4: Act | AI4: Act | AJ4: Act | AK4: Act | AL4: Act | AM4: Act | AN4: Act | AO4: Act | AP4: Act | AQ4: Act | AR4: Act | AS4: Act | AT4: Act | AU4: Act | AV4: Act | AY4: Act
C5: FY 16 | D5: FY 17 | E5: FY 18 | F5: FY 19 | G5: FY 20 | H5: FY 21 | I5: FY 22 | J5: FY 23 | K5: FY 24 | L5: FY 24 | M5: LTM | O5: Q1 18 | P5: Q2 18 | Q5: Q3 18 | R5: Q4 18 | S5: Q1 19 | T5: Q2 19 | U5: Q3 19 | V5: Q4 19 | W5: Q1 20 | X5: Q2 20 | Y5: Q3 20 | Z5: Q4 20 | AA5: Q1 21 | AB5: Q2 21 | AC5: Q3 21 | AD5: Q4 21 | AE5: Q1 22 | AF5: Q2 22 | AG5: Q3 22 | AH5: Q4 22 | AI5: Q1 23 | AJ5: Q2 23 | AK5: Q3 23 | AL5: Q4 23 | AM5: Q1 24 | AN5: Q2 24 | AO5: Q3 24 | AP5: Q4 24 | AQ5: Q1 25 | AR5: Q2 25 | AS5: Q3 25 | AT5: Q4 25 | AU5: Q1 26 | AV5: Q2 25 | AY5: Q3 20
B6: INCOME STATEMENT | AY6: Restated
B7: Service revenues | C7: 157210 | D7: 150172 | E7: 152369 | F7: 161355 | G7: 173634 | H7: 184680 | I7: 195344 | J7: 201832 | K7: 208382 | L7: 212186 | M7: =SUM(AS7:AV7) -> 214610 | O7: 37745 | P7: 38616 | Q7: 38015 | R7: =E7-Q7-P7-O7 -> 37993 | S7: 38792 | T7: 39564 | U7: 40652 | V7: =F7-U7-T7-S7 -> 42347 | W7: 41797 | X7: 41685 | Y7: 44367 | Z7: =G7-Y7-X7-W7 -> 45785 | AA7: 45677 | AB7: 45916 | AC7: 46867 | AD7: =H7-AC7-AB7-AA7 -> 46220 | AE7: 47651 | AF7: 48849 | AG7: 49215 | AH7: =I7-AG7-AF7-AE7 -> 49629 | AI7: 49726 | AJ7: 49525 | AK7: 50501 | AL7: =J7-AK7-AJ7-AI7 -> 52080 | AM7: 52195 | AN7: 51248 | AO7: 51552 | AP7: =K7-AO7-AN7-AM7 -> 53387 | AQ7: 53421 | AR7: 52887 | AS7: 52595 | AT7: =L7-AS7-AR7-AQ7 -> 53283 | AU7: 54905 | AV7: 53827 | AY7: 44367
B8: % growth | D8: =D7/C7-1 -> -0.044768145 | E8: =E7/D7-1 -> 0.014629891 | F8: =F7/E7-1 -> 0.058975251 | G8: =G7/F7-1 -> 0.076099284 | H8: =H7/G7-1 -> 0.063616573 | I8: =I7/H7-1 -> 0.057743123 | J8: =J7/I7-1 -> 0.033213203 | K8: =K7/J7-1 -> 0.032452733 | L8: =L7/K7-1 -> 0.018254936 | S8: =S7/O7-1 -> 0.027738773 | T8: =T7/P7-1 -> 0.02454941 | U8: =U7/Q7-1 -> 0.069367355 | V8: =V7/R7-1 -> 0.11460006 | W8: =W7/S7-1 -> 0.077464426 | X8: =X7/T7-1 -> 0.053609342 | Y8: =Y7/U7-1 -> 0.091385418 | Z8: =Z7/V7-1 -> 0.081186389 | ... AV8: =AV7/AR7-1 -> 0.017773744 | AY8: =AY7/U7-1 -> 0.091385418
B9: Non-service revenues | C9: 8052 | D9: 8761 | E9: 10545 | F9: 7832 | G9: 7370 | H9: 7506 | I9: 9018 | J9: 9121 | K9: 8451 | L9: 6202 | M9: =SUM(AS9:AV9) -> 6210 | O9: 2762 | P9: 3116 | Q9: 2397 | R9: =E9-Q9-P9-O9 -> 2270 | S9: 1826 | T9: 1802 | U9: 1800 | V9: =F9-U9-T9-S9 -> 2404 | W9: 1849 | X9: 1404 | Y9: 2120 | Z9: =G9-Y9-X9-W9 -> 1997 | AA9: 2247 | AB9: 1783 | AC9: 1366 | AD9: =H9-AC9-AB9-AA9 -> 2110 | AE9: 2174 | AF9: 2113 | AG9: 2132 | AH9: =I9-AG9-AF9-AE9 -> 2599 | AI9: 2636 | AJ9: 2151 | AK9: 1817 | AL9: =J9-AK9-AJ9-AI9 -> 2517 | AM9: 2029 | AN9: 2111 | AO9: 1807 | AP9: =K9-AO9-AN9-AM9 -> 2504 | AQ9: 1856 | AR9: 1410 | AS9: 1114 | AT9: =L9-AS9-AR9-AQ9 -> 1822 | AU9: 1608 | AV9: 1666 | AY9: 2120
B10: Total revenue | C10: =C7+C9 -> 165262 | D10: =D7+D9 -> 158933 | E10: =E7+E9 -> 162914 | F10: =F7+F9 -> 169187 | G10: =G7+G9 -> 181004 | H10: =H7+H9 -> 192186 | I10: =I7+I9 -> 204362 | J10: =J7+J9 -> 210953 | ... M10: =M7+M9 -> 220820 | O10: =O7+O9 -> 40507 | P10: =P7+P9 -> 41732 | Q10: =Q7+Q9 -> 40412 | R10: =R7+R9 -> 40263 | S10: =S7+S9 -> 40618 | T10: =T7+T9 -> 41366 | U10: =U7+U9 -> 42452 | V10: =V7+V9 -> 44751 | ... AV10: =AV7+AV9 -> 55493 | AY10: =AY7+AY9 -> 46487
B11: % growth | D11: =D10/C10-1 -> -0.038296765 | E11: =E10/D10-1 -> 0.025048291 | F11: =F10/E10-1 -> 0.038504978 | G11: =G10/F10-1 -> 0.069845792 | H11: =H10/G10-1 -> 0.06177764 | I11: =I10/H10-1 -> 0.063355291 | J11: =J10/I10-1 -> 0.032251593 | K11: =K10/J10-1 -> 0.027873507 | L11: =L10/K10-1 -> 0.0071714176 | S11: =S10/O10-1 -> 0.0027402671 | T11: =T10/P10-1 -> -0.0087702483 | U11: =U10/Q10-1 -> 0.050480055 | V11: =V10/R10-1 -> 0.1114671 | W11: =W10/S10-1 -> 0.07454823 | X11: =X10/T10-1 -> 0.041652565 | Y11: =Y10/U10-1 -> 0.095048525 | Z11: =Z10/V10-1 -> 0.06773033 | ... AV11: =AV10/AR10-1 -> 0.022027 | AY11: =AY10/U10-1 -> 0.095048525
B12: Expenses
B13: Cost of sales and services | C13: 18293 | D13: 13633 | E13: 14427 | F13: 13429 | G13: 12295 | H13: 12917 | I13: 14172 | J13: 15092 | K13: 14011 | L13: 12784 | M13: =SUM(AS13:AV13) -> 13664 | O13: 3614 | P13: 3896 | Q13: 3560 | R13: =E13-Q13-P13-O13 -> 3357 | S13: 2884 | T13: 3418 | U13: 3162 | V13: =F13-U13-T13-S13 -> 3965 | W13: 3029 | X13: 2587 | Y13: 3461 | Z13: =G13-Y13-X13-W13 -> 3218 | AA13: 3588 | AB13: 3109 | AC13: 2852 | AD13: =H13-AC13-AB13-AA13 -> 3368 | AE13: 3119 | AF13: 3286 | AG13: 3654 | AH13: =I13-AG13-AF13-AE13 -> 4113 | AI13: 4047 | AJ13: 3643 | AK13: 3212 | AL13: =J13-AK13-AJ13-AI13 -> 4190 | AM13: 3253 | AN13: 3592 | AO13: 3174 | AP13: =K13-AO13-AN13-AM13 -> 3992 | AQ13: 3366 | AR13: 2592 | AS13: 2883 | AT13: =L13-AS13-AR13-AQ13 -> 3943 | AU13: 3444 | AV13: 3394 | AY13: 3461
B14: Selling, general and administrative expenses | C14: 67196 | D14: 68990 | E14: 73916 | F14: 68230 | G14: 75255 | H14: 77686 | I14: 84476 | J14: 81876 | K14: 78308 | L14: 75789 | M14: =SUM(AS14:AV14) -> 74443 | O14: 17309 | P14: 17943 | Q14: 17758 | R14: =E14-Q14-P14-O14 -> 20906 | S14: 15891 | T14: 16172 | U14: 18964 | V14: =F14-U14-T14-S14 -> 17203 | W14: =17851 -> 17851 | X14: 16337 | Y14: 16941 | Z14: =G14-Y14-X14-W14 -> 24126 | AA14: 20014 | AB14: 19768 | AC14: 19536 | AD14: =H14-AC14-AB14-AA14 -> 18368 | AE14: 23359 | AF14: 21444 | AG14: 19934 | AH14: =I14-AG14-AF14-AE14 -> 19739 | AI14: 20251 | AJ14: 19582 | AK14: 19056 | AL14: =J14-AK14-AJ14-AI14 -> 22987 | AM14: 19276 | AN14: 20469 | AO14: 18990 | AP14: =K14-AO14-AN14-AM14 -> 19573 | AQ14: 18851 | AR14: 19121 | AS14: 19041 | AT14: =L14-AS14-AR14-AQ14 -> 18776 | AU14: 18204 | AV14: 18422 | AY14: 16941
B15: Interconnection costs | C15: 9573 | D15: 6626 | E15: 5493 | F15: 3638 | G15: 2146 | H15: 3698 | I15: 6104 | J15: 10418 | K15: 13718 | L15: 16010 | M15: =SUM(AS15:AV15) -> 17781 | O15: 1874 | P15: 2034 | Q15: 1441 | R15: =E15-Q15-P15-O15 -> 144 | S15: 835 | T15: 866 | U15: 1039 | V15: =F15-U15-T15-S15 -> 898 | W15: =302 -> 302 | X15: 339 | Y15: 619 | Z15: =G15-Y15-X15-W15 -> 886 | AA15: 833 | AB15: 894 | AC15: 839 | AD15: =H15-AC15-AB15-AA15 -> 1132 | AE15: 1596 | AF15: 1252 | AG15: 1709 | AH15: =I15-AG15-AF15-AE15 -> 1547 | AI15: 2619 | AJ15: 2101 | AK15: 2743 | AL15: =J15-AK15-AJ15-AI15 -> 2955 | AM15: 3491 | AN15: 3055 | AO15: 3556 | AP15: =K15-AO15-AN15-AM15 -> 3616 | AQ15: 4464 | AR15: 4723 | AS15: 3816 | AT15: =L15-AS15-AR15-AQ15 -> 3007 | AU15: 5996 | AV15: 4962 | AY15: 619
B16: Depreciation and amortisation | C16: 34455 | D16: 51915 | E16: 47240 | F16: 39656 | G16: 47480 | H16: 52072 | I16: 98631 | J16: 58441 | K16: 55988 | L16: 59487 | M16: =SUM(AS16:AV16) -> 61997 | O16: 9373 | P16: 8516 | Q16: 9611 | R16: =E16-Q16-P16-O16 -> 19740 | S16: 9346 | T16: 9557 | U16: 9710 | V16: =F16-U16-T16-S16 -> 11043 | W16: 10286 | X16: 10611 | Y16: 10690 | Z16: =G16-Y16-X16-W16 -> 15893 | AA16: 11721 | AB16: 12633 | AC16: 12839 | AD16: =H16-AC16-AB16-AA16 -> 14879 | AE16: 12543 | AF16: 28151 | AG16: 12061 | AH16: =I16-AG16-AF16-AE16 -> 45876 | AI16: 11679 | AJ16: 12271 | AK16: 12094 | AL16: =J16-AK16-AJ16-AI16 -> 22397 | AM16: 11642 | AN16: 12639 | AO16: 12881 | AP16: =K16-AO16-AN16-AM16 -> 18826 | AQ16: 13001 | AR16: 13042 | AS16: 15633 | AT16: =L16-AS16-AR16-AQ16 -> 17811 | AU16: 14280 | AV16: 14273 | AY16: 10690
B17: Asset impairment | C17: 11042 | D17: 8258 | E17: 8065 | F17: 4833 | G17: 7646 | H17: 4942 | I17: 6044 | J17: 4432 | K17: 4321 | L17: 3970 | M17: =SUM(AS17:AV17) -> 4011 | O17: 1391 | P17: 1421 | Q17: 1352 | R17: =E17-Q17-P17-O17 -> 3901 | S17: 1357 | T17: 1287 | U17: 1208 | V17: =F17-U17-T17-S17 -> 981 | W17: 1060 | X17: 2417 | Y17: 2943 | Z17: =G17-Y17-X17-W17 -> 1226 | AA17: 1592 | AB17: 1847 | AC17: 941 | AD17: =H17-AC17-AB17-AA17 -> 562 | AE17: 1076 | AF17: 1269 | AG17: 1513 | AH17: =I17-AG17-AF17-AE17 -> 2186 | AI17: 1102 | AJ17: 1045 | AK17: 1142 | AL17: =J17-AK17-AJ17-AI17 -> 1143 | AM17: 959 | AN17: 1090 | AO17: 1020 | AP17: =K17-AO17-AN17-AM17 -> 1252 | AQ17: 867 | AR17: 1001 | AS17: 984 | AT17: =L17-AS17-AR17-AQ17 -> 1118 | AU17: 828 | AV17: 1081 | AY17: 2943
B18: Operating profit | C18: =C10-SUM(C13:C17) -> 24703 | D18: =D10-SUM(D13:D17) -> 9511 | E18: =E10-SUM(E13:E17) -> 13773 | F18: =F10-SUM(F13:F17) -> 39401 | G18: =G10-SUM(G13:G17) -> 36182 | H18: =H10-SUM(H13:H17) -> 40871 | I18: =I10-SUM(I13:I17) -> -5065 | J18: =J10-SUM(J13:J17) -> 40694 | ... M18: =M10-SUM(M13:M17) -> 48924 | O18: =O10-SUM(O13:O17) -> 6946 | P18: =P10-SUM(P13:P17) -> 7922 | Q18: =Q10-SUM(Q13:Q17) -> 6690 | R18: =R10-SUM(R13:R17) -> -7785 | S18: =S10-SUM(S13:S17) -> 10305 | T18: =T10-SUM(T13:T17) -> 10066 | U18: =U10-SUM(U13:U17) -> 8369 | V18: =V10-SUM(V13:V17) -> 10661 | ... AV18: =AV10-SUM(AV13:AV17) -> 13361 | AY18: =AY10-SUM(AY13:AY17) -> 11833
B19: % margin | C19: =C18/C10 -> 0.1494778 | D19: =D18/D10 -> 0.059842827 | E19: =E18/E10 -> 0.084541537 | F19: =F18/F10 -> 0.23288432 | G19: =G18/G10 -> 0.19989613 | H19: =H18/H10 -> 0.21266377 | I19: =I18/I10 -> -0.024784451 | J19: =J18/J10 -> 0.19290553 | ... M19: =M18/M10 -> 0.22155602 | O19: =O18/O10 -> 0.17147653 | P19: =P18/P10 -> 0.18983035 | Q19: =Q18/Q10 -> 0.16554489 | R19: =R18/R10 -> -0.1933537 | S19: =S18/S10 -> 0.25370525 | T19: =T18/T10 -> 0.24333994 | U19: =U18/U10 -> 0.1971403 | V19: =V18/V10 -> 0.23822931 | ... AV19: =AV18/AV10 -> 0.24076911 | AY19: =AY18/AY10 -> 0.25454428
B20: Other expenses - net | C20: 2632 | D20: -5058 | E20: -9042 | F20: 7065 | G20: 3161 | H20: 6615 | I20: -19097 | J20: 4217 | K20: 7794 | L20: 10859 | M20: =SUM(AS20:AV20) -> 11833 | O20: -1889 | P20: 1195 | Q20: 1003 | R20: =E20-Q20-P20-O20 -> -9351 | S20: 1292 | T20: 2008 | U20: 2825 | V20: =F20-U20-T20-S20 -> 940 | W20: 2787 | X20: 2010 | Y20: 1371 | Z20: =G20-Y20-X20-W20 -> -3007 | AA20: 2480 | AB20: 436 | AC20: 3503 | AD20: =H20-AC20-AB20-AA20 -> 196 | AE20: -3795 | AF20: -14185 | AG20: -1616 | AH20: =I20-AG20-AF20-AE20 -> 499 | AI20: 442 | AJ20: 482 | AK20: 1301 | AL20: =J20-AK20-AJ20-AI20 -> 1992 | AM20: 2411 | AN20: 1403 | AO20: 978 | AP20: =K20-AO20-AN20-AM20 -> 3002 | AQ20: 2924 | AR20: 1944 | AS20: 2312 | AT20: =L20-AS20-AR20-AQ20 -> 3679 | AU20: 2504 | AV20: 3338 | AY20: 1371
B21: Profit before tax | C21: =C18-C20 -> 22071 | D21: =D18-D20 -> 14569 | E21: =E18-E20 -> 22815 | F21: =F18-F20 -> 32336 | G21: =G18-G20 -> 33021 | H21: =H18-H20 -> 34256 | I21: =I18-I20 -> 14032 | J21: =J18-J20 -> 36477 | ... M21: =M18-M20 -> 37091 | O21: =O18-O20 -> 8835 | P21: =P18-P20 -> 6727 | Q21: =Q18-Q20 -> 5687 | R21: =R18-R20 -> 1566 | S21: =S18-S20 -> 9013 | T21: =T18-T20 -> 8058 | U21: =U18-U20 -> 5544 | V21: =V18-V20 -> 9721 | ... AV21: =AV18-AV20 -> 10023 | AY21: =AY18-AY20 -> 10462
B22: Income Tax Expense | C22: -1909 | D22: -1103 | E22: -3842 | F22: -9550 | G22: -8441 | H22: -7459 | I22: -2697 | J22: -9612 | K22: -10138 | L22: -9271 | M22: =SUM(AS22:AV22) -> -8517 | O22: -1911 | P22: -1846 | Q22: -1166 | R22: =E22-Q22-P22-O22 -> 1081 | S22: -2290 | T22: -2546 | U22: -1743 | V22: =F22-U22-T22-S22 -> -2971 | W22: -2356 | X22: -2340 | Y22: -2985 | Z22: =G22-Y22-X22-W22 -> -760 | AA22: -1822 | AB22: -1818 | AC22: -1722 | AD22: =H22-AC22-AB22-AA22 -> -2097 | AE22: -2753 | AF22: -1881 | AG22: -3232 | AH22: =I22-AG22-AF22-AE22 -> 5169 | AI22: -3148 | AJ22: -3090 | AK22: -3295 | AL22: =J22-AK22-AJ22-AI22 -> -79 | AM22: -3299 | AN22: -2487 | AO22: -3053 | AP22: =K22-AO22-AN22-AM22 -> -1299 | AQ22: -2740 | AR22: -2760 | AS22: -2083 | AT22: =L22-AS22-AR22-AQ22 -> -1688 | AU22: -2339 | AV22: -2407 | AY22: -2985
B23: Net profit/loss from continuing operations | C23: =C21+C22 -> 20162 | D23: =D21+D22 -> 13466 | E23: =E21+E22 -> 18973 | F23: =F21+F22 -> 22786 | G23: =G21+G22 -> 24580 | H23: =H21+H22 -> 26797 | I23: =I21+I22 -> 11335 | J23: =J21+J22 -> 26865 | ... M23: =M21+M22 -> 28574 | O23: =O21+O22 -> 6924 | P23: =P21+P22 -> 4881 | Q23: =Q21+Q22 -> 4521 | R23: =R21+R22 -> 2647 | S23: =S21+S22 -> 6723 | T23: =T21+T22 -> 5512 | U23: =U21+U22 -> 3801 | V23: =V21+V22 -> 6750 | ... AV23: =AV21+AV22 -> 7616 | AY23: =AY19+AY20 -> 1371.2545
B24: Net Loss From Discontinued Operations | H24: -121 | I24: -600 | J24: -41 | K24: 0 | L24: 0 | M24: =SUM(AS24:AV24) -> 0 | AE24: -20 | AF24: -41 | AG24: -64 | AH24: =I24-AG24-AF24-AE24 -> -475 | AI24: -25 | AJ24: -4 | AK24: 16 | AL24: =J24-AK24-AJ24-AI24 -> -28 | AM24: 0 | AN24: 0 | AO24: 0 | AP24: =K24-AO24-AN24-AM24 -> 0 | AQ24: 0 | AR24: 0 | AS24: 0 | AT24: =L24-AS24-AR24-AQ24 -> 0 | AU24: 0 | AV24: 0
B25: Net profit/loss | C25: =C23+C24 -> 20162 | D25: =D23+D24 -> 13466 | E25: =E23+E24 -> 18973 | F25: =F23+F24 -> 22786 | G25: =G23+G24 -> 24580 | H25: =H23+H24 -> 26676 | I25: =I23+I24 -> 10735 | J25: =J23+J24 -> 26824 | ... M25: =M23+M24 -> 28574 | O25: =O23+O24 -> 6924 | P25: =P23+P24 -> 4881 | Q25: =Q23+Q24 -> 4521 | R25: =R23+R24 -> 2647 | S25: =S23+S24 -> 6723 | T25: =T23+T24 -> 5512 | U25: =U23+U24 -> 3801 | V25: =V23+V24 -> 6750 | ... AV25: =AV23+AV24 -> 7616 | AY25: =AY21+AY22 -> 7477
B26: % margin | C26: =C25/C10 -> 0.12200022 | D26: =D25/D10 -> 0.084727527 | E26: =E25/E10 -> 0.11646022 | F26: =F25/F10 -> 0.13467938 | G26: =G25/G10 -> 0.1357981 | H26: =H25/H10 -> 0.13880303 | I26: =I25/I10 -> 0.052529335 | J26: =J25/J10 -> 0.12715629 | ... M26: =M25/M10 -> 0.12939951 | O26: =O25/O10 -> 0.17093342 | P26: =P25/P10 -> 0.11696061 | Q26: =Q25/Q10 -> 0.11187271 | R26: =R25/R10 -> 0.065742741 | S26: =S25/S10 -> 0.16551775 | T26: =T25/T10 -> 0.13324953 | U26: =U25/U10 -> 0.089536418 | V26: =V25/V10 -> 0.15083462 | ... AV26: =AV25/AV10 -> 0.13724254 | AY26: =AY25/AY10 -> 0.16084067
B28: Net income attributACle to non-controlling interests | C28: 156 | D28: 95 | E28: 57 | F28: 265 | G28: 296 | H28: 309 | I28: 250 | J28: 210 | K28: 248 | L28: 207 | M28: =SUM(AS28:AV28) -> 254 | O28: 24 | P28: 19 | Q28: 14 | R28: =E28-Q28-P28-O28 -> 0 | S28: 15 | T28: 13 | U28: 12 | V28: =F28-U28-T28-S28 -> 225 | W28: 63 | X28: 80 | Y28: 70 | Z28: =G28-Y28-X28-W28 -> 83 | AA28: 71 | AB28: 75 | AC28: 76 | AD28: =H28-AC28-AB28-AA28 -> 87 | AE28: 75 | AF28: 116 | AG28: 83 | AH28: =I28-AG28-AF28-AE28 -> -24 | AI28: 34 | AJ28: 22 | AK28: 63 | AL28: =J28-AK28-AJ28-AI28 -> 91 | AM28: 69 | AN28: 35 | AO28: 50 | AP28: =K28-AO28-AN28-AM28 -> 94 | AQ28: 39 | AR28: 2 | AS28: 23 | AT28: =L28-AS28-AR28-AQ28 -> 143 | AU28: 49 | AV28: 39 | AY28: 70
B29: Net income attributACle to shareholders | C29: 20006 | D29: 13371 | E29: 18916 | F29: 22521 | G29: 24284 | H29: 26367 | I29: 10485 | J29: 26614 | K29: 32307 | L29: 30011 | M29: =SUM(AS29:AV29) -> 28320 | O29: 6900 | P29: 4862 | Q29: 4507 | R29: =E29-Q29-P29-O29 -> 2647 | S29: 6708 | T29: 5499 | U29: 3789 | V29: =F29-U29-T29-S29 -> 6525 | W29: 5912 | X29: 6368 | Y29: 7407 | Z29: =G29-Y29-X29-W29 -> 4597 | AA29: 5803 | AB29: 7119 | AC29: 5925 | AD29: =H29-AC29-AB29-AA29 -> 7520 | AE29: 9079 | AF29: 7707 | AG29: 10713 | AH29: =I29-AG29-AF29-AE29 -> -17014 | AI29: 9015 | AJ29: 9436 | AK29: 9428 | AL29: =J29-AK29-AJ29-AI29 -> -1265 | AM29: 9824 | AN29: 8589 | AO29: 9657 | AP29: =K29-AO29-AN29-AM29 -> 4237 | AQ29: 9025 | AR29: 9112 | AS29: 6934 | AT29: =L29-AS29-AR29-AQ29 -> 4940 | AU29: 8869 | AV29: 7577 | AY29: 7407
B30: Check | C30: =C25-C28-C29 -> 0 | D30: =D25-D28-D29 -> 0 | E30: =E25-E28-E29 -> 0 | F30: =F25-F28-F29 -> 0 | G30: =G25-G28-G29 -> 0 | H30: =H25-H28-H29 -> 0 | I30: =I25-I28-I29 -> 0 | J30: =J25-J28-J29 -> 0 | ... M30: =M25-M28-M29 -> 0 | O30: =O25-O28-O29 -> 0 | P30: =P25-P28-P29 -> 0 | Q30: =Q25-Q28-Q29 -> 0 | R30: =R25-R28-R29 -> 0 | S30: =S25-S28-S29 -> 0 | T30: =T25-T28-T29 -> 0 | U30: =U25-U28-U29 -> 0 | V30: =V25-V28-V29 -> 0 | ... AV30: =AV25-AV28-AV29 -> 0 | AY30: =AY25-AY28-AY29 -> 0
B32: As % of service revenues unless stated otherwise
B33: =B13 -> Cost of sales and services | C33: =C13/C7 -> 0.11636028 | D33: =D13/D7 -> 0.090782569 | E33: =E13/E7 -> 0.094684614 | F33: =F13/F7 -> 0.083226426 | G33: =G13/G7 -> 0.070809864 | H33: =H13/H7 -> 0.069942603 | I33: =I13/I7 -> 0.072548939 | J33: =J13/J7 -> 0.07477506 | ... M33: =M13/M7 -> 0.063668981 | O33: =O13/O7 -> 0.095747781 | P33: =P13/P7 -> 0.10089082 | Q33: =Q13/Q7 -> 0.093647245 | R33: =R13/R7 -> 0.088358382 | S33: =S13/S7 -> 0.074345226 | T33: =T13/T7 -> 0.086391669 | U33: =U13/U7 -> 0.077782151 | V33: =V13/V7 -> 0.09363119 | ... AV33: =AV13/AV7 -> 0.063053858 | AY33: =AY13/AY7 -> 0.07800843
B34: =B14 -> Selling, general and administrative expenses | C34: =C14/C7 -> 0.42742828 | D34: =D14/D7 -> 0.45940655 | E34: =E14/E7 -> 0.4851118 | F34: =F14/F7 -> 0.42285643 | G34: =G14/G7 -> 0.43341166 | H34: =H14/H7 -> 0.42065194 | I34: =I14/I7 -> 0.43244737 | J34: =J14/J7 -> 0.40566412 | ... M34: =M14/M7 -> 0.34687573 | O34: =O14/O7 -> 0.4585773 | P34: =P14/P7 -> 0.46465196 | Q34: =Q14/Q7 -> 0.4671314 | R34: =R14/R7 -> 0.55025926 | S34: =S14/S7 -> 0.40964632 | T34: =T14/T7 -> 0.40875543 | U34: =U14/U7 -> 0.46649611 | V34: =V14/V7 -> 0.40623893 | ... AV34: =AV14/AV7 -> 0.3422446 | AY34: =AY14/AY7 -> 0.38183785
B35: =B15 -> Interconnection costs | C35: =C15/C7 -> 0.060893073 | D35: =D15/D7 -> 0.044122739 | E35: =E15/E7 -> 0.03605064 | F35: =F15/F7 -> 0.022546559 | G35: =G15/G7 -> 0.012359331 | H35: =H15/H7 -> 0.020023825 | I35: =I15/I7 -> 0.03124744 | J35: =J15/J7 -> 0.051617187 | ... M35: =M15/M7 -> 0.082852616 | O35: =O15/O7 -> 0.04964896 | P35: =P15/P7 -> 0.052672467 | Q35: =Q15/Q7 -> 0.03790609 | R35: =R15/R7 -> 0.0037901719 | S35: =S15/S7 -> 0.021525057 | T35: =T15/T7 -> 0.021888586 | U35: =U15/U7 -> 0.025558398 | V35: =V15/V7 -> 0.021205752 | ... AV35: =AV15/AV7 -> 0.09218422 | AY35: =AY15/AY7 -> 0.013951811
B36: =B18 -> Operating profit | C36: =C18/C7 -> 0.15713377 | D36: =D18/D7 -> 0.063334044 | E36: =E18/E7 -> 0.090392403 | F36: =F18/F7 -> 0.24418828 | G36: =G18/G7 -> 0.20838085 | H36: =H18/H7 -> 0.22130713 | I36: =I18/I7 -> -0.025928618 | J36: =J18/J7 -> 0.20162313 | ... M36: =M18/M7 -> 0.22796701 | O36: =O18/O7 -> 0.18402437 | P36: =P18/P7 -> 0.20514813 | Q36: =Q18/Q7 -> 0.17598316 | R36: =R18/R7 -> -0.20490617 | S36: =S18/S7 -> 0.26564756 | T36: =T18/T7 -> 0.25442321 | U36: =U18/U7 -> 0.20586933 | V36: =V18/V7 -> 0.25175337 | ... AV36: =AV18/AV7 -> 0.24822115 | AY36: =AY18/AY7 -> 0.26670724
B37: PBT | C37: =C21/C7 -> 0.14039183 | D37: =D21/D7 -> 0.097015422 | E37: =E21/E7 -> 0.14973518 | F37: =F21/F7 -> 0.20040284 | G37: =G21/G7 -> 0.19017589 | H37: =H21/H7 -> 0.18548841 | I37: =I21/I7 -> 0.071832255 | J37: =J21/J7 -> 0.18072952 | ... M37: =M21/M7 -> 0.17282978 | O37: =O21/O7 -> 0.23407074 | P37: =P21/P7 -> 0.1742024 | Q37: =Q21/Q7 -> 0.14959884 | R37: =R21/R7 -> 0.041218119 | S37: =S21/S7 -> 0.23234172 | T37: =T21/T7 -> 0.20367 | U37: =U21/U7 -> 0.13637705 | V37: =V21/V7 -> 0.22955581 | ... AV37: =AV21/AV7 -> 0.18620767 | AY37: =AY21/AY7 -> 0.23580589
B38: Income Tax Expense as a % PBT | C38: =-C22/C21 -> 0.086493589 | D38: =-D22/D21 -> 0.075708697 | E38: =-E22/E21 -> 0.16839798 | F38: =-F22/F21 -> 0.29533647 | G38: =-G22/G21 -> 0.25562521 | H38: =-H22/H21 -> 0.21774288 | I38: =-I22/I21 -> 0.19220353 | J38: =-J22/J21 -> 0.26350851 | ... M38: =-M22/M21 -> 0.22962444 | O38: =-O22/O21 -> 0.21629881 | P38: =-P22/P21 -> 0.27441653 | Q38: =-Q22/Q21 -> 0.20502901 | R38: =-R22/R21 -> -0.69029374 | S38: =-S22/S21 -> 0.25407744 | T38: =-T22/T21 -> 0.3159593 | U38: =-U22/U21 -> 0.31439394 | V38: =-V22/V21 -> 0.30562699 | ... AV38: =-AV22/AV21 -> 0.24014766 | AY38: =-AY22/AY21 -> 0.28531829
B39: =B20 -> Other expenses - net | C39: =C20/C7 -> 0.016741938 | D39: =D20/D7 -> -0.033681379 | E39: =E20/E7 -> -0.05934278 | F39: =F20/F7 -> 0.043785442 | G39: =G20/G7 -> 0.01820496 | H39: =H20/H7 -> 0.035818713 | I39: =I20/I7 -> -0.097760873 | J39: =J20/J7 -> 0.020893614 | ... M39: =M20/M7 -> 0.055137226 | O39: =O20/O7 -> -0.050046364 | P39: =P20/P7 -> 0.030945722 | Q39: =Q20/Q7 -> 0.026384322 | R39: =R20/R7 -> -0.24612429 | S39: =S20/S7 -> 0.033305836 | T39: =T20/T7 -> 0.05075321 | U39: =U20/U7 -> 0.069492276 | V39: =V20/V7 -> 0.022197558 | ... AV39: =AV20/AV7 -> 0.062013488 | AY39: =AY20/AY7 -> 0.030901346
B41: Working capital/sales | C41: =C97/C81 -> -0.14988322 | D41: =D97/D81 -> -0.14314837 | E41: =E97/E81 -> -0.2926452 | F41: =F97/F81 -> -0.30733449 | G41: =G97/G81 -> -0.31090473 | H41: =H97/H81 -> -0.38642773 | I41: =I97/I81 -> -0.36877697 | J41: =J97/J81 -> -0.24454736 | ... M41: =M97/M81 -> -0.068675845 | R41: =R97/R81 -> -0.2926452 | S41: =S97/S81 -> -0.28257016 | T41: =T97/T81 -> -0.30377046 | U41: =U97/U81 -> -0.33776161 | V41: =V97/V81 -> -0.30733449 | W41: =W97/W81 -> -0.30916587 | X41: =X97/X81 -> -0.18130598 | Y41: =Y97/Y81 -> -0.18603384 | ... AV41: =AV97/AV81 -> -0.068675845 | AY41: =AY97/AY81 -> -0.18603384
B43: EBITDA | C43: =C3 -> 42735 | D43: =D3 -> 43100 | E43: =E3 -> 43465 | F43: =F3 -> 43830 | G43: =G3 -> 44196 | H43: =H3 -> 44561 | I43: =I3 -> 44926 | J43: =J3 -> 45291 | ... M43: =M3 -> 46203 | O43: =O3 -> 43190 | P43: =P3 -> 43281 | Q43: =Q3 -> 43373 | R43: =R3 -> 43465 | S43: =S3 -> 43555 | T43: =T3 -> 43646 | U43: =U3 -> 43738 | V43: =V3 -> 43830 | ... AV43: =AV3 -> 46203 | AY43: =AY3 -> 44104
B44: =B18 -> Operating profit | C44: =C18 -> 24703 | D44: =D18 -> 9511 | E44: =E18 -> 13773 | F44: =F18 -> 39401 | G44: =G18 -> 36182 | H44: =H18 -> 40871 | I44: =I18 -> -5065 | ... M44: =M18 -> 48924 | O44: =O18 -> 6946 | P44: =P18 -> 7922 | Q44: =Q18 -> 6690 | R44: =R18 -> -7785 | S44: =S18 -> 10305 | T44: =T18 -> 10066 | U44: =U18 -> 8369 | V44: =V18 -> 10661 | ... AV44: =AV18 -> 13361 | AY44: =AY18 -> 11833
B45: Depreciation & amortisation | C45: 34455 | D45: 51915 | E45: 47240 | F45: 39656 | G45: 47480 | H45: 52169 | I45: 98714 | J45: 58462 | K45: 55988 | L45: 59487 | M45: =SUM(AS45:AV45) -> 61997 | O45: 9373 | P45: 8516 | Q45: 9611 | R45: =#REF!-Q45-P45-O45 -> #REF! | S45: 9346 | T45: 9557 | U45: 9710 | V45: =F45-U45-T45-S45 -> 11043 | W45: 10286 | X45: 10611 | Y45: 10690 | Z45: =G45-Y45-X45-W45 -> 15893 | AA45: 11721 | AB45: 12633 | AC45: 12839 | AD45: =H45-AC45-AB45-AA45 -> 14976 | AE45: 12564 | AF45: 28151 | AG45: 12061 | AH45: =I45-AG45-AF45-AE45 -> 45938 | AI45: 11688 | AJ45: 12271 | AK45: 12094 | AL45: =J45-AK45-AJ45-AI45 -> 22409 | AM45: 11642 | AN45: 12639 | AO45: 12881 | AP45: =K45-AO45-AN45-AM45 -> 18826 | AQ45: 13001 | AR45: =26043-AQ45 -> 13042 | AS45: =41820-AR45-AQ45 -> 15777 | AT45: =L45-AS45-AR45-AQ45 -> 17667 | AU45: 14280 | AV45: =28553-AU45 -> 14273 | AY45: 10690
...

Sheet KPIs
B2: PLDT INC. | C2: Annual | D2: Annual | E2: Annual | F2: Annual | G2: Annual | H2: Annual | I2: Annual | J2: Annual | K2: Annual | L2: Annual | M2: LTM | O2: Quarterly | P2: Quarterly | Q2: Quarterly | R2: Quarterly | S2: Quarterly | T2: Quarterly | U2: Quarterly | V2: Quarterly | W2: Quarterly | X2: Quarterly | Y2: Quarterly | Z2: Quarterly | AA2: Quarterly | AB2: Quarterly | AC2: Quarterly | AD2: Quarterly | AE2: Quarterly | AF2: Quarterly | AG2: Quarterly | AH2: Quarterly | AI2: Quarterly | AJ2: Quarterly | AK2: Quarterly | AL2: Quarterly | AM2: Quarterly | AN2: Quarterly | AO2: Quarterly | AP2: Quarterly | AQ2: Quarterly | AR2: Quarterly | AS2: Quarterly | AT2: Quarterly | AU2: Quarterly | AV2: Quarterly
B3: (PHP millions) | C3: 42735 | D3: =EDATE(C3,12) -> 43100 | E3: =EDATE(D3,12) -> 43465 | F3: =EDATE(E3,12) -> 43830 | G3: =EDATE(F3,12) -> 44196 | H3: =EDATE(G3,12) -> 44561 | I3: =EDATE(H3,12) -> 44926 | J3: =EDATE(I3,12) -> 45291 | K3: =EDATE(J3,12) -> 45657 | L3: =EDATE(K3,12) -> 46022 | M3: =AV3 -> 46203 | O3: 43160 | P3: 43252 | Q3: 43344 | R3: 43435 | S3: 43525 | T3: 43617 | U3: 43709 | V3: 43800 | W3: 43891 | X3: 43983 | Y3: 44075 | Z3: 44166 | AA3: 44256 | AB3: 44348 | AC3: 44440 | AD3: 44531 | AE3: 44651 | AF3: 44742 | AG3: 44805 | AH3: 44896 | AI3: 45016 | AJ3: 45107 | AK3: 45170 | AL3: 45261 | AM3: 45382 | AN3: 45473 | AO3: 45536 | AP3: 45627 | AQ3: 45747 | AR3: 45838 | AS3: 45901 | AT3: 45992 | AU3: 46112 | AV3: 46203
I4: Act | J4: Act | K4: Act | L4: Act | M4: Act | AM4: Act | AN4: Act | AO4: Act | AP4: Act | AQ4: Act | AR4: Act | AS4: Act | AT4: Act | AU4: Act | AV4: Act
C5: FY | D5: FY | E5: FY | F5: FY | G5: FY | H5: FY | I5: FY | J5: FY | K5: FY | L5: FY | M5: LTM | O5: Q1 | P5: Q2 | Q5: Q3 | R5: Q4 | S5: Q1 | T5: Q2 | U5: Q3 | V5: Q4 | W5: Q1 | X5: Q2 | Y5: Q3 | Z5: Q4 | AA5: Q1 | AB5: Q2 | AC5: Q3 | AD5: Q4 | AE5: Q1 | AF5: Q2 | AG5: Q3 | AH5: Q4 | AI5: Q1 | AJ5: Q2 | AK5: Q3 | AL5: Q4 | AM5: Q1 | AN5: Q2 | AO5: Q3 | AP5: Q4 | AQ5: Q1 | AR5: Q2 | AS5: Q3 | AT5: Q4 | AU5: Q1 | AV5: Q2
B8: Revenue by business segment
B9: Wireless | C9: 104087 | D9: 92572 | E9: 89929 | F9: 96906 | G9: 104211 | H9: 106619 | I9: 104274 | J9: 104401 | K9: 105734 | L9: 103316 | M9: =SUM(AS9:AV9) -> 104236 | O9: 22592 | P9: =45235-O9 -> 22643 | Q9: =67363-P9-O9 -> 22128 | R9: =+E9-SUM(O9:Q9) -> 22566 | S9: 22489 | T9: =46231-S9 -> 23742 | U9: =70635-T9-S9 -> 24404 | V9: =+F9-SUM(S9:U9) -> 26271 | W9: 25354 | X9: =49911-W9 -> 24557 | Y9: =76716-X9-W9 -> 26805 | Z9: =+G9-SUM(W9:Y9) -> 27495 | AA9: 27383 | AB9: =53902-AA9 -> 26519 | AC9: =79821-AB9-AA9 -> 25919 | AD9: =+H9-SUM(AA9:AC9) -> 26798 | AE9: 25747 | AF9: =52012-AE9 -> 26265 | AG9: =77971-AF9-AE9 -> 25959 | AH9: =+I9-SUM(AE9:AG9) -> 26303 | AI9: 25879 | AJ9: =51589-AI9 -> 25710 | AK9: =77234-AJ9-AI9 -> 25645 | AL9: =+J9-SUM(AI9:AK9) -> 27167 | AM9: 26668 | AN9: =52999-AM9 -> 26331 | AO9: =78535-AN9-AM9 -> 25536 | AP9: =+K9-SUM(AM9:AO9) -> 27199 | AQ9: 26117 | AR9: =51372-AQ9 -> 25255 | AS9: =76468-AR9-AQ9 -> 25096 | AT9: =+L9-SUM(AQ9:AS9) -> 26848 | AU9: 26145 | AV9: =52292-AU9 -> 26147
B10: Fixed Line | C10: 72728 | D10: 78341 | E10: 85222 | F10: 89406 | G10: 98739 | H10: 115992 | I10: 127810 | J10: 120734 | K10: 126490 | L10: 130810 | M10: =SUM(AS10:AV10) -> 129615 | O10: 20457 | P10: =41652-O10 -> 21195 | Q10: =63336-P10-O10 -> 21684 | R10: =+E10-SUM(O10:Q10) -> 21886 | S10: 21999 | T10: =44217-S10 -> 22218 | U10: =66468-T10-S10 -> 22251 | V10: =+F10-SUM(S10:U10) -> 22938 | W10: 22695 | X10: =46483-W10 -> 23788 | Y10: =72031-X10-W10 -> 25548 | Z10: =+G10-SUM(W10:Y10) -> 26708 | AA10: 26555 | AB10: =54840-AA10 -> 28285 | AC10: =84779-AB10-AA10 -> 29939 | AD10: =+H10-SUM(AA10:AC10) -> 31213 | AE10: 34214 | AF10: =70446-AE10 -> 36232 | AG10: =105104-AF10-AE10 -> 34658 | AH10: =+I10-SUM(AE10:AG10) -> 22706 | AI10: 30047 | AJ10: =59606-AI10 -> 29559 | AK10: =89727-AJ10-AI10 -> 30121 | AL10: =+J10-SUM(AI10:AK10) -> 31007 | AM10: 31845 | AN10: =64106-AM10 -> 32261 | AO10: =95435-AN10-AM10 -> 31329 | AP10: =+K10-SUM(AM10:AO10) -> 31055 | AQ10: 33467 | AR10: =67092-AQ10 -> 33625 | AS10: =100248-AR10-AQ10 -> 33156 | AT10: =+L10-SUM(AQ10:AS10) -> 30562 | AU10: 33932 | AV10: =65897-AU10 -> 31965
B11: Others. | C11: 847 | D11: 1279 | E11: 1138 | F11: 0 | G11: 0 | H11: 0 | I11: 0 | J11: 0 | K11: 0 | L11: 0 | M11: =SUM(AS11:AV11) -> 0 | O11: 312 | P11: =612-O11 -> 300 | Q11: =922-P11-O11 -> 310 | R11: =+E11-SUM(O11:Q11) -> 216 | S11: 0 | T11: =0-S11 -> 0 | U11: =0-T11-S11 -> 0 | V11: =+F11-SUM(S11:U11) -> 0 | W11: 0 | X11: =0-W11 -> 0 | Y11: =0-X11-W11 -> 0 | Z11: =+G11-SUM(W11:Y11) -> 0 | AA11: 0 | AB11: =0-AA11 -> 0 | AC11: =0-AB11-AA11 -> 0 | AD11: =+H11-SUM(AA11:AC11) -> 0 | AE11: 0 | AF11: =0-AE11 -> 0 | AG11: =0-AF11-AE11 -> 0 | AH11: =+I11-SUM(AE11:AG11) -> 0 | AI11: 0 | AJ11: =0-AI11 -> 0 | AK11: =0-AJ11-AI11 -> 0 | AL11: =+J11-SUM(AI11:AK11) -> 0 | AM11: 0 | AN11: =0-AM11 -> 0 | AO11: =0-AN11-AM11 -> 0 | AP11: =+K11-SUM(AM11:AO11) -> 0 | AQ11: 0 | AR11: =0-AQ11 -> 0 | AS11: =0-AR11-AQ11 -> 0 | AT11: =+L11-SUM(AQ11:AS11) -> 0 | AU11: 0 | AV11: =0-AU11 -> 0
B12: Inter-segment transactions | C12: -13216 | D12: -13259 | E12: -13375 | F12: -17125 | G12: -21946 | H12: -30425 | I12: -27722 | J12: -14182 | K12: -15391 | L12: -15738 | M12: =SUM(AS12:AV12) -> -13031 | O12: -2854 | P12: =-5260-O12 -> -2406 | Q12: =-9745-P12-O12 -> -4485 | R12: =+E12-SUM(O12:Q12) -> -3630 | S12: -3870 | T12: =-8464-S12 -> -4594 | U12: =-12667-T12-S12 -> -4203 | V12: =+F12-SUM(S12:U12) -> -4458 | W12: -4403 | X12: =-9659-W12 -> -5256 | Y12: =-15525-X12-W12 -> -5866 | Z12: =+G12-SUM(W12:Y12) -> -6421 | AA12: -6014 | AB12: =-13119-AA12 -> -7105 | AC12: =-20744-AB12-AA12 -> -7625 | AD12: =+H12-SUM(AA12:AC12) -> -9681 | AE12: -10136 | AF12: =-21671-AE12 -> -11535 | AG12: =-30941-AF12-AE12 -> -9270 | AH12: =+I12-SUM(AE12:AG12) -> 3219 | AI12: -3564 | AJ12: =-7157-AI12 -> -3593 | AK12: =-10605-AJ12-AI12 -> -3448 | AL12: =+J12-SUM(AI12:AK12) -> -3577 | AM12: -4289 | AN12: =-9522-AM12 -> -5233 | AO12: =-13028-AN12-AM12 -> -3506 | AP12: =+K12-SUM(AM12:AO12) -> -2363 | AQ12: -4307 | AR12: =-8890-AQ12 -> -4583 | AS12: =-13433-AR12-AQ12 -> -4543 | AT12: =+L12-SUM(AQ12:AS12) -> -2305 | AU12: -3564 | AV12: =-6183-AU12 -> -2619
B13: Total | C13: =+C9+C10+C11+C12 -> 164446 | D13: =+D9+D10+D11+D12 -> 158933 | E13: =+E9+E10+E11+E12 -> 162914 | F13: =+F9+F10+F11+F12 -> 169187 | G13: =+G9+G10+G11+G12 -> 181004 | H13: =+H9+H10+H11+H12 -> 192186 | I13: =+I9+I10+I11+I12 -> 204362 | J13: =+J9+J10+J11+J12 -> 210953 | ... M13: =+M9+M10+M11+M12 -> 220820 | O13: =+O9+O10+O11+O12 -> 40507 | P13: =+P9+P10+P11+P12 -> 41732 | Q13: =+Q9+Q10+Q11+Q12 -> 39637 | R13: =+R9+R10+R11+R12 -> 41038 | S13: =+S9+S10+S11+S12 -> 40618 | T13: =+T9+T10+T11+T12 -> 41366 | U13: =+U9+U10+U11+U12 -> 42452 | V13: =+V9+V10+V11+V12 -> 44751 | ... AV13: =+AV9+AV10+AV11+AV12 -> 55493
B14: Check | C14: =C13-Model!C10 -> -816 | D14: =D13-Model!D10 -> 0 | E14: =E13-Model!E10 -> 0 | F14: =F13-Model!F10 -> 0 | G14: =G13-Model!G10 -> 0 | H14: =H13-Model!H10 -> 0 | I14: =I13-Model!I10 -> 0 | J14: =J13-Model!J10 -> 0 | ... M14: =M13-Model!M10 -> 0 | O14: =O13-Model!O10 -> 0 | P14: =P13-Model!P10 -> 0 | Q14: =Q13-Model!Q10 -> -775 | R14: =R13-Model!R10 -> 775 | S14: =S13-Model!S10 -> 0 | T14: =T13-Model!T10 -> 0 | U14: =U13-Model!U10 -> 0 | V14: =V13-Model!V10 -> 0 | ... AV14: =AV13-Model!AV10 -> 0
B16: Revenue by business segment (Share %)
B17: Wireless | C17: =+C9/C$13 -> 0.6329555 | D17: =+D9/D$13 -> 0.58245928 | E17: =+E9/E$13 -> 0.5520029 | F17: =+F9/F$13 -> 0.5727745 | G17: =+G9/G$13 -> 0.57573866 | H17: =+H9/H$13 -> 0.55476986 | I17: =+I9/I$13 -> 0.51024163 | J17: =+J9/J$13 -> 0.49490171 | ... M17: =+M9/M$13 -> 0.47204058 | O17: =+O9/O$13 -> 0.55773076 | P17: =+P9/P$13 -> 0.54258123 | Q17: =+Q9/Q$13 -> 0.55826627 | R17: =+R9/R$13 -> 0.5498806 | S17: =+S9/S$13 -> 0.55367079 | T17: =+T9/T$13 -> 0.57394962 | U17: =+U9/U$13 -> 0.57486102 | V17: =+V9/V$13 -> 0.58704833 | ... AV17: =+AV9/AV$13 -> 0.47117654
B18: Fixed Line | C18: =+C10/C$13 -> 0.44226068 | D18: =+D10/D$13 -> 0.4929184 | E18: =+E10/E$13 -> 0.52311035 | F18: =+F10/F$13 -> 0.52844486 | G18: =+G10/G$13 -> 0.54550728 | H18: =+H10/H$13 -> 0.60354032 | I18: =+I10/I$13 -> 0.62540981 | J18: =+J10/J$13 -> 0.57232654 | ... M18: =+M10/M$13 -> 0.58697129 | O18: =+O10/O$13 -> 0.50502382 | P18: =+P10/P$13 -> 0.50788364 | Q18: =+Q10/Q$13 -> 0.54706461 | R18: =+R10/R$13 -> 0.53331059 | S18: =+S10/S$13 -> 0.54160717 | T18: =+T10/T$13 -> 0.53710777 | U18: =+U10/U$13 -> 0.52414492 | V18: =+V10/V$13 -> 0.51256955 | ... AV18: =+AV10/AV$13 -> 0.5760186
B19: Others. | C19: =+C11/C$13 -> 0.005150627 | D19: =+D11/D$13 -> 0.0080474162 | E19: =+E11/E$13 -> 0.0069852806 | F19: =+F11/F$13 -> 0 | G19: =+G11/G$13 -> 0 | H19: =+H11/H$13 -> 0 | I19: =+I11/I$13 -> 0 | J19: =+J11/J$13 -> 0 | ... M19: =+M11/M$13 -> 0 | O19: =+O11/O$13 -> 0.0077023724 | P19: =+P11/P$13 -> 0.0071887281 | Q19: =+Q11/Q$13 -> 0.0078209754 | R19: =+R11/R$13 -> 0.0052634144 | S19: =+S11/S$13 -> 0 | T19: =+T11/T$13 -> 0 | U19: =+U11/U$13 -> 0 | V19: =+V11/V$13 -> 0 | ... AV19: =+AV11/AV$13 -> 0
B20: Inter-segment transactions | C20: =+C12/C$13 -> -0.080366807 | D20: =+D12/D$13 -> -0.083425091 | E20: =+E12/E$13 -> -0.082098531 | F20: =+F12/F$13 -> -0.10121936 | G20: =+G12/G$13 -> -0.12124594 | H20: =+H12/H$13 -> -0.15831018 | I20: =+I12/I$13 -> -0.13565144 | J20: =+J12/J$13 -> -0.067228245 | ... M20: =+M12/M$13 -> -0.059011865 | O20: =+O12/O$13 -> -0.070456958 | P20: =+P12/P$13 -> -0.057653599 | Q20: =+Q12/Q$13 -> -0.11315185 | R20: =+R12/R$13 -> -0.088454603 | S20: =+S12/S$13 -> -0.095277956 | T20: =+T12/T$13 -> -0.11105739 | U20: =+U12/U$13 -> -0.099005936 | V20: =+V12/V$13 -> -0.099617886 | ... AV20: =+AV12/AV$13 -> -0.047195142
B21: Total | C21: =+C17+C18+C19+C20 -> 1 | D21: =+D17+D18+D19+D20 -> 1 | E21: =+E17+E18+E19+E20 -> 1 | F21: =+F17+F18+F19+F20 -> 1 | G21: =+G17+G18+G19+G20 -> 1 | H21: =+H17+H18+H19+H20 -> 1 | I21: =+I17+I18+I19+I20 -> 1 | J21: =+J17+J18+J19+J20 -> 1 | ... M21: =+M17+M18+M19+M20 -> 1 | O21: =+O17+O18+O19+O20 -> 1 | P21: =+P17+P18+P19+P20 -> 1 | Q21: =+Q17+Q18+Q19+Q20 -> 1 | R21: =+R17+R18+R19+R20 -> 1 | S21: =+S17+S18+S19+S20 -> 1 | T21: =+T17+T18+T19+T20 -> 1 | U21: =+U17+U18+U19+U20 -> 1 | V21: =+V17+V18+V19+V20 -> 1 | ... AV21: =+AV17+AV18+AV19+AV20 -> 1
B23: Revenue by business segment (YoY % Growth)
B24: Wireless | D24: =D9/C9-1 -> -0.11062861 | E24: =E9/D9-1 -> -0.02855075 | F24: =F9/E9-1 -> 0.077583427 | G24: =G9/F9-1 -> 0.075382329 | H24: =H9/G9-1 -> 0.023106966 | I24: =I9/H9-1 -> -0.021994204 | J24: =J9/I9-1 -> 0.001217945 | K24: =K9/J9-1 -> 0.012768077 | L24: =L9/K9-1 -> -0.022868708 | S24: =S9/O9-1 -> -0.004559136 | T24: =T9/P9-1 -> 0.048535971 | U24: =U9/Q9-1 -> 0.10285611 | V24: =V9/R9-1 -> 0.16418506 | W24: =W9/S9-1 -> 0.12739562 | X24: =X9/T9-1 -> 0.034327352 | Y24: =Y9/U9-1 -> 0.098385511 | Z24: =Z9/V9-1 -> 0.046591298 | ... AV24: =AV9/AR9-1 -> 0.035319739
B25: Fixed Line | D25: =D10/C10-1 -> 0.077177978 | E25: =E10/D10-1 -> 0.087833957 | F25: =F10/E10-1 -> 0.049095304 | G25: =G10/F10-1 -> 0.10438897 | H25: =H10/G10-1 -> 0.17473339 | I25: =I10/H10-1 -> 0.10188634 | J25: =J10/I10-1 -> -0.05536343 | K25: =K10/J10-1 -> 0.047675054 | L25: =L10/K10-1 -> 0.034152897 | S25: =S10/O10-1 -> 0.075377621 | T25: =T10/P10-1 -> 0.0482661 | U25: =U10/Q10-1 -> 0.026148312 | V25: =V10/R10-1 -> 0.048067258 | W25: =W10/S10-1 -> 0.031637802 | X25: =X10/T10-1 -> 0.070663426 | Y25: =Y10/U10-1 -> 0.14817312 | Z25: =Z10/V10-1 -> 0.16435609 | ... AV25: =AV10/AR10-1 -> -0.04936803
B26: Others. | D26: =D11/C11-1 -> 0.51003542 | E26: =E11/D11-1 -> -0.11024238 | F26: =F11/E11-1 -> -1 | G26: =G11/F11-1 -> #DIV/0! | H26: =H11/G11-1 -> #DIV/0! | I26: =I11/H11-1 -> #DIV/0! | J26: =J11/I11-1 -> #DIV/0! | K26: =K11/J11-1 -> #DIV/0! | L26: =L11/K11-1 -> #DIV/0! | S26: =S11/O11-1 -> -1 | T26: =T11/P11-1 -> -1 | U26: =U11/Q11-1 -> -1 | V26: =V11/R11-1 -> -1 | W26: =W11/S11-1 -> #DIV/0! | X26: =X11/T11-1 -> #DIV/0! | Y26: =Y11/U11-1 -> #DIV/0! | Z26: =Z11/V11-1 -> #DIV/0! | ... AV26: =AV11/AR11-1 -> #DIV/0!
B27: Inter-segment transactions | D27: =D12/C12-1 -> 0.003253632 | E27: =E12/D12-1 -> 0.0087487744 | F27: =F12/E12-1 -> 0.28037383 | G27: =G12/F12-1 -> 0.28151825 | H27: =H12/G12-1 -> 0.38635742 | I27: =I12/H12-1 -> -0.088841413 | J27: =J12/I12-1 -> -0.48842075 | K27: =K12/J12-1 -> 0.085248907 | L27: =L12/K12-1 -> 0.022545644 | S27: =S12/O12-1 -> 0.35599159 | T27: =T12/P12-1 -> 0.90939318 | U27: =U12/Q12-1 -> -0.062876254 | V27: =V12/R12-1 -> 0.22809917 | W27: =W12/S12-1 -> 0.1377261 | X27: =X12/T12-1 -> 0.144101 | Y27: =Y12/U12-1 -> 0.39566976 | Z27: =Z12/V12-1 -> 0.44033199 | ... AV27: =AV12/AR12-1 -> -0.42854026
B28: Total | D28: =D13/C13-1 -> -0.033524683 | E28: =E13/D13-1 -> 0.025048291 | F28: =F13/E13-1 -> 0.038504978 | G28: =G13/F13-1 -> 0.069845792 | H28: =H13/G13-1 -> 0.06177764 | I28: =I13/H13-1 -> 0.063355291 | J28: =J13/I13-1 -> 0.032251593 | K28: =K13/J13-1 -> 0.027873507 | L28: =L13/K13-1 -> 0.0071714176 | S28: =S13/O13-1 -> 0.0027402671 | T28: =T13/P13-1 -> -0.0087702483 | U28: =U13/Q13-1 -> 0.071019502 | V28: =V13/R13-1 -> 0.090477119 | W28: =W13/S13-1 -> 0.07454823 | X28: =X13/T13-1 -> 0.041652565 | Y28: =Y13/U13-1 -> 0.095048525 | Z28: =Z13/V13-1 -> 0.06773033 | ... AV28: =AV13/AR13-1 -> 0.022027
B31: EBITDA by business segment
B32: Wireless | C32: 32915 | D32: 36395 | E32: 34235 | F32: 52789 | G32: 60272 | H32: 60971 | I32: 52215 | J32: 56505 | K32: 55634 | L32: 57589 | M32: =SUM(AS32:AV32) -> 59003 | O32: 8539 | P32: =17577-O32 -> 9038 | Q32: =26046-P32-O32 -> 8469 | R32: =+E32-SUM(O32:Q32) -> 8189 | S32: 12166 | T32: =26005-S32 -> 13839 | U32: =39126-T32-S32 -> 13121 | V32: =+F32-SUM(S32:U32) -> 13663 | W32: 14213 | X32: =29012-W32 -> 14799 | Y32: =44248-X32-W32 -> 15236 | Z32: =+G32-SUM(W32:Y32) -> 16024 | AA32: 14802 | AB32: =30138-AA32 -> 15336 | AC32: =45469-AB32-AA32 -> 15331 | AD32: =+H32-SUM(AA32:AC32) -> 15502 | AE32: 13292 | AF32: =25640-AE32 -> 12348 | AG32: =36160-AF32-AE32 -> 10520 | AH32: =+I32-SUM(AE32:AG32) -> 16055 | AI32: 13236 | AJ32: =25803-AI32 -> 12567 | AK32: =39408-AJ32-AI32 -> 13605 | AL32: =+J32-SUM(AI32:AK32) -> 17097 | AM32: 12832 | AN32: =25015-AM32 -> 12183 | AO32: =38285-AM32-AN32 -> 13270 | AP32: =+K32-SUM(AM32:AO32) -> 17349 | AQ32: 13706 | AR32: =27116-AQ32 -> 13410 | AS32: =40084-AQ32-AR32 -> 12968 | AT32: =+L32-SUM(AQ32:AS32) -> 17505 | AU32: 13637 | AV32: =28530-AU32 -> 14893
B33: Fixed Line | C33: 26950 | D33: 29478 | E33: 30875 | F33: 33162 | G33: 33405 | H33: 46019 | I33: 55051 | J33: 56966 | K33: 61953 | L33: 63253 | M33: =SUM(AS33:AV33) -> 60678 | O33: 8229 | P33: =16127-O33 -> 7898 | Q33: =24320-P33-O33 -> 8193 | R33: =+E33-SUM(O33:Q33) -> 6555 | S33: 9044 | T33: =16389-S33 -> 7345 | U33: =23039-T33-S33 -> 6650 | V33: =+F33-SUM(S33:U33) -> 10123 | W33: 9068 | X33: =17373-W33 -> 8305 | Y33: =26475-X33-W33 -> 9102 | Z33: =+G33-SUM(W33:Y33) -> 6930 | AA33: 10307 | AB33: =20534-AA33 -> 10227 | AC33: =32120-AB33-AA33 -> 11586 | AD33: =+H33-SUM(AA33:AC33) -> 13899 | AE33: 11213 | AF33: =26555-AE33 -> 15342 | AG33: =44410-AF33-AE33 -> 17855 | AH33: =+I33-SUM(AE33:AG33) -> 10641 | AI33: 13621 | AJ33: =28896-AI33 -> 15275 | AK33: =43630-AJ33-AI33 -> 14734 | AL33: =+J33-SUM(AI33:AK33) -> 13336 | AM33: 15597 | AN33: =31989-AM33 -> 16392 | AO33: =47819-AM33-AN33 -> 15830 | AP33: =+K33-SUM(AM33:AO33) -> 14134 | AQ33: 16449 | AR33: =32823-AQ33 -> 16374 | AS33: =49331-AQ33-AR33 -> 16508 | AT33: =+L33-SUM(AQ33:AS33) -> 13922 | AU33: 15846 | AV33: =30248-AU33 -> 14402
B34: Others. | C34: -276 | D34: -1307 | E34: -2688 | F34: -101 | G34: -12 | H34: -7 | I34: -12 | J34: -18 | K34: -48 | L34: -7 | M34: =SUM(AS34:AV34) -> -3 | O34: -621 | P34: =-1313-O34 -> -692 | Q34: =-1839-P34-O34 -> -526 | R34: =+E34-SUM(O34:Q34) -> -849 | S34: -6 | T34: =-10-S34 -> -4 | U34: =-91-T34-S34 -> -81 | V34: =+F34-SUM(S34:U34) -> -10 | W34: -6 | X34: =-8-W34 -> -2 | Y34: =-7-X34-W34 -> 1 | Z34: =+G34-SUM(W34:Y34) -> -5 | AA34: -2 | AB34: =-4-AA34 -> -2 | AC34: =-7-AB34-AA34 -> -3 | AD34: =+H34-SUM(AA34:AC34) -> 0 | AE34: -5 | AF34: =-8-AE34 -> -3 | AG34: =-11-AF34-AE34 -> -3 | AH34: =+I34-SUM(AE34:AG34) -> -1 | AI34: -5 | AJ34: =-7-AI34 -> -2 | AK34: =-15-AJ34-AI34 -> -8 | AL34: =+J34-SUM(AI34:AK34) -> -3 | AM34: -31 | AN34: =-46-AM34 -> -15 | AO34: =-102-AM34-AN34 -> -56 | AP34: =+K34-SUM(AM34:AO34) -> 54 | AQ34: -5 | AR34: =-6-AQ34 -> -1 | AS34: =-6-AQ34-AR34 -> 0 | AT34: =+L34-SUM(AQ34:AS34) -> -1 | AU34: -1 | AV34: =-2-AU34 -> -1
B35: Inter-segment transactions | C35: 1572 | D35: 1608 | E35: 1605 | F35: -6035 | G35: -7507 | H35: -10801 | I35: -9666 | J35: -9156 | K35: -9024 | L35: -9604 | M35: =SUM(AS35:AV35) -> -7929 | O35: 386 | P35: =794-O35 -> 408 | Q35: =1172-P35-O35 -> 378 | R35: =+E35-SUM(O35:Q35) -> 433 | S35: -1357 | T35: =-2718-S35 -> -1361 | U35: =-4139-T35-S35 -> -1421 | V35: =+F35-SUM(S35:U35) -> -1896 | W35: -1663 | X35: =-3212-W35 -> -1549 | Y35: =-4852-X35-W35 -> -1640 | Z35: =+G35-SUM(W35:Y35) -> -2655 | AA35: -2035 | AB35: =-4341-AA35 -> -2306 | AC35: =-6766-AB35-AA35 -> -2425 | AD35: =+H35-SUM(AA35:AC35) -> -4035 | AE35: -3597 | AF35: =-7443-AE35 -> -3846 | AG35: =-11158-AF35-AE35 -> -3715 | AH35: =+I35-SUM(AE35:AG35) -> 1492 | AI35: -2453 | AJ35: =-4934-AI35 -> -2481 | AK35: =-7044-AJ35-AI35 -> -2110 | AL35: =+J35-SUM(AI35:AK35) -> -2112 | AM35: -1083 | AN35: =-3022-AM35 -> -1939 | AO35: =-5284-AM35-AN35 -> -2262 | AP35: =+K35-SUM(AM35:AO35) -> -3740 | AQ35: -2285 | AR35: =-4401-AQ35 -> -2116 | AS35: =-6564-AQ35-AR35 -> -2163 | AT35: =+L35-SUM(AQ35:AS35) -> -3040 | AU35: -1194 | AV35: =-2726-AU35 -> -1532
B36: Discontinued Operations | H36: -13 | I36: -326 | J36: 0 | K36: 0 | L36: 0 | M36: =SUM(AS36:AV36) -> 0 | AD36: =+H36-SUM(AA36:AC36) -> -13 | AE36: 4 | AF36: =-8-AE36 -> -12 | AG36: =-59-AF36-AE36 -> -51 | AH36: =+I36-SUM(AE36:AG36) -> -267 | AI36: -21 | AJ36: =-39-AI36 -> -18 | AK36: =-45-AJ36-AI36 -> -6 | AL36: =+J36-SUM(AI36:AK36) -> 45 | AM36: 0 | AN36: =0-AM36 -> 0 | AO36: =0-AM36-AN36 -> 0 | AP36: =+K36-SUM(AM36:AO36) -> 0 | AQ36: 0 | AR36: =0-AQ36 -> 0 | AS36: =0-AQ36-AR36 -> 0 | AT36: =+L36-SUM(AQ36:AS36) -> 0 | AU36: 0 | AV36: =0-AU36 -> 0
B37: Total | C37: =+C32+C33+C34+C35+C36 -> 61161 | D37: =+D32+D33+D34+D35+D36 -> 66174 | E37: =+E32+E33+E34+E35+E36 -> 64027 | F37: =+F32+F33+F34+F35+F36 -> 79815 | G37: =+G32+G33+G34+G35+G36 -> 86158 | H37: =+H32+H33+H34+H35+H36 -> 96169 | I37: 100262 | J37: =+J32+J33+J34+J35+J36 -> 104297 | K37: =+K32+K33+K34+K35+K36 -> 108515 | L37: =+L32+L33+L34+L35+L36 -> 111231 | M37: =+M32+M33+M34+M35+M36 -> 111749 | O37: =+O32+O33+O34+O35+O36 -> 16533 | P37: =+P32+P33+P34+P35+P36 -> 16652 | Q37: =+Q32+Q33+Q34+Q35+Q36 -> 16514 | R37: =+R32+R33+R34+R35+R36 -> 14328 | S37: =+S32+S33+S34+S35+S36 -> 19847 | T37: =+T32+T33+T34+T35+T36 -> 19819 | U37: =+U32+U33+U34+U35+U36 -> 18269 | V37: =+V32+V33+V34+V35+V36 -> 21880 | ... AG37: =+AG32+AG33+AG34+AG35+AG36 -> 24606 | AH37: =+AH32+AH33+AH34+AH35+AH36+3000 -> 30920 | AI37: =+AI32+AI33+AI34+AI35+AI36 -> 24378 | AJ37: =+AJ32+AJ33+AJ34+AJ35+AJ36 -> 25341 | AK37: =+AK32+AK33+AK34+AK35+AK36 -> 26215 | AL37: =+AL32+AL33+AL34+AL35+AL36 -> 28363 | AM37: =+AM32+AM33+AM34+AM35+AM36 -> 27315 | AN37: =+AN32+AN33+AN34+AN35+AN36 -> 26621 | AO37: =+AO32+AO33+AO34+AO35+AO36 -> 26782 | AP37: =+AP32+AP33+AP34+AP35+AP36 -> 27797 | ... AV37: =+AV32+AV33+AV34+AV35+AV36 -> 27762
B38: Check | C38: =C37-Model!C55 -> 0 | D38: =D37-Model!D55 -> 0 | E38: =E37-Model!E55 -> 0 | F38: =F37-Model!F55 -> 0 | G38: =G37-Model!G55 -> 0 | H38: =H37-Model!H51 -> 0 | I38: =I37-Model!I51 -> 0 | J38: =J37-Model!J51 -> 0 | K38: =K37-Model!K51 -> 0 | L38: =L37-Model!L51 -> 0 | M38: =M37-Model!M51 -> 0 | O38: =O37-Model!O55 -> 0 | P38: =P37-Model!P55 -> 0 | Q38: =Q37-Model!Q55 -> 0 | R38: =R37-Model!R55 -> 0 | S38: =S37-Model!S55 -> 0 | T38: =T37-Model!T55 -> 0 | U38: =U37-Model!U55 -> 0 | V38: =V37-Model!V55 -> 0 | ... Z38: =Z37-Model!Z55 -> 0 | AA38: =AA37-Model!AA51 -> 0 | AB38: =AB37-Model!AB51 -> 0 | AC38: =AC37-Model!AC51 -> 0 | AD38: =AD37-Model!AD51 -> 0 | AE38: =AE37-Model!AE51 -> 0 | AF38: =AF37-Model!AF51 -> 0 | AG38: =AG37-Model!AG51 -> 0 | AH38: =AH37-Model!AH51 -> 0 | ... AV38: =AV37-Model!AV51 -> 0
B40: % margin
B41: Wireless | C41: =+C32/C9 -> 0.31622585 | D41: =+D32/D9 -> 0.39315344 | E41: =+E32/E9 -> 0.38068921 | F41: =+F32/F9 -> 0.54474439 | G41: =+G32/G9 -> 0.57836505 | H41: =+H32/H9 -> 0.57185867 | I41: =+I32/I9 -> 0.50074803 | J41: =+J32/J9 -> 0.54123045 | ... M41: =+M32/M9 -> 0.56605204 | O41: =+O32/O9 -> 0.37796565 | P41: =+P32/P9 -> 0.39915206 | Q41: =+Q32/Q9 -> 0.38272777 | R41: =+R32/R9 -> 0.36289108 | S41: =+S32/S9 -> 0.54097559 | T41: =+T32/T9 -> 0.58289108 | U41: =+U32/U9 -> 0.53765776 | V41: =+V32/V9 -> 0.52007917 | ... AV41: =+AV32/AV9 -> 0.56958733
B42: Fixed Line | C42: =+C33/C10 -> 0.37055879 | D42: =+D33/D10 -> 0.37627807 | E42: =+E33/E10 -> 0.36228908 | F42: =+F33/F10 -> 0.3709147 | G42: =+G33/G10 -> 0.33831617 | H42: =+H33/H10 -> 0.39674288 | I42: =+I33/I10 -> 0.4307253 | J42: =+J33/J10 -> 0.47183064 | ... M42: =+M33/M10 -> 0.46814026 | O42: =+O33/O10 -> 0.4022584 | P42: =+P33/P10 -> 0.37263506 | Q42: =+Q33/Q10 -> 0.37783619 | R42: =+R33/R10 -> 0.29950653 | S42: =+S33/S10 -> 0.4111096 | T42: =+T33/T10 -> 0.33058781 | U42: =+U33/U10 -> 0.29886297 | V42: =+V33/V10 -> 0.44132008 | ... AV42: =+AV33/AV10 -> 0.45055529
B43: Others. | C43: =+IFERROR(C34/C11,"") -> -0.32585596 | D43: =+IFERROR(D34/D11,"") -> -1.0218921 | E43: =+IFERROR(E34/E11,"") -> -2.3620387 | F43: =+IFERROR(F34/F11,"") | G43: =+IFERROR(G34/G11,"") | H43: =+IFERROR(H34/H11,"") | I43: =+IFERROR(I34/I11,"") | J43: =+IFERROR(J34/J11,"") | ... M43: =+IFERROR(M34/M11,"") | O43: =+IFERROR(O34/O11,"") -> -1.9903846 | P43: =+IFERROR(P34/P11,"") -> -2.3066667 | Q43: =+IFERROR(Q34/Q11,"") -> -1.6967742 | R43: =+IFERROR(R34/R11,"") -> -3.9305556 | S43: =+IFERROR(S34/S11,"") | T43: =+IFERROR(T34/T11,"") | U43: =+IFERROR(U34/U11,"") | V43: =+IFERROR(V34/V11,"") | ... AV43: =+IFERROR(AV34/AV11,"")
B44: Inter-segment transactions | C44: =+C35/C12 -> -0.11894673 | D44: =+D35/D12 -> -0.12127611 | E44: =+E35/E12 -> -0.12 | F44: =+F35/F12 -> 0.35240876 | G44: =+G35/G12 -> 0.34206689 | H44: =+H35/H12 -> 0.35500411 | I44: =+I35/I12 -> 0.34867614 | J44: =+J35/J12 -> 0.64560711 | ... M44: =+M35/M12 -> 0.6084721 | O44: =+O35/O12 -> -0.13524877 | P44: =+P35/P12 -> -0.16957606 | Q44: =+Q35/Q12 -> -0.084280936 | R44: =+R35/R12 -> -0.11928375 | S44: =+S35/S12 -> 0.35064599 | T44: =+T35/T12 -> 0.29625599 | U44: =+U35/U12 -> 0.33809184 | V44: =+V35/V12 -> 0.42530283 | ... AV44: =+AV35/AV12 -> 0.58495609
B45: Total | C45: =+C37/C13 -> 0.37192148 | D45: =+D37/D13 -> 0.41636413 | E45: =+E37/E13 -> 0.39301104 | F45: =+F37/F13 -> 0.4717561 | G45: =+G37/G13 -> 0.47600053 | H45: =+H37/H13 -> 0.50039545 | I45: =+I37/I13 -> 0.4906098 | J45: =+J37/J13 -> 0.49440871 | ... M45: =+M37/M13 -> 0.50606376 | O45: =+O37/O13 -> 0.40815168 | P45: =+P37/P13 -> 0.39902233 | Q45: =+Q37/Q13 -> 0.41663093 | R45: =+R37/R13 -> 0.34913982 | S45: =+S37/S13 -> 0.48862573 | T45: =+T37/T13 -> 0.47911328 | U45: =+U37/U13 -> 0.43034486 | V45: =+V37/V13 -> 0.48892762 | ... AV45: =+AV37/AV13 -> 0.50027931
B48: Mobile Subscribers by Category | C48: =+C49+C54 -> 62763209 | D48: =+D49+D54 -> 58293908 | E48: =+E49+E54 -> 60499017 | F48: =+F49+F54 -> 73118155 | G48: =+G49+G54 -> 72933839 | H48: =+H49+H54 -> 71221952 | I48: =+I49+I54 -> 66304761 | J48: =+J49+J54 -> 57827126 | ... M48: =+M49+M54 -> 60088208 | O48: =+O49+O54 -> 58117819 | P48: =+P49+P54 -> 58510872 | Q48: =+Q49+Q54 -> 58034007 | R48: =+R49+R54 -> 60499017 | S48: =+S49+S54 -> 63948886 | T48: =+T49+T54 -> 67547646 | U48: =+U49+U54 -> 71451288 | V48: =+V49+V54 -> 73118155 | ... AV48: =+AV49+AV54 -> 60088208
B49: Prepaid | C49: =+C50+C51+C52 -> 59952941 | D49: =+D50+D51+D52 -> 55776646 | E49: =+E50+E51+E52 -> 58178978 | F49: =+F50+F51+F52 -> 70721789 | G49: =+G50+G51+G52 -> 70779021 | H49: =+H50+H51+H52 -> 69205731 | I49: =+I50+I51+I52 -> 64287019 | J49: =+J50+J51+J52 -> 55667880 | ... M49: =+M50+M51+M52 -> 57684768 | O49: =+O50+O51+O52 -> 55666020 | P49: =+P50+P51+P52 -> 56081230 | Q49: =+Q50+Q51+Q52 -> 55627968 | R49: =+R50+R51+R52 -> 58178978 | S49: =+S50+S51+S52 -> 61585197 | T49: =+T50+T51+T52 -> 65151418 | U49: =+U50+U51+U52 -> 69012106 | V49: =+V50+V51+V52 -> 70721789 | ... AV49: =+AV50+AV51+AV52 -> 57684768
B50: Smart Prepaid | C50: 21643963 | D50: 20433351 | E50: 20532174 | F50: 25866195 | G50: 29090167 | H50: 26665974 | I50: 24394379 | J50: 21530993 | K50: 21759728 | L50: 21713502 | M50: =AV50 -> 21737420 | O50: 20198965 | P50: 20261130 | Q50: 19526064 | R50: =+E50 -> 20532174 | S50: 22011859 | T50: 23734790 | U50: 25240171 | V50: =+F50 -> 25866195 | W50: 24830033 | X50: 23413304 | Y50: 23983929 | Z50: =+G50 -> 29090167 | AA50: 27227210 | AB50: 26915884 | AC50: 25966496 | AD50: =+H50 -> 26665974 | AE50: 26229708 | AF50: 25679480 | AG50: 25103659 | AH50: =+I50 -> 24394379 | AI50: 24044239 | AJ50: 23486725 | AK50: 20494009 | AL50: =+J50 -> 21530993 | AM50: 21856044 | AN50: 22550066 | AO50: 22416116 | AP50: =+K50 -> 21759728 | AQ50: 21324961 | AR50: 21247707 | AS50: 21420767 | AT50: =L50 -> 21713502 | AU50: 22005736 | AV50: 21737420
...
