Workbook
Name \A: #REF!
Name \B: #REF!
Name \C: #REF!
Name \L: #REF!
Name \M: #REF!
Name \P: #REF!
Name \Y: #REF!
Name _01_30_04: MonthlyOpStats
Name _01_30_04: MonthlyOpStats
Name _01_30_04: MonthlyOpStats
Name _1_30_01: MonthlyOpStats
Name _1_30_01: MonthlyOpStats
Name _1_30_01: MonthlyOpStats
Name _1_30_02: MonthlyOpStats
Name _1_30_02: MonthlyOpStats
Name _1_30_02: MonthlyOpStats
Name _1_31_01: MonthlyOpStats
Name _1_31_01: MonthlyOpStats
Name _1_31_01: MonthlyOpStats
Name _1_31_02: MonthlyOpStats
Name _1_31_02: MonthlyOpStats
Name _1_31_02: MonthlyOpStats
Name _12_31_05: MonthlyOpStats
Name _12_31_05: MonthlyOpStats
Name _12_31_05: MonthlyOpStats
Name _A: #REF!
Name _A___0: #REF!
Name _B: #REF!
Name _B___0: #REF!
Name _C: #REF!
Name _C___0: #REF!
Name _ent1: [1]Inputs!$J$17
Name _ent10: [1]Inputs!$J$476
Name _ent11: [1]Inputs!$J$527
Name _ent12: [1]Inputs!$J$578
Name _ent13: [1]Inputs!$J$629
Name _ent14: [1]Inputs!$J$680
Name _ent15: [1]Inputs!$J$731
Name _ent2: [1]Inputs!$J$68
Name _ent3: [1]Inputs!$J$119
Name _ent4: [1]Inputs!$J$170
Name _ent5: [1]Inputs!$J$221
Name _ent6: [1]Inputs!$J$272
Name _ent7: [1]Inputs!$J$323
Name _ent8: [1]Inputs!$J$374
Name _ent9: [1]Inputs!$J$425
Name _eps1: [1]Inputs!$P$42
Name _eps10: [1]Inputs!$P$501
Name _eps11: [1]Inputs!$P$552
Name _eps12: [1]Inputs!$P$603
Name _eps13: [1]Inputs!$P$654
Name _eps14: [1]Inputs!$P$705
Name _eps15: [1]Inputs!$P$756
Name _eps2: [1]Inputs!$P$93
Name _eps3: [1]Inputs!$P$144
Name _eps4: [1]Inputs!$P$195
Name _eps5: [1]Inputs!$P$246
Name _eps6: [1]Inputs!$P$297
Name _eps7: [1]Inputs!$P$348
Name _eps8: [1]Inputs!$P$399

Sheet Capitalisation
B2: 1Q26 | I2: Exchange rate as at end | J2: =Model!$M$203 -> 0.2664535
I3: LTM Average Exchange rate | J3: =Model!$M$205 -> 0.26659423
C5: Amount outstanding as on Mar 2026 | D5: SAR (mn) | E5: USD (mn) | F5: Leverage | G5: USD Leverage | I5: Company reported | J5: =D5 -> SAR (mn)
I6: Net debt | J6: 11982
C7: Current Liabilities | D7: =SUM(D8:D13) -> 1555.181 | E7: =SUM(E8:E13) -> 414.38343 | I7: Net debt / EBITDA | J7: 2.48x
C8: Islamic Banking Facilities (Murabaha) | D8: 1058.026 | E8: =D8*$J$2 -> 281.91473
C9: Saudi Industrial Development Fund ("SIDF") | D9: 287.182 | E9: =D9*$J$2 -> 76.52065
C10: Banking Facilities of Non-GCC Subsidiaries | D10: 88.716 | E10: =D10*$J$2 -> 23.638689
C11: Supranational (Murabaha) | D11: 72.858 | E11: =D11*$J$2 -> 19.413269
C12: Agricultural Development Fund ("ADF") | D12: 24.207 | E12: =D12*$J$2 -> 6.45004
C13: International Sukuk | D13: 24.192 | E13: =D13*$J$2 -> 6.4460432
C15: Non-Current Liabilities | D15: =SUM(D16:D21) -> 12021.836 | E15: =SUM(E16:E21) -> 3203.2603
C16: Islamic Banking Facilities (Murabaha) | D16: 7132.026 | E16: =D16*$J$2 -> 1900.3533
C17: Saudi Industrial Development Fund ("SIDF") | D17: 41.169 | E17: =D17*$J$2 -> 10.969624
C18: Banking Facilities of Non-GCC Subsidiaries | D18: 136.616 | E18: =D18*$J$2 -> 36.401812
C19: Supranational (Murabaha) | D19: 23.205 | E19: =D19*$J$2 -> 6.1830536
C20: Agricultural Development Fund ("ADF") | D20: 18.643 | E20: =D20*$J$2 -> 4.9674927
C21: International Sukuk | D21: 4670.177 | E21: =D21*$J$2 -> 1244.385
C23: Bank Overdraft | D23: 24.934 | E23: =D23*$J$2 -> 6.6437517
C25: Leases | D25: =SUM(D26:D27) -> 536.34 | E25: =SUM(E26:E27) -> 142.90967
C26: Current | D26: 95.07 | E26: =D26*$J$2 -> 25.331735
C27: Non-current | D27: 441.27 | E27: =D27*$J$2 -> 117.57794
C29: Total Loans & Borrowings | D29: =SUM(D7,D15,D25,D23) -> 14138.291 | E29: =SUM(E7,E15,E25,E23) -> 3767.1972 | F29: =+D29/D34 -> 2.8615825 | G29: =+E29/E34 -> 2.8600719
C30: Cash & Equivalents | D30: =Model!$AU$109 -> 1620.349 | E30: =D30*$J$2 -> 431.74767
C31: Net debt | D31: =+D29-D30 -> 12517.942 | E31: =+E29-E30 -> 3335.4495 | F31: =+D31/D34 -> 2.5336247 | G31: =+E31/E34 -> 2.5322873
C32: Equity | D32: =Model!$AU$116 -> 21117.81 | E32: =D32*$J$2 -> 5626.9145
C33: Total Capitalisation | D33: =D29+D32 -> 35256.101 | E33: =E29+E32 -> 9394.1116 | F33: =D33/D34 -> 7.1358159 | G33: =E33/E34 -> 7.132049
C34: LTM Adjusted EBITDA | D34: =Model!$AU$82 -> 4940.7246 | E34: =D34*J3 -> 1317.1687
C35: check | D35: =D29-Model!$AU$112 -> 0
C38: Liquidity Table | D38: =D5 -> SAR (mn) | E38: =E5 -> USD (mn)
C39: Cash and cash equivalents | D39: =D30 -> 1620.349 | E39: =D39*$J$2 -> 431.74767
C40: Total Liquidity | D40: =SUM(D39:D39) -> 1620.349 | E40: =SUM(E39:E39) -> 431.74767
C44: Debt Maturity of the debt at end (from PPT) | D44: =D5 -> SAR (mn) | E44: =E5 -> USD (mn)
C46: less than 1 year | D46: 1600 | E46: =D46*J2 -> 426.32561
C47: Between 1-2 years | D47: 2400 | E47: =D47*J2 -> 639.48841
C48: Between 2-3 years | D48: 400 | E48: =D48*J2 -> 106.5814
C49: Between 3-4 years | D49: 0 | E49: =D49*J2 -> 0
C50: Between 4-5 years | D50: 3000 | E50: =D50*J2 -> 799.36051
C51: Over 5 years | D51: 6300 | E51: =D51*J2 -> 1678.6571
C53: Total debt (excluding lease liabilities and bank overdrafts) | D53: =SUM(D45:D52) -> 13700 | E53: =SUM(E45:E52) -> 3650.413
...

Sheet Model
B2: ALMARAI | C2: Annual | D2: Annual | E2: Annual | F2: Annual | G2: Annual | H2: Annual | I2: Annual | J2: Annual | K2: Annual | L2: Annual | M2: LTM | O2: Quarterly | P2: Quarterly | Q2: Quarterly | R2: Quarterly | S2: Quarterly | T2: Quarterly | U2: Quarterly | V2: Quarterly | W2: Quarterly | X2: Quarterly | Y2: Quarterly | Z2: Quarterly | AA2: Quarterly | AB2: Quarterly | AC2: Quarterly | AD2: Quarterly | AE2: Quarterly | AF2: Quarterly | AG2: Quarterly | AH2: QuarterIy | AI2: Quarterly | AJ2: Quarterly | AK2: Quarterly | AL2: QuarterIy | AM2: Quarterly | AN2: Quarterly | AO2: Quarterly | AP2: QuarterIy | AQ2: Quarterly | AR2: Quarterly | AS2: Quarterly | AT2: QuarterIy | AU2: Quarterly | AW2: Quarterly | AX2: Quarterly
B3: (SAR millions) | C3: 42735 | D3: 43100 | E3: 43465 | F3: 43830 | G3: 44196 | H3: 44561 | I3: 44926 | J3: 45291 | K3: 45657 | L3: 46022 | M3: =AU3 -> 46111 | O3: 43189 | P3: 43281 | Q3: 43373 | R3: 43464 | S3: 43554 | T3: 43646 | U3: 43738 | V3: 43829 | W3: 43920 | X3: 44012 | Y3: 44104 | Z3: 44195 | AA3: 44285 | AB3: 44377 | AC3: 44469 | AD3: 44560 | AE3: 44650 | AF3: 44742 | AG3: 44834 | AH3: 44926 | AI3: 45015 | AJ3: 45107 | AK3: 45199 | AL3: 45291 | AM3: 45381 | AN3: 45473 | AO3: 45565 | AP3: 45657 | AQ3: 45746 | AR3: 45838 | AS3: 45930 | AT3: 46022 | AU3: 46111 | AW3: 43554 | AX3: 43646
C4: Act | D4: Act | E4: Act | F4: Act | G4: Act | H4: Act | I4: Act | J4: Act | K4: Act | L4: Act | M4: Act | O4: Act | P4: Act | Q4: Act | R4: Act | S4: Act | T4: Act | U4: Act | V4: Act | W4: Act | X4: Act | Y4: Act | Z4: Act | AA4: Act | AB4: Act | AC4: Act | AD4: Act | AE4: Act | AF4: Act | AG4: Act | AH4: Act | AI4: Act | AJ4: Act | AK4: Act | AL4: Act | AM4: Act | AN4: Act | AO4: Act | AP4: Act | AQ4: Act | AR4: Act | AS4: Act | AT4: Act | AU4: Act | AW4: Restated | AX4: Restated
C5: FY | D5: FY | E5: FY | F5: FY | G5: FY | H5: FY | I5: FY | J5: FY | K5: FY | L5: FY | M5: LTM | O5: Q1 | P5: Q2 | Q5: Q3 | R5: Q4 | S5: Q1 | T5: Q2 | U5: Q3 | V5: Q4 | W5: Q1 | X5: Q2 | Y5: Q3 | Z5: Q4 | AA5: Q1 | AB5: Q2 | AC5: Q3 | AD5: Q4 | AE5: Q1 | AF5: Q2 | AG5: Q3 | AH5: Q4 | AI5: Q1 | AJ5: Q2 | AK5: Q3 | AL5: Q4 | AM5: Q1 | AN5: Q2 | AO5: Q3 | AP5: Q4 | AQ5: Q1 | AR5: Q2 | AS5: Q3 | AT5: Q4 | AU5: Q1 | AW5: Q1 | AX5: Q2
B6: INCOME STATEMENT
B7: Revenue | C7: 14338.579 | D7: 13935.532 | E7: 13557.837 | F7: 14351.277 | G7: 15356.948 | H7: 15849.72 | I7: 18722.258 | J7: 19575.585 | K7: 20979.512 | L7: 22064.876 | M7: =SUM(AR7:AU7) -> 22457.839 | O7: 3232.205 | P7: =6859.293-O7 -> 3627.088 | Q7: =10176.653-P7-O7 -> 3317.36 | R7: =E7-Q7-P7-O7 -> 3381.184 | S7: 3354.083 | T7: =7074.082-S7 -> 3719.999 | U7: =10647.339-T7-S7 -> 3573.257 | V7: =F7-U7-T7-S7 -> 3703.938 | W7: 3592.44 | X7: 4081.844 | Y7: 3863.079 | Z7: =G7-Y7-X7-W7 -> 3819.585 | AA7: 3645.014 | AB7: 4005.568 | AC7: 3941.73 | AD7: =H7-AC7-AB7-AA7 -> 4257.408 | AE7: 4503.457 | AF7: 4610.447 | AG7: 4769.121 | AH7: =I7-AG7-AF7-AE7 -> 4839.233 | AI7: 5066.564 | AJ7: 4792.349 | AK7: 4796.934 | AL7: =J7-AK7-AJ7-AI7 -> 4919.738 | AM7: 5458.641 | AN7: 5154.621 | AO7: 5208.921 | AP7: =K7-AO7-AN7-AM7 -> 5157.329 | AQ7: 5767.09 | AR7: 5288.402 | AS7: 5552.599 | AT7: =L7-AS7-AR7-AQ7 -> 5456.785 | AU7: 6160.053 | AW7: 3308.892 | AX7: 3767.424
B8: % y-o-y growth | D8: =D7/C7-1 -> -0.028109271 | E8: =E7/D7-1 -> -0.02710302 | F8: =F7/E7-1 -> 0.058522609 | G8: =G7/F7-1 -> 0.070075367 | H8: =H7/G7-1 -> 0.032087886 | I8: =I7/H7-1 -> 0.18123588 | J8: =J7/I7-1 -> 0.04557821 | K8: =K7/J7-1 -> 0.071718265 | L8: =L7/K7-1 -> 0.051734473 | S8: =S7/O7-1 -> 0.037707386 | T8: =T7/P7-1 -> 0.025615866 | U8: =U7/Q7-1 -> 0.077138749 | V8: =V7/R7-1 -> 0.095455911 | W8: =W7/AW7-1 -> 0.085692733 | X8: =X7/AX7-1 -> 0.083457556 | Y8: =Y7/U7-1 -> 0.081108636 | Z8: =Z7/V7-1 -> 0.031222715 | AA8: =AA7/W7-1 -> 0.014634622 | AB8: =AB7/X7-1 -> -0.018686652 | AC8: =AC7/Y7-1 -> 0.020359666 | AD8: =AD7/Z7-1 -> 0.1146258 | AE8: =AE7/AA7-1 -> 0.23551158 | AF8: =AF7/AB7-1 -> 0.15100954 | ... AU8: =AU7/AQ7-1 -> 0.068138871 | AW8: =AW7/O7-1 -> 0.023725908 | AX8: =AX7/W7-1 -> 0.048708955
B9: Cost of Sales | C9: -8816.092 | D9: -8351.893 | E9: -8230.763 | F9: -8984.603 | G9: -9821.44 | H9: -10790.45 | I9: -13098.035 | J9: -13524.295 | K9: -14315.46 | L9: -15177.063 | M9: =SUM(AR9:AU9) -> -15472.772 | O9: -1977.776 | P9: =-4201.65-O9 -> -2223.874 | Q9: =-6112.52-P9-O9 -> -1910.87 | R9: =E9-Q9-P9-O9 -> -2118.243 | S9: -2144.464 | T9: =-4444.682-S9 -> -2300.218 | U9: =-6574.174-T9-S9 -> -2129.492 | V9: =F9-U9-T9-S9 -> -2410.429 | W9: -2339.247 | X9: -2546.659 | Y9: -2348.379 | Z9: =G9-Y9-X9-W9 -> -2587.155 | AA9: -2409.909 | AB9: -2649.829 | AC9: -2666.017 | AD9: =H9-AC9-AB9-AA9 -> -3064.695 | AE9: -3171.541 | AF9: -3140.841 | AG9: -3280.406 | AH9: =I9-AG9-AF9-AE9 -> -3505.247 | AI9: -3448.713 | AJ9: -3225.27 | AK9: -3327.482 | AL9: =J9-AK9-AJ9-AI9 -> -3522.83 | AM9: -3750.18 | AN9: -3452.286 | AO9: -3539.024 | AP9: =K9-AO9-AN9-AM9 -> -3573.97 | AQ9: -3998.435 | AR9: -3575.223 | AS9: -3805.242 | AT9: =L9-AS9-AR9-AQ9 -> -3798.163 | AU9: -4294.144 | AW9: -2144.986 | AX9: -2301.203
B10: Gross Profit | C10: =C7+C9 -> 5522.487 | D10: =D7+D9 -> 5583.639 | E10: =E7+E9 -> 5327.074 | F10: =F7+F9 -> 5366.674 | G10: =G7+G9 -> 5535.508 | H10: =H7+H9 -> 5059.27 | I10: =I7+I9 -> 5624.223 | J10: =J7+J9 -> 6051.29 | ... M10: =M7+M9 -> 6985.067 | O10: =O7+O9 -> 1254.429 | P10: =P7+P9 -> 1403.214 | Q10: =Q7+Q9 -> 1406.49 | R10: =R7+R9 -> 1262.941 | S10: =S7+S9 -> 1209.619 | T10: =T7+T9 -> 1419.781 | U10: =U7+U9 -> 1443.765 | V10: =V7+V9 -> 1293.509 | ... AU10: =AU7+AU9 -> 1865.909 | AW10: =AW7+AW9 -> 1163.906 | AX10: =AX7+AX9 -> 1466.221
B11: Gross Profit margin | C11: =C10/C7 -> 0.38514884 | D11: =D10/D7 -> 0.40067641 | E11: =E10/E7 -> 0.39291474 | F11: =F10/F7 -> 0.37395097 | G11: =G10/G7 -> 0.36045626 | H11: =H10/H7 -> 0.31920248 | I11: =I10/I7 -> 0.30040303 | J11: =J10/J7 -> 0.30912435 | ... M11: =M10/M7 -> 0.31103024 | O11: =O10/O7 -> 0.38810317 | P11: =P10/P7 -> 0.38687068 | Q11: =Q10/Q7 -> 0.42397871 | R11: =R10/R7 -> 0.37352034 | S11: =S10/S7 -> 0.36064075 | T11: =T10/T7 -> 0.38166166 | U11: =U10/U7 -> 0.40404734 | V11: =V10/V7 -> 0.34922534 | ... AU11: =AU10/AU7 -> 0.3029047 | AW11: =AW10/AW7 -> 0.35175098 | AX11: =AX10/AX7 -> 0.38918396
B12: Selling and Distribution Expenses | C12: -2480.361 | D12: -2343.046 | E12: -2180.244 | F12: -2376.328 | G12: -2490.479 | H12: -2518.851 | I12: -2709.538 | J12: -2789.745 | K12: -2993.918 | L12: -3231.061 | M12: =SUM(AR12:AU12) -> -3295.359 | O12: -595.196 | P12: =-1107.697-O12 -> -512.501 | Q12: =-1647.242-P12-O12 -> -539.545 | R12: =E12-Q12-P12-O12 -> -533.002 | S12: -609.729 | T12: =-1148.217-S12 -> -538.488 | U12: =-1742.32-T12-S12 -> -594.103 | V12: =F12-U12-T12-S12 -> -634.008 | W12: -611.569 | X12: -632.958 | Y12: -642.003 | Z12: =G12-Y12-X12-W12 -> -603.949 | AA12: -604.052 | AB12: -634.826 | AC12: -646.441 | AD12: =H12-AC12-AB12-AA12 -> -633.532 | AE12: -647.428 | AF12: -666.308 | AG12: -709.792 | AH12: =I12-AG12-AF12-AE12 -> -686.01 | AI12: -678.841 | AJ12: -689.08 | AK12: -725.211 | AL12: =J12-AK12-AJ12-AI12 -> -696.613 | AM12: -695.754 | AN12: -726.777 | AO12: -778.439 | AP12: =K12-AO12-AN12-AM12 -> -792.948 | AQ12: -754.094 | AR12: -766.224 | AS12: -835.842 | AT12: =L12-AS12-AR12-AQ12 -> -874.901 | AU12: -818.392 | AW12: -564.538 | AX12: -585.913
B13: General and Administration Expenses | C13: -432.949 | D13: -397.339 | E13: -375.204 | F13: -400.273 | G13: -419.79 | H13: -428.157 | I13: -458.694 | J13: -469.023 | K13: -508.149 | L13: -561.463 | M13: =SUM(AR13:AU13) -> -570.157 | O13: -96.127 | P13: =-195.1-O13 -> -98.973 | Q13: =-274.326-P13-O13 -> -79.226 | R13: =E13-Q13-P13-O13 -> -100.878 | S13: -94.754 | T13: =-194.58-S13 -> -99.826 | U13: =-274.095-T13-S13 -> -79.515 | V13: =F13-U13-T13-S13 -> -126.178 | W13: -99.828 | X13: -105.109 | Y13: -83.956 | Z13: =G13-Y13-X13-W13 -> -130.897 | AA13: -97.308 | AB13: -104.96 | AC13: -85.095 | AD13: =H13-AC13-AB13-AA13 -> -140.794 | AE13: -104.787 | AF13: -110.733 | AG13: -95.831 | AH13: =I13-AG13-AF13-AE13 -> -147.343 | AI13: -113.199 | AJ13: -117.414 | AK13: -95.626 | AL13: =J13-AK13-AJ13-AI13 -> -142.784 | AM13: -121.607 | AN13: -124.305 | AO13: -103.052 | AP13: =K13-AO13-AN13-AM13 -> -159.185 | AQ13: -129.293 | AR13: -130.036 | AS13: -121.737 | AT13: =L13-AS13-AR13-AQ13 -> -180.397 | AU13: -137.987 | AW13: -94.754 | AX13: -99.826
B14: Other Expenses, net | C14: -91.398 | D14: -211.071 | E14: -275.075 | F14: -88.672 | G14: -78.428 | H14: -85.563 | I14: -153.356 | J14: -64.461 | K14: -63.166 | L14: -14.813 | M14: =SUM(AR14:AU14) -> -29.649 | O14: -44.446 | P14: =-78.251-O14 -> -33.805 | Q14: =-116.079-P14-O14 -> -37.828 | R14: =E14-Q14-P14-O14 -> -158.996 | S14: -22.437 | T14: =-67.604-S14 -> -45.167 | U14: =-81.511-T14-S14 -> -13.907 | V14: =F14-U14-T14-S14 -> -7.161 | W14: -0.491 | X14: -31.172 | Y14: -39.514 | Z14: =G14-Y14-X14-W14 -> -7.251 | AA14: -31.217 | AB14: -19.902 | AC14: -19.247 | AD14: =H14-AC14-AB14-AA14 -> -15.197 | AE14: -22.43 | AF14: -33.699 | AG14: -100.073 | AH14: =I14-AG14-AF14-AE14 -> 2.846 | AI14: -13.312 | AJ14: -38.782 | AK14: -2.779 | AL14: =J14-AK14-AJ14-AI14 -> -9.588 | AM14: -0.518 | AN14: -39.824 | AO14: -29.638 | AP14: =K14-AO14-AN14-AM14 -> 6.814 | AQ14: -11.373 | AR14: 11.991 | AS14: -30.428 | AT14: =L14-AS14-AR14-AQ14 -> 14.997 | AU14: -26.209 | AW14: -16.422 | AX14: -40.221
B15: Impairment (Loss) / Reversal on Financial Assets | C15: 0 | D15: -48.833 | E15: 24.684 | F15: -28.193 | G15: -24.477 | H15: -11.845 | I15: -26.303 | J15: -34.173 | K15: -103.458 | L15: -20.214 | M15: =SUM(AR15:AU15) -> -28.647 | O15: -33.45 | P15: =-27.245-O15 -> 6.205 | Q15: =-3.106-P15-O15 -> 24.139 | R15: =E15-Q15-P15-O15 -> 27.79 | S15: -1.882 | T15: =0.365-S15 -> 2.247 | U15: =-0.296-T15-S15 -> -0.661 | V15: =F15-U15-T15-S15 -> -27.897 | W15: -28.54 | X15: -6.721 | Y15: 0.96 | Z15: =G15-Y15-X15-W15 -> 9.824 | AA15: -0.176 | AB15: 5.595 | AC15: -6.29 | AD15: =H15-AC15-AB15-AA15 -> -10.974 | AE15: -10.165 | AF15: -12.567 | AG15: -4.115 | AH15: =I15-AG15-AF15-AE15 -> 0.544 | AI15: -9.956 | AJ15: -3.288 | AK15: -1.901 | AL15: =J15-AK15-AJ15-AI15 -> -19.028 | AM15: -21.716 | AN15: -18.475 | AO15: -16.354 | AP15: =K15-AO15-AN15-AM15 -> -46.913 | AQ15: 0.241 | AR15: -15.667 | AS15: -2.077 | AT15: =L15-AS15-AR15-AQ15 -> -2.711 | AU15: -8.192 | AW15: -1.882 | AX15: 2.247
B16: Operating Profit | C16: =C10+SUM(C12:C15) -> 2517.779 | D16: =D10+SUM(D12:D15) -> 2583.35 | E16: =E10+SUM(E12:E15) -> 2521.235 | F16: =F10+SUM(F12:F15) -> 2473.208 | G16: =G10+SUM(G12:G15) -> 2522.334 | H16: =H10+SUM(H12:H15) -> 2014.854 | I16: =I10+SUM(I12:I15) -> 2276.332 | J16: =J10+SUM(J12:J15) -> 2693.888 | ... M16: =M10+SUM(M12:M15) -> 3061.255 | O16: =O10+SUM(O12:O15) -> 485.21 | P16: =P10+SUM(P12:P15) -> 764.14 | Q16: =Q10+SUM(Q12:Q15) -> 774.03 | R16: =R10+SUM(R12:R15) -> 497.855 | S16: =S10+SUM(S12:S15) -> 480.817 | T16: =T10+SUM(T12:T15) -> 738.547 | U16: =U10+SUM(U12:U15) -> 755.579 | V16: =V10+SUM(V12:V15) -> 498.265 | ... AU16: =AU10+SUM(AU12:AU15) -> 875.129 | AW16: =AW10+SUM(AW12:AW15) -> 486.31 | AX16: =AX10+SUM(AX12:AX15) -> 742.508
B17: Exchange Gain, net | C17: 44.676 | D17: 7.094 | E17: 0 | F17: 0 | G17: 0 | H17: 0 | I17: 0 | J17: 0 | K17: 0 | L17: 0 | M17: =SUM(AR17:AU17) -> 0 | O17: -19.144 | P17: =7.024-O17 -> 26.168 | Q17: =-P17-O17 -> -7.024 | R17: =E17-Q17-P17-O17 -> 0 | S17: 9.355 | T17: =10.196-S17 -> 0.841 | U17: =-T17-S17 -> -10.196 | V17: =F17-U17-T17-S17 -> 0 | W17: 0 | X17: 0 | Y17: 0 | Z17: =G17-Y17-X17-W17 -> 0 | AA17: 0 | AB17: 0 | AC17: 0 | AD17: =H17-AC17-AB17-AA17 -> 0 | AE17: 0 | AF17: 0 | AG17: 0 | AH17: =I17-AG17-AF17-AE17 -> 0 | AI17: 0 | AJ17: 0 | AK17: 0 | AL17: =J17-AK17-AJ17-AI17 -> 0 | AM17: 0 | AN17: 0 | AO17: 0 | AP17: =K17-AO17-AN17-AM17 -> 0 | AQ17: 0 | AR17: 0 | AS17: 0 | AT17: =L17-AS17-AR17-AQ17 -> 0 | AU17: 0 | AW17: 0 | AX17: 0
B18: Financial Cost, net | C18: -351.336 | D18: -401.254 | E18: -436.766 | F18: -550.739 | G18: -495.881 | H18: -346.063 | I18: -428.119 | J18: -527.019 | K18: -530.26 | L18: -463.346 | M18: =SUM(AR18:AU18) -> -469.195 | O18: -102.271 | P18: =-197.209-O18 -> -94.938 | Q18: =-307.671-P18-O18 -> -110.462 | R18: =E18-Q18-P18-O18 -> -129.095 | S18: -130.281 | T18: =-266.425-S18 -> -136.144 | U18: =-396.887-T18-S18 -> -130.462 | V18: =F18-U18-T18-S18 -> -153.852 | W18: -124.875 | X18: -120.302 | Y18: -117.764 | Z18: =G18-Y18-X18-W18 -> -132.94 | AA18: -88.794 | AB18: -93.319 | AC18: -84.617 | AD18: =H18-AC18-AB18-AA18 -> -79.333 | AE18: -89.54 | AF18: -96.624 | AG18: -111.035 | AH18: =I18-AG18-AF18-AE18 -> -130.92 | AI18: -120.488 | AJ18: -136.379 | AK18: -128.527 | AL18: =J18-AK18-AJ18-AI18 -> -141.625 | AM18: -141.575 | AN18: -142.658 | AO18: -128.326 | AP18: =K18-AO18-AN18-AM18 -> -117.701 | AQ18: -99.691 | AR18: -124.962 | AS18: -118.633 | AT18: =L18-AS18-AR18-AQ18 -> -120.06 | AU18: -105.54 | AW18: -126.419 | AX18: -139.264
B19: Share of Results of Associates | C19: 13.323 | D19: 13.018 | E19: -5.413 | F19: 0 | G19: 1.405 | H19: -0.941 | I19: 0.716 | J19: -1.064 | K19: -1.774 | L19: -1.222 | M19: =SUM(AR19:AU19) -> -0.323 | O19: -3.43 | P19: =-7.456-O19 -> -4.026 | Q19: =-6.338-P19-O19 -> 1.118 | R19: =E19-Q19-P19-O19 -> 0.925 | S19: 0 | T19: =-S19 -> 0 | U19: =-T19-S19 -> 0 | V19: =F19-U19-T19-S19 -> 0 | W19: -1.598 | X19: 2.234 | Y19: 0.907 | Z19: =G19-Y19-X19-W19 -> -0.138 | AA19: -1.304 | AB19: -0.181 | AC19: -0.543 | AD19: =H19-AC19-AB19-AA19 -> 1.087 | AE19: -1.028 | AF19: 0.65 | AG19: 0.189 | AH19: =I19-AG19-AF19-AE19 -> 0.905 | AI19: -1.031 | AJ19: 0.097 | AK19: 1.358 | AL19: =J19-AK19-AJ19-AI19 -> -1.488 | AM19: -0.948 | AN19: -0.112 | AO19: -0.238 | AP19: =K19-AO19-AN19-AM19 -> -0.476 | AQ19: -0.899 | AR19: -0.323 | AS19: 0 | AT19: =L19-AS19-AR19-AQ19 -> 0 | AU19: 0 | AW19: 0 | AX19: 0
B20: Profit before Zakat and Income Tax | C20: =+C16+C18+C19+C17 -> 2224.442 | D20: =+D16+D18+D19+D17 -> 2202.208 | E20: =+E16+E18+E19+E17 -> 2079.056 | F20: =+F16+F18+F19+F17 -> 1922.469 | G20: =+G16+G18+G19+G17 -> 2027.858 | H20: =+H16+H18+H19+H17 -> 1667.85 | I20: =+I16+I18+I19+I17 -> 1848.929 | J20: =+J16+J18+J19+J17 -> 2165.805 | ... M20: =+M16+M18+M19+M17 -> 2591.737 | O20: =+O16+O18+O19+O17 -> 360.365 | P20: =+P16+P18+P19+P17 -> 691.344 | Q20: =+Q16+Q18+Q19+Q17 -> 657.662 | R20: =+R16+R18+R19+R17 -> 369.685 | S20: =+S16+S18+S19+S17 -> 359.891 | T20: =+T16+T18+T19+T17 -> 603.244 | U20: =+U16+U18+U19+U17 -> 614.921 | V20: =+V16+V18+V19+V17 -> 344.413 | ... AU20: =+AU16+AU18+AU19+AU17 -> 769.589 | AW20: =+AW16+AW18+AW19+AW17 -> 359.891 | AX20: =+AX16+AX18+AX19+AX17 -> 603.244
B21: Zakat and Income Tax | C21: -74.345 | D21: -42.245 | E21: =-49.352-21.146 -> -70.498 | F21: =-71.426-49.471 -> -120.897 | G21: =-72.042-20.26 -> -92.302 | H21: =-77.08-11.334 -> -88.414 | I21: =-62.6-8.191 -> -70.791 | J21: =-85.101-29.175 -> -114.276 | K21: =-105.326-44.334 -> -149.66 | L21: =-86.831-52.19 -> -139.021 | M21: =SUM(AR21:AU21) -> -134.153 | O21: -19.964 | P21: =-32.945-15.173-O21 -> -28.154 | Q21: =-49.312-15.223-P21-O21 -> -16.417 | R21: =E21-Q21-P21-O21 -> -5.963 | S21: -22.943 | T21: =-35.523-6.809-S21 -> -19.389 | U21: =-46.814-17.717-T21-S21 -> -22.199 | V21: =F21-U21-T21-S21 -> -56.366 | W21: =-12.985-5.913 -> -18.898 | X21: =-15.514-5.705 -> -21.219 | Y21: =-11.693-6.499 -> -18.192 | Z21: =G21-Y21-X21-W21 -> -33.993 | AA21: =-11.953-11.62 -> -23.573 | AB21: =-16.375-1.743 -> -18.118 | AC21: =-11.033-11.599 -> -22.632 | AD21: =H21-AC21-AB21-AA21 -> -24.091 | AE21: =-22.526-11.479 -> -34.005 | AF21: =-22.167-2.064 -> -24.231 | AG21: =12.636-5.8 -> 6.836 | AH21: =I21-AG21-AF21-AE21 -> -19.391 | AI21: =-26.975-18.093 -> -45.068 | AJ21: =-23.106-2.059 -> -25.165 | AK21: =-15.519-14.48 -> -29.999 | AL21: =J21-AK21-AJ21-AI21 -> -14.044 | AM21: =-24.869-8.093 -> -32.962 | AN21: =-22.949-6.125 -> -29.074 | AO21: =-22.909-22.115 -> -45.024 | AP21: =K21-AO21-AN21-AM21 -> -42.6 | AQ21: =-27.464-14.555 -> -42.019 | AR21: =-27.981-12.867 -> -40.848 | AS21: =(-20460-4664)/1000 -> -25.124 | AT21: =L21-AS21-AR21-AQ21 -> -31.03 | AU21: =-26.573-10.578 -> -37.151 | AW21: =-15.334-7.609 -> -22.943 | AX21: =-20.189+0.8 -> -19.389
B22: Profit for the year | C22: =C20+C21 -> 2150.097 | D22: =D20+D21 -> 2159.963 | E22: =E20+E21 -> 2008.558 | F22: =F20+F21 -> 1801.572 | G22: =G20+G21 -> 1935.556 | H22: =H20+H21 -> 1579.436 | I22: =I20+I21 -> 1778.138 | J22: =J20+J21 -> 2051.529 | ... M22: =M20+M21 -> 2457.584 | O22: =O20+O21 -> 340.401 | P22: =P20+P21 -> 663.19 | Q22: =Q20+Q21 -> 641.245 | R22: =R20+R21 -> 363.722 | S22: =S20+S21 -> 336.948 | T22: =T20+T21 -> 583.855 | U22: =U20+U21 -> 592.722 | V22: =V20+V21 -> 288.047 | ... AU22: =AU20+AU21 -> 732.438 | AW22: =AW20+AW21 -> 336.948 | AX22: =AX20+AX21 -> 583.855
B24: Profit (loss) attributable to non-controlling interests | C24: 2.311 | D24: -22.323 | E24: -3.417 | F24: -10.181 | G24: -48.805 | H24: 15.893 | I24: 18.326 | J24: 2.406 | K24: 0.567 | L24: 0.58 | M24: =SUM(AR24:AU24) -> 0.463 | O24: -4.466 | P24: =-2.663-O24 -> 1.803 | Q24: =3.627-P24-O24 -> 6.29 | R24: =E24-Q24-P24-O24 -> -7.044 | S24: 0.92 | T24: =2.244-S24 -> 1.324 | U24: 11.475 | V24: =F24-U24-T24-S24 -> -23.9 | W24: -15.611 | X24: -23.994 | Y24: -6.382 | Z24: =G24-Y24-X24-W24 -> -2.818 | AA24: 2.735 | AB24: 8.049 | AC24: 1.761 | AD24: =H24-AC24-AB24-AA24 -> 3.348 | AE24: 2.076 | AF24: 5.734 | AG24: 11.722 | AH24: =I24-AG24-AF24-AE24 -> -1.206 | AI24: 0.899 | AJ24: -0.016 | AK24: 0.504 | AL24: =J24-AK24-AJ24-AI24 -> 1.019 | AM24: 1.154 | AN24: 1.417 | AO24: -1.628 | AP24: =K24-AO24-AN24-AM24 -> -0.376 | AQ24: 0.333 | AR24: 0.244 | AS24: 0.277 | AT24: =L24-AS24-AR24-AQ24 -> -0.274 | AU24: 0.216 | AW24: 0.92 | AX24: 1.324
B25: Profit (loss) attributable to shareholders | C25: 2147.786 | D25: 2182.286 | E25: 2011.975 | F25: 1811.753 | G25: 1984.361 | H25: 1563.543 | I25: 1759.812 | J25: 2049.123 | K25: 2313.1 | L25: 2456.093 | M25: =SUM(AR25:AU25) -> 2457.121 | O25: 344.867 | P25: =1006.254-O25 -> 661.387 | Q25: =1641.209-P25-O25 -> 634.955 | R25: =E25-Q25-P25-O25 -> 370.766 | S25: 336.028 | T25: =918.559-S25 -> 582.531 | U25: 581.246 | V25: =F25-U25-T25-S25 -> 311.948 | W25: 383.005 | X25: 643.932 | Y25: 621.52 | Z25: =G25-Y25-X25-W25 -> 335.904 | AA25: 385.946 | AB25: 481.979 | AC25: 409.087 | AD25: =H25-AC25-AB25-AA25 -> 286.531 | AE25: 420.457 | AF25: 520.36 | AG25: 463.172 | AH25: =I25-AG25-AF25-AE25 -> 355.823 | AI25: 635.057 | AJ25: 557.084 | AK25: 486.263 | AL25: =J25-AK25-AJ25-AI25 -> 370.719 | AM25: 692.227 | AN25: 619.693 | AO25: 570.454 | AP25: =K25-AO25-AN25-AM25 -> 430.726 | AQ25: 731.194 | AR25: 646.866 | AS25: 613.239 | AT25: =L25-AS25-AR25-AQ25 -> 464.794 | AU25: 732.222 | AW25: 336.028 | AX25: 582.531
B27: check | C27: =C22-C24-C25 -> 0 | D27: =D22-D24-D25 -> 0 | E27: =E22-E24-E25 -> 0 | F27: =F22-F24-F25 -> 0 | G27: =G22-G24-G25 -> 0 | H27: =H22-H24-H25 -> 0 | I27: =I22-I24-I25 -> 2.0463631e-12 | J27: =J22-J24-J25 -> 0 | ... M27: =M22-M24-M25 -> 0 | O27: =O22-O24-O25 -> 0 | P27: =P22-P24-P25 -> 0 | Q27: =Q22-Q24-Q25 -> 0 | R27: =R22-R24-R25 -> -1.3073986e-12 | S27: =S22-S24-S25 -> 0 | T27: =T22-T24-T25 -> 0 | U27: =U22-U24-U25 -> 0.001 | V27: =V22-V24-V25 -> -0.001 | ... AU27: =AU22-AU24-AU25 -> 0 | AW27: =AW22-AW24-AW25 -> 0 | AX27: =AX22-AX24-AX25 -> 0
B29: As % of Net sales or stated otherwise
B30: =B9 -> Cost of Sales | C30: =-C9/C7 -> 0.61485116 | D30: =-D9/D7 -> 0.59932359 | E30: =-E9/E7 -> 0.60708526 | F30: =-F9/F7 -> 0.62604903 | G30: =-G9/G7 -> 0.63954374 | H30: =-H9/H7 -> 0.68079752 | I30: =-I9/I7 -> 0.69959697 | J30: =-J9/J7 -> 0.69087565 | ... M30: =-M9/M7 -> 0.68896976 | O30: =-O9/O7 -> 0.61189683 | P30: =-P9/P7 -> 0.61312932 | Q30: =-Q9/Q7 -> 0.57602129 | R30: =-R9/R7 -> 0.62647966 | S30: =-S9/S7 -> 0.63935925 | T30: =-T9/T7 -> 0.61833834 | U30: =-U9/U7 -> 0.59595266 | V30: =-V9/V7 -> 0.65077466 | ... AU30: =-AU9/AU7 -> 0.6970953 | AW30: =-AW9/AW7 -> 0.64824902 | AX30: =-AX9/AX7 -> 0.61081604
B31: =B12 -> Selling and Distribution Expenses | C31: =-C12/C7 -> 0.17298513 | D31: =-D12/D7 -> 0.16813466 | E31: =-E12/E7 -> 0.16081061 | F31: =-F12/F7 -> 0.16558303 | G31: =-G12/G7 -> 0.16217278 | H31: =-H12/H7 -> 0.15892085 | I31: =-I12/I7 -> 0.14472282 | J31: =-J12/J7 -> 0.14251145 | ... M31: =-M12/M7 -> 0.14673536 | O31: =-O12/O7 -> 0.1841455 | P31: =-P12/P7 -> 0.1412982 | Q31: =-Q12/Q7 -> 0.16264288 | R31: =-R12/R7 -> 0.15763768 | S31: =-S12/S7 -> 0.18178709 | T31: =-T12/T7 -> 0.14475488 | U31: =-U12/U7 -> 0.16626372 | V31: =-V12/V7 -> 0.17117133 | ... AU31: =-AU12/AU7 -> 0.1328547 | AW31: =-AW12/AW7 -> 0.1706124 | AX31: =-AX12/AX7 -> 0.15552085
B32: =B13 -> General and Administration Expenses | C32: =-C13/C7 -> 0.030194694 | D32: =-D13/D7 -> 0.028512654 | E32: =-E13/E7 -> 0.027674326 | F32: =-F13/F7 -> 0.027891107 | G32: =-G13/G7 -> 0.02733551 | H32: =-H13/H7 -> 0.027013537 | I32: =-I13/I7 -> 0.024499929 | J32: =-J13/J7 -> 0.02395959 | ... M32: =-M13/M7 -> 0.025387883 | O32: =-O13/O7 -> 0.029740378 | P32: =-P13/P7 -> 0.027287179 | Q32: =-Q13/Q7 -> 0.023882244 | R32: =-R13/R7 -> 0.029835111 | S32: =-S13/S7 -> 0.028250344 | T32: =-T13/T7 -> 0.026834953 | U32: =-U13/U7 -> 0.022252807 | V32: =-V13/V7 -> 0.034065905 | ... AU32: =-AU13/AU7 -> 0.022400294 | AW32: =-AW13/AW7 -> 0.028636172 | AX32: =-AX13/AX7 -> 0.02649715
B33: =B14 -> Other Expenses, net | C33: =-C14/C$7 -> 0.0063742718 | D33: =-D14/D$7 -> 0.015146246 | E33: =-E14/E$7 -> 0.020289003 | F33: =-F14/F$7 -> 0.0061786836 | G33: =-G14/G$7 -> 0.0051070043 | H33: =-H14/H$7 -> 0.0053983919 | I33: =-I14/I$7 -> 0.008191106 | J33: =-J14/J$7 -> 0.0032929284 | ... M33: =-M14/M$7 -> 0.0013202072 | O33: =-O14/O$7 -> 0.013750984 | P33: =-P14/P$7 -> 0.0093201488 | Q33: =-Q14/Q$7 -> 0.011403043 | R33: =-R14/R$7 -> 0.047023764 | S33: =-S14/S$7 -> 0.0066894588 | T33: =-T14/T$7 -> 0.01214167 | U33: =-U14/U$7 -> 0.0038919675 | V33: =-V14/V$7 -> 0.0019333477 | ... AU33: =-AU14/AU$7 -> 0.0042546712 | AW33: =-AW14/AW$7 -> 0.0049629906 | AX33: =-AX14/AX$7 -> 0.010675995
B34: =B15 -> Impairment (Loss) / Reversal on Financial Assets | C34: =-C15/C$7 -> 0 | D34: =-D15/D$7 -> 0.0035042078 | E34: =-E15/E$7 -> -0.0018206444 | F34: =-F15/F$7 -> 0.0019644942 | G34: =-G15/G$7 -> 0.0015938714 | H34: =-H15/H$7 -> 0.00074733181 | I34: =-I15/I$7 -> 0.0014049053 | J34: =-J15/J$7 -> 0.001745695 | ... M34: =-M15/M$7 -> 0.0012755902 | O34: =-O15/O$7 -> 0.010348972 | P34: =-P15/P$7 -> -0.0017107388 | Q34: =-Q15/Q$7 -> -0.0072765693 | R34: =-R15/R$7 -> -0.0082190144 | S34: =-S15/S$7 -> 0.00056110716 | T34: =-T15/T$7 -> -0.00060403242 | U34: =-U15/U$7 -> 0.00018498529 | V34: =-V15/V$7 -> 0.0075317135 | ... AU34: =-AU15/AU$7 -> 0.0013298587 | AW34: =-AW15/AW$7 -> 0.00056877045 | AX34: =-AX15/AX$7 -> -0.00059642875
B35: =B16 -> Operating Profit | C35: =C16/C7 -> 0.17559474 | D35: =D16/D7 -> 0.18537864 | E35: =E16/E7 -> 0.18596145 | F35: =F16/F7 -> 0.17233365 | G35: =G16/G7 -> 0.16424709 | H35: =H16/H7 -> 0.12712237 | I35: =I16/I7 -> 0.12158427 | J35: =J16/J7 -> 0.13761469 | ... M35: =M16/M7 -> 0.1363112 | O35: =O16/O7 -> 0.15011733 | P35: =P16/P7 -> 0.21067589 | Q35: =Q16/Q7 -> 0.2333271 | R35: =R16/R7 -> 0.1472428 | S35: =S16/S7 -> 0.14335274 | T35: =T16/T7 -> 0.19853419 | U35: =U16/U7 -> 0.21145386 | V35: =V16/V7 -> 0.13452304 | ... AU35: =AU16/AU7 -> 0.14206517 | AW35: =AW16/AW7 -> 0.14697065 | AX35: =AX16/AX7 -> 0.19708639
B36: Finance costs as a % of debt at end of period | D36: =-D18/D105 -> 0.031342795 | E36: =-E18/E105 -> 0.030278233 | F36: =-F18/F105 -> 0.040692253 | G36: =-G18/G105 -> 0.042462949 | H36: =-H18/H105 -> 0.033850165 | I36: =-I18/I105 -> 0.042522775 | J36: =-J18/J105 -> 0.042232359 | K36: =-K18/K105 -> 0.049706645 | ... M36: =-M18/M105 -> 0.033186118 | R36: =-(R18+Q18+P18+O18)/R105 -> 0.031364288 | S36: =-(S18+R18+Q18+P18)/S105 -> 0.034148637 | T36: =-(T18+S18+R18+Q18)/T105 -> 0.036254977 | U36: =-(U18+T18+S18+R18)/U105 -> 0.03699678 | V36: =-(V18+U18+T18+S18)/V105 -> 0.040692253 | W36: =-(W18+V18+U18+T18)/W105 -> 0.041609419 | X36: =-(X18+W18+V18+U18)/X105 -> 0.040137557 | Y36: =-(Y18+X18+W18+V18)/Y105 -> 0.039972035 | ... AU36: =-(AU18+AT18+AS18+AR18)/AU105 -> 0.033186118 | AW36: =-(AW18+R18+Q18+P18)/S105 -> 0.033864883 | AX36: =-(AX18+S18+R18+Q18)/T105 -> 0.036478533
B37: =B20 -> Profit before Zakat and Income Tax | C37: =C20/C7 -> 0.15513685 | D37: =D20/D7 -> 0.15802827 | E37: =E20/E7 -> 0.15334717 | F37: =F20/F7 -> 0.13395804 | G37: =G20/G7 -> 0.13204824 | H37: =H20/H7 -> 0.10522899 | I37: =I20/I7 -> 0.098755663 | J37: =J20/J7 -> 0.11063807 | ... M37: =M20/M7 -> 0.11540456 | O37: =O20/O7 -> 0.111492 | P37: =P20/P7 -> 0.1906058 | Q37: =Q20/Q7 -> 0.19824861 | R37: =R20/R7 -> 0.10933596 | S37: =S20/S7 -> 0.10729937 | T37: =T20/T7 -> 0.16216241 | U37: =U20/U7 -> 0.17208978 | V37: =V20/V7 -> 0.092985628 | ... AU37: =AU20/AU7 -> 0.1249322 | AW37: =AW20/AW7 -> 0.10876481 | AX37: =AX20/AX7 -> 0.16012108
B38: Income tax benefit/(expense) as a % of Profit before tax | C38: =-C21/C20 -> 0.033421865 | D38: =-D21/D20 -> 0.01918302 | E38: =-E21/E20 -> 0.033908659 | F38: =-F21/F20 -> 0.06288632 | G38: =-G21/G20 -> 0.045516994 | H38: =-H21/H20 -> 0.053010762 | I38: =-I21/I20 -> 0.038287571 | J38: =-J21/J20 -> 0.052763753 | ... M38: =-M21/M20 -> 0.051761811 | O38: =-O21/O20 -> 0.055399387 | P38: =-P21/P20 -> 0.040723576 | Q38: =-Q21/Q20 -> 0.024962671 | R38: =-R21/R20 -> 0.016129948 | S38: =-S21/S20 -> 0.063749858 | T38: =-T21/T20 -> 0.032141223 | U38: =-U21/U20 -> 0.036100572 | V38: =-V21/V20 -> 0.16365817 | ... AU38: =-AU21/AU20 -> 0.048273819 | AW38: =-AW21/AW20 -> 0.063749858 | AX38: =-AX21/AX20 -> 0.032141223
B40: capex/sales | C40: =-C61/C7 -> 0.34117356 | D40: =-D61/D7 -> 0.23204346 | E40: =-E61/E7 -> 0.17847692 | F40: =-F61/F7 -> 0.13918288 | G40: =-G61/G7 -> 0.08094805 | H40: =-H61/H7 -> 0.10214319 | I40: =-I61/I7 -> 0.10247316 | J40: =-J61/J7 -> 0.16852901 | ... M40: =-M61/M7 -> 0.21541017 | O40: =-O61/O7 -> 0.1724903 | P40: =-P61/P7 -> 0.15154223 | Q40: =-Q61/Q7 -> 0.18920798 | R40: =-R61/R7 -> 0.20256484 | S40: =-S61/S7 -> 0.1716973 | T40: =-T61/T7 -> 0.11017503 | U40: =-U61/U7 -> 0.1395805 | V40: =-V61/V7 -> 0.13848963 | ... AU40: =-AU61/AU7 -> 0.17425743 | AW40: =-AW61/AW7 -> 0.17404225 | AX40: =-AX61/AX7 -> 0.10878813
B41: D/A/sales | C41: =C45/C7 -> 0.12671137 | D41: =D45/D7 -> 0.13774967 | E41: =E45/E7 -> 0.15785165 | F41: =F45/F7 -> 0.15151788 | G41: =G45/G7 -> 0.13770783 | H41: =H45/H7 -> 0.13489342 | I41: =I45/I7 -> 0.12742485 | J41: =J45/J7 -> 0.12435439 | ... M41: =M45/M7 -> 0.11141513 | O41: =O45/O7 -> 0.16142479 | P41: =P45/P7 -> 0.15086813 | Q41: =Q45/Q7 -> 0.16411062 | R41: =R45/R7 -> 0.15578655 | S41: =S45/S7 -> 0.15302126 | T41: =T45/T7 -> 0.13662423 | U41: =U45/U7 -> 0.14914964 | V41: =V45/V7 -> 0.1673994 | ... AU41: =AU45/AU7 -> 0.10052495 | AW41: =AW45/AW7 -> 0.15511114 | AX41: =AX45/AX7 -> 0.13490438
B43: EBITDA | C43: =+C3 -> 42735 | D43: =+D3 -> 43100 | E43: =+E3 -> 43465 | F43: =F3 -> 43830 | G43: =G3 -> 44196 | H43: =H3 -> 44561 | I43: =I3 -> 44926 | J43: =J3 -> 45291 | K43: =K3 -> 45657 | L43: =L3 -> 46022 | M43: =M3 -> 46111 | O43: =O3 -> 43189 | P43: =P3 -> 43281 | Q43: =Q3 -> 43373 | R43: =R3 -> 43464 | S43: =S3 -> 43554 | T43: =T3 -> 43646 | U43: =U3 -> 43738 | V43: =V3 -> 43829 | ... AU43: =AU3 -> 46111 | AW43: =AW3 -> 43554 | AX43: =AX3 -> 43646
B44: Operating profit | C44: =C16 -> 2517.779 | D44: =D16 -> 2583.35 | E44: =E16 -> 2521.235 | F44: =F16 -> 2473.208 | G44: =G16 -> 2522.334 | H44: =H16 -> 2014.854 | I44: =I16 -> 2276.332 | J44: =J16 -> 2693.888 | ... M44: =M16 -> 3061.255 | O44: =O16 -> 485.21 | P44: =P16 -> 764.14 | Q44: =Q16 -> 774.03 | R44: =R16 -> 497.855 | S44: =S16 -> 480.817 | T44: =T16 -> 738.547 | U44: =U16 -> 755.579 | V44: =V16 -> 498.265 | ... AU44: =AU16 -> 875.129 | AW44: =AW16 -> 486.31 | AX44: =AX16 -> 742.508
B45: Depreciation & amortisation | C45: =1442.341+32.479+342.041 -> 1816.861 | D45: =1573.671+50.017+295.927 -> 1919.615 | E45: =1684.106+94.732+47.451+313.838 -> 2140.127 | F45: =1638.626+101.788+49.938+384.123 -> 2174.475 | G45: =1600.408+108.505+56.681+349.178 -> 2114.772 | H45: =1608.569+102.737+66.476+360.241 -> 2138.023 | I45: =1752.245+105.557+480.494+47.385 -> 2385.681 | J45: =1711.751+110.9+574.264+37.395 -> 2434.31 | K45: =1688.316+117.99+39.97+566.338 -> 2412.614 | L45: =1663.88+125.446+45.389+635.25 -> 2469.965 | M45: =SUM(AR45:AU45) -> 2502.143 | O45: =418.349+21.234+11.123+71.052 -> 521.758 | P45: =862.864+43.171+22.563+140.372-O45 -> 547.212 | Q45: =1286.854+66.946+34.678+224.906-P45-O45 -> 544.414 | R45: =E45-Q45-P45-O45 -> 526.743 | S45: =386.904+25.479+12.151+88.712 -> 513.246 | T45: =785.343+48.446+23.87+163.829-S45 -> 508.242 | U45: =1196.136+72.622+36.182+249.498-T45-S45 -> 532.95 | V45: =F45-U45-T45-S45 -> 620.037 | W45: =401.165+25.981+12.711+77.09 -> 516.947 | X45: =806.035+51.168+25.91+157.743-W45 -> 523.909 | Y45: =1196.136+72.622+36.182+249.498-X45-W45 -> 513.582 | Z45: =G45-Y45-X45-W45 -> 560.334 | AA45: =414.202+26.253+16.955+85.262 -> 542.672 | AB45: =808.738+51.799+35.38+155.797-AA45 -> 509.042 | AC45: =1209.29+76.739+51.327+241.321-AB45-AA45 -> 526.963 | AD45: =H45-AC45-AB45-AA45 -> 559.346 | AE45: =400.25+23.052+16.104+114.786 -> 554.192 | AF45: =801.961+50.397+21.803+211.568-AE45 -> 531.537 | AG45: =1207.267+75.034+32.268+319.268-AF45-AE45 -> 548.108 | AH45: =I45-AG45-AF45-AE45 -> 751.844 | AI45: 609.129 | AJ45: =1176.2-AI45 -> 567.071 | AK45: =1207.267+75.034+32.268+319.268-AJ45-AI45 -> 457.637 | AL45: =J45-AK45-AJ45-AI45 -> 800.473 | AM45: 543.063 | AN45: =1133.871-AM45 -> 590.808 | AO45: =1731.543-AN45-AM45 -> 597.672 | AP45: =K45-AO45-AN45-AM45 -> 681.071 | AQ45: 587.061 | AR45: 614.6 | AS45: =1801.121-AR45-AQ45 -> 599.46 | AT45: =L45-AS45-AR45-AQ45 -> 668.844 | AU45: 619.239 | AW45: =386.904+25.479+12.151+88.712 -> 513.246 | AX45: =785.343+48.446+23.87+163.829-AW45 -> 508.242
B46: EBITDA | C46: =SUM(C44:C45) -> 4334.64 | D46: =SUM(D44:D45) -> 4502.965 | E46: =SUM(E44:E45) -> 4661.362 | F46: =SUM(F44:F45) -> 4647.683 | G46: =SUM(G44:G45) -> 4637.106 | H46: =SUM(H44:H45) -> 4152.877 | I46: =SUM(I44:I45) -> 4662.013 | J46: =SUM(J44:J45) -> 5128.198 | ... M46: =SUM(M44:M45) -> 5563.398 | O46: =SUM(O44:O45) -> 1006.968 | P46: =SUM(P44:P45) -> 1311.352 | Q46: =SUM(Q44:Q45) -> 1318.444 | R46: =SUM(R44:R45) -> 1024.598 | S46: =SUM(S44:S45) -> 994.063 | T46: =SUM(T44:T45) -> 1246.789 | U46: =SUM(U44:U45) -> 1288.529 | V46: =SUM(V44:V45) -> 1118.302 | ... AU46: =SUM(AU44:AU45) -> 1494.368 | AW46: =SUM(AW44:AW45) -> 999.556 | AX46: =SUM(AX44:AX45) -> 1250.75
...

Sheet KPIs
B2: ALMARAI | C2: Annual | D2: Annual | E2: Annual | F2: Annual | G2: Annual | H2: Annual | I2: Annual | J2: Annual | K2: Annual | L2: Annual | M2: LTM | O2: Quarterly | P2: Quarterly | Q2: Quarterly | R2: Quarterly | S2: Quarterly | T2: Quarterly | U2: Quarterly | V2: Quarterly | W2: Quarterly | X2: Quarterly | Y2: Quarterly | Z2: Quarterly | AA2: Quarterly | AB2: Quarterly | AC2: Quarterly | AD2: Quarterly | AE2: Quarterly | AF2: Quarterly | AG2: Quarterly | AH2: QuarterIy | AI2: Quarterly | AJ2: Quarterly | AK2: Quarterly | AL2: QuarterIy | AM2: Quarterly | AN2: Quarterly | AO2: Quarterly | AP2: QuarterIy | AQ2: Quarterly | AR2: Quarterly | AS2: Quarterly | AT2: QuarterIy | AU2: Quarterly | AW2: Quarterly | AX2: Quarterly
B3: (SAR millions) | C3: 42735 | D3: 43100 | E3: 43465 | F3: 43830 | G3: 44196 | H3: 44561 | I3: 44926 | J3: 45291 | K3: 45657 | L3: 46022 | M3: =AU3 -> 46111 | O3: 43189 | P3: 43281 | Q3: 43373 | R3: 43464 | S3: 43554 | T3: 43646 | U3: 43738 | V3: 43829 | W3: 43920 | X3: 44012 | Y3: 44104 | Z3: 44195 | AA3: 44285 | AB3: 44377 | AC3: 44469 | AD3: 44560 | AE3: 44650 | AF3: 44742 | AG3: 44834 | AH3: 44926 | AI3: 45015 | AJ3: 45107 | AK3: 45199 | AL3: 45291 | AM3: 45381 | AN3: 45473 | AO3: 45565 | AP3: 45657 | AQ3: 45746 | AR3: 45838 | AS3: 45930 | AT3: 46022 | AU3: 46111 | AW3: 43554 | AX3: 43646
C4: Act | D4: Act | E4: Act | F4: Act | G4: Act | H4: Act | I4: Act | J4: Act | K4: Act | L4: Act | M4: Act | O4: Act | P4: Act | Q4: Act | R4: Act | S4: Act | T4: Act | U4: Act | V4: Act | W4: Act | X4: Act | Y4: Act | Z4: Act | AA4: Act | AB4: Act | AC4: Act | AD4: Act | AE4: Act | AF4: Act | AG4: Act | AH4: Act | AI4: Act | AJ4: Act | AK4: Act | AL4: Act | AM4: Act | AN4: Act | AO4: Act | AP4: Act | AQ4: Act | AR4: Act | AS4: Act | AT4: Act | AU4: Act | AW4: Restated | AX4: Act
C5: FY | D5: FY | E5: FY | F5: FY | G5: FY | H5: FY | I5: FY | J5: FY | K5: FY | L5: FY | M5: LTM | O5: Q1 | P5: Q2 | Q5: Q3 | R5: Q4 | S5: Q1 | T5: Q2 | U5: Q3 | V5: Q4 | W5: Q1 | X5: Q2 | Y5: Q3 | Z5: Q4 | AA5: Q1 | AB5: Q2 | AC5: Q3 | AD5: Q4 | AE5: Q1 | AF5: Q2 | AG5: Q3 | AH5: Q4 | AI5: Q1 | AJ5: Q2 | AK5: Q3 | AL5: Q4 | AM5: Q1 | AN5: Q2 | AO5: Q3 | AP5: Q4 | AQ5: Q1 | AR5: Q2 | AS5: Q3 | AT5: Q4 | AU5: Q1 | AW5: Q1 | AX5: Q2
B7: Revenue by Business Segments
B8: Dairy and Juice | C8: 10961.324 | D8: 10510.471 | E8: 9919.665 | F8: 10209.987 | G8: 10923.68 | H8: 11141.325 | I8: 12504.123 | J8: 12902.558 | K8: 14007.348 | L8: 14632.844 | M8: =SUM(AR8:AU8) -> 14793.022 | O8: 2356.948 | P8: =5109.44-O8 -> 2752.492 | Q8: =7514.694-P8-O8 -> 2405.254 | R8: =E8-Q8-P8-O8 -> 2404.971 | S8: 2366.404 | T8: =5116.547-S8 -> 2750.143 | U8: =7669.403-T8-S8 -> 2552.856 | V8: =F8-U8-T8-S8 -> 2540.584 | W8: 2520.118 | X8: =5486.358-W8 -> 2966.24 | Y8: =8256.707-X8-W8 -> 2770.349 | Z8: =G8-Y8-X8-W8 -> 2666.973 | AA8: 2581.482 | AB8: =5477.111-AA8 -> 2895.629 | AC8: =8197.756-AB8-AA8 -> 2720.645 | AD8: =H8-AC8-AB8-AA8 -> 2943.569 | AE8: 3116.247 | AF8: =6252.251-AE8 -> 3136.004 | AG8: =9390.973-AF8-AE8 -> 3138.722 | AH8: =I8-AG8-AF8-AE8 -> 3113.15 | AI8: 3448.786 | AJ8: =6627.534-AI8 -> 3178.748 | AK8: =9772.245-AJ8-AI8 -> 3144.711 | AL8: =J8-AK8-AJ8-AI8 -> 3130.313 | AM8: 3792.198 | AN8: =7211.721-AM8 -> 3419.523 | AO8: =10696.12-AN8-AM8 -> 3484.399 | AP8: =K8-AO8-AN8-AM8 -> 3311.228 | AQ8: 4018.412 | AR8: =7533.771-AQ8 -> 3515.359 | AS8: =11189.163-AR8-AQ8 -> 3655.392 | AT8: =L8-AS8-AR8-AQ8 -> 3443.681 | AU8: 4178.59 | AW8: 2333.971 | AX8: 2783
B9: Bakery | C9: 1880.789 | D9: 1807.09 | E9: 1641.393 | F9: 1749.297 | G9: 1711.952 | H9: 1788.862 | I9: 2439.3 | J9: 2584.458 | K9: 2661.579 | L9: 2789.339 | M9: =SUM(AR9:AU9) -> 2818.396 | O9: 405.466 | P9: =782.901-O9 -> 377.435 | Q9: =1194.499-P9-O9 -> 411.598 | R9: =E9-Q9-P9-O9 -> 446.894 | S9: 430.019 | T9: =815.67-S9 -> 385.651 | U9: =1270.167-T9-S9 -> 454.497 | V9: =F9-U9-T9-S9 -> 479.13 | W9: 432.81 | X9: =857.026-W9 -> 424.216 | Y9: =1276.232-X9-W9 -> 419.206 | Z9: =G9-Y9-X9-W9 -> 435.72 | AA9: 391.085 | AB9: =792.002-AA9 -> 400.917 | AC9: =1259.39-AB9-AA9 -> 467.388 | AD9: =H9-AC9-AB9-AA9 -> 529.472 | AE9: 571.275 | AF9: =1138.796-AE9 -> 567.521 | AG9: =1754.7-AF9-AE9 -> 615.904 | AH9: =I9-AG9-AF9-AE9 -> 684.6 | AI9: 622.058 | AJ9: =1243.047-AI9 -> 620.989 | AK9: =1883.825-AJ9-AI9 -> 640.778 | AL9: =J9-AK9-AJ9-AI9 -> 700.633 | AM9: 624.382 | AN9: =1270.256-AM9 -> 645.874 | AO9: =1932.139-AN9-AM9 -> 661.883 | AP9: =K9-AO9-AN9-AM9 -> 729.44 | AQ9: 632.628 | AR9: =1327.445-AQ9 -> 694.817 | AS9: =2029.927-AR9-AQ9 -> 702.482 | AT9: =L9-AS9-AR9-AQ9 -> 759.412 | AU9: 661.685 | AW9: 421.073 | AX9: 395
B10: Poultry | C10: 1331.506 | D10: 1463.626 | E10: 1800.35 | F10: 2124.593 | G10: 2292.779 | H10: 2301.459 | I10: 3013.435 | J10: 3518.336 | K10: 3794.209 | L10: 3927.229 | M10: =SUM(AR10:AU10) -> 4048.118 | O10: 420.639 | P10: =855.297-O10 -> 434.658 | Q10: =1308.663-P10-O10 -> 453.366 | R10: =E10-Q10-P10-O10 -> 491.687 | S10: 502.267 | T10: =1026.643-S10 -> 524.376 | U10: =1515.605-T10-S10 -> 488.962 | V10: =F10-U10-T10-S10 -> 608.988 | W10: 558.388 | X10: =1173.006-W10 -> 614.618 | Y10: =1697.756-X10-W10 -> 524.75 | Z10: =G10-Y10-X10-W10 -> 595.023 | AA10: 551.842 | AB10: =1118.023-AA10 -> 566.181 | AC10: =1659.646-AB10-AA10 -> 541.623 | AD10: =H10-AC10-AB10-AA10 -> 641.813 | AE10: 659.468 | AF10: =1395.813-AE10 -> 736.345 | AG10: =2171.597-AE10-AF10 -> 775.784 | AH10: =I10-AG10-AF10-AE10 -> 841.838 | AI10: 848.032 | AJ10: =1697.441-AI10 -> 849.409 | AK10: =2573.457-AI10-AJ10 -> 876.016 | AL10: =J10-AK10-AJ10-AI10 -> 944.879 | AM10: 921.283 | AN10: =1890.687-AM10 -> 969.404 | AO10: =2819.222-AM10-AN10 -> 928.535 | AP10: =K10-AO10-AN10-AM10 -> 974.987 | AQ10: 979.975 | AR10: =1949.988-AQ10 -> 970.013 | AS10: =2905.302-AQ10-AR10 -> 955.314 | AT10: =L10-AS10-AR10-AQ10 -> 1021.927 | AU10: 1100.864 | AW10: 499.501 | AX10: 527
B11: Other Activities | C11: 164.96 | D11: 154.345 | E11: 196.429 | F11: 267.4 | G11: 428.537 | H11: 618.074 | I11: 765.4 | J11: 570.233 | K11: 516.376 | L11: 715.464 | M11: =SUM(AR11:AU11) -> 798.303 | O11: 49.152 | P11: =111.655-O11 -> 62.503 | Q11: =158.797-P11-O11 -> 47.142 | R11: =E11-Q11-P11-O11 -> 37.632 | S11: 55.393 | T11: =115.222-S11 -> 59.829 | U11: =192.164-T11-S11 -> 76.942 | V11: =F11-U11-T11-S11 -> 75.236 | W11: 81.124 | X11: =157.894-W11 -> 76.77 | Y11: =306.668-X11-W11 -> 148.774 | Z11: =G11-Y11-X11-W11 -> 121.869 | AA11: 120.605 | AB11: =263.446-AA11 -> 142.841 | AC11: =475.52-AB11-AA11 -> 212.074 | AD11: =H11-AC11-AB11-AA11 -> 142.554 | AE11: 156.467 | AF11: =327.044-AE11 -> 170.577 | AG11: =565.755-AE11-AF11 -> 238.711 | AH11: =I11-AG11-AF11-AE11 -> 199.645 | AI11: 147.688 | AJ11: =290.891-AI11 -> 143.203 | AK11: =426.32-AI11-AJ11 -> 135.429 | AL11: =J11-AK11-AJ11-AI11 -> 143.913 | AM11: 120.778 | AN11: =240.598-AM11 -> 119.82 | AO11: =374.702-AM11-AN11 -> 134.104 | AP11: =K11-AO11-AN11-AM11 -> 141.674 | AQ11: 136.075 | AR11: =244.288-AQ11 -> 108.213 | AS11: =483.699-AQ11-AR11 -> 239.411 | AT11: =L11-AS11-AR11-AQ11 -> 231.765 | AU11: 218.914 | AW11: 54.347 | AX11: 61
B12: Total | C12: =SUM(C8:C11) -> 14338.579 | D12: =SUM(D8:D11) -> 13935.532 | E12: =SUM(E8:E11) -> 13557.837 | F12: =SUM(F8:F11) -> 14351.277 | G12: =SUM(G8:G11) -> 15356.948 | H12: =SUM(H8:H11) -> 15849.72 | I12: =SUM(I8:I11) -> 18722.258 | J12: =SUM(J8:J11) -> 19575.585 | ... M12: =SUM(M8:M11) -> 22457.839 | O12: =SUM(O8:O11) -> 3232.205 | P12: =SUM(P8:P11) -> 3627.088 | Q12: =SUM(Q8:Q11) -> 3317.36 | R12: =SUM(R8:R11) -> 3381.184 | S12: =SUM(S8:S11) -> 3354.083 | T12: =SUM(T8:T11) -> 3719.999 | U12: =SUM(U8:U11) -> 3573.257 | V12: =SUM(V8:V11) -> 3703.938 | ... AU12: =SUM(AU8:AU11) -> 6160.053 | AW12: =SUM(AW8:AW11) -> 3308.892 | AX12: =SUM(AX8:AX11) -> 3766
B13: check | C13: =C12-Model!C7 -> 0 | D13: =D12-Model!D7 -> 0 | E13: =E12-Model!E7 -> 0 | F13: =F12-Model!F7 -> 0 | G13: =G12-Model!G7 -> 0 | H13: =H12-Model!H7 -> 0 | I13: =I12-Model!I7 -> 0 | J13: =J12-Model!J7 -> 0 | ... M13: =M12-Model!M7 -> 0 | O13: =O12-Model!O7 -> 0 | P13: =P12-Model!P7 -> 0 | Q13: =Q12-Model!Q7 -> 0 | R13: =R12-Model!R7 -> 0 | S13: =S12-Model!S7 -> 0 | T13: =T12-Model!T7 -> 0 | U13: =U12-Model!U7 -> 0 | V13: =V12-Model!V7 -> 0 | ... AU13: =AU12-Model!AU7 -> 0 | AW13: =AW12-Model!AW7 -> 0 | AX13: =AX12-Model!AX7 -> -1.424
B15: Revenue Composition (%)
B16: Dairy and Juice | C16: =C8/C$12 -> 0.76446376 | D16: =D8/D$12 -> 0.75422101 | E16: =E8/E$12 -> 0.73165543 | F16: =F8/F$12 -> 0.71143404 | G16: =G8/G$12 -> 0.71131842 | H16: =H8/H$12 -> 0.70293513 | I16: =I8/I$12 -> 0.66787473 | J16: =J8/J$12 -> 0.65911481 | ... M16: =M8/M$12 -> 0.65870193 | O16: =O8/O$12 -> 0.72920746 | P16: =P8/P$12 -> 0.75887103 | Q16: =Q8/Q$12 -> 0.72505064 | R16: =R8/R$12 -> 0.71128072 | S16: =S8/S$12 -> 0.70552935 | T16: =T8/T$12 -> 0.73928595 | U16: =U8/U$12 -> 0.71443392 | V16: =V8/V$12 -> 0.68591429 | ... AU16: =AU8/AU$12 -> 0.6783367 | AW16: =AW8/AW$12 -> 0.70536331 | AX16: =AX8/AX$12 -> 0.73898035
B17: Bakery | C17: =C9/C$12 -> 0.13116983 | D17: =D9/D$12 -> 0.12967499 | E17: =E9/E$12 -> 0.12106599 | F17: =F9/F$12 -> 0.12189138 | G17: =G9/G$12 -> 0.11147736 | H17: =H9/H$12 -> 0.11286395 | I17: =I9/I$12 -> 0.13028877 | J17: =J9/J$12 -> 0.13202456 | ... M17: =M9/M$12 -> 0.1254972 | O17: =O9/O$12 -> 0.12544563 | P17: =P9/P$12 -> 0.10406006 | Q17: =Q9/Q$12 -> 0.12407396 | R17: =R9/R$12 -> 0.13217086 | S17: =S9/S$12 -> 0.12820762 | T17: =T9/T$12 -> 0.10366965 | U17: =U9/U$12 -> 0.12719404 | V17: =V9/V$12 -> 0.12935692 | ... AU17: =AU9/AU$12 -> 0.10741547 | AW17: =AW9/AW$12 -> 0.12725498 | AX17: =AX9/AX$12 -> 0.10488582
B18: Poultry | C18: =C10/C$12 -> 0.092861782 | D18: =D10/D$12 -> 0.10502835 | E18: =E10/E$12 -> 0.13279036 | F18: =F10/F$12 -> 0.14804209 | G18: =G10/G$12 -> 0.14929913 | H18: =H10/H$12 -> 0.14520503 | I18: =I10/I$12 -> 0.16095468 | J18: =J10/J$12 -> 0.17973082 | ... M18: =M10/M$12 -> 0.18025412 | O18: =O10/O$12 -> 0.13013995 | P18: =P10/P$12 -> 0.11983663 | Q18: =Q10/Q$12 -> 0.1366647 | R18: =R10/R$12 -> 0.14541859 | S18: =S10/S$12 -> 0.14974793 | T18: =T10/T$12 -> 0.14096133 | U18: =U10/U$12 -> 0.1368393 | V18: =V10/V$12 -> 0.16441636 | ... AU18: =AU10/AU$12 -> 0.17871015 | AW18: =AW10/AW$12 -> 0.15095718 | AX18: =AX10/AX$12 -> 0.13993627
B19: Other Activities | C19: =C11/C$12 -> 0.011504627 | D19: =D11/D$12 -> 0.011075645 | E19: =E11/E$12 -> 0.014488226 | F19: =F11/F$12 -> 0.018632488 | G19: =G11/G$12 -> 0.027905089 | H19: =H11/H$12 -> 0.038995894 | I19: =I11/I$12 -> 0.040881821 | J19: =J11/J$12 -> 0.029129806 | ... M19: =M11/M$12 -> 0.035546742 | O19: =O11/O$12 -> 0.015206956 | P19: =P11/P$12 -> 0.017232281 | Q19: =Q11/Q$12 -> 0.014210698 | R19: =R11/R$12 -> 0.011129829 | S19: =S11/S$12 -> 0.016515095 | T19: =T11/T$12 -> 0.016083069 | U19: =U11/U$12 -> 0.021532736 | V19: =V11/V$12 -> 0.020312435 | ... AU19: =AU11/AU$12 -> 0.035537681 | AW19: =AW11/AW$12 -> 0.016424531 | AX19: =AX11/AX$12 -> 0.016197557
B20: Total | C20: =SUM(C16:C19) -> 1 | D20: =SUM(D16:D19) -> 1 | E20: =SUM(E16:E19) -> 1 | F20: =SUM(F16:F19) -> 1 | G20: =SUM(G16:G19) -> 1 | H20: =SUM(H16:H19) -> 1 | I20: =SUM(I16:I19) -> 1 | J20: =SUM(J16:J19) -> 1 | ... M20: =SUM(M16:M19) -> 1 | O20: =SUM(O16:O19) -> 1 | P20: =SUM(P16:P19) -> 1 | Q20: =SUM(Q16:Q19) -> 1 | R20: =SUM(R16:R19) -> 1 | S20: =SUM(S16:S19) -> 1 | T20: =SUM(T16:T19) -> 1 | U20: =SUM(U16:U19) -> 1 | V20: =SUM(V16:V19) -> 1 | ... AU20: =SUM(AU16:AU19) -> 1 | AW20: =SUM(AW16:AW19) -> 1 | AX20: =SUM(AX16:AX19) -> 1
B22: y-o-y growth in Revenue
B23: Dairy and Juice | D23: =D8/C8-1 -> -0.041131254 | E23: =E8/D8-1 -> -0.056211182 | F23: =F8/E8-1 -> 0.029267319 | G23: =G8/F8-1 -> 0.06990146 | H23: =H8/G8-1 -> 0.019924146 | I23: =I8/H8-1 -> 0.1223192 | J23: =J8/I8-1 -> 0.03186429 | K23: =K8/J8-1 -> 0.085625657 | L23: =L8/K8-1 -> 0.044654848 | S23: =S8/O8-1 -> 0.004011968 | T23: =T8/P8-1 -> -0.00085340847 | U23: =U8/Q8-1 -> 0.061366492 | V23: =V8/R8-1 -> 0.056388622 | W23: =W8/S8-1 -> 0.064956787 | X23: =X8/T8-1 -> 0.078576641 | Y23: =Y8/U8-1 -> 0.085195953 | Z23: =Z8/V8-1 -> 0.049748011 | ... AD23: =AD8/Z8-1 -> 0.10371159 | AE23: =$AE8/$AA8-1 -> 0.20715426 | AF23: =AF8/AB8-1 -> 0.083013052 | AG23: =AG8/AC8-1 -> 0.15366834 | AH23: =AH8/AD8-1 -> 0.057610676 | AI23: =AI8/AE8-1 -> 0.10671137 | AJ23: =AJ8/AF8-1 -> 0.013630085 | AK23: =AK8/AG8-1 -> 0.0019081015 | AL23: =AL8/AH8-1 -> 0.0055130655 | AM23: =AM8/AI8-1 -> 0.099574749 | ... AU23: =AU8/AQ8-1 -> 0.03986102 | AW23: =AW8/O8-1 -> -0.0097486241 | AX23: =AX8/P8-1 -> 0.011083774
B24: Bakery | D24: =D9/C9-1 -> -0.03918515 | E24: =E9/D9-1 -> -0.091692721 | F24: =F9/E9-1 -> 0.065739284 | G24: =G9/F9-1 -> -0.021348576 | H24: =H9/G9-1 -> 0.044925325 | I24: =I9/H9-1 -> 0.36360435 | J24: =J9/I9-1 -> 0.059508056 | K24: =K9/J9-1 -> 0.029840299 | L24: =L9/K9-1 -> 0.048001581 | S24: =S9/O9-1 -> 0.060555016 | T24: =T9/P9-1 -> 0.021767987 | U24: =U9/Q9-1 -> 0.10422548 | V24: =V9/R9-1 -> 0.072133437 | W24: =W9/S9-1 -> 0.0064904109 | X24: =X9/T9-1 -> 0.099999741 | Y24: =Y9/U9-1 -> -0.077648477 | Z24: =Z9/V9-1 -> -0.090601716 | ... AD24: =AD9/Z9-1 -> 0.2151657 | AE24: =$AE9/$AA9-1 -> 0.46074383 | AF24: =AF9/AB9-1 -> 0.41555733 | AG24: =AG9/AC9-1 -> 0.31775741 | AH24: =AH9/AD9-1 -> 0.29298622 | AI24: =AI9/AE9-1 -> 0.08889414 | AJ24: =AJ9/AF9-1 -> 0.094213254 | AK24: =AK9/AG9-1 -> 0.040386164 | AL24: =AL9/AH9-1 -> 0.023419515 | AM24: =AM9/AI9-1 -> 0.003735986 | ... AU24: =AU9/AQ9-1 -> 0.045930626 | AW24: =AW9/O9-1 -> 0.038491513 | AX24: =AX9/P9-1 -> 0.046537814
B25: Poultry | D25: =D10/C10-1 -> 0.099225989 | E25: =E10/D10-1 -> 0.2300615 | F25: =F10/E10-1 -> 0.18009998 | G25: =G10/F10-1 -> 0.079161515 | H25: =H10/G10-1 -> 0.0037857988 | I25: =I10/H10-1 -> 0.30935854 | J25: =J10/I10-1 -> 0.16754999 | K25: =K10/J10-1 -> 0.078410078 | L25: =L10/K10-1 -> 0.035058691 | S25: =S10/O10-1 -> 0.19405714 | T25: =T10/P10-1 -> 0.20641056 | U25: =U10/Q10-1 -> 0.078514931 | V25: =V10/R10-1 -> 0.23856844 | W25: =W10/S10-1 -> 0.11173539 | X25: =X10/T10-1 -> 0.17209407 | Y25: =Y10/U10-1 -> 0.073191782 | Z25: =Z10/V10-1 -> -0.022931486 | ... AD25: =AD10/Z10-1 -> 0.078635616 | AE25: =$AE10/$AA10-1 -> 0.19503046 | AF25: =AF10/AB10-1 -> 0.300547 | AG25: =AG10/AC10-1 -> 0.43233208 | AH25: =AH10/AD10-1 -> 0.3116562 | AI25: =AI10/AE10-1 -> 0.28593351 | AJ25: =AJ10/AF10-1 -> 0.15354759 | AK25: =AK10/AG10-1 -> 0.12920091 | AL25: =AL10/AH10-1 -> 0.12240003 | AM25: =AM10/AI10-1 -> 0.086377637 | ... AU25: =AU10/AQ10-1 -> 0.12335927 | AW25: =AW10/O10-1 -> 0.18748143 | AX25: =AX10/P10-1 -> 0.21244749
B26: Other Activities | D26: =D11/C11-1 -> -0.064348933 | E26: =E11/D11-1 -> 0.27266189 | F26: =F11/E11-1 -> 0.36130612 | G26: =G11/F11-1 -> 0.60260658 | H26: =H11/G11-1 -> 0.44228853 | I26: =I11/H11-1 -> 0.23836304 | J26: =J11/I11-1 -> -0.25498693 | K26: =K11/J11-1 -> -0.094447357 | L26: =L11/K11-1 -> 0.38554852 | S26: =S11/O11-1 -> 0.12697347 | T26: =T11/P11-1 -> -0.042781946 | U26: =U11/Q11-1 -> 0.63213271 | V26: =V11/R11-1 -> 0.99925595 | W26: =W11/S11-1 -> 0.46451718 | X26: =X11/T11-1 -> 0.283157 | Y26: =Y11/U11-1 -> 0.93358634 | Z26: =Z11/V11-1 -> 0.61982296 | ... AD26: =AD11/Z11-1 -> 0.16973143 | AE26: =$AE11/$AA11-1 -> 0.29735086 | AF26: =AF11/AB11-1 -> 0.19417394 | AG26: =AG11/AC11-1 -> 0.12560238 | AH26: =AH11/AD11-1 -> 0.40048683 | AI26: =AI11/AE11-1 -> -0.056107678 | AJ26: =AJ11/AF11-1 -> -0.16047885 | AK26: =AK11/AG11-1 -> -0.43266544 | AL26: =AL11/AH11-1 -> -0.2791555 | AM26: =AM11/AI11-1 -> -0.18220844 | ... AU26: =AU11/AQ11-1 -> 0.60877457 | AW26: =AW11/O11-1 -> 0.10569255 | AX26: =AX11/P11-1 -> -0.024046846
B27: Total | D27: =D12/C12-1 -> -0.028109271 | E27: =E12/D12-1 -> -0.02710302 | F27: =F12/E12-1 -> 0.058522609 | G27: =G12/F12-1 -> 0.070075367 | H27: =H12/G12-1 -> 0.032087886 | I27: =I12/H12-1 -> 0.18123588 | J27: =J12/I12-1 -> 0.04557821 | K27: =K12/J12-1 -> 0.071718265 | L27: =L12/K12-1 -> 0.051734473 | S27: =S12/O12-1 -> 0.037707386 | T27: =T12/P12-1 -> 0.025615866 | U27: =U12/Q12-1 -> 0.077138749 | V27: =V12/R12-1 -> 0.095455911 | W27: =W12/S12-1 -> 0.071064729 | X27: =X12/T12-1 -> 0.097270187 | Y27: =Y12/U12-1 -> 0.081108636 | Z27: =Z12/V12-1 -> 0.031222715 | ... AD27: =AD12/Z12-1 -> 0.1146258 | AE27: =$AE12/$AA12-1 -> 0.23551158 | AF27: =AF12/AB12-1 -> 0.15100954 | AG27: =AG12/AC12-1 -> 0.20990555 | AH27: =AH12/AD12-1 -> 0.13666179 | AI27: =AI12/AE12-1 -> 0.12503883 | AJ27: =AJ12/AF12-1 -> 0.039454309 | AK27: =AK12/AG12-1 -> 0.0058318923 | AL27: =AL12/AH12-1 -> 0.016635901 | AM27: =AM12/AI12-1 -> 0.077385186 | ... AU27: =AU12/AQ12-1 -> 0.068138871 | AW27: =AW12/O12-1 -> 0.023725908 | AX27: =AX12/P12-1 -> 0.038298492
B29: Profit / (loss) by Business Segments
B30: Dairy and Juice | C30: 2275.335 | D30: 2007.276 | E30: 1713.399 | F30: 1401.976 | G30: 1412.726 | H30: 1220.186 | I30: 1261.552 | J30: 1298.813 | K30: 1489.538 | L30: 1537.705 | M30: =SUM(AR30:AU30) -> 1554.679 | O30: 271.65 | P30: =826.677-O30 -> 555.027 | Q30: =1338.251-P30-O30 -> 511.574 | R30: =E30-Q30-P30-O30 -> 375.148 | S30: 266.301 | T30: =748.858-S30 -> 482.557 | U30: =1203.312-T30-S30 -> 454.454 | V30: =F30-U30-T30-S30 -> 198.664 | W30: 251.906 | X30: =730.447-W30 -> 478.541 | Y30: =1199.052-X30-W30 -> 468.605 | Z30: =G30-Y30-X30-W30 -> 213.674 | AA30: 288.564 | AB30: =683.115-AA30 -> 394.551 | AC30: =1013.099-AB30-AA30 -> 329.984 | AD30: =H30-AC30-AB30-AA30 -> 207.087 | AE30: 308.661 | AF30: =673.306-AE30 -> 364.645 | AG30: =1060.571-AE30-AF30 -> 387.265 | AH30: =I30-AG30-AF30-AE30 -> 200.981 | AI30: 429.96 | AJ30: =791.658-AI30 -> 361.698 | AK30: =1086.696-AI30-AJ30 -> 295.038 | AL30: =J30-AK30-AJ30-AI30 -> 212.117 | AM30: 498.489 | AN30: =892.978-AM30 -> 394.489 | AO30: =1249.743-AM30-AN30 -> 356.765 | AP30: =K30-AO30-AN30-AM30 -> 239.795 | AQ30: 521.292 | AR30: =905.237-AQ30 -> 383.945 | AS30: =1283.165-AQ30-AR30 -> 377.928 | AT30: =L30-AS30-AR30-AQ30 -> 254.54 | AU30: 538.266 | AX30: 483
B31: Bakery | C31: 347.014 | D31: 312.042 | E31: 212.714 | F31: 250.84 | G31: 237.012 | H31: 226.199 | I31: 334.07 | J31: 384.417 | K31: 403.325 | L31: 452.073 | M31: =SUM(AR31:AU31) -> 470.795 | O31: 45.207 | P31: =85.994-O31 -> 40.787 | Q31: =165.604-P31-O31 -> 79.61 | R31: =E31-Q31-P31-O31 -> 47.11 | S31: 56.668 | T31: =85.435-S31 -> 28.767 | U31: =166.41-T31-S31 -> 80.975 | V31: =F31-U31-T31-S31 -> 84.43 | W31: 63.919 | X31: =105.02-W31 -> 41.101 | Y31: =169.376-X31-W31 -> 64.356 | Z31: =G31-Y31-X31-W31 -> 67.636 | AA31: 41.769 | AB31: =76.7-AA31 -> 34.931 | AC31: =155.538-AB31-AA31 -> 78.838 | AD31: =H31-AC31-AB31-AA31 -> 70.661 | AE31: 68.253 | AF31: =147.587-AE31 -> 79.334 | AG31: =257.8-AE31-AF31 -> 110.213 | AH31: =I31-AG31-AF31-AE31 -> 76.27 | AI31: 88.468 | AJ31: =177.39-AI31 -> 88.922 | AK31: =292.2-AI31-AJ31 -> 114.81 | AL31: =J31-AK31-AJ31-AI31 -> 92.217 | AM31: 90.027 | AN31: =184.027-AM31 -> 94 | AO31: =304.421-AM31-AN31 -> 120.394 | AP31: =K31-AO31-AN31-AM31 -> 98.904 | AQ31: 90.085 | AR31: =191.6-AQ31 -> 101.515 | AS31: =324.473-AQ31-AR31 -> 132.873 | AT31: =L31-AS31-AR31-AQ31 -> 127.6 | AU31: 108.807 | AX31: 27
B32: Poultry | C32: -294.46 | D32: -29.161 | E32: 180.084 | F32: 263.295 | G32: 344.033 | H32: 217.487 | I32: 302.422 | J32: 429.854 | K32: 485.782 | L32: 489.6 | M32: =SUM(AR32:AU32) -> 451.978 | O32: 25.348 | P32: =92.001-O32 -> 66.653 | Q32: =142.909-P32-O32 -> 50.908 | R32: =E32-Q32-P32-O32 -> 37.175 | S32: 39.062 | T32: =121.776-S32 -> 82.714 | U32: =184.012-T32-S32 -> 62.236 | V32: =F32-U32-T32-S32 -> 79.283 | W32: 73.147 | X32: =198.616-W32 -> 125.469 | Y32: =271.186-X32-W32 -> 72.57 | Z32: =G32-Y32-X32-W32 -> 72.847 | AA32: 55.779 | AB32: =124.981-AA32 -> 69.202 | AC32: =161.279-AB32-AA32 -> 36.298 | AD32: =H32-AC32-AB32-AA32 -> 56.208 | AE32: 60.889 | AF32: =140.443-AE32 -> 79.554 | AG32: =234.428-AE32-AF32 -> 93.985 | AH32: =I32-AG32-AF32-AE32 -> 67.994 | AI32: 133.475 | AJ32: =237.248-AI32 -> 103.773 | AK32: =350.05-AI32-AJ32 -> 112.802 | AL32: =J32-AK32-AJ32-AI32 -> 79.804 | AM32: 140.165 | AN32: =271.245-AM32 -> 131.08 | AO32: =401.043-AM32-AN32 -> 129.798 | AP32: =K32-AO32-AN32-AM32 -> 84.739 | AQ32: 145.05 | AR32: =275.5-AQ32 -> 130.45 | AS32: =405.6-AQ32-AR32 -> 130.1 | AT32: =L32-AS32-AR32-AQ32 -> 84 | AU32: 107.428 | AX32: 83
B33: Other Activities | C33: -177.792 | D33: -130.194 | E33: -97.639 | F33: -114.539 | G33: -58.215 | H33: -84.436 | I33: -119.906 | J33: -61.555 | K33: -64.978 | L33: -22.705 | M33: =SUM(AR33:AU33) -> -19.868 | O33: -1.804 | P33: =-1.081-O33 -> 0.723 | Q33: =-1.928-P33-O33 -> -0.847 | R33: =E33-Q33-P33-O33 -> -95.711 | S33: -25.083 | T33: =-35.266-S33 -> -10.183 | U33: =-40.21-T33-S33 -> -4.944 | V33: =F33-U33-T33-S33 -> -74.329 | W33: -21.578 | X33: =-46.751-W33 -> -25.173 | Y33: =-37.144-X33-W33 -> 9.607 | Z33: =G33-Y33-X33-W33 -> -21.071 | AA33: 2.569 | AB33: =-6.087-AA33 -> -8.656 | AC33: =-40.359-AB33-AA33 -> -34.272 | AD33: =H33-AC33-AB33-AA33 -> -44.077 | AE33: -15.28 | AF33: =-12.709-AE33 -> 2.571 | AG33: =-129.278-AE33-AF33 -> -116.569 | AH33: =I33-AG33-AF33-AE33 -> 9.372 | AI33: -15.947 | AJ33: =-13.272-AI33 -> 2.675 | AK33: =-49.155-AI33-AJ33 -> -35.883 | AL33: =J33-AK33-AJ33-AI33 -> -12.4 | AM33: -35.3 | AN33: =-33.759-AM33 -> 1.541 | AO33: =-71.89-AM33-AN33 -> -38.131 | AP33: =K33-AO33-AN33-AM33 -> 6.912 | AQ33: -24.9 | AR33: =6.3-AQ33 -> 31.2 | AS33: =-21.085-AQ33-AR33 -> -27.385 | AT33: =L33-AS33-AR33-AQ33 -> -1.62 | AU33: -22.063
B34: Total | C34: =SUM(C30:C33) -> 2150.097 | D34: =SUM(D30:D33) -> 2159.963 | E34: =SUM(E30:E33) -> 2008.558 | F34: =SUM(F30:F33) -> 1801.572 | G34: =SUM(G30:G33) -> 1935.556 | H34: =SUM(H30:H33) -> 1579.436 | I34: =SUM(I30:I33) -> 1778.138 | J34: =SUM(J30:J33) -> 2051.529 | ... M34: =SUM(M30:M33) -> 2457.584 | O34: =SUM(O30:O33) -> 340.401 | P34: =SUM(P30:P33) -> 663.19 | Q34: =SUM(Q30:Q33) -> 641.245 | R34: =SUM(R30:R33) -> 363.722 | S34: =SUM(S30:S33) -> 336.948 | T34: =SUM(T30:T33) -> 583.855 | U34: =SUM(U30:U33) -> 592.721 | V34: =SUM(V30:V33) -> 288.048 | ... AU34: =SUM(AU30:AU33) -> 732.438 | AX34: =SUM(AX30:AX33) -> 593
B35: check | C35: =C34-Model!C22 -> 0 | D35: =D34-Model!D22 -> 0 | E35: =E34-Model!E22 -> 0 | F35: =F34-Model!F22 -> 0 | G35: =G34-Model!G22 -> 0 | H35: =H34-Model!H22 -> 1.8189894e-12 | I35: =I34-Model!I22 -> -2.0463631e-12 | J35: =J34-Model!J22 -> 0 | ... M35: =M34-Model!M22 -> 0 | O35: =O34-Model!O22 -> 0 | P35: =P34-Model!P22 -> 0 | Q35: =Q34-Model!Q22 -> 0 | R35: =R34-Model!R22 -> 1.2505552e-12 | S35: =S34-Model!S22 -> 0 | T35: =T34-Model!T22 -> 0 | U35: =U34-Model!U22 -> -0.001 | V35: =V34-Model!V22 -> 0.001 | ... AU35: =AU34-Model!AU22 -> 0 | AX35: =AX34-Model!AX22 -> 9.145
B37: Revenue Composition (%)
B38: Dairy and Juice | C38: =C30/C$34 -> 1.0582476 | D38: =D30/D$34 -> 0.92931036 | E38: =E30/E$34 -> 0.8530493 | F38: =F30/F$34 -> 0.77819593 | G38: =G30/G$34 -> 0.72988123 | H38: =H30/H$34 -> 0.77254539 | I38: =I30/I$34 -> 0.70947924 | J38: =J30/J$34 -> 0.63309512 | ... M38: =M30/M$34 -> 0.63260462 | O38: =O30/O$34 -> 0.79802938 | P38: =P30/P$34 -> 0.83690496 | Q38: =Q30/Q$34 -> 0.79778244 | R38: =R30/R$34 -> 1.0314141 | S38: =S30/S$34 -> 0.79033263 | T38: =T30/T$34 -> 0.82650144 | U38: =U30/U$34 -> 0.76672499 | V38: =V30/V$34 -> 0.68969061 | ... AU38: =AU30/AU$34 -> 0.73489633 | AX38: =AX30/AX$34 -> 0.81450253
B39: Bakery | C39: =C31/C$34 -> 0.16139458 | D39: =D31/D$34 -> 0.14446636 | E39: =E31/E$34 -> 0.10590384 | F39: =F31/F$34 -> 0.13923396 | G39: =G31/G$34 -> 0.12245164 | H39: =H31/H$34 -> 0.14321505 | I39: =I31/I$34 -> 0.18787631 | J39: =J31/J$34 -> 0.18738073 | ... M39: =M31/M$34 -> 0.19156822 | O39: =O31/O$34 -> 0.13280513 | P39: =P31/P$34 -> 0.061501229 | Q39: =Q31/Q$34 -> 0.12414912 | R39: =R31/R$34 -> 0.129522 | S39: =S31/S$34 -> 0.16818025 | T39: =T31/T$34 -> 0.049270795 | U39: =U31/U$34 -> 0.13661571 | V39: =V31/V$34 -> 0.29311087 | ... AU39: =AU31/AU$34 -> 0.14855455 | AX39: =AX31/AX$34 -> 0.045531197
B40: Poultry | C40: =C32/C$34 -> -0.13695196 | D40: =D32/D$34 -> -0.013500694 | E40: =E32/E$34 -> 0.089658352 | F40: =F32/F$34 -> 0.14614736 | G40: =G32/G$34 -> 0.17774376 | H40: =H32/H$34 -> 0.13769915 | I40: =I32/I$34 -> 0.17007791 | J40: =J32/J$34 -> 0.2095286 | ... M40: =M32/M$34 -> 0.18391152 | O40: =O32/O$34 -> 0.074465116 | P40: =P32/P$34 -> 0.10050363 | Q40: =Q32/Q$34 -> 0.079389313 | R40: =R32/R$34 -> 0.10220718 | S40: =S32/S$34 -> 0.11592887 | T40: =T32/T$34 -> 0.14166874 | U40: =U32/U$34 -> 0.1050005 | V40: =V32/V$34 -> 0.27524232 | ... AU40: =AU32/AU$34 -> 0.1466718 | AX40: =AX32/AX$34 -> 0.13996627
