Workbook
Name \A: #REF!
Name \B: #REF!
Name \C: #REF!
Name \L: #REF!
Name \M: #REF!
Name \P: #REF!
Name \Y: #REF!
Name _01_30_04: MonthlyOpStats
Name _01_30_04: MonthlyOpStats
Name _01_30_04: MonthlyOpStats
Name _01_30_04: MonthlyOpStats
Name _1_30_01: MonthlyOpStats
Name _1_30_01: MonthlyOpStats
Name _1_30_01: MonthlyOpStats
Name _1_30_01: MonthlyOpStats
Name _1_30_02: MonthlyOpStats
Name _1_30_02: MonthlyOpStats
Name _1_30_02: MonthlyOpStats
Name _1_30_02: MonthlyOpStats
Name _1_31_01: MonthlyOpStats
Name _1_31_01: MonthlyOpStats
Name _1_31_01: MonthlyOpStats
Name _1_31_01: MonthlyOpStats
Name _1_31_02: MonthlyOpStats
Name _1_31_02: MonthlyOpStats
Name _1_31_02: MonthlyOpStats
Name _1_31_02: MonthlyOpStats
Name _12_31_05: MonthlyOpStats
Name _12_31_05: MonthlyOpStats
Name _12_31_05: MonthlyOpStats
Name _12_31_05: MonthlyOpStats
Name _A: #REF!
Name _A___0: #REF!
Name _B: #REF!
Name _B___0: #REF!
Name _C: #REF!
Name _C___0: #REF!
Name _ent1: [15]Inputs!$J$17
Name _ent10: [15]Inputs!$J$476
Name _ent11: [15]Inputs!$J$527
Name _ent12: [15]Inputs!$J$578
Name _ent13: [15]Inputs!$J$629
Name _ent14: [15]Inputs!$J$680
Name _ent15: [15]Inputs!$J$731
Name _ent2: [15]Inputs!$J$68
Name _ent3: [15]Inputs!$J$119
Name _ent4: [15]Inputs!$J$170
Name _ent5: [15]Inputs!$J$221
Name _ent6: [15]Inputs!$J$272
Name _ent7: [15]Inputs!$J$323
Name _ent8: [15]Inputs!$J$374
Name _ent9: [15]Inputs!$J$425
Name _eps1: [15]Inputs!$P$42
Name _eps10: [15]Inputs!$P$501
Name _eps11: [15]Inputs!$P$552
Name _eps12: [15]Inputs!$P$603
Name _eps13: [15]Inputs!$P$654
Name _eps14: [15]Inputs!$P$705
Name _eps15: [15]Inputs!$P$756
Name _eps2: [15]Inputs!$P$93

Sheet Capitalisation
A3: 1Q26
B4: As of March 2026 | C4: TRY (mn) | D4: USD( mn) | E4: Leverage (TRY) | F4: Leverage (USD) | H4: Company Reported
H5: Net Financial Debt / EBITDA on Combined Basis | I5: 1.5
B6: Current: | C6: =SUM(C7:C9) -> 759029 | D6: =SUM(D7:D9) -> 17074.597
B7: Bank borrowings | C7: 546345 | D7: =+C7/$C$28 -> 12290.203
B8: Issued debt securities | C8: 207996 | D8: =+C8/$C$28 -> 4678.9356
B9: Factoring debts | C9: 4688 | D9: =+C9/$C$28 -> 105.45804
B11: Non Current: | C11: =SUM(C12:C13) -> 602002 | D11: =SUM(D12:D13) -> 13542.225
B12: Bank borrowings | C12: 226305 | D12: =+C12/$C$28 -> 5090.8023
B13: Issued debt securities | C13: 375697 | D13: =+C13/$C$28 -> 8451.4225
B15: Lease Liabilities: | C15: =SUM(C16:C17) -> 23468 | D15: =SUM(D16:D17) -> 527.92006
B16: Current leases | C16: 7141 | D16: =+C16/$C$28 -> 160.63905
B17: Non-current leases | C17: 16327 | D17: =+C17/$C$28 -> 367.28101
B20: Total debt | C20: =SUM(C6,C11,C15) -> 1384499 | D20: =+C20/$C28 -> 31144.742 | E20: =+C20/C27 -> 5.9009769 | F20: =+D20/D27 -> 5.5027837
B21: Cash * | C21: =Model!BI$56 -> 898265 | D21: =+C21/$C28 -> 20206.754
B22: Net debt | C22: =+C20-C21 -> 486234 | D22: =+D20-D21 -> 10937.987 | E22: =+C22/C27 -> 2.0724144 | F22: =+D22/D27 -> 1.9325695
B24: Market cap | C24: =Model!BI$60 -> 469141.1 | D24: =+C24/$C28 -> 10553.477
B25: Total capitalisation | C25: =+C24+C22 -> 955375.1 | D25: =+D24+D22 -> 21491.464 | E25: =+C25/C27 -> 4.0719758 | F25: =+D25/D27 -> 3.7972021
B27: LTM EBITDA | C27: =Model!BI$44 -> 234622 | D27: =+C27/C29 -> 5659.8157
B28: TRY/USD exchange rate - end period | C28: =Model!BI$95 -> 44.4537
B29: TRY/USD exchange rate - average | C29: =AVERAGE(Model!$BF$96:$BI$96) -> 41.454
B30: check | C30: =C20-Model!$BI$55 -> 0
B33: Liquidity table | C33: TRY (mn) | D33: USD (mn)
B34: Cash | C34: =C21 -> 898265 | D34: =C34/$C$28 -> 20206.754
B35: Total | C35: =SUM(C34:C34) -> 898265 | D35: =SUM(D34:D34) -> 20206.754
B40: Debt maturity schedule: | C40: TRY mn | D40: USDmn
B41: Less than 1 year | C41: =Model!$BI$53 -> 766170 | D41: =C41/$C$28 -> 17235.236
B42: 1-2 years | C42: 180601 | D42: =C42/$C$28 -> 4062.6764
B43: 2-3 years | C43: 146917 | D43: =C43/$C$28 -> 3304.9442
B44: 3-4 years | C44: 87374 | D44: =C44/$C$28 -> 1965.5057
B45: 4-5 years | C45: 64503 | D45: =C45/$C$28 -> 1451.0153
B46: 5 years and over | C46: 138934 | D46: =C46/$C$28 -> 3125.3641
B47: Total | C47: =SUM(C41:C46) -> 1384499 | D47: =SUM(D41:D46) -> 31144.742
B48: check | C48: =C47-C20 -> 0
A53: FY25
B54: As of Dec 2025 | C54: TRY (mn) | D54: USD( mn) | E54: Leverage (TRY) | F54: Leverage (USD) | H54: Company Reported
H55: Net Financial Debt / EBITDA on Combined Basis | I55: 1.2
B56: Current: | C56: =SUM(C57:C59) -> 748278 | D56: =SUM(D57:D59) -> 17418.544
B57: Bank borrowings | C57: 504342 | D57: =+C57/$C$78 -> 11740.16
B58: Issued debt securities | C58: 240032 | D58: =+C58/$C$78 -> 5587.5061
...

Sheet Model
B2: KOC HOLDING | D2: Annual | E2: Annual | F2: Annual | G2: Annual | H2: Annual | I2: Annual | J2: Annual | K2: Annual | L2: Annual | M2: Annual | N2: Annual | O2: Annual | P2: Annual | Q2: Annual | R2: Annual | S2: Annual | T2: Annual | U2: LTM | V2: Annual | W2: Annual | Y2: Quarters | Z2: Quarters | AA2: Quarters | AB2: Quarters | AC2: Quarters | AD2: Quarters | AE2: Quarters | AF2: Quarters | AG2: Quarters | AH2: Quarters | AI2: Quarters | AJ2: Quarters | AK2: Quarters | AL2: Quarters | AM2: Quarters | AN2: Quarters | AO2: Quarters | AP2: Quarters | AQ2: Quarters | AR2: Quarters | AS2: Quarters | AT2: Quarters | AU2: Quarters | AV2: Quarters | AW2: Quarters | AX2: Quarters | AY2: Quarters | AZ2: Quarters | BA2: Quarters | BB2: Quarters | BC2: Quarters | BD2: Quarters | BE2: Quarters | BF2: Quarters | BG2: Quarters | BH2: Quarters | BI2: Quarters | BK2: 9M | BL2: 9M | BN2: Quarters | BO2: Quarters | BP2: Quarters | BQ2: Quarters | BR2: Quarters | BS2: H1 | BT2: H2 | BU2: H1 | BV2: H2 | BW2: H1 | BX2: H2 | BY2: H1 | BZ2: H2 | CA2: H1 | CB2: H2 | CC2: H1 | CD2: H2 | CE2: H1 | CF2: H2 | CG2: H1 | CI2: H1 | CJ2: H2 | CK2: H1
B3: TRY mn | D3: 41274 | E3: =D3+365 -> 41639 | F3: =E3+365 -> 42004 | G3: =F3+365 -> 42369 | H3: =G3+365 -> 42734 | I3: =H3+365 -> 43099 | J3: =I3+365 -> 43464 | K3: =J3+365 -> 43829 | L3: =K3+365 -> 44194 | ... N3: =M3+365 -> 44924 | O3: =N3 -> 44924 | P3: =N3+365 -> 45289 | Q3: =O3+365 -> 45289 | R3: =P3+365 -> 45654 | S3: =Q3+365 -> 45654 | T3: =R3+365 -> 46019 | U3: =BI3 -> 46111 | V3: =G3+366 -> 42735 | W3: =V3+365 -> 43100 | Y3: 42825 | Z3: =EDATE(Y3,3) -> 42916 | AA3: =EDATE(Z3,3) -> 43008 | AB3: =EDATE(AA3,3) -> 43099 | AC3: =EDATE(AB3,3) -> 43189 | AD3: =EDATE(AC3,3) -> 43281 | AE3: =EDATE(AD3,3) -> 43373 | AF3: =EDATE(AE3,3) -> 43464 | AG3: =EDATE(AF3,3) -> 43554 | ... BI3: =EDATE(BH3,3) -> 46111 | BK3: 45565 | BL3: 45930 | BN3: 45381 | BO3: =EDATE(BN3,3) -> 45473 | BP3: =EDATE(BO3,3) -> 45565 | BQ3: =EDATE(BP3,3) -> 45656 | BR3: 45746 | BS3: 42156 | BT3: 42369 | BU3: 42522 | BV3: 42735 | BW3: 43983 | BX3: 44196 | BY3: 44348 | BZ3: 44561 | CA3: 44713 | CB3: 44926 | CC3: 45078 | CD3: 45291 | CE3: 45444 | CF3: 45657 | CG3: 45809 | CI3: 45078 | CJ3: 45291 | CK3: 45444
D4: Act | E4: Act | F4: Act | G4: Act | H4: Act | I4: Act | J4: Act | K4: Act | L4: Act | M4: Act | N4: Act | O4: Act | P4: Act | Q4: Act | R4: Act | S4: Act | T4: Act | U4: Act | V4: Proj | W4: Proj | Y4: Act | Z4: Act | AA4: Act | AB4: Act | AC4: Act | AD4: Act | AE4: Act | AF4: Act | AG4: Act | AH4: Act | AI4: Act | AJ4: Act | AK4: Act | AL4: Act | AM4: Act | AN4: Act | AO4: Act | AP4: Act | AQ4: Act | AR4: Act | AS4: Act | AT4: Act | AU4: Act | AV4: Act | AW4: Act | AX4: Act | AY4: Act | AZ4: Act | BA4: Act | BB4: Act | BC4: Act | BD4: Act | BE4: Act | BF4: Act | BG4: Act | BH4: Act | BI4: Act | BK4: Act | BL4: Act | BN4: Act | BO4: Act | BP4: Act | BQ4: Act | BR4: Act | BS4: Act | BT4: Act | BU4: Act | BV4: Act | BW4: Act | BX4: Act | BY4: Act | BZ4: Act | CA4: Act | CB4: Act | CC4: Act | CD4: Act | CE4: Act | CF4: Act | CG4: Act | CI4: Restated | CJ4: Restated | CK4: Restated
D5: FY | E5: FY | F5: FY | G5: FY | H5: FY | I5: FY | J5: FY | K5: FY | L5: FY | M5: FY | N5: FY | O5: FY | P5: FY | Q5: FY | R5: FY | S5: FY | T5: FY | U5: FY | Y5: 1Q | Z5: 2Q | AA5: 3Q | AB5: 4Q | AC5: 1Q | AD5: 2Q | AE5: 3Q | AF5: 4Q | AG5: 1Q | AH5: 2Q | AI5: 3Q | AJ5: 4Q | AK5: 1Q | AL5: 2Q | AM5: 3Q | AN5: 4Q | AO5: 1Q | AP5: 2Q | AQ5: 3Q | AR5: 4Q | AS5: 1Q | AT5: 2Q | AU5: 3Q | AV5: 4Q | AW5: 1Q | AX5: 2Q | AY5: 3Q | AZ5: 4Q | BA5: 1Q | BB5: 2Q | BC5: 3Q | BD5: 4Q | BE5: 1Q | BF5: 2Q | BG5: 3Q | BH5: 4Q | BI5: 1Q | BK5: 9M | BL5: 9M | BS5: 6M | BT5: 6M | BU5: 6M | BV5: 6M | BW5: 6M | BX5: 6M | BY5: 6M | BZ5: 6M | CA5: 6M | CB5: 6M | CC5: 6M | CD5: 6M | CE5: 6M | CF5: 6M | CG5: 6M
B6: SUMMARY FINANCIALS - CONSOLIDATED | O6: Restated | Q6: Restated | S6: Restated | BN6: Restated | BO6: Restated | BP6: Restated | BQ6: Restated | BR6: Restated
B7: Combined revenues by segment:
B8: Energy | D8: 63225 | E8: 65458 | F8: 68343 | G8: 62397 | H8: 67273.473 | I8: 97574.116 | J8: 153250.04 | K8: 153426.36 | L8: 115839.99 | M8: 229549.24 | N8: 713727 | O8: 1353617 | P8: 1051742 | Q8: 1518495 | R8: 1291970 | S8: 1691087 | T8: 1419042 | U8: =BG8+BF8+BH8+BI8 -> 1558911 | Y8: 21706.751 | Z8: =44766.375-Y8 -> 23059.624 | AA8: =70993.13-Z8-Y8 -> 26226.755 | AB8: =I8-AA8-Z8-Y8 -> 26580.986 | AC8: 25753.228 | AD8: =61647.231-AC8 -> 35894.003 | AE8: =111704.372-AD8-AC8 -> 50057.141 | AF8: =J8-AE8-AD8-AC8 -> 41545.665 | AG8: 35505.985 | AH8: =75465.13-AG8 -> 39959.145 | AI8: =115889.709-AH8-AG8 -> 40424.579 | AJ8: =K8-AI8-AH8-AG8 -> 37536.655 | AK8: 29045.338 | AL8: =48227.598-AK8 -> 19182.26 | AM8: =81690.069-AL8-AK8 -> 33462.471 | AN8: =L8-AM8-AL8-AK8 -> 34149.92 | AO8: 33280.593 | AP8: =82076.796-AO8 -> 48796.203 | AQ8: =146275.599-AP8-AO8 -> 64198.803 | AR8: =M8-AQ8-AP8-AO8 -> 83273.639 | AS8: 113178.05 | AT8: =310142.923-AS8 -> 196964.87 | AU8: =528048.25-AT8-AS8 -> 217905.33 | AV8: =N8-AU8-AT8-AS8 -> 185678.75 | AW8: 253773 | AX8: 282047 | AY8: =1056315-AX8-AW8 -> 520495 | AZ8: =Q8-AY8-AX8-AW8 -> 462180 | BA8: 258566 | BB8: 288610 | BC8: =948415-BB8-BA8 -> 401239 | BD8: =R8-BC8-BB8-BA8 -> 343555 | BE8: 264705 | BF8: 308079 | BG8: 390749 | BH8: =T8-BG8-BF8-BE8 -> 455509 | BI8: 404574 | BK8: 1264180 | BL8: 1023611 | BN8: 357090 | BO8: 389765 | BP8: 417656 | BQ8: =S8-BN8-BO8-BP8 -> 526576 | BR8: 346406 | BS8: 29443 | BT8: =G8-BS8 -> 32954 | BU8: 28996 | BV8: =H8-BU8 -> 38277.473 | BW8: 48227.598 | BX8: =L8-BW8 -> 67612.391 | BY8: =82076.796 -> 82076.796 | BZ8: =M8-BY8 -> 147472.44 | CA8: 310142.92 | CB8: =N8-CA8 -> 403584.08 | CC8: 307307 | CD8: =P8-CC8 -> 744435 | CE8: 568908 | CF8: =R8-CE8 -> 723062 | CG8: 588686 | CI8: 55715 | CJ8: =Q8-CI8 -> 1462780 | CK8: 768305
B9: Automotive | D9: 22172 | E9: 25114 | F9: 26829 | G9: 35868 | H9: 42703.575 | I9: 55556.629 | J9: 65716.103 | K9: 74447.601 | L9: 98338.398 | M9: 139014.96 | N9: 312873 | O9: 589035 | P9: 739103 | Q9: 1067110 | R9: 971573 | S9: 1271711 | T9: 1444986 | U9: =BG9+BF9+BH9+BI9 -> 1559576 | Y9: 12165.689 | Z9: =25936.526-Y9 -> 13770.837 | AA9: =38317.951-Z9-Y9 -> 12381.425 | AB9: =I9-AA9-Z9-Y9 -> 17238.678 | AC9: 14500.697 | AD9: =30978.781-AC9 -> 16478.084 | AE9: =46354.832-AD9-AC9 -> 15376.051 | AF9: =J9-AE9-AD9-AC9 -> 19361.271 | AG9: 16272.41 | AH9: =34500.939-AG9 -> 18228.529 | AI9: =51563.928-AH9-AG9 -> 17062.989 | AJ9: =K9-AI9-AH9-AG9 -> 22883.673 | AK9: 17854.572 | AL9: =30904.898-AK9 -> 13050.326 | AM9: =57973.607-AL9-AK9 -> 27068.709 | AN9: =L9-AM9-AL9-AK9 -> 40364.791 | AO9: 30610.845 | AP9: =57579.073-AO9 -> 26968.228 | AQ9: =90847.275-AP9-AO9 -> 33268.202 | AR9: =M9-AQ9-AP9-AO9 -> 48167.689 | AS9: 50194.507 | AT9: =114997.673-AS9 -> 64803.166 | AU9: =199588.174-AT9-AS9 -> 84590.501 | AV9: =N9-AU9-AT9-AS9 -> 113284.83 | AW9: 196083 | AX9: 232543 | AY9: =733428-AX9-AW9 -> 304802 | AZ9: =Q9-AY9-AX9-AW9 -> 333682 | BA9: 211002 | BB9: 182446 | BC9: =668056-BB9-BA9 -> 274608 | BD9: =R9-BC9-BB9-BA9 -> 303517 | BE9: 236908 | BF9: 325057 | BG9: 343285 | BH9: =T9-BG9-BF9-BE9 -> 539736 | BI9: 351498 | BK9: 890479 | BL9: 962719 | BN9: 291402 | BO9: 246392 | BP9: 293510 | BQ9: =S9-BN9-BO9-BP9 -> 440407 | BR9: 310030 | BS9: 16257 | BT9: =G9-BS9 -> 19611 | BU9: 19920 | BV9: =H9-BU9 -> 22783.575 | BW9: 30904.898 | BX9: =L9-BW9 -> 67433.5 | BY9: =57579.073 -> 57579.073 | BZ9: =M9-BY9 -> 81435.891 | CA9: 114997.67 | CB9: =N9-CA9 -> 197875.33 | CC9: 247251 | CD9: =P9-CC9 -> 491852 | CE9: 411183 | CF9: =R9-CE9 -> 560390 | CG9: 576196 | CI9: 445107 | CJ9: =Q9-CI9 -> 622003 | CK9: 555299
B10: Consumer durables | D10: 11194 | E10: 11806 | F10: 12941 | G10: 14651 | H10: 17997.17 | I10: 23360.88 | J10: 30244.192 | K10: 36310.763 | L10: 47170.723 | M10: 76889.132 | N10: 153713 | O10: 291269 | P10: 297189 | Q10: 429079 | R10: 485412 | S10: 635365 | T10: 597907 | U10: =BG10+BF10+BH10+BI10 -> 615784 | Y10: 5085.728 | Z10: =10900.311-Y10 -> 5814.583 | AA10: =17034.106-Z10-Y10 -> 6133.795 | AB10: =I10-AA10-Z10-Y10 -> 6326.774 | AC10: 6173.981 | AD10: =13734.803-AC10 -> 7560.822 | AE10: =22125.788-AD10-AC10 -> 8390.985 | AF10: =J10-AE10-AD10-AC10 -> 8118.404 | AG10: 7886.199 | AH10: =17602.89-AG10 -> 9716.691 | AI10: =26769.357-AH10-AG10 -> 9166.467 | AJ10: =K10-AI10-AH10-AG10 -> 9541.406 | AK10: 9028.126 | AL10: =18168.213-AK10 -> 9140.087 | AM10: =32219.42-AL10-AK10 -> 14051.207 | AN10: =L10-AM10-AL10-AK10 -> 14951.303 | AO10: 15105.577 | AP10: =31855.798-AO10 -> 16750.221 | AQ10: =52304.98-AP10-AO10 -> 20449.182 | AR10: =M10-AQ10-AP10-AO10 -> 24584.152 | AS10: 32558.289 | AT10: =70240.258-AS10 -> 37681.969 | AU10: =109212.105-AT10-AS10 -> 38971.847 | AV10: =N10-AU10-AT10-AS10 -> 44500.895 | AW10: 81504 | AX10: 94599 | AY10: =303150-AX10-AW10 -> 127047 | AZ10: =Q10-AY10-AX10-AW10 -> 125929 | BA10: 86490 | BB10: 113384 | BC10: =344026-BB10-BA10 -> 144152 | BD10: =R10-BC10-BB10-BA10 -> 141386 | BE10: 125545 | BF10: 140988 | BG10: 140857 | BH10: =T10-BG10-BF10-BE10 -> 190517 | BI10: 143422 | BK10: 458566 | BL10: 435498 | BN10: 119446 | BO10: 153124 | BP10: 157829 | BQ10: =S10-BN10-BO10-BP10 -> 204966 | BR10: 164294 | BS10: 6510 | BT10: =G10-BS10 -> 8141 | BU10: 8425 | BV10: =H10-BU10 -> 9572.17 | BW10: 18168.213 | BX10: =L10-BW10 -> 29002.51 | BY10: =31855.798 -> 31855.798 | BZ10: =M10-BY10 -> 45033.334 | CA10: 70240.258 | CB10: =N10-CA10 -> 83472.742 | CC10: 103353 | CD10: =P10-CC10 -> 193836 | CE10: 207143 | CF10: =R10-CE10 -> 278269 | CG10: 274074 | CI10: 182953 | CJ10: =Q10-CI10 -> 246126 | CK10: 279745
B11: Finance | D11: 12985 | E11: 13834 | F11: 16838 | G11: 21514 | H11: 24235.787 | I11: 29699.776 | J11: 43227.187 | K11: 47843.543 | L11: 45183.224 | M11: 73513.573 | N11: 168699 | O11: 317826 | P11: 388576 | Q11: 561022 | R11: 710437 | S11: 929906 | T11: 923792 | U11: =BG11+BF11+BH11+BI11 -> 982056 | Y11: 6839.52 | Z11: =14096.285-Y11 -> 7256.765 | AA11: =21544.943-Z11-Y11 -> 7448.658 | AB11: =I11-AA11-Z11-Y11 -> 8154.833 | AC11: 8405.358 | AD11: =17865.292-AC11 -> 9459.934 | AE11: =30424.138-AD11-AC11 -> 12558.846 | AF11: =J11-AE11-AD11-AC11 -> 12803.049 | AG11: 12149.961 | AH11: =24643.626-AG11 -> 12493.665 | AI11: =36596.155-AH11-AG11 -> 11952.529 | AJ11: =K11-AI11-AH11-AG11 -> 11247.388 | AK11: 10945.379 | AL11: =21200.874-AK11 -> 10255.495 | AM11: =32785.443-AL11-AK11 -> 11584.569 | AN11: =L11-AM11-AL11-AK11 -> 12397.781 | AO11: 14095.293 | AP11: =29611.25-AO11 -> 15515.957 | AQ11: =47600.715-AP11-AO11 -> 17989.465 | AR11: =M11-AQ11-AP11-AO11 -> 25912.858 | AS11: 27471.108 | AT11: =63841.977-AS11 -> 36370.869 | AU11: =111649.534-AT11-AS11 -> 47807.557 | AV11: =N11-AU11-AT11-AS11 -> 57049.466 | AW11: 86708 | AX11: 120107 | AY11: =378450-AX11-AW11 -> 171635 | AZ11: =Q11-AY11-AX11-AW11 -> 182572 | BA11: 139382 | BB11: 156197 | BC11: =503349-BB11-BA11 -> 207770 | BD11: =R11-BC11-BB11-BA11 -> 207088 | BE11: 187607 | BF11: 201398 | BG11: 225849 | BH11: =T11-BG11-BF11-BE11 -> 308938 | BI11: 245871 | BK11: 670934 | BL11: 656161 | BN11: 192492 | BO11: 210942 | BP11: 224796 | BQ11: =S11-BN11-BO11-BP11 -> 301676 | BR11: 245512 | BS11: 9973 | BT11: =G11-BS11 -> 11541 | BU11: 11993 | BV11: =H11-BU11 -> 12242.787 | BW11: 21200.874 | BX11: =L11-BW11 -> 23982.35 | BY11: =29611.25 -> 29611.25 | BZ11: =M11-BY11 -> 43902.323 | CA11: 63841.977 | CB11: =N11-CA11 -> 104857.02 | CC11: 118506 | CD11: =P11-CC11 -> 270070 | CE11: 307294 | CF11: =R11-CE11 -> 403143 | CG11: 400275 | CI11: 214103 | CJ11: =Q11-CI11 -> 346919 | CK11: 414997
B12: Other | D12: 7008 | E12: 7265 | F12: 8514 | G12: 9880 | H12: 9581.51 | I12: 11107.987 | J12: 13837.305 | K12: 17014.195 | L12: 18365.73 | M12: 25364.622 | N12: 56527 | O12: 106791 | P12: 116697 | Q12: 168486 | R12: 166325 | S12: 217706 | T12: 217750 | U12: =BG12+BF12+BH12+BI12 -> 230369 | Y12: 2373.273 | Z12: =5057.218-Y12 -> 2683.945 | AA12: =7899.816-Z12-Y12 -> 2842.598 | AB12: =I12-AA12-Z12-Y12 -> 3208.171 | AC12: 2645.087 | AD12: =5882.612-AC12 -> 3237.525 | AE12: =9555.058-AD12-AC12 -> 3672.446 | AF12: =J12-AE12-AD12-AC12 -> 4282.247 | AG12: 3580.001 | AH12: =7892.198-AG12 -> 4312.197 | AI12: =12208.894-AH12-AG12 -> 4316.696 | AJ12: =K12-AI12-AH12-AG12 -> 4805.301 | AK12: 3825.729 | AL12: =7625.018-AK12 -> 3799.289 | AM12: =11943.176-AL12-AK12 -> 4318.158 | AN12: =L12-AM12-AL12-AK12 -> 6422.554 | AO12: 4584.137 | AP12: =10263.258-AO12 -> 5679.121 | AQ12: =16332.193-AP12-AO12 -> 6068.935 | AR12: =M12-AQ12-AP12-AO12 -> 9032.429 | AS12: 9527.536 | AT12: =22832.153-AS12 -> 13304.617 | AU12: =37428.86-AT12-AS12 -> 14596.707 | AV12: =N12-AU12-AT12-AS12 -> 19098.14 | AW12: 26204 | AX12: 36307 | AY12: =110914-AX12-AW12 -> 48403 | AZ12: =Q12-AY12-AX12-AW12 -> 57572 | BA12: 30042 | BB12: 35894 | BC12: =112056-BB12-BA12 -> 46120 | BD12: =R12-BC12-BB12-BA12 -> 54269 | BE12: 40111 | BF12: 49493 | BG12: 52923 | BH12: =T12-BG12-BF12-BE12 -> 75223 | BI12: 52730 | BK12: 149364 | BL12: 151841 | BN12: 41489 | BO12: 48475 | BP12: 49970 | BQ12: =S12-BN12-BO12-BP12 -> 77772 | BR12: 52491 | BS12: 4618 | BT12: =G12-BS12 -> 5262 | BU12: 4616 | BV12: =H12-BU12 -> 4965.51 | BW12: 7625.018 | BX12: =L12-BW12 -> 10740.712 | BY12: =10263.258 -> 10263.258 | BZ12: =M12-BY12 -> 15101.364 | CA12: 22832.153 | CB12: =N12-CA12 -> 33694.847 | CC12: 35744 | CD12: =P12-CC12 -> 80953 | CE12: 68461 | CF12: =R12-CE12 -> 97864 | CG12: 92013 | CI12: 64713 | CJ12: =Q12-CI12 -> 103773 | CK12: 92456
B13: Total combined revenues | D13: =SUM(D8:D12) -> 116584 | E13: =SUM(E8:E12) -> 123477 | F13: =SUM(F8:F12) -> 133465 | G13: =SUM(G8:G12) -> 144310 | H13: =SUM(H8:H12) -> 161791.52 | I13: =SUM(I8:I12) -> 217299.39 | J13: =SUM(J8:J12) -> 306274.82 | K13: =SUM(K8:K12) -> 329042.47 | ... U13: =SUM(U8:U12) -> 4946696 | Y13: =SUM(Y8:Y12) -> 48170.961 | Z13: =SUM(Z8:Z12) -> 52585.754 | AA13: =SUM(AA8:AA12) -> 55033.231 | AB13: =SUM(AB8:AB12) -> 61509.442 | AC13: =SUM(AC8:AC12) -> 57478.351 | AD13: =SUM(AD8:AD12) -> 72630.368 | AE13: =SUM(AE8:AE12) -> 90055.469 | AF13: =SUM(AF8:AF12) -> 86110.636 | ... BI13: =SUM(BI8:BI12) -> 1198095 | BK13: =SUM(BK8:BK12) -> 3433523 | BL13: =SUM(BL8:BL12) -> 3229830 | BN13: =SUM(BN8:BN12) -> 1001919 | BO13: =SUM(BO8:BO12) -> 1048698 | BP13: =SUM(BP8:BP12) -> 1143761 | BQ13: =SUM(BQ8:BQ12) -> 1551397 | BR13: =SUM(BR8:BR12) -> 1118733 | BS13: =SUM(BS8:BS12) -> 66801 | BT13: =SUM(BT8:BT12) -> 77509 | BU13: =SUM(BU8:BU12) -> 73950 | ... CG13: =SUM(CG8:CG12) -> 1931244 | CI13: =SUM(CI8:CI12) -> 962591 | CJ13: =SUM(CJ8:CJ12) -> 2781601 | CK13: =SUM(CK8:CK12) -> 2110802
B15: Combined operating profit by segment:
B16: Energy | D16: 1674 | E16: 453 | F16: 618 | G16: 3277 | H16: 3393.549 | I16: 6048.895 | J16: 7069.308 | K16: 3842.488 | L16: 329.861 | M16: 3439.376 | N16: 49727 | O16: 78106 | P16: 75417 | Q16: 108886 | R16: 36628 | S16: 50560 | T16: 49495 | U16: =BG16+BF16+BH16+BI16 -> 58190 | Y16: 1576.47 | Z16: =3328.217-Y16 -> 1751.747 | AA16: =5014.777-Z16-Y16 -> 1686.56 | AB16: =I16-AA16-Z16-Y16 -> 1034.118 | AC16: 917.008 | AD16: =2486.617-AC16 -> 1569.609 | AE16: =3843.024-AD16-AC16 -> 1356.407 | AF16: =J16-AE16-AD16-AC16 -> 3226.284 | AG16: 594.485 | AH16: =2294.591-AG16 -> 1700.106 | AI16: =3446.398-AH16-AG16 -> 1151.807 | AJ16: =K16-AI16-AH16-AG16 -> 396.09 | AK16: -1957.239 | AL16: =-1608.476-AK16 -> 348.763 | AM16: =-890.364-AL16-AK16 -> 718.112 | AN16: =L16-AM16-AL16-AK16 -> 1220.225 | AO16: -310.571 | AP16: =2196.575-AO16 -> 2507.146 | AQ16: =5552.116-AP16-AO16 -> 3355.541 | AR16: =M16-AQ16-AP16-AO16 -> -2112.74 | AS16: 4204.592 | AT16: =18060.696-AS16 -> 13856.104 | AU16: =33221.418-AT16-AS16 -> 15160.722 | AV16: =N16-AU16-AT16-AS16 -> 16505.582 | AW16: 15632 | AX16: 13758 | AY16: =78810-AX16-AW16 -> 49420 | AZ16: =Q16-AY16-AX16-AW16 -> 30076 | BA16: 4003 | BB16: 10225 | BC16: =29706-BB16-BA16 -> 15478 | BD16: =R16-BC16-BB16-BA16 -> 6922 | BE16: 4852 | BF16: 12103 | BG16: 18589 | BH16: =T16-BG16-BF16-BE16 -> 13951 | BI16: 13547 | BK16: 39596 | BL16: 37129 | BN16: 5528 | BO16: 13809 | BP16: 18336 | BQ16: =S16-BN16-BO16-BP16 -> 12887 | BR16: 6350 | BS16: 1503 | BT16: =G16-BS16 -> 1774 | BU16: 1125 | BV16: =H16-BU16 -> 2268.549 | BW16: -1608.476 | BX16: =L16-BW16 -> 1938.337 | BY16: =2196.575 -> 2196.575 | BZ16: =M16-BY16 -> 1242.801 | CA16: 18060.696 | CB16: =N16-CA16 -> 31666.304 | CC16: 21657 | CD16: =P16-CC16 -> 53760 | CE16: 14564 | CF16: =R16-CE16 -> 22064 | CG16: 17246 | CI16: 30704 | CJ16: =Q16-CI16 -> 78182 | CK16: 19669
B17: Automotive | D17: 1649 | E17: 1705 | F17: 1618 | G17: 2529 | H17: 2915.291 | I17: 3940.78 | J17: 5033.674 | K17: 5917.559 | L17: 10178.502 | M17: 18553.981 | N17: 39861 | O17: 47807 | P17: 76416 | Q17: 110329 | R17: 33235 | S17: 43502 | T17: 52735 | U17: =BG17+BF17+BH17+BI17 -> 49290 | Y17: 798.689 | Z17: =1676.912-Y17 -> 878.223 | AA17: =2660.983-Z17-Y17 -> 984.071 | AB17: =I17-AA17-Z17-Y17 -> 1279.797 | AC17: 989.857 | AD17: =2277.998-AC17 -> 1288.141 | AE17: =3513.38-AD17-AC17 -> 1235.382 | AF17: =J17-AE17-AD17-AC17 -> 1520.294 | AG17: 1209.477 | AH17: =2796.337-AG17 -> 1586.86 | AI17: =4088.696-AH17-AG17 -> 1292.359 | AJ17: =K17-AI17-AH17-AG17 -> 1828.863 | AK17: 1562.445 | AL17: =2962.411-AK17 -> 1399.966 | AM17: =5937.128-AL17-AK17 -> 2974.717 | AN17: =L17-AM17-AL17-AK17 -> 4241.374 | AO17: 3056.525 | AP17: =6390.94-AO17 -> 3334.415 | AQ17: =10260.536-AP17-AO17 -> 3869.596 | AR17: =M17-AQ17-AP17-AO17 -> 8293.445 | AS17: 6035.239 | AT17: =14219.273-AS17 -> 8184.034 | AU17: =24028.789-AT17-AS17 -> 9809.516 | AV17: =N17-AU17-AT17-AS17 -> 15832.211 | AW17: 16813 | AX17: 31348 | AY17: =91282-AX17-AW17 -> 43121 | AZ17: =Q17-AY17-AX17-AW17 -> 19047 | BA17: 14664 | BB17: 7526 | BC17: =32944-BB17-BA17 -> 10754 | BD17: =R17-BC17-BB17-BA17 -> 291 | BE17: 6480 | BF17: 15872 | BG17: 9837 | BH17: =T17-BG17-BF17-BE17 -> 20546 | BI17: 3035 | BK17: 43912 | BL17: 34284 | BN17: 20252 | BO17: 10164 | BP17: 11469 | BQ17: =S17-BN17-BO17-BP17 -> 1617 | BR17: 8480 | BS17: 1071 | BT17: =G17-BS17 -> 1458 | BU17: 1370 | BV17: =H17-BU17 -> 1545.291 | BW17: 2962.411 | BX17: =L17-BW17 -> 7216.091 | BY17: =6390.94 -> 6390.94 | BZ17: =M17-BY17 -> 12163.041 | CA17: 14219.273 | CB17: =N17-CA17 -> 25641.727 | CC17: 33543 | CD17: =P17-CC17 -> 42873 | CE17: 23423 | CF17: =R17-CE17 -> 9812 | CG17: 22741 | CI17: 49574 | CJ17: =Q17-CI17 -> 60755 | CK17: 31633
B18: Consumer durables | D18: 743 | E18: 1157 | F18: 954 | G18: 1292 | H18: 1571.926 | I18: 1784.994 | J18: 2791.546 | K18: 2759.185 | L18: 5047.164 | M18: 7131.123 | N18: 9789 | O18: 11071 | P18: 12175 | Q18: 17578 | R18: 10098 | S18: 13217 | T18: 13113 | U18: =BG18+BF18+BH18+BI18 -> 11095 | Y18: 435.89 | Z18: =807.479-Y18 -> 371.589 | AA18: =1329.221-Z18-Y18 -> 521.742 | AB18: =I18-AA18-Z18-Y18 -> 455.773 | AC18: 522.334 | AD18: =1203.676-AC18 -> 681.342 | AE18: =2640.988-AD18-AC18 -> 1437.312 | AF18: =J18-AE18-AD18-AC18 -> 150.558 | AG18: 663.147 | AH18: =1370.553-AG18 -> 707.406 | AI18: =2139.414-AH18-AG18 -> 768.861 | AJ18: =K18-AI18-AH18-AG18 -> 619.771 | AK18: 791.701 | AL18: =1610.986-AK18 -> 819.285 | AM18: =3610.968-AL18-AK18 -> 1999.982 | AN18: =L18-AM18-AL18-AK18 -> 1436.196 | AO18: 1709.324 | AP18: =2816.317-AO18 -> 1106.993 | AQ18: =4107.18-AP18-AO18 -> 1290.863 | AR18: =M18-AQ18-AP18-AO18 -> 3023.943 | AS18: 2875.79 | AT18: =5005.57-AS18 -> 2129.78 | AU18: =7089.788-AT18-AS18 -> 2084.218 | AV18: =N18-AU18-AT18-AS18 -> 2699.212 | AW18: 2110 | AX18: 6504 | AY18: =12158-AX18-AW18 -> 3544 | AZ18: =Q18-AY18-AX18-AW18 -> 5420 | BA18: 3388 | BB18: 730 | BC18: =3646-BB18-BA18 -> -472 | BD18: =R18-BC18-BB18-BA18 -> 6452 | BE18: 2610 | BF18: 3895 | BG18: 3100 | BH18: =T18-BG18-BF18-BE18 -> 3508 | BI18: 592 | BK18: 26214 | BL18: 10262 | BN18: 4679 | BO18: 20847 | BP18: -1530 | BQ18: =S18-BN18-BO18-BP18 -> -10779 | BR18: 3416 | BS18: 470 | BT18: =G18-BS18 -> 822 | BU18: 681 | BV18: =H18-BU18 -> 890.926 | BW18: 1610.986 | BX18: =L18-BW18 -> 3436.178 | BY18: =2816.317 -> 2816.317 | BZ18: =M18-BY18 -> 4314.806 | CA18: 5005.57 | CB18: =N18-CA18 -> 4783.43 | CC18: 6728 | CD18: =P18-CC18 -> 5447 | CE18: 4403 | CF18: =R18-CE18 -> 5695 | CG18: 6662 | CI18: 8791 | CJ18: =Q18-CI18 -> 8787 | CK18: 25807
B19: Finance | D19: 2825 | E19: 3313 | F19: 3044 | G19: 3382 | H19: 3984.558 | I19: 4236.005 | J19: 6038.627 | K19: 4575.856 | L19: 6269.404 | M19: 13487.672 | N19: 69108 | O19: 125026 | P19: 95956 | Q19: 138540 | R19: 19228 | S19: 25168 | T19: 37862 | U19: =BG19+BF19+BH19+BI19 -> 49935 | Y19: 1171.935 | Z19: =2249.02-Y19 -> 1077.085 | AA19: =3408.338-Z19-Y19 -> 1159.318 | AB19: =I19-AA19-Z19-Y19 -> 827.667 | AC19: 1618.949 | AD19: =3167.2-AC19 -> 1548.251 | AE19: =4577.795-AD19-AC19 -> 1410.595 | AF19: =J19-AE19-AD19-AC19 -> 1460.832 | AG19: 1584.131 | AH19: =2888.95-AG19 -> 1304.819 | AI19: =4112.097-AH19-AG19 -> 1223.147 | AJ19: =K19-AI19-AH19-AG19 -> 463.759 | AK19: 1674.497 | AL19: =3044.416-AK19 -> 1369.919 | AM19: =5146.49-AL19-AK19 -> 2102.074 | AN19: =L19-AM19-AL19-AK19 -> 1122.914 | AO19: 1649.76 | AP19: =4378.401-AO19 -> 2728.641 | AQ19: =8626.036-AP19-AO19 -> 4247.635 | AR19: =M19-AQ19-AP19-AO19 -> 4861.636 | AS19: 9496.257 | AT19: =24237.42-AS19 -> 14741.163 | AU19: =45782.457-AT19-AS19 -> 21545.037 | AV19: =N19-AU19-AT19-AS19 -> 23325.543 | AW19: 26217 | AX19: 24868 | AY19: =106531-AX19-AW19 -> 55446 | AZ19: =Q19-AY19-AX19-AW19 -> 32009 | BA19: 11699 | BB19: 6786 | BC19: =17242-BB19-BA19 -> -1243 | BD19: =R19-BC19-BB19-BA19 -> 1986 | BE19: 8923 | BF19: 8000 | BG19: 6293 | BH19: =T19-BG19-BF19-BE19 -> 14646 | BI19: 20996 | BK19: 22983 | BL19: 25062 | BN19: 16157 | BO19: 9163 | BP19: -5281 | BQ19: =S19-BN19-BO19-BP19 -> 5129 | BR19: 11677 | BS19: 1463 | BT19: =G19-BS19 -> 1919 | BU19: 2157 | BV19: =H19-BU19 -> 1827.558 | BW19: 3044.416 | BX19: =L19-BW19 -> 3224.988 | BY19: =4378.401 -> 4378.401 | BZ19: =M19-BY19 -> 9109.271 | CA19: 24237.42 | CB19: =N19-CA19 -> 44870.58 | CC19: 30836 | CD19: =P19-CC19 -> 65120 | CE19: 19468 | CF19: =R19-CE19 -> -240 | CG19: 17459 | CI19: 53289 | CJ19: =Q19-CI19 -> 85251 | CK19: 26291
B20: Other | D20: 138 | E20: 131 | F20: 80 | G20: 207 | H20: 70.063 | I20: 185.121 | J20: 73.931 | K20: 390.828 | L20: 511.901 | M20: 723.378 | N20: 2056 | O20: -565 | P20: -864 | Q20: -1247 | R20: -256 | S20: -333 | T20: -1010 | U20: =BG20+BF20+BH20+BI20 -> -4131 | Y20: -18.943 | Z20: =39.073-Y20 -> 58.016 | AA20: =107.522-Z20-Y20 -> 68.449 | AB20: =I20-AA20-Z20-Y20 -> 77.599 | AC20: -57.355 | AD20: =-44.972-AC20 -> 12.383 | AE20: =-54.408-AD20-AC20 -> -9.436 | AF20: =J20-AE20-AD20-AC20 -> 128.339 | AG20: -124.809 | AH20: =-36.135-AG20 -> 88.674 | AI20: =99.751-AH20-AG20 -> 135.886 | AJ20: =K20-AI20-AH20-AG20 -> 291.077 | AK20: 41.935 | AL20: =56.213-AK20 -> 14.278 | AM20: =155.275-AL20-AK20 -> 99.062 | AN20: =L20-AM20-AL20-AK20 -> 356.626 | AO20: -55.917 | AP20: =48.091-AO20 -> 104.008 | AQ20: =283.327-AP20-AO20 -> 235.236 | AR20: =M20-AQ20-AP20-AO20 -> 440.051 | AS20: -45.155 | AT20: =415.158-AS20 -> 460.313 | AU20: =1098.523-AT20-AS20 -> 683.365 | AV20: =N20-AU20-AT20-AS20 -> 957.477 | AW20: -777 | AX20: -16 | AY20: =-84-AX20-AW20 -> 709 | AZ20: =Q20-AY20-AX20-AW20 -> -1163 | BA20: -824 | BB20: -576 | BC20: =-1632-BB20-BA20 -> -232 | BD20: =R20-BC20-BB20-BA20 -> 1376 | BE20: -1001 | BF20: 248 | BG20: -213 | BH20: =T20-BG20-BF20-BE20 -> -44 | BI20: -4122 | BK20: -2175 | BL20: -1087 | BN20: -1138 | BO20: -778 | BP20: -42 | BQ20: =S20-BN20-BO20-BP20 -> 1625 | BR20: -1310 | BS20: -32 | BT20: =G20-BS20 -> 239 | BU20: 63 | BV20: =H20-BU20 -> 7.063 | BW20: 56.213 | BX20: =L20-BW20 -> 455.688 | BY20: =48.091 -> 48.091 | BZ20: =M20-BY20 -> 675.287 | CA20: 415.158 | CB20: =N20-CA20 -> 1640.842 | CC20: 657 | CD20: =P20-CC20 -> -1521 | CE20: -1469 | CF20: =R20-CE20 -> 1213 | CG20: -813 | CI20: -858 | CJ20: =Q20-CI20 -> -389 | CK20: -1984
B21: Total combined operating profit | D21: =SUM(D16:D20) -> 7029 | E21: =SUM(E16:E20) -> 6759 | F21: =SUM(F16:F20) -> 6314 | G21: =SUM(G16:G20) -> 10687 | H21: =SUM(H16:H20) -> 11935.387 | I21: =SUM(I16:I20) -> 16195.795 | J21: =SUM(J16:J20) -> 21007.086 | K21: =SUM(K16:K20) -> 17485.916 | ... U21: =SUM(U16:U20) -> 164379 | Y21: =SUM(Y16:Y20) -> 3964.041 | Z21: =SUM(Z16:Z20) -> 4136.66 | AA21: =SUM(AA16:AA20) -> 4420.14 | AB21: =SUM(AB16:AB20) -> 3674.954 | AC21: =SUM(AC16:AC20) -> 3990.793 | AD21: =SUM(AD16:AD20) -> 5099.726 | AE21: =SUM(AE16:AE20) -> 5430.26 | AF21: =SUM(AF16:AF20) -> 6486.307 | ... BI21: =SUM(BI16:BI20) -> 34048 | BK21: =SUM(BK16:BK20) -> 130530 | BL21: =SUM(BL16:BL20) -> 105650 | BN21: =SUM(BN16:BN20) -> 45478 | BO21: =SUM(BO16:BO20) -> 53205 | BP21: =SUM(BP16:BP20) -> 22952 | BQ21: =SUM(BQ16:BQ20) -> 10479 | BR21: =SUM(BR16:BR20) -> 28613 | BS21: =SUM(BS16:BS20) -> 4475 | BT21: =SUM(BT16:BT20) -> 6212 | BU21: =SUM(BU16:BU20) -> 5396 | ... CG21: =SUM(CG16:CG20) -> 63295 | CI21: =SUM(CI16:CI20) -> 141500 | CJ21: =SUM(CJ16:CJ20) -> 232586 | CK21: =SUM(CK16:CK20) -> 101416
B23: Combined operating profit % margin by segment:
B24: Energy | D24: =+D16/D8 -> 0.026476868 | E24: =+E16/E8 -> 0.0069204681 | F24: =+F16/F8 -> 0.0090426232 | G24: =+G16/G8 -> 0.052518551 | H24: =+H16/H8 -> 0.050444088 | I24: =+I16/I8 -> 0.061992824 | J24: =+J16/J8 -> 0.046129242 | K24: =+K16/K8 -> 0.025044509 | ... U24: =+U16/U8 -> 0.037327339 | Y24: =+Y16/Y8 -> 0.072625793 | Z24: =+Z16/Z8 -> 0.075965983 | AA24: =+AA16/AA8 -> 0.06430685 | AB24: =+AB16/AB8 -> 0.038904426 | AC24: =+AC16/AC8 -> 0.035607497 | AD24: =+AD16/AD8 -> 0.043729004 | AE24: =+AE16/AE8 -> 0.027097173 | AF24: =+AF16/AF8 -> 0.077656333 | ... BI24: =+BI16/BI8 -> 0.033484604 | BK24: =+BK16/BK8 -> 0.031321489 | BL24: =+BL16/BL8 -> 0.036272568 | BN24: =+BN16/BN8 -> 0.015480691 | BO24: =+BO16/BO8 -> 0.035429041 | BP24: =+BP16/BP8 -> 0.043902159 | BQ24: =+BQ16/BQ8 -> 0.0244732 | BR24: =+BR16/BR8 -> 0.018331091 | BS24: =+BS16/BS8 -> 0.051047787 | BT24: =+BT16/BT8 -> 0.053832615 | BU24: =+BU16/BU8 -> 0.038798455 | ... CG24: =+CG16/CG8 -> 0.029295754 | CI24: =+CI16/CI8 -> 0.55109037 | CJ24: =+CJ16/CJ8 -> 0.053447545 | CK24: =+CK16/CK8 -> 0.02560051
B25: Automotive | D25: =+D17/D9 -> 0.074373083 | E25: =+E17/E9 -> 0.06789042 | F25: =+F17/F9 -> 0.060307876 | G25: =+G17/G9 -> 0.070508531 | H25: =+H17/H9 -> 0.068268078 | I25: =+I17/I9 -> 0.070932669 | J25: =+J17/J9 -> 0.076597269 | K25: =+K17/K9 -> 0.079486228 | ... U25: =+U17/U9 -> 0.031604744 | Y25: =+Y17/Y9 -> 0.065650947 | Z25: =+Z17/Z9 -> 0.063774119 | AA25: =+AA17/AA9 -> 0.079479624 | AB25: =+AB17/AB9 -> 0.074239858 | AC25: =+AC17/AC9 -> 0.068262719 | AD25: =+AD17/AD9 -> 0.078172984 | AE25: =+AE17/AE9 -> 0.080344557 | AF25: =+AF17/AF9 -> 0.078522428 | ... BI25: =+BI17/BI9 -> 0.008634473 | BK25: =+BK17/BK9 -> 0.049312786 | BL25: =+BL17/BL9 -> 0.035611637 | BN25: =+BN17/BN9 -> 0.069498493 | BO25: =+BO17/BO9 -> 0.041251339 | BP25: =+BP17/BP9 -> 0.03907533 | BQ25: =+BQ17/BQ9 -> 0.0036716038 | BR25: =+BR17/BR9 -> 0.027352192 | BS25: =+BS17/BS9 -> 0.065879314 | BT25: =+BT17/BT9 -> 0.07434603 | BU25: =+BU17/BU9 -> 0.0687751 | ... CG25: =+CG17/CG9 -> 0.039467473 | CI25: =+CI17/CI9 -> 0.11137547 | CJ25: =+CJ17/CJ9 -> 0.097676378 | CK25: =+CK17/CK9 -> 0.056965707
B26: Consumer durables | D26: =+D18/D10 -> 0.066374844 | E26: =+E18/E10 -> 0.098001016 | F26: =+F18/F10 -> 0.073719187 | G26: =+G18/G10 -> 0.088185107 | H26: =+H18/H10 -> 0.087342954 | I26: =+I18/I10 -> 0.076409536 | J26: =+J18/J10 -> 0.092300234 | K26: =+K18/K10 -> 0.075988075 | ... U26: =+U18/U10 -> 0.018017682 | Y26: =+Y18/Y10 -> 0.085708477 | Z26: =+Z18/Z10 -> 0.063906388 | AA26: =+AA18/AA10 -> 0.085060228 | AB26: =+AB18/AB10 -> 0.072038767 | AC26: =+AC18/AC10 -> 0.084602463 | AD26: =+AD18/AD10 -> 0.090114805 | AE26: =+AE18/AE10 -> 0.1712924 | AF26: =+AF18/AF10 -> 0.018545271 | ... BI26: =+BI18/BI10 -> 0.0041276792 | BK26: =+BK18/BK10 -> 0.057165163 | BL26: =+BL18/BL10 -> 0.023563828 | BN26: =+BN18/BN10 -> 0.039172513 | BO26: =+BO18/BO10 -> 0.13614456 | BP26: =+BP18/BP10 -> -0.009694036 | BQ26: =+BQ18/BQ10 -> -0.05258921 | BR26: =+BR18/BR10 -> 0.020791995 | BS26: =+BS18/BS10 -> 0.072196621 | BT26: =+BT18/BT10 -> 0.1009704 | BU26: =+BU18/BU10 -> 0.080830861 | ... CG26: =+CG18/CG10 -> 0.024307304 | CI26: =+CI18/CI10 -> 0.048050592 | CJ26: =+CJ18/CJ10 -> 0.035701226 | CK26: =+CK18/CK10 -> 0.092251872
B27: Finance | D27: =+D19/D11 -> 0.21755872 | E27: =+E19/E11 -> 0.23948243 | F27: =+F19/F11 -> 0.18078157 | G27: =+G19/G11 -> 0.15719996 | H27: =+H19/H11 -> 0.16440803 | I27: =+I19/I11 -> 0.14262751 | J27: =+J19/J11 -> 0.13969512 | K27: =+K19/K11 -> 0.095642081 | ... U27: =+U19/U11 -> 0.050847406 | Y27: =+Y19/Y11 -> 0.17134755 | Z27: =+Z19/Z11 -> 0.14842495 | AA27: =+AA19/AA11 -> 0.15564119 | AB27: =+AB19/AB11 -> 0.10149405 | AC27: =+AC19/AC11 -> 0.19260917 | AD27: =+AD19/AD11 -> 0.16366404 | AE27: =+AE19/AE11 -> 0.11231884 | AF27: =+AF19/AF11 -> 0.11410032 | ... BI27: =+BI19/BI11 -> 0.085394373 | BK27: =+BK19/BK11 -> 0.034255232 | BL27: =+BL19/BL11 -> 0.038194894 | BN27: =+BN19/BN11 -> 0.083935956 | BO27: =+BO19/BO11 -> 0.043438481 | BP27: =+BP19/BP11 -> -0.023492411 | BQ27: =+BQ19/BQ11 -> 0.017001684 | BR27: =+BR19/BR11 -> 0.04756183 | BS27: =+BS19/BS11 -> 0.14669608 | BT27: =+BT19/BT11 -> 0.16627675 | BU27: =+BU19/BU11 -> 0.17985492 | ... CG27: =+CG19/CG11 -> 0.043617513 | CI27: =+CI19/CI11 -> 0.24889422 | CJ27: =+CJ19/CJ11 -> 0.24573748 | CK27: =+CK19/CK11 -> 0.063352265
B28: Other | D28: =+D20/D12 -> 0.019691781 | E28: =+E20/E12 -> 0.018031659 | F28: =+F20/F12 -> 0.0093962885 | G28: =+G20/G12 -> 0.020951417 | H28: =+H20/H12 -> 0.007312313 | I28: =+I20/I12 -> 0.016665576 | J28: =+J20/J12 -> 0.0053428757 | K28: =+K20/K12 -> 0.022970702 | ... U28: =+U20/U12 -> -0.0179321 | Y28: =+Y20/Y12 -> -0.007981804 | Z28: =+Z20/Z12 -> 0.021615942 | AA28: =+AA20/AA12 -> 0.024079733 | AB28: =+AB20/AB12 -> 0.024187925 | AC28: =+AC20/AC12 -> -0.021683597 | AD28: =+AD20/AD12 -> 0.0038248353 | AE28: =+AE20/AE12 -> -0.0025694047 | AF28: =+AF20/AF12 -> 0.029970013 | ... BI28: =+BI20/BI12 -> -0.078171819 | BK28: =+BK20/BK12 -> -0.014561742 | BL28: =+BL20/BL12 -> -0.0071588043 | BN28: =+BN20/BN12 -> -0.027428957 | BO28: =+BO20/BO12 -> -0.01604951 | BP28: =+BP20/BP12 -> -0.0008405043 | BQ28: =+BQ20/BQ12 -> 0.020894409 | BR28: =+BR20/BR12 -> -0.024956659 | BS28: =+BS20/BS12 -> -0.0069294067 | BT28: =+BT20/BT12 -> 0.045419992 | BU28: =+BU20/BU12 -> 0.01364818 | ... CG28: =+CG20/CG12 -> -0.008835708 | CI28: =+CI20/CI12 -> -0.013258542 | CJ28: =+CJ20/CJ12 -> -0.0037485666 | CK28: =+CK20/CK12 -> -0.021458856
B29: Total combined operating profit | D29: =+D21/D13 -> 0.060291292 | E29: =+E21/E13 -> 0.054738939 | F29: =+F21/F13 -> 0.047308283 | G29: =+G21/G13 -> 0.074055852 | H29: =+H21/H13 -> 0.073770167 | I29: =+I21/I13 -> 0.07453217 | J29: =+J21/J13 -> 0.068589007 | K29: =+K21/K13 -> 0.053141822 | ... U29: =+U21/U13 -> 0.033230059 | Y29: =+Y21/Y13 -> 0.082291092 | Z29: =+Z21/Z13 -> 0.078665032 | AA29: =+AA21/AA13 -> 0.080317654 | AB29: =+AB21/AB13 -> 0.059746177 | AC29: =+AC21/AC13 -> 0.069431237 | AD29: =+AD21/AD13 -> 0.070214789 | AE29: =+AE21/AE13 -> 0.060299059 | AF29: =+AF21/AF13 -> 0.075325271 | ... BI29: =+BI21/BI13 -> 0.028418448 | BK29: =+BK21/BK13 -> 0.038016346 | BL29: =+BL21/BL13 -> 0.0327107 | BN29: =+BN21/BN13 -> 0.045390895 | BO29: =+BO21/BO13 -> 0.050734339 | BP29: =+BP21/BP13 -> 0.020067129 | BQ29: =+BQ21/BQ13 -> 0.0067545573 | BR29: =+BR21/BR13 -> 0.025576255 | BS29: =+BS21/BS13 -> 0.066990015 | BT29: =+BT21/BT13 -> 0.080145531 | BU29: =+BU21/BU13 -> 0.072968222 | ... CG29: =+CG21/CG13 -> 0.032774212 | CI29: =+CI21/CI13 -> 0.14699909 | CJ29: =+CJ21/CJ13 -> 0.083615874 | CK29: =+CK21/CK13 -> 0.048046193
B31: Consolidated revenues | D31: 65666 | E31: 66182 | F31: 68622 | G31: 69491 | H31: 70432.243 | I31: 98866.749 | J31: 143248.31 | K31: 153516.01 | L31: 183777.28 | M31: 346688.7 | N31: 901857 | O31: 1715942 | P31: 1604647 | Q31: 2316773 | R31: 2317907 | S31: 3033955 | T31: 2757295 | U31: =BG31+BF31+BH31+BI31 -> 2957018 | Y31: 22274.111 | Z31: 23059.286 | AA31: 25874.941 | AB31: =I31-AA31-Z31-Y31 -> 27658.411 | AC31: 24587.937 | AD31: 33272.37 | AE31: 45553.375 | AF31: =J31-AE31-AD31-AC31 -> 39834.626 | AG31: 34261.702 | AH31: 40487.809 | AI31: 39364.507 | AJ31: =K31-AI31-AH31-AG31 -> 39401.989 | AK31: 39435.731 | AL31: 34530.996 | AM31: 51753.061 | AN31: =L31-AM31-AL31-AK31 -> 58057.488 | AO31: 57304.999 | AP31: 74654.636 | AQ31: 91650.156 | AR31: =M31-AQ31-AP31-AO31 -> 123078.91 | AS31: 152105.05 | AT31: 233773.06 | AU31: 260994.13 | AV31: =N31-AU31-AT31-AS31 -> 254984.76 | AW31: 386677 | AX31: 467136 | AY31: 628852 | AZ31: =Q31-AY31-AX31-AW31 -> 834108 | BA31: 450415 | BB31: 521453 | BC31: 560733 | BD31: =R31-BC31-BB31-BA31 -> 785306 | BE31: 538320 | BF31: 606756 | BG31: 688860 | BH31: =T31-BG31-BF31-BE31 -> 923359 | BI31: 738043 | BK31: 2213367 | BL31: 1954626 | BN31: 622041 | BO31: 704216 | BP31: 747418 | BQ31: =S31-BN31-BO31-BP31 -> 960280 | BR31: 704473 | BS31: 32128 | BT31: =G31-BS31 -> 37363 | BU31: 31122 | BV31: =H31-BU31 -> 39310.243 | BW31: 73966.727 | BX31: =L31-BW31 -> 109810.55 | BY31: 131959.64 | BZ31: =M31-BY31 -> 214729.07 | CA31: 385878.11 | CB31: =N31-CA31 -> 515978.89 | CC31: 490302 | CD31: =P31-CC31 -> 1114345 | CE31: 1009725 | CF31: =R31-CE31 -> 1308182 | CG31: 1177413 | CI31: 886314 | CJ31: =Q31-CI31 -> 1430459 | CK31: 1363623
B32: % growth | E32: =+E31/D31-1 -> 0.0078579478 | F32: =+F31/E31-1 -> 0.036868031 | G32: =+G31/F31-1 -> 0.012663577 | H32: =+H31/G31-1 -> 0.013544819 | I32: =+I31/H31-1 -> 0.40371433 | J32: =+J31/I31-1 -> 0.44890279 | K32: =+K31/J31-1 -> 0.071677628 | L32: =+L31/K31-1 -> 0.19712126 | ... N32: =+N31/M31-1 -> 1.6013452 | O32: =+O31/M31-1 -> 3.9495181 | P32: =+P31/O31-1 -> -0.064859418 | Q32: =+Q31/O31-1 -> 0.35014645 | R32: =+R31/P31-1 -> 0.44449652 | S32: =+S31/Q31-1 -> 0.30956076 | T32: =+T31/S31-1 -> -0.091187905 | V32: =+V31/G31-1 -> -1 | W32: =+W31/V31-1 -> #DIV/0! | AC32: =+AC31/Y31-1 -> 0.10387961 | AD32: =+AD31/Z31-1 -> 0.44290547 | AE32: =+AE31/AA31-1 -> 0.76052092 | AF32: =+AF31/AB31-1 -> 0.44023552 | AG32: =+AG31/AC31-1 -> 0.39343541 | AH32: =+AH31/AD31-1 -> 0.21685978 | AI32: =+AI31/AE31-1 -> -0.1358597 | AJ32: =+AJ31/AF31-1 -> -0.010860827 | ... BD32: =+BD31/AZ31-1 -> -0.058508011 | BE32: =+BE31/BN31-1 -> -0.13459081 | BF32: =+BF31/BB31-1 -> 0.16358713 | BG32: =+BG31/BC31-1 -> 0.22849913 | BH32: =+BH31/BD31-1 -> 0.17579517 | BI32: =+BI31/BR31-1 -> 0.047652642 | BL32: =BL31/BK31-1 -> -0.11689928 | BN32: =+BN31/AW31-1 -> 0.60868373 | BO32: =+BO31/AX31-1 -> 0.50751815 | BP32: =+BP31/AY31-1 -> 0.18854357 | BQ32: =+BQ31/AZ31-1 -> 0.15126578 | BR32: =+BR31/BA31-1 -> 0.56405315 | BU32: =+BU31/BS31-1 -> -0.031312251 | BV32: =+BV31/BT31-1 -> 0.05211688 | BY32: =+BY31/BW31-1 -> 0.78404048 | CA32: =+CA31/BY31-1 -> 1.9242132 | CC32: =+CC31/CA31-1 -> 0.27061367 | CD32: =+CD31/CB31-1 -> 1.1596717 | CE32: =+CE31/CC31-1 -> 1.059394 | CF32: =+CF31/CJ31-1 -> -0.085480954 | CG32: =+CG31/CE31-1 -> 0.16607294 | CI32: =+CI31/CE31-1 -> -0.12222239 | CJ32: =+CJ31/CB31-1 -> 1.7723208 | CK32: =+CK31/CI31-1 -> 0.53853262
B33: Consolidated operating profit | D33: 3811 | E33: 3727 | F33: 3329 | G33: 6677 | H33: 6948.742 | I33: 10426.63 | J33: 12963.431 | K33: 10373.674 | L33: 16831.917 | M33: 34674.985 | N33: 149346 | O33: 240746 | P33: 222656 | Q33: 321467 | R33: 87366 | S33: 114356 | T33: 117608 | U33: =BG33+BF33+BH33+BI33 -> 130556 | Y33: 2604.591 | Z33: 2711.758 | AA33: 2842.224 | AB33: =I33-AA33-Z33-Y33 -> 2268.057 | AC33: 2132.406 | AD33: 2861.476 | AE33: 3439.073 | AF33: =J33-AE33-AD33-AC33 -> 4530.476 | AG33: 1944.846 | AH33: 3450.31 | AI33: 2893.682 | AJ33: =K33-AI33-AH33-AG33 -> 2084.836 | AK33: 1060.524 | AL33: 3532.662 | AM33: 6419.996 | AN33: =L33-AM33-AL33-AK33 -> 5818.735 | AO33: 5173.743 | AP33: 8181.422 | AQ33: 11021.515 | AR33: =M33-AQ33-AP33-AO33 -> 10298.305 | AS33: 19335.686 | AT33: 34279.746 | AU33: 43946.037 | AV33: =N33-AU33-AT33-AS33 -> 51784.531 | AW33: 52455 | AX33: 59902 | AY33: 110545 | AZ33: =Q33-AY33-AX33-AW33 -> 98565 | BA33: 26574 | BB33: 21477 | BC33: 12188 | BD33: =R33-BC33-BB33-BA33 -> 27127 | BE33: 17485 | BF33: 28190 | BG33: 30879 | BH33: =T33-BG33-BF33-BE33 -> 41054 | BI33: 30433 | BK33: 110599 | BL33: 81111 | BN33: 36698 | BO33: 50099 | BP33: 16245 | BQ33: =S33-BN33-BO33-BP33 -> 11314 | BR33: 22883 | BS33: 2490 | BT33: =G33-BS33 -> 4187 | BU33: 2755 | BV33: =H33-BU33 -> 4193.742 | BW33: 4593.186 | BX33: =L33-BW33 -> 12238.731 | BY33: 13355.165 | BZ33: =M33-BY33 -> 21319.82 | CA33: 53615.432 | CB33: =N33-CA33 -> 95730.568 | CC33: 75796 | CD33: =P33-CC33 -> 146860 | CE33: 50284 | CF33: =R33-CE33 -> 37082 | CG33: 46726 | CI33: 116767 | CJ33: =Q33-CI33 -> 204700 | CK33: 87769
B34: % margin | D34: =+D33/D31 -> 0.058036122 | E34: =+E33/E31 -> 0.056314406 | F34: =+F33/F31 -> 0.048512139 | G34: =+G33/G31 -> 0.096084385 | H34: =+H33/H31 -> 0.098658536 | I34: =+I33/I31 -> 0.10546144 | J34: =+J33/J31 -> 0.090496224 | K34: =+K33/K31 -> 0.067573891 | ... W34: =+W33/W31 -> #DIV/0! | Y34: =+Y33/Y31 -> 0.11693356 | Z34: =+Z33/Z31 -> 0.11759939 | AA34: =+AA33/AA31 -> 0.10984466 | AB34: =+AB33/AB31 -> 0.082002433 | AC34: =+AC33/AC31 -> 0.086725698 | AD34: =+AD33/AD31 -> 0.086001568 | AE34: =+AE33/AE31 -> 0.07549546 | AF34: =+AF33/AF31 -> 0.11373211 | ... BI34: =+BI33/BI31 -> 0.041234725 | BL34: =BL33/BK33-1 -> -0.26662086 | BN34: =+BN33/BN31 -> 0.058996111 | BO34: =+BO33/BO31 -> 0.071141525 | BP34: =+BP33/BP31 -> 0.021734826 | BQ34: =+BQ33/BQ31 -> 0.01178198 | BR34: =+BR33/BR31 -> 0.032482437 | BS34: =+BS33/BS31 -> 0.07750249 | BT34: =+BT33/BT31 -> 0.11206274 | BU34: =+BU33/BU31 -> 0.088522589 | ... CG34: =+CG33/CG31 -> 0.03968531 | CI34: =+CI33/CI31 -> 0.13174451 | CJ34: =+CJ33/CJ31 -> 0.14310092 | CK34: =+CK33/CK31 -> 0.064364564
B35: Depreciation and amortisation | H35: 1428.311 | I35: 1579.49 | J35: 2113.296 | K35: 2765.255 | L35: 4063.559 | M35: 5285.513 | N35: 8260 | O35: 25457 | P35: 30612 | Q35: 44197 | R35: 58268 | S35: 76268 | T35: 74392 | U35: =BG35+BF35+BH35+BI35 -> 79278 | Y35: 378.934 | Z35: =769.774-Y35 -> 390.84 | AA35: =1164.154-Z35-Y35 -> 394.38 | AB35: =I35-AA35-Z35-Y35 -> 415.336 | AC35: 446.431 | AD35: =962.39-AC35 -> 515.959 | AE35: =1540.756-AD35-AC35 -> 578.366 | AF35: =J35-AE35-AD35-AC35 -> 572.54 | AG35: 643.715 | AH35: =1331.263-AG35 -> 687.548 | AI35: =2049.401-AH35-AG35 -> 718.138 | AJ35: =K35-AI35-AH35-AG35 -> 715.854 | AK35: 895.994 | AL35: 1016.824 | AM35: 1068.361 | AN35: =L35-AM35-AL35-AK35 -> 1082.38 | AO35: 1129.65 | AP35: 1210.899 | AQ35: 1349.258 | AR35: =M35-AQ35-AP35-AO35 -> 1595.706 | AS35: 1780.528 | AT35: 1940.226 | AU35: 2184.199 | AV35: =N35-AU35-AT35-AS35 -> 2355.047 | AW35: 13446 | AX35: 12913 | AY35: 3346 | AZ35: =Q35-AY35-AX35-AW35 -> 14492 | BA35: 13106 | BB35: 18966 | BC35: 18387 | BD35: =R35-BC35-BB35-BA35 -> 7809 | BE35: 15193 | BF35: 16665 | BG35: 18745 | BH35: =T35-BG35-BF35-BE35 -> 23789 | BI35: 20079 | BK35: 49606 | BL35: 53974 | BN35: 11858 | BO35: 17414 | BP35: 17370 | BQ35: =S35-BN35-BO35-BP35 -> 29626 | BR35: 19882 | BS35: 568.401 | BU35: 697.347 | BV35: =H35-BU35 -> 730.964 | BW35: 1912.818 | BX35: =L35-BW35 -> 2150.741 | BY35: 2340.549 | BZ35: =M35-BY35 -> 2944.964 | CA35: 3720.754 | CB35: =N35-CA35 -> 4539.246 | CC35: 5118 | CD35: =P35-CC35 -> 25494 | CE35: 33174 | CF35: =R35-CE35 -> 25094 | CG35: 32770 | CI35: 26963 | CJ35: =Q35-CI35 -> 17234 | CK35: 29985
B36: Other adjustments | H36: =-1807.742+1864.258-2235.378 -> -2178.862 | I36: =-2508.489+2239.369-2691.404 -> -2960.524 | J36: =7275.918-5637.086-3175.787 -> -1536.955 | K36: =4086.379-3626.01-2902.947 -> -2442.578 | L36: =12342.768-4878.475-2966.673 -> 4497.62 | M36: =30422.344-12314.28-5879.657 -> 12228.407 | N36: =36082-15045-12416 -> 8621 | O36: =73325-30260-16157 -> 26908 | P36: =64942-30720-38273 -> -4051 | Q36: =93764-55258-44353 -> -5847 | R36: =69329-57949-20615 -> -9235 | S36: =90746-75851-26983 -> -12088 | T36: =89403-52600-16441 -> 20362 | U36: =BG36+BF36+BH36+BI36 -> 24788 | Y36: =-747.773+701.997-615.381 -> -661.157 | Z36: =-327.401+146.521-685.8 -> -866.68 | AA36: =-413.466+326.706-685.424 -> -772.184 | AB36: =I36-AA36-Z36-Y36 -> -660.503 | AC36: =-616.567+570.02-795.066 -> -841.613 | AD36: =-1182.042+1859.496-920.138 -> -242.684 | AE36: =-2733.757+4771.926-712.894 -> 1325.275 | AF36: =J36-AE36-AD36-AC36 -> -1777.933 | AG36: =-924.618+1109.753-779.731 -> -594.596 | AH36: =-1030.045+905.51-794.367 -> -918.902 | AI36: =-952.255+985.474-733.016 -> -699.797 | AJ36: =K36-AI36-AH36-AG36 -> -229.283 | AK36: =-1194.826+2974.263-441.042 -> 1338.395 | AL36: =-968.469+2677.523-231.381 -> 1477.673 | AM36: =-1366.953+3853.362-958.54 -> 1527.869 | AN36: =L36-AM36-AL36-AK36 -> 153.683 | AO36: =-1907.956+4992.94-985.257 -> 2099.727 | AP36: =-1521.476+2347.805-953.147 -> -126.818 | AQ36: =-1700.121+2283.821-1364.086 -> -780.386 | AR36: =M36-AQ36-AP36-AO36 -> 11035.884 | AS36: =-3669.155+6850.833-1942.431 -> 1239.247 | AT36: =-4811.662+11524.462-2584.094 -> 4128.706 | AU36: =-3683.503+9843.317-2934.035 -> 3225.779 | AV36: =N36-AU36-AT36-AS36 -> 27.268 | AW36: =-4959+6962-5392 -> -3389 | AX36: =-20349+40453-8754 -> 11350 | AY36: =-11293+21324-11406 -> -1375 | AZ36: =Q36-AY36-AX36-AW36 -> -12433 | BA36: =-8355+15579-5381 -> 1843 | BB36: =-9285+7282-3668 -> -5671 | BC36: =-8966+14936-4585 -> 1385 | BD36: =R36-BC36-BB36-BA36 -> -6792 | BE36: =21671-12959-2394 -> 6318 | BF36: =18994-11708-3486 -> 3800 | BG36: =20765-9708-4239 -> 6818 | BH36: =T36-BG36-BF36-BE36 -> 3426 | BI36: =28954-15720-2490 -> 10744 | BK36: =-59934+55002-19905 -> -24837 | BL36: =-37062+65881-10715 -> 18104 | BN36: =21516-11539-7431 -> 2546 | BO36: =-9835+32401+4954 -> 27520 | BP36: =19909-11952-6111 -> 1846 | BQ36: =S36-BN36-BO36-BP36 -> -44000 | BR36: =28360-16959-3133 -> 8268 | BS36: =-988.769+1152.559-797.775 -> -633.985 | BU36: =-516.137+458.802-1143.482 -> -1200.817 | BV36: =H36-BU36 -> -978.045 | BW36: =-2163.295+5651.786-672.423 -> 2816.068 | BX36: =L36-BW36 -> 1681.552 | BY36: =-3429.432+7340.745-1938.404 -> 1972.909 | BZ36: =M36-BY36 -> 10255.498 | CA36: =-8480.817+18375.295-4526.525 -> 5367.953 | CB36: =N36-CA36 -> 3253.047 | CC36: =-14823+27193-9641 -> 2729 | CD36: =P36-CC36 -> -6780 | CE36: =-18342+24170-9501 -> -3673 | CF36: =R36-CE36 -> -5562 | CG36: =25445-41967+6024 -> -10498 | CI36: =-25725+48000-14599 -> 7676 | CJ36: =Q36-CI36 -> -13523 | CK36: =44633-32643+12831 -> 24821
B37: Consolidated EBITDA | D37: 4410 | E37: 4962 | F37: 4339 | G37: 8236 | H37: =+H33+H35+H36 -> 6198.191 | I37: =+I33+I35+I36 -> 9045.596 | J37: =+J33+J35+J36 -> 13539.772 | K37: =+K33+K35+K36 -> 10696.351 | L37: =+L33+L35+L36 -> 25393.096 | M37: =+M33+M35+M36 -> 52188.905 | N37: =+N33+N35+N36 -> 166227 | O37: =+O33+O35+O36 -> 293111 | ... U37: =+U33+U35+U36 -> 234622 | Y37: =+Y33+Y35+Y36 -> 2322.368 | Z37: =+Z33+Z35+Z36 -> 2235.918 | AA37: =+AA33+AA35+AA36 -> 2464.42 | AB37: =+AB33+AB35+AB36 -> 2022.89 | AC37: =+AC33+AC35+AC36 -> 1737.224 | AD37: =+AD33+AD35+AD36 -> 3134.751 | AE37: =+AE33+AE35+AE36 -> 5342.714 | AF37: =+AF33+AF35+AF36 -> 3325.083 | ... BI37: =+BI33+BI35+BI36 -> 61256 | BK37: =+BK33+BK35+BK36 -> 135368 | BL37: =+BL33+BL35+BL36 -> 153189 | BN37: =+BN33+BN35+BN36 -> 51102 | BO37: =+BO33+BO35+BO36 -> 95033 | BP37: =+BP33+BP35+BP36 -> 35461 | BQ37: =+BQ33+BQ35+BQ36 -> -3060 | BR37: =+BR33+BR35+BR36 -> 51033 | BS37: =+BS33+BS35+BS36 -> 2424.416 | BT37: =+BT33+BT35+BT36 -> 4187 | BU37: =+BU33+BU35+BU36 -> 2251.53 | ... CG37: =+CG33+CG35+CG36 -> 68998 | CI37: =+CI33+CI35+CI36 -> 151406 | CJ37: =+CJ33+CJ35+CJ36 -> 208411 | CK37: =+CK33+CK35+CK36 -> 142575
B38: % growth | E38: =+E37/D37-1 -> 0.12517007 | F38: =+F37/E37-1 -> -0.12555421 | G38: =+G37/F37-1 -> 0.89813321 | H38: =+H37/G37-1 -> -0.24742703 | I38: =+I37/H37-1 -> 0.45939291 | J38: =+J37/I37-1 -> 0.49683581 | K38: =+K37/J37-1 -> -0.21000509 | L38: =+L37/K37-1 -> 1.3739961 | ... N38: =+N37/M37-1 -> 2.1851023 | O38: =+O37/M37-1 -> 4.616347 | P38: =+P37/O37-1 -> -0.14975214 | Q38: =+Q37/O37-1 -> 0.22757931 | R38: =+R37/P37-1 -> -0.45268982 | S38: =+S37/Q37-1 -> -0.50381444 | T38: =+T37/S37-1 -> 0.18946319 | V38: =+V37/V31 -> #DIV/0! | W38: =+W37/W31 -> #DIV/0! | AC38: =+AC37/Y37-1 -> -0.25196007 | AD38: =+AD37/Z37-1 -> 0.4019973 | AE38: =+AE37/AA37-1 -> 1.1679397 | AF38: =+AF37/AB37-1 -> 0.64372902 | AG38: =+AG37/AC37-1 -> 0.14778808 | AH38: =+AH37/AD37-1 -> 0.026861783 | AI38: =+AI37/AE37-1 -> -0.45495435 | AJ38: =+AJ37/AF37-1 -> -0.22666382 | ... BD38: =+BD37/AZ37-1 -> -0.72030529 | BE38: =+BE37/BN37-1 -> -0.23689875 | BF38: =+BF37/BB37-1 -> 0.39925802 | BG38: =+BG37/BC37-1 -> 0.76602003 | BH38: =+BH37/BD37-1 -> 1.4257035 | BI38: =+BI37/BR37-1 -> 0.20032136 | BL38: =BL37/BK37-1 -> 0.13164854 | BN38: =+BN37/AW37-1 -> -0.18252496 | BO38: =+BO37/AX37-1 -> 0.12912731 | BP38: =+BP37/AY37-1 -> -0.68483593 | BQ38: =+BQ37/AZ37-1 -> -1.0304102 | BR38: =+BR37/BA37-1 -> 0.22902969 | BU38: =+BU37/BS37-1 -> -0.071310369 | BV38: =+BV37/BT37-1 -> -0.057401242 | BY38: =+BY37/BW37-1 -> 0.89535363 | CA38: =+CA37/BY37-1 -> 2.5488979 | CC38: =+CC37/CA37-1 -> 0.33393108 | CD38: =+CD37/CB37-1 -> 0.59939552 | CE38: =+CE37/CC37-1 -> -0.046124601 | CF38: =+CF37/CJ37-1 -> -0.72835407 | CG38: =+CG37/CE37-1 -> -0.13520085 | CI38: =+CI37/CE37-1 -> 0.897675 | CJ38: =+CJ37/CB37-1 -> 1.0131882 | CK38: =+CK37/CI37-1 -> -0.058326618
B39: % margin | D39: =+D37/D31 -> 0.067158042 | E39: =+E37/E31 -> 0.074975069 | F39: =+F37/F31 -> 0.063230451 | G39: =+G37/G31 -> 0.11851894 | H39: =+H37/H31 -> 0.088002181 | I39: =+I37/I31 -> 0.091492803 | J39: =+J37/J31 -> 0.094519595 | K39: =+K37/K31 -> 0.069675803 | ... U39: =+U37/U31 -> 0.079344123 | Y39: =+Y37/Y31 -> 0.10426311 | Z39: =+Z37/Z31 -> 0.096963887 | AA39: =+AA37/AA31 -> 0.095243502 | AB39: =+AB37/AB31 -> 0.07313833 | AC39: =+AC37/AC31 -> 0.070653508 | AD39: =+AD37/AD31 -> 0.09421484 | AE39: =+AE37/AE31 -> 0.1172847 | AF39: =+AF37/AF31 -> 0.083472178 | ... BI39: =+BI37/BI31 -> 0.082997874 | BL39: =+BL37/BL31 -> 0.078372538 | BN39: =+BN37/BN31 -> 0.082152141 | BO39: =+BO37/BO31 -> 0.13494865 | BP39: =+BP37/BP31 -> 0.04744467 | BQ39: =+BQ37/BQ31 -> -0.0031865706 | BR39: =+BR37/BR31 -> 0.072441385 | BS39: =+BS37/BS31 -> 0.075461155 | BT39: =+BT37/BT31 -> 0.11206274 | BU39: =+BU37/BU31 -> 0.072345286 | ... CG39: =+CG37/CG31 -> 0.058601357 | CI39: =+CI37/CI31 -> 0.17082659 | CJ39: =+CJ37/CJ31 -> 0.14569519 | CK39: =+CK37/CK31 -> 0.10455602
B40: Consolidated net profit attributable to Equity holders | D40: 2324 | E40: 2680 | F40: 2710 | G40: 3567 | H40: 3459.993 | I40: 4908.74 | J40: 5537.028 | K40: 4391.159 | L40: 9272.57 | M40: 15192.711 | N40: 69806 | O40: 72662 | P40: 72230 | Q40: 108176 | R40: 1306 | S40: 1709 | T40: 22001 | U40: =BG40+BF40+BH40+BI40 -> 23938 | Y40: 1124.52 | Z40: 1417.058 | AA40: 1289.954 | AB40: =I40-AA40-Z40-Y40 -> 1077.208 | AC40: 1141.185 | AD40: 1418.434 | AE40: 1267.019 | AF40: =J40-AE40-AD40-AC40 -> 1710.39 | AG40: 779.309 | AH40: 1425.446 | AI40: 1075.923 | AJ40: =K40-AI40-AH40-AG40 -> 1110.481 | AK40: 3469.812 | AL40: 961.37 | AM40: 2305.391 | AN40: =L40-AM40-AL40-AK40 -> 2535.997 | AO40: 2113.184 | AP40: 3198.229 | AQ40: 4105.632 | AR40: =M40-AQ40-AP40-AO40 -> 5775.666 | AS40: =6713.112 -> 6713.112 | AT40: 15448.77 | AU40: 19860.447 | AV40: =N40-AU40-AT40-AS40 -> 27783.671 | AW40: 10693 | AX40: 9693 | AY40: 13477 | AZ40: =Q40-AY40-AX40-AW40 -> 74313 | BA40: 1354 | BB40: 164 | BC40: -3682 | BD40: =R40-BC40-BB40-BA40 -> 3470 | BE40: -1415 | BF40: 7733 | BG40: 7650 | BH40: =T40-BG40-BF40-BE40 -> 8033 | BI40: 522 | BK40: 9300 | BL40: 14352 | BN40: 2737 | BO40: 9857 | BP40: -4413 | BQ40: =S40-BN40-BO40-BP40 -> -6472 | BR40: -1852 | BS40: 1326 | BT40: =G40-BS40 -> 2241 | BU40: 1433 | BV40: =H40-BU40 -> 2026.993 | BW40: 4431.182 | BX40: =L40-BW40 -> 4841.388 | BY40: 5311.413 | BZ40: =M40-BY40 -> 9881.298 | CA40: 22161.882 | CB40: =N40-CA40 -> 47644.118 | CC40: 37372 | CD40: =P40-CC40 -> 34858 | CE40: 1632 | CF40: =R40-CE40 -> -326 | CG40: 6235 | CI40: 36165 | CJ40: =Q40-CI40 -> 72011 | CK40: 12758
B41: % margin | D41: =+D40/D31 -> 0.035391222 | E41: =+E40/E31 -> 0.040494394 | F41: =+F40/F31 -> 0.039491708 | G41: =+G40/G31 -> 0.051330388 | H41: =+H40/H31 -> 0.049125129 | I41: =+I40/I31 -> 0.04965006 | J41: =+J40/J31 -> 0.038653357 | K41: =+K40/K31 -> 0.028603916 | ... W41: =+W40/W31 -> #DIV/0! | Y41: =+Y40/Y31 -> 0.050485517 | Z41: =+Z40/Z31 -> 0.061452813 | AA41: =+AA40/AA31 -> 0.049853408 | AB41: =+AB40/AB31 -> 0.038946851 | AC41: =+AC40/AC31 -> 0.046412393 | AD41: =+AD40/AD31 -> 0.042630988 | AE41: =+AE40/AE31 -> 0.027813944 | AF41: =+AF40/AF31 -> 0.042937268 | ... BI41: =+BI40/BI31 -> 0.00070727586 | BN41: =+BN40/BN31 -> 0.0044000315 | BO41: =+BO40/BO31 -> 0.013997126 | BP41: =+BP40/BP31 -> -0.0059043266 | BQ41: =+BQ40/BQ31 -> -0.0067397009 | BR41: =+BR40/BR31 -> -0.0026289155 | BS41: =+BS40/BS31 -> 0.04127241 | BT41: =+BT40/BT31 -> 0.059979124 | BU41: =+BU40/BU31 -> 0.046044599 | ... CG41: =+CG40/CG31 -> 0.005295508 | CI41: =+CI40/CI31 -> 0.040803823 | CJ41: =+CJ40/CJ31 -> 0.050341184 | CK41: =+CK40/CK31 -> 0.0093559584
B43: LTM revenues | D43: =+D31 -> 65666 | E43: =+E31 -> 66182 | F43: =+F31 -> 68622 | G43: =+G31 -> 69491 | H43: =+H31 -> 70432.243 | I43: =+I31 -> 98866.749 | J43: =+J31 -> 143248.31 | K43: =+K31 -> 153516.01 | ... W43: =+W31 -> 0 | AB43: =+AB31+AA31+Z31+Y31 -> 98866.749 | AC43: =+AC31+AB31+AA31+Z31 -> 101180.57 | AD43: =+AD31+AC31+AB31+AA31 -> 111393.66 | AE43: =+AE31+AD31+AC31+AB31 -> 131072.09 | AF43: =+AF31+AE31+AD31+AC31 -> 143248.31 | AG43: =+AG31+AF31+AE31+AD31 -> 152922.07 | AH43: =+AH31+AG31+AF31+AE31 -> 160137.51 | AI43: =+AI31+AH31+AG31+AF31 -> 153948.64 | ... BI43: =+BI31+BH31+BG31+BF31 -> 2957018 | BN43: =BN31+AZ31+AY31+AX31 -> 2552137 | BO43: =+BO31+BN31+AY31+AZ31 -> 2789217 | BP43: =+BP31+BO31+AZ31+BN31 -> 2907783 | BQ43: =S43 -> 3033955 | BR43: =BR31+BD31+BC31+BB31 -> 2571965 | BT43: =+BT31+BS31 -> 69491 | BU43: =+BU31+BT31 -> 68485 | BV43: =+BV31+BU31 -> 70432.243 | BX43: =+BX31+BW31 -> 183777.28 | BY43: =+BY31+BX31 -> 241770.18 | BZ43: =+BZ31+BY31 -> 346688.7 | CA43: =+CA31+BZ31 -> 600607.18 | CB43: =+CB31+CA31 -> 901857 | CC43: =+CC31+CB31 -> 1006280.9 | CD43: =+CD31+CC31 -> 1604647 | CE43: =+CE31+CD31 -> 2124070 | ... CG43: =+CG31+CF31 -> 2485595 | CI43: =+CI31+CH31 -> 886314 | CJ43: =+CJ31+CI31 -> 2316773 | CK43: =+CK31+CJ31 -> 2794082
B44: LTM EBITDA | D44: =+D37 -> 4410 | E44: =+E37 -> 4962 | F44: =+F37 -> 4339 | G44: =+G37 -> 8236 | H44: =+H37 -> 6198.191 | I44: =+I37 -> 9045.596 | J44: =+J37 -> 13539.772 | K44: =+K37 -> 10696.351 | ... W44: =+W37 -> 0 | AB44: =+AB37+AA37+Z37+Y37 -> 9045.596 | AC44: =+AC37+AB37+AA37+Z37 -> 8460.452 | AD44: =+AD37+AC37+AB37+AA37 -> 9359.285 | AE44: =+AE37+AD37+AC37+AB37 -> 12237.579 | AF44: =+AF37+AE37+AD37+AC37 -> 13539.772 | AG44: =+AG37+AF37+AE37+AD37 -> 13796.513 | AH44: =+AH37+AG37+AF37+AE37 -> 13880.718 | AI44: =+AI37+AH37+AG37+AF37 -> 11450.027 | ... BI44: =+BI37+BH37+BG37+BF37 -> 234622 | BN44: =BN37+AZ37+AY37+AX37 -> 348407 | BO44: =+BO37+BN37+AZ37+AY37 -> 359275 | BP44: =+BP37+BO37+BA37+AZ37 -> 272641 | BQ44: =S44 -> 178536 | BR44: =BR37+BD37+BC37+BB37 -> 145909 | BT44: =+BT37+BS37 -> 6611.416 | BU44: =+BU37+BT37 -> 6438.53 | BV44: =+BV37+BU37 -> 6198.191 | BX44: =+BX37+BW37 -> 25393.096 | BY44: =+BY37+BX37 -> 33739.647 | BZ44: =+BZ37+BY37 -> 52188.905 | CA44: =+CA37+BZ37 -> 97224.421 | CB44: =+CB37+CA37 -> 166227 | CC44: =+CC37+CB37 -> 187165.86 | CD44: =+CD37+CC37 -> 249217 | CE44: =+CE37+CD37 -> 245359 | ... CG44: =+CG37+CF37 -> 125612 | CI44: =+CI37+CH37 -> 151406 | CJ44: =+CJ37+CI37 -> 359817 | CK44: =+CK37+CJ37 -> 350986
B46: Cash flow from operations | D46: 3327.547 | E46: 3529.265 | F46: 4103.667 | G46: 2291.997 | H46: 8318.315 | I46: 5065.641 | J46: 6830.054 | K46: 19017.986 | L46: 20209.815 | M46: 50664.147 | N46: 115479 | O46: 153543 | P46: 339016 | Q46: 489465 | R46: 116308 | S46: 152242 | T46: -101956 | U46: =BG46+BF46+BH46+BI46 -> -12217 | Y46: 524.398 | Z46: =2311.695-Y46 -> 1787.297 | AA46: =4522.42-Z46-Y46 -> 2210.725 | AB46: =I46-AA46-Z46-Y46 -> 543.221 | AC46: -470.039 | AD46: =3166.38-AC46 -> 3636.419 | AE46: =5169.215-AD46-AC46 -> 2002.835 | AF46: =J46-AE46-AD46-AC46 -> 1660.839 | AG46: 5873.257 | AH46: =11013.459-AG46 -> 5140.202 | AI46: =14466.364-AH46-AG46 -> 3452.905 | AJ46: =K46-AI46-AH46-AG46 -> 4551.622 | AK46: 5743.255 | AL46: =10875.612-AK46 -> 5132.357 | AM46: =5514.364-AL46-AK46 -> -5361.248 | AN46: =L46-AM46-AL46-AK46 -> 14695.451 | AO46: 8866.78 | AP46: =17766.751-AO46 -> 8899.971 | AQ46: =32173.516-AP46-AO46 -> 14406.765 | AR46: =M46-AQ46-AP46-AO46 -> 18490.631 | AS46: 23376.924 | AT46: =57977.459-AS46 -> 34600.535 | AU46: =71485.456-AT46-AS46 -> 13507.997 | AV46: =N46-AU46-AT46-AS46 -> 43993.544 | AW46: 154703 | AX46: =131997-AW46 -> -22706 | AY46: =424611-AX46-AW46 -> 292614 | AZ46: =Q46-AY46-AX46-AW46 -> 64854 | BA46: -58747 | BB46: =89843-BA46 -> 148590 | BC46: =85903-BB46-BA46 -> -3940 | BD46: =R46-BC46-BB46-BA46 -> 30405 | BE46: -13401 | BF46: =-51070-BE46 -> -37669 | BG46: =-46711-BF46-BE46 -> 4359 | BH46: =T46-BG46-BF46-BE46 -> -55245 | BI46: 76338 | BN46: -81133 | BO46: =60177-BN46 -> 141310 | BP46: =114173-60177 -> 53996 | BQ46: =S46-BN46-BO46-BP46 -> 38069 | BR46: -17535 | BS46: -483.43 | BT46: =G46-BS46 -> 2775.427 | BU46: 3461.647 | BV46: =H46-BU46 -> 4856.668 | BW46: 10875.612 | BX46: =L46-BW46 -> 9334.203 | BY46: =17766.751 -> 17766.751 | BZ46: =M46-BY46 -> 32897.396 | CA46: 57977.459 | CB46: =N46-CA46 -> 57501.541 | CC46: 131997 | CD46: =P46-CC46 -> 207019 | CE46: 89843 | CF46: =R46-CE46 -> 26465 | CG46: =-51070 -> -51070
...

Sheet KPI
B2: KOC HOLDING | C2: Annual | D2: Annual | E2: Annual | F2: Annual | G2: Annual | H2: Annual | I2: Annual | J2: Annual | K2: Annual | L2: Annual | M2: Annual | N2: Annual | O2: Annual | P2: Annual | Q2: Annual | R2: Annual | S2: Annual | T2: LTM | V2: Quarters | W2: Quarters | X2: Quarters | Y2: Quarters | Z2: Quarters | AA2: Quarters | AB2: Quarters | AC2: Quarters | AD2: Quarters | AE2: Quarters | AF2: Quarters | AG2: Quarters | AH2: Quarters | AI2: Quarters | AJ2: Quarters | AK2: Quarters | AL2: Quarters | AM2: Quarters | AN2: Quarters | AO2: Quarters | AP2: Quarters | AQ2: Quarters | AR2: Quarters | AS2: Quarters | AT2: Quarters | AU2: Quarters | AV2: Quarters | AW2: Quarters | AX2: Quarters | AY2: Quarters | AZ2: Quarters | BA2: Quarters | BB2: Quarters | BC2: Quarters | BD2: Quarters | BE2: Quarters | BF2: Quarters | BH2: Quarters
B3: TRY mn | C3: 41274 | D3: =C3+365 -> 41639 | E3: =D3+365 -> 42004 | F3: =E3+365 -> 42369 | G3: =F3+365 -> 42734 | H3: =G3+365 -> 43099 | I3: =H3+365 -> 43464 | J3: =I3+365 -> 43829 | K3: =J3+365 -> 44194 | ... M3: =L3+365 -> 44924 | N3: =M3 -> 44924 | O3: =M3+365 -> 45289 | P3: =N3+365 -> 45289 | Q3: =O3+365 -> 45654 | R3: =P3+365 -> 45654 | S3: =Q3+365 -> 46019 | T3: =BF3 -> 46111 | V3: 42825 | W3: =EDATE(V3,3) -> 42916 | X3: =EDATE(W3,3) -> 43008 | Y3: =EDATE(X3,3) -> 43099 | Z3: =EDATE(Y3,3) -> 43189 | AA3: =EDATE(Z3,3) -> 43281 | AB3: =EDATE(AA3,3) -> 43373 | AC3: =EDATE(AB3,3) -> 43464 | AD3: =EDATE(AC3,3) -> 43554 | ... BF3: =EDATE(BE3,3) -> 46111 | BH3: =BB3 -> 45746
