Workbook
Name \A: #REF!
Name \B: #REF!
Name \C: #REF!
Name \L: #REF!
Name \M: #REF!
Name \P: #REF!
Name \Y: #REF!
Name _01_30_04: MonthlyOpStats
Name _01_30_04: MonthlyOpStats
Name _01_30_04: MonthlyOpStats
Name _01_30_04: MonthlyOpStats
Name _1_30_01: MonthlyOpStats
Name _1_30_01: MonthlyOpStats
Name _1_30_01: MonthlyOpStats
Name _1_30_01: MonthlyOpStats
Name _1_30_02: MonthlyOpStats
Name _1_30_02: MonthlyOpStats
Name _1_30_02: MonthlyOpStats
Name _1_30_02: MonthlyOpStats
Name _1_31_01: MonthlyOpStats
Name _1_31_01: MonthlyOpStats
Name _1_31_01: MonthlyOpStats
Name _1_31_01: MonthlyOpStats
Name _1_31_02: MonthlyOpStats
Name _1_31_02: MonthlyOpStats
Name _1_31_02: MonthlyOpStats
Name _1_31_02: MonthlyOpStats
Name _12_31_05: MonthlyOpStats
Name _12_31_05: MonthlyOpStats
Name _12_31_05: MonthlyOpStats
Name _12_31_05: MonthlyOpStats
Name _A: #REF!
Name _A___0: #REF!
Name _B: #REF!
Name _B___0: #REF!
Name _C: #REF!
Name _C___0: #REF!
Name _ent1: [1]Inputs!$J$17
Name _ent10: [1]Inputs!$J$476
Name _ent11: [1]Inputs!$J$527
Name _ent12: [1]Inputs!$J$578
Name _ent13: [1]Inputs!$J$629
Name _ent14: [1]Inputs!$J$680
Name _ent15: [1]Inputs!$J$731
Name _ent2: [1]Inputs!$J$68
Name _ent3: [1]Inputs!$J$119
Name _ent4: [1]Inputs!$J$170
Name _ent5: [1]Inputs!$J$221
Name _ent6: [1]Inputs!$J$272
Name _ent7: [1]Inputs!$J$323
Name _ent8: [1]Inputs!$J$374
Name _ent9: [1]Inputs!$J$425
Name _eps1: [1]Inputs!$P$42
Name _eps10: [1]Inputs!$P$501
Name _eps11: [1]Inputs!$P$552
Name _eps12: [1]Inputs!$P$603
Name _eps13: [1]Inputs!$P$654
Name _eps14: [1]Inputs!$P$705
Name _eps15: [1]Inputs!$P$756
Name _eps2: [1]Inputs!$P$93

Sheet Capitalisation
B3: 1Q26 | I3: Exchange rate as at end | J3: =Model!$Q$211 -> 0.055744467
I4: LTM Average exchange rate | J4: =Model!$Q$210 -> 0.054085873
C6: Amount outstanding as on 31-Mar-2026 | D6: MXN mn | E6: USD mn | F6: Leverage (MXN) | G6: Leverage (USD) | I6: Company reported | J6: =D6 -> MXN mn
I7: Total debt and lease liabilities | J7: 88557.8
C8: Current portion of long-term debt | D8: 0 | E8: =D8*$J3 -> 0 | I8: Net debt | J8: 49752.4
I9: Net debt / EBITDA | J9: =J8/D21 -> 2.1876949
C10: Long-term debt, net of current portion | D10: =SUM(D11:D12) -> 82048.136 | E10: =SUM(E11:E12) -> 4573.7296
C11: Long-term bank loans | D11: 9949.316 | E11: =D11*J3 -> 554.61932
C12: Long-term stock market loans | D12: 72098.82 | E12: =D12*J3 -> 4019.1103
C14: Lease Liabilties | D14: =Model!$BC$108 -> 6509.7 | E14: =D14*$J3 -> 362.87976
C16: Total Loans & Borrows (including finance lease obligations) | D16: =SUM(D8,D10,D14) -> 88557.836 | E16: =SUM(E8,E10,E14) -> 4936.6094 | F16: =+D16/D21 -> 3.8940338 | G16: =+E16/E21 -> 4.013448
C17: Cash & Equivalents | D17: =Model!BC$113 -> 24976.8 | E17: =D17*$J3 -> 1392.3184
C18: Net debt | D18: =+D16-D17 -> 63581.036 | E18: =+E16-E17 -> 3544.291 | F18: =+D18/D21 -> 2.7957628 | G18: =+E18/E21 -> 2.8814975
C19: Equity | D19: =Model!BC$120 -> 104339.7 | E19: =D19*$J3 -> 5816.361
C20: Total Capitalisation | D20: =D16+D19 -> 192897.54 | E20: =E16+E19 -> 10752.97 | F20: =D20/D21 -> 8.4820221 | G20: =E20/E21 -> 8.7421313
C21: LTM Adjusted EBITDA | D21: =Model!BC$85 -> 22741.928 | E21: =D21*J4 -> 1230.017
C22: check | D22: =D16-Model!BC$116 -> 0.036
C24: short term investments | D24: 9733.4 | E24: =D24*J3 -> 542.5832
C25: Net debt including short-term investments | D25: =D18-D24 -> 53847.636 | E25: =E18-E24 -> 3001.7078
C26: Net leverage including short-term investments | D26: =D25/D21 -> 2.3677692 | E26: =E25/E21 -> 2.440379
C30: Liquidity Table at end | D30: =D6 -> MXN mn | E30: =E6 -> USD mn
C31: Cash and cash equivalents | D31: =D17 -> 24976.8 | E31: =D31*$J3 -> 1392.3184
C32: short term investments | D32: =D24 -> 9733.4 | E32: =D32*$J3 -> 542.5832
C33: Total Liquidity | D33: =SUM(D31:D32) -> 34710.2 | E33: =SUM(E31:E32) -> 1934.9016
C36: Total Debt as at end (excluding leases) | D36: =D30 -> MXN mn | E36: =E30 -> USD mn
E37: =D37*$J3 -> 0
C38: Secured - Banks
B39: 2029 | C39: Union 1 TIE+1.25 | D39: 2469.409 | E39: =D39*$J3 -> 137.65589
B40: 2029 | C40: Union 2 TIE+1.25 | D40: 7479.907 | E40: =D40*$J3 -> 416.96343
C42: Unsecured - Notes
B43: 2037 | C43: Senior notes 1 @ 8.93% | D43: 4485.361 | E43: =D43*$J3 -> 250.03406
B44: 2043 | C44: Senior notes 2 @ 7.62% | D44: 6164.304 | E44: =D44*$J3 -> 343.62584
B45: 2027 | C45: Stock Certificates 3 @ 8.79% | D45: 4494.794 | E45: =D45*$J3 -> 250.5599
B46: 2032 | C46: Senior notes 4 @ 8.94% | D46: 5353.741 | E46: =D46*$J3 -> 298.44144
B47: 2040 | C47: Senior notes 5 @ 6.97% | D47: 10633.157 | E47: =D47*$J3 -> 592.73967
B48: 2045 | C48: Senior notes 6 @ 5.26% | D48: 13751.371 | E48: =D48*$J3 -> 766.56285
B49: 2046 | C49: Senior notes 7 @ 6.44% | D49: 15661.618 | E49: =D49*$J3 -> 873.04855
B50: 2049 | C50: Senior notes 8 @ 5.52% | D50: 11554.474 | E50: =D50*$J3 -> 644.098
C52: Total debt | D52: =SUM(D39:D51) -> 82048.136 | E52: =SUM(E39:E51) -> 4573.7296
C53: Check | D53: =D52-D8-D10 -> 0
...

Sheet Model
B2: Grupo Televisa, S.A.B. | C2: Annual | D2: Annual | E2: Annual | F2: Annual | G2: Annual | H2: Annual | I2: Annual | J2: Annual | K2: Annual | L2: Annual | M2: Annual | N2: Annual | O2: Annual | P2: Annual | Q2: LTM | S2: Quarterly | T2: Quarterly | U2: Quarterly | V2: Quarterly | W2: Quarterly | X2: Quarterly | Y2: Quarterly | Z2: Quarterly | AA2: Quarterly | AB2: Quarterly | AC2: Quarterly | AD2: Quarterly | AE2: Quarterly | AF2: Quarterly | AG2: Quarterly | AH2: Quarterly | AI2: Quarterly | AJ2: Quarterly | AK2: Quarterly | AL2: Quarterly | AM2: Quarterly | AN2: Quarterly | AO2: Quarterly | AP2: Quarterly | AQ2: Quarterly | AR2: Quarterly | AS2: Quarterly | AT2: Quarterly | AU2: Quarterly | AV2: Quarterly | AW2: Quarterly | AX2: Quarterly | AY2: Quarterly | AZ2: Quarterly | BA2: Quarterly | BB2: Quarterly | BC2: Quarterly | BF2: Quarterly | BG2: Quarterly | BH2: Quarterly | BI2: Quarterly | BJ2: Quarterly | BK2: Quarterly | BL2: Quarterly
B3: (MXN millions) | C3: 42735 | D3: 43100 | E3: 43465 | F3: 43830 | G3: 43830 | H3: 44196 | I3: 44561 | J3: 44561 | K3: 44926 | L3: 44926 | M3: 45291 | N3: 45291 | O3: 45657 | P3: 46022 | Q3: =BC3 -> 46112 | S3: 42825 | T3: 42916 | U3: 43008 | V3: 43100 | W3: 43190 | X3: 43281 | Y3: 43373 | Z3: 43465 | AA3: 43555 | AB3: 43646 | AC3: 43738 | AD3: 43830 | AE3: 43921 | AF3: 44012 | AG3: 44104 | AH3: 44196 | AI3: 44286 | AJ3: 44377 | AK3: 44469 | AL3: 44561 | AM3: 44651 | AN3: 44742 | AO3: 44834 | AP3: 44926 | AQ3: 45016 | AR3: 45107 | AS3: 45199 | AT3: 45291 | AU3: 45382 | AV3: 45473 | AW3: 45565 | AX3: 45657 | AY3: 45747 | AZ3: 45838 | BA3: 45930 | BB3: 46022 | BC3: 46112 | BF3: 43830 | BG3: 44286 | BH3: 44377 | BI3: 44469 | BJ3: 44561 | BK3: 45016 | BL3: 45107
C4: Act | D4: Act | E4: Act | F4: Act | G4: Act | H4: Act | I4: Act | J4: Act | K4: Act | L4: Act | M4: Act | N4: Act | O4: Act | P4: Act | Q4: Act | S4: Act | T4: Act | U4: Act | V4: Act | W4: Act | X4: Act | Y4: Act | Z4: Act | AA4: Act | AB4: Act | AC4: Act | AD4: Act | AE4: Act | AF4: Act | AG4: Act | AH4: Act | AI4: Act | AJ4: Act | AK4: Act | AL4: Act | AM4: Act | AN4: Act | AO4: Act | AP4: Act | AQ4: Act | AR4: Act | AS4: Act | AT4: Act | AU4: Act | AV4: Act | AW4: Act | AX4: Act | AY4: Act | AZ4: Act | BA4: Act | BB4: Act | BC4: Act | BF4: Act | BG4: Act | BH4: Act | BI4: Act | BJ4: Act | BK4: Act | BL4: Act
C5: FY | D5: FY | E5: FY | F5: FY | G5: FY | H5: FY | I5: FY | J5: FY | K5: FY | L5: FY | M5: FY | N5: FY | O5: FY | P5: FY | Q5: LTM | S5: Q1 | T5: Q2 | U5: Q3 | V5: Q4 | W5: Q1 | X5: Q2 | Y5: Q3 | Z5: Q4 | AA5: Q1 | AB5: Q2 | AC5: Q3 | AD5: Q4 | AE5: Q1 | AF5: Q2 | AG5: Q3 | AH5: Q4 | AI5: Q1 | AJ5: Q2 | AK5: Q3 | AL5: Q4 | AM5: Q1 | AN5: Q2 | AO5: Q3 | AP5: Q4 | AQ5: Q1 | AR5: Q2 | AS5: Q3 | AT5: Q4 | AU5: Q1 | AV5: Q2 | AW5: Q3 | AX5: Q4 | AY5: Q1 | AZ5: Q2 | BA5: Q3 | BB5: Q4 | BC5: Q1 | BF5: Q4 | BG5: Q1 | BH5: Q2 | BI5: Q3 | BJ5: Q4 | BK5: Q1 | BL5: Q2
B6: INCOME STATEMENT | G6: restated | J6: restated | L6: restated | N6: restated | BF6: restated | BG6: Restated | BH6: Restated | BI6: Restated | BJ6: Restated | BK6: Restated | BL6: Restated
B7: Net Sales (LFL) | C7: 96287.4 | D7: 93586.2 | E7: 98548.7 | F7: 101492.18 | G7: 101757.18 | H7: 97361.634 | I7: 103521.82 | J7: 73915.4 | K7: 75526.609 | L7: 68615.768 | M7: 73767.9 | N7: 66222.836 | O7: 62260.864 | P7: 58878.15 | Q7: =SUM(AZ7:BC7) -> 58417.05 | S7: 21954.3 | T7: 22976.8 | U7: 22663 | V7: 25992.1 | W7: 22812 | X7: 24978.3 | Y7: 24023.1 | Z7: 26735.3 | AA7: 23395.2 | AB7: 24307.6 | AC7: 25786.149 | AD7: =F7-AA7-AB7-AC7 -> 28003.232 | AE7: 23228.8 | AF7: 22407.2 | AG7: 23943 | AH7: =H7-AE7-AF7-AG7 -> 27782.634 | AI7: 23828.9 | AJ7: 24753.2 | AK7: 26127.867 | AL7: =I7-AI7-AJ7-AK7 -> 28811.856 | AM7: 18609.2 | AN7: 18533.5 | AO7: 19251.7 | AP7: =K7-AM7-AN7-AO7 -> 19132.209 | AQ7: 18519.633 | AR7: 18520.2 | AS7: 16416 | AT7: =M7-AQ7-AR7-AS7 -> 20312.067 | AU7: 15951.4 | AV7: 15720.3 | AW7: 15362.8 | AX7: =O7-SUM(AU7:AW7) -> 15226.364 | AY7: 14973.6 | AZ7: 14729.4 | BA7: 14627.086 | BB7: =P7-SUM(AY7:BA7) -> 14548.064 | BC7: 14512.5 | BF7: =G7-AA7-AB7-AC7 -> 28268.232 | BG7: 18022.3 | BH7: 18473.9 | BI7: 18590.1 | BJ7: =J7-BG7-BH7-BI7 -> 18829.1 | BK7: 16753.3 | BL7: 16693.7
B8: Non-Recurring Licensing revenues | C8: 0 | D8: 0 | E8: 2733.6 | F8: 0 | G8: 0 | H8: 0 | I8: 0 | J8: 0 | K8: 0 | L8: 0 | M8: 0 | N8: 0 | O8: 0 | P8: 0 | Q8: =SUM(AZ8:BC8) -> 0 | S8: 0 | T8: 0 | U8: 0 | V8: =D8-U8-T8-S8 -> 0 | W8: 0 | X8: 1723.5 | Y8: 1010.1 | Z8: =E8-Y8-X8-W8 -> 0 | AA8: 0 | AB8: 0 | AC8: 0 | AD8: =F8-AA8-AB8-AC8 -> 0 | AE8: 0 | AF8: 0 | AG8: 0 | AH8: =H8-AE8-AF8-AG8 -> 0 | AI8: 0 | AJ8: 0 | AK8: 0 | AL8: =I8-AI8-AJ8-AK8 -> 0 | AM8: 0 | AN8: 0 | AO8: 0 | AP8: =K8-AM8-AN8-AO8 -> 0 | AQ8: 0 | AR8: 0 | AS8: 0 | AT8: =M8-AQ8-AR8-AS8 -> 0 | AU8: 0 | AV8: 0 | AW8: 0 | AX8: =S8-AU8-AV8-AW8 -> 0 | AY8: 0 | AZ8: 0 | BA8: 0 | BB8: =P8-SUM(AY8:BA8) -> 0 | BC8: 0 | BF8: =G8-AA8-AB8-AC8 -> 0 | BG8: 0 | BH8: 0 | BI8: 0 | BJ8: =J8-BG8-BH8-BI8 -> 0 | BK8: 0 | BL8: 0
B9: Net Sales including non-recurring licensing revenues | C9: =+C7+C8 -> 96287.4 | D9: =+D7+D8 -> 93586.2 | E9: =+E7+E8 -> 101282.3 | F9: =+F7+F8 -> 101492.18 | G9: =+G7+G8 -> 101757.18 | H9: =+H7+H8 -> 97361.634 | I9: =+I7+I8 -> 103521.82 | J9: =+J7+J8 -> 73915.4 | ... Q9: =+Q7+Q8 -> 58417.05 | S9: =+S7+S8 -> 21954.3 | T9: =+T7+T8 -> 22976.8 | U9: =+U7+U8 -> 22663 | V9: =+V7+V8 -> 25992.1 | W9: =+W7+W8 -> 22812 | X9: =+X7+X8 -> 26701.8 | Y9: =+Y7+Y8 -> 25033.2 | Z9: =+Z7+Z8 -> 26735.3 | ... BC9: =+BC7+BC8 -> 14512.5 | BF9: =+BF7+BF8 -> 28268.232 | BG9: =+BG7+BG8 -> 18022.3 | BH9: =+BH7+BH8 -> 18473.9 | BI9: =+BI7+BI8 -> 18590.1 | BJ9: =+BJ7+BJ8 -> 18829.1 | BK9: =+BK7+BK8 -> 16753.3 | BL9: =+BL7+BL8 -> 16693.7
B10: % y-o-y growth (LFL sales) | D10: =D7/C7-1 -> -0.028053515 | E10: =E7/D7-1 -> 0.05302598 | F10: =F7/E7-1 -> 0.029868288 | G10: =G7/E7-1 -> 0.032557314 | H10: =H7/G7-1 -> -0.043196431 | I10: =I7/H7-1 -> 0.063271216 | J10: =J7/H7-1 -> -0.24081595 | K10: =K7/J7-1 -> 0.021798015 | L10: =L7/J7-1 -> -0.071698618 | M10: =M7/K7-1 -> -0.023285952 | N10: =N7/L7-1 -> -0.034874375 | O10: =O7/N7-1 -> -0.059827882 | P10: =P7/O7-1 -> -0.054331305 | W10: =W7/S7-1 -> 0.039067518 | X10: =X7/T7-1 -> 0.087109606 | Y10: =Y7/U7-1 -> 0.06001412 | Z10: =Z7/V7-1 -> 0.028593303 | AA10: =AA7/W7-1 -> 0.025565492 | AB10: =AB7/X7-1 -> -0.026851307 | AC10: =AC7/Y7-1 -> 0.073389737 | AD10: =AD7/Z7-1 -> 0.047425389 | ... AG10: =AG7/AC7-1 -> -0.071478258 | AH10: =AH7/BF7-1 -> -0.017178223 | AI10: =AI7/AE7-1 -> 0.025834309 | AJ10: =AJ7/AF7-1 -> 0.10469849 | AK10: =AK7/AG7-1 -> 0.091252851 | AL10: =AL7/AH7-1 -> 0.037045516 | AM10: =AM7/BG7-1 -> 0.032565211 | AN10: =AN7/AJ7-1 -> -0.25126852 | AO10: =AO7/AK7-1 -> -0.26317368 | AP10: =AP7/AL7-1 -> -0.33596055 | AQ10: =AQ7/AM7-1 -> -0.0048130495 | AR10: =AR7/AN7-1 -> -0.00071761945 | AS10: =AS7/AO7-1 -> -0.14729608 | AT10: =AT7/AP7-1 -> 0.061668676 | AU10: =AU7/BK7-1 -> -0.047865197 | AV10: =AV7/AR7-1 -> -0.15118087 | AW10: =AW7/AS7-1 -> -0.06415692 | AX10: =AX7/AT7-1 -> -0.25037841 | AY10: =AY7/AU7-1 -> -0.061298695 | AZ10: =AZ7/AV7-1 -> -0.063033148 | BA10: =BA7/AW7-1 -> -0.047889317 | BB10: =BB7/AX7-1 -> -0.044547733 | BC10: =BC7/AY7-1 -> -0.030794198 | BL10: =BL7/BH7-1 -> -0.096362977
B11: % y-o-y growth | D11: =D9/C9-1 -> -0.028053515 | E11: =E9/D9-1 -> 0.082235415 | F11: =F9/E9-1 -> 0.0020722377 | G11: =G9/E9-1 -> 0.004688687 | H11: =H9/G9-1 -> -0.043196431 | I11: =I9/H9-1 -> 0.063271216 | J11: =J9/H9-1 -> -0.24081595 | K11: =K9/J9-1 -> 0.021798015 | L11: =L9/J9-1 -> -0.071698618 | M11: =M9/K9-1 -> -0.023285952 | N11: =N9/L9-1 -> -0.034874375 | O11: =O9/N9-1 -> -0.059827882 | P11: =P9/O9-1 -> -0.054331305 | W11: =W9/S9-1 -> 0.039067518 | X11: =X9/T9-1 -> 0.16212005 | Y11: =Y9/U9-1 -> 0.10458457 | Z11: =Z9/V9-1 -> 0.028593303 | AA11: =AA9/W9-1 -> 0.025565492 | AB11: =AB9/X9-1 -> -0.089664367 | AC11: =AC9/Y9-1 -> 0.030078016 | AD11: =AD9/Z9-1 -> 0.047425389 | ... AG11: =AG9/AC9-1 -> -0.071478258 | AH11: =AH9/BF9-1 -> -0.017178223 | AI11: =AI9/AE9-1 -> 0.025834309 | AJ11: =AJ9/AF9-1 -> 0.10469849 | AK11: =AK9/AG9-1 -> 0.091252851 | AL11: =AL9/AH9-1 -> 0.037045516 | AM11: =AM9/BG9-1 -> 0.032565211 | AN11: =AN9/AJ9-1 -> -0.25126852 | AO11: =AO9/AK9-1 -> -0.26317368 | AP11: =AP9/AL9-1 -> -0.33596055 | AQ11: =AQ9/AM9-1 -> -0.0048130495 | AR11: =AR9/AN9-1 -> -0.00071761945 | AS11: =AS9/AO9-1 -> -0.14729608 | AT11: =AT9/AP9-1 -> 0.061668676 | AU11: =AU9/BK9-1 -> -0.047865197 | AV11: =AV9/AR9-1 -> -0.15118087 | AW11: =AW9/AS9-1 -> -0.06415692 | AX11: =AX9/AT9-1 -> -0.25037841 | AY11: =AY9/AU9-1 -> -0.061298695 | AZ11: =AZ9/AV9-1 -> -0.063033148 | BA11: =BA9/AW9-1 -> -0.047889317 | BB11: =BB9/AX9-1 -> -0.044547733 | BC11: =BC9/AY9-1 -> -0.030794198 | BL11: =BL9/BH9-1 -> -0.096362977
B12: COGS | C12: -52377.79 | D12: -52983.38 | E12: -57839.268 | F12: -58725.362 | G12: -59067.362 | H12: -56989.655 | I12: -59561.521 | J12: -46653.6 | K12: -48807.606 | L12: -43357.747 | M12: -48893.6 | N12: -43297.44 | O12: -41117.033 | P12: -36394.735 | Q12: =SUM(AZ12:BC12) -> -36021.235 | S12: -12655.512 | T12: -12820.791 | U12: -12592.025 | V12: =D12-U12-T12-S12 -> -14915.052 | W12: -13060.608 | X12: -15079.753 | Y12: -14208.501 | Z12: =E12-Y12-X12-W12 -> -15490.406 | AA12: -13264.015 | AB12: -13815.4 | AC12: -14946.51 | AD12: =F12-AA12-AB12-AC12 -> -16699.437 | AE12: -13738 | AF12: -13941.8 | AG12: -13871 | AH12: =H12-AE12-AF12-AG12 -> -15438.855 | AI12: -13884.6 | AJ12: -14545.3 | AK12: -15358.168 | AL12: =I12-AI12-AJ12-AK12 -> -15773.453 | AM12: -11826.9 | AN12: -11848.2 | AO12: -12229.1 | AP12: =K12-AM12-AN12-AO12 -> -12903.406 | AQ12: -12081.971 | AR12: -12123.8 | AS12: -11071.6 | AT12: =M12-AQ12-AR12-AS12 -> -13616.229 | AU12: -10411.9 | AV12: -10506.6 | AW12: -9944.3 | AX12: =O12-SUM(AU12:AW12) -> -10254.233 | AY12: -9215.4 | AZ12: -9019.7 | BA12: -9258.735 | BB12: =P12-SUM(AY12:BA12) -> -8900.9 | BC12: -8841.9 | BF12: =G12-AA12-AB12-AC12 -> -17041.437 | BG12: -11383.2 | BH12: -11899.8 | BI12: -11505.9 | BJ12: =J12-BG12-BH12-BI12 -> -11864.7 | BK12: -10714.7 | BL12: -10797.7
B13: Gross Profit | C13: =C9+C12 -> 43909.61 | D13: =D9+D12 -> 40602.82 | E13: =E9+E12 -> 43443.032 | F13: =F9+F12 -> 42766.819 | G13: =G9+G12 -> 42689.819 | H13: =H9+H12 -> 40371.979 | I13: =I9+I12 -> 43960.302 | J13: =J9+J12 -> 27261.8 | ... Q13: =Q9+Q12 -> 22395.815 | S13: =S9+S12 -> 9298.788 | T13: =T9+T12 -> 10156.009 | U13: =U9+U12 -> 10070.975 | V13: =V9+V12 -> 11077.048 | W13: =W9+W12 -> 9751.392 | X13: =X9+X12 -> 11622.047 | Y13: =Y9+Y12 -> 10824.699 | Z13: =Z9+Z12 -> 11244.894 | ... BC13: =BC9+BC12 -> 5670.6 | BF13: =BF9+BF12 -> 11226.795 | BG13: =BG9+BG12 -> 6639.1 | BH13: =BH9+BH12 -> 6574.1 | BI13: =BI9+BI12 -> 7084.2 | BJ13: =BJ9+BJ12 -> 6964.4 | BK13: =BK9+BK12 -> 6038.6 | BL13: =BL9+BL12 -> 5896
B14: Gross Profit margin | C14: =C13/C9 -> 0.45602654 | D14: =D13/D9 -> 0.43385478 | E14: =E13/E9 -> 0.42893015 | F14: =F13/F9 -> 0.42138043 | G14: =G13/G9 -> 0.41952635 | H14: =H13/H9 -> 0.41466004 | I14: =I13/I9 -> 0.42464768 | J14: =J13/J9 -> 0.36882436 | ... Q14: =Q13/Q9 -> 0.38337805 | S14: =S13/S9 -> 0.42355201 | T14: =T13/T9 -> 0.44201146 | U14: =U13/U9 -> 0.44437961 | V14: =V13/V9 -> 0.4261698 | W14: =W13/W9 -> 0.42746765 | X14: =X13/X9 -> 0.43525332 | Y14: =Y13/Y9 -> 0.43241371 | Z14: =Z13/Z9 -> 0.420601 | ... BC14: =BC13/BC9 -> 0.39073902 | BF14: =BF13/BF9 -> 0.39715236 | BG14: =BG13/BG9 -> 0.3683825 | BH14: =BH13/BH9 -> 0.35585881 | BI14: =BI13/BI9 -> 0.3810738 | BJ14: =BJ13/BJ9 -> 0.36987429 | BK14: =BK13/BK9 -> 0.36044242 | BL14: =BL13/BL9 -> 0.35318713
B15: Distribution costs | C15: -10900.695 | D15: -10446.596 | E15: -11023.466 | F15: -11193.011 | G15: -11099.011 | H15: -10366.582 | I15: -10460.246 | J15: -8099.6 | K15: -9422.916 | L15: -9155.448 | M15: -9146.9 | N15: -8848.181 | O15: -8815.211 | P15: -7721.811 | Q15: =SUM(AZ15:BC15) -> -7453.011 | S15: -2607.368 | T15: -2490.263 | U15: -2472.521 | V15: =D15-U15-T15-S15 -> -2876.444 | W15: -2581.37 | X15: -2846.36 | Y15: -2609.679 | Z15: =E15-Y15-X15-W15 -> -2986.057 | AA15: -2764.384 | AB15: -2782.6 | AC15: -2797.238 | AD15: =F15-AA15-AB15-AC15 -> -2848.789 | AE15: -2718 | AF15: -2538.4 | AG15: -2312.3 | AH15: =H15-AE15-AF15-AG15 -> -2797.882 | AI15: -2522.6 | AJ15: -2571.9 | AK15: -2642.442 | AL15: =I15-AI15-AJ15-AK15 -> -2723.304 | AM15: -2133.2 | AN15: -2097.8 | AO15: -2462.4 | AP15: =K15-AM15-AN15-AO15 -> -2729.516 | AQ15: -2238.488 | AR15: -2212.9 | AS15: -2065.7 | AT15: =M15-AQ15-AR15-AS15 -> -2629.812 | AU15: -2354.9 | AV15: -2199.1 | AW15: -2131.4 | AX15: =O15-SUM(AU15:AW15) -> -2129.811 | AY15: -2029.4 | AZ15: -2247.9 | BA15: -1655.117 | BB15: =P15-SUM(AY15:BA15) -> -1789.394 | BC15: -1760.6 | BF15: =G15-AA15-AB15-AC15 -> -2754.789 | BG15: -1977.1 | BH15: -1970.6 | BI15: -2034.5 | BJ15: =J15-BG15-BH15-BI15 -> -2117.4 | BK15: -2162.8 | BL15: -2135.5
B16: Administrative expenses | C16: -13273.397 | D16: -13459.487 | E16: -13729.325 | F16: -13269.191 | G16: -13269.191 | H16: -12713.657 | I16: -13710.793 | J16: -12189.5 | K16: -12061.932 | L16: -11341.657 | M16: -12196.9 | N16: -11305.619 | O16: -10592.581 | P16: -9522.888 | Q16: =SUM(AZ16:BC16) -> -9170.988 | S16: -3250.568 | T16: -3375.039 | U16: -3419.804 | V16: =D16-U16-T16-S16 -> -3414.076 | W16: -3391.751 | X16: -3391.337 | Y16: -3440.751 | Z16: =E16-Y16-X16-W16 -> -3505.486 | AA16: -3707.54 | AB16: -3316.6 | AC16: -3057.286 | AD16: =F16-AA16-AB16-AC16 -> -3187.765 | AE16: -3631.1 | AF16: -2940.3 | AG16: -2856.6 | AH16: =H16-AE16-AF16-AG16 -> -3285.657 | AI16: -3728.3 | AJ16: -3251.4 | AK16: -3002.365 | AL16: =I16-AI16-AJ16-AK16 -> -3728.728 | AM16: -2843.4 | AN16: -2994.9 | AO16: -2906.7 | AP16: =K16-AM16-AN16-AO16 -> -3316.932 | AQ16: -2813.247 | AR16: -3010.1 | AS16: -2933.7 | AT16: =M16-AQ16-AR16-AS16 -> -3439.853 | AU16: -2551.9 | AV16: -2395.5 | AW16: -2603.1 | AX16: =O16-SUM(AU16:AW16) -> -3042.081 | AY16: -2640.1 | AZ16: -2234.2 | BA16: -2740.685 | BB16: =P16-SUM(AY16:BA16) -> -1907.903 | BC16: -2288.2 | BF16: =G16-AA16-AB16-AC16 -> -3187.765 | BG16: -2764.3 | BH16: -2666.5 | BI16: -2972.1 | BJ16: =J16-BG16-BH16-BI16 -> -3786.6 | BK16: -2584.2 | BL16: -2772.7
B17: Other income | C17: 0 | D17: 0 | E17: 1562.284 | F17: 0 | G17: 0 | H17: 233.628 | I17: 2393.963 | J17: 3716.2 | K17: 0 | L17: 0 | M17: 0 | N17: 0 | O17: 0 | P17: 0 | Q17: =SUM(AZ17:BC17) -> 0 | S17: 0 | T17: 0 | U17: 0 | V17: =D17-U17-T17-S17 -> 0 | W17: 0 | X17: 3237.923 | Y17: 0 | Z17: =E17-Y17-X17-W17 -> -1675.639 | AA17: 0 | AB17: 0 | AC17: 0 | AD17: =F17-AA17-AB17-AC17 -> 0 | AE17: 284.9 | AF17: 0 | AG17: 666 | AH17: =H17-AE17-AF17-AG17 -> -717.272 | AI17: 0 | AJ17: 0 | AK17: 0 | AL17: =I17-AI17-AJ17-AK17 -> 2393.963 | AM17: 0 | AN17: 0 | AO17: 0 | AP17: =K17-AM17-AN17-AO17 -> 0 | AQ17: 0 | AR17: 0 | AS17: 0 | AT17: =M17-AQ17-AR17-AS17 -> 0 | AU17: 2293.2 | AV17: 0 | AW17: 0 | AX17: =O17-SUM(AU17:AW17) -> -2293.2 | AY17: 0 | AZ17: 0 | BA17: 0 | BB17: =P17-SUM(AY17:BA17) -> 0 | BC17: 0 | BF17: =G17-AA17-AB17-AC17 -> 0 | BG17: 0 | BH17: 0 | BI17: 0 | BJ17: =J17-BG17-BH17-BI17 -> 3716.2 | BK17: 0 | BL17: 0
B18: Other expense | C18: -3137.384 | D18: -2453.572 | E18: 0 | F18: -1095.587 | G18: -1316.587 | H18: 0 | I18: 0 | J18: 0 | K18: =-846.654 -> -846.654 | L18: -1023.169 | M18: =-866.8 -> -866.8 | N18: -913.801 | O18: -4554.9 | P18: -1013.824 | Q18: =SUM(AZ18:BC18) -> -894.524 | S18: -410.743 | T18: -385.606 | U18: -500.501 | V18: =D18-U18-T18-S18 -> -1156.722 | W18: -154.086 | X18: 0 | Y18: -432.463 | Z18: =E18-Y18-X18-W18 -> 586.549 | AA18: -188.91 | AB18: -283 | AC18: -389.362 | AD18: =F18-AA18-AB18-AC18 -> -234.315 | AE18: 0 | AF18: -293.5 | AG18: 0 | AH18: =H18-AE18-AF18-AG18 -> 293.5 | AI18: -152.9 | AJ18: -398.9 | AK18: -293.662 | AL18: =I18-AI18-AJ18-AK18 -> 845.462 | AM18: -168.3 | AN18: -40.9 | AO18: -291.2 | AP18: =K18-AM18-AN18-AO18 -> -346.254 | AQ18: -182.18 | AR18: -181.2 | AS18: -726.6 | AT18: =M18-AQ18-AR18-AS18 -> 223.18 | AU18: 0 | AV18: -529.6 | AW18: -319.3 | AX18: =O18-SUM(AU18:AW18) -> -3706 | AY18: -198.7 | AZ18: -274.2 | BA18: -43.754 | BB18: =P18-SUM(AY18:BA18) -> -497.17 | BC18: -79.4 | BF18: =G18-AA18-AB18-AC18 -> -455.315 | BG18: -77.6 | BH18: -278.3 | BI18: -232.3 | BJ18: =J18-BG18-BH18-BI18 -> 588.2 | BK18: -179.2 | BL18: -194.8
B19: Operating Profit | C19: =C13+SUM(C15:C18) -> 16598.134 | D19: =D13+SUM(D15:D18) -> 14243.165 | E19: =E13+SUM(E15:E18) -> 20252.525 | F19: =F13+SUM(F15:F18) -> 17209.03 | G19: =G13+SUM(G15:G18) -> 17005.03 | H19: =H13+SUM(H15:H18) -> 17525.368 | I19: =I13+SUM(I15:I18) -> 22183.226 | J19: =J13+SUM(J15:J18) -> 10688.9 | ... Q19: =Q13+SUM(Q15:Q18) -> 4877.292 | S19: =S13+SUM(S15:S18) -> 3030.109 | T19: =T13+SUM(T15:T18) -> 3905.101 | U19: =U13+SUM(U15:U18) -> 3678.149 | V19: =V13+SUM(V15:V18) -> 3629.806 | W19: =W13+SUM(W15:W18) -> 3624.185 | X19: =X13+SUM(X15:X18) -> 8622.273 | Y19: =Y13+SUM(Y15:Y18) -> 4341.806 | Z19: =Z13+SUM(Z15:Z18) -> 3664.261 | ... BC19: =BC13+SUM(BC15:BC18) -> 1542.4 | BF19: =BF13+SUM(BF15:BF18) -> 4828.926 | BG19: =BG13+SUM(BG15:BG18) -> 1820.1 | BH19: =BH13+SUM(BH15:BH18) -> 1658.7 | BI19: =BI13+SUM(BI15:BI18) -> 1845.3 | BJ19: =BJ13+SUM(BJ15:BJ18) -> 5364.8 | BK19: =BK13+SUM(BK15:BK18) -> 1112.4 | BL19: =BL13+SUM(BL15:BL18) -> 793
B20: Finance income | C20: 1499.473 | D20: 3153.54 | E20: 1787.249 | F20: 2464.403 | G20: 2464.403 | H20: 4227.192 | I20: 620.222 | J20: 560 | K20: 2151.109 | L20: 2129.011 | M20: 3307.4 | N20: 3180.192 | O20: 4117.583 | P20: 3226.718 | Q20: =SUM(AZ20:BC20) -> 2178.218 | S20: 1504.788 | T20: 1116.156 | U20: 392.16 | V20: =D20-U20-T20-S20 -> 140.436 | W20: 1297.85 | X20: 1065.149 | Y20: 436.195 | Z20: =E20-Y20-X20-W20 -> -1011.945 | AA20: 435.445 | AB20: 674 | AC20: 920.723 | AD20: =F20-AA20-AB20-AC20 -> 434.235 | AE20: 2422 | AF20: 2803 | AG20: 3353.1 | AH20: =H20-AE20-AF20-AG20 -> -4350.908 | AI20: 121.3 | AJ20: 2156.7 | AK20: 186.032 | AL20: =I20-AI20-AJ20-AK20 -> -1843.81 | AM20: 338.9 | AN20: 1146 | AO20: 1283.4 | AP20: =K20-AM20-AN20-AO20 -> -617.191 | AQ20: 883.42 | AR20: 1318.3 | AS20: 905.4 | AT20: =M20-AQ20-AR20-AS20 -> 200.28 | AU20: 777.8 | AV20: 1282.7 | AW20: 1100.4 | AX20: =O20-SUM(AU20:AW20) -> 956.683 | AY20: 1421.3 | AZ20: 1224.4 | BA20: 1159.194 | BB20: =P20-SUM(AY20:BA20) -> -578.176 | BC20: 372.8 | BF20: =G20-AA20-AB20-AC20 -> 434.235 | BG20: 181.1 | BH20: 1796 | BI20: 204 | BJ20: =J20-BG20-BH20-BI20 -> -1621.1 | BK20: 885.2 | BL20: 1293.6
B21: Finance costs | C21: -11031.585 | D21: -9245.671 | E21: -10566.966 | F21: -11275.198 | G21: -11275.198 | H21: -10482.168 | I21: -12290.187 | J21: =-12478 -> -12478 | K21: -11346.39 | L21: -11385.381 | M21: -7931.7 | N21: -8026.093 | O21: -8812.754 | P21: -7508.6 | Q21: =SUM(AZ21:BC21) -> -7669 | S21: -2286.444 | T21: -2258.077 | U21: -2313.831 | V21: =D21-U21-T21-S21 -> -2387.319 | W21: -3498.519 | X21: -2840.369 | Y21: -2925.538 | Z21: =E21-Y21-X21-W21 -> -1302.54 | AA21: -2709.535 | AB21: -2942.5 | AC21: -3790.923 | AD21: =F21-AA21-AB21-AC21 -> -1832.24 | AE21: -11129.6 | AF21: -2891.9 | AG21: -3043.5 | AH21: =H21-AE21-AF21-AG21 -> 6582.832 | AI21: -4142.9 | AJ21: -2810.1 | AK21: -5078.375 | AL21: =I21-AI21-AJ21-AK21 -> -258.812 | AM21: -5228.6 | AN21: -2214.9 | AO21: -2306.6 | AP21: =K21-AM21-AN21-AO21 -> -1596.29 | AQ21: -3081.995 | AR21: -2069.8 | AS21: -1549.8 | AT21: =M21-AQ21-AR21-AS21 -> -1230.105 | AU21: -1911.2 | AV21: -1872.7 | AW21: -2359.7 | AX21: =O21-SUM(AU21:AW21) -> -2669.154 | AY21: -1850 | AZ21: -2896.8 | BA21: -1834.533 | BB21: =P21-SUM(AY21:BA21) -> -927.267 | BC21: -2010.4 | BF21: =G21-AA21-AB21-AC21 -> -1832.24 | BG21: -3797.1 | BH21: -2802.3 | BI21: -4702.7 | BJ21: =J21-BG21-BH21-BI21 -> -1175.9 | BK21: -3039.9 | BL21: -2123.9
B22: Share of profit (loss) of associates and joint ventures accounted for using equity method | C22: 1139.604 | D22: 1913.273 | E22: 532.933 | F22: 581.023 | G22: 581.023 | H22: -5739.668 | I22: 3558.811 | J22: 3671 | K22: -8453.302 | L22: -7378.249 | M22: -6210.1 | N22: -4086.628 | O22: -182.577 | P22: -578.343 | Q22: =SUM(AZ22:BC22) -> 669.557 | S22: 263.71 | T22: 86.956 | U22: 670.041 | V22: =D22-U22-T22-S22 -> 892.566 | W22: 107.096 | X22: 477.188 | Y22: 326.609 | Z22: =E22-Y22-X22-W22 -> -377.96 | AA22: 165.821 | AB22: 163.8 | AC22: 159.917 | AD22: =F22-AA22-AB22-AC22 -> 91.485 | AE22: -5348.6 | AF22: 137.6 | AG22: -119.9 | AH22: =H22-AE22-AF22-AG22 -> -408.768 | AI22: 51.8 | AJ22: 889.2 | AK22: 1240.248 | AL22: =I22-AI22-AJ22-AK22 -> 1377.563 | AM22: 465.4 | AN22: 4218.6 | AO22: 575.7 | AP22: =K22-AM22-AN22-AO22 -> -13713.002 | AQ22: 96.756 | AR22: 24.9 | AS22: 588.8 | AT22: =M22-AQ22-AR22-AS22 -> -6920.556 | AU22: -356.6 | AV22: 338.3 | AW22: 1736.1 | AX22: =O22-SUM(AU22:AW22) -> -1900.377 | AY22: 91.2 | AZ22: 1211.5 | BA22: 843.03 | BB22: =P22-SUM(AY22:BA22) -> -2724.073 | BC22: 1339.1 | BF22: =G22-AA22-AB22-AC22 -> 91.485 | BG22: 51.8 | BH22: 888.4 | BI22: 1240.2 | BJ22: =J22-BG22-BH22-BI22 -> 1490.6 | BK22: 96.756 | BL22: 24.8
B23: Profit before tax | C23: =SUM(C19,C20,C21,C22) -> 8205.626 | D23: =SUM(D19,D20,D21,D22) -> 10064.307 | E23: =SUM(E19,E20,E21,E22) -> 12005.741 | F23: =SUM(F19,F20,F21,F22) -> 8979.258 | G23: =SUM(G19,G20,G21,G22) -> 8775.258 | H23: =SUM(H19,H20,H21,H22) -> 5530.724 | I23: =SUM(I19,I20,I21,I22) -> 14072.072 | J23: =SUM(J19,J20,J21,J22) -> 2441.9 | ... Q23: =SUM(Q19,Q20,Q21,Q22) -> 56.067 | S23: =SUM(S19,S20,S21,S22) -> 2512.163 | T23: =SUM(T19,T20,T21,T22) -> 2850.136 | U23: =SUM(U19,U20,U21,U22) -> 2426.519 | V23: =SUM(V19,V20,V21,V22) -> 2275.489 | W23: =SUM(W19,W20,W21,W22) -> 1530.612 | X23: =SUM(X19,X20,X21,X22) -> 7324.241 | Y23: =SUM(Y19,Y20,Y21,Y22) -> 2179.072 | Z23: =SUM(Z19,Z20,Z21,Z22) -> 971.816 | ... BC23: =SUM(BC19,BC20,BC21,BC22) -> 1243.9 | BF23: =SUM(BF19,BF20,BF21,BF22) -> 3522.406 | BG23: =SUM(BG19,BG20,BG21,BG22) -> -1744.1 | BH23: =SUM(BH19,BH20,BH21,BH22) -> 1540.8 | BI23: =SUM(BI19,BI20,BI21,BI22) -> -1413.2 | BJ23: =SUM(BJ19,BJ20,BJ21,BJ22) -> 4058.4 | BK23: =SUM(BK19,BK20,BK21,BK22) -> -945.544 | BL23: =SUM(BL19,BL20,BL21,BL22) -> -12.5
B24: Tax income (expenses) | C24: -2872.235 | D24: -4037.931 | E24: -4390.504 | F24: -2776.445 | G24: -2668.445 | H24: -5227.9 | I24: -7493.818 | J24: -1673 | K24: 967.377 | L24: 1352.889 | M24: -2440.9 | N24: -2360.634 | O24: -688.587 | P24: -7926.381 | Q24: =SUM(AZ24:BC24) -> -7891.981 | S24: -798.013 | T24: -968.583 | U24: -906.006 | V24: =D24-U24-T24-S24 -> -1365.329 | W24: -535.715 | X24: -2563.5 | Y24: -699.487 | Z24: =E24-Y24-X24-W24 -> -591.802 | AA24: -503.987 | AB24: -741.9 | AC24: -726.784 | AD24: =F24-AA24-AB24-AC24 -> -803.774 | AE24: 1725.9 | AF24: -752.5 | AG24: -2119.2 | AH24: =H24-AE24-AF24-AG24 -> -4082.1 | AI24: 103.5 | AJ24: -1800 | AK24: -111.462 | AL24: =I24-AI24-AJ24-AK24 -> -5685.856 | AM24: 878.1 | AN24: -1510.9 | AO24: -351.5 | AP24: =K24-AM24-AN24-AO24 -> 1951.677 | AQ24: 187.965 | AR24: -93.1 | AS24: -869 | AT24: =M24-AQ24-AR24-AS24 -> -1666.765 | AU24: -541 | AV24: 84.2 | AW24: -171 | AX24: =O24-SUM(AU24:AW24) -> -60.787 | AY24: -221 | AZ24: 60 | BA24: -3008.176 | BB24: =P24-SUM(AY24:BA24) -> -4757.205 | BC24: -186.6 | BF24: =G24-AA24-AB24-AC24 -> -695.774 | BG24: 762.9 | BH24: -419.6 | BI24: -5 | BJ24: =J24-BG24-BH24-BI24 -> -2011.3 | BK24: 232.2 | BL24: -50.8
B25: Profit (loss) from Continuing Operations | C25: =C23+C24 -> 5333.391 | D25: =D23+D24 -> 6026.376 | E25: =E23+E24 -> 7615.237 | F25: =F23+F24 -> 6202.813 | G25: =G23+G24 -> 6106.813 | H25: =H23+H24 -> 302.824 | I25: =I23+I24 -> 6578.254 | J25: =J23+J24 -> 768.9 | ... Q25: =Q23+Q24 -> -7835.914 | S25: =S23+S24 -> 1714.15 | T25: =T23+T24 -> 1881.553 | U25: =U23+U24 -> 1520.513 | V25: =V23+V24 -> 910.16 | W25: =W23+W24 -> 994.897 | X25: =X23+X24 -> 4760.741 | Y25: =Y23+Y24 -> 1479.585 | Z25: =Z23+Z24 -> 380.014 | ... BC25: =BC23+BC24 -> 1057.3 | BF25: =BF23+BF24 -> 2826.632 | BG25: =BG23+BG24 -> -981.2 | BH25: =BH23+BH24 -> 1121.2 | BI25: =BI23+BI24 -> -1418.2 | BJ25: =BJ23+BJ24 -> 2047.1 | BK25: =BK23+BK24 -> -713.344 | BL25: =BL23+BL24 -> -63.3
B26: Discontinued Operations | C26: 0 | D26: 0 | E26: 0 | F26: 0 | G26: 0 | H26: 0 | I26: 0 | J26: 6585.9 | K26: 55922.583 | L26: 56827.807 | M26: 0 | N26: 628.116 | O26: 56.816 | P26: 0 | Q26: =SUM(AZ26:BC26) -> 0 | S26: 0 | T26: 0 | U26: 0 | V26: =D26-U26-T26-S26 -> 0 | W26: 0 | X26: 0 | Y26: 0 | Z26: =E26-Y26-X26-W26 -> 0 | AA26: 0 | AB26: 0 | AC26: 0 | AD26: =F26-AA26-AB26-AC26 -> 0 | AE26: 0 | AF26: 0 | AG26: 0 | AH26: =H26-AE26-AF26-AG26 -> 0 | AI26: 0 | AJ26: 0 | AK26: 0 | AL26: =I26-AI26-AJ26-AK26 -> 0 | AM26: 54765.4 | AN26: 98.9 | AO26: 739.4 | AP26: =K26-AM26-AN26-AO26 -> 318.883 | AQ26: 0 | AR26: 0 | AS26: 0 | AT26: =M26-AQ26-AR26-AS26 -> 0 | AU26: 56.8 | AV26: 0 | AW26: 0 | AX26: =O26-SUM(AU26:AW26) -> 0.016 | AY26: 0 | AZ26: 0 | BA26: 0 | BB26: =P26-SUM(AY26:BA26) -> 0 | BC26: 0 | BF26: =G26-AA26-AB26-AC26 -> 0 | BG26: 655.4 | BH26: 1300.4 | BI26: 2485.9 | BJ26: =J26-BG26-BH26-BI26 -> 2144.2 | BK26: 3.2 | BL26: 235.8
B27: Profit (loss)/Net Income | C27: =C25+C26 -> 5333.391 | D27: =D25+D26 -> 6026.376 | E27: =E25+E26 -> 7615.237 | F27: =F25+F26 -> 6202.813 | G27: =G25+G26 -> 6106.813 | H27: =H25+H26 -> 302.824 | I27: =I25+I26 -> 6578.254 | J27: =J25+J26 -> 7354.8 | ... Q27: =Q25+Q26 -> -7835.914 | S27: =S25+S26 -> 1714.15 | T27: =T25+T26 -> 1881.553 | U27: =U25+U26 -> 1520.513 | V27: =V25+V26 -> 910.16 | W27: =W25+W26 -> 994.897 | X27: =X25+X26 -> 4760.741 | Y27: =Y25+Y26 -> 1479.585 | Z27: =Z25+Z26 -> 380.014 | ... BC27: =BC25+BC26 -> 1057.3 | BF27: =BF25+BF26 -> 2826.632 | BG27: =BG25+BG26 -> -325.8 | BH27: =BH25+BH26 -> 2421.6 | BI27: =BI25+BI26 -> 1067.7 | BJ27: =BJ25+BJ26 -> 4191.3 | BK27: =BK25+BK26 -> -710.144 | BL27: =BL25+BL26 -> 172.5
B29: % of Net sales or stated otherwise
B30: =B12 -> COGS | C30: =-C12/C9 -> 0.54397346 | D30: =-D12/D9 -> 0.56614522 | E30: =-E12/E9 -> 0.57106985 | F30: =-F12/F9 -> 0.57861957 | G30: =-G12/G9 -> 0.58047365 | H30: =-H12/H9 -> 0.58533996 | I30: =-I12/I9 -> 0.57535232 | J30: =-J12/J9 -> 0.63117564 | ... Q30: =-Q12/Q9 -> 0.61662195 | S30: =-S12/S9 -> 0.57644799 | T30: =-T12/T9 -> 0.55798854 | U30: =-U12/U9 -> 0.55562039 | V30: =-V12/V9 -> 0.5738302 | W30: =-W12/W9 -> 0.57253235 | X30: =-X12/X9 -> 0.56474668 | Y30: =-Y12/Y9 -> 0.56758629 | Z30: =-Z12/Z9 -> 0.579399 | ... BC30: =-BC12/BC9 -> 0.60926098 | BF30: =-BF12/BF9 -> 0.60284764 | BG30: =-BG12/BG9 -> 0.6316175 | BH30: =-BH12/BH9 -> 0.64414119 | BI30: =-BI12/BI9 -> 0.6189262 | BJ30: =-BJ12/BJ9 -> 0.63012571 | BK30: =-BK12/BK9 -> 0.63955758 | BL30: =-BL12/BL9 -> 0.64681287
B31: =B15 -> Distribution costs | C31: =-C15/C9 -> 0.11320998 | D31: =-D15/D9 -> 0.11162539 | E31: =-E15/E9 -> 0.10883902 | F31: =-F15/F9 -> 0.11028447 | G31: =-G15/G9 -> 0.10907349 | H31: =-H15/H9 -> 0.10647502 | I31: =-I15/I9 -> 0.10104387 | J31: =-J15/J9 -> 0.10957933 | ... Q31: =-Q15/Q9 -> 0.1275828 | S31: =-S15/S9 -> 0.11876343 | T31: =-T15/T9 -> 0.10838163 | U31: =-U15/U9 -> 0.10909946 | V31: =-V15/V9 -> 0.11066609 | W31: =-W15/W9 -> 0.11315843 | X31: =-X15/X9 -> 0.10659806 | Y31: =-Y15/Y9 -> 0.10424872 | Z31: =-Z15/Z9 -> 0.11168968 | ... BC31: =-BC15/BC9 -> 0.12131611 | BF31: =-BF15/BF9 -> 0.097451761 | BG31: =-BG15/BG9 -> 0.10970298 | BH31: =-BH15/BH9 -> 0.10666941 | BI31: =-BI15/BI9 -> 0.10943997 | BJ31: =-BJ15/BJ9 -> 0.1124536 | BK31: =-BK15/BK9 -> 0.12909695 | BL31: =-BL15/BL9 -> 0.12792251
B32: General and Administrative expenses | C32: =-C16/C9 -> 0.13785186 | D32: =-D16/D9 -> 0.14381914 | E32: =-E16/E9 -> 0.13555503 | F32: =-F16/F9 -> 0.13074102 | G32: =-G16/G9 -> 0.13040054 | H32: =-H16/H9 -> 0.1305818 | I32: =-I16/I9 -> 0.1324435 | J32: =-J16/J9 -> 0.16491151 | ... Q32: =-Q16/Q9 -> 0.15699163 | S32: =-S16/S9 -> 0.14806065 | T32: =-T16/T9 -> 0.14688899 | U32: =-U16/U9 -> 0.15089812 | V32: =-V16/V9 -> 0.13135053 | W32: =-W16/W9 -> 0.14868275 | X32: =-X16/X9 -> 0.1270078 | Y32: =-Y16/Y9 -> 0.13744751 | Z32: =-Z16/Z9 -> 0.13111826 | ... BC32: =-BC16/BC9 -> 0.15767097 | BF32: =-BF16/BF9 -> 0.11276846 | BG32: =-BG16/BG9 -> 0.1533822 | BH32: =-BH16/BH9 -> 0.14433877 | BI32: =-BI16/BI9 -> 0.15987542 | BJ32: =-BJ16/BJ9 -> 0.20110361 | BK32: =-BK16/BK9 -> 0.15425021 | BL32: =-BL16/BL9 -> 0.1660926
B33: =B18 -> Other expense | C33: =-C18/C9 -> 0.032583536 | D33: =-D18/D9 -> 0.026217241 | E33: =-E18/E9 -> 0 | F33: =-F18/F9 -> 0.010794792 | G33: =-G18/G9 -> 0.012938517 | H33: =-H18/H9 -> 0 | I33: =-I18/I9 -> 0 | J33: =-J18/J9 -> 0 | ... Q33: =-Q18/Q9 -> 0.015312721 | S33: =-S18/S9 -> 0.018709 | T33: =-T18/T9 -> 0.016782407 | U33: =-U18/U9 -> 0.022084499 | V33: =-V18/V9 -> 0.04450283 | W33: =-W18/W9 -> 0.0067546028 | X33: =-X18/X9 -> 0 | Y33: =-Y18/Y9 -> 0.017275578 | Z33: =-Z18/Z9 -> -0.021939122 | ... BC33: =-BC18/BC9 -> 0.0054711456 | BF33: =-BF18/BF9 -> 0.01610695 | BG33: =-BG18/BG9 -> 0.0043057767 | BH33: =-BH18/BH9 -> 0.015064496 | BI33: =-BI18/BI9 -> 0.012495898 | BJ33: =-BJ18/BJ9 -> -0.03123888 | BK33: =-BK18/BK9 -> 0.0106964 | BL33: =-BL18/BL9 -> 0.011669073
B34: =B17 -> Other income | C34: =C17/C12 -> 0 | D34: =D17/D12 -> 0 | E34: =E17/E12 -> -0.027010784 | F34: =F17/F12 -> 0 | G34: =G17/G12 -> 0 | H34: =H17/H12 -> -0.0040994809 | I34: =I17/I12 -> -0.040193114 | J34: =J17/J12 -> -0.079655161 | ... Q34: =Q17/Q12 -> 0 | S34: =S17/S12 -> 0 | T34: =T17/T12 -> 0 | U34: =U17/U12 -> 0 | V34: =V17/V12 -> 0 | W34: =W17/W12 -> 0 | X34: =X17/X12 -> -0.2147199 | Y34: =Y17/Y12 -> 0 | Z34: =Z17/Z12 -> 0.1081727 | ... AH34: =AH17/AH12 -> 0.046458886 | AI34: =AI18/AI12 -> 0.011012201 | AJ34: =AJ18/AJ12 -> 0.027424666 | AK34: =AK17/AK12 -> 0 | AL34: =AL17/AL12 -> -0.15177165 | AM34: =AM17/AM12 -> 0 | AN34: =AN18/AN12 -> 0.0034520011 | AO34: =AO17/AO12 -> 0 | AP34: =AP17/AP12 -> 0 | AQ34: =AQ17/AQ12 -> 0 | AR34: =AR18/AR12 -> 0.014945809 | AS34: =AS17/AS12 -> 0 | AT34: =AT17/AT12 -> 0 | AU34: =AU17/AU12 -> -0.22024799 | AV34: =AV18/AV12 -> 0.050406411 | AW34: =AW17/AW12 -> 0 | AX34: =AX17/AX12 -> 0.22363447 | AY34: =AY17/AY12 -> 0 | AZ34: =AZ18/AZ12 -> 0.030400124 | BA34: =BA17/BA12 -> 0 | BB34: =BB17/BB12 -> 0 | BC34: =BC17/BC12 -> 0 | BF34: =BF17/BF12 -> 0 | BG34: =BG18/BG12 -> 0.0068170637 | BH34: =BH18/BH12 -> 0.023386948 | BI34: =BI18/BI12 -> 0.020189642 | BJ34: =BJ18/BJ12 -> -0.049575632 | BK34: =BK17/BK12 -> 0 | BL34: =BL17/BL12 -> 0
B35: =B19 -> Operating Profit | C35: =C19/C9 -> 0.17238116 | D35: =D19/D9 -> 0.152193 | E35: =E19/E9 -> 0.19996115 | F35: =F19/F9 -> 0.16956016 | G35: =G19/G9 -> 0.16711381 | H35: =H19/H9 -> 0.18000281 | I35: =I19/I9 -> 0.2142855 | J35: =J19/J9 -> 0.14460992 | ... Q35: =Q19/Q9 -> 0.083490899 | S35: =S19/S9 -> 0.13801893 | T35: =T19/T9 -> 0.16995844 | U35: =U19/U9 -> 0.16229753 | V35: =V19/V9 -> 0.13965036 | W35: =W19/W9 -> 0.15887187 | X35: =X19/X9 -> 0.3229098 | Y35: =Y19/Y9 -> 0.17344191 | Z35: =Z19/Z9 -> 0.13705704 | ... BC35: =BC19/BC9 -> 0.10628079 | BF35: =BF19/BF9 -> 0.17082519 | BG35: =BG19/BG9 -> 0.10099155 | BH35: =BH19/BH9 -> 0.089786131 | BI35: =BI19/BI9 -> 0.099262511 | BJ35: =BJ19/BJ9 -> 0.28492068 | BK35: =BK19/BK9 -> 0.066398859 | BL35: =BL19/BL9 -> 0.04750295
B36: Finance Income as a % of cash at end of period | C36: =C20/C113 -> 0.031537256 | D36: =D20/D113 -> 0.081413299 | E36: =E20/E113 -> 0.055732593 | F36: =F20/F113 -> 0.089771356 | G36: =G20/G113 -> 0.08977048 | H36: =H20/H113 -> 0.14547383 | I36: =I20/I113 -> 0.024233706 | J36: =J20/J113 -> 0.021681728 | ... Q36: =Q20/Q113 -> 0.087209651 | S36: =SUM(S20:S20)/S113 -> 0.034562412 | T36: =SUM(S20:T20)/T113 -> 0.063580082 | U36: =SUM(S20:U20)/U113 -> 0.077941452 | V36: =SUM(S20:V20)/V113 -> 0.081413299 | W36: =SUM(T20:W20)/W113 -> 0.078147901 | X36: =SUM(U20:X20)/X113 -> 0.064933856 | Y36: =SUM(V20:Y20)/Y113 -> 0.069287172 | Z36: =SUM(W20:Z20)/Z113 -> 0.055732593 | AA36: =SUM(X20:AA20)/AA113 -> 0.039249818 | AB36: =SUM(Y20:AB20)/AB113 -> 0.01407494 | AC36: =SUM(Z20:AC20)/AC113 -> 0.026303252 | ... BC36: =SUM(AZ20:BC20)/BC113 -> 0.087209651 | BF36: =SUM(AA20:AC20, BF20)/AD113 -> 0.089771356 | BG36: =SUM(AF20:AH20,BG20)/AI113 -> 0.068819824 | BH36: =SUM(AG20:AI20,BH20)/AJ113 -> 0.034853931 | BI36: =SUM(AH20:AJ20,BI20)/AK113 -> -0.086105818 | BJ36: =SUM(AI20:AK20, BJ20)/AL113 -> 0.032935571 | BK36: =SUM(BH20:BK20)/AQ113 -> 0.029026732 | BL36: =SUM(BI20:BL20)/AR113 -> 0.019579316
B37: Finance costs as a % of debt at end of period | C37: =-C21/C110 -> 0.079798853 | D37: =-D21/D110 -> 0.070252175 | E37: =-E21/E110 -> 0.081367787 | F37: =-F21/F110 -> 0.085661979 | G37: =-G21/G110 -> 0.085661993 | H37: =-H21/H110 -> 0.079503526 | I37: =-I21/I110 -> 0.090720764 | J37: =-J21/J110 -> 0.092107118 | ... Q37: =-Q21/Q110 -> 0.086598809 | S37: =-SUM(S21:S21)/S110 -> 0.017808708 | T37: =-SUM(S21:T21)/T110 -> 0.036198141 | U37: =-SUM(S21:U21)/U110 -> 0.054786959 | V37: =-SUM(S21:V21)/V110 -> 0.07026611 | W37: =-SUM(T21:W21)/W110 -> 0.083896475 | X37: =-SUM(U21:X21)/X110 -> 0.084481402 | Y37: =-SUM(V21:Y21)/Y110 -> 0.09238303 | Z37: =-SUM(W21:Z21)/Z110 -> 0.081367787 | AA37: =-SUM(X21:AA21)/AA110 -> 0.073965346 | AB37: =-SUM(Y21:AB21)/AB110 -> 0.068182112 | AC37: =-SUM(Z21:AC21)/AC110 -> 0.073730855 | ... BC37: =-SUM(AZ21:BC21)/BC110 -> 0.086598809 | BF37: =-SUM(AA21:AC21,BF21)/AD110 -> 0.085661979 | BG37: =SUM(AF21:AH21,BG21)/AI110 -> -0.023529674 | BH37: =SUM(AG21:AI21,BH21)/AJ110 -> -0.025978309 | BI37: =SUM(AH21:AJ21,BI21)/AK110 -> -0.037676374 | BJ37: =-SUM(AE21:AG21,BJ21)/AH110 -> 0.13835076 | BK37: =-SUM(BH21:BK21)/AQ110 -> 0.10957736 | BL37: =-SUM(BI21:BL21)/AR110 -> 0.10705145
B38: =B23 -> Profit before tax | C38: =C23/C9 -> 0.085220143 | D38: =D23/D9 -> 0.1075405 | E38: =E23/E9 -> 0.1185374 | F38: =F23/F9 -> 0.088472411 | G38: =G23/G9 -> 0.086237236 | H38: =H23/H9 -> 0.05680599 | I38: =I23/I9 -> 0.13593339 | J38: =J23/J9 -> 0.033036417 | ... Q38: =Q23/Q9 -> 0.00095977116 | S38: =S23/S9 -> 0.11442692 | T38: =T23/T9 -> 0.12404408 | U38: =U23/U9 -> 0.10706963 | V38: =V23/V9 -> 0.087545408 | W38: =W23/W9 -> 0.067096791 | X38: =X23/X9 -> 0.27429765 | Y38: =Y23/Y9 -> 0.087047281 | Z38: =Z23/Z9 -> 0.036349545 | ... BC38: =BC23/BC9 -> 0.085712317 | BF38: =BF23/BF9 -> 0.12460652 | BG38: =BG23/BG9 -> -0.096774552 | BH38: =BH23/BH9 -> 0.083404154 | BI38: =BI23/BI9 -> -0.076018956 | BJ38: =BJ23/BJ9 -> 0.21553871 | BK38: =BK23/BK9 -> -0.056439269 | BL38: =BL23/BL9 -> -0.00074878547
B39: Income tax benefit/(expense) as a % of Profit before tax | C39: =-C24/C23 -> 0.3500324 | D39: =-D24/D23 -> 0.40121302 | E39: =-E24/E23 -> 0.36570038 | F39: =-F24/F23 -> 0.30920651 | G39: =-G24/G23 -> 0.30408736 | H39: =-H24/H23 -> 0.94524695 | I39: =-I24/I23 -> 0.53253124 | J39: =-J24/J23 -> 0.68512224 | ... Q39: =-Q24/Q23 -> 140.75982 | S39: =-S24/S23 -> 0.31765972 | T39: =-T24/T23 -> 0.33983747 | U39: =-U24/U23 -> 0.37337684 | V39: =-V24/V23 -> 0.60001564 | W39: =-W24/W23 -> 0.35000052 | X39: =-X24/X23 -> 0.35000214 | Y39: =-Y24/Y23 -> 0.32100224 | Z39: =-Z24/Z23 -> 0.60896507 | ... BC39: =-BC24/BC23 -> 0.15001206 | BF39: =-BF24/BF23 -> 0.19752805 | BG39: =-BG24/BG23 -> 0.43741758 | BH39: =-BH24/BH23 -> 0.27232606 | BI39: =-BI24/BI23 -> -0.0035380696 | BJ39: =-BJ24/BJ23 -> 0.49558939 | BK39: =-BK24/BK23 -> 0.24557292 | BL39: =-BL24/BL23 -> -4.064
B41: capex/sales | C41: =-C63/C9 -> 0.27387149 | D41: =-D63/D9 -> 0.16934222 | E41: =-E63/E9 -> 0.17253716 | F41: =-F63/F9 -> 0.17860273 | G41: =-G63/G9 -> 0.17813761 | H41: =-H63/H9 -> 0.19115662 | I41: =-I63/I9 -> 0.21826724 | J41: =-J63/J9 -> 0.30569304 | ... Q41: =-Q63/Q9 -> 0.21771656 | S41: =-S63/S9 -> 0.19874225 | T41: =-T63/T9 -> 0.13048301 | U41: =-U63/U9 -> 0.15764325 | V41: =-V63/V9 -> 0.18906118 | W41: =-W63/W9 -> 0.12477977 | X41: =-X63/X9 -> 0.14097866 | Y41: =-Y63/Y9 -> 0.20665696 | Z41: =-Z63/Z9 -> 0.21285772 | ... BC41: =-BC63/BC9 -> 0.16800496 | BF41: =-BF63/BF9 -> 0 | BG41: =-BG63/BG9 -> 0 | BH41: =-BH63/BH9 -> 0 | BI41: =-BI63/BI9 -> 0 | BJ41: =-BJ63/BJ9 -> 0 | BK41: =-BK63/BK9 -> 0 | BL41: =-BL63/BL9 -> 0
B42: D/A/sales | C42: =C46/C9 -> 0.17634533 | D42: =D46/D9 -> 0.19772963 | E42: =E46/E9 -> 0.19583386 | F42: =F46/F9 -> 0.20699679 | G42: =G46/G9 -> 0.20646008 | H42: =H46/H9 -> 0.21836925 | I42: =I46/I9 -> 0.20689714 | J42: =J46/J9 -> 0.2897687 | ... Q42: =Q46/Q9 -> 0.2904993 | S42: =S46/S9 -> 0.20696779 | T42: =T46/T9 -> 0.19927444 | U42: =U46/U9 -> 0.20338049 | V42: =V46/V9 -> 0.18363391 | W42: =W46/W9 -> 0.21045068 | X42: =X46/X9 -> 0.18156544 | Y42: =Y46/Y9 -> 0.20124487 | Z42: =Z46/Z9 -> 0.19254603 | ... BC42: =BC46/BC9 -> 0.29363652 | BF42: =BF46/BF9 -> 0.19075731 | BG42: =BG46/BG9 -> 0.25846867 | BH42: =BH46/BH9 -> 0.27568624 | BI42: =BI46/BI9 -> 0.27108515 | BJ42: =BJ46/BJ9 -> 0.35199075 | BK42: =BK46/BK9 -> 0.31177738 | BL42: =BL46/BL9 -> 0.31203388
B44: EBITDA | C44: =+C3 -> 42735 | D44: =+D3 -> 43100 | E44: =E3 -> 43465 | F44: =F3 -> 43830 | G44: =G3 -> 43830 | H44: =H3 -> 44196 | I44: =I3 -> 44561 | J44: =J3 -> 44561 | K44: =K3 -> 44926 | L44: =L3 -> 44926 | ... P44: =P3 -> 46022 | Q44: =+Q3 -> 46112 | S44: =+S3 -> 42825 | T44: =+T3 -> 42916 | U44: =+U3 -> 43008 | V44: =+V3 -> 43100 | W44: =+W3 -> 43190 | X44: =X3 -> 43281 | Y44: =Y3 -> 43373 | Z44: =Z3 -> 43465 | AA44: =+AA3 -> 43555 | AB44: =AB3 -> 43646 | AC44: =+AC3 -> 43738 | AD44: =+AD3 -> 43830 | AE44: =+AE3 -> 43921 | AF44: =+AF3 -> 44012 | AG44: =+AG3 -> 44104 | AH44: =+AH3 -> 44196 | AI44: =+AI3 -> 44286 | AJ44: =+AJ3 -> 44377 | ... BC44: =+BC3 -> 46112 | BF44: =+BF3 -> 43830 | BG44: =+BG3 -> 44286 | BH44: =+BH3 -> 44377 | BI44: =+BI3 -> 44469 | BJ44: =+BJ3 -> 44561 | BK44: =+BK3 -> 45016 | BL44: =+BL3 -> 45107
...

Sheet KPIS
B2: Grupo Televisa, S.A.B. | C2: Annual | D2: Annual | E2: Annual | F2: Annual | G2: Annual | H2: Annual | I2: Annual | J2: Annual | K2: Annual | L2: Annual | M2: Annual | N2: Annual | O2: Annual | P2: Annual | Q2: LTM | S2: Quarterly | T2: Quarterly | U2: Quarterly | V2: Quarterly | W2: Quarterly | X2: Quarterly | Y2: Quarterly | Z2: Quarterly | AA2: Quarterly | AB2: Quarterly | AC2: Quarterly | AD2: Quarterly | AE2: Quarterly | AF2: Quarterly | AG2: Quarterly | AH2: Quarterly | AI2: Quarterly | AJ2: Quarterly | AK2: Quarterly | AL2: Quarterly | AM2: Quarterly | AN2: Quarterly | AO2: Quarterly | AP2: Quarterly | AQ2: Quarterly | AR2: Quarterly | AS2: Quarterly | AT2: Quarterly | AU2: Quarterly | AV2: Quarterly | AW2: Quarterly | AX2: Quarterly | AY2: Quarterly | AZ2: Quarterly | BA2: Quarterly | BB2: Quarterly | BC2: Quarterly | BF2: Quarterly | BG2: Quarterly | BH2: Quarterly | BI2: Quarterly | BJ2: Quarterly
B3: (MXN millions) | C3: 42707 | D3: 43100 | E3: 43465 | F3: 43830 | G3: 43830 | H3: 44196 | I3: 44561 | J3: 44561 | K3: 44926 | L3: 44926 | M3: 45291 | N3: 45291 | O3: 45657 | P3: 46022 | Q3: =BC3 -> 46112 | S3: 42801 | T3: 42892 | U3: 42987 | V3: 43079 | W3: 43190 | X3: 43281 | Y3: 43373 | Z3: 43465 | AA3: 43555 | AB3: 43646 | AC3: 43738 | AD3: 43830 | AE3: 43921 | AF3: 44012 | AG3: 44104 | AH3: 44196 | AI3: 44286 | AJ3: 44377 | AK3: 44469 | AL3: 44561 | AM3: 44651 | AN3: 44742 | AO3: 44834 | AP3: 44926 | AQ3: 45016 | AR3: 45107 | AS3: 45199 | AT3: 45291 | AU3: 45382 | AV3: 45473 | AW3: 45565 | AX3: 45657 | AY3: 45747 | AZ3: 45838 | BA3: 45930 | BB3: 46022 | BC3: 46112 | BF3: 43830 | BG3: 44286 | BH3: 44377 | BI3: 44469 | BJ3: 44560
C4: Act | D4: Act | E4: Act | F4: Act | G4: Act | H4: Act | I4: Act | J4: Act | K4: Act | L4: Act | M4: Act | N4: Act | O4: Act | P4: Act | Q4: Act | S4: Act | T4: Act | U4: Act | V4: Act | W4: Act | X4: Act | Y4: Act | Z4: Act | AA4: Act | AB4: Act | AC4: Act | AD4: Act | AE4: Act | AF4: Act | AG4: Act | AH4: Act | AI4: Act | AJ4: Act | AK4: Act | AL4: Act | AM4: Act | AN4: Act | AO4: Act | AP4: Act | AQ4: Act | AR4: Act | AS4: Act | AT4: Act | AU4: Act | AV4: Act | AW4: Act | AX4: Act | AY4: Act | AZ4: Act | BA4: Act | BB4: Act | BC4: Act
C5: FY | D5: FY | E5: FY | F5: FY | G5: FY | H5: FY | I5: FY | J5: FY | K5: FY | L5: FY | M5: FY | N5: FY | O5: FY | P5: FY | Q5: LTM | S5: Q1 | T5: Q2 | U5: Q3 | V5: Q4 | W5: Q1 | X5: Q2 | Y5: Q3 | Z5: Q4 | AA5: Q1 | AB5: Q2 | AC5: Q3 | AD5: Q4 | AE5: Q1 | AF5: Q2 | AG5: Q3 | AH5: Q4 | AI5: Q1 | AJ5: Q2 | AK5: Q3 | AL5: Q4 | AM5: Q1 | AN5: Q2 | AO5: Q3 | AP5: Q4 | AQ5: Q1 | AR5: Q2 | AS5: Q3 | AT5: Q4 | AU5: Q1 | AV5: Q2 | AW5: Q3 | AX5: Q4 | AY5: Q1 | AZ5: Q2 | BA5: Q3 | BB5: Q4 | BC5: Q1 | BF5: Q4 | BG5: Q1 | BH5: Q2 | BI5: Q3 | BJ5: Q4
G6: Restated | J6: Restated | L6: Restated | N6: Restated | BF6: Restated | BG6: Restated | BH6: Restated | BI6: Restated | BJ6: Restated
B8: Net Sales by Business Segment
B9: Subtotal Content | D9: 33997.2 | T9: 8075.9 | U9: 8024.9
B10: World Cup rights
B11: Content | C11: 36686.7 | D11: =+D9+D10 -> 33997.2 | E11: 36490.1 | F11: 34795.5 | G11: 35060.5 | H11: 32613 | I11: 35941.918 | J11: 0 | K11: 0 | L11: 0 | M11: 0 | N11: 0 | O11: 0 | S11: 7290.7 | T11: =+T9+T10 -> 8075.9 | U11: =+U9+U10 -> 8024.9 | V11: =D11-U11-T11-S11 -> 10605.7 | W11: 7899.4 | X11: 9247.9 | Y11: 8700 | Z11: =E11-Y11-X11-W11 -> 10642.8 | AA11: 7184.9 | AB11: 8050 | AC11: 8659 | AD11: =F11-AC11-AB11-AA11 -> 10901.6 | AE11: 6727.6 | AF11: 6740.6 | AG11: 8033.4 | AH11: =H11-AG11-AF11-AE11 -> 11111.4 | AI11: 7416.1 | AJ11: 7856.8 | AK11: 9109.8 | AL11: =I11-AK11-AJ11-AI11 -> 11559.218 | AM11: 0 | AN11: 0 | AO11: 0 | AP11: =K11-AO11-AN11-AM11 -> 0 | AQ11: 0 | AR11: 0 | AS11: 0 | AT11: =N11-AS11-AR11-AQ11 -> 0 | AU11: 0 | AV11: 0 | AW11: 0 | AX11: =O11-SUM(AU11:AW11) -> 0 | AY11: 0 | AZ11: 0 | BA11: 0 | BC11: 0 | BF11: =G11-AC11-AB11-AA11 -> 11166.6 | BG11: 0 | BH11: 0 | BI11: 0 | BJ11: =J11-BG11-BH11-BI11 -> 0
B12: Sky | C12: 21941.2 | D12: 22196.6 | E12: 22002.2 | F12: 21347.1 | G12: 21347.1 | H12: 22134.7 | I12: 22026.616 | J12: 22026.616 | K12: 20339.038 | L12: 20339.038 | M12: 17585.2 | N12: 17585.175 | O12: 15337.288 | S12: 5540.6 | T12: 5641.9 | U12: 5445.2 | V12: =D12-U12-T12-S12 -> 5568.9 | W12: 5474.2 | X12: 5658.8 | Y12: 5407.3 | Z12: =E12-Y12-X12-W12 -> 5461.9 | AA12: 5281.6 | AB12: 5348.1 | AC12: 5338.3 | AD12: =F12-AC12-AB12-AA12 -> 5379.1 | AE12: 5405.3 | AF12: 5514.7 | AG12: 5597.9 | AH12: =H12-AG12-AF12-AE12 -> 5616.8 | AI12: 5624.8 | AJ12: 5570.1 | AK12: 5459.4 | AL12: =J12-AK12-AJ12-AI12 -> 5372.316 | AM12: 5275.7 | AN12: 5140.1 | AO12: 4986.6 | AP12: =K12-AO12-AN12-AM12 -> 4936.638 | AQ12: 4657.6 | AR12: 4449.5 | AS12: 4296.6 | AT12: =N12-AS12-AR12-AQ12 -> 4181.475 | AU12: 4083.6 | AV12: 3858.3 | AW12: 3731.1 | AX12: =O12-SUM(AU12:AW12) -> 3664.288 | AY12: 3544 | AZ12: 3229.5 | BA12: 3051 | BC12: 3544 | BF12: =G12-AC12-AB12-AA12 -> 5379.1 | BG12: 5624.8 | BH12: 5570.1 | BI12: 5459.4 | BJ12: =J12-BG12-BH12-BI12 -> 5372.316
B13: Cable | C13: 31891.6 | D13: 33048.3 | E13: 36233 | F13: 41702 | G13: 41702 | H13: 45367.1 | I13: 48020.929 | J13: 48020.929 | K13: 48411.776 | L13: 48411.776 | M13: 48802.5 | N13: 48802.544 | O13: 47393.111 | S13: 8096.3 | T13: 8036.7 | U13: 8322.5 | V13: =D13-U13-T13-S13 -> 8592.8 | W13: 8669.7 | X13: 8825.7 | Y13: 9219.9 | Z13: =E13-Y13-X13-W13 -> 9517.7 | AA13: 9898.1 | AB13: 10215.7 | AC13: 10572.1 | AD13: =F13-AC13-AB13-AA13 -> 11016.1 | AE13: 10824.7 | AF13: 11308.8 | AG13: 11407.9 | AH13: =H13-AG13-AF13-AE13 -> 11825.7 | AI13: 11676.5 | AJ13: 11981.6 | AK13: 12066.6 | AL13: =J13-AK13-AJ13-AI13 -> 12296.229 | AM13: 11804.5 | AN13: 11750 | AO13: 12394 | AP13: =K13-AO13-AN13-AM13 -> 12463.276 | AQ13: 12122.7 | AR13: 12291.5 | AS13: 12147.9 | AT13: =N13-AS13-AR13-AQ13 -> 12240.444 | AU13: 11908.7 | AV13: 11904.8 | AW13: 11675.4 | AX13: =O13-SUM(AU13:AW13) -> 11904.211 | AY13: 11537.7 | AZ13: 11602 | BA13: 11679.8 | BC13: 11537.7 | BF13: =G13-AC13-AB13-AA13 -> 11016.1 | BG13: 11676.5 | BH13: 11981.6 | BI13: 12066.6 | BJ13: =J13-BG13-BH13-BI13 -> 12296.229
B14: Other Businesses | C14: 8828.3 | D14: 7688.3 | E14: 8635.5 | F14: 8200.3 | G14: 8200.3 | H14: 4276 | I14: 5029.067 | J14: 4388.2 | K14: 7338.79 | L14: 0 | M14: 7870.6 | N14: 0 | O14: 0 | S14: 1758.6 | T14: 2009.6 | U14: 1801.7 | V14: =D14-U14-T14-S14 -> 2118.4 | W14: 1778.4 | X14: 2312.6 | Y14: 1946.5 | Z14: =E14-Y14-X14-W14 -> 2598 | AA14: 2260.3 | AB14: 1946.5 | AC14: 2633.1 | AD14: =F14-AC14-AB14-AA14 -> 1360.4 | AE14: 1756.5 | AF14: 567.1 | AG14: 782.5 | AH14: =H14-AG14-AF14-AE14 -> 1169.9 | AI14: 951.5 | AJ14: 1220.2 | AK14: 1409.1 | AL14: =J14-AK14-AJ14-AI14 -> 807.4 | AM14: 1661.1 | AN14: 1742.7 | AO14: 1932.7 | AP14: =K14-AO14-AN14-AM14 -> 2002.29 | AQ14: 1850.3 | AR14: 1917.6 | AS14: 1974.7 | AT14: =N14-AS14-AR14-AQ14 -> -5742.6 | AU14: 0 | AV14: 0 | AW14: 0 | AX14: =O14-SUM(AU14:AW14) -> 0 | AY14: 0 | AZ14: 0 | BA14: 0 | BC14: 0 | BF14: =G14-AC14-AB14-AA14 -> 1360.4 | BG14: 859.5 | BH14: 1051.1 | BI14: 1174.2 | BJ14: =J14-BG14-BH14-BI14 -> 1303.4
B15: Segment Net Sales | C15: =+C11+C12+C13+C14 -> 99347.8 | D15: =+D11+D12+D13+D14 -> 96930.4 | E15: =+E11+E12+E13+E14 -> 103360.8 | F15: =+F11+F12+F13+F14 -> 106044.9 | G15: =+G11+G12+G13+G14 -> 106309.9 | H15: =+H11+H12+H13+H14 -> 104390.8 | I15: =+I11+I12+I13+I14 -> 111018.53 | J15: =+J11+J12+J13+J14 -> 74435.745 | ... O15: =+O11+O12+O13+O14 -> 62730.399 | S15: =+S11+S12+S13+S14 -> 22686.2 | T15: =+T11+T12+T13+T14 -> 23764.1 | U15: =+U11+U12+U13+U14 -> 23594.3 | V15: =+V11+V12+V13+V14 -> 26885.8 | W15: =+W11+W12+W13+W14 -> 23821.7 | X15: =+X11+X12+X13+X14 -> 26045 | Y15: =+Y11+Y12+Y13+Y14 -> 25273.7 | Z15: =+Z11+Z12+Z13+Z14 -> 28220.4 | ... BA15: =+BA11+BA12+BA13+BA14 -> 14730.8 | BC15: =+BC11+BC12+BC13+BC14 -> 15081.7 | BF15: =+BF11+BF12+BF13+BF14 -> 28922.2 | BG15: =+BG11+BG12+BG13+BG14 -> 18160.8 | BH15: =+BH11+BH12+BH13+BH14 -> 18602.8 | BI15: =+BI11+BI12+BI13+BI14 -> 18700.2 | BJ15: =J15-BG15-BH15-BI15 -> 18971.945
B16: Intersegment Operations | C16: -3060.4 | D16: -3344.2 | E16: -4812.1 | F16: -5394.1 | G16: -5394.1 | H16: -7252.5 | I16: -7496.707 | J16: -520.3 | K16: -562.995 | L16: -135.046 | M16: -490.4 | N16: -164.883 | O16: -469.535 | S16: -731.9 | T16: -787.3 | U16: -931.3 | V16: =D16-U16-T16-S16 -> -893.7 | W16: -1009.7 | X16: -1066.7 | Y16: -1250.6 | Z16: =E16-Y16-X16-W16 -> -1485.1 | AA16: -1229.7 | AB16: -1252.7 | AC16: -1416.4 | AD16: =F16-AC16-AB16-AA16 -> -1495.3 | AE16: -1632.8 | AF16: -1799.8 | AG16: -1878.7 | AH16: =H16-AG16-AF16-AE16 -> -1941.2 | AI16: -1840 | AJ16: -1875.5 | AK16: -1917 | AL16: =J16-AK16-AJ16-AI16 -> 5112.2 | AM16: -132.1 | AN16: -99.3 | AO16: -61.6 | AP16: =K16-AO16-AN16-AM16 -> -269.995 | AQ16: -111 | AR16: -138.4 | AS16: -103.5 | AT16: =N16-AS16-AR16-AQ16 -> 188.017 | AU16: -40.9 | AV16: -42.8 | AW16: -43.7 | AX16: =O16-SUM(AU16:AW16) -> -342.135 | AY16: -108.1 | AZ16: -102.1 | BA16: -103.8 | BC16: -108.1 | BF16: =G16-AC16-AB16-AA16 -> -1495.3 | BG16: -138.5 | BH16: -128.9 | BI16: -110.1 | BJ16: =J16-BG16-BH16-BI16 -> -142.8
B17: Net Sales (LFL) | C17: =+C15+C16 -> 96287.4 | D17: =+D15+D16 -> 93586.2 | E17: =+E15+E16 -> 98548.7 | F17: =+F15+F16 -> 100650.8 | G17: =+G15+G16 -> 100915.8 | H17: =+H15+H16 -> 97138.3 | I17: =+I15+I16 -> 103521.82 | J17: =+J15+J16 -> 73915.445 | ... O17: =+O15+O16 -> 62260.864 | S17: =+S15+S16 -> 21954.3 | T17: =+T15+T16 -> 22976.8 | U17: =+U15+U16 -> 22663 | V17: =+V15+V16 -> 25992.1 | W17: =+W15+W16 -> 22812 | X17: =+X15+X16 -> 24978.3 | Y17: =+Y15+Y16 -> 24023.1 | Z17: =+Z15+Z16 -> 26735.3 | ... BA17: =+BA15+BA16 -> 14627 | BC17: =+BC15+BC16 -> 14973.6 | BF17: =+BF15+BF16 -> 27426.9 | BG17: =+BG15+BG16 -> 18022.3 | BH17: =+BH15+BH16 -> 18473.9 | BI17: =+BI15+BI16 -> 18590.1 | BJ17: =J17-BG17-BH17-BI17 -> 18829.145
B18: Non-Recurring Licensing revenues | C18: 0 | D18: 0 | E18: 2733.6 | F18: 0 | G18: 0 | H18: 0 | I18: 0 | J18: 0 | K18: 0 | L18: 0 | M18: 0 | N18: 0 | O18: 0 | S18: 0 | T18: 0 | U18: 0 | V18: =D18-U18-T18-S18 -> 0 | W18: 0 | X18: 1723.5 | Y18: 1010.1 | Z18: =E18-Y18-X18-W18 -> 0 | AA18: 0 | AB18: 0 | AC18: 0 | AD18: =F18-AC18-AB18-AA18 -> 0 | AE18: 0 | AF18: 0 | AG18: 0 | AH18: =H18-AG18-AF18-AE18 -> 0 | AI18: 0 | AJ18: 0 | AK18: 0 | AL18: =J18-AK18-AJ18-AI18 -> 0 | AM18: 0 | AN18: 0 | AO18: 0 | AP18: =K18-AO18-AN18-AM18 -> 0 | AQ18: 0 | AR18: 0 | AS18: 0 | AT18: =N18-AS18-AR18-AQ18 -> 0 | AU18: 0 | AV18: 0 | AW18: 0 | AX18: =O18-SUM(AU18:AW18) -> 0 | AY18: 0 | AZ18: 0 | BA18: 0 | BC18: 0 | BF18: =G18-AC18-AB18-AA18 -> 0 | BG18: 0 | BH18: 0 | BI18: 0 | BJ18: =J18-BG18-BH18-BI18 -> 0
B19: Held-to-sale Operations | F19: 841.4 | G19: 841.4 | H19: 223.3 | I19: 0 | J19: 0 | K19: 0 | L19: 0 | M19: 0 | N19: 0 | O19: 0 | AD19: =F19-AC19-AB19-AA19 -> 841.4 | AE19: 147.5 | AF19: 75.8 | AG19: 0 | AH19: =H19-AG19-AF19-AE19 -> 0 | AI19: 0 | AJ19: 0 | AK19: 0 | AL19: =J19-AK19-AJ19-AI19 -> 0 | AM19: 0 | AN19: 0 | AO19: 0 | AP19: =K19-AO19-AN19-AM19 -> 0 | AQ19: 0 | AR19: 0 | AS19: 0 | AT19: =N19-AS19-AR19-AQ19 -> 0 | AU19: 0 | AV19: 0 | AW19: 0 | AX19: =O19-SUM(AU19:AW19) -> 0 | AY19: 0 | AZ19: 0 | BA19: 0 | BC19: 0 | BF19: =G19-AC19-AB19-AA19 -> 841.4 | BG19: 0 | BH19: 0 | BI19: 0 | BJ19: =J19-BG19-BH19-BI19 -> 0
B20: Net Sales including non-recurring revenues | C20: =+C17+C18+C19 -> 96287.4 | D20: =+D17+D18+D19 -> 93586.2 | E20: =+E17+E18+E19 -> 101282.3 | F20: =+F17+F18+F19 -> 101492.2 | G20: =+G17+G18+G19 -> 101757.2 | H20: =+H17+H18+H19 -> 97361.6 | I20: =+I17+I18+I19 -> 103521.82 | J20: =+J17+J18+J19 -> 73915.445 | ... O20: =+O17+O18+O19 -> 62260.864 | S20: =+S17+S18+S19 -> 21954.3 | T20: =+T17+T18+T19 -> 22976.8 | U20: =+U17+U18+U19 -> 22663 | V20: =+V17+V18+V19 -> 25992.1 | W20: =+W17+W18+W19 -> 22812 | X20: =+X17+X18+X19 -> 26701.8 | Y20: =+Y17+Y18+Y19 -> 25033.2 | Z20: =+Z17+Z18+Z19 -> 26735.3 | ... BA20: =+BA17+BA18+BA19 -> 14627 | BC20: =+BC17+BC18+BC19 -> 14973.6 | BF20: =+BF17+BF18+BF19 -> 28268.3 | BG20: =+BG17+BG18+BG19 -> 18022.3 | BH20: =+BH17+BH18+BH19 -> 18473.9 | BI20: =+BI17+BI18+BI19 -> 18590.1 | BJ20: =J20-BG20-BH20-BI20 -> 18829.145
B21: Check | C21: =+C20-Model!C8 -> 96287.4 | D21: =+D20-Model!D9 -> 0 | E21: =+E20-Model!E9 -> 0 | F21: =+F20-Model!F9 -> 0.019 | G21: =+G20-Model!G9 -> 0.019 | H21: =+H20-Model!H9 -> -0.034 | I21: =+I20-Model!I9 -> 0 | J21: =+J20-Model!J9 -> 0.045 | K21: =+K20-Model!K9 -> 0 | L21: =+L20-Model!L9 -> 0 | M21: =+M20-Model!L9 -> 5152.132 | N21: =+N20-Model!N9 -> 0 | O21: =+O20-Model!O9 -> 0 | S21: =+S20-Model!S9 -> 0 | T21: =+T20-Model!T9 -> 0 | U21: =+U20-Model!U9 -> 0 | V21: =+V20-Model!V9 -> 0 | W21: =+W20-Model!W9 -> 0 | X21: =+X20-Model!X9 -> 0 | Y21: =+Y20-Model!Y9 -> 0 | Z21: =+Z20-Model!Z9 -> 0 | ... AJ21: =+AJ20-Model!AJ9 -> 0 | AK21: =+AJ20-Model!AJ9 -> 0 | AL21: =+AK20-Model!AK9 -> 0.033 | AM21: =+AM20-Model!AM9 -> 0 | AN21: =+AN20-Model!AN9 -> 0 | AO21: =+AO20-Model!AO9 -> 0 | AP21: =+AP20-Model!AP9 -> 0 | AQ21: =+AQ20-Model!AQ9 -> -0.033 | AR21: =+AR20-Model!AR9 -> 0 | AS21: =+AS20-Model!AS9 -> 1899.7 | AT21: =+AT20-Model!AT9 -> -9444.731 | ... BA21: =+BA20-Model!BA9 -> -0.086 | BC21: =+BC20-Model!BC9 -> 461.1 | BF21: =+BF20-Model!BF9 -> 0.068 | BG21: =+BG20-Model!BG9 -> 0 | BH21: =+BH20-Model!BH9 -> 0 | BI21: =+BI20-Model!BI9 -> 0 | BJ21: =+BJ20-Model!BJ9 -> 0.045
B23: Net Sales y-o-y Growth
B24: Content | D24: =D11/C11-1 -> -0.073309946 | E24: =E11/D11-1 -> 0.073326627 | F24: =F11/E11-1 -> -0.046439993 | G24: =G11/E11-1 -> -0.03917775 | H24: =H11/G11-1 -> -0.069807903 | I24: =I11/H11-1 -> 0.10207334 | W24: =W11/S11-1 -> 0.083489926 | X24: =X11/T11-1 -> 0.14512314 | Y24: =Y11/U11-1 -> 0.084125659 | Z24: =Z11/V11-1 -> 0.0034981189 | AA24: =AA11/W11-1 -> -0.090449908 | AB24: =AB11/X11-1 -> -0.12953211 | AC24: =AC11/Y11-1 -> -0.0047126437 | AD24: =AD11/Z11-1 -> 0.024316909 | ... AG24: =AG11/AC11-1 -> -0.072248528 | AH24: =AH11/BF11-1 -> -0.0049433131 | AI24: =AI11/AE11-1 -> 0.10233962 | AJ24: =AJ11/AF11-1 -> 0.16559357 | AK24: =AK11/AG11-1 -> 0.13399059 | AL24: =AL11/AH11-1 -> 0.040302572 | BF24: =BF11/Z11-1 -> 0.049216372
B25: Sky | D25: =D12/C12-1 -> 0.011640202 | E25: =E12/D12-1 -> -0.0087580981 | F25: =F12/E12-1 -> -0.029774295 | G25: =G12/E12-1 -> -0.029774295 | H25: =H12/G12-1 -> 0.036894941 | I25: =I12/H12-1 -> -0.0048830117 | J25: =J12/H12-1 -> -0.0048830117 | K25: =K12/J12-1 -> -0.0766154 | L25: =L12/J12-1 -> -0.0766154 | M25: =M12/K12-1 -> -0.13539667 | N25: =N12/L12-1 -> -0.1353979 | O25: =O12/N12-1 -> -0.12782853 | W25: =W12/S12-1 -> -0.011984262 | X25: =X12/T12-1 -> 0.0029954448 | Y25: =Y12/U12-1 -> -0.0069602586 | Z25: =Z12/V12-1 -> -0.019213848 | AA25: =AA12/W12-1 -> -0.035183223 | AB25: =AB12/X12-1 -> -0.054905634 | AC25: =AC12/Y12-1 -> -0.012760527 | AD25: =AD12/Z12-1 -> -0.01515956 | ... AG25: =AG12/AC12-1 -> 0.048629714 | AH25: =AH12/BF12-1 -> 0.044189548 | AI25: =AI12/AE12-1 -> 0.040608292 | AJ25: =AJ12/AF12-1 -> 0.010045877 | AK25: =AK12/AG12-1 -> -0.024741421 | AL25: =AL12/AH12-1 -> -0.043527275 | AM25: =AM12/BG12-1 -> -0.062064429 | AN25: =AN12/BH12-1 -> -0.077197896 | AO25: =AO12/AK12-1 -> -0.086602923 | AP25: =AP12/AL12-1 -> -0.081096868 | AQ25: =AQ12/AM12-1 -> -0.11715981 | AR25: =AR12/AN12-1 -> -0.13435536 | AS25: =AS12/AO12-1 -> -0.13837083 | AT25: =AT12/AP12-1 -> -0.15297111 | AU25: =AU12/AQ12-1 -> -0.12323944 | AV25: =AV12/AR12-1 -> -0.13286886 | ... BA25: =BA12/AW12-1 -> -0.18227868 | BC25: =BC12/AY12-1 -> 0 | BF25: =BF12/Z12-1 -> -0.01515956 | BG25: =BG12/AE12-1 -> 0.040608292 | BH25: =BH12/AF12-1 -> 0.010045877 | BI25: =BI12/AG12-1 -> -0.024741421 | BJ25: =BJ12/AH12-1 -> -0.043527275
B26: Cable | D26: =D13/C13-1 -> 0.036269739 | E26: =E13/D13-1 -> 0.096365017 | F26: =F13/E13-1 -> 0.15093975 | G26: =G13/E13-1 -> 0.15093975 | H26: =H13/G13-1 -> 0.087887871 | I26: =I13/H13-1 -> 0.058496774 | J26: =J13/H13-1 -> 0.058496774 | K26: =K13/J13-1 -> 0.008139097 | L26: =L13/J13-1 -> 0.008139097 | M26: =M13/K13-1 -> 0.0080708462 | N26: =N13/L13-1 -> 0.0080717551 | O26: =O13/N13-1 -> -0.028880318 | W26: =W13/S13-1 -> 0.070822474 | X26: =X13/T13-1 -> 0.098174624 | Y26: =Y13/U13-1 -> 0.10782818 | Z26: =Z13/V13-1 -> 0.10763663 | AA26: =AA13/W13-1 -> 0.14168887 | AB26: =AB13/X13-1 -> 0.15749459 | AC26: =AC13/Y13-1 -> 0.14666103 | AD26: =AD13/Z13-1 -> 0.15743299 | ... AG26: =AG13/AC13-1 -> 0.079057141 | AH26: =AH13/BF13-1 -> 0.073492434 | AI26: =AI13/AE13-1 -> 0.078690403 | AJ26: =AJ13/AF13-1 -> 0.059493492 | AK26: =AK13/AG13-1 -> 0.057740688 | AL26: =AL13/AH13-1 -> 0.039788681 | AM26: =AM13/BG13-1 -> 0.010962189 | AN26: =AN13/BH13-1 -> -0.019329639 | AO26: =AO13/AK13-1 -> 0.027132747 | AP26: =AP13/AL13-1 -> 0.013585222 | AQ26: =AQ13/AM13-1 -> 0.026955822 | AR26: =AR13/AN13-1 -> 0.046085106 | AS26: =AS13/AO13-1 -> -0.019856382 | AT26: =AT13/AP13-1 -> -0.017879087 | AU26: =AU13/AQ13-1 -> -0.017652833 | AV26: =AV13/AR13-1 -> -0.031460766 | ... BA26: =BA13/AW13-1 -> 0.00037686075 | BC26: =BC13/AY13-1 -> 0 | BF26: =BF13/Z13-1 -> 0.15743299 | BG26: =BG13/AE13-1 -> 0.078690403 | BH26: =BH13/AF13-1 -> 0.059493492 | BI26: =BI13/AG13-1 -> 0.057740688 | BJ26: =BJ13/AH13-1 -> 0.039788681
