Workbook
Name \A: #REF!
Name \B: #REF!
Name \C: #REF!
Name \L: #REF!
Name \M: #REF!
Name \P: #REF!
Name \Y: #REF!
Name _01_30_04: MonthlyOpStats
Name _1_30_01: MonthlyOpStats
Name _1_30_02: MonthlyOpStats
Name _1_31_01: MonthlyOpStats
Name _1_31_02: MonthlyOpStats
Name _12_31_05: MonthlyOpStats
Name _A: #REF!
Name _A___0: #REF!
Name _B: #REF!
Name _B___0: #REF!
Name _C: #REF!
Name _C___0: #REF!
Name _ent1: [3]Inputs!$J$17
Name _ent10: [3]Inputs!$J$476
Name _ent11: [3]Inputs!$J$527
Name _ent12: [3]Inputs!$J$578
Name _ent13: [3]Inputs!$J$629
Name _ent14: [3]Inputs!$J$680
Name _ent15: [3]Inputs!$J$731
Name _ent2: [3]Inputs!$J$68
Name _ent3: [3]Inputs!$J$119
Name _ent4: [3]Inputs!$J$170
Name _ent5: [3]Inputs!$J$221
Name _ent6: [3]Inputs!$J$272
Name _ent7: [3]Inputs!$J$323
Name _ent8: [3]Inputs!$J$374
Name _ent9: [3]Inputs!$J$425
Name _eps1: [3]Inputs!$P$42
Name _eps10: [3]Inputs!$P$501
Name _eps11: [3]Inputs!$P$552
Name _eps12: [3]Inputs!$P$603
Name _eps13: [3]Inputs!$P$654
Name _eps14: [3]Inputs!$P$705
Name _eps15: [3]Inputs!$P$756
Name _eps2: [3]Inputs!$P$93
Name _eps3: [3]Inputs!$P$144
Name _eps4: [3]Inputs!$P$195
Name _eps5: [3]Inputs!$P$246
Name _eps6: [3]Inputs!$P$297
Name _eps7: [3]Inputs!$P$348
Name _eps8: [3]Inputs!$P$399
Name _eps9: [3]Inputs!$P$450
Name _fye1: [3]Inputs!$E$12
Name _fye10: [3]Inputs!$E$471
Name _fye11: [3]Inputs!$E$522
Name _fye12: [3]Inputs!$E$573
Name _fye13: [3]Inputs!$E$624
Name _fye14: [3]Inputs!$E$675
Name _fye15: [3]Inputs!$E$726
Name _fye2: [3]Inputs!$E$63
Name _fye3: [3]Inputs!$E$114
Name _fye4: [3]Inputs!$E$165
Name _fye5: [3]Inputs!$E$216

Sheet __FDSCACHE__
B1: This sheet contains FactSet XML data for use with this workbook's =FDS codes. Modifying the worksheet's contents may damage the workbook's =FDS functionality.

Sheet Old
B2: US$ Thousands | C2: =DATE(2022,3,31) -> 44651 | D2: =+EDATE(C2,3) -> 44742 | E2: =+EDATE(D2,3) -> 44834 | F2: =+EDATE(E2,3) -> 44925 | G2: =+EDATE(F2,3) -> 45015 | H2: =+EDATE(G2,3) -> 45107 | I2: =+EDATE(H2,3) -> 45199 | J2: =+EDATE(I2,3) -> 45290 | K2: =+EDATE(J2,3) -> 45381
B3: Operational data | C3: 1Q22 | D3: 2Q22 | E3: 3Q22 | F3: 4Q22 | G3: 1Q23 | H3: 2Q23 | I3: 3Q23 | J3: 4Q23 | K3: 1Q24
B5: Departing passengers (millions) | C5: =+C7+C6 -> 0.406613 | D5: =+D7+D6 -> 0.540633 | E5: =+E7+E6 -> 0.628894 | F5: =+F7+F6 -> 0.60369 | G5: =+G7+G6 -> 0.617955 | H5: =+H7+H6 -> 0.680338 | I5: =+I7+I6 -> 0.761969 | J5: =+J7+J6 -> 0.672324 | K5: =+K7+K6 -> 0.647506
B6: International | C6: =+(60744+55031+71487)/1000000 -> 0.187262 | D6: =+(75793+77231+68573)/1000000 -> 0.221597 | E6: =+(84436+98917+85116)/1000000 -> 0.268469 | F6: =+((85695+88535+82442)/1000000) -> 0.256672 | G6: =+(89178+85348+105802)/1000000 -> 0.280328 | H6: =+(98376+91542+96216)/1000000 -> 0.286134 | I6: =+(125011+131850+111412)/1000000 -> 0.368273 | J6: =+(109563+102871+97519)/1000000 -> 0.309953 | K6: =+(98399+97894+115334)/1000000 -> 0.311627 | M6: 120 | N6: 20 | O6: =+M6*N6 -> 2400
B7: Domestic | C7: =+(52197+70580+96574)/1000000 -> 0.219351 | D7: =+(110329+110038+98669)/1000000 -> 0.319036 | E7: =+(123549+126262+110614)/1000000 -> 0.360425 | F7: =+(113968+110628+122422)/1000000 -> 0.347018 | G7: =+(102783+105458+129386)/1000000 -> 0.337627 | H7: =+(129892+131056+133256)/1000000 -> 0.394204 | I7: =+(142884+131333+119479)/1000000 -> 0.393696 | J7: =+(116051+119573+126747)/1000000 -> 0.362371 | K7: =+(103335+110173+122371)/1000000 -> 0.335879 | M7: 100 | N7: 50 | O7: =+M7*N7 -> 5000
B9: Aircraft movements | G9: =+SUM(G10:G13) -> 0 | H9: =+SUM(H10:H13) -> 0 | I9: =+SUM(I10:I13) -> 0 | J9: =+SUM(J10:J13) -> 0 | K9: =+SUM(K10:K13) -> 0 | N9: =+SUMPRODUCT(M6:M7,N6:N7) -> 7400
B10: Passengers domestic | M10: 120 | N10: 100
B11: Passengers international | M11: 100 | N11: 20
B12: Cargo international
B13: Military and others | N13: =+SUMPRODUCT(M10:M11,N10:N11) -> 14000
N14: =+N13/N9-1 -> 0.89189189
B15: Arriving cargo (tons) | C15: =+C17+C16 -> 11131.09 | D15: =+D17+D16 -> 11893.04 | E15: =+E17+E16 -> 11845.11 | F15: =+F17+F16 -> 12933.3 | G15: =+G17+G16 -> 12923.22 | H15: =+H17+H16 -> 13356.9 | I15: =+I17+I16 -> 12923.6 | J15: =+J17+J16 -> 14123.03 | K15: =+K17+K16 -> 12486.67
B16: International (Imports) | C16: =3809.79+3552.12+3563.83 -> 10925.74 | D16: =3843.27+3967.02+3507.87 -> 11318.16 | E16: =3626.28+3713.17+4170 -> 11509.45 | F16: =4390.92+4001.95+4079.15 -> 12472.02 | G16: =3935.31+3942.21+4816.62 -> 12694.14 | H16: =4076.92+4767.41+3871.25 -> 12715.58 | I16: =4214.24+4182.27+4152.65 -> 12549.16 | J16: =4501.05+4510.2+4597.2 -> 13608.45 | K16: =3725.97+4259.58+4249.47 -> 12235.02 | M16: 120 | N16: 20 | O16: =+M16*N16 -> 2400
B17: Domestic | C17: =55.61+74.6+75.14 -> 205.35 | D17: =76.81+75.08+422.99 -> 574.88 | E17: =121.2+111.71+102.75 -> 335.66 | F17: =111.58+156+193.7 -> 461.28 | G17: =62.04+83.22+83.82 -> 229.08 | H17: =85.69+83.76+471.87 -> 641.32 | I17: =135.2+124.62+114.62 -> 374.44 | J17: =124.47+174.03+216.08 -> 514.58 | K17: =68.15+91.42+92.08 -> 251.65 | M17: 100 | N17: 50 | O17: =+M17*N17 -> 5000
B19: Departing cargo (tons) | C19: =+C21+C20 -> 62802.049 | D19: =+D21+D20 -> 59961.48 | E19: =+E21+E20 -> 57306.41 | F19: =+F21+F20 -> 61988.53 | G19: =+G21+G20 -> 76362.47 | H19: =+H21+H20 -> 75101.15 | I19: =+I21+I20 -> 66527.97 | J19: =+J21+J20 -> 67642.4 | K19: =+K21+K20 -> 80535.74
B20: International (Exports) | C20: =22411.76+22593.339+17133.06 -> 62138.159 | D20: =23467.63+20354.14+15101.57 -> 58923.34 | E20: =18816.4+18768.59+18962.89 -> 56547.88 | F20: =20360.03+21680.42+19243.75 -> 61284.2 | G20: =25905.62+27550.52+21958.35 -> 75414.49 | H20: =25613.92+26744.01+21580.32 -> 73938.25 | I20: =20727.88+22101.86+22599.3 -> 65429.04 | J20: =23760.94+21990.59+20968.95 -> 66720.48 | K20: 79551.88
B21: Domestic | C21: =198.72+217.34+247.83 -> 663.89 | D21: =252.45+257.26+528.43 -> 1038.14 | E21: =294.65+241.7+222.18 -> 758.53 | F21: =245.19+255.42+203.72 -> 704.33 | G21: =301.39+282.08+364.51 -> 947.98 | H21: =365.61+395.92+401.37 -> 1162.9 | I21: =393.53+380.51+324.89 -> 1098.93 | J21: =278.69+349.41+293.82 -> 921.92 | K21: 983.86
B23: Tariffs, US$
B24: Tariff per intl. departing passenger | F24: 57.571947 | J24: 58.83853
B25: Tariff per domestic departing passenger | F25: 15.902994 | J25: 16.25286
B26: Regulated revenues per departing passenger | F26: 48.175194 | J26: 49.235048
B27: Non-regulated revenue per departing passenger | F27: 58.284399 | J27: 78.113562
B28: Check-in counters revenue per intl. passenger | F28: 2.1934796 | J28: 2.1868992
B29: Check-in counters revenue per domestic passenger | F29: 1.1066204 | J29: 1.1033005
B30: Fee per international ton of cargo | F30: 8.2107278 | J30: 8.1860957
B33: Revenues | C33: =+C3 -> 1Q22 | D33: =+D3 -> 2Q22 | E33: =+E3 -> 3Q22 | F33: =+F3 -> 4Q22 | G33: =+G3 -> 1Q23 | H33: =+H3 -> 2Q23 | I33: =+I3 -> 3Q23 | J33: =+J3 -> 4Q23 | K33: =+K3 -> 1Q24
B35: Revenues | C35: 32461 | D35: 37500 | E35: 42098 | F35: =+Operations!H13-SUM(C35:E35) -> -111906.6 | G35: 43567 | H35: 47524 | I35: 53233 | J35: =+Operations!I13-SUM(G35:I35) -> -144132.3 | K35: 50064
B36: Regulated Revenues | C36: 21927 | D36: 25748 | E36: 28925 | F36: =+Operations!#REF!-SUM(C36:E36) -> #REF! | G36: 31685 | H36: 34019 | I36: 38456 | J36: =+Operations!#REF!-SUM(G36:I36) -> #REF! | K36: 36460
B37: US$/Passenger | C37: =+C36/(C$5*1000) -> 53.925969 | D37: =+D36/(D$5*1000) -> 47.625654 | E37: =+E36/(E$5*1000) -> 45.993442 | F37: =+F36/(F$5*1000) -> #REF! | G37: =+G36/(G$5*1000) -> 51.27396 | H37: =+H36/(H$5*1000) -> 50.003087 | I37: =+I36/(I$5*1000) -> 50.469245 | J37: =+J36/(J$5*1000) -> #REF! | K37: =+K36/(K$5*1000) -> 56.308359
B38: Non-regulated revenues | C38: 8283 | D38: 9710 | E38: 10732 | F38: =+Operations!#REF!-SUM(C38:E38) -> #REF! | G38: 11042 | H38: 12748 | I38: 12969 | J38: =+Operations!#REF!-SUM(G38:I38) -> #REF! | K38: 12726
B39: US$/Passenger | C39: =+C38/(C$5*1000) -> 20.370721 | D39: =+D38/(D$5*1000) -> 17.960428 | E39: =+E38/(E$5*1000) -> 17.064879 | F39: =+F38/(F$5*1000) -> #REF! | G39: =+G38/(G$5*1000) -> 17.868615 | H39: =+H38/(H$5*1000) -> 18.737745 | I39: =+I38/(I$5*1000) -> 17.020377 | J39: =+J38/(J$5*1000) -> #REF! | K39: =+K38/(K$5*1000) -> 19.653872
B40: Aeronautical revenue | C40: 4085 | D40: 4520 | E40: 4939 | F40: =+Operations!#REF!-SUM(C40:E40) -> #REF! | G40: 5222 | H40: 5486 | I40: 5674 | J40: =+Operations!#REF!-SUM(G40:I40) -> #REF! | K40: 5599
B41: US$/Passenger | C41: =+C40/(C$5*1000) -> 10.046408 | D41: =+D40/(D$5*1000) -> 8.3605699 | E41: =+E40/(E$5*1000) -> 7.8534697 | F41: =+F40/(F$5*1000) -> #REF! | G41: =+G40/(G$5*1000) -> 8.4504535 | H41: =+H40/(H$5*1000) -> 8.063639 | I41: =+I40/(I$5*1000) -> 7.4464972 | J41: =+J40/(J$5*1000) -> #REF! | K41: =+K40/(K$5*1000) -> 8.6470241
B42: Non-aeronautical revenue | C42: =4196+2 -> 4198 | D42: =5186+4 -> 5190 | E42: =5787+6 -> 5793 | F42: =+Operations!#REF!-SUM(C42:E42) -> #REF! | G42: =5814+6 -> 5820 | H42: =6569+693 -> 7262 | I42: =7292+3 -> 7295 | J42: =+Operations!#REF!-SUM(G42:I42) -> #REF! | K42: =7121+8 -> 7129
B43: US$/Passenger | C43: =+C42/(C$5*1000) -> 10.324313 | D43: =+D42/(D$5*1000) -> 9.5998579 | E43: =+E42/(E$5*1000) -> 9.2114092 | F43: =+F42/(F$5*1000) -> #REF! | G43: =+G42/(G$5*1000) -> 9.4181615 | H43: =+H42/(H$5*1000) -> 10.674106 | I43: =+I42/(I$5*1000) -> 9.5738803 | J43: =+J42/(J$5*1000) -> #REF! | K43: =+K42/(K$5*1000) -> 11.009937
B44: Commercial incentives | C44: -186 | D44: -394 | E44: -610 | F44: =+Operations!#REF!-SUM(C44:E44) -> #REF! | G44: -248 | H44: -490 | I44: -747 | J44: =+Operations!#REF!-SUM(G44:I44) -> #REF! | K44: -953
B45: US$/Passenger | C45: =+C44/(C$5*1000) -> -0.45743742 | D45: =+D44/(D$5*1000) -> -0.72877534 | E45: =+E44/(E$5*1000) -> -0.96995678 | F45: =+F44/(F$5*1000) -> #REF! | G45: =+G44/(G$5*1000) -> -0.40132372 | H45: =+H44/(H$5*1000) -> -0.72023024 | I45: =+I44/(I$5*1000) -> -0.98035484 | J45: =+J44/(J$5*1000) -> #REF! | K45: =+K44/(K$5*1000) -> -1.471801
B46: Recognition of MSIA contract liabilities (Note 15) | C46: 2437 | D46: 2436 | E46: 2437 | F46: =+Operations!#REF!-SUM(C46:E46) -> #REF! | G46: 1088 | H46: 1247 | I46: 1274 | J46: =+Operations!#REF!-SUM(G46:I46) -> #REF! | K46: 1831
B48: Interest revenue | C48: 598 | D48: 596 | E48: 614 | F48: =+Operations!#REF!-SUM(C48:E48) -> #REF! | G48: 693 | H48: 834 | I48: 1281 | J48: =+Operations!#REF!-SUM(G48:I48) -> #REF! | K48: 1144
B50: EBIT Driver | C50: =+C$3 -> 1Q22 | D50: =+D$3 -> 2Q22 | E50: =+E$3 -> 3Q22 | F50: =+F$3 -> 4Q22 | G50: =+G$3 -> 1Q23 | H50: =+H$3 -> 2Q23 | I50: =+I$3 -> 3Q23 | J50: =+J$3 -> 4Q23 | K50: =+K$3 -> 1Q24
...

Sheet Quarterlies
C2: =DATE(2022,3,31) -> 44651 | D2: =+EDATE(C2,3) -> 44742 | E2: =+EDATE(D2,3) -> 44834 | F2: =+EDATE(E2,3) -> 44925 | G2: =+EDATE(F2,3) -> 45015 | H2: =+EDATE(G2,3) -> 45107 | I2: =+EDATE(H2,3) -> 45199 | J2: =+EDATE(I2,3) -> 45290 | K2: =+EDATE(J2,3) -> 45381 | ... S2: =+EDATE(R2,3) -> 46111
B3: Operational data | C3: 1Q22 | D3: 2Q22 | E3: 3Q22 | F3: 4Q22 | G3: 1Q23 | H3: 2Q23 | I3: 3Q23 | J3: 4Q23 | K3: 1Q24 | L3: 2Q24 | M3: 3Q24 | N3: 4Q24 | O3: 1Q25 | P3: 2Q25 | Q3: 3Q25 | R3: 4Q25 | S3: 1Q26
B5: Departing Passengers, M | C5: =+C9+C7 -> 0.406613 | D5: =+D9+D7 -> 0.540633 | E5: =+E9+E7 -> 0.628894 | F5: =+F9+F7 -> 0.60369 | G5: =+G9+G7 -> 0.617955 | H5: =+H9+H7 -> 0.680338 | I5: =+I9+I7 -> 0.761969 | J5: =+J9+J7 -> 0.672324 | ... Q5: =+Q9+Q7 -> 0.743261 | R5: =SUM(R7,R9) -> 0.670704 | S5: =+S9+S7 -> 0.662089
B6: % | G6: =+G5/C5-1 -> 0.51976203 | H6: =+H5/D5-1 -> 0.25841005 | I6: =+I5/E5-1 -> 0.21160164 | J6: =+J5/F5-1 -> 0.1136908 | K6: =+K5/G5-1 -> 0.047820634 | L6: =+L5/H5-1 -> -0.025669594 | M6: =+M5/I5-1 -> -0.044988707 | N6: =+N5/J5-1 -> -0.049644219 | ... S6: =+S5/O5-1 -> 0.069437894
B7: International | C7: =+(60744+55031+71487)/1000000 -> 0.187262 | D7: =+(75793+77231+68573)/1000000 -> 0.221597 | E7: =+(84436+98917+85116)/1000000 -> 0.268469 | F7: =+((85695+88535+82442)/1000000) -> 0.256672 | G7: =+(89178+85348+105802)/1000000 -> 0.280328 | H7: =+(98376+91542+96216)/1000000 -> 0.286134 | I7: =+(125011+131850+111412)/1000000 -> 0.368273 | J7: =+(109563+102871+97519)/1000000 -> 0.309953 | K7: =+(98399+97894+115334)/1000000 -> 0.311627 | L7: =0.61805-K7 -> 0.306423 | M7: =+(105110+124708+117734)/1000000 -> 0.347552 | N7: =+Operations!J6-SUM(Quarterlies!K7:M7) -> 0.28401 | O7: 0.2969 | P7: =0.596277-O7 -> 0.299377 | Q7: =+(126920+135133+110778)/1000000 -> 0.372831 | R7: =(108276+99767+95765)/1000000 -> 0.303808 | S7: =(103720+97378+118947)/1000000 -> 0.320045
B8: % | G8: =+G7/C7-1 -> 0.49698284 | H8: =+H7/D7-1 -> 0.29123589 | I8: =+I7/E7-1 -> 0.37175242 | J8: =+J7/F7-1 -> 0.207584 | K8: =+K7/G7-1 -> 0.11165135 | L8: =+L7/H7-1 -> 0.070907337 | M8: =+M7/I7-1 -> -0.056265325 | N8: =+N7/J7-1 -> -0.083699787 | ... S8: =+S7/O7-1 -> 0.077955541
B9: Domestic | C9: =+(52197+70580+96574)/1000000 -> 0.219351 | D9: =+(110329+110038+98669)/1000000 -> 0.319036 | E9: =+(123549+126262+110614)/1000000 -> 0.360425 | F9: =+(113968+110628+122422)/1000000 -> 0.347018 | G9: =+(102783+105458+129386)/1000000 -> 0.337627 | H9: =+(129892+131056+133256)/1000000 -> 0.394204 | I9: =+(142884+131333+119479)/1000000 -> 0.393696 | J9: =+(116051+119573+126747)/1000000 -> 0.362371 | K9: =+(103335+110173+122371)/1000000 -> 0.335879 | L9: =0.69233-K9 -> 0.356451 | M9: =+(111468+133490+135179)/1000000 -> 0.380137 | N9: =+Operations!J8-SUM(Quarterlies!K9:M9) -> 0.354937 | O9: 0.3222 | P9: =0.66851-O9 -> 0.34631 | Q9: =+(134058+129026+107346)/1000000 -> 0.37043 | R9: =0.120852+0.124604+0.12144 -> 0.366896 | S9: =(110565+109881+121598)/1000000 -> 0.342044
B10: % | G10: =+G9/C9-1 -> 0.53920885 | H10: =+H9/D9-1 -> 0.23560977 | I10: =+I9/E9-1 -> 0.092310467 | J10: =+J9/F9-1 -> 0.044242662 | K10: =+K9/G9-1 -> -0.0051773111 | L10: =+L9/H9-1 -> -0.09577021 | M10: =+M9/I9-1 -> -0.034440279 | N10: =+N9/J9-1 -> -0.020514887 | ... S10: =+S9/O9-1 -> 0.061589075
B12: Revenues | C12: =+C3 -> 1Q22 | D12: =+D3 -> 2Q22 | E12: =+E3 -> 3Q22 | F12: =+F3 -> 4Q22 | G12: =+G3 -> 1Q23 | H12: =+H3 -> 2Q23 | I12: =+I3 -> 3Q23 | J12: =+J3 -> 4Q23 | ... S12: =+S3 -> 1Q26
B14: Core Revenues, US$M | C14: 32.461 | D14: 37.5 | E14: 42.098 | F14: =152.4-E14-D14-C14 -> 40.341 | G14: 43.567 | H14: 47.524 | I14: 53.233 | J14: =191.7-I14-H14-G14 -> 47.376 | K14: 50.064 | L14: 50.78 | M14: 53.635 | N14: =Operations!J13-M14-L14-K14 -> 49.221 | O14: 49.66 | P14: =101.4-O14 -> 51.74 | Q14: 58.491 | R14: =Operations!K13-Q14-P14-O14 -> 54.381 | S14: 54.87
B16: Regulated Revenues, US$M | C16: 21.927 | D16: 25.748 | E16: 28.925 | F16: =105.2-E16-D16-C16 -> 28.6 | G16: 31.685 | H16: 34.019 | I16: 38.456 | J16: =Operations!I15-I16-H16-G16 -> 34.94 | K16: 36.46 | L16: 36.151 | M16: 38.371 | N16: =Operations!J15-M16-L16-K16 -> 34.518 | O16: 36.241 | P16: =73.673-O16 -> 37.432 | Q16: 42.291 | R16: =Operations!K15-Q16-P16-O16 -> 38.165 | S16: 39.555
B17: Passenger Revenues, US$M | C17: 12.567 | D17: 16.086 | E17: 19.111 | F17: 18.33 | G17: 20.109 | H17: 21.804 | I17: 26.746 | J17: 22.716 | K17: 23 | L17: 23.045 | M17: 25.829 | N17: =Operations!J16-M17-L17-K17 -> 21.89 | O17: 22.525 | P17: =45.58-O17 -> 23.055 | Q17: 28.071 | R17: =Operations!K16-Q17-P17-O17 -> 23.76 | S17: 24.721
B18: Realized Net Tariffs, US$ | C18: =+C16/C$5 -> 53.925969 | D18: =+D16/D$5 -> 47.625654 | E18: =+E16/E$5 -> 45.993442 | F18: =+F16/F$5 -> 47.375309 | G18: =+G16/G$5 -> 51.27396 | H18: =+H16/H$5 -> 50.003087 | I18: =+I16/I$5 -> 50.469245 | J18: =+J16/J$5 -> 51.968991 | ... S18: =+S16/S$5 -> 59.742723
B19: Quiport Participation | C19: 0.89 | D19: 0.89 | E19: 0.89 | F19: 0.89 | G19: 0.89 | H19: 0.89 | I19: 0.89 | J19: 0.89 | K19: 0.89 | L19: 0.89 | M19: 0.89 | N19: 0.89 | O19: 0.89 | P19: 0.89 | Q19: 0.89 | R19: 0.89 | S19: 0.89
B20: International (estimated) | C20: =+Operations!$H$19 -> 64.477106 | D20: =+Operations!$H$19 -> 64.477106 | E20: =+Operations!$H$19 -> 64.477106 | F20: =+Operations!$H$19 -> 64.477106 | G20: =+Operations!$I$19 -> 66.604851 | H20: =+Operations!$I$19 -> 66.604851 | I20: =+Operations!$I$19 -> 66.604851 | J20: =+Operations!$I$19 -> 66.604851 | K20: =+Operations!$J$19 -> 64.9 | L20: =+Operations!$J$19 -> 64.9 | M20: =+Operations!$J$19 -> 64.9 | N20: =+Operations!$J$19 -> 64.9 | O20: =+Operations!$K$19 -> 67.0417 | P20: =+Operations!$K$19 -> 67.0417 | Q20: =+Operations!$K$19 -> 67.0417 | R20: =+Operations!$K$19 -> 67.0417 | S20: =+Operations!$L$19 -> 68.382534
B21: Domestic (estimated) | C21: =+Operations!$H$20 -> 11.270642 | D21: =+Operations!$H$20 -> 11.270642 | E21: =+Operations!$H$20 -> 11.270642 | F21: =+Operations!$H$20 -> 11.270642 | G21: =+Operations!I20 -> 13.284701 | H21: =+Operations!$I$20 -> 13.284701 | I21: =+Operations!$I$20 -> 13.284701 | J21: =+Operations!$I$20 -> 13.284701 | K21: =+Operations!J20 -> 14.4 | L21: =+Operations!$J$20 -> 14.4 | M21: =+Operations!$J$20 -> 14.4 | N21: =+Operations!$I$20 -> 13.284701 | O21: =+Operations!N20 -> 18.201243 | P21: =+Operations!$J$20 -> 14.4 | Q21: =+Operations!$J$20 -> 14.4 | R21: =+Operations!$K$20 -> 17.151438 | S21: =+Operations!$L$20 -> 17.494467
B22: Airport Services, US$M | C22: =+C16-C17 -> 9.36 | D22: =+D16-D17 -> 9.662 | E22: =+E16-E17 -> 9.814 | F22: =+F16-F17 -> 10.27 | G22: =+G16-G17 -> 11.576 | H22: =+H16-H17 -> 12.215 | I22: =+I16-I17 -> 11.71 | J22: =+J16-J17 -> 12.224 | ... M22: =+M16-M17 -> 12.542 | N22: =Operations!J21-M22-L22-K22 -> 12.628 | O22: =+O16-O17 -> 13.716 | P22: =+P16-P17 -> 14.377 | Q22: =+Q16-Q17 -> 14.22 | R22: =Operations!K21-Q22-P22-O22 -> 14.405 | S22: =+S16-S17 -> 14.834
B23: Quiport Participation | C23: =+C19 -> 0.89 | D23: =+D19 -> 0.89 | E23: =+E19 -> 0.89 | F23: =+F19 -> 0.89 | G23: =+G19 -> 0.89 | H23: =+H19 -> 0.89 | I23: =+I19 -> 0.89 | J23: =+J19 -> 0.89 | ... S23: =+S19 -> 0.89
B24: Realized Net Tariffs, US$ | C24: =+C22/C$5 -> 23.019431 | D24: =+D22/D$5 -> 17.871643 | E24: =+E22/E$5 -> 15.605174 | F24: =+F22/F$5 -> 17.012043 | G24: =+G22/G$5 -> 18.732756 | H24: =+H22/H$5 -> 17.954311 | I24: =+I22/I$5 -> 15.368079 | J24: =+J22/J$5 -> 18.18171 | ... S24: =+S22/S$5 -> 22.404843
B26: Non-Regulated, US$M | C26: 8.283 | D26: 9.71 | E26: 10.732 | F26: =+Operations!H25-SUM(Quarterlies!C26:E26) -> 11.169 | G26: 11.042 | H26: 12.748 | I26: 12.969 | J26: =+Operations!I25-SUM(Quarterlies!G26:I26) -> 13.82 | K26: 12.726 | L26: 13.312 | M26: 13.892 | N26: =Operations!J25-M26-L26-K26 -> 13.55 | O26: 12.771 | P26: =26.717-O26 -> 13.946 | Q26: 14.466 | R26: =Operations!K25-Q26-P26-O26 -> 14.796 | S26: 14.314
B27: Aeronautical, US$M | C27: 4.085 | D27: 4.52 | E27: 4.939 | F27: =+Operations!H26-SUM(Quarterlies!C27:E27) -> 4.959 | G27: 5.222 | H27: 5.486 | I27: 5.674 | J27: =+Operations!I26-SUM(Quarterlies!G27:I27) -> 5.512 | K27: 5.599 | L27: 5.667 | M27: 5.745 | N27: =Operations!J26-M27-L27-K27 -> 6.044 | O27: 5.844 | P27: =12.069-O27 -> 6.225 | Q27: 6.276 | R27: =Operations!K26-Q27-P27-O27 -> 6.337 | S27: 6.431
B28: US$/Passenger | C28: =+C27/C$5 -> 10.046408 | D28: =+D27/D$5 -> 8.3605699 | E28: =+E27/E$5 -> 7.8534697 | F28: =+F27/F$5 -> 8.2144809 | G28: =+G27/G$5 -> 8.4504535 | H28: =+H27/H$5 -> 8.063639 | I28: =+I27/I$5 -> 7.4464972 | J28: =+J27/J$5 -> 8.1984281 | ... S28: =+S27/S$5 -> 9.7131957
B29: Non-Aeronautical, US$M | C29: 4.198 | D29: 5.19 | E29: 5.793 | F29: =+Operations!H28-SUM(Quarterlies!C29:E29) -> 6.21 | G29: 5.82 | H29: 7.262 | I29: 7.295 | J29: =+Operations!I28-SUM(Quarterlies!G29:I29) -> 8.308 | K29: 7.129 | L29: 7.645 | M29: 8.317 | N29: =Operations!J28-M29-L29-K29 -> 7.334 | O29: 7.051 | P29: =14.648-O29 -> 7.597 | Q29: 8.243 | R29: =Operations!K28-Q29-P29-O29 -> 8.406 | S29: 7.994
B30: US$/Passenger | C30: =+C29/C$5 -> 10.324313 | D30: =+D29/D$5 -> 9.5998579 | E30: =+E29/E$5 -> 9.2114092 | F30: =+F29/F$5 -> 10.286737 | G30: =+G29/G$5 -> 9.4181615 | H30: =+H29/H$5 -> 10.674106 | I30: =+I29/I$5 -> 9.5738803 | J30: =+J29/J$5 -> 12.357137 | ... S30: =+S29/S$5 -> 12.073905
B32: Others, US$M | C32: =+C14-C16-C26 -> 2.251 | D32: =+D14-D16-D26 -> 2.042 | E32: =+E14-E16-E26 -> 2.441 | F32: =+F14-F16-F26 -> 0.572 | G32: =+G14-G16-G26 -> 0.84 | H32: =+H14-H16-H26 -> 0.757 | I32: =+I14-I16-I26 -> 1.808 | J32: =+J14-J16-J26 -> -1.384 | ... S32: =+S14-S16-S26 -> 1.001
B34: P&L | C34: =+C12 -> 1Q22 | D34: =+D12 -> 2Q22 | E34: =+E12 -> 3Q22 | F34: =+F12 -> 4Q22 | G34: =+G12 -> 1Q23 | H34: =+H12 -> 2Q23 | I34: =+I12 -> 3Q23 | J34: =+J12 -> 4Q23 | ... S34: =+S12 -> 1Q26
B36: Revenues, US$M | C36: =+C14 -> 32.461 | D36: =+D14 -> 37.5 | E36: =+E14 -> 42.098 | F36: =+F14 -> 40.341 | G36: =+G14 -> 43.567 | H36: =+H14 -> 47.524 | I36: =+I14 -> 53.233 | J36: =+J14 -> 47.376 | ... S36: =+S14 -> 54.87
B38: Opex, US$M | C38: =+SUM(C40:C47) -> 7.339 | D38: =+SUM(D40:D47) -> 8.602 | E38: =+SUM(E40:E47) -> 8.844 | F38: =+SUM(F40:F47) -> 11.109 | G38: =+SUM(G40:G47) -> 9.517 | H38: =+SUM(H40:H47) -> 10.379 | I38: =+SUM(I40:I47) -> 10.444 | J38: =+SUM(J40:J47) -> 11.659 | ... S38: =+SUM(S40:S47) -> 10.53
B39: US$/Passenger | C39: =+C38/(C$5) -> 18.049103 | D39: =+D38/(D$5) -> 15.910978 | E39: =+E38/(E$5) -> 14.062783 | F39: =+F38/(F$5) -> 18.401829 | G39: =+G38/(G$5) -> 15.400798 | H39: =+H38/(H$5) -> 15.255652 | I39: =+I38/(I$5) -> 13.706594 | J39: =+J38/(J$5) -> 17.341341 | ... S39: =+S38/(S$5) -> 15.904206
B40: Employee Benefits | C40: 2 | D40: 2.184 | E40: 1.986 | F40: =9.039-E40-D40-C40 -> 2.869 | G40: 2.294 | H40: 2.391 | I40: 2.453 | J40: =10.046-I40-H40-G40 -> 2.908 | K40: 2.37 | L40: 2.484 | M40: 2.499 | N40: =Operations!J41-M40-L40-K40 -> 2.723 | O40: 2.477 | P40: =4.869-O40 -> 2.392 | Q40: 2.389 | R40: =Operations!K41-Q40-P40-O40 -> 2.997 | S40: 2.794
B41: Services & Supplies | C41: 1.742 | D41: 2.01 | E41: 2.099 | F41: =8.28-E41-D41-C41 -> 2.429 | G41: 2.063 | H41: 2.202 | I41: 2.461 | J41: =9.561-I41-H41-G41 -> 2.835 | K41: 2.187 | L41: 2.443 | M41: 2.334 | N41: =Operations!J42-M41-L41-K41 -> 2.515 | O41: 2.194 | P41: =4.492-O41 -> 2.298 | Q41: 2.351 | R41: =Operations!K42-Q41-P41-O41 -> 2.464 | S41: 2.223
B42: Operations and Repairs | C42: 1.306 | D42: 1.56 | E42: 1.778 | F42: =6.2-E42-D42-C42 -> 1.556 | G42: 1.934 | H42: 2.074 | I42: 2.368 | J42: =8.4-I42-H42-G42 -> 2.024 | K42: 2.23 | L42: 2.229 | M42: 2.329 | N42: =Operations!J43-M42-L42-K42 -> 1.989 | O42: 2.219 | P42: =4.553-O42 -> 2.334 | Q42: 2.641 | R42: =Operations!K43-Q42-P42-O42 -> 2.246 | S42: 2.429
B43: Professional Fees | C43: 0.831 | D43: 0.647 | E43: 0.725 | F43: =3.186-E43-D43-C43 -> 0.983 | G43: 0.914 | H43: 0.749 | I43: 0.769 | J43: =3.385-I43-H43-G43 -> 0.953 | K43: 0.963 | L43: 1.047 | M43: 0.665 | N43: =Operations!J44-M43-L43-K43 -> 0.955 | O43: 0.839 | P43: =1.534-O43 -> 0.695 | Q43: 1.089 | R43: =Operations!K44-Q43-P43-O43 -> 0.808 | S43: 0.858
B44: Insurance Expenses | C44: 0.577 | D44: 0.59 | E44: 0.589 | F44: =2.383-E44-D44-C44 -> 0.627 | G44: 0.741 | H44: 0.745 | I44: 0.758 | J44: =3.025-I44-H44-G44 -> 0.781 | K44: 0.796 | L44: 0.806 | M44: 0.808 | N44: =Operations!J45-M44-L44-K44 -> 0.828 | O44: 0.732 | P44: =1.475-O44 -> 0.743 | Q44: 0.762 | R44: =Operations!K45-Q44-P44-O44 -> 0.729 | S44: 0.729
B45: Maintenance & Repairs | C45: 0.603 | D45: 0.584 | E45: 0.648 | F45: =2.7-E45-D45-C45 -> 0.865 | G45: 0.595 | H45: 0.583 | I45: 0.646 | J45: =2.3-I45-H45-G45 -> 0.476 | K45: 0.657 | L45: 0.662 | M45: 0.615 | N45: =Operations!J46-M45-L45-K45 -> 0.726 | O45: 0.536 | P45: =1.131-O45 -> 0.595 | Q45: 0.611 | R45: =Operations!K46-Q45-P45-O45 -> 0.64 | S45: 0.595
B46: Utilities | C46: 0.454 | D46: 0.48 | E46: 0.494 | F46: =1.936-E46-D46-C46 -> 0.508 | G46: 0.499 | H46: 0.531 | I46: 0.561 | J46: =2.134-I46-H46-G46 -> 0.543 | K46: 0.536 | L46: 0.58 | M46: 0.549 | N46: =Operations!J47-M46-L46-K46 -> 0.542 | O46: 0.526 | P46: =1.054-O46 -> 0.528 | Q46: 0.636 | R46: =Operations!K47-Q46-P46-O46 -> 0.644 | S46: 0.658
B47: Other Costs & Expenses | C47: -0.174 | D47: 0.547 | E47: 0.525 | F47: =2.17-E47-D47-C47 -> 1.272 | G47: 0.477 | H47: 1.104 | I47: 0.428 | J47: =3.148-I47-H47-G47 -> 1.139 | K47: 0.475 | L47: 0.505 | M47: 1.385 | N47: =Operations!J48-M47-L47-K47 -> 3.083 | O47: =0.275 -> 0.275 | P47: =0.49-O47 -> 0.215 | Q47: 0.21 | R47: =Operations!K48-Q47-P47-O47 -> 0.389 | S47: 0.244
B48: Employee Profit Sharing, US$M | C48: 1.742 | D48: 1.754 | E48: 2.111 | F48: =6.395-E48-D48-C48 -> 0.788 | G48: 2.294 | H48: 2.513 | I48: 3.108 | J48: =9.82-I48-H48-G48 -> 1.905 | K48: 2.912 | L48: 2.98 | M48: 2.974 | N48: =Operations!J49-M48-L48-K48 -> 2.354 | O48: 2.589 | P48: =5.596-O48 -> 3.007 | Q48: 3.483 | R48: =Operations!K49-Q48-P48-O48 -> 1.282 | S48: 3.054
B51: EBITDA, US$M | C51: =+C36-C38-C48 -> 23.38 | D51: =+D36-D38-D48 -> 27.144 | E51: =+E36-E38-E48 -> 31.143 | F51: =+F36-F38-F48 -> 28.444 | G51: =+G36-G38-G48 -> 31.756 | H51: =+H36-H38-H48 -> 34.632 | I51: =+I36-I38-I48 -> 39.681 | J51: =+J36-J38-J48 -> 33.812 | ... M51: =+M36-M38-M48 -> 39.477 | N51: =Operations!J52-M51-L51-K51 -> 33.506 | O51: =+O36-O38-O48 -> 37.273 | P51: =+P36-P38-P48 -> 38.933 | Q51: =+Q36-Q38-Q48 -> 44.319 | R51: =Operations!K52-Q51-P51-O51 -> 42.182 | S51: =+S36-S38-S48 -> 41.286
B52: EBITDA margin | C52: =+C51/C14 -> 0.72024891 | D52: =+D51/D14 -> 0.72384 | E52: =+E51/E14 -> 0.73977386 | F52: =+F51/F14 -> 0.70508912 | G52: =+G51/G14 -> 0.72890031 | H52: =+H51/H14 -> 0.72872654 | I52: =+I51/I14 -> 0.74542107 | J52: =+J51/J14 -> 0.7136947 | ... S52: =+S51/S14 -> 0.75243302
...

Sheet Financials
B2: P&L | C2: =+Operations!E3 -> 2019 | D2: =+Operations!F3 -> 2020 | E2: =+Operations!G3 -> 2021 | F2: =+Operations!H3 -> 2022 | G2: =+Operations!I3 -> 2023 | H2: =+Operations!J3 -> 2024 | I2: =+Operations!K3 -> 2025 | J2: =+Operations!L3 -> 2026E | ... V2: =+Operations!X3 -> 2038E
B4: Core Revenues, US$M | C4: =Operations!E13 -> 174.155 | D4: =Operations!F13 -> 80.653 | E4: =Operations!G13 -> 103.831 | F4: =Operations!H13 -> 152.4 | G4: =Operations!I13 -> 191.7 | H4: =Operations!J13 -> 203.7 | I4: =Operations!K13 -> 214.272 | J4: =Operations!L13 -> 217.93589 | ... V4: =Operations!X13 -> 318.68145
B5: Opex - D&A, US$M | C5: =+C4-C6 -> 51.984 | D5: =+D4-D6 -> 31.322 | E5: =+E4-E6 -> 36.028 | F5: =+F4-F6 -> 42.279 | G5: =+G4-G6 -> 51.818 | H5: =+H4-H6 -> 56.735 | I5: =+I4-I6 -> 51.565 | J5: =+J4-J6 -> 51.269885 | ... V5: =+V4-V6 -> 85.330631
B6: EBITDA, US$M | C6: =+Operations!E52 -> 122.171 | D6: =+Operations!F52 -> 49.331 | E6: =+Operations!G52 -> 67.803 | F6: =+Operations!H52 -> 110.121 | G6: =+Operations!I52 -> 139.882 | H6: =+Operations!J52 -> 146.965 | I6: =+Operations!K52 -> 162.707 | J6: =+Operations!L52 -> 166.66601 | ... V6: =+Operations!X52 -> 233.35082
B7: D&A, US$M | C7: =+C6-C8 -> 34.151 | D7: =+D6-D8 -> 28.608 | E7: =+E6-E8 -> 16.192 | F7: =+F6-F8 -> 26.3 | G7: =+G6-G8 -> 36.2 | H7: =+H6-H8 -> 37.682 | I7: =+I6-I8 -> 45.019 | J7: =+J6-J8 -> 35.3182 | ... V7: =+V6-V8 -> 27.946262
B8: EBIT, US$M | C8: =+Operations!E58 -> 88.02 | D8: =+Operations!F58 -> 20.723 | E8: =+Operations!G58 -> 51.611 | F8: =+Operations!H58 -> 83.821 | G8: =+Operations!I58 -> 103.682 | H8: =+Operations!J58 -> 109.283 | I8: =+Operations!K58 -> 117.688 | J8: =+Operations!L58 -> 131.34781 | ... V8: =+Operations!X58 -> 205.40456
B9: Interest Revenue, US$M | C9: 6.1 | D9: 2.9 | E9: 2.5 | F9: 2.4 | G9: 4 | H9: 5.156 | I9: 4.722 | J9: =+J38*I37 -> 8.0853825 | K9: =+K38*J37 -> 8.1685018 | L9: =+L38*K37 -> 8.6735523 | M9: =+M38*L37 -> 7.8088848 | N9: =+N38*M37 -> 1.9354891 | O9: =+O38*N37 -> 1.9581709 | P9: =+P38*O37 -> 1.927522 | Q9: =+Q38*P37 -> 1.7927158 | ... V9: =+V38*U37 -> 2.5099485
B10: Interest Paid (Financial Costs), US$M | C10: 44.6 | D10: 49.6 | E10: 50.8 | F10: 48.9 | G10: 49.5 | H10: 49.775 | I10: 59.707 | J10: =J47*I40 -> 43.58133 | K10: =+K47*J40 -> 43.52886 | L10: =+L47*K40 -> 43.52886 | M10: =+M47*L40 -> 42.44886 | N10: =+N47*M40 -> 39.92886 | O10: =+O47*N40 -> 37.04886 | P10: =+P47*O40 -> 33.53886 | Q10: =+Q47*P40 -> 29.39886 | R10: =+R47*Q40 -> 24.71886 | ... V10: =+V47*U40 -> -1.29114
B11: Pre-Tax Earnings, US$M | C11: =+C8+C9-C10 -> 49.52 | D11: =+D8+D9-D10 -> -25.977 | E11: =+E8+E9-E10 -> 3.311 | F11: =+F8+F9-F10 -> 37.321 | G11: =+G8+G9-G10 -> 58.182 | H11: =+H8+H9-H10 -> 64.664 | I11: =+I8+I9-I10 -> 62.703 | J11: =+J8+J9-J10 -> 95.851862 | ... V11: =+V8+V9-V10 -> 209.20565
B12: Taxes, US$M | C12: =+C11-C13 -> 1.72 | D12: =+D11-D13 -> 1.023 | E12: =+E11-E13 -> 1.111 | F12: =+F11-F13 -> 1.121 | G12: =+G11-G13 -> 1.282 | H12: =+H11-H13 -> 1.083 | I12: =+I11-I13 -> 6.029 | J12: =+J11*J17 -> 23.962965 | K12: =+K11*K17 -> 25.248119 | L12: =+L11*L17 -> 27.132221 | M12: =+M11*M17 -> 28.905875 | N12: =+N11*N17 -> 29.634401 | O12: =+O11*O17 -> 32.391863 | P12: =+P11*P17 -> 35.132365 | Q12: =+Q11*Q17 -> 38.079883 | ... V12: =+V11*V17 -> 52.301412
B13: Net Income, US$M | C13: 47.8 | D13: -27 | E13: 2.2 | F13: 36.2 | G13: 56.9 | H13: 63.581 | I13: 56.674 | J13: =+J11-J12 -> 71.888896 | K13: =+K11-K12 -> 75.744357 | L13: =+L11-L12 -> 81.396664 | M13: =+M11-M12 -> 86.717624 | N13: =+N11-N12 -> 88.903203 | O13: =+O11-O12 -> 97.17559 | P13: =+P11-P12 -> 105.3971 | Q13: =+Q11-Q12 -> 114.23965 | ... V13: =+V11-V12 -> 156.90424
B15: Dividends, US$M | C15: 230 | D15: 0 | E15: 0 | F15: 31.3 | G15: 65.8 | H15: 51.51 | I15: 152.49 | J15: =+J16*J13 -> 71.888896 | K15: =+K16*K13 -> 75.744357 | L15: =+L16*L13 -> 81.396664 | M15: =+M16*M13 -> 69.374099 | N15: =+N16*N13 -> 71.122562 | O15: =+O16*O13 -> 77.740472 | P15: =+P16*P13 -> 84.317676 | Q15: =+Q16*Q13 -> 57.119825 | ... V15: =+V16*V13 -> 78.452118
B16: Payout as % of Net Income | C16: =+C15/C13 -> 4.8117155 | D16: =+D15/D13 -> 0 | E16: =+E15/E13 -> 0 | F16: =+F15/F13 -> 0.86464088 | G16: =+G15/G13 -> 1.1564148 | H16: =+H15/H13 -> 0.81014769 | I16: =+I15/I13 -> 2.6906518 | J16: 1 | K16: 1 | L16: 1 | M16: 0.8 | N16: 0.8 | O16: 0.8 | P16: 0.8 | Q16: 0.5 | R16: 0.5 | S16: 0.5 | T16: 0.5 | U16: 0.5 | V16: 0.5
B17: Effective Tax Rate | C17: =+C12/C11 -> 0.034733441 | D17: =+D12/D11 -> -0.039380991 | E17: =+E12/E11 -> 0.33554817 | F17: =+F12/F11 -> 0.030036709 | G17: =+G12/G11 -> 0.022034306 | H17: =+H12/H11 -> 0.016748113 | I17: =+I12/I11 -> 0.096151699 | J17: 0.25 | K17: 0.25 | L17: 0.25 | M17: 0.25 | N17: 0.25 | O17: 0.25 | P17: 0.25 | Q17: 0.25 | R17: 0.25 | S17: 0.25 | T17: 0.25 | U17: 0.25 | V17: 0.25
B18: US CPI Inflation | C18: =+Operations!E33 -> 0.023 | D18: =+Operations!F33 -> 0.014 | E18: =+Operations!G33 -> 0.07 | F18: =+Operations!H33 -> 0.065 | G18: =+Operations!I33 -> 0.033 | H18: =+Operations!J33 -> 0.023 | I18: =+Operations!K33 -> 0.033 | J18: =+Operations!L33 -> 0.02 | ... V18: =+Operations!X33 -> 0
B20: Balance Sheet | C20: =+C2 -> 2019 | D20: =+D2 -> 2020 | E20: =+E2 -> 2021 | F20: =+F2 -> 2022 | G20: =+G2 -> 2023 | H20: =+H2 -> 2024 | I20: =+I2 -> 2025 | J20: =+J2 -> 2026E | ... V20: =+V2 -> 2038E
B22: Cash, US$M | C22: 67.9 | D22: 33.1 | E22: 36.7 | F22: =45.8+0.5 -> 46.3 | G22: =37.6+16 -> 53.6 | H22: =37.179+5.089 -> 42.268 | I22: 79.49 | J22: =+I22+SUM(I23:I25)-SUM(J23:J25)+J31-I31+J33-I33 -> 89.06327 | K22: =+J22+SUM(J23:J25)-SUM(K23:K25)+K31-J31+K33-J33 -> 106.14301 | L22: =+K22+SUM(K23:K25)-SUM(L23:L25)+L31-K31+L33-K33 -> 108.88666 | M22: =+L22+SUM(L23:L25)-SUM(M23:M25)+M31-L31+M33-L33 -> 96.774453 | N22: =+M22+SUM(M23:M25)-SUM(N23:N25)+N31-M31+N33-M33 -> 97.908547 | O22: =+N22+SUM(N23:N25)-SUM(O23:O25)+O31-N31+O33-N33 -> 96.376098 | P22: =+O22+SUM(O23:O25)-SUM(P23:P25)+P31-O31+P33-O33 -> 89.635791 | Q22: =+P22+SUM(P23:P25)-SUM(Q23:Q25)+Q31-P31+Q33-P33 -> 109.63592 | ... V22: =+U22+SUM(U23:U25)-SUM(V23:V25)+V31-U31+V33-U33 -> 207.31225
B23: Trade and Other Receivables, US$M | C23: 42.757 | D23: 32.26 | E23: 30.516 | F23: 34.835 | G23: 31.055 | H23: 47.37 | I23: 14.705 | J23: =+I23*J4/I4 -> 14.956445 | K23: =+J23*K4/J4 -> 15.513759 | L23: =+K23*L4/K4 -> 16.091931 | M23: =+L23*M4/L4 -> 16.691747 | N23: =+M23*N4/M4 -> 17.314021 | O23: =+N23*O4/N4 -> 17.959595 | P23: =+O23*P4/O4 -> 18.629348 | Q23: =+P23*Q4/P4 -> 19.324189 | ... V23: =+U23*V4/U4 -> 21.870383
B24: PP&E + Intangibles, US$M | C24: =+Operations!E56 -> 732.949 | D24: =+Operations!F56 -> 725.062 | E24: =+Operations!G56 -> 725 | F24: =+Operations!H56 -> 708.9 | G24: =+Operations!I56 -> 707.8 | H24: =+Operations!J56 -> 701.7 | I24: =+Operations!K56 -> 706.364 | J24: =+Operations!L56 -> 690.5458 | ... V24: =+Operations!X56 -> 557.17899
B25: Others, US$M | C25: =+C26-SUM(C22:C24) -> 23.712 | D25: =+D26-SUM(D22:D24) -> 23.646 | E25: =+E26-SUM(E22:E24) -> 22.17 | F25: =+F26-SUM(F22:F24) -> 21.965 | G25: =+G26-SUM(G22:G24) -> 21.545 | H25: =+H26-SUM(H22:H24) -> 21.762 | I25: =+I26-SUM(I22:I24) -> 3.335 | J25: =+I25 -> 3.335 | K25: =+J25 -> 3.335 | L25: =+K25 -> 3.335 | M25: =+L25 -> 3.335 | N25: =+M25 -> 3.335 | O25: =+N25 -> 3.335 | P25: =+O25 -> 3.335 | Q25: =+P25 -> 3.335 | ... V25: =+U25 -> 3.335
B26: Assets, US$M | C26: 867.318 | D26: 814.068 | E26: 814.386 | F26: 812 | G26: 814 | H26: 813.1 | I26: 803.894 | J26: =+SUM(J22:J25) -> 797.90051 | K26: =+SUM(K22:K25) -> 798.11028 | L26: =+SUM(L22:L25) -> 786.67617 | M26: =+SUM(M22:M25) -> 778.84566 | N26: =+SUM(N22:N25) -> 761.8998 | O26: =+SUM(O22:O25) -> 742.54581 | P26: =+SUM(P22:P25) -> 717.9315 | Q26: =+SUM(Q22:Q25) -> 723.9099 | ... V26: =+SUM(V22:V25) -> 789.69662
B28: Financial Debt, US$M | C28: 397.728 | D28: 394.7 | E28: 392.711 | F28: =9.4+380.1 -> 389.5 | G28: =17.5+376.6 -> 394.1 | H28: =21.459+363.334 -> 384.793 | I28: =1.621+482.616 -> 484.237 | J28: =+J40 -> 483.654 | K28: =+K40 -> 483.654 | L28: =+L40 -> 471.654 | M28: =+M40 -> 443.654 | N28: =+N40 -> 411.654 | O28: =+O40 -> 372.654 | P28: =+P40 -> 326.654 | Q28: =+Q40 -> 274.654 | ... V28: =+V40 -> -14.346
B29: Trade and Other Payables, US$M | C29: 11.1 | D29: 7.5 | E29: 10.4 | F29: 11.3 | G29: 17.6 | H29: 21.6 | I29: 15.263 | J29: =+I29*(J5+J67)/(I5+I67) -> 9.8525148 | K29: =+J29*(K5+K67)/(J5+J67) -> 10.062278 | L29: =+K29*(L5+L67)/(K5+K67) -> 10.628172 | M29: =+L29*(M5+M67)/(L5+L67) -> 13.454131 | N29: =+M29*(N5+N67)/(M5+M67) -> 10.727635 | O29: =+N29*(O5+O67)/(N5+N67) -> 10.938531 | P29: =+O29*(P5+P67)/(O5+O67) -> 11.244801 | Q29: =+P29*(Q5+Q67)/(P5+P67) -> 12.103378 | ... V29: =+U29*(V5+V67)/(U5+U67) -> 15.527186
B30: Others, US$M | C30: =+C31-C29-C28 -> 218.585 | D30: =+D31-D29-D28 -> 200.934 | E30: =+E31-E29-E28 -> 198.049 | F30: =+F31-F29-F28 -> 192.835 | G30: =+G31-G29-G28 -> 193.083 | H30: =+H31-H29-H28 -> 185.907 | I30: =+I31-I29-I28 -> 178.909 | J30: =+I30 -> 178.909 | K30: =+J30 -> 178.909 | L30: =+K30 -> 178.909 | M30: =+L30 -> 178.909 | N30: =+M30 -> 178.909 | O30: =+N30 -> 178.909 | P30: =+O30 -> 178.909 | Q30: =+P30 -> 178.909 | ... V30: =+U30 -> 178.909
B31: Liabilities, US$M | C31: 627.413 | D31: 603.134 | E31: 601.16 | F31: 593.635 | G31: 604.783 | H31: 592.3 | I31: 678.409 | J31: =+SUM(J28:J30) -> 672.41551 | K31: =+SUM(K28:K30) -> 672.62528 | L31: =+SUM(L28:L30) -> 661.19117 | M31: =+SUM(M28:M30) -> 636.01713 | N31: =+SUM(N28:N30) -> 601.29063 | O31: =+SUM(O28:O30) -> 562.50153 | P31: =+SUM(P28:P30) -> 516.8078 | Q31: =+SUM(Q28:Q30) -> 465.66638 | ... V31: =+SUM(V28:V30) -> 180.09019
B33: Equity, US$M | C33: =+C26-C31 -> 239.905 | D33: =+D26-D31 -> 210.934 | E33: =+E26-E31 -> 213.226 | F33: =+F26-F31 -> 218.365 | G33: =+G26-G31 -> 209.217 | H33: =+H26-H31 -> 220.8 | I33: =+I26-I31 -> 125.485 | J33: =+I33+J13-J15 -> 125.485 | K33: =+J33+K13-K15 -> 125.485 | L33: =+K33+L13-L15 -> 125.485 | M33: =+L33+M13-M15 -> 142.82852 | N33: =+M33+N13-N15 -> 160.60917 | O33: =+N33+O13-O15 -> 180.04428 | P33: =+O33+P13-P15 -> 201.1237 | Q33: =+P33+Q13-Q15 -> 258.24353 | ... V33: =+U33+V13-V15 -> 609.60643
C34: =+C33+C31-C26 -> 0 | D34: =+D33+D31-D26 -> 0 | E34: =+E33+E31-E26 -> 0 | F34: =+F33+F31-F26 -> 0 | G34: =+G33+G31-G26 -> 0 | H34: =+H33+H31-H26 -> 0
B35: Leverage and Cash Flows | C35: =+C20 -> 2019 | D35: =+D20 -> 2020 | E35: =+E20 -> 2021 | F35: =+F20 -> 2022 | G35: =+G20 -> 2023 | H35: =+H20 -> 2024 | I35: =+I20 -> 2025 | J35: =+J20 -> 2026E | ... V35: =+V20 -> 2038E
B37: Cash & Equivalents | C37: =+C22 -> 67.9 | D37: =+D22 -> 33.1 | E37: =+E22 -> 36.7 | F37: =+F22 -> 46.3 | G37: =+G22 -> 53.6 | H37: =+H22 -> 42.268 | I37: =+I22 -> 79.49 | J37: =+J22 -> 89.06327 | ... V37: =+V22 -> 207.31225
B38: Interest on Cash | D38: =+D9/C37 -> 0.042709867 | E38: =+E9/D37 -> 0.075528701 | F38: =+F9/E37 -> 0.065395095 | G38: =+G9/F37 -> 0.086393089 | H38: =+H9/G37 -> 0.09619403 | I38: =+I9/H37 -> 0.11171572 | J38: =+I38-0.01 -> 0.10171572 | K38: =+J38-0.01 -> 0.091715719 | L38: =+K38-0.01 -> 0.081715719 | M38: =+L38-0.01 -> 0.071715719 | N38: 0.02 | O38: 0.02 | P38: 0.02 | Q38: 0.02 | R38: 0.02 | S38: 0.02 | T38: 0.02 | U38: 0.02 | V38: 0.02
B40: Financial Debt, US$M | C40: =+C28 -> 397.728 | D40: =+D28 -> 394.7 | E40: =+E28 -> 392.711 | F40: =+F28 -> 389.5 | G40: =+G28 -> 394.1 | H40: =+H28 -> 384.793 | I40: =+I28 -> 484.237 | J40: =+I40+J49-J51 -> 483.654 | K40: =+J40+K49-K51 -> 483.654 | L40: =+K40+L49-L51 -> 471.654 | M40: =+L40+M49-M51 -> 443.654 | N40: =+M40+N49-N51 -> 411.654 | O40: =+N40+O49-O51 -> 372.654 | P40: =+O40+P49-P51 -> 326.654 | Q40: =+P40+Q49-Q51 -> 274.654 | ... V40: =+U40+V49-V51 -> -14.346
B41: QUIPORT US$400M 12.0% due Mar. 2033 | C41: 397.3 | D41: 394.2 | E41: 302.2 | F41: 388.7 | G41: 383.5 | H41: 370.823 | I41: 0 | J41: =+I41-J52 -> 0 | K41: =+J41-K52 -> 0 | L41: =+K41-L52 -> 0 | M41: =+L41-M52 -> 0 | N41: =+M41-N52 -> 0 | O41: =+N41-O52 -> 0 | P41: =+O41-P52 -> 0 | Q41: =+P41-Q52 -> 0 | ... V41: =+U41-V52 -> 0
B42: Local Banks | C42: 0 | D42: 0 | E42: 90 | F42: 0 | G42: 10 | H42: 13.3 | I42: 210.157 | J42: 0 | K42: =+J42-K53 -> 0 | L42: =+K42-L53 -> 0 | M42: =+L42-M53 -> 0 | N42: =+M42-N53 -> 0 | O42: =+N42-O53 -> 0 | P42: =+O42-P53 -> 0 | Q42: =+P42-Q53 -> 0 | R42: =+Q42-R53 -> 0 | ... V42: =+U42-V53 -> 0
B43: Foreings | I43: 273.497 | J43: 0 | K43: =+J43-K54 -> 0 | L43: =+K43-L54 -> 0 | M43: =+L43-M54 -> 0 | N43: =+M43-N54 -> 0 | O43: =+N43-O54 -> 0 | P43: =+O43-P54 -> 0 | Q43: =+P43-Q54 -> 0 | R43: =+Q43-R54 -> 0 | ... V43: =+U43-V54 -> 0
B44: QUIPORT US$300M 9.0% due Dec. 2037 | J44: 300 | K44: =+J44-K55 -> 300 | L44: =+K44-L55 -> 300 | M44: =+L44-M55 -> 300 | N44: =+M44-N55 -> 281 | O44: =+N44-O55 -> 262 | P44: =+O44-P55 -> 242 | Q44: =+P44-Q55 -> 222 | R44: =+Q44-R55 -> 202 | ... V44: =+U44-V55 -> 1
B45: Ecuadorian Loans due 2035 | J45: 200 | K45: =+J45-K56 -> 200 | L45: =+K45-L56 -> 188 | M45: =+L45-M56 -> 160 | N45: =+M45-N56 -> 147 | O45: =+N45-O56 -> 127 | P45: =+O45-P56 -> 101 | Q45: =+P45-Q56 -> 69 | R45: =+Q45-R56 -> 34 | ... V45: =+U45-V56 -> 1
B46: Others (incl. accrued interest) | C46: =+C40-C41-C42 -> 0.428 | D46: =+D40-D41-D42 -> 0.5 | E46: =+E40-E41-E42 -> 0.511 | F46: =+F40-F41-F42 -> 0.8 | G46: =+G40-G41-G42 -> 0.6 | H46: =+H40-H41-H42 -> 0.67 | I46: =+I40-SUM(I41:I45) -> 0.583 | J46: =+J40-SUM(J41:J45) -> -16.346 | K46: =+K40-SUM(K41:K45) -> -16.346 | L46: =+L40-SUM(L41:L45) -> -16.346 | M46: =+M40-SUM(M41:M45) -> -16.346 | N46: =+N40-SUM(N41:N45) -> -16.346 | O46: =+O40-SUM(O41:O45) -> -16.346 | P46: =+P40-SUM(P41:P45) -> -16.346 | ... V46: =+V40-SUM(V41:V45) -> -16.346
B47: Interest on Debt | D47: =+D10/C40 -> 0.12470834 | E47: =+E10/D40 -> 0.12870535 | F47: =+F10/E40 -> 0.12451905 | G47: =+G10/F40 -> 0.12708601 | H47: =+H10/G40 -> 0.12630043 | I47: =+I10/H40 -> 0.15516654 | J47: 0.09 | K47: 0.09 | L47: 0.09 | M47: 0.09 | N47: 0.09 | O47: 0.09 | P47: 0.09 | Q47: 0.09 | R47: 0.09 | S47: 0.09 | T47: 0.09 | U47: 0.09 | V47: 0.09
B49: New Debt, US$M | C49: 0 | D49: 0 | E49: 0 | F49: 0 | G49: 10 | H49: 3.5 | I49: 200 | J49: 0 | K49: 0 | L49: 0 | M49: 0 | N49: 0 | O49: 0 | P49: 0 | Q49: 0 | R49: 0 | S49: 0 | T49: 0 | U49: 0 | V49: 0
B51: Debt Amortizations | C51: 0 | D51: 0 | E51: 5 | F51: 4.1 | G51: 6.2 | H51: =14.12+0.26 -> 14.38 | I51: =70.814+0.26 -> 71.074 | J51: =+SUM(J52:J57) -> 0.583 | K51: =+SUM(K52:K56) -> 0 | L51: =+SUM(L52:L56) -> 12 | M51: =+SUM(M52:M56) -> 28 | N51: =+SUM(N52:N56) -> 32 | O51: =+SUM(O52:O56) -> 39 | P51: =+SUM(P52:P56) -> 46 | Q51: =+SUM(Q52:Q56) -> 52 | R51: =+SUM(R52:R56) -> 55 | ... V51: =+SUM(V52:V56) -> 0
...

Sheet Operations
C2: =DATE(2018,12,31) -> 43465 | E2: 43830 | F2: =DATE(YEAR(E2+1),12,31) -> 44196 | G2: =DATE(YEAR(F2+1),12,31) -> 44561 | H2: =DATE(YEAR(G2+1),12,31) -> 44926 | I2: =DATE(YEAR(H2+1),12,31) -> 45291 | J2: =DATE(YEAR(I2+1),12,31) -> 45657 | K2: =DATE(YEAR(J2+1),12,31) -> 46022 | L2: =DATE(YEAR(K2+1),12,31) -> 46387 | M2: =DATE(YEAR(L2+1),12,31) -> 46752 | ... X2: =DATE(YEAR(W2+1),12,31) -> 50770
B3: Operational data | C3: 2018 | E3: =+[36]PG!I3 -> 2019 | F3: 2020 | G3: 2021 | H3: 2022 | I3: 2023 | J3: 2024 | K3: 2025 | L3: =+(CONCATENATE((LEFT(K3,4)*1+1),"E")) -> 2026E | M3: =+(CONCATENATE((LEFT(L3,4)*1+1),"E")) -> 2027E | N3: =+(CONCATENATE((LEFT(M3,4)*1+1),"E")) -> 2028E | O3: =+(CONCATENATE((LEFT(N3,4)*1+1),"E")) -> 2029E | P3: =+(CONCATENATE((LEFT(O3,4)*1+1),"E")) -> 2030E | Q3: =+(CONCATENATE((LEFT(P3,4)*1+1),"E")) -> 2031E | R3: =+(CONCATENATE((LEFT(Q3,4)*1+1),"E")) -> 2032E | S3: =+(CONCATENATE((LEFT(R3,4)*1+1),"E")) -> 2033E | ... X3: =+(CONCATENATE((LEFT(W3,4)*1+1),"E")) -> 2038E
B5: Departing Passengers, M | C5: =+C8+C6 -> 2.602629 | D5: =1.431+1.17 -> 2.601 | E5: =+E8+E6 -> 2.520575 | F5: =+F8+F6 -> 0.773384 | G5: =+G8+G6 -> 1.215388 | H5: =+H8+H6 -> 2.17983 | I5: =+I8+I6 -> 2.732586 | J5: =+J6+J8 -> 2.677016 | K5: =K6+K8 -> 2.678752 | L5: =+L6+L8 -> 2.7259625 | M5: =+M6+M8 -> 2.7740217 | N5: =+N6+N8 -> 2.8229451 | O5: =+O6+O8 -> 2.8727487 | P5: =+P6+P8 -> 2.9234486 | Q5: =+Q6+Q8 -> 2.9750611 | R5: =+R6+R8 -> 3.027603 | S5: =+S6+S8 -> 3.0810914 | ... X5: =+X6+X8 -> 3.3633491
B6: International | C6: 1.17089 | E6: 1.167121 | F6: 0.369627 | G6: 0.638771 | H6: 0.934 | I6: 1.244688 | J6: 1.249612 | K6: 1.272916 | L6: =+K6*(1+L7) -> 1.2920097 | M6: =+L6*(1+M7) -> 1.3113899 | N6: =+M6*(1+N7) -> 1.3310607 | O6: =+N6*(1+O7) -> 1.3510266 | P6: =+O6*(1+P7) -> 1.371292 | Q6: =+P6*(1+Q7) -> 1.3918614 | R6: =+Q6*(1+R7) -> 1.4127393 | S6: =+R6*(1+S7) -> 1.4339304 | ... X6: =+W6*(1+X7) -> 1.5447503
B7: YOY | E7: =+E6/C6-1 -> -0.0032189189 | F7: =+F6/E6-1 -> -0.68330019 | G7: =+G6/F6-1 -> 0.72815027 | H7: =+H6/G6-1 -> 0.46218285 | I7: =+I6/H6-1 -> 0.3326424 | J7: =+J6/I6-1 -> 0.0039560115 | K7: =+K6/J6-1 -> 0.018648989 | L7: 0.015 | M7: 0.015 | N7: 0.015 | O7: 0.015 | P7: 0.015 | Q7: 0.015 | R7: 0.015 | S7: 0.015 | T7: 0.015 | U7: 0.015 | V7: 0.015 | W7: 0.015 | X7: 0.015
B8: Domestic | C8: 1.431739 | E8: 1.353454 | F8: 0.403757 | G8: 0.576617 | H8: 1.24583 | I8: 1.487898 | J8: 1.427404 | K8: 1.405836 | L8: =+K8*(1+L9) -> 1.4339527 | M8: =+L8*(1+M9) -> 1.4626318 | N8: =+M8*(1+N9) -> 1.4918844 | O8: =+N8*(1+O9) -> 1.5217221 | P8: =+O8*(1+P9) -> 1.5521565 | Q8: =+P8*(1+Q9) -> 1.5831997 | R8: =+Q8*(1+R9) -> 1.6148637 | S8: =+R8*(1+S9) -> 1.6471609 | ... X8: =+W8*(1+X9) -> 1.8185988
B9: YOY | E9: =+E8/C8-1 -> -0.054678262 | F9: =+F8/E8-1 -> -0.70168399 | G9: =+G8/F8-1 -> 0.4281288 | H9: =+H8/G8-1 -> 1.1605849 | I9: =+I8/H8-1 -> 0.19430259 | J9: =+J8/I8-1 -> -0.040657357 | K9: =+K8/J8-1 -> -0.015109948 | L9: =+L7+0.005 -> 0.02 | M9: =+M7+0.005 -> 0.02 | N9: =+N7+0.005 -> 0.02 | O9: =+O7+0.005 -> 0.02 | P9: =+P7+0.005 -> 0.02 | Q9: =+Q7+0.005 -> 0.02 | R9: =+R7+0.005 -> 0.02 | S9: =+S7+0.005 -> 0.02 | ... X9: =+X7+0.005 -> 0.02
B11: Revenues | C11: =+C3 -> 2018 | E11: =+E3 -> 2019 | F11: =+F3 -> 2020 | G11: =+G3 -> 2021 | H11: =+H3 -> 2022 | I11: =+I3 -> 2023 | J11: =+J3 -> 2024 | K11: =+K3 -> 2025 | L11: =+L3 -> 2026E | ... X11: =+X3 -> 2038E
B13: Core Revenues, US$M | E13: 174.155 | F13: 80.653 | G13: 103.831 | H13: 152.4 | I13: 191.7 | J13: 203.7 | K13: 214.272 | L13: =+L15+L25 -> 217.93589 | M13: =+M15+M25 -> 226.05672 | N13: =+N15+N25 -> 234.48149 | O13: =+O15+O25 -> 243.22163 | P13: =+P15+P25 -> 252.289 | Q13: =+Q15+Q25 -> 261.69591 | R13: =+R15+R25 -> 271.45513 | S13: =+S15+S25 -> 281.57991 | ... X13: =+X15+X25 -> 318.68145
B15: Regulated Revenues, US$M | E15: 122.344 | F15: 53.863 | G15: 73.497 | H15: 105.174 | I15: 139.1 | J15: 145.5 | K15: 154.129 | L15: =+L16+L21 -> 159.83101 | M15: =+M16+M21 -> 165.74485 | N15: =+N16+N21 -> 171.87843 | O15: =+O16+O21 -> 178.23995 | P15: =+P16+P21 -> 184.83792 | Q15: =+Q16+Q21 -> 191.68116 | R15: =+R16+R21 -> 198.77884 | S15: =+S16+S21 -> 206.14045 | ... X15: =+X16+X21 -> 233.00405
B16: Passenger Revenues, US$M | E16: 77.483 | F16: 24.517 | G16: 39.351 | H16: 66.094 | I16: 91.375 | J16: 93.764 | K16: 97.411 | L16: =+((L19*L6)+(L20*L8))*L18 -> 100.95905 | M16: =+((M19*M6)+(M20*M8))*M18 -> 104.63677 | N16: =+((N19*N6)+(N20*N8))*N18 -> 108.44892 | O16: =+((O19*O6)+(O20*O8))*O18 -> 112.40042 | P16: =+((P19*P6)+(P20*P8))*P18 -> 116.49639 | Q16: =+((Q19*Q6)+(Q20*Q8))*Q18 -> 120.74212 | R16: =+((R19*R6)+(R20*R8))*R18 -> 125.14312 | S16: =+((S19*S6)+(S20*S8))*S18 -> 129.70508 | ... X16: =+((X19*X6)+(X20*X8))*X18 -> 146.19559
B17: Realized Net Tariffs, US$ | E17: =+E16/E$5 -> 30.740208 | F17: =+F16/F$5 -> 31.70094 | G17: =+G16/G$5 -> 32.377315 | H17: =+H16/H$5 -> 30.320713 | I17: =+I16/I$5 -> 33.439021 | J17: =+J16/J$5 -> 35.025566 | K17: =+K16/K$5 -> 36.364322 | L17: =+L16/L$5 -> 37.036113 | ... X17: =+X16/X$5 -> 43.467266
B18: Quiport Participation | E18: 0.89 | F18: 0.89 | G18: 0.89 | H18: 0.89 | I18: 0.89 | J18: 0.89 | K18: 0.89 | L18: 0.89 | M18: =+L18 -> 0.89 | N18: =+M18 -> 0.89 | O18: =+N18 -> 0.89 | P18: =+O18 -> 0.89 | Q18: =+P18 -> 0.89 | R18: =+Q18 -> 0.89 | S18: =+R18 -> 0.89 | T18: =+S18 -> 0.89 | ... X18: =+W18 -> 0.89
B19: International (estimated) | C19: 55.57 | E19: 55.8 | F19: =+E19*(1+F$33) -> 56.5812 | G19: =+F19*(1+G$33) -> 60.541884 | H19: =+G19*(1+H$33) -> 64.477106 | I19: =+H19*(1+I$33) -> 66.604851 | J19: 64.9 | K19: =+J19*(1+K$33) -> 67.0417 | L19: =+K19*(1+L$33) -> 68.382534 | M19: =+L19*(1+M$33) -> 69.750185 | N19: =+M19*(1+N$33) -> 71.145188 | O19: =+N19*(1+O$33) -> 72.568092 | P19: =+O19*(1+P$33) -> 74.019454 | Q19: =+P19*(1+Q$33) -> 75.499843 | R19: =+Q19*(1+R$33) -> 77.00984 | ... X19: =+W19*(1+X$33) -> 81.723458
B20: Domestic (estimated) | E20: =((E16-(E19*E6*E18)))/E18/E8 -> 16.206091 | F20: =((F16-(F19*F6*F18)))/F18/F8 -> 16.428822 | G20: =((G16-(G19*G6*G18)))/G18/G8 -> 9.6115913 | H20: =((H16-(H19*H6*H18)))/H18/H8 -> 11.270642 | I20: =((I16-(I19*I6*I18)))/I18/I8 -> 13.284701 | J20: 14.4 | K20: =((K16-(K19*K6*K18)))/K18/K8 -> 17.151438 | L20: =+K20*(1+L$33) -> 17.494467 | M20: =+L20*(1+M$33) -> 17.844356 | N20: =+M20*(1+N$33) -> 18.201243 | O20: =+N20*(1+O$33) -> 18.565268 | P20: =+O20*(1+P$33) -> 18.936574 | Q20: =+P20*(1+Q$33) -> 19.315305 | R20: =+Q20*(1+R$33) -> 19.701611 | S20: =+R20*(1+S$33) -> 20.095643 | ... X20: =+W20*(1+X$33) -> 20.907507
B21: Airport Services, US$M | E21: =+E15-E16 -> 44.861 | F21: =+F15-F16 -> 29.346 | G21: =+G15-G16 -> 34.146 | H21: =+H15-H16 -> 39.08 | I21: =+I15-I16 -> 47.725 | J21: =+J15-J16 -> 51.736 | K21: =+K15-K16 -> 56.718 | L21: =+L23*L5*L22 -> 58.871953 | M21: =+M23*M5*M22 -> 61.108073 | N21: =+N23*N5*N22 -> 63.42951 | O21: =+O23*O5*O22 -> 65.839531 | P21: =+P23*P5*P22 -> 68.341533 | Q21: =+Q23*Q5*Q22 -> 70.939042 | R21: =+R23*R5*R22 -> 73.635719 | S21: =+S23*S5*S22 -> 76.435366 | ... X21: =+X23*X5*X22 -> 86.808462
B22: Quiport Participation | E22: =+E18 -> 0.89 | F22: =+F18 -> 0.89 | G22: =+G18 -> 0.89 | H22: =+H18 -> 0.89 | I22: =+I18 -> 0.89 | J22: =+J18 -> 0.89 | K22: =+K18 -> 0.89 | L22: =+L18 -> 0.89 | ... X22: =+X18 -> 0.89
B23: Realized Net Tariffs, US$ | E23: =+E21/E$5/E22 -> 19.997666 | F23: =+F21/F$5/F22 -> 42.63475 | G23: =+G21/G$5/G22 -> 31.567114 | H23: =+H21/H$5/H22 -> 20.143824 | I23: =+I21/I$5/I22 -> 19.623754 | J23: =+J21/J$5/J22 -> 21.714602 | K23: =+K21/K$5/K22 -> 23.790216 | L23: =+K23*(1+L$33) -> 24.266021 | M23: =+L23*(1+M$33) -> 24.751341 | N23: =+M23*(1+N$33) -> 25.246368 | O23: =+N23*(1+O$33) -> 25.751295 | P23: =+O23*(1+P$33) -> 26.266321 | Q23: =+P23*(1+Q$33) -> 26.791648 | R23: =+Q23*(1+R$33) -> 27.327481 | S23: =+R23*(1+S$33) -> 27.87403 | ... X23: =+W23*(1+X$33) -> 29.000141
B25: Non-Regulated, US$M | E25: 44.651 | F25: 18.41 | G25: 27.668 | H25: 39.894 | I25: 50.579 | J25: 53.48 | K25: 55.979 | L25: =+L26+L28 -> 58.104888 | M25: =+M26+M28 -> 60.311873 | N25: =+N26+N28 -> 62.603063 | O25: =+O26+O28 -> 64.981683 | P25: =+P26+P28 -> 67.451086 | Q25: =+Q26+Q28 -> 70.014751 | R25: =+R26+R28 -> 72.676292 | S25: =+S26+S28 -> 75.439462 | ... X25: =+X26+X28 -> 85.677403
B26: Aeronautical, US$M | E26: 19.835 | F26: 10.201 | G26: 14.775 | H26: 18.503 | I26: 21.894 | J26: 23.055 | K26: 24.682 | L26: =+L27*L5 -> 25.619337 | M26: =+M27*M5 -> 26.59243 | N26: =+N27*N5 -> 27.602651 | O26: =+O27*O5 -> 28.651421 | P26: =+P27*P5 -> 29.740219 | Q26: =+Q27*Q5 -> 30.870578 | R26: =+R27*R5 -> 32.044092 | S26: =+S27*S5 -> 33.262416 | ... X26: =+X27*X5 -> 37.776481
B27: US$/Passenger | E27: =+E26/E5 -> 7.8692362 | F27: =+F26/F5 -> 13.190084 | G27: =+G26/G5 -> 12.156612 | H27: =+H26/H5 -> 8.4882766 | I27: =+I26/I5 -> 8.0121907 | J27: =+J26/J5 -> 8.612201 | K27: =+K26/K5 -> 9.2139922 | L27: =+K27*(1+L$33) -> 9.398272 | M27: =+L27*(1+M$33) -> 9.5862375 | N27: =+M27*(1+N$33) -> 9.7779622 | O27: =+N27*(1+O$33) -> 9.9735215 | P27: =+O27*(1+P$33) -> 10.172992 | Q27: =+P27*(1+Q$33) -> 10.376452 | R27: =+Q27*(1+R$33) -> 10.583981 | S27: =+R27*(1+S$33) -> 10.79566 | ... X27: =+W27*(1+X$33) -> 11.231805
B28: Non-Aeronautical, US$M | E28: =+E25-E26 -> 24.816 | F28: =+F25-F26 -> 8.209 | G28: =+G25-G26 -> 12.893 | H28: =+H25-H26 -> 21.391 | I28: =+I25-I26 -> 28.685 | J28: =+J25-J26 -> 30.425 | K28: =+K25-K26 -> 31.297 | L28: =+K28*L27/K27*L5/K5 -> 32.485552 | M28: =+L28*M27/L27*M5/L5 -> 33.719443 | N28: =+M28*N27/M27*N5/M5 -> 35.000412 | O28: =+N28*O27/N27*O5/N5 -> 36.330262 | P28: =+O28*P27/O27*P5/O5 -> 37.710867 | Q28: =+P28*Q27/P27*Q5/P5 -> 39.144173 | R28: =+Q28*R27/Q27*R5/Q5 -> 40.6322 | S28: =+R28*S27/R27*S5/R5 -> 42.177045 | ... X28: =+W28*X27/W27*X5/W5 -> 47.900921
B29: US$/Passenger | E29: =+E28/E8 -> 18.335311 | F29: =+F28/F8 -> 20.331536 | G29: =+G28/G8 -> 22.359729 | H29: =+H28/H8 -> 17.170079 | I29: =+I28/I8 -> 19.278875 | J29: =+J28/J8 -> 21.314919 | K29: =+K28/K8 -> 22.262198 | L29: =+K29*(1+L$33) -> 22.707442 | M29: =+L29*(1+M$33) -> 23.161591 | N29: =+M29*(1+N$33) -> 23.624823 | O29: =+N29*(1+O$33) -> 24.09732 | P29: =+O29*(1+P$33) -> 24.579266 | Q29: =+P29*(1+Q$33) -> 25.070851 | R29: =+Q29*(1+R$33) -> 25.572268 | S29: =+R29*(1+S$33) -> 26.083714 | ... X29: =+W29*(1+X$33) -> 27.137496
B31: Others, US$M | E31: =+E13-E15-E25 -> 7.16 | F31: =+F13-F15-F25 -> 8.38 | G31: =+G13-G15-G25 -> 2.666 | H31: =+H13-H15-H25 -> 7.332 | I31: =+I13-I15-I25 -> 2.021 | J31: =+J13-J15-J25 -> 4.72 | K31: =+K13-K15-K25 -> 4.164 | L31: 1 | M31: =+L31*(1+M$33) -> 1.02 | N31: =+M31*(1+N$33) -> 1.0404 | O31: =+N31*(1+O$33) -> 1.061208 | P31: =+O31*(1+P$33) -> 1.0824322 | Q31: =+P31*(1+Q$33) -> 1.1040808 | R31: =+Q31*(1+R$33) -> 1.1261624 | S31: =+R31*(1+S$33) -> 1.1486857 | T31: =+S31*(1+T$33) -> 1.1716594 | ... X31: =+W31*(1+X$33) -> 1.1950926
B33: US CPI Inflation | E33: 0.023 | F33: 0.014 | G33: 0.07 | H33: 0.065 | I33: 0.033 | J33: 0.023 | K33: 0.033 | L33: 0.02 | M33: 0.02 | N33: 0.02 | O33: 0.02 | P33: 0.02 | Q33: 0.02 | R33: 0.02 | S33: 0.02 | T33: 0.02 | U33: 0.02 | V33: 0 | W33: 0 | X33: 0
B35: EBITDA | C35: =+C11 -> 2018 | E35: =+E11 -> 2019 | F35: =+F11 -> 2020 | G35: =+G11 -> 2021 | H35: =+H11 -> 2022 | I35: =+I11 -> 2023 | J35: =+J11 -> 2024 | K35: =+K11 -> 2025 | L35: =+L11 -> 2026E | ... X35: =+X11 -> 2038E
B37: Revenues, US$M | D37: 171.7 | E37: =+E13 -> 174.155 | F37: =+F13 -> 80.653 | G37: =+G13 -> 103.831 | H37: =+H13 -> 152.4 | I37: =+I13 -> 191.7 | J37: =+J13 -> 203.7 | K37: =+K13 -> 214.272 | L37: =+L13 -> 217.93589 | ... X37: =+X13 -> 318.68145
B39: Opex, US$M | E39: =+SUM(E41:E48) -> 43.543 | F39: =+SUM(F41:F48) -> 31.322 | G39: =+SUM(G41:G48) -> 34.579 | H39: =+SUM(H41:H48) -> 35.884 | I39: =+SUM(I41:I48) -> 41.998 | J39: =+SUM(J41:J48) -> 45.515 | K39: =+SUM(K41:K48) -> 41.204 | L39: =+L40*L5 -> 42.768785 | M39: =+M40*M5 -> 44.393262 | N39: =+N40*N5 -> 46.079719 | O39: =+O40*O5 -> 47.830531 | P39: =+P40*P5 -> 49.648164 | Q39: =+Q40*Q5 -> 51.535179 | R39: =+R40*R5 -> 53.494237 | S39: =+S40*S5 -> 55.528101 | ... X39: =+X40*X5 -> 63.063858
B40: US$/Passenger | E40: =+E39/E5 -> 17.275027 | F40: =+F39/F5 -> 40.499933 | G40: =+G39/G5 -> 28.450997 | H40: =+H39/H5 -> 16.461834 | I40: =+I39/I5 -> 15.369324 | J40: =+J39/J5 -> 17.00214 | K40: =+K39/K5 -> 15.38179 | L40: =+K40*(1+L$33) -> 15.689426 | M40: =+L40*(1+M$33) -> 16.003214 | N40: =+M40*(1+N$33) -> 16.323278 | O40: =+N40*(1+O$33) -> 16.649744 | P40: =+O40*(1+P$33) -> 16.982739 | Q40: =+P40*(1+Q$33) -> 17.322394 | R40: =+Q40*(1+R$33) -> 17.668841 | S40: =+R40*(1+S$33) -> 18.022218 | ... X40: =+W40*(1+X$33) -> 18.750316
B41: Employee Benefits | E41: 10.459 | F41: 9.595 | G41: 9.407 | H41: 9.039 | I41: 10.046 | J41: 10.076 | K41: 10.255
B42: Services & Supplies | E42: 9.405 | F42: 6.305 | G42: 6.513 | H42: 8.27 | I42: 9.561 | J42: 9.479 | K42: 9.307
B43: Operations and Repairs | E43: 7.1 | F43: 2.4 | G43: 3.9 | H43: 6.2 | I43: 8.4 | J43: 8.777 | K43: 9.44
B44: Professional Fees | E44: 6.911 | F44: 5.687 | G44: 6.786 | H44: 3.186 | I44: 3.385 | J44: 3.63 | K44: 3.431
B45: Insurance Expenses | E45: 2.286 | F45: 2.396 | G45: 2.511 | H45: 2.383 | I45: 3.024 | J45: 3.238 | K45: 2.966
B46: Maintenance & Repairs | E46: 3.2 | F46: 2.4 | G46: 2.4 | H46: 2.7 | I46: 2.3 | J46: 2.66 | K46: 2.382
B47: Utilities | E47: 2.495 | F47: 1.661 | G47: 1.741 | H47: 1.936 | I47: 2.134 | J47: 2.207 | K47: 2.334
B48: Other Costs & Expenses | E48: 1.687 | F48: 0.878 | G48: 1.321 | H48: 2.17 | I48: 3.148 | J48: 5.448 | K48: 1.089
B49: Employee Profit Sharing, US$M | E49: 8.441 | F49: 0 | G49: 1.449 | H49: 6.395 | I49: 9.82 | J49: 11.22 | K49: 10.361 | L49: =+L50*Financials!I13 -> 8.5011 | M49: =+M50*Financials!J13 -> 10.783334 | N49: =+N50*Financials!K13 -> 11.361654 | O49: =+O50*Financials!L13 -> 12.2095 | P49: =+P50*Financials!M13 -> 13.007644 | Q49: =+Q50*Financials!N13 -> 13.33548 | R49: =+R50*Financials!O13 -> 14.576338 | S49: =+S50*Financials!P13 -> 15.809564 | ... X49: =+X50*Financials!U13 -> 22.266774
B50: % of Net Income (projected on t-1) | E50: =+E49/Financials!C13 -> 0.17658996 | F50: =+F49/Financials!D13 -> 0 | G50: =+G49/Financials!E13 -> 0.65863636 | H50: =+H49/Financials!F13 -> 0.17665746 | I50: =+I49/Financials!G13 -> 0.17258348 | J50: =+J49/Financials!H13 -> 0.17646781 | K50: =+K49/Financials!I13 -> 0.18281752 | L50: 0.15 | M50: 0.15 | N50: 0.15 | O50: 0.15 | P50: 0.15 | Q50: 0.15 | R50: 0.15 | S50: 0.15 | T50: 0.15 | U50: 0.15 | V50: 0.15 | W50: 0.15 | X50: 0.15
B52: EBITDA, US$M | E52: =+E37-E39-E49 -> 122.171 | F52: =+F37-F39-F49 -> 49.331 | G52: =+G37-G39-G49 -> 67.803 | H52: =+H37-H39-H49 -> 110.121 | I52: =+I37-I39-I49 -> 139.882 | J52: =+J37-J39-J49 -> 146.965 | K52: =+K37-K39-K49 -> 162.707 | L52: =+L37-L39-L49 -> 166.66601 | ... X52: =+X37-X39-X49 -> 233.35082
...

Sheet Overview
B2: Quiport Quaterlies
C4: =+Quarterlies!L12 -> 2Q24 | D4: =+Quarterlies!M12 -> 3Q24 | E4: =+Quarterlies!N12 -> 4Q24 | F4: =+Quarterlies!O12 -> 1Q25 | G4: =+Quarterlies!P12 -> 2Q25 | H4: =+Quarterlies!Q12 -> 3Q25 | I4: =+Quarterlies!R12 -> 4Q25 | J4: =+Quarterlies!S12 -> 1Q26 | K4: YOY | L4: QoQ
B5: Passengers, M | C5: =+Quarterlies!L5 -> 0.662874 | D5: =+Quarterlies!M5 -> 0.727689 | E5: =+Quarterlies!N5 -> 0.638947 | F5: =+Quarterlies!O5 -> 0.6191 | G5: =+Quarterlies!P5 -> 0.645687 | H5: =+Quarterlies!Q5 -> 0.743261 | I5: =+Quarterlies!R5 -> 0.670704 | J5: =+Quarterlies!S5 -> 0.662089 | K5: =++IFERROR(J5/F5-1,"-") -> 0.069437894 | L5: =++IFERROR(J5/I5-1,"-") -> -0.012844712
B6: International, M | C6: =+Quarterlies!L7 -> 0.306423 | D6: =+Quarterlies!M7 -> 0.347552 | E6: =+Quarterlies!N7 -> 0.28401 | F6: =+Quarterlies!O7 -> 0.2969 | G6: =+Quarterlies!P7 -> 0.299377 | H6: =+Quarterlies!Q7 -> 0.372831 | I6: =+Quarterlies!R7 -> 0.303808 | J6: =+Quarterlies!S7 -> 0.320045 | K6: =++IFERROR(J6/F6-1,"-") -> 0.077955541 | L6: =++IFERROR(J6/I6-1,"-") -> 0.053444939
B7: Domestic, M | C7: =+Quarterlies!L9 -> 0.356451 | D7: =+Quarterlies!M9 -> 0.380137 | E7: =+Quarterlies!N9 -> 0.354937 | F7: =+Quarterlies!O9 -> 0.3222 | G7: =+Quarterlies!P9 -> 0.34631 | H7: =+Quarterlies!Q9 -> 0.37043 | I7: =+Quarterlies!R9 -> 0.366896 | J7: =+Quarterlies!S9 -> 0.342044 | K7: =++IFERROR(J7/F7-1,"-") -> 0.061589075 | L7: =++IFERROR(J7/I7-1,"-") -> -0.067735816
B8: Revenues, US$M | C8: =+Quarterlies!L14 -> 50.78 | D8: =+Quarterlies!M14 -> 53.635 | E8: =+Quarterlies!N14 -> 49.221 | F8: =+Quarterlies!O14 -> 49.66 | G8: =+Quarterlies!P14 -> 51.74 | H8: =+Quarterlies!Q14 -> 58.491 | I8: =+Quarterlies!R14 -> 54.381 | J8: =+Quarterlies!S14 -> 54.87 | K8: =++IFERROR(J8/F8-1,"-") -> 0.10491341 | L8: =++IFERROR(J8/I8-1,"-") -> 0.0089921112
B9: US$/passenger | C9: =+C8/C5 -> 76.60581 | D9: =+D8/D5 -> 73.705938 | E9: =+E8/E5 -> 77.034558 | F9: =+F8/F5 -> 80.213213 | G9: =+G8/G5 -> 80.131705 | H9: =+H8/H5 -> 78.695102 | I9: =+I8/I5 -> 81.080477 | J9: =+J8/J5 -> 82.874055 | K9: =++IFERROR(J9/F9-1,"-") -> 0.033172116 | L9: =++IFERROR(J9/I9-1,"-") -> 0.022120961
B10: Regulated, US$M | C10: =+Quarterlies!L16 -> 36.151 | D10: =+Quarterlies!M16 -> 38.371 | E10: =+Quarterlies!N16 -> 34.518 | F10: =+Quarterlies!O16 -> 36.241 | G10: =+Quarterlies!P16 -> 37.432 | H10: =+Quarterlies!Q16 -> 42.291 | I10: =+Quarterlies!R16 -> 38.165 | J10: =+Quarterlies!S16 -> 39.555 | K10: =++IFERROR(J10/F10-1,"-") -> 0.091443393 | L10: =++IFERROR(J10/I10-1,"-") -> 0.036420804
B11: Non-Regulated, US$M | C11: =+Quarterlies!L26 -> 13.312 | D11: =+Quarterlies!M26 -> 13.892 | E11: =+Quarterlies!N26 -> 13.55 | F11: =+Quarterlies!O26 -> 12.771 | G11: =+Quarterlies!P26 -> 13.946 | H11: =+Quarterlies!Q26 -> 14.466 | I11: =+Quarterlies!R26 -> 14.796 | J11: =+Quarterlies!S26 -> 14.314 | K11: =++IFERROR(J11/F11-1,"-") -> 0.12082061 | L11: =++IFERROR(J11/I11-1,"-") -> -0.032576372
B12: Opex, US$M | C12: =+Quarterlies!L38 -> 10.756 | D12: =+Quarterlies!M38 -> 11.184 | E12: =+Quarterlies!N38 -> 13.361 | F12: =+Quarterlies!O38 -> 9.798 | G12: =+Quarterlies!P38 -> 9.8 | H12: =+Quarterlies!Q38 -> 10.689 | I12: =+Quarterlies!R38 -> 10.917 | J12: =+Quarterlies!S38 -> 10.53 | K12: =++IFERROR(J12/F12-1,"-") -> 0.074709124 | L12: =++IFERROR(J12/I12-1,"-") -> -0.035449299
B13: EBITDA, US$M | C13: =+Quarterlies!L51 -> 37.044 | D13: =+Quarterlies!M51 -> 39.477 | E13: =+Quarterlies!N51 -> 33.506 | F13: =+Quarterlies!O51 -> 37.273 | G13: =+Quarterlies!P51 -> 38.933 | H13: =+Quarterlies!Q51 -> 44.319 | I13: =+Quarterlies!R51 -> 42.182 | J13: =+Quarterlies!S51 -> 41.286 | K13: =++IFERROR(J13/F13-1,"-") -> 0.10766507 | L13: =++IFERROR(J13/I13-1,"-") -> -0.021241288
B14: EBITDA Mg. | C14: =+Quarterlies!L52 -> 0.7294998 | D14: =+Quarterlies!M52 -> 0.73603058 | E14: =+Quarterlies!N52 -> 0.68072571 | F14: =+Quarterlies!O52 -> 0.75056383 | G14: =+Quarterlies!P52 -> 0.75247391 | H14: =+Quarterlies!Q52 -> 0.75770631 | I14: =+Quarterlies!R52 -> 0.77567533 | J14: =+Quarterlies!S52 -> 0.75243302 | K14: =+(J14-F14)*100 -> 0.18691894 | L14: =+(J14-I14)*100 -> -2.3242304
B15: Capex, US$M | C15: =+Quarterlies!L73 -> 2.26 | D15: =+Quarterlies!M73 -> 5.559 | E15: =+Quarterlies!N73 -> 21.097 | F15: =+Quarterlies!O73 -> 10.024 | G15: =+Quarterlies!P73 -> 24.631 | H15: =+Quarterlies!Q73 -> 0.478 | I15: =+Quarterlies!R73 -> 22.935 | J15: =+Quarterlies!S73 -> 4.766 | K15: =++IFERROR(J15/F15-1,"-") -> -0.5245411 | L15: =++IFERROR(J15/I15-1,"-") -> -0.79219533
B16: Net Debt, US$M | C16: =+Quarterlies!L69 -> 323.354 | D16: =+Quarterlies!M69 -> 284.244 | E16: =+Quarterlies!N69 -> 342.525 | F16: =+Quarterlies!O69 -> 313.328 | G16: =+Quarterlies!P69 -> 326.648 | H16: =+Quarterlies!Q69 -> 309.417 | I16: =+Quarterlies!R69 -> 404.747 | J16: =+Quarterlies!S69 -> 379.798 | K16: =++IFERROR(J16/F16-1,"-") -> 0.21214191 | L16: =++IFERROR(J16/I16-1,"-") -> -0.061640976
