Workbook
Name \A: #REF!
Name \B: #REF!
Name \C: #REF!
Name \L: #REF!
Name \M: #REF!
Name \P: #REF!
Name \Y: #REF!
Name _01_30_04: MonthlyOpStats
Name _01_30_04: MonthlyOpStats
Name _1_30_01: MonthlyOpStats
Name _1_30_01: MonthlyOpStats
Name _1_30_02: MonthlyOpStats
Name _1_30_02: MonthlyOpStats
Name _1_31_01: MonthlyOpStats
Name _1_31_01: MonthlyOpStats
Name _1_31_02: MonthlyOpStats
Name _1_31_02: MonthlyOpStats
Name _12_31_05: MonthlyOpStats
Name _12_31_05: MonthlyOpStats
Name _A: #REF!
Name _A___0: #REF!
Name _B: #REF!
Name _B___0: #REF!
Name _C: #REF!
Name _C___0: #REF!
Name _ent1: [1]Inputs!$J$17
Name _ent10: [1]Inputs!$J$476
Name _ent11: [1]Inputs!$J$527
Name _ent12: [1]Inputs!$J$578
Name _ent13: [1]Inputs!$J$629
Name _ent14: [1]Inputs!$J$680
Name _ent15: [1]Inputs!$J$731
Name _ent2: [1]Inputs!$J$68
Name _ent3: [1]Inputs!$J$119
Name _ent4: [1]Inputs!$J$170
Name _ent5: [1]Inputs!$J$221
Name _ent6: [1]Inputs!$J$272
Name _ent7: [1]Inputs!$J$323
Name _ent8: [1]Inputs!$J$374
Name _ent9: [1]Inputs!$J$425
Name _eps1: [1]Inputs!$P$42
Name _eps10: [1]Inputs!$P$501
Name _eps11: [1]Inputs!$P$552
Name _eps12: [1]Inputs!$P$603
Name _eps13: [1]Inputs!$P$654
Name _eps14: [1]Inputs!$P$705
Name _eps15: [1]Inputs!$P$756
Name _eps2: [1]Inputs!$P$93
Name _eps3: [1]Inputs!$P$144
Name _eps4: [1]Inputs!$P$195
Name _eps5: [1]Inputs!$P$246
Name _eps6: [1]Inputs!$P$297
Name _eps7: [1]Inputs!$P$348
Name _eps8: [1]Inputs!$P$399
Name _eps9: [1]Inputs!$P$450
Name _fye1: [1]Inputs!$E$12
Name _fye10: [1]Inputs!$E$471
Name _fye11: [1]Inputs!$E$522
Name _fye12: [1]Inputs!$E$573
Name _fye13: [1]Inputs!$E$624

Sheet Capitalisation
A3: 2Q26 | H3: Exchange rate as at end | I3: =Model!$AL$206 -> 0
H4: LTM Average Exchange rate | I4: =Model!$AL$207 -> 0
B6: Debt Breakdown as on 30-Jun-2026 | C6: RMB mn | D6: Leverage | E6: USD mn | F6: Leverage
B7: Current | C7: =SUM(C8:C9) -> 17089 | E7: =SUM(E8:E9) -> 0
B8: Short-term debts | C8: 3534 | E8: =C8*$I3 -> 0
B9: Unsecured senior notes | C9: 13555 | E9: =C9*$I3 -> 0
B11: Non Current | C11: =SUM(C12:C13) -> 52803 | E11: =SUM(E12:E13) -> 0
B12: Long-term borrowings | C12: 36196 | E12: =C12*$I3 -> 0
B13: Unsecured senior notes | C13: 16607 | E13: =C13*$I3 -> 0
B15: Leases | C15: =SUM(C16:C17) -> 35416 | E15: =SUM(E16:E17) -> 0
B16: Current | C16: 10049 | E16: =C16*$I3 -> 0
B17: Non Current | C17: 25367 | E17: =C17*$I3 -> 0
B19: Total Loans & Borrowings | C19: =SUM(C7,C11,C15) -> 105308 | D19: =C19/C25 -> #DIV/0! | E19: =SUM(E7,E11,E15) -> 0 | F19: =E19/E25 -> #DIV/0!
B20: Cash and Cash Equivalents | C20: =Model!$AL$121 -> 0 | E20: =C20*$I3 -> 0
B21: Short term Investments | C21: =Model!$AL$122 -> 0 | E21: =C21*$I3 -> 0
B22: Net debt | C22: =C19-C20-C21 -> 105308 | D22: =C22/C25 -> #DIV/0! | E22: =E19-E20-E21 -> 0 | F22: =E22/E25 -> #DIV/0!
B23: Equity | C23: =Model!$AL$126 -> 0 | E23: =C23*$I3 -> 0
B24: Total Capitalisation | C24: =C22+C23 -> 105308 | E24: =C24*$I3 -> 0
B25: LTM Adjusted EBITDA | C25: =Model!$AL$87 -> 0 | E25: =C25*I4 -> 0
B26: check | C26: =+C19-Model!$AL$119 -> 105308
B29: Liquidity at end 2Q26 | C29: =C6 -> RMB mn | D29: USD mn
B30: Cash and Cash Equivalents | C30: =C20 -> 0 | D30: =C30*I3 -> 0
B31: Short term Investments | C31: =C21 -> 0 | D31: =C31*I3 -> 0
B32: Total liquidity | C32: =SUM(C30:C31) -> 0 | D32: =SUM(D30:D31) -> 0
B35: Debt Maturity Profile at end-2Q26 (from BBG), excluding leases | C35: =C6 -> RMB mn | D35: USD mn
B36: 2026 | C36: 2000 | D36: =C36*I3 -> 0
B37: 2028 | C37: 3600 | D37: =C37*I3 -> 0
B38: 2029 | C38: 13489.82 | D38: =C38*I3 -> 0
B39: 2030 | C39: 5121.44 | D39: =C39*I3 -> 0
B40: 2031 & beyond | C40: =C11+C7-SUM(C36:C39) -> 45680.74 | D40: =C40*I3 -> 0
B41: Total Debt | C41: =SUM(C36:C40) -> 69892 | D41: =SUM(D36:D40) -> 0
A47: 1Q26 | H47: Exchange rate as at end | I47: =Model!$K$206 -> 0
H48: LTM Average Exchange rate | I48: =Model!$K$207 -> 0
B50: Debt Breakdown as on 31-Mar-2026 | C50: RMB mn | D50: Leverage | E50: USD mn | F50: Leverage
B51: Current | C51: =SUM(C52:C53) -> 11733 | E51: =SUM(E52:E53) -> 0
B52: Short-term debts | C52: 8274 | E52: =C52*$I47 -> 0
B53: Unsecured senior notes | C53: 3459 | E53: =C53*$I47 -> 0
B55: Non Current | C55: =SUM(C56:C57) -> 62656 | E55: =SUM(E56:E57) -> 0
B56: Long-term borrowings | C56: 42162 | E56: =C56*$I47 -> 0
B57: Unsecured senior notes | C57: 20494 | E57: =C57*$I47 -> 0
...

Sheet Model
B2: JD.com, Inc. | C2: Annual | D2: Annual | E2: Annual | F2: Annual | G2: Annual | H2: Annual | I2: Annual | J2: Annual | M2: Quarters | N2: Quarters | O2: Quarters | P2: Quarters | Q2: Quarters | R2: Quarters | S2: Quarters | T2: Quarters | U2: Quarters | V2: Quarters | W2: Quarters | X2: Quarters | Y2: Quarters | Z2: Quarters | AA2: Quarters | AB2: Quarters | AC2: Quarters | AD2: Quarters | AE2: Quarters | AF2: Quarters | AG2: Quarters | AH2: Quarters | AI2: Quarters | AJ2: Quarters | AK2: Quarters
B3: (RMB million) | C3: 43465 | D3: 43830 | E3: 44196 | F3: 44561 | G3: 44926 | H3: 45291 | I3: 45657 | J3: 46022 | M3: 43921 | N3: 44012 | O3: 44104 | P3: 44196 | Q3: 44286 | R3: 44377 | S3: 44469 | T3: 44561 | U3: 44651 | V3: 44742 | W3: 44834 | X3: 44926 | Y3: 45016 | Z3: 45107 | AA3: 45199 | AB3: 45291 | AC3: 45382 | AD3: 45473 | AE3: 45565 | AF3: 45657 | AG3: 45747 | AH3: 45838 | AI3: 45930 | AJ3: 46022 | AK3: 46112
C4: Act | D4: Act | E4: Act | F4: Act | G4: Act | H4: Act | I4: Act | J4: Act | M4: Act | N4: Act | O4: Act | P4: Act | Q4: Act | R4: Act | S4: Act | T4: Act | U4: Act | V4: Act | W4: Act | X4: Act | Y4: Act | Z4: Act | AA4: Act | AB4: Act | AC4: Act | AD4: Act | AE4: Act | AF4: Act | AG4: Act | AH4: Act | AI4: Act | AJ4: Act | AK4: Act
C5: FY | D5: FY | E5: FY | F5: FY | G5: FY | H5: FY | I5: FY | J5: FY | M5: 1Q | N5: 2Q | O5: 3Q | P5: 4Q | Q5: 1Q | R5: 2Q | S5: 3Q | T5: 4Q | U5: 1Q | V5: 2Q | W5: 3Q | X5: 4Q | Y5: 1Q | Z5: 2Q | AA5: 3Q | AB5: 4Q | AC5: 1Q | AD5: 2Q | AE5: 3Q | AF5: 4Q | AG5: 1Q | AH5: 2Q | AI5: 3Q | AJ5: 4Q | AK5: 1Q
B6: INCOME STATEMENT
B7: Revenue | C7: 462019.76 | D7: 576888.48 | E7: 745801.89 | F7: 951592.15 | G7: 1046236 | H7: 1084662 | I7: 1158819 | J7: 1309085 | M7: 146205.21 | N7: 201054.06 | O7: 174214.46 | P7: =E7-SUM(M7:O7) -> 224328.16 | Q7: 203176.17 | R7: 253800.47 | S7: 218708.36 | T7: =F7-SUM(Q7:S7) -> 275907.16 | U7: 239655 | V7: 267600 | W7: 243535 | X7: =G7-SUM(U7:W7) -> 295446 | Y7: 242956 | Z7: 287931 | AA7: 247698 | AB7: =H7-SUM(Y7:AA7) -> 306077 | AC7: 260049 | AD7: 291397 | AE7: 260387 | AF7: =I7-SUM(AC7:AE7) -> 346986 | AG7: 301082 | AH7: 356660 | AI7: 299059 | AJ7: =J7-SUM(AG7:AI7) -> 352284 | AK7: 315694
B8: % of growth | D8: =(D7/C7)-1 -> 0.24862297 | E8: =(E7/D7)-1 -> 0.29280079 | F8: =(F7/E7)-1 -> 0.27593155 | G8: =(G7/F7)-1 -> 0.099458414 | H8: =(H7/G7)-1 -> 0.036727851 | I8: =(I7/H7)-1 -> 0.068368764 | J8: =(J7/I7)-1 -> 0.12967167 | Q8: =(Q7/M7)-1 -> 0.38966437 | R8: =(R7/N7)-1 -> 0.2623494 | S8: =(S7/O7)-1 -> 0.25539724 | T8: =(T7/P7)-1 -> 0.22992656 | U8: =(U7/Q7)-1 -> 0.17954286 | V8: =(V7/R7)-1 -> 0.05437157 | W8: =(W7/S7)-1 -> 0.11351483 | X8: =(X7/T7)-1 -> 0.070816731 | ... AK8: =(AK7/AG7)-1 -> 0.048531629
B9: Cost of revenues | C9: -396066.13 | D9: -492467.39 | E9: -636693.55 | F9: -822525.46 | G9: -899163 | H9: -924958 | I9: -974951 | J9: -1099057 | M9: -123669.7 | N9: -172418.57 | O9: -147419.45 | P9: =E9-SUM(M9:O9) -> -193185.83 | Q9: -174054.15 | R9: -222070.88 | S9: -187615.62 | T9: =F9-SUM(Q9:S9) -> -238784.82 | U9: -206209 | V9: -231706 | W9: -207339 | X9: =G9-SUM(U9:W9) -> -253909 | Y9: -206938 | Z9: -246498 | AA9: -208947 | AB9: =H9-SUM(Y9:AA9) -> -262575 | AC9: -220279 | AD9: -245459 | AE9: -215344 | AF9: =I9-SUM(AC9:AE9) -> -293869 | AG9: -253234 | AH9: -300020 | AI9: -248585 | AJ9: =J9-SUM(AG9:AI9) -> -297218 | AK9: -262667
B10: Gross Profit | C10: =C7+C9 -> 65953.633 | D10: =D7+D9 -> 84421.093 | E10: =E7+E9 -> 109108.34 | F10: =F7+F9 -> 129066.69 | G10: =G7+G9 -> 147073 | H10: =H7+H9 -> 159704 | I10: =I7+I9 -> 183868 | J10: =J7+J9 -> 210028 | M10: =M7+M9 -> 22535.51 | N10: =N7+N9 -> 28635.487 | O10: =O7+O9 -> 26795.018 | P10: =P7+P9 -> 31142.32 | Q10: =Q7+Q9 -> 29122.019 | R10: =R7+R9 -> 31729.594 | S10: =S7+S9 -> 31092.737 | T10: =T7+T9 -> 37122.342 | ... AK10: =AK7+AK9 -> 53027
B11: Gross Profit margin | C11: =C10/C7 -> 0.14275068 | D11: =D10/D7 -> 0.14633867 | E11: =E10/E7 -> 0.14629667 | F11: =F10/F7 -> 0.13563236 | G11: =G10/G7 -> 0.14057345 | H11: =H10/H7 -> 0.14723849 | I11: =I10/I7 -> 0.15866844 | J11: =J10/J7 -> 0.16043878 | M11: =M10/M7 -> 0.15413616 | N11: =N10/N7 -> 0.1424268 | O11: =O10/O7 -> 0.15380478 | P11: =P10/P7 -> 0.13882484 | Q11: =Q10/Q7 -> 0.14333383 | R11: =R10/R7 -> 0.12501787 | S11: =S10/S7 -> 0.14216529 | T11: =T10/T7 -> 0.1345465 | ... AK11: =AK10/AK7 -> 0.16796962
B12: Operating expenses:
B13: Fulfillment | C13: -32009.658 | D13: -36968.041 | E13: -48700.211 | F13: -59055.207 | G13: -63011 | H13: -64558 | I13: -70426 | J13: -88176 | M13: -10399.79 | N13: -11956.352 | O13: -11592.062 | P13: =E13-SUM(M13:O13) -> -14752.007 | Q13: -13803.401 | R13: -14649.314 | S13: -14275.651 | T13: =F13-SUM(Q13:S13) -> -16326.841 | U13: -15486 | V13: -16308 | W13: -14354 | X13: =G13-SUM(U13:W13) -> -16863 | Y13: -15371 | Z13: -16679 | AA13: -15225 | AB13: =H13-SUM(Y13:AA13) -> -17283 | AC13: -16806 | AD13: -17221 | AE13: -16278 | AF13: =I13-SUM(AC13:AE13) -> -20121 | AG13: -19737 | AH13: -22145 | AI13: -22002 | AJ13: =J13-SUM(AG13:AI13) -> -24292 | AK13: -23393
B14: Marketing | C14: -19236.74 | D14: -22234.045 | E14: -27155.972 | F14: -38743.04 | G14: -37772 | H14: -40133 | I14: -47953 | J14: -83953 | M14: -4468.316 | N14: -6803.919 | O14: -5460.508 | P14: =E14-SUM(M14:O14) -> -10423.229 | Q14: -6998.757 | R14: -10612.42 | S14: -7769.166 | T14: =F14-SUM(Q14:S14) -> -13362.697 | U14: -8705 | V14: -9477 | W14: -7605 | X14: =G14-SUM(U14:W14) -> -11985 | Y14: -8005 | Z14: -11063 | AA14: -7955 | AB14: =H14-SUM(Y14:AA14) -> -13110 | AC14: -9254 | AD14: -11867 | AE14: -10000 | AF14: =I14-SUM(AC14:AE14) -> -16832 | AG14: -10543 | AH14: -27013 | AI14: -21050 | AJ14: =J14-SUM(AG14:AI14) -> -25347 | AK14: -15372
B15: Research and development | C15: -12144.383 | D15: -14618.677 | E15: -16148.948 | F15: -16332.036 | G15: -16893 | H15: -16393 | I15: -17031 | J15: -22229 | M15: -3935.159 | N15: -3603.6 | O15: -4106.739 | P15: =E15-SUM(M15:O15) -> -4503.45 | Q15: -4529.506 | R15: -3693.41 | S15: -4004.001 | T15: =F15-SUM(Q15:S15) -> -4105.119 | U15: -4384 | V15: -4027 | W15: -4116 | X15: =G15-SUM(U15:W15) -> -4366 | Y15: -4186 | Z15: -4072 | AA15: -3794 | AB15: =H15-SUM(Y15:AA15) -> -4341 | AC15: -4034 | AD15: -4217 | AE15: -4396 | AF15: =I15-SUM(AC15:AE15) -> -4384 | AG15: -4621 | AH15: -5299 | AI15: -5646 | AJ15: =J15-SUM(AG15:AI15) -> -6663 | AK15: -6866
B16: General and administrative | C16: =-5159.666-22.317 -> -5181.983 | D16: -5490.159 | E16: -6409.131 | F16: -11562.451 | G16: -11053 | H16: -9710 | I16: -8888 | J16: -11980 | M16: -1411.796 | N16: -1423.127 | O16: -1596.342 | P16: =E16-SUM(M16:O16) -> -1977.866 | Q16: -2213.373 | R16: -2561.031 | S16: -3050.183 | T16: =F16-SUM(Q16:S16) -> -3737.864 | U16: -2462 | V16: -2324 | W16: -2622 | X16: =G16-SUM(U16:W16) -> -3645 | Y16: -2501 | Z16: -2358 | AA16: -2474 | AB16: =H16-SUM(Y16:AA16) -> -2377 | AC16: -1976 | AD16: -2132 | AE16: -2325 | AF16: =I16-SUM(AC16:AE16) -> -2455 | AG16: -2414 | AH16: -3266 | AI16: -2990 | AJ16: =J16-SUM(AG16:AI16) -> -3310 | AK16: -3589
B17: Gain on sale of development properties | C17: 0 | D17: 3884.709 | E17: 1648.747 | F17: 766.992 | G17: 1379 | H17: 2283 | I17: 1527 | J17: 387 | M17: 0 | N17: 195.586 | O17: 343.982 | P17: =E17-SUM(M17:O17) -> 1109.179 | Q17: 82.762 | R17: 87.337 | S17: 578.701 | T17: =F17-SUM(Q17:S17) -> 18.192 | U17: 0 | V17: 0 | W17: 1229 | X17: =G17-SUM(U17:W17) -> 150 | Y17: 472 | Z17: 1009 | AA17: 0 | AB17: =H17-SUM(Y17:AA17) -> 802 | AC17: 0 | AD17: 0 | AE17: 0 | AF17: =I17-SUM(AC17:AE17) -> 1527 | AG17: 0 | AH17: 224 | AI17: 163 | AJ17: =J17-SUM(AG17:AI17) -> 0 | AK17: 0
B18: Impairment of goodwill and impairment of long-lived assets | H18: =-3143-2025 -> -5168 | I18: =-799-1562 -> -2361 | J18: =-1303 -> -1303 | T18: =F18-SUM(Q18:S18) -> 0 | X18: =G18-SUM(U18:W18) -> 0 | AB18: =H18-SUM(Y18:AA18) -> -5168 | AC18: 0 | AD18: 0 | AE18: 0 | AF18: =I18-SUM(AC18:AE18) -> -2361 | AG18: 0 | AH18: 0 | AI18: 0 | AJ18: =J18-SUM(AG18:AI18) -> -1303 | AK18: 0
B19: Operating profit | C19: =C10+SUM(C13:C18) -> -2619.131 | D19: =D10+SUM(D13:D18) -> 8994.88 | E19: =E10+SUM(E13:E18) -> 12342.82 | F19: =F10+SUM(F13:F18) -> 4140.95 | G19: =G10+SUM(G13:G18) -> 19723 | H19: =H10+SUM(H13:H18) -> 26025 | I19: =I10+SUM(I13:I18) -> 38736 | J19: =J10+SUM(J13:J18) -> 2774 | M19: =M10+SUM(M13:M17) -> 2320.449 | N19: =N10+SUM(N13:N17) -> 5044.075 | O19: =O10+SUM(O13:O17) -> 4383.349 | P19: =P10+SUM(P13:P17) -> 594.947 | Q19: =Q10+SUM(Q13:Q18) -> 1659.744 | R19: =R10+SUM(R13:R18) -> 300.756 | S19: =S10+SUM(S13:S18) -> 2572.437 | T19: =T10+SUM(T13:T18) -> -391.987 | U19: =U10+SUM(U13:U18) -> 2409 | V19: =V10+SUM(V13:V18) -> 3758 | W19: =W10+SUM(W13:W18) -> 8728 | X19: =X10+SUM(X13:X18) -> 4828 | ... AK19: =AK10+SUM(AK13:AK18) -> 3807
B20: Share of results of equity investees | C20: -1113.105 | D20: -1738.219 | E20: 4291.453 | F20: -4918.023 | G20: -2195 | H20: 1010 | I20: 2327 | J20: 8025 | M20: -1120.22 | N20: 4004.164 | O20: -272.313 | P20: =E20-SUM(M20:O20) -> 1679.822 | Q20: 682.329 | R20: 522.781 | S20: -1850.787 | T20: =F20-SUM(Q20:S20) -> -4272.346 | U20: -1081 | V20: -1604 | W20: 377 | X20: =G20-SUM(U20:W20) -> 113 | Y20: -821 | Z20: 907 | AA20: 427 | AB20: =H20-SUM(Y20:AA20) -> 497 | AC20: -730 | AD20: 1142 | AE20: 1359 | AF20: =I20-SUM(AC20:AE20) -> 556 | AG20: 1330 | AH20: 2072 | AI20: 2740 | AJ20: =J20-SUM(AG20:AI20) -> 1883 | AK20: 1636
B21: Interest expense | C21: -854.538 | D21: -725.01 | E21: -1125.181 | F21: -1213.455 | G21: -2106 | H21: -2881 | I21: -2896 | J21: -2803 | M21: -207.1 | N21: -324.218 | O21: -297.802 | P21: =E21-SUM(M21:O21) -> -296.061 | Q21: -257.821 | R21: -232.325 | S21: -276.139 | T21: =F21-SUM(Q21:S21) -> -447.17 | U21: -345 | V21: -484 | W21: -579 | X21: =G21-SUM(U21:W21) -> -698 | Y21: -590 | Z21: -654 | AA21: -710 | AB21: =H21-SUM(Y21:AA21) -> -927 | AC21: -601 | AD21: -688 | AE21: -681 | AF21: =I21-SUM(AC21:AE21) -> -926 | AG21: -600 | AH21: -643 | AI21: -730 | AJ21: =J21-SUM(AG21:AI21) -> -830 | AK21: -686
B22: Finance income | C22: 2117.921 | D22: 1785.572 | E22: 2753.36 | F22: 0 | G22: 0 | H22: 0 | I22: 0 | J22: 0 | M22: 0 | N22: 0 | O22: 0 | P22: =E22-SUM(M22:O22) -> 2753.36 | Q22: 0 | R22: 0 | S22: 0 | T22: =F22-SUM(Q22:S22) -> 0 | U22: 0 | V22: 0 | W22: 0 | X22: =G22-SUM(U22:W22) -> 0 | Y22: 0 | Z22: 0 | AA22: 0 | AB22: =H22-SUM(Y22:AA22) -> 0 | AC22: 0 | AD22: 0 | AE22: 0 | AF22: =I22-SUM(AC22:AE22) -> 0 | AG22: 0 | AH22: 0 | AI22: 0 | AJ22: =J22-SUM(AG22:AI22) -> 0 | AK22: 0
B23: Others, net | C23: 95.175 | D23: 5375.309 | E23: 32556.439 | F23: -590.222 | G23: -1555 | H23: =7496 -> 7496 | I23: 13371 | J23: 17327 | M23: 390.498 | N23: 8485.552 | O23: 4462.624 | P23: =E23-SUM(M23:O23) -> 19217.765 | Q23: 2037.735 | R23: 455.936 | S23: -3061.899 | T23: =F23-SUM(Q23:S23) -> -21.994 | U23: -3898 | V23: 3586 | W23: -816 | X23: =G23-SUM(U23:W23) -> -427 | Y23: 2792 | Z23: 1211 | AA23: 1782 | AB23: =H23-SUM(Y23:AA23) -> 1711 | AC23: 2696 | AD23: 4661 | AE23: 2521 | AF23: =I23-SUM(AC23:AE23) -> 3493 | AG23: 2079 | AH23: 6129 | AI23: 5674 | AJ23: =J23-SUM(AG23:AI23) -> 3445 | AK23: 2333
B24: Profit before tax | C24: =C19+SUM(C20:C23) -> -2373.678 | D24: =D19+SUM(D20:D23) -> 13692.532 | E24: =E19+SUM(E20:E23) -> 50818.891 | F24: =F19+SUM(F20:F23) -> -2580.75 | G24: =G19+SUM(G20:G23) -> 13867 | H24: =H19+SUM(H20:H23) -> 31650 | I24: =I19+SUM(I20:I23) -> 51538 | J24: =J19+SUM(J20:J23) -> 25323 | M24: =M19+SUM(M20:M23) -> 1383.627 | N24: =N19+SUM(N20:N23) -> 17209.573 | O24: =O19+SUM(O20:O23) -> 8275.858 | P24: =P19+SUM(P20:P23) -> 23949.833 | Q24: =Q19+SUM(Q20:Q23) -> 4121.987 | R24: =R19+SUM(R20:R23) -> 1047.148 | S24: =S19+SUM(S20:S23) -> -2616.388 | T24: =T19+SUM(T20:T23) -> -5133.497 | ... AK24: =AK19+SUM(AK20:AK23) -> 7090
B25: Income tax expenses | C25: -426.872 | D25: -1802.44 | E25: -1481.645 | F25: -1886.535 | G25: -4176 | H25: -8393 | I25: -6878 | J25: -2181 | M25: -326.444 | N25: -796.55 | O25: -690.373 | P25: =E25-SUM(M25:O25) -> 331.722 | Q25: -479.489 | R25: -569.624 | S25: -652.199 | T25: =F25-SUM(Q25:S25) -> -185.223 | U25: -603 | V25: -1227 | W25: -1751 | X25: =G25-SUM(U25:W25) -> -595 | Y25: -1609 | Z25: -2811 | AA25: -2579 | AB25: =H25-SUM(Y25:AA25) -> -1394 | AC25: -1700 | AD25: -2022 | AE25: -2406 | AF25: =I25-SUM(AC25:AE25) -> -750 | AG25: -2063 | AH25: 10 | AI25: -252 | AJ25: =J25-SUM(AG25:AI25) -> 124 | AK25: -1260
B26: Net profit/loss | C26: =+C24+C25 -> -2800.55 | D26: =+D24+D25 -> 11890.092 | E26: =+E24+E25 -> 49337.246 | F26: =+F24+F25 -> -4467.285 | G26: =+G24+G25 -> 9691 | H26: =+H24+H25 -> 23257 | I26: =+I24+I25 -> 44660 | J26: =+J24+J25 -> 23142 | M26: =+M24+M25 -> 1057.183 | N26: =+N24+N25 -> 16413.023 | O26: =+O24+O25 -> 7585.485 | P26: =+P24+P25 -> 24281.555 | Q26: =+Q24+Q25 -> 3642.498 | R26: =+R24+R25 -> 477.524 | S26: =+S24+S25 -> -3268.587 | T26: =+T24+T25 -> -5318.72 | ... AK26: =+AK24+AK25 -> 5830
B27: % margin | C27: =+C26/C7 -> -0.0060615373 | D27: =+D26/D7 -> 0.020610729 | E27: =+E26/E7 -> 0.066153287 | F27: =+F26/F7 -> -0.0046945374 | G27: =+G26/G7 -> 0.0092627285 | H27: =+H26/H7 -> 0.021441703 | I27: =+I26/I7 -> 0.038539237 | J27: =+J26/J7 -> 0.017677996 | M27: =+M26/M7 -> 0.0072308162 | N27: =+N26/N7 -> 0.081634876 | O27: =+O26/O7 -> 0.043541075 | P27: =+P26/P7 -> 0.10824123 | Q27: =+Q26/Q7 -> 0.017927782 | R27: =+R26/R7 -> 0.0018814938 | S27: =+S26/S7 -> -0.014944957 | T27: =+T26/T7 -> -0.019277209 | ... AK27: =+AK26/AK7 -> 0.01846725
B28: Non-controlling interest | C28: =311.409-2.492 -> 308.917 | D28: =297.163-3.1 -> 294.063 | E28: =74.618-6.641 -> 67.977 | F28: =923.696-15.965 -> 907.731 | G28: =697-8 -> 689 | H28: 910 | I28: -3301 | J28: 3511 | M28: =16.42-0.782 -> 15.638 | N28: =34.384-0.794 -> 33.59 | O28: =-23.127-2.02 -> -25.147 | P28: =E28-SUM(M28:O28) -> 43.896 | Q28: =-22.248-2.965 -> -25.213 | R28: =320.368-3.625 -> 316.743 | S28: =466.736-4.687 -> 462.049 | T28: =F28-SUM(Q28:S28) -> 154.152 | U28: =532-5 -> 527 | V28: =350-3 -> 347 | W28: 4 | X28: =G28-SUM(U28:W28) -> -189 | Y28: 62 | Z28: -342 | AA28: -287 | AB28: =H28-SUM(Y28:AA28) -> 1477 | AC28: -235 | AD28: -950 | AE28: -1106 | AF28: =I28-SUM(AC28:AE28) -> -1010 | AG28: -389 | AH28: -531 | AI28: -1105 | AJ28: =J28-SUM(AG28:AI28) -> 5536 | AK28: -728
B29: Net profit/loss | C29: =+C26+C28 -> -2491.633 | D29: =+D26+D28 -> 12184.155 | E29: =+E26+E28 -> 49405.223 | F29: =+F26+F28 -> -3559.554 | G29: =+G26+G28 -> 10380 | H29: =+H26+H28 -> 24167 | I29: =+I26+I28 -> 41359 | J29: =+J26+J28 -> 26653 | M29: =+M26+M28 -> 1072.821 | N29: =+N26+N28 -> 16446.613 | O29: =+O26+O28 -> 7560.338 | P29: =+P26+P28 -> 24325.451 | Q29: =+Q26+Q28 -> 3617.285 | R29: =+R26+R28 -> 794.267 | S29: =+S26+S28 -> -2806.538 | T29: =+T26+T28 -> -5164.568 | ... AK29: =+AK26+AK28 -> 5102
B31: As % of sales unless stated otherwise
B32: =B13 -> Fulfillment | C32: =-C13/C7 -> 0.069282011 | D32: =-D13/D7 -> 0.06408178 | E32: =-E13/E7 -> 0.065299126 | F32: =-F13/F7 -> 0.062059367 | G32: =-G13/G7 -> 0.060226373 | H32: =-H13/H7 -> 0.059519002 | I32: =-I13/I7 -> 0.060773943 | J32: =-J13/J7 -> 0.067356971 | M32: =-M13/M7 -> 0.07113146 | N32: =-N13/N7 -> 0.059468345 | O32: =-O13/O7 -> 0.066539033 | P32: =-P13/P7 -> 0.065760836 | Q32: =-Q13/Q7 -> 0.067938091 | R32: =-R13/R7 -> 0.057719806 | S32: =-S13/S7 -> 0.065272544 | T32: =-T13/T7 -> 0.059175127 | ... AK32: =-AK13/AK7 -> 0.074100236
B33: =B14 -> Marketing | C33: =-C14/C7 -> 0.041636185 | D33: =-D14/D7 -> 0.038541322 | E33: =-E14/E7 -> 0.036411777 | F33: =-F14/F7 -> 0.040713913 | G33: =-G14/G7 -> 0.036102753 | H33: =-H14/H7 -> 0.037000467 | I33: =-I14/I7 -> 0.041380923 | J33: =-J14/J7 -> 0.064131053 | M33: =-M14/M7 -> 0.030561948 | N33: =-N14/N7 -> 0.033841242 | O33: =-O14/O7 -> 0.031343597 | P33: =-P14/P7 -> 0.046464203 | Q33: =-Q14/Q7 -> 0.034446742 | R33: =-R14/R7 -> 0.041814028 | S33: =-S14/S7 -> 0.03552295 | T33: =-T14/T7 -> 0.048431861 | ... AK33: =-AK14/AK7 -> 0.048692721
B34: =B15 -> Research and development | C34: =-C15/C7 -> 0.026285419 | D34: =-D15/D7 -> 0.02534056 | E34: =-E15/E7 -> 0.021653134 | F34: =-F15/F7 -> 0.017162853 | G34: =-G15/G7 -> 0.016146453 | H34: =-H15/H7 -> 0.015113464 | I34: =-I15/I7 -> 0.014696859 | J34: =-J15/J7 -> 0.016980563 | M34: =-M15/M7 -> 0.026915313 | N34: =-N15/N7 -> 0.017923538 | O34: =-O15/O7 -> 0.023572893 | P34: =-P15/P7 -> 0.020075278 | Q34: =-Q15/Q7 -> 0.022293491 | R34: =-R15/R7 -> 0.014552416 | S34: =-S15/S7 -> 0.01830749 | T34: =-T15/T7 -> 0.014878625 | ... AK34: =-AK15/AK7 -> 0.021748909
B35: =B16 -> General and administrative | C35: =-C16/C7 -> 0.011215934 | D35: =-D16/D7 -> 0.0095168462 | E35: =-E16/E7 -> 0.0085936106 | F35: =-F16/F7 -> 0.012150637 | G35: =-G16/G7 -> 0.010564538 | H35: =-H16/H7 -> 0.0089520975 | I35: =-I16/I7 -> 0.0076698777 | J35: =-J16/J7 -> 0.0091514302 | M35: =-M16/M7 -> 0.0096562633 | N35: =-N16/N7 -> 0.0070783301 | O35: =-O16/O7 -> 0.0091630853 | P35: =-P16/P7 -> 0.0088168425 | Q35: =-Q16/Q7 -> 0.010893861 | R35: =-R16/R7 -> 0.010090726 | S35: =-S16/S7 -> 0.013946349 | T35: =-T16/T7 -> 0.013547543 | ... AK35: =-AK16/AK7 -> 0.011368604
B36: =B17 -> Gain on sale of development properties | C36: =-C17/C7 -> 0 | D36: =-D17/D7 -> -0.0067338994 | E36: =-E17/E7 -> -0.0022107037 | F36: =-F17/F7 -> -0.00080600917 | G36: =-G17/G7 -> -0.0013180583 | H36: =-H17/H7 -> -0.0021048032 | I36: =-I17/I7 -> -0.0013177209 | J36: =-J17/J7 -> -0.00029562633 | M36: =-M17/M7 -> 0 | N36: =-N17/N7 -> -0.00097280305 | O36: =-O17/O7 -> -0.0019744744 | P36: =-P17/P7 -> -0.0049444485 | Q36: =-Q17/Q7 -> -0.00040734108 | R36: =-R17/R7 -> -0.00034411678 | S36: =-S17/S7 -> -0.002645994 | T36: =-T17/T7 -> -6.5935223e-05 | ... AG36: =-AG17/AG7 -> 0 | AH36: =-AH16/AH7 -> 0.0091571805 | AI36: =-AI17/AI7 -> -0.00054504295 | AJ36: =-AJ17/AJ7 -> 0 | AK36: =-AK17/AK7 -> 0
B37: =B20 -> Share of results of equity investees | C37: =-C20/C7 -> 0.0024092151 | D37: =-D20/D7 -> 0.0030130936 | E37: =-E20/E7 -> -0.0057541461 | F37: =-F20/F7 -> 0.0051682047 | G37: =-G20/G7 -> 0.002097997 | H37: =-H20/H7 -> -0.00093116565 | I37: =-I20/I7 -> -0.0020080789 | J37: =-J20/J7 -> -0.006130236 | M37: =-M20/M7 -> 0.0076619705 | N37: =-N20/N7 -> -0.019915858 | O37: =-O20/O7 -> 0.0015630907 | P37: =-P20/P7 -> -0.0074882353 | Q37: =-Q20/Q7 -> -0.0033583122 | R37: =-R20/R7 -> -0.002059811 | S37: =-S20/S7 -> 0.0084623515 | T37: =-T20/T7 -> 0.015484723 | ... AK37: =-AK20/AK7 -> -0.0051822334
B38: Interest expense as % of debt | C38: =-C21/C119 -> 0.085267516 | D38: =-D21/D119 -> 0.038629238 | E38: =-E21/E119 -> 0.035658751 | F38: =-F21/F119 -> 0.035544257 | G38: =-G21/G119 -> 0.032377585 | H38: =-H21/H119 -> 0.042100802 | I38: =-I21/I119 -> 0.032260939 | J38: =-J21/J119 -> 0.02617058 | P38: =-SUM(M21:P21)/P119 -> 0.035658751 | Q38: =-SUM(N21:Q21)/Q119 -> 0.035797466 | R38: =-SUM(O21:R21)/R119 -> 0.035533356 | S38: =-SUM(P21:S21)/S119 -> 0.028248142 | T38: =-SUM(Q21:T21)/T119 -> 0.035544257 | U38: =-SUM(R21:U21)/U119 -> 0.024469625 | V38: =-SUM(S21:V21)/V119 -> 0.026274695 | W38: =-SUM(T21:W21)/W119 -> 0.026874837 | ... AK38: =-SUM(AH21:AK21)/AK119 -> 0.026745047
B39: Finance income as % of cash and cash equivalents | C39: =-C22/C120 -> -0.058348114 | D39: =-D22/D120 -> -0.028998705 | E39: =-E22/E120 -> -0.018773511 | F39: =-F22/F120 -> 0 | G39: =-G22/G120 -> 0 | H39: =-H22/H120 -> 0 | I39: =-I22/I120 -> 0 | J39: =-J22/J120 -> 0 | P39: =-SUM(M22:P22)/P120 -> -0.013285911 | Q39: =-SUM(N22:Q22)/Q120 -> -0.020413607 | R39: =-SUM(O22:R22)/R120 -> -0.015933832 | S39: =-SUM(P22:S22)/S120 -> -0.014465135 | T39: =-SUM(Q22:T22)/T120 -> 0 | U39: =-SUM(R22:U22)/U120 -> 0 | V39: =-SUM(S22:V22)/V120 -> 0 | W39: =-SUM(T22:W22)/W120 -> 0 | ... AK39: =-SUM(AH22:AK22)/AK120 -> 0
B40: =B23 -> Others, net | C40: =-C23/C7 -> -0.00020599768 | D40: =-D23/D7 -> -0.009317761 | E40: =-E23/E7 -> -0.043652932 | F40: =-F23/F7 -> 0.00062024681 | G40: =-G23/G7 -> 0.0014862803 | H40: =-H23/H7 -> -0.0069109087 | I40: =-I23/I7 -> -0.011538471 | J40: =-J23/J7 -> -0.013235963 | M40: =-M23/M7 -> -0.0026708898 | N40: =-N23/N7 -> -0.042205326 | O40: =-O23/O7 -> -0.025615692 | P40: =-P23/P7 -> -0.085668092 | Q40: =-Q23/Q7 -> -0.0100294 | R40: =-R23/R7 -> -0.0017964348 | S40: =-S23/S7 -> 0.013999918 | T40: =-T23/T7 -> 7.9715221e-05 | ... AK40: =-AK23/AK7 -> -0.0073900676
B41: Tax % of PBT | C41: =-C25/C24 -> -0.17983568 | D41: =-D25/D24 -> 0.13163672 | E41: =-E25/E24 -> 0.029155398 | F41: =-F25/F24 -> -0.73100262 | G41: =-G25/G24 -> 0.30114661 | H41: =-H25/H24 -> 0.26518167 | I41: =-I25/I24 -> 0.13345493 | J41: =-J25/J24 -> 0.086127236 | M41: =-M25/M24 -> 0.23593353 | N41: =-N25/N24 -> 0.046285286 | O41: =-O25/O24 -> 0.083420112 | P41: =-P25/P24 -> -0.013850702 | Q41: =-Q25/Q24 -> 0.11632472 | R41: =-R25/R24 -> 0.54397659 | S41: =-S25/S24 -> -0.24927457 | T41: =-T25/T24 -> -0.036081252 | ... AK41: =-AK25/AK24 -> 0.17771509
B44: EBITDA | C44: =C3 -> 43465 | D44: =D3 -> 43830 | E44: =E3 -> 44196 | F44: =F3 -> 44561 | G44: =G3 -> 44926 | H44: =H3 -> 45291 | I44: =I3 -> 45657 | J44: =J3 -> 46022 | M44: =M3 -> 43921 | N44: =N3 -> 44012 | O44: =O3 -> 44104 | P44: =P3 -> 44196 | Q44: =Q3 -> 44286 | R44: =R3 -> 44377 | S44: =S3 -> 44469 | T44: =T3 -> 44561 | ... AK44: =AK3 -> 46112
...

Sheet KPIs
B2: JD.com, Inc. | C2: Annual | D2: Annual | E2: Annual | F2: Annual | G2: Annual | H2: Annual | I2: Annual | J2: Annual | M2: Quarters | N2: Quarters | O2: Quarters | P2: Quarters | Q2: Quarters | R2: Quarters | S2: Quarters | T2: Quarters | U2: Quarters | V2: Quarters | W2: Quarters | X2: Quarters | Y2: Quarters | Z2: Quarters | AA2: Quarters | AB2: Quarters | AC2: Quarters | AD2: Quarters | AE2: Quarters | AF2: Quarters | AG2: Quarters | AH2: Quarters | AI2: Quarters | AJ2: Quarters | AK2: Quarters
B3: (RMB million) | C3: 43465 | D3: 43830 | E3: 44196 | F3: 44561 | G3: 44926 | H3: 45291 | I3: 45657 | J3: 46022 | M3: 43921 | N3: 44012 | O3: 44104 | P3: 44196 | Q3: 44286 | R3: 44377 | S3: 44469 | T3: 44561 | U3: 44651 | V3: 44742 | W3: 44834 | X3: 44926 | Y3: 45016 | Z3: 45107 | AA3: 45199 | AB3: 45291 | AC3: 45382 | AD3: 45473 | AE3: 45565 | AF3: 45657 | AG3: 45747 | AH3: 45838 | AI3: 45930 | AJ3: 46022 | AK3: 46112
C4: Act | D4: Act | E4: Act | F4: Act | G4: Act | H4: Act | I4: Act | J4: Act | M4: Act | N4: Act | O4: Act | P4: Act | Q4: Act | R4: Act | S4: Act | T4: Act | U4: Act | V4: Act | W4: Act | X4: Act | Y4: Act | Z4: Act | AA4: Act | AB4: Act | AC4: Act | AD4: Act | AE4: Act | AF4: Act | AG4: Act | AH4: Act | AI4: Act | AJ4: Act | AK4: Act
C5: FY | D5: FY | E5: FY | F5: FY | G5: FY | H5: FY | I5: FY | J5: FY | M5: 1Q | N5: 2Q | O5: 3Q | P5: 4Q | Q5: 1Q | R5: 2Q | S5: 3Q | T5: 4Q | U5: 1Q | V5: 2Q | W5: 3Q | X5: 4Q | Y5: 1Q | Z5: 2Q | AA5: 3Q | AB5: 4Q | AC5: 1Q | AD5: 2Q | AE5: 3Q | AF5: 4Q | AG5: 1Q | AH5: 2Q | AI5: 3Q | AJ5: 4Q | AK5: 1Q
B7: Net revenues
B8: JD Retail | C8: 447502.17 | D8: 552245.14 | E8: 702929.62 | F8: 866302.54 | G8: 929929 | H8: 945343 | I8: 1015948 | J8: 1126399 | M8: 137356.07 | N8: 189482.78 | O8: 161081.24 | P8: =E8-SUM(M8:O8) -> 215009.52 | Q8: 185796.24 | R8: 232556.81 | S8: 198080.24 | T8: =F8-SUM(Q8:S8) -> 249869.24 | U8: 217524 | V8: 241557 | W8: 211923 | X8: =G8-SUM(U8:W8) -> 258925 | Y8: 212358 | Z8: 253280 | AA8: 212059 | AB8: =H8-SUM(Y8:AA8) -> 267646 | AC8: 226835 | AD8: 257072 | AE8: 224986 | AF8: =I8-SUM(AC8:AE8) -> 307055 | AG8: 263845 | AH8: 310075 | AI8: 250577 | AJ8: =J8-SUM(AG8:AI8) -> 301902 | AK8: 268588
B9: JD Logistics | F9: 104693.4 | G9: 137402 | H9: 166625 | I9: 182837 | J9: 217146 | M9: 13656.913 | N9: 17885.953 | O9: 17964.35 | P9: =E9-SUM(M9:O9) -> -49507.216 | Q9: 22411.019 | R9: 26061.431 | S9: 25749.276 | T9: =F9-SUM(Q9:S9) -> 30471.676 | U9: 27351 | V9: 31272 | W9: 35771 | X9: =G9-SUM(U9:W9) -> 43008 | Y9: 36728 | Z9: 41033 | AA9: 41663 | AB9: =H9-SUM(Y9:AA9) -> 47201 | AC9: 42137 | AD9: 44207 | AE9: 44396 | AF9: =I9-SUM(AC9:AE9) -> 52097 | AG9: 46967 | AH9: 51564 | AI9: 55084 | AJ9: =J9-SUM(AG9:AI9) -> 63531 | AK9: 60581
B10: Dada | G10: 8030 | U10: 688 | V10: 2281 | W10: 2380 | X10: =G10-SUM(U10:W10) -> 2681 | Y10: 2576 | Z10: 2811 | AA10: 2867 | AB10: =H10-SUM(Y10:AA10) -> -8254
B11: New businesses | C11: 14665.281 | D11: 23932.278 | E11: 42790.954 | F11: 26063.231 | G11: 21779 | H11: 26617 | I11: 19157 | J11: 49282 | M11: 3309.375 | N11: 4345.183 | O11: 4302.067 | P11: =E11-SUM(M11:O11) -> 30834.329 | Q11: 5154.277 | R11: 6963.307 | S11: 5732.81 | T11: =F11-SUM(Q11:S11) -> 8212.837 | U11: 5756 | V11: 6265 | W11: 4997 | X11: =G11-SUM(U11:W11) -> 4761 | Y11: 3450 | Z11: 4316 | AA11: 3818 | AB11: =H11-SUM(Y11:AA11) -> 15033 | AC11: 4870 | AD11: 4636 | AE11: 4970 | AF11: =I11-SUM(AC11:AE11) -> 4681 | AG11: 5753 | AH11: 13852 | AI11: 15592 | AJ11: =J11-SUM(AG11:AI11) -> 14085 | AK11: 6279
B12: Inter-segment | C12: -1103.943 | D12: -435.364 | E12: -724.639 | F12: -46042.537 | G12: -50904 | H12: -53923 | I12: -59123 | J12: -83742 | M12: -8440.135 | N12: -10844.903 | O12: -9291.697 | P12: =E12-SUM(M12:O12) -> 27852.096 | Q12: -10321.12 | R12: -11920.408 | S12: -11003.427 | T12: =F12-SUM(Q12:S12) -> -12797.582 | U12: -11664 | V12: -13775 | W12: -11536 | X12: =G12-SUM(U12:W12) -> -13929 | Y12: -12156 | Z12: -13509 | AA12: -12709 | AB12: =H12-SUM(Y12:AA12) -> -15549 | AC12: -13793 | AD12: -14518 | AE12: -13965 | AF12: =I12-SUM(AC12:AE12) -> -16847 | AG12: -15483 | AH12: -18831 | AI12: -22194 | AJ12: =J12-SUM(AG12:AI12) -> -27234 | AK12: -19754
B13: Total segment net revenues | C13: =SUM(C8:C12) -> 461063.51 | D13: =SUM(D8:D12) -> 575742.06 | E13: =SUM(E8:E12) -> 744995.93 | F13: =SUM(F8:F12) -> 951016.64 | G13: =SUM(G8:G12) -> 1046236 | H13: =SUM(H8:H12) -> 1084662 | I13: =SUM(I8:I12) -> 1158819 | J13: =SUM(J8:J12) -> 1309085 | M13: =SUM(M8:M12) -> 145882.23 | N13: =SUM(N8:N12) -> 200869.01 | O13: =SUM(O8:O12) -> 174055.97 | P13: =SUM(P8:P12) -> 224188.73 | Q13: =SUM(Q8:Q12) -> 203040.42 | R13: =SUM(R8:R12) -> 253661.14 | S13: =SUM(S8:S12) -> 218558.9 | T13: =SUM(T8:T12) -> 275756.18 | ... AK13: =SUM(AK8:AK12) -> 315694
B14: Unallocated items | C14: 956.248 | D14: 1146.429 | E14: 805.952 | F14: 575.519 | G14: 0 | H14: 0 | I14: 0 | J14: 0 | M14: 322.982 | N14: 185.045 | O14: 158.499 | P14: =E14-SUM(M14:O14) -> 139.426 | Q14: 135.754 | R14: 139.33 | S14: 149.454 | T14: =F14-SUM(Q14:S14) -> 150.981 | U14: 0 | V14: 0 | W14: 0 | X14: =G14-SUM(U14:W14) -> 0 | Z14: 0 | AA14: 0 | AB14: =H14-SUM(Y14:AA14) -> 0 | AD14: 0 | AE14: 0 | AF14: =I14-SUM(AC14:AE14) -> 0 | AH14: 0 | AI14: 0 | AJ14: =J14-SUM(AG14:AI14) -> 0
B15: Total consolidated net revenues | C15: =SUM(C13:C14) -> 462019.76 | D15: =SUM(D13:D14) -> 576888.48 | E15: =SUM(E13:E14) -> 745801.89 | F15: =SUM(F13:F14) -> 951592.15 | G15: =SUM(G13:G14) -> 1046236 | H15: =SUM(H13:H14) -> 1084662 | I15: =SUM(I13:I14) -> 1158819 | J15: =SUM(J13:J14) -> 1309085 | M15: =SUM(M13:M14) -> 146205.21 | N15: =SUM(N13:N14) -> 201054.06 | O15: =SUM(O13:O14) -> 174214.46 | P15: =SUM(P13:P14) -> 224328.15 | Q15: =SUM(Q13:Q14) -> 203176.17 | R15: =SUM(R13:R14) -> 253800.47 | S15: =SUM(S13:S14) -> 218708.36 | T15: =SUM(T13:T14) -> 275907.16 | ... AK15: =SUM(AK13:AK14) -> 315694
B16: check | C16: =C15-Model!C7 -> 0 | D16: =D15-Model!D7 -> 0 | E16: =E15-Model!E7 -> 0 | F16: =F15-Model!F7 -> 0 | G16: =G15-Model!G7 -> 0 | H16: =H15-Model!H7 -> 0 | I16: =I15-Model!I7 -> 0 | J16: =J15-Model!J7 -> 0 | M16: =M15-Model!M7 -> 0 | N16: =N15-Model!N7 -> 0 | O16: =O15-Model!O7 -> 0 | P16: =P15-Model!P7 -> 0 | Q16: =Q15-Model!Q7 -> 0 | R16: =R15-Model!R7 -> 0 | S16: =S15-Model!S7 -> 0 | T16: =T15-Model!T7 -> 0 | ... AK16: =AK15-Model!AK7 -> 0
B18: Net revenues (Share %)
B19: JD Retail | C19: =C8/C$15 -> 0.968578 | D19: =D8/D$15 -> 0.95728231 | E19: =E8/E$15 -> 0.94251521 | F19: =F8/F$15 -> 0.91037167 | G19: =G8/G$15 -> 0.88883292 | H19: =H8/H$15 -> 0.87155538 | I19: =I8/I$15 -> 0.87670982 | J19: =J8/J$15 -> 0.86044756 | M19: =M8/M$15 -> 0.93947456 | N19: =N8/N$15 -> 0.94244693 | O19: =O8/O$15 -> 0.92461465 | P19: =P8/P$15 -> 0.95845981 | Q19: =Q8/Q$15 -> 0.91445882 | R19: =R8/R$15 -> 0.91629779 | S19: =S8/S$15 -> 0.9056821 | T19: =T8/T$15 -> 0.90562799 | ... AK19: =AK8/AK$15 -> 0.85078589
B20: JD Logistics | C20: =C9/C$15 -> 0 | D20: =D9/D$15 -> 0 | E20: =E9/E$15 -> 0 | F20: =F9/F$15 -> 0.11001919 | G20: =G9/G$15 -> 0.13132983 | H20: =H9/H$15 -> 0.15361928 | I20: =I9/I$15 -> 0.15777874 | J20: =J9/J$15 -> 0.16587617 | M20: =M9/M$15 -> 0.09340921 | N20: =N9/N$15 -> 0.088960915 | O20: =O9/O$15 -> 0.10311629 | P20: =P9/P$15 -> -0.22069105 | Q20: =Q9/Q$15 -> 0.11030338 | R20: =R9/R$15 -> 0.10268472 | S20: =S9/S$15 -> 0.11773339 | T20: =T9/T$15 -> 0.11044177 | ... AK20: =AK9/AK$15 -> 0.19189785
B21: Dada | C21: =C10/C$15 -> 0 | D21: =D10/D$15 -> 0 | E21: =E10/E$15 -> 0 | F21: =F10/F$15 -> 0 | G21: =G10/G$15 -> 0.0076751326 | H21: =H10/H$15 -> 0 | I21: =I10/I$15 -> 0 | J21: =J10/J$15 -> 0 | M21: =M10/M$15 -> 0 | N21: =N10/N$15 -> 0 | O21: =O10/O$15 -> 0 | P21: =P10/P$15 -> 0 | Q21: =Q10/Q$15 -> 0 | R21: =R10/R$15 -> 0 | S21: =S10/S$15 -> 0 | T21: =T10/T$15 -> 0 | ... AK21: =AK10/AK$15 -> 0
B22: New businesses | C22: =C11/C$15 -> 0.031741675 | D22: =D11/D$15 -> 0.041485103 | E22: =E11/E$15 -> 0.057375765 | F22: =F11/F$15 -> 0.027389077 | G22: =G11/G$15 -> 0.020816527 | H22: =H11/H$15 -> 0.024539442 | I22: =I11/I$15 -> 0.016531486 | J22: =J11/J$15 -> 0.037646142 | M22: =M11/M$15 -> 0.022635137 | N22: =N11/N$15 -> 0.021612013 | O22: =O11/O$15 -> 0.024694086 | P22: =P11/P$15 -> 0.13745189 | Q22: =Q11/Q$15 -> 0.025368512 | R22: =R11/R$15 -> 0.027436147 | S22: =S11/S$15 -> 0.026212121 | T22: =T11/T$15 -> 0.029766669 | ... AK22: =AK11/AK$15 -> 0.019889513
B23: Inter-segment | C23: =C12/C$15 -> -0.0023893848 | D23: =D12/D$15 -> -0.00075467618 | E23: =E12/E$15 -> -0.00097162398 | F23: =F12/F$15 -> -0.048384738 | G23: =G12/G$15 -> -0.048654414 | H23: =H12/H$15 -> -0.049714104 | I23: =I12/I$15 -> -0.051020047 | J23: =J12/J$15 -> -0.063969872 | M23: =M12/M$15 -> -0.057728005 | N23: =N12/N$15 -> -0.053940234 | O23: =O12/O$15 -> -0.05333482 | P23: =P12/P$15 -> 0.12415783 | Q23: =Q12/Q$15 -> -0.050798871 | R23: =R12/R$15 -> -0.046967636 | S23: =S12/S$15 -> -0.050310958 | T23: =T12/T$15 -> -0.046383654 | ... AK23: =AK12/AK$15 -> -0.062573251
B24: Total segment net revenues | C24: =C13/C$15 -> 0.99793029 | D24: =D13/D$15 -> 0.99801274 | E24: =E13/E$15 -> 0.99891935 | F24: =F13/F$15 -> 0.9993952 | G24: =G13/G$15 -> 1 | H24: =H13/H$15 -> 1 | I24: =I13/I$15 -> 1 | J24: =J13/J$15 -> 1 | M24: =M13/M$15 -> 0.9977909 | N24: =N13/N$15 -> 0.99907963 | O24: =O13/O$15 -> 0.99909021 | P24: =P13/P$15 -> 0.99937847 | Q24: =Q13/Q$15 -> 0.99933184 | R24: =R13/R$15 -> 0.99945103 | S24: =S13/S$15 -> 0.99931665 | T24: =T13/T$15 -> 0.99945278 | ... AK24: =AK13/AK$15 -> 1
B25: Unallocated items | C25: =C14/C$15 -> 0.0020697123 | D25: =D14/D$15 -> 0.0019872628 | E25: =E14/E$15 -> 0.0010806516 | F25: =F14/F$15 -> 0.00060479587 | G25: =G14/G$15 -> 0 | H25: =H14/H$15 -> 0 | I25: =I14/I$15 -> 0 | J25: =J14/J$15 -> 0 | M25: =M14/M$15 -> 0.0022091005 | N25: =N14/N$15 -> 0.00092037436 | O25: =O14/O$15 -> 0.00090979243 | P25: =P14/P$15 -> 0.00062152698 | Q25: =Q14/Q$15 -> 0.00066815907 | R25: =R14/R$15 -> 0.00054897455 | S25: =S14/S$15 -> 0.00068334837 | T25: =T14/T$15 -> 0.00054721669 | ... AK25: =AK14/AK$15 -> 0
B26: Total consolidated net revenues | C26: =SUM(C24:C25) -> 1 | D26: =SUM(D24:D25) -> 1 | E26: =SUM(E24:E25) -> 1 | F26: =SUM(F24:F25) -> 1 | G26: =SUM(G24:G25) -> 1 | H26: =SUM(H24:H25) -> 1 | I26: =SUM(I24:I25) -> 1 | J26: =SUM(J24:J25) -> 1 | M26: =SUM(M24:M25) -> 1 | N26: =SUM(N24:N25) -> 1 | O26: =SUM(O24:O25) -> 1 | P26: =SUM(P24:P25) -> 1 | Q26: =SUM(Q24:Q25) -> 1 | R26: =SUM(R24:R25) -> 1 | S26: =SUM(S24:S25) -> 1 | T26: =SUM(T24:T25) -> 1 | ... AK26: =SUM(AK24:AK25) -> 1
B28: Net revenues (YoY % Growth)
B29: JD Retail | D29: =D8/C8-1 -> 0.23406136 | E29: =E8/D8-1 -> 0.27285795 | F29: =F8/E8-1 -> 0.23241718 | G29: =G8/F8-1 -> 0.073446005 | H29: =H8/G8-1 -> 0.016575459 | I29: =I8/H8-1 -> 0.074687177 | J29: =J8/I8-1 -> 0.10871718 | Q29: =Q8/M8-1 -> 0.35266125 | R29: =R8/N8-1 -> 0.22732425 | S29: =S8/O8-1 -> 0.22969154 | T29: =T8/P8-1 -> 0.16213108 | U29: =U8/Q8-1 -> 0.17076643 | V29: =V8/R8-1 -> 0.038701038 | W29: =W8/S8-1 -> 0.069884581 | X29: =X8/T8-1 -> 0.036241975 | ... AK29: =AK8/AG8-1 -> 0.017976463
B30: JD Logistics | D30: =D9/C9-1 -> #DIV/0! | E30: =E9/D9-1 -> #DIV/0! | F30: =F9/E9-1 -> #DIV/0! | G30: =G9/F9-1 -> 0.31242273 | H30: =H9/G9-1 -> 0.21268249 | I30: =I9/H9-1 -> 0.097296324 | J30: =J9/I9-1 -> 0.18764801 | Q30: =Q9/M9-1 -> 0.64100181 | R30: =R9/N9-1 -> 0.45708931 | S30: =S9/O9-1 -> 0.43335417 | T30: =T9/P9-1 -> -1.6154997 | U30: =U9/Q9-1 -> 0.22042643 | V30: =V9/R9-1 -> 0.19993411 | W30: =W9/S9-1 -> 0.38920411 | X30: =X9/T9-1 -> 0.41140907 | ... AK30: =AK9/AG9-1 -> 0.2898631
B31: Dada | D31: =D10/C10-1 -> #DIV/0! | E31: =E10/D10-1 -> #DIV/0! | F31: =F10/E10-1 -> #DIV/0! | G31: =G10/F10-1 -> #DIV/0! | H31: =H10/G10-1 -> -1 | I31: =I10/H10-1 -> #DIV/0! | J31: =J10/I10-1 -> #DIV/0! | Q31: =Q10/M10-1 -> #DIV/0! | R31: =R10/N10-1 -> #DIV/0! | S31: =S10/O10-1 -> #DIV/0! | T31: =T10/P10-1 -> #DIV/0! | U31: =U10/Q10-1 -> #DIV/0! | V31: =V10/R10-1 -> #DIV/0! | W31: =W10/S10-1 -> #DIV/0! | X31: =X10/T10-1 -> #DIV/0! | ... AK31: =AK10/AG10-1 -> #DIV/0!
B32: New businesses | D32: =D11/C11-1 -> 0.6319004 | E32: =E11/D11-1 -> 0.78800171 | F32: =F11/E11-1 -> -0.39091727 | G32: =G11/F11-1 -> -0.16437835 | H32: =H11/G11-1 -> 0.22214059 | I32: =I11/H11-1 -> -0.28027201 | J32: =J11/I11-1 -> 1.5725322 | Q32: =Q11/M11-1 -> 0.55747747 | R32: =R11/N11-1 -> 0.60253481 | S32: =S11/O11-1 -> 0.33257106 | T32: =T11/P11-1 -> -0.73364632 | U32: =U11/Q11-1 -> 0.11674246 | V32: =V11/R11-1 -> -0.10028382 | W32: =W11/S11-1 -> -0.12835067 | X32: =X11/T11-1 -> -0.42029776 | ... AK32: =AK11/AG11-1 -> 0.091430558
B33: Inter-segment | D33: =D12/C12-1 -> -0.60562819 | E33: =E12/D12-1 -> 0.66444401 | F33: =F12/E12-1 -> 62.538585 | G33: =G12/F12-1 -> 0.10558634 | H33: =H12/G12-1 -> 0.059307716 | I33: =I12/H12-1 -> 0.096433804 | J33: =J12/I12-1 -> 0.41640309 | Q33: =Q12/M12-1 -> 0.22286196 | R33: =R12/N12-1 -> 0.099171473 | S33: =S12/O12-1 -> 0.18422146 | T33: =T12/P12-1 -> -1.4594836 | U33: =U12/Q12-1 -> 0.13010991 | V33: =V12/R12-1 -> 0.15558125 | W33: =W12/S12-1 -> 0.048400648 | X33: =X12/T12-1 -> 0.088408732 | ... AK33: =AK12/AG12-1 -> 0.27585093
B34: Total segment net revenues | D34: =D13/C13-1 -> 0.24872613 | E34: =E13/D13-1 -> 0.29397519 | F34: =F13/E13-1 -> 0.27653936 | G34: =G13/F13-1 -> 0.10012376 | H34: =H13/G13-1 -> 0.036727851 | I34: =I13/H13-1 -> 0.068368764 | J34: =J13/I13-1 -> 0.12967167 | Q34: =Q13/M13-1 -> 0.3918105 | R34: =R13/N13-1 -> 0.26281867 | S34: =S13/O13-1 -> 0.25568178 | T34: =T13/P13-1 -> 0.23001802 | U34: =U13/Q13-1 -> 0.18033151 | V34: =V13/R13-1 -> 0.054950711 | W34: =W13/S13-1 -> 0.11427627 | X34: =X13/T13-1 -> 0.071403021 | ... AK34: =AK13/AG13-1 -> 0.048531629
B35: Unallocated items | D35: =D14/C14-1 -> 0.19888251 | E35: =E14/D14-1 -> -0.29698917 | F35: =F14/E14-1 -> -0.28591405 | G35: =G14/F14-1 -> -1 | H35: =H14/G14-1 -> #DIV/0! | I35: =I14/H14-1 -> #DIV/0! | J35: =J14/I14-1 -> #DIV/0! | Q35: =Q14/M14-1 -> -0.57968556 | R35: =R14/N14-1 -> -0.24704802 | S35: =S14/O14-1 -> -0.057066606 | T35: =T14/P14-1 -> 0.082875504 | U35: =U14/Q14-1 -> -1 | V35: =V14/R14-1 -> -1 | W35: =W14/S14-1 -> -1 | X35: =X14/T14-1 -> -1 | ... AK35: =AK14/AG14-1 -> #DIV/0!
B36: Total consolidated net revenues | D36: =D15/C15-1 -> 0.24862297 | E36: =E15/D15-1 -> 0.29280079 | F36: =F15/E15-1 -> 0.27593155 | G36: =G15/F15-1 -> 0.099458414 | H36: =H15/G15-1 -> 0.036727851 | I36: =I15/H15-1 -> 0.068368764 | J36: =J15/I15-1 -> 0.12967167 | Q36: =Q15/M15-1 -> 0.38966437 | R36: =R15/N15-1 -> 0.2623494 | S36: =S15/O15-1 -> 0.25539724 | T36: =T15/P15-1 -> 0.22992656 | U36: =U15/Q15-1 -> 0.17954286 | V36: =V15/R15-1 -> 0.05437157 | W36: =W15/S15-1 -> 0.11351483 | X36: =X15/T15-1 -> 0.070816731 | ... AK36: =AK15/AG15-1 -> 0.048531629
B39: Operating income/(loss)
B40: JD Retail | C40: 7049.222 | D40: 13775.339 | E40: 19484.484 | F40: 26612.604 | G40: 34852 | H40: 35925 | I40: 41077 | J40: 51402 | M40: 5061.433 | N40: 4859.411 | O40: 6734.811 | P40: =E40-SUM(M40:O40) -> 2828.829 | Q40: 7340.103 | R40: 5986.538 | S40: 7942.242 | T40: =F40-SUM(Q40:S40) -> 5343.721 | U40: 7891 | V40: 8173 | W40: 10926 | X40: =G40-SUM(U40:W40) -> 7862 | Y40: 9844 | Z40: 8143 | AA40: 11001 | AB40: =H40-SUM(Y40:AA40) -> 6937 | AC40: 9325 | AD40: 10108 | AE40: 11608 | AF40: =I40-SUM(AC40:AE40) -> 10036 | AG40: 12846 | AH40: 13939 | AI40: 14828 | AJ40: =J40-SUM(AG40:AI40) -> 9789 | AK40: 14960
B41: JD Logistics | F41: -1827.056 | G41: 528 | H41: 1005 | I41: 6317 | J41: 5269 | M41: -421.385 | N41: 2101.478 | O41: 83.549 | P41: =E41-SUM(M41:O41) -> -1763.642 | Q41: -1473.582 | R41: -356.599 | S41: -726.612 | T41: =F41-SUM(Q41:S41) -> 729.737 | U41: -661 | V41: 36 | W41: 253 | X41: =G41-SUM(U41:W41) -> 900 | Y41: -1123 | Z41: 510 | AA41: 288 | AB41: =H41-SUM(Y41:AA41) -> 1330 | AC41: 224 | AD41: 2183 | AE41: 2086 | AF41: =I41-SUM(AC41:AE41) -> 1824 | AG41: 145 | AH41: 1958 | AI41: 1282 | AJ41: =J41-SUM(AG41:AI41) -> 1884 | AK41: 1020
B42: Dada | G42: -1122 | U42: -191 | V42: -424 | W42: -300 | X42: =G42-SUM(U42:W42) -> -207 | Y42: -217 | Z42: -29 | AA42: -52 | AB42: =H42-SUM(Y42:AA42) -> 298
B43: New businesses | C43: -5136.657 | D43: -1022.281 | E43: -2498.85 | F43: -10599.085 | G43: -5295 | H43: -329 | I43: -2865 | J43: -46641 | M43: -1384.165 | N43: -1171.713 | O43: -1200.492 | P43: =E43-SUM(M43:O43) -> 1257.52 | Q43: -2281.486 | R43: -3020.114 | S43: -2073.45 | T43: =F43-SUM(Q43:S43) -> -3224.035 | U43: -2386 | V43: -2032 | W43: 276 | X43: =G43-SUM(U43:W43) -> -1153 | Y43: -157 | Z43: 1061 | AA43: -140 | AB43: =H43-SUM(Y43:AA43) -> -1093 | AC43: -670 | AD43: -695 | AE43: -615 | AF43: =I43-SUM(AC43:AE43) -> -885 | AG43: -1327 | AH43: -14777 | AI43: -15736 | AJ43: =J43-SUM(AG43:AI43) -> -14801 | AK43: -10352
B44: Total segment operating income | C44: =SUM(C40:C43) -> 1912.565 | D44: =SUM(D40:D43) -> 12753.058 | E44: =SUM(E40:E43) -> 16985.634 | F44: =SUM(F40:F43) -> 14186.463 | G44: =SUM(G40:G43) -> 28963 | H44: =SUM(H40:H43) -> 36601 | I44: =SUM(I40:I43) -> 44529 | J44: =SUM(J40:J43) -> 10030 | M44: =SUM(M40:M43) -> 3255.883 | N44: =SUM(N40:N43) -> 5789.176 | O44: =SUM(O40:O43) -> 5617.868 | P44: =SUM(P40:P43) -> 2322.707 | Q44: =SUM(Q40:Q43) -> 3585.035 | R44: =SUM(R40:R43) -> 2609.825 | S44: =SUM(S40:S43) -> 5142.18 | T44: =SUM(T40:T43) -> 2849.423 | ... AK44: =SUM(AK40:AK43) -> 5628
B45: Unallocated items | C45: -4531.696 | D45: -3758.178 | E45: -4642.814 | F45: -10045.513 | G45: -9240 | H45: -10576 | I45: -5793 | J45: -7256 | M45: -935.434 | N45: -745.101 | O45: -1234.519 | P45: =E45-SUM(M45:O45) -> -1727.76 | Q45: -1925.291 | R45: -2309.069 | S45: -2569.743 | T45: =F45-SUM(Q45:S45) -> -3241.41 | U45: -2244 | V45: -1995 | W45: -2427 | X45: =G45-SUM(U45:W45) -> -2574 | Y45: -1920 | Z45: -1415 | AA45: -1794 | AB45: =H45-SUM(Y45:AA45) -> -5447 | AC45: -1179 | AD45: -1095 | AE45: -1035 | AF45: =I45-SUM(AC45:AE45) -> -2484 | AG45: -1131 | AH45: -1979 | AI45: -1425 | AJ45: =J45-SUM(AG45:AI45) -> -2721 | AK45: -1821
B46: Total consolidated operating income | C46: =SUM(C44:C45) -> -2619.131 | D46: =SUM(D44:D45) -> 8994.88 | E46: =SUM(E44:E45) -> 12342.82 | F46: =SUM(F44:F45) -> 4140.95 | G46: =SUM(G44:G45) -> 19723 | H46: =SUM(H44:H45) -> 26025 | I46: =SUM(I44:I45) -> 38736 | J46: =SUM(J44:J45) -> 2774 | M46: =SUM(M44:M45) -> 2320.449 | N46: =SUM(N44:N45) -> 5044.075 | O46: =SUM(O44:O45) -> 4383.349 | P46: =SUM(P44:P45) -> 594.947 | Q46: =SUM(Q44:Q45) -> 1659.744 | R46: =SUM(R44:R45) -> 300.756 | S46: =SUM(S44:S45) -> 2572.437 | T46: =SUM(T44:T45) -> -391.987 | ... AK46: =SUM(AK44:AK45) -> 3807
...
