Workbook
Name IQ_CH: 110000
Name IQ_CQ: 5000
Name IQ_CY: 10000
Name IQ_DAILY: 500000
Name IQ_FH: 100000
Name IQ_FQ: 500
Name IQ_FY: 1000
Name IQ_LTM: 2000
Name IQ_MONTH: 15000
Name IQ_NTM: 6000
Name IQ_WEEK: 50000
Name IQ_YTD: 3000

Sheet Capitalisation
A3: 1Q26 | I3: Exchange rate as at end | J3: =Model!O$204 -> 0.86557604
I4: LTM Average exchange rate | J4: =Model!O$205 -> 0.87061569
B7: Debt Breakdown as on 31-Mar-2026 | C7: EUR (mn) | D7: USD (mn) | E7: Leverage | F7: Leverage (USD) | I7: Company reported
B8: Long term | I8: Gross debt | J8: =4347.2+5030 -> 9377.2
B9: Interest-bearing loans and borrowings from financial institutions | C9: 4276.9 | D9: =C9/$J3 -> 4941.1026 | I9: Cash and cash equivalents | J9: =C17 -> 633
B10: Bonds issued | C10: 4218 | D10: =C10/$J3 -> 4873.0554 | I10: Net Debt | J10: =J8-J9 -> 8744.2
B12: Short term | I12: NORMALISED NET DEBT TO EBITDA | J12: 9.4x
B13: Interest-bearing loans and borrowings from financial institutions | C13: 70.4 | D13: =C13/$J3 -> 81.33312
B14: Bonds issued | C14: 812.1 | D14: =C14/$J3 -> 938.21913
B16: Total Debt | C16: =SUM(C9:C14) -> 9377.4 | D16: =SUM(D9:D14) -> 10833.71 | E16: =C16/C21 -> 13.053174 | F16: =D16/D21 -> 13.129173
B17: Cash and Short-Term Investments | C17: =Model!BF$130 -> 633 | D17: =C17/$J3 -> 731.3049
B18: Net debt | C18: =C16-C17 -> 8744.4 | D18: =D16-D17 -> 10102.405 | E18: =C18/C21 -> 12.172049 | F18: =D18/D21 -> 12.242918
B19: Equity | C19: =Model!BF$134 -> 8679.8 | D19: =C19/$J3 -> 10027.773
B20: Total Capitalisation | C20: =C18+C19 -> 17424.2 | D20: =C20/$J3 -> 20130.178
B21: LTM Adjusted EBITDA | C21: =Model!BF$110 -> 718.4 | D21: =C21/$J4 -> 825.16316
B22: check | C22: =+C16-Model!BF$128 -> 0
B25: Debt Maturity for 1Q26 | C25: EUR mn | D25: USD mn
B26: 2026 | C26: 327 | D26: =+C26/$J3 -> 377.7831
B27: =B26+1 -> 2027 | C27: 583 | D27: =+C27/$J3 -> 673.5399
B28: =B27+1 -> 2028 | C28: 478 | D28: =+C28/$J3 -> 552.2334
B29: =B28+1 -> 2029 | C29: 1338 | D29: =+C29/$J3 -> 1545.7914
B30: =B29+1 -> 2030 | C30: 2094 | D30: =+C30/$J3 -> 2419.1982
B31: =B30+1 -> 2031 | C31: 2438 | D31: =+C31/$J3 -> 2816.6214
B32: =B31+1 -> 2032 | C32: 1199 | D32: =+C32/$J3 -> 1385.2047
B33: =B32+1 -> 2033 | C33: 35 | D33: =+C33/$J3 -> 40.4355
B34: =B33+1 -> 2034 | C34: 397 | D34: =+C34/$J3 -> 458.6541
B35: 2035+ | C35: 513 | D35: =+C35/$J3 -> 592.6689
B36: Total Debt | C36: =+SUM(C26:C35) -> 9402 | D36: =+SUM(D26:D35) -> 10862.131
A39: FY25 | I39: Exchange rate as at end | J39: =Model!O$204 -> 0.86557604
I40: LTM Average exchange rate | J40: =Model!O$205 -> 0.87061569
B43: Debt Breakdown as on31-Dec-2025 | C43: EUR (mn) | D43: USD (mn) | E43: Leverage | F43: Leverage (USD) | I43: Company reported
B44: Long term | I44: Gross debt | J44: =5142.6+4085.9 -> 9228.5
B45: Interest-bearing loans and borrowings from financial institutions | C45: 4013.5 | D45: =C45/$J39 -> 4636.7966 | I45: Cash and cash equivalents | J45: =C53 -> 708.4
B46: Bonds issued | C46: 4434.3 | D46: =C46/$J39 -> 5122.9468 | I46: Net Debt | J46: =J44-J45 -> 8520.1
B48: Short term | I48: NORMALISED NET DEBT TO EBITDA | J48: 9.3x
B49: Interest-bearing loans and borrowings from financial institutions | C49: 72.4 | D49: =C49/$J39 -> 83.64372
B50: Bonds issued | C50: 708.4 | D50: =C50/$J39 -> 818.41452
B52: Total Debt | C52: =SUM(C45:C50) -> 9228.6 | D52: =SUM(D45:D50) -> 10661.802 | E52: =C52/C57 -> 13.161152 | F52: =D52/D57 -> 13.237781
B53: Cash and Short-Term Investments | C53: =Model!BE$130 -> 708.4 | D53: =C53/$J39 -> 818.41452
B54: Net debt | C54: =C52-C53 -> 8520.2 | D54: =D52-D53 -> 9843.3871 | E54: =C54/C57 -> 12.150884 | F54: =D54/D57 -> 12.22163
...

Sheet Model
B2: CTP Group | C2: Annual | D2: Annual | E2: Annual | F2: Annual | G2: Annual | H2: Annual | I2: Annual | J2: Annual | K2: Annual | L2: Annual | M2: Annual | N2: Annual | O2: LTM | Q2: Half-yearly | R2: Half-yearly | S2: Half-yearly | T2: Half-yearly | U2: Half-yearly | V2: Half-yearly | W2: Half-yearly | X2: Half-yearly | Y2: Half-yearly | Z2: Half-yearly | AA2: Half-yearly | AB2: Half-yearly | AC2: Half-yearly | AD2: Half-yearly | AF2: Quarterly | AG2: Quarterly | AH2: Quarterly | AI2: Quarterly | AJ2: Quarterly | AK2: Quarterly | AL2: Quarterly | AM2: Quarterly | AN2: Quarterly | AO2: Quarterly | AP2: Quarterly | AQ2: Quarterly | AR2: Quarterly | AS2: Quarterly | AT2: Quarterly | AU2: Quarterly | AV2: Quarterly | AW2: Quarterly | AX2: Quarterly | AY2: Quarterly | AZ2: Quarterly | BA2: Quarterly | BB2: Quarterly | BC2: Quarterly | BD2: Quarterly | BE2: Quarterly | BF2: Quarterly
B3: (EUR millions) | C3: 42735 | D3: 43100 | E3: 43465 | F3: 43830 | G3: 44196 | H3: 44561 | I3: 44926 | J3: 44926 | K3: 45291 | L3: 45291 | M3: 45657 | N3: 46022 | O3: =BF3 -> 46112 | Q3: 43646 | R3: 43830 | S3: 44012 | T3: 44196 | U3: 44377 | V3: 44561 | W3: 44742 | X3: 44926 | Y3: 45107 | Z3: 45291 | AA3: 45473 | AB3: 45657 | AC3: 45838 | AD3: 46022 | AF3: 43738 | AG3: 43830 | AH3: 43920 | AI3: 44012 | AJ3: 44104 | AK3: 44196 | AL3: 44285 | AM3: 44377 | AN3: 44469 | AO3: 44561 | AP3: 44651 | AQ3: 44742 | AR3: 44834 | AS3: 44926 | AT3: 45016 | AU3: 45107 | AV3: 45199 | AW3: 45291 | AX3: 45382 | AY3: 45473 | AZ3: 45565 | BA3: 45657 | BB3: 45747 | BC3: 45838 | BD3: 45930 | BE3: 46022 | BF3: 46112
C4: Act | D4: Act | E4: Act | F4: Act | G4: Act | H4: Act | I4: Act | J4: Restated | K4: Act | L4: Restated | M4: Act | N4: Act | O4: Act | Q4: Act | R4: Act | S4: Act | T4: Act | U4: Act | V4: Act | W4: Act | X4: Act | Y4: Act | Z4: Act | AA4: Act | AB4: Act | AC4: Act | AD4: Act | AF4: Act | AG4: Act | AH4: Act | AI4: Act | AJ4: Act | AK4: Act | AL4: Act | AM4: Act | AN4: Act | AO4: Act | AP4: Act | AQ4: Act | AR4: Act | AS4: Act | AT4: Act | AU4: Act | AV4: Act | AW4: Act | AX4: Act | AY4: Act | AZ4: Act | BA4: Act | BB4: Act | BC4: Act | BD4: Act | BE4: Act | BF4: Act
C5: FY 16 | D5: FY 17 | E5: FY 18 | F5: FY 19 | G5: FY 20 | H5: FY 21 | I5: FY 22 | J5: FY 22 | K5: FY 23 | L5: FY 23 | M5: FY 24 | N5: FY 25 | O5: LTM | Q5: 1H 19 | R5: 2H 19 | S5: 1H 20 | T5: 2H 20 | U5: 1H 21 | V5: 2H 21 | W5: 1H22 | X5: 2H 22 | Y5: 1H23 | Z5: 2H 22 | AA5: 1H24 | AB5: 2H 24 | AC5: 1H 25 | AD5: 2H 25 | AF5: 3Q19 | AG5: 4Q19 | AH5: 1Q20 | AI5: 2Q20 | AJ5: 3Q20 | AK5: 4Q20 | AL5: 1Q21 | AM5: 2Q21 | AN5: 3Q21 | AO5: 4Q21 | AP5: 1Q22 | AQ5: 2Q22 | AR5: 3Q22 | AS5: 4Q22 | AT5: 1Q23 | AU5: 2Q23 | AV5: 3Q23 | AW5: 4Q23 | AX5: 1Q24 | AY5: 2Q24 | AZ5: 3Q24 | BA5: 4Q24 | BB5: 1Q25 | BC5: 2Q25 | BD5: 3Q25 | BE5: 4Q25 | BF5: 1Q25
B6: INCOME STATEMENT
B7: Rental income | C7: 182.705 | D7: 208.26 | E7: 241.96 | F7: 257.986 | G7: 291.935 | H7: 334.651 | I7: 485.017 | J7: 485.017 | K7: 571.9 | L7: 571.9 | M7: 664.1 | N7: 759.8 | O7: =SUM(BC7:BF7) -> 782.4 | Q7: 122.901 | R7: =F7-Q7 -> 135.085 | S7: 140.587 | T7: =G7-S7 -> 151.348 | U7: 159.808 | V7: =H7-U7 -> 174.843 | W7: 230.5 | X7: =I7-W7 -> 254.517 | Y7: 280.4 | Z7: =K7-Y7 -> 291.5 | AA7: 320.9 | AB7: =M7-AA7 -> 343.2 | AC7: 367.2 | AD7: =N7-AC7 -> 392.6 | AF7: =181.313-Q7 -> 58.412 | AG7: =F7-AF7-Q7 -> 76.673 | AH7: 68.382 | AI7: =S7-AH7 -> 72.205 | AJ7: =209.693-S7 -> 69.106 | AK7: =G7-AJ7-S7 -> 82.242 | AL7: 77.772 | AM7: =U7-AL7 -> 82.036 | AN7: =245.712-U7 -> 85.904 | AO7: =H7-AN7-U7 -> 88.939 | AP7: 109.593 | AQ7: =W7-AP7 -> 120.907 | AR7: =354.226-W7 -> 123.726 | AS7: =I7-AR7-W7 -> 130.791 | AT7: 136.031 | AU7: =Y7-AT7 -> 144.369 | AV7: =421.5-Y7 -> 141.1 | AW7: =K7-AV7-Y7 -> 150.4 | AX7: 157.5 | AY7: =AA7-AX7 -> 163.4 | AZ7: =488.4-AA7 -> 167.5 | BA7: =M7-AZ7-AA7 -> 175.7 | BB7: 182.5 | BC7: =AC7-BB7 -> 184.7 | BD7: =562-AC7 -> 194.8 | BE7: =N7-AC7-BD7 -> 197.8 | BF7: 205.1
B8: Service charge income | C8: 12.325 | D8: 14.049 | E8: 19.99 | F8: 22.379 | G8: 25.882 | H8: 31.112 | I8: 51.875 | J8: 51.875 | K8: 60.7 | L8: 60.7 | M8: 75.9 | N8: 92.3 | O8: =SUM(BC8:BF8) -> 96 | Q8: 10.916 | R8: =F8-Q8 -> 11.463 | S8: 12.159 | T8: =G8-S8 -> 13.723 | U8: 14.704 | V8: =H8-U8 -> 16.408 | W8: 23.866 | X8: =I8-W8 -> 28.009 | Y8: 29.1 | Z8: =K8-Y8 -> 31.6 | AA8: 35.4 | AB8: =M8-AA8 -> 40.5 | AC8: 44.8 | AD8: =N8-AC8 -> 47.5 | AF8: =16.176-Q8 -> 5.26 | AG8: =F8-AF8-Q8 -> 6.203 | AH8: 6.046 | AI8: =S8-AH8 -> 6.113 | AJ8: =18.093-S8 -> 5.934 | AK8: =G8-AJ8-S8 -> 7.789 | AL8: 7.402 | AM8: =U8-AL8 -> 7.302 | AN8: =22.597-U8 -> 7.893 | AO8: =H8-AN8-U8 -> 8.515 | AP8: 11.106 | AQ8: =W8-AP8 -> 12.76 | AR8: =37.755-W8 -> 13.889 | AS8: =I8-AR8-W8 -> 14.12 | AT8: 14.434 | AU8: =Y8-AT8 -> 14.666 | AV8: =43.4-Y8 -> 14.3 | AW8: =K8-AV8-Y8 -> 17.3 | AX8: 17.5 | AY8: =AA8-AX8 -> 17.9 | AZ8: =54.9-AA8 -> 19.5 | BA8: =M8-AZ8-AA8 -> 21 | BB8: 21.8 | BC8: =AC8-BB8 -> 23 | BD8: =68.8-AC8 -> 24 | BE8: =N8-AC8-BD8 -> 23.5 | BF8: 25.5
B9: Property operating expenses | C9: -13.371 | D9: -15.221 | E9: -29.799 | F9: -40.575 | G9: -37.148 | H9: -38.91 | I9: -84.758 | J9: -84.758 | K9: -89.4 | L9: -89.2 | M9: -93.2 | N9: -114.1 | O9: =SUM(BC9:BF9) -> -120.1 | Q9: -21.254 | R9: =F9-Q9 -> -19.321 | S9: -16.256 | T9: =G9-S9 -> -20.892 | U9: -14.205 | V9: =H9-U9 -> -24.705 | W9: -42.861 | X9: =I9-W9 -> -41.897 | Y9: =-41.2+1.5 -> -39.7 | Z9: =K9-Y9 -> -49.7 | AA9: =-42.4+1.8 -> -40.6 | AB9: =M9-AA9 -> -52.6 | AC9: =-51.6 -> -51.6 | AD9: =N9-AC9 -> -62.5 | AF9: =-31.938-Q9 -> -10.684 | AG9: =F9-AF9-Q9 -> -8.637 | AH9: -7.613 | AI9: =S9-AH9 -> -8.643 | AJ9: =-24.509-S9 -> -8.253 | AK9: =G9-AJ9-S9 -> -12.639 | AL9: -7.086 | AM9: =U9-AL9 -> -7.119 | AN9: =-28.44-U9 -> -14.235 | AO9: =H9-AN9-U9 -> -10.47 | AP9: -13.5 | AQ9: =W9-AP9 -> -29.361 | AR9: =-(63.745)-W9 -> -20.884 | AS9: =I9-AR9-W9 -> -21.013 | AT9: -19.814 | AU9: =Y9-AT9 -> -19.886 | AV9: =-62.4-Y9+3.2 -> -19.5 | AW9: =K9-AV9-Y9 -> -30.2 | AX9: =-21.5+0.3 -> -21.2 | AY9: =AA9-AX9 -> -19.4 | AZ9: =-67.4-AA9+3.1 -> -23.7 | BA9: =M9-AZ9-AA9 -> -28.9 | BB9: -25 | BC9: =AC9-BB9 -> -26.6 | BD9: =-81.9-AC9 -> -30.3 | BE9: =N9-AC9-BD9 -> -32.2 | BF9: -31
B10: Net rental income | C10: =SUM(C7:C9) -> 181.659 | D10: =SUM(D7:D9) -> 207.088 | E10: =SUM(E7:E9) -> 232.151 | F10: =SUM(F7:F9) -> 239.79 | G10: =SUM(G7:G9) -> 280.669 | H10: =SUM(H7:H9) -> 326.853 | I10: =SUM(I7:I9) -> 452.134 | J10: =SUM(J7:J9) -> 452.134 | ... O10: =SUM(O7:O9) -> 758.3 | Q10: =SUM(Q7:Q9) -> 112.563 | R10: =SUM(R7:R9) -> 127.227 | S10: =SUM(S7:S9) -> 136.49 | T10: =SUM(T7:T9) -> 144.179 | U10: =SUM(U7:U9) -> 160.307 | V10: =SUM(V7:V9) -> 166.546 | W10: =SUM(W7:W9) -> 211.505 | X10: =SUM(X7:X9) -> 240.629 | ... AD10: =SUM(AD7:AD9) -> 377.6 | AF10: =SUM(AF7:AF9) -> 52.988 | AG10: =SUM(AG7:AG9) -> 74.239 | AH10: =SUM(AH7:AH9) -> 66.815 | AI10: =SUM(AI7:AI9) -> 69.675 | AJ10: =SUM(AJ7:AJ9) -> 66.787 | AK10: =SUM(AK7:AK9) -> 77.392 | AL10: =SUM(AL7:AL9) -> 78.088 | AM10: =SUM(AM7:AM9) -> 82.219 | ... BF10: =SUM(BF7:BF9) -> 199.6
B11: Income from renewable energy | L11: 6.3 | M11: 7.6 | N11: 14.7 | O11: =SUM(BC11:BF11) -> 16.1 | AB11: =M11-AA11 -> 7.6 | AC11: 8 | AD11: =N11-AC11 -> 6.7 | AX11: 1 | BA11: =M11-AZ11-AA11 -> 7.6 | BB11: 1.9 | BC11: =AC11-BB11 -> 6.1 | BD11: =12.4-AC11 -> 4.4 | BE11: =N11-AC11-BD11 -> 2.3 | BF11: 3.3
B12: Expenses from renewable energy | L12: -2.8 | M12: -4.2 | N12: -9.5 | O12: =SUM(BC12:BF12) -> -12.8 | AB12: =M12-AA12 -> -4.2 | AC12: -4.1 | AD12: =N12-AC12 -> -5.4 | AX12: -0.7 | BA12: =M12-AZ12-AA12 -> -4.2 | BB12: -1.8 | BC12: =AC12-BB12 -> -2.3 | BD12: =-6.6-AC12 -> -2.5 | BE12: =N12-AC12-BD12 -> -2.9 | BF12: -5.1
B13: Net income from renewable energy | L13: =SUM(L11:L12) -> 3.5 | M13: =SUM(M11:M12) -> 3.4 | N13: =SUM(N11:N12) -> 5.2 | O13: =SUM(O11:O12) -> 3.3 | AB13: =SUM(AB11:AB12) -> 3.4 | AC13: =SUM(AC11:AC12) -> 3.9 | AD13: =SUM(AD11:AD12) -> 1.3 | AX13: =SUM(AX11:AX12) -> 0.3 | BA13: =SUM(BA11:BA12) -> 3.4 | BB13: =SUM(BB11:BB12) -> 0.1 | BC13: =SUM(BC11:BC12) -> 3.8 | BD13: =SUM(BD11:BD12) -> 1.9 | BE13: =SUM(BE11:BE12) -> -0.6 | BF13: =SUM(BF11:BF12) -> -1.8
B14: Hotel operating revenue | C14: 9.772 | D14: 14.978 | E14: 16.805 | F14: 17.312 | G14: 5.752 | H14: 8.779 | I14: 16.021 | J14: 16.021 | K14: 21.1 | L14: 21.1 | M14: 22.4 | N14: 22.8 | O14: =SUM(BC14:BF14) -> 22.7 | Q14: 8.679 | R14: =F14-Q14 -> 8.633 | S14: 3.274 | T14: =G14-S14 -> 2.478 | U14: 2.664 | V14: =H14-U14 -> 6.115 | W14: 7.181 | X14: =I14-W14 -> 8.84 | Y14: 10 | Z14: =K14-Y14 -> 11.1 | AA14: 10.5 | AB14: =M14-AA14 -> 11.9 | AC14: 10.9 | AD14: =N14-AC14 -> 11.9 | AF14: =13.437-Q14 -> 4.758 | AG14: =F14-AF14-Q14 -> 3.875 | AH14: 2.542 | AI14: =S14-AH14 -> 0.732 | AJ14: =4.846-S14 -> 1.572 | AK14: =G14-AJ14-S14 -> 0.906 | AL14: 0.83 | AM14: =U14-AL14 -> 1.834 | AN14: =5.838-U14 -> 3.174 | AO14: =H14-AN14-U14 -> 2.941 | AP14: 2.249 | AQ14: =W14-AP14 -> 4.932 | AR14: =11.074-W14 -> 3.893 | AS14: =I14-AR14-W14 -> 4.947 | AT14: 4.039 | AU14: =Y14-AT14 -> 5.961 | AV14: =15.3-Y14 -> 5.3 | AW14: =K14-AV14-Y14 -> 5.8 | AX14: 4.5 | AY14: =AA14-AX14 -> 6 | AZ14: =16.1-AA14 -> 5.6 | BA14: =M14-AZ14-AA14 -> 6.3 | BB14: 4.6 | BC14: =AC14-BB14 -> 6.3 | BD14: =16.6-AC14 -> 5.7 | BE14: =N14-AC14-BD14 -> 6.2 | BF14: 4.5
B15: Hotel operating expenses | C15: -6.961 | D15: -10.564 | E15: -10.681 | F15: -11.545 | G15: -5.897 | H15: -11.334 | I15: -12.28 | J15: -12.28 | K15: -15.7 | L15: -15.7 | M15: -16.3 | N15: -13.7 | O15: =SUM(BC15:BF15) -> -13.8 | Q15: -5.605 | R15: =F15-Q15 -> -5.94 | S15: -3.24 | T15: =G15-S15 -> -2.657 | U15: -2.538 | V15: =H15-U15 -> -8.796 | W15: -6.048 | X15: =I15-W15 -> -6.232 | Y15: -7.4 | Z15: =K15-Y15 -> -8.3 | AA15: -5.4 | AB15: =M15-AA15 -> -10.9 | AC15: -5 | AD15: =N15-AC15 -> -8.7 | AF15: =-7.9-Q15 -> -2.295 | AG15: =F15-AF15-Q15 -> -3.645 | AH15: -2.298 | AI15: =S15-AH15 -> -0.942 | AJ15: =-4.508-S15 -> -1.268 | AK15: =G15-AJ15-S15 -> -1.389 | AL15: -1.166 | AM15: =U15-AL15 -> -1.372 | AN15: =-5.693-U15 -> -3.155 | AO15: =H15-AN15-U15 -> -5.641 | AP15: -2.649 | AQ15: =W15-AP15 -> -3.399 | AR15: =-9.324-W15 -> -3.276 | AS15: =I15-AR15-W15 -> -2.956 | AT15: -3.356 | AU15: =Y15-AT15 -> -4.044 | AV15: =-11.6-Y15 -> -4.2 | AW15: =K15-AV15-Y15 -> -4.1 | AX15: -3.2 | AY15: =AA15-AX15 -> -2.2 | AZ15: =-10-AA15 -> -4.6 | BA15: =M15-AZ15-AA15 -> -6.3 | BB15: -3.6 | BC15: =AC15-BB15 -> -1.4 | BD15: =-9-AC15 -> -4 | BE15: =N15-AC15-BD15 -> -4.7 | BF15: -3.7
B16: Net operating income from hotel operations | C16: =SUM(C14:C15) -> 2.811 | D16: =SUM(D14:D15) -> 4.414 | E16: =SUM(E14:E15) -> 6.124 | F16: =SUM(F14:F15) -> 5.767 | G16: =SUM(G14:G15) -> -0.145 | H16: =SUM(H14:H15) -> -2.555 | I16: =SUM(I14:I15) -> 3.741 | J16: =SUM(J14:J15) -> 3.741 | ... O16: =SUM(O14:O15) -> 8.9 | Q16: =SUM(Q14:Q15) -> 3.074 | R16: =SUM(R14:R15) -> 2.693 | S16: =SUM(S14:S15) -> 0.034 | T16: =SUM(T14:T15) -> -0.179 | U16: =SUM(U14:U15) -> 0.126 | V16: =SUM(V14:V15) -> -2.681 | W16: =SUM(W14:W15) -> 1.133 | X16: =SUM(X14:X15) -> 2.608 | ... AD16: =SUM(AD14:AD15) -> 3.2 | AF16: =SUM(AF14:AF15) -> 2.463 | AG16: =SUM(AG14:AG15) -> 0.23 | AH16: =SUM(AH14:AH15) -> 0.244 | AI16: =SUM(AI14:AI15) -> -0.21 | AJ16: =SUM(AJ14:AJ15) -> 0.304 | AK16: =SUM(AK14:AK15) -> -0.483 | AL16: =SUM(AL14:AL15) -> -0.336 | AM16: =SUM(AM14:AM15) -> 0.462 | ... BF16: =SUM(BF14:BF15) -> 0.8
B17: Income from development activities | C17: 5.194 | D17: 16.55 | E17: 9.358 | F17: 4.483 | G17: 49.411 | H17: 32.824 | I17: 36.2 | J17: 36.2 | K17: 20.1 | L17: 20.1 | M17: 100.7 | N17: 82.9 | O17: =SUM(BC17:BF17) -> 86 | Q17: 6.059 | R17: =F17-Q17 -> -1.576 | S17: 43.576 | T17: =G17-S17 -> 5.835 | U17: 23.399 | V17: =H17-U17 -> 9.425 | W17: 23.251 | X17: =I17-W17 -> 12.949 | Y17: 7.1 | Z17: =K17-Y17 -> 13 | AA17: 32.3 | AB17: =M17-AA17 -> 68.4 | AC17: 21.4 | AD17: =N17-AC17 -> 61.5 | AF17: =10.269-Q17 -> 4.21 | AG17: =F17-AF17-Q17 -> -5.786 | AH17: 21.629 | AI17: =S17-AH17 -> 21.947 | AJ17: =45.956-S17 -> 2.38 | AK17: =G17-AJ17-S17 -> 3.455 | AL17: 17.519 | AM17: =U17-AL17 -> 5.88 | AN17: =24.866-U17 -> 1.467 | AO17: =H17-AN17-U17 -> 7.958 | AP17: 11.869 | AQ17: =W17-AP17 -> 11.382 | AR17: =31.187-W17 -> 7.936 | AS17: =I17-AR17-W17 -> 5.013 | AT17: 3.446 | AU17: =Y17-AT17 -> 3.654 | AV17: =12.1-Y17 -> 5 | AW17: =K17-AV17-Y17 -> 8 | AX17: 10.4 | AY17: =AA17-AX17 -> 21.9 | AZ17: =41.5-AA17 -> 9.2 | BA17: =M17-AZ17-AA17 -> 59.2 | BB17: 10.4 | BC17: =AC17-BB17 -> 11 | BD17: =33.7-AC17 -> 12.3 | BE17: =N17-AC17-BD17 -> 49.2 | BF17: 13.5
B18: Expenses from development activities | C18: -4.108 | D18: -12.55 | E18: -7.891 | F18: -3.927 | G18: -26.984 | H18: -23.459 | I18: -27.158 | J18: -27.1 | K18: -14.7 | L18: -14.7 | M18: -75.2 | N18: -55.9 | O18: =SUM(BC18:BF18) -> -55.4 | Q18: -4.838 | R18: =F18-Q18 -> 0.911 | S18: -20.019 | T18: =G18-S18 -> -6.965 | U18: -17.141 | V18: =H18-U18 -> -6.318 | W18: -17.427 | X18: =I18-W18 -> -9.731 | Y18: -5.1 | Z18: =K18-Y18 -> -9.6 | AA18: -23.7 | AB18: =M18-AA18 -> -51.5 | AC18: -15 | AD18: =N18-AC18 -> -40.9 | AF18: =-8.565-Q18 -> -3.727 | AG18: =F18-AF18-Q18 -> 4.638 | AH18: -11.556 | AI18: =S18-AH18 -> -8.463 | AJ18: =-21.621-S18 -> -1.602 | AK18: =G18-AJ18-S18 -> -5.363 | AL18: -12.826 | AM18: =U18-AL18 -> -4.315 | AN18: =-17.991-U18 -> -0.85 | AO18: =H18-AN18-U18 -> -5.468 | AP18: -8.827 | AQ18: =W18-AP18 -> -8.6 | AR18: =-(23.623)-W18 -> -6.196 | AS18: =I18-AR18-W18 -> -3.535 | AT18: -2.608 | AU18: =Y18-AT18 -> -2.492 | AV18: =-9.2-Y18 -> -4.1 | AW18: =K18-AV18-Y18 -> -5.5 | AX18: -7.4 | AY18: =AA18-AX18 -> -16.3 | AZ18: =-31-AA18 -> -7.3 | BA18: =M18-AZ18-AA18 -> -44.2 | BB18: -7.9 | BC18: =AC18-BB18 -> -7.1 | BD18: =-23.4-AC18 -> -8.4 | BE18: =N18-AC18-BD18 -> -32.5 | BF18: -7.4
B19: Net income from development activities | C19: =SUM(C17:C18) -> 1.086 | D19: =SUM(D17:D18) -> 4 | E19: =SUM(E17:E18) -> 1.467 | F19: =SUM(F17:F18) -> 0.556 | G19: =SUM(G17:G18) -> 22.427 | H19: =SUM(H17:H18) -> 9.365 | I19: =SUM(I17:I18) -> 9.042 | J19: =SUM(J17:J18) -> 9.1 | ... O19: =SUM(O17:O18) -> 30.6 | Q19: =SUM(Q17:Q18) -> 1.221 | R19: =SUM(R17:R18) -> -0.665 | S19: =SUM(S17:S18) -> 23.557 | T19: =SUM(T17:T18) -> -1.13 | U19: =SUM(U17:U18) -> 6.258 | V19: =SUM(V17:V18) -> 3.107 | W19: =SUM(W17:W18) -> 5.824 | X19: =SUM(X17:X18) -> 3.218 | ... AD19: =SUM(AD17:AD18) -> 20.6 | AF19: =SUM(AF17:AF18) -> 0.483 | AG19: =SUM(AG17:AG18) -> -1.148 | AH19: =SUM(AH17:AH18) -> 10.073 | AI19: =SUM(AI17:AI18) -> 13.484 | AJ19: =SUM(AJ17:AJ18) -> 0.778 | AK19: =SUM(AK17:AK18) -> -1.908 | AL19: =SUM(AL17:AL18) -> 4.693 | AM19: =SUM(AM17:AM18) -> 1.565 | ... BB19: =SUM(BB17:BB18) -> 2.5 | BC19: =AC19-BB19 -> 3.9 | BD19: =SUM(BD17:BD18) -> 3.9 | BE19: =SUM(BE17:BE18) -> 16.7 | BF19: =SUM(BF17:BF18) -> 6.1
B20: Revenue | C20: =C10+C16+C19 -> 185.556 | D20: =D10+D16+D19 -> 215.502 | E20: =E10+E16+E19 -> 239.742 | F20: =F10+F16+F19 -> 246.113 | G20: =G10+G16+G19 -> 302.951 | H20: =H10+H16+H19 -> 333.663 | I20: =I10+I16+I19 -> 464.917 | J20: =J10+J16+J19 -> 464.975 | K20: =K10+K16+K19 -> 554 | L20: =L10+L16+L19+L13 -> 557.7 | M20: =M10+M16+M19+M13 -> 681.8 | N20: =N10+N16+N19+N13 -> 779.3 | O20: =O10+O16+O19+O13 -> 801.1 | Q20: =Q10+Q16+Q19+Q13 -> 116.858 | R20: =R10+R16+R19+R13 -> 129.255 | S20: =S10+S16+S19+S13 -> 160.081 | T20: =T10+T16+T19+T13 -> 142.87 | U20: =U10+U16+U19+U13 -> 166.691 | V20: =V10+V16+V19+V13 -> 166.972 | W20: =W10+W16+W19+W13 -> 218.462 | X20: =X10+X16+X19+X13 -> 246.455 | ... AD20: =AD10+AD16+AD19+AD13 -> 402.7 | AF20: =AF10+AF16+AF19+AF13 -> 55.934 | AG20: =AG10+AG16+AG19+AG13 -> 73.321 | AH20: =AH10+AH16+AH19+AH13 -> 77.132 | AI20: =AI10+AI16+AI19+AI13 -> 82.949 | AJ20: =AJ10+AJ16+AJ19+AJ13 -> 67.869 | AK20: =AK10+AK16+AK19+AK13 -> 75.001 | AL20: =AL10+AL16+AL19+AL13 -> 82.445 | AM20: =AM10+AM16+AM19+AM13 -> 84.246 | ... BF20: =BF10+BF16+BF19+BF13 -> 204.7
B21: % growth | D21: =D20/C20-1 -> 0.16138524 | E21: =E20/D20-1 -> 0.11248155 | F21: =F20/E20-1 -> 0.026574401 | G21: =G20/F20-1 -> 0.2309427 | H21: =H20/G20-1 -> 0.10137613 | I21: =I20/H20-1 -> 0.39337295 | J21: =J20/I20-1 -> 0.00012475345 | K21: =K20/I20-1 -> 0.19161055 | L21: =L20/J20-1 -> 0.19941932 | M21: =M20/L20-1 -> 0.22252107 | N21: =N20/M20-1 -> 0.14300381 | S21: =S20/Q20-1 -> 0.36987626 | U21: =U20/S20-1 -> 0.041291596 | W21: =W20/U20-1 -> 0.31058066 | Y21: =Y20/W20-1 -> 0.25605368 | AA21: =AA20/X20-1 -> 0.33655231 | AC21: =AC20/Z20-1 -> 0.34692418 | AJ21: =AJ20/AF20-1 -> 0.21337648 | AK21: =AK20/AG20-1 -> 0.022912944 | AL21: =AL20/AH20-1 -> 0.068881917 | AM21: =AM20/AI20-1 -> 0.015636114 | AN21: =AN20/AJ20-1 -> 0.18165878 | AO21: =AO20/AK20-1 -> 0.15697124 | AP21: =+AP20/AL20-1 -> 0.33229426 | AQ21: =+AQ20/AM20-1 -> 0.28933124 | AR21: =AR20/AN20-1 -> 0.48492481 | AS21: =AS20/AO20-1 -> 0.46780142 | AT21: =+AT20/AP20-1 -> 0.20330296 | AU21: =+AU20/AQ20-1 -> 0.30939689 | AV21: =AV20/AR20-1 -> 0.15796722 | AW21: =AW20/AS20-1 -> 0.11253307 | AX21: =+AX20/AT20-1 -> 0.1984384 | AY21: =+AY20/AU20-1 -> 0.2044042 | AZ21: =+AZ20/AV20-1 -> 0.20522117 | BA21: =BA20/AW20-1 -> 0.31404375 | BB21: =+BB20/AX20-1 -> 0.15467172 | BC21: =+BC20/AY20-1 -> 0.13076474 | BD21: =+BD20/AZ20-1 -> 0.17930205 | BE21: =BE20/BA20-1 -> 0.11009667 | BF21: =+BF20/BB20-1 -> 0.11919081
B22: Net valuation result on investment property | C22: =296.326-35.491 -> 260.835 | D22: =407.417-78.889 -> 328.528 | E22: 238.017 | F22: 406.775 | G22: 152.162 | H22: 1100.571 | I22: 723.58 | J22: 697.3 | K22: 878.7 | L22: 878.7 | M22: 941.5 | N22: 1139.9 | O22: =SUM(BC22:BF22) -> 1147.8 | Q22: 145.243 | R22: =F22-Q22 -> 261.532 | S22: 29.96 | T22: =G22-S22 -> 122.202 | U22: 145.743 | V22: =H22-U22 -> 954.828 | W22: 499.016 | X22: =I22-W22 -> 224.564 | Y22: 417.2 | Z22: =K22-Y22 -> 461.5 | AA22: 436.7 | AB22: =M22-AA22 -> 504.8 | AC22: 597.9 | AD22: =N22-AC22 -> 542 | AF22: =179.608-Q22 -> 34.365 | AG22: =F22-AF22-Q22 -> 227.167 | AH22: 28.68 | AI22: =S22-AH22 -> 1.28 | AJ22: =76.627-S22 -> 46.667 | AK22: =G22-AJ22-S22 -> 75.535 | AL22: 67.101 | AM22: =U22-AL22 -> 78.642 | AN22: =265.232-U22 -> 119.489 | AO22: =H22-AN22-U22 -> 835.339 | AP22: 27.521 | AQ22: =W22-AP22 -> 471.495 | AR22: =558.138 -W22 -> 59.122 | AS22: =I22-AR22-W22 -> 165.442 | AT22: 208.282 | AU22: =Y22-AT22 -> 208.918 | AV22: =656.3 -Y22 -> 239.1 | AW22: =K22-AV22-Y22 -> 222.4 | AX22: 165.6 | AY22: =AA22-AX22 -> 271.1 | AZ22: =604.1-AA22 -> 167.4 | BA22: =M22-AZ22-AA22 -> 337.4 | BB22: 156.2 | BC22: =AC22-BB22 -> 441.7 | BD22: =801.6-AC22 -> 203.7 | BE22: =N22-AC22-BD22 -> 338.3 | BF22: 164.1
B24: Net business income | C24: =+C20+C22 -> 446.391 | D24: =+D20+D22 -> 544.03 | E24: =+E20+E22 -> 477.759 | F24: =+F20+F22 -> 652.888 | G24: =+G20+G22 -> 455.113 | H24: =+H20+H22 -> 1434.234 | I24: =+I20+I22 -> 1188.497 | J24: =+J20+J22 -> 1162.275 | ... O24: =+O20+O22 -> 1948.9 | Q24: =+Q20+Q22 -> 262.101 | R24: =+R20+R22 -> 390.787 | S24: =+S20+S22 -> 190.041 | T24: =+T20+T22 -> 265.072 | U24: =+U20+U22 -> 312.434 | V24: =+V20+V22 -> 1121.8 | W24: =+W20+W22 -> 717.478 | X24: =+X20+X22 -> 471.019 | ... AD24: =+AD20+AD22 -> 944.7 | AF24: =+AF20+AF22 -> 90.299 | AG24: =+AG20+AG22 -> 300.488 | AH24: =+AH20+AH22 -> 105.812 | AI24: =+AI20+AI22 -> 84.229 | AJ24: =+AJ20+AJ22 -> 114.536 | AK24: =+AK20+AK22 -> 150.536 | AL24: =+AL20+AL22 -> 149.546 | AM24: =+AM20+AM22 -> 162.888 | ... BF24: =+BF20+BF22 -> 368.8
B25: % growth | D25: =D24/C24-1 -> 0.21872977 | E25: =E24/D24-1 -> -0.12181497 | F25: =F24/E24-1 -> 0.36656348 | G25: =G24/F24-1 -> -0.30292332 | H25: =H24/G24-1 -> 2.15138 | I25: =I24/H24-1 -> -0.17133676 | J25: =J24/I24-1 -> -0.02206316 | K25: =K24/I24-1 -> 0.20547212 | L25: =L24/J24-1 -> 0.2358521 | M25: =M24/J24-1 -> 0.39665742 | N25: =N24/K24-1 -> 0.33956865 | S25: =S24/Q24-1 -> -0.27493218 | U25: =U24/S24-1 -> 0.64403471 | W25: =W24/U24-1 -> 1.2964146 | Y25: =Y24/W24-1 -> -0.036068005 | AA25: =AA24/X24-1 -> 0.62647367 | AC25: =AC24/Z24-1 -> 0.31493726
B26: Other income | C26: 9.17 | D26: 3.794 | E26: 49.693 | F26: 9.094 | G26: 4.01 | H26: 10.445 | I26: 8.182 | J26: 8.182 | K26: 14.1 | L26: 7.8 | M26: 10.7 | N26: 12.4 | O26: =SUM(BC26:BF26) -> 14.2 | Q26: 14.528 | R26: =F26-Q26 -> -5.434 | S26: 3.871 | T26: =G26-S26 -> 0.139 | U26: 4.047 | V26: =H26-U26 -> 6.398 | W26: 4.369 | X26: =I26-W26 -> 3.813 | Y26: 8.6 | Z26: =K26-Y26 -> 5.5 | AA26: 8.1 | AB26: =M26-AA26 -> 2.6 | AC26: 6.5 | AD26: =N26-AC26 -> 5.9 | AF26: =15.17-Q26 -> 0.642 | AG26: =F26-AF26-Q26 -> -6.076 | AH26: 0.951 | AI26: =S26-AH26 -> 2.92 | AJ26: =7.296-S26 -> 3.425 | AK26: =G26-AJ26-S26 -> -3.286 | AL26: 1.769 | AM26: =U26-AL26 -> 2.278 | AN26: =7.338-U26 -> 3.291 | AO26: =H26-AN26-U26 -> 3.107 | AP26: 2.53 | AQ26: =W26-AP26 -> 1.839 | AR26: =6.597-W26 -> 2.228 | AS26: =I26-AR26-W26 -> 1.585 | AT26: 0.6 | AU26: =Y26-AT26 -> 8 | AV26: =6.6-Y26 -> -2 | AW26: =K26-AV26-Y26 -> 7.5 | AX26: 4.6 | AY26: =AA26-AX26 -> 3.5 | AZ26: =10-AA26 -> 1.9 | BA26: =M26-AZ26-AA26 -> 0.7 | BB26: 2.7 | BC26: =AC26-BB26 -> 3.8 | BD26: =7.6-AC26 -> 1.1 | BE26: =N26-AC26-BD26 -> 4.8 | BF26: 4.5
B27: Amortization and depreciation | C27: -3.996 | D27: -5.418 | E27: -3.868 | F27: -9.753 | G27: -10.462 | H27: -8.447 | I27: -10.729 | J27: -10.729 | K27: -12.7 | L27: -11.3 | M27: -11 | N27: -12.2 | O27: =SUM(BC27:BF27) -> -13 | Q27: -3.456 | R27: =F27-Q27 -> -6.297 | S27: -4.317 | T27: =G27-S27 -> -6.145 | U27: -5.102 | V27: =H27-U27 -> -3.345 | W27: -5.015 | X27: =I27-W27 -> -5.714 | Y27: -6.1 | Z27: =K27-Y27 -> -6.6 | AA27: -5.7 | AB27: =M27-AA27 -> -5.3 | AC27: -5.7 | AD27: =N27-AC27 -> -6.5 | AF27: =-4.487-Q27 -> -1.031 | AG27: =F27-AF27-Q27 -> -5.266 | AH27: -2.635 | AI27: =S27-AH27 -> -1.682 | AJ27: =-6.424-S27 -> -2.107 | AK27: =G27-AJ27-S27 -> -4.038 | AL27: -2.564 | AM27: =U27-AL27 -> -2.538 | AN27: =-6.371-U27 -> -1.269 | AO27: =H27-AN27-U27 -> -2.076 | AP27: -2.225 | AQ27: =W27-AP27 -> -2.79 | AR27: =-(7.906)-W27 -> -2.891 | AS27: =I27-AR27-W27 -> -2.823 | AT27: -2.8 | AU27: =Y27-AT27 -> -3.3 | AV27: =-8.2-Y27 -> -2.1 | AW27: =K27-AV27-Y27 -> -4.5 | AX27: -3.2 | AY27: =AA27-AX27 -> -2.5 | AZ27: =-8.4-AA27 -> -2.7 | BA27: =M27-AZ27-AA27 -> -2.6 | BB27: -2.8 | BC27: =AC27-BB27 -> -2.9 | BD27: =-8.5-AC27 -> -2.8 | BE27: =N27-AC27-BD27 -> -3.7 | BF27: -3.6
B28: Employee benefits | C28: 0 | D28: 0 | E28: -11.335 | F28: -17.172 | G28: -22.969 | H28: -31.883 | I28: -43.706 | J28: -43.706 | K28: -50.4 | L28: -50.4 | M28: -52.8 | N28: -51.4 | O28: =SUM(BC28:BF28) -> -53.5 | Q28: -8.221 | R28: =F28-Q28 -> -8.951 | S28: -9.321 | T28: =G28-S28 -> -13.648 | U28: -12.321 | V28: =H28-U28 -> -19.562 | W28: -21.588 | X28: =I28-W28 -> -22.118 | Y28: -25.5 | Z28: =K28-Y28 -> -24.9 | AA28: -24.9 | AB28: =M28-AA28 -> -27.9 | AC28: -26.5 | AD28: =N28-AC28 -> -24.9 | AF28: =-12.236-Q28 -> -4.015 | AG28: =F28-AF28-Q28 -> -4.936 | AH28: -4.293 | AI28: =S28-AH28 -> -5.028 | AJ28: =-13.486-S28 -> -4.165 | AK28: =G28-AJ28-S28 -> -9.483 | AL28: -5.693 | AM28: =U28-AL28 -> -6.628 | AN28: =-22.616-U28 -> -10.295 | AO28: =H28-AN28-U28 -> -9.267 | AP28: -9.704 | AQ28: =W28-AP28 -> -11.884 | AR28: =-(33.563)-W28 -> -11.975 | AS28: =I28-AR28-W28 -> -10.143 | AT28: -13.026 | AU28: =Y28-AT28 -> -12.474 | AV28: =-35.4-Y28 -> -9.9 | AW28: =K28-AV28-Y28 -> -15 | AX28: -13.4 | AY28: =AA28-AX28 -> -11.5 | AZ28: =-39.9-AA28 -> -15 | BA28: =M28-AZ28-AA28 -> -12.9 | BB28: -13.1 | BC28: =AC28-BB28 -> -13.4 | BD28: =-38.6-AC28 -> -12.1 | BE28: =N28-AC28-BD28 -> -12.8 | BF28: -15.2
B29: Impairment of goodwill | N29: -113.6 | O29: =SUM(BC29:BF29) -> -113.6 | AD29: =N29-AC29 -> -113.6 | BE29: =N29-AC29-BD29 -> -113.6
B30: Impairment of financial assets | C30: 0 | D30: 0 | E30: 0 | F30: -0.009 | G30: -0.685 | H30: -1.078 | I30: 1.225 | J30: 1.225 | K30: -1.4 | L30: -1.4 | M30: -3.7 | N30: -0.2 | O30: =SUM(BC30:BF30) -> -0.1 | Q30: 0 | R30: =F30-Q30 -> -0.009 | S30: 0 | T30: =G30-S30 -> -0.685 | U30: 0.248 | V30: =H30-U30 -> -1.326 | W30: 0.463 | X30: =I30-W30 -> 0.762 | Y30: -0.5 | Z30: =K30-Y30 -> -0.9 | AA30: -1.1 | AB30: =M30-AA30 -> -2.6 | AC30: 0 | AD30: =N30-AC30 -> -0.2 | AF30: =0-Q30 -> 0 | AG30: =F30-AF30-Q30 -> -0.009 | AH30: -0.039 | AI30: =S30-AH30 -> 0.039 | AJ30: =-S30 -> 0 | AK30: =G30-AJ30-S30 -> -0.685 | AL30: 0.24 | AM30: =U30-AL30 -> 0.008 | AN30: =-0.254-U30 -> -0.502 | AO30: =H30-AN30-U30 -> -0.824 | AP30: 0.337 | AQ30: =W30-AP30 -> 0.126 | AR30: =1.723-W30 -> 1.26 | AS30: =I30-AR30-W30 -> -0.498 | AT30: -0.124 | AU30: =Y30-AT30 -> -0.376 | AV30: =-0.8-Y30 -> -0.3 | AW30: =K30-AV30-Y30 -> -0.6 | AX30: -0.7 | AY30: =AA30-AX30 -> -0.4 | AZ30: =-1.4-AA30 -> -0.3 | BA30: =M30-AZ30-AA30 -> -2.3 | BB30: 0 | BC30: =AC30-BB30 -> 0 | BD30: =0-AC30 -> 0 | BE30: =N30-AC30-BD30 -> -0.2 | BF30: 0.1
B31: Other expenses | C31: -29.766 | D31: -33.309 | E31: -28.356 | F31: -17.149 | G31: -33.121 | H31: -26.463 | I31: -59.584 | J31: -69.7 | K31: -58.5 | L31: -57.3 | M31: -55.3 | N31: -65.5 | O31: =SUM(BC31:BF31) -> -69.9 | Q31: -17.315 | R31: =F31-Q31 -> 0.166 | S31: -12.225 | T31: =G31-S31 -> -20.896 | U31: -9.589 | V31: =H31-U31 -> -16.874 | W31: -35.198 | X31: =I31-W31 -> -24.386 | Y31: -29.6 | Z31: =K31-Y31 -> -28.9 | AA31: -26.3 | AB31: =M31-AA31 -> -29 | AC31: -25.5 | AD31: =N31-AC31 -> -40 | AF31: =-15.365-Q31 -> 1.95 | AG31: =F31-AF31-Q31 -> -1.784 | AH31: -6.785 | AI31: =S31-AH31 -> -5.44 | AJ31: =-16.723-S31 -> -4.498 | AK31: =G31-AJ31-S31 -> -16.398 | AL31: -5.081 | AM31: =U31-AL31 -> -4.508 | AN31: =-14.291-U31 -> -4.702 | AO31: =H31-AN31-U31 -> -12.172 | AP31: -20.59 | AQ31: =W31-AP31 -> -14.608 | AR31: =-48.127-W31 -> -12.929 | AS31: =I31-AR31-W31 -> -11.457 | AT31: -17.107 | AU31: =Y31-AT31 -> -12.493 | AV31: =-41-Y31 -> -11.4 | AW31: =K31-AV31-Y31 -> -17.5 | AX31: -10.9 | AY31: =AA31-AX31 -> -15.4 | AZ31: =-35.6-AA31 -> -9.3 | BA31: =M31-AZ31-AA31 -> -19.7 | BB31: -12.4 | BC31: =AC31-BB31 -> -13.1 | BD31: =-37.7-AC31 -> -12.2 | BE31: =N31-AC31-BD31 -> -27.8 | BF31: -16.8
B32: Net other income/expenses | C32: =SUM(C26:C31) -> -24.592 | D32: =SUM(D26:D31) -> -34.933 | E32: =SUM(E26:E31) -> 6.134 | F32: =SUM(F26:F31) -> -34.989 | G32: =SUM(G26:G31) -> -63.227 | H32: =SUM(H26:H31) -> -57.426 | I32: =SUM(I26:I31) -> -104.612 | J32: =SUM(J26:J31) -> -114.728 | ... O32: =SUM(O26:O31) -> -235.9 | Q32: =SUM(Q26:Q31) -> -14.464 | R32: =SUM(R26:R31) -> -20.525 | S32: =SUM(S26:S31) -> -21.992 | T32: =SUM(T26:T31) -> -41.235 | U32: =SUM(U26:U31) -> -22.717 | V32: =SUM(V26:V31) -> -34.709 | W32: =SUM(W26:W31) -> -56.969 | X32: =SUM(X26:X31) -> -47.643 | ... AD32: =SUM(AD26:AD31) -> -179.3 | AF32: =SUM(AF26:AF31) -> -2.454 | AG32: =SUM(AG26:AG31) -> -18.071 | AH32: =SUM(AH26:AH31) -> -12.801 | AI32: =SUM(AI26:AI31) -> -9.191 | AJ32: =SUM(AJ26:AJ31) -> -7.345 | AK32: =SUM(AK26:AK31) -> -33.89 | AL32: =SUM(AL26:AL31) -> -11.329 | AM32: =SUM(AM26:AM31) -> -11.388 | ... BF32: =SUM(BF26:BF31) -> -31
B34: Profit before net financing cost | C34: =C24+C32 -> 421.799 | D34: =D24+D32 -> 509.097 | E34: =E24+E32 -> 483.893 | F34: =F24+F32 -> 617.899 | G34: =G24+G32 -> 391.886 | H34: =H24+H32 -> 1376.808 | I34: =I24+I32 -> 1083.885 | J34: =J24+J32 -> 1047.547 | ... O34: =O24+O32 -> 1713 | Q34: =Q24+Q32 -> 247.637 | R34: =R24+R32 -> 370.262 | S34: =S24+S32 -> 168.049 | T34: =T24+T32 -> 223.837 | U34: =U24+U32 -> 289.717 | V34: =V24+V32 -> 1087.091 | W34: =W24+W32 -> 660.509 | X34: =X24+X32 -> 423.376 | ... AD34: =AD24+AD32 -> 765.4 | AF34: =AF24+AF32 -> 87.845 | AG34: =AG24+AG32 -> 282.417 | AH34: =AH24+AH32 -> 93.011 | AI34: =AI24+AI32 -> 75.038 | AJ34: =AJ24+AJ32 -> 107.191 | AK34: =AK24+AK32 -> 116.646 | AL34: =AL24+AL32 -> 138.217 | AM34: =AM24+AM32 -> 151.5 | ... BF34: =BF24+BF32 -> 337.8
B35: % margin | C35: =C34/C20 -> 2.2731628 | D35: =D34/D20 -> 2.3623771 | E35: =E34/E20 -> 2.0183906 | F35: =F34/F20 -> 2.5106313 | G35: =G34/G20 -> 1.2935623 | H35: =H34/H20 -> 4.126343 | I35: =I34/I20 -> 2.3313516 | J35: =J34/J20 -> 2.2529104 | ... O35: =O34/O20 -> 2.1383098 | Q35: =Q34/Q20 -> 2.1191275 | R35: =R34/R20 -> 2.8645855 | S35: =S34/S20 -> 1.0497748 | T35: =T34/T20 -> 1.566718 | U35: =U34/U20 -> 1.7380482 | V35: =V34/V20 -> 6.5106185 | W35: =W34/W20 -> 3.0234503 | X35: =X34/X20 -> 1.7178633 | ... AD35: =AD34/AD20 -> 1.9006705 | AF35: =AF34/AF20 -> 1.5705117 | AG35: =AG34/AG20 -> 3.8517887 | AH35: =AH34/AH20 -> 1.2058679 | AI35: =AI34/AI20 -> 0.90462815 | AJ35: =AJ34/AJ20 -> 1.5793809 | AK35: =AK34/AK20 -> 1.5552593 | AL35: =AL34/AL20 -> 1.6764752 | AM35: =AM34/AM20 -> 1.798305 | ... BF35: =BF34/BF20 -> 1.6502198
B36: Interest income | C36: 0.89 | D36: 1.323 | E36: 1.953 | F36: 0.582 | G36: 0.953 | H36: 1.993 | I36: 4.235 | J36: 4.235 | K36: 17.2 | L36: 17.2 | M36: 36.7 | N36: 26.9 | O36: =SUM(BC36:BF36) -> 24.2 | Q36: 0.298 | R36: =F36-Q36 -> 0.284 | S36: 0.411 | T36: =G36-S36 -> 0.542 | U36: 0.977 | V36: =H36-U36 -> 1.016 | W36: 2.27 | X36: =I36-W36 -> 1.965 | Y36: 7 | Z36: =K36-Y36 -> 10.2 | AA36: 18.6 | AB36: =M36-AA36 -> 18.1 | AC36: 15.5 | AD36: =N36-AC36 -> 11.4 | AF36: =0.392-Q36 -> 0.094 | AG36: =F36-AF36-Q36 -> 0.19 | AH36: 0.278 | AI36: =S36-AH36 -> 0.133 | AJ36: =0.538-S36 -> 0.127 | AK36: =G36-AJ36-S36 -> 0.415 | AL36: 0.475 | AM36: =U36-AL36 -> 0.502 | AN36: =1.468-U36 -> 0.491 | AO36: =H36-AN36-U36 -> 0.525 | AP36: 1.005 | AQ36: =W36-AP36 -> 1.265 | AR36: =3.213-W36 -> 0.943 | AS36: =I36-AR36-W36 -> 1.022 | AT36: 3.062 | AU36: =Y36-AT36 -> 3.938 | AV36: =11.7-Y36 -> 4.7 | AW36: =K36-AV36-Y36 -> 5.5 | AX36: 8 | AY36: =AA36-AX36 -> 10.6 | AZ36: =27.7-AA36 -> 9.1 | BA36: =M36-AZ36-AA36 -> 9 | BB36: 5.5 | BC36: =AC36-BB36 -> 10 | BD36: =19.7-AC36 -> 4.2 | BE36: =N36-AC36-BD36 -> 7.2 | BF36: 2.8
B37: Interest expense | C37: -38.556 | D37: -44.426 | E37: -54.927 | F37: -57.019 | G37: -68.534 | H37: -70.883 | I37: -84.944 | J37: -84.944 | K37: -129 | L37: -129 | M37: -241.7 | N37: -293.7 | O37: =SUM(BC37:BF37) -> -290.6 | Q37: -25.962 | R37: =F37-Q37 -> -31.057 | S37: -30.877 | T37: =G37-S37 -> -37.657 | U37: -43.721 | V37: =H37-U37 -> -27.162 | W37: -40.423 | X37: =I37-W37 -> -44.521 | Y37: -59.8 | Z37: =K37-Y37 -> -69.2 | AA37: -107 | AB37: =M37-AA37 -> -134.7 | AC37: -143.1 | AD37: =N37-AC37 -> -150.6 | AF37: =-40.697-Q37 -> -14.735 | AG37: =F37-AF37-Q37 -> -16.322 | AH37: -16.468 | AI37: =S37-AH37 -> -14.409 | AJ37: =-54.531-S37 -> -23.654 | AK37: =G37-AJ37-S37 -> -14.003 | AL37: -18.875 | AM37: =U37-AL37 -> -24.846 | AN37: =-55.89-U37 -> -12.169 | AO37: =H37-AN37-U37 -> -14.993 | AP37: -21.822 | AQ37: =W37-AP37 -> -18.601 | AR37: =-(60.087) -W37 -> -19.664 | AS37: =I37-AR37-W37 -> -24.857 | AT37: -28.052 | AU37: =Y37-AT37 -> -31.748 | AV37: =-(90.2) -Y37 -> -30.4 | AW37: =K37-AV37-Y37 -> -38.8 | AX37: -50.7 | AY37: =AA37-AX37 -> -56.3 | AZ37: =-171.9-AA37 -> -64.9 | BA37: =M37-AZ37-AA37 -> -69.8 | BB37: -67 | BC37: =AC37-BB37 -> -76.1 | BD37: =-215.9-AC37 -> -72.8 | BE37: =N37-AC37-BD37 -> -77.8 | BF37: -63.9
B38: Other financial expenses | C38: -6.441 | D38: -6.587 | E38: -8.405 | F38: -15.944 | G38: -11.501 | H38: -38.12 | I38: -17.939 | J38: -17.939 | K38: -8.5 | L38: -8.5 | M38: -17.3 | N38: -33.2 | O38: =SUM(BC38:BF38) -> -43.8 | Q38: -15.79 | R38: =F38-Q38 -> -0.154 | S38: -2.495 | T38: =G38-S38 -> -9.006 | U38: -20.29 | V38: =H38-U38 -> -17.83 | W38: -14.914 | X38: =I38-W38 -> -3.025 | Y38: -3.1 | Z38: =K38-Y38 -> -5.4 | AA38: -3 | AB38: =M38-AA38 -> -14.3 | AC38: -18.4 | AD38: =N38-AC38 -> -14.8 | AF38: =-20.56-Q38 -> -4.77 | AG38: =F38-AF38-Q38 -> 4.616 | AH38: -0.973 | AI38: =S38-AH38 -> -1.522 | AJ38: =-9.105-S38 -> -6.61 | AK38: =G38-AJ38-S38 -> -2.396 | AL38: -8.02 | AM38: =U38-AL38 -> -12.27 | AN38: =-33.39-U38 -> -13.1 | AO38: =H38-AN38-U38 -> -4.73 | AP38: -12.04 | AQ38: =W38-AP38 -> -2.874 | AR38: =-(16.367)-W38 -> -1.453 | AS38: =I38-AR38-W38 -> -1.572 | AT38: -1.393 | AU38: =Y38-AT38 -> -1.707 | AV38: =-(6.5)-Y38 -> -3.4 | AW38: =K38-AV38-Y38 -> -2 | AX38: -1.393 | AY38: =AA38-AX38 -> -1.607 | AZ38: =-5.1-AA38 -> -2.1 | BA38: =M38-AZ38-AA38 -> -12.2 | BB38: -5.3 | BC38: =AC38-BB38 -> -13.1 | BD38: =-21.6-AC38 -> -3.2 | BE38: =N38-AC38-BD38 -> -11.6 | BF38: -15.9
B39: Other financial gains/losses | C39: 6.474 | D39: -0.178 | E39: 1.361 | F39: -44.809 | G39: -22.379 | H39: 6.892 | I39: 2.031 | J39: 2.031 | K39: 8.6 | L39: 8.6 | M39: 41.2 | N39: -23.2 | O39: =SUM(BC39:BF39) -> -15.4 | Q39: -32.136 | R39: =F39-Q39 -> -12.673 | S39: -8.146 | T39: =G39-S39 -> -14.233 | U39: 6.531 | V39: =H39-U39 -> 0.361 | W39: 2.6 | X39: =I39-W39 -> -0.569 | Y39: 1 | Z39: =K39-Y39 -> 7.6 | AA39: 37.7 | AB39: =M39-AA39 -> 3.5 | AC39: -7.7 | AD39: =N39-AC39 -> -15.5 | AF39: =-66.055-Q39 -> -33.919 | AG39: =F39-AF39-Q39 -> 21.246 | AH39: -1.928 | AI39: =S39-AH39 -> -6.218 | AJ39: =-6.563-S39 -> 1.583 | AK39: =G39-AJ39-S39 -> -15.816 | AL39: 9.325 | AM39: =U39-AL39 -> -2.794 | AN39: =5.961-U39 -> -0.57 | AO39: =H39-AN39-U39 -> 0.931 | AP39: 0.153 | AQ39: =W39-AP39 -> 2.447 | AR39: =0.397-W39 -> -2.203 | AS39: =I39-AR39-W39 -> 1.634 | AT39: -2.136 | AU39: =Y39-AT39 -> 3.136 | AV39: =3.2-Y39 -> 2.2 | AW39: =K39-AV39-Y39 -> 5.4 | AX39: 25.6 | AY39: =AA39-AX39 -> 12.1 | AZ39: =39.7-AA39 -> 2 | BA39: =M39-AZ39-AA39 -> 1.5 | BB39: -5.6 | BC39: =AC39-BB39 -> -2.1 | BD39: =-17.9-AC39 -> -10.2 | BE39: =N39-AC39-BD39 -> -5.3 | BF39: 2.2
B40: Profit before tax | C40: =C34+C37+C36+C38+C39 -> 384.166 | D40: =D34+D37+D36+D38+D39 -> 459.229 | E40: =E34+E37+E36+E38+E39 -> 423.875 | F40: =F34+F37+F36+F38+F39 -> 500.709 | G40: =G34+G37+G36+G38+G39 -> 290.425 | H40: =H34+H37+H36+H38+H39 -> 1276.69 | I40: =I34+I37+I36+I38+I39 -> 987.268 | J40: =J34+J37+J36+J38+J39 -> 950.93 | ... O40: =O34+O37+O36+O38+O39 -> 1387.4 | Q40: =Q34+Q37+Q36+Q38+Q39 -> 174.047 | R40: =R34+R37+R36+R38+R39 -> 326.662 | S40: =S34+S37+S36+S38+S39 -> 126.942 | T40: =T34+T37+T36+T38+T39 -> 163.483 | U40: =U34+U37+U36+U38+U39 -> 233.214 | V40: =V34+V37+V36+V38+V39 -> 1043.476 | W40: =W34+W37+W36+W38+W39 -> 610.042 | X40: =X34+X37+X36+X38+X39 -> 377.226 | ... AD40: =AD34+AD37+AD36+AD38+AD39 -> 595.9 | AF40: =AF34+AF37+AF36+AF38+AF39 -> 34.515 | AG40: =AG34+AG37+AG36+AG38+AG39 -> 292.147 | AH40: =AH34+AH37+AH36+AH38+AH39 -> 73.92 | AI40: =AI34+AI37+AI36+AI38+AI39 -> 53.022 | AJ40: =AJ34+AJ37+AJ36+AJ38+AJ39 -> 78.637 | AK40: =AK34+AK37+AK36+AK38+AK39 -> 84.846 | AL40: =AL34+AL37+AL36+AL38+AL39 -> 121.122 | AM40: =AM34+AM37+AM36+AM38+AM39 -> 112.092 | ... BF40: =BF34+BF37+BF36+BF38+BF39 -> 263
BC41: =AC41-BB41 -> 0
B42: Income tax expense | C42: -73.369 | D42: -109.41 | E42: -60.992 | F42: -108.548 | G42: -37.901 | H42: -250.754 | I42: -190.743 | J42: -186.6 | K42: -289.5 | L42: -289.5 | M42: -248.7 | N42: -283.7 | O42: =SUM(BC42:BF42) -> -289 | Q42: -33.794 | R42: =F42-Q42 -> -74.754 | S42: -27.659 | T42: =G42-S42 -> -10.242 | U42: -44.935 | V42: =H42-U42 -> -205.819 | W42: -119.82 | X42: =I42-W42 -> -70.923 | Y42: =-112.5 -> -112.5 | Z42: =K42-Y42 -> -177 | AA42: -128.7 | AB42: =M42-AA42 -> -120 | AC42: -143.9 | AD42: =N42-AC42 -> -139.8 | AF42: =-45.585-Q42 -> -11.791 | AG42: =F42-AF42-Q42 -> -62.963 | AH42: -16.153 | AI42: =S42-AH42 -> -11.506 | AJ42: =-44.513-S42 -> -16.854 | AK42: =G42-AJ42-S42 -> 6.612 | AL42: -22.636 | AM42: =U42-AL42 -> -22.299 | AN42: =-76.296-U42 -> -31.361 | AO42: =H42-AN42-U42 -> -174.458 | AP42: -14.793 | AQ42: =W42-AP42 -> -105.027 | AR42: =-145.669-W42 -> -25.849 | AS42: =I42-AR42-W42 -> -45.074 | AT42: -53.992 | AU42: =Y42-AT42 -> -58.508 | AV42: =-175.5-Y42 -> -63 | AW42: =K42-AV42-Y42 -> -114 | AX42: -54.7 | AY42: =AA42-AX42 -> -74 | AZ42: =-177.8-AA42 -> -49.1 | BA42: =M42-AZ42-AA42 -> -70.9 | BB42: -45.1 | BC42: =AC42-BB42 -> -98.8 | BD42: =-198.4-AC42 -> -54.5 | BE42: =N42-AC42-BD42 -> -85.3 | BF42: -50.4
B43: Net profit/loss | C43: =C40+C42 -> 310.797 | D43: =D40+D42 -> 349.819 | E43: =E40+E42 -> 362.883 | F43: =F40+F42 -> 392.161 | G43: =G40+G42 -> 252.524 | H43: =H40+H42 -> 1025.936 | I43: =I40+I42 -> 796.525 | J43: =J40+J42 -> 764.33 | ... O43: =O40+O42 -> 1098.4 | Q43: =Q40+Q42 -> 140.253 | R43: =R40+R42 -> 251.908 | S43: =S40+S42 -> 99.283 | T43: =T40+T42 -> 153.241 | U43: =U40+U42 -> 188.279 | V43: =V40+V42 -> 837.657 | W43: =W40+W42 -> 490.222 | X43: =X40+X42 -> 306.303 | ... AD43: =AD40+AD42 -> 456.1 | AF43: =AF40+AF42 -> 22.724 | AG43: =AG40+AG42 -> 229.184 | AH43: =AH40+AH42 -> 57.767 | AI43: =AI40+AI42 -> 41.516 | AJ43: =AJ40+AJ42 -> 61.783 | AK43: =AK40+AK42 -> 91.458 | AL43: =AL40+AL42 -> 98.486 | AM43: =AM40+AM42 -> 89.793 | ... BF43: =BF40+BF42 -> 212.6
...

Sheet KPIs
B2: CTP Group | C2: Annual | D2: Annual | E2: Annual | F2: Annual | G2: Annual | H2: Annual | I2: Annual | J2: Annual | K2: Annual | L2: Annual | M2: LTM | O2: Half Yearly | P2: Half Yearly | Q2: Half Yearly | R2: Half Yearly | S2: Half Yearly | T2: Half Yearly | U2: Half Yearly | V2: Half Yearly | W2: Half Yearly | X2: Half Yearly | Y2: Half Yearly | Z2: Half Yearly | AA2: Half Yearly | AB2: Half Yearly | AD2: Quaterly | AE2: Quaterly | AF2: Quaterly | AG2: Quaterly | AH2: Quaterly | AI2: Quaterly | AJ2: Quaterly | AK2: Quaterly | AL2: Quaterly | AM2: Quaterly | AN2: Quaterly | AO2: Quaterly | AP2: Quaterly | AQ2: Quaterly | AR2: Quaterly | AS2: Quaterly | AT2: Quaterly | AU2: Quaterly | AV2: Quaterly | AW2: Quaterly | AX2: Quaterly | AY2: Quaterly | AZ2: Quaterly | BA2: Quaterly | BB2: Quaterly | BC2: Quaterly | BD2: Quaterly
B3: (EUR millions) | C3: 42735 | D3: 43100 | E3: 43465 | F3: 43830 | G3: 44196 | H3: 44561 | I3: 44926 | J3: 45291 | K3: 45657 | L3: 46022 | M3: =BD3 -> 46111 | O3: 43646 | P3: 43829 | Q3: 44012 | R3: 44195 | S3: 44377 | T3: 44560 | U3: 44742 | V3: 44925 | W3: 45107 | X3: 45290 | Y3: 45473 | Z3: 45656 | AA3: 45838 | AB3: 46021 | AD3: 43738 | AE3: 43830 | AF3: 43920 | AG3: 44012 | AH3: 44104 | AI3: 44196 | AJ3: 44285 | AK3: 44377 | AL3: 44469 | AM3: 44561 | AN3: 44650 | AO3: 44742 | AP3: 44834 | AQ3: 44926 | AR3: 45015 | AS3: 45107 | AT3: 45199 | AU3: 45291 | AV3: 45381 | AW3: 45473 | AX3: 45565 | AY3: 45657 | AZ3: 45746 | BA3: 45838 | BB3: 45930 | BC3: 46022 | BD3: 46111
C4: Act | D4: Act | E4: Act | F4: Act | G4: Act | H4: Act | I4: Act | J4: Act | K4: Act | L4: Act | M4: Act | O4: Act | P4: Act | Q4: Act | R4: Act | S4: Act | T4: Act | U4: Act | V4: Act | W4: Act | X4: Act | Y4: Act | Z4: Act | AA4: Act | AB4: Act | AD4: Act | AE4: Act | AF4: Act | AG4: Act | AH4: Act | AI4: Act | AJ4: Act | AK4: Act | AL4: Act | AM4: Act | AN4: Act | AO4: Act | AP4: Act | AQ4: Act | AR4: Act | AS4: Act | AT4: Act | AU4: Act | AV4: Act | AW4: Act | AX4: Act | AY4: Act | AZ4: Act | BA4: Act | BB4: Act | BC4: Act | BD4: Act
C5: FY | D5: FY | E5: FY | F5: FY | G5: FY | H5: FY | I5: FY | J5: FY | K5: FY | L5: FY | M5: LTM | O5: 1H19 | P5: 2H19 | Q5: 1H20 | R5: 2H20 | S5: 1H21 | T5: 2H21 | U5: 1H22 | V5: 2H22 | W5: 1H23 | X5: 2H23 | Y5: 1H24 | Z5: 2H24 | AA5: 1H25 | AB5: 2H25 | AD5: 3Q19 | AE5: 4Q19 | AF5: 1Q20 | AG5: 2Q20 | AH5: 3Q20 | AI5: 4Q20 | AJ5: 1Q21 | AK5: 2Q21 | AL5: 3Q21 | AM5: 4Q21 | AN5: 1Q22 | AO5: 2Q22 | AP5: 3Q22 | AQ5: 4Q22 | AR5: 1Q23 | AS5: 2Q23 | AT5: 3Q23 | AU5: 4Q23 | AV5: 1Q24 | AW5: 2Q23 | AX5: 3Q24 | AY5: 4Q24 | AZ5: 1Q25 | BA5: 2Q24 | BB5: 3Q25 | BC5: 4Q25 | BD5: 1Q26
B8: Net rental Income by segment
B9: Czech Republic | E9: 170.029 | F9: 164.654 | G9: 183.356 | H9: 199.473 | I9: 215.536 | J9: 247.1 | K9: 273.3 | L9: 288.5 | O9: 78.898 | P9: =+F9-O9 -> 85.756 | Q9: 89.906 | R9: =+G9-Q9 -> 93.45 | S9: 100.465 | T9: =+H9-S9 -> 99.008 | U9: 102.726 | V9: =+I9-U9 -> 112.81 | W9: 133.9 | X9: =+J9-W9 -> 113.2 | Y9: 136.2 | Z9: =+K9-Y9 -> 137.1 | AA9: 142.5 | AB9: =+L9-AA9 -> 146 | AF9: =0.68*66.814 -> 45.43352 | AG9: =Q9-AF9 -> 44.47248 | AJ9: =0.64*78.087 -> 49.97568 | AK9: =S9-AJ9 -> 50.48932 | AL9: =(0.61*239.869)-S9 -> 45.85509 | AM9: =H9-AL9-AK9-AJ9 -> 53.15291
B10: Romania | E10: 33.31 | F10: 36.416 | G10: 47.338 | H10: 61.769 | I10: 85.73 | J10: 101.1 | K10: 121.7 | L10: 142.7 | O10: 16.231 | P10: =+F10-O10 -> 20.185 | Q10: 23.512 | R10: =+G10-Q10 -> 23.826 | S10: 30.482 | T10: =+H10-S10 -> 31.287 | U10: 40.488 | V10: =+I10-U10 -> 45.242 | W10: 48.5 | X10: =+J10-W10 -> 52.6 | Y10: 58.1 | Z10: =+K10-Y10 -> 63.6 | AA10: 69.3 | AB10: =+L10-AA10 -> 73.4 | AF10: =0.16*66.814 -> 10.69024 | AG10: =Q10-AF10 -> 12.82176 | AJ10: =0.19*78.087 -> 14.83653 | AK10: =S10-AJ10 -> 15.64547 | AL10: =(0.19*239.869)-S10 -> 15.09311 | AM10: =H10-AL10-AK10-AJ10 -> 16.19389
B11: Hungary | E11: 7.307 | F11: 17.93 | G11: 22.292 | H11: 29.043 | I11: 48.228 | J11: 56.7 | K11: 61.8 | L11: 78.1 | O11: 7.402 | P11: =+F11-O11 -> 10.528 | Q11: 9.766 | R11: =+G11-Q11 -> 12.526 | S11: 11.782 | T11: =+H11-S11 -> 17.261 | U11: 22.825 | V11: =+I11-U11 -> 25.403 | W11: 29 | X11: =+J11-W11 -> 27.7 | Y11: 30.8 | Z11: =+K11-Y11 -> 31 | AA11: 39 | AB11: =+L11-AA11 -> 39.1 | AF11: =0.06*66.814 -> 4.00884 | AG11: =Q11-AF11 -> 5.75716 | AJ11: =0.07*78.087 -> 5.46609 | AK11: =S11-AJ11 -> 6.31591 | AL11: =(0.09*239.869)-S11 -> 9.80621 | AM11: =H11-AL11-AK11-AJ11 -> 7.45479
B12: Slovakia | H12: 24.383 | I12: 36.351 | J12: 42.5 | K12: 53.5 | L12: 66.4 | S12: 12.764 | T12: =+H12-S12 -> 11.619 | U12: 17.216 | V12: =+I12-U12 -> 19.135 | W12: 20.4 | X12: =+J12-W12 -> 22.1 | Y12: 25.7 | Z12: =+K12-Y12 -> 27.8 | AA12: 32.5 | AB12: =+L12-AA12 -> 33.9 | AK12: =S12-AJ12 -> 12.764 | AL12: =(0.08*239.869)-S12 -> 6.42552 | AM12: =H12-AL12-AK12-AJ12 -> 5.19348
B13: Netherland, Germany and Poland | E13: 21.505 | F13: 20.79 | G13: =21.376+6.644-0.337 -> 27.683 | H13: =11.84+0.659-0.115 -> 12.384 | I13: =22.041+41.919+2.761 -> 66.721 | J13: =32.2+6.5+57.9 -> 96.6 | K13: =7.7+70.7+11.6 -> 90 | L13: =8.8+60.3+31.7 -> 100.8 | O13: 10.032 | P13: =+F13-O13 -> 10.758 | Q13: 13.306 | R13: =+G13-Q13 -> 14.377 | S13: 4.91 | T13: =+H13-S13 -> 7.474 | U13: =7.307+1.035+20.102 -> 28.444 | V13: =+I13-U13 -> 38.277 | W13: =3.7+28.1+14.2-9.5 -> 36.5 | X13: =+J13-W13 -> 60.1 | Y13: =4+34.2+3.5+21.4 -> 63.1 | Z13: =+K13-Y13 -> 26.9 | AA13: =4.2+29.7+13.1+30 -> 77 | AB13: =+L13-AA13 -> 23.8 | AF13: =0.1*66.814 -> 6.6814 | AG13: =Q13-AF13 -> 6.6246 | AJ13: =0.1*78.087 -> 7.8087 | AK13: =S13-AJ13 -> -2.8987 | AL13: =(0.03*239.869)-S13 -> 2.28607 | AM13: =H13-AL13-AK13-AJ13 -> 5.18793
B14: Others | H14: -0.199 | I14: -0.432 | J14: -0.8 | K14: 46.6 | L14: 61.4 | S14: -0.096 | T14: =+H14-S14 -> -0.103 | U14: -0.194 | V14: =+I14-U14 -> -0.238 | W14: 2.6 | X14: =+J14-W14 -> -3.4 | Y14: 5.2 | Z14: =+K14-Y14 -> 41.4 | AA14: 0 | AB14: =+L14-AA14 -> 61.4 | AK14: =S14-AJ14 -> -0.096 | AM14: =H14-AL14-AK14-AJ14 -> -0.103
B15: Total | C15: =+SUM(C9:C13) -> 0 | D15: =+SUM(D9:D13) -> 0 | E15: =+SUM(E9:E13) -> 232.151 | F15: =+SUM(F9:F13) -> 239.79 | G15: =+SUM(G9:G13) -> 280.669 | H15: =+SUM(H9:H14) -> 326.853 | I15: =+SUM(I9:I14) -> 452.134 | J15: =+SUM(J9:J14) -> 543.2 | K15: =+SUM(K9:K14) -> 646.9 | L15: =+SUM(L9:L14) -> 737.9 | O15: =+SUM(O9:O13) -> 112.563 | P15: =+SUM(P9:P13) -> 127.227 | Q15: =+SUM(Q9:Q13) -> 136.49 | R15: =+SUM(R9:R13) -> 144.179 | S15: =+SUM(S9:S14) -> 160.307 | T15: =+SUM(T9:T14) -> 166.546 | U15: =+SUM(U9:U14) -> 211.505 | V15: =+SUM(V9:V14) -> 240.629 | W15: =+SUM(W9:W14) -> 270.9 | X15: =+SUM(X9:X14) -> 272.3 | Y15: =+SUM(Y9:Y14) -> 319.1 | Z15: =+SUM(Z9:Z14) -> 327.8 | ... AB15: =+SUM(AB9:AB14) -> 377.6 | AF15: =+SUM(AF9:AF13) -> 66.814 | AG15: =+SUM(AG9:AG13) -> 69.676 | AJ15: =+SUM(AJ9:AJ13) -> 78.087 | AK15: =+SUM(AK9:AK13) -> 82.316 | AL15: =+SUM(AL9:AL13) -> 79.466 | AM15: =SUM(AM9:AM14) -> 87.08
B16: check | E16: =+E15-Model!E10 -> 0 | F16: =+F15-Model!F10 -> 0 | G16: =+G15-Model!G10 -> 0 | H16: =+H15-Model!H10 -> 0 | I16: =+I15-Model!J10 -> 0 | J16: =+J15-Model!K10 -> 0 | K16: =+K15-Model!M10 -> 0.1 | L16: =+L15-Model!N10 -> -0.1 | M16: =+M15-Model!O10 -> -758.3 | O16: =+O15-Model!Q10 -> 0 | P16: =+P15-Model!R10 -> 0 | Q16: =+Q15-Model!S10 -> 0 | R16: =+R15-Model!T10 -> 0 | S16: =+S15-Model!U10 -> 0 | T16: =+T15-Model!V10 -> 0 | U16: =+U15-Model!W10 -> 0 | V16: =+V15-Model!X10 -> 0 | W16: =+W15-Model!Y10 -> 1.1 | Y16: =+Y15-Model!AA10 -> 3.4 | Z16: =+Z15-Model!AB10 -> -3.3 | AA16: =+AA15-Model!AC10 -> -0.1 | AB16: =+AB15-Model!AD10 -> 0 | AF16: =+AF15-Model!AH10 -> -0.001 | AG16: =+AG15-Model!AI10 -> 0.001 | AJ16: =+AJ15-Model!AL10 -> -0.001 | AK16: =+AK15-Model!AM10 -> 0.097 | AL16: =+AL15-Model!AN10 -> -0.096 | AM16: =+AM15-Model!AO10 -> 0.096
B18: Revenue (% Share)
B19: Czech Republic | E19: =+E9/E$15 -> 0.73240692 | F19: =+F9/F$15 -> 0.68665916 | G19: =+G9/G$15 -> 0.65328198 | H19: =+H9/H$15 -> 0.61028352 | I19: =+I9/I$15 -> 0.47670823 | J19: =+J9/J$15 -> 0.45489691 | K19: =+K9/K$15 -> 0.42247643 | L19: =+L9/L$15 -> 0.39097439 | M19: =+M9/M$15 -> #DIV/0! | O19: =+O9/O$15 -> 0.70092304 | P19: =+P9/P$15 -> 0.67403932 | Q19: =+Q9/Q$15 -> 0.65870027 | R19: =+R9/R$15 -> 0.64815264 | S19: =+S9/S$15 -> 0.62670376 | T19: =+T9/T$15 -> 0.5944784 | U19: =+U9/U$15 -> 0.48569065 | V19: =+V9/V$15 -> 0.46881299 | ... AB19: =+AB9/AB$15 -> 0.38665254 | AF19: =+AF9/AF$15 -> 0.68 | AG19: =+AG9/AG$15 -> 0.63827545 | AJ19: =+AJ9/AJ$15 -> 0.64 | AK19: =+AK9/AK$15 -> 0.61335974 | AL19: =+AL9/AL$15 -> 0.57704037 | AM19: =+AM9/AM$15 -> 0.61039171
B20: Romania | E20: =+E10/E$15 -> 0.1434842 | F20: =+F10/F$15 -> 0.15186622 | G20: =+G10/G$15 -> 0.16866131 | H20: =+H10/H$15 -> 0.18898098 | I20: =+I10/I$15 -> 0.18961193 | J20: =+J10/J$15 -> 0.18611929 | K20: =+K10/K$15 -> 0.188128 | L20: =+L10/L$15 -> 0.19338664 | M20: =+M10/M$15 -> #DIV/0! | O20: =+O10/O$15 -> 0.14419481 | P20: =+P10/P$15 -> 0.15865343 | Q20: =+Q10/Q$15 -> 0.1722617 | R20: =+R10/R$15 -> 0.16525291 | S20: =+S10/S$15 -> 0.19014765 | T20: =+T10/T$15 -> 0.18785801 | U20: =+U10/U$15 -> 0.1914281 | V20: =+V10/V$15 -> 0.18801558 | ... AB20: =+AB10/AB$15 -> 0.19438559 | AF20: =+AF10/AF$15 -> 0.16 | AG20: =+AG10/AG$15 -> 0.18401975 | AJ20: =+AJ10/AJ$15 -> 0.19 | AK20: =+AK10/AK$15 -> 0.19006597 | AL20: =+AL10/AL$15 -> 0.18993167 | AM20: =+AM10/AM$15 -> 0.18596566
B21: Hungary | E21: =+E11/E$15 -> 0.031475204 | F21: =+F11/F$15 -> 0.07477376 | G21: =+G11/G$15 -> 0.079424518 | H21: =+H11/H$15 -> 0.088856458 | I21: =+I11/I$15 -> 0.10666749 | J21: =+J11/J$15 -> 0.10438144 | K21: =+K11/K$15 -> 0.09553254 | L21: =+L11/L$15 -> 0.1058409 | M21: =+M11/M$15 -> #DIV/0! | O21: =+O11/O$15 -> 0.065758731 | P21: =+P11/P$15 -> 0.082749731 | Q21: =+Q11/Q$15 -> 0.071551029 | R21: =+R11/R$15 -> 0.086878117 | S21: =+S11/S$15 -> 0.073496479 | T21: =+T11/T$15 -> 0.10364104 | U21: =+U11/U$15 -> 0.10791707 | V21: =+V11/V$15 -> 0.10556915 | ... AB21: =+AB11/AB$15 -> 0.10354873 | AF21: =+AF11/AF$15 -> 0.06 | AG21: =+AG11/AG$15 -> 0.082627591 | AJ21: =+AJ11/AJ$15 -> 0.07 | AK21: =+AK11/AK$15 -> 0.076727611 | AL21: =+AL11/AL$15 -> 0.12340133 | AM21: =+AM11/AM$15 -> 0.085608521
B22: Slovakia | H22: =+H12/H$15 -> 0.074599285 | I22: =+I12/I$15 -> 0.080398731 | J22: =+J12/J$15 -> 0.078240059 | K22: =+K12/K$15 -> 0.082702118 | L22: =+L12/L$15 -> 0.089985093 | M22: =+M12/M$15 -> #DIV/0! | S22: =+S12/S$15 -> 0.079622225 | T22: =+T12/T$15 -> 0.06976451 | U22: =+U12/U$15 -> 0.081397603 | V22: =+V12/V$15 -> 0.079520756 | W22: =+W12/W$15 -> 0.07530454 | X22: =+X12/X$15 -> 0.081160485 | Y22: =+Y12/Y$15 -> 0.080539016 | Z22: =+Z12/Z$15 -> 0.08480781 | ... AB22: =+AB12/AB$15 -> 0.089777542 | AK22: =+AK12/AK$15 -> 0.15506098 | AL22: =+AL12/AL$15 -> 0.080858732 | AM22: =+AM12/AM$15 -> 0.059640331
B23: Netherland, Germany and Poland | E23: =+E13/E$15 -> 0.092633674 | F23: =+F13/F$15 -> 0.086700863 | G23: =+G13/G$15 -> 0.098632197 | H23: =+H13/H$15 -> 0.037888592 | I23: =+I13/I$15 -> 0.14756908 | J23: =+J13/J$15 -> 0.17783505 | K23: =+K13/K$15 -> 0.13912506 | L23: =+L13/L$15 -> 0.13660388 | M23: =+M13/M$15 -> #DIV/0! | O23: =+O13/O$15 -> 0.089123424 | P23: =+P13/P$15 -> 0.084557523 | Q23: =+Q13/Q$15 -> 0.097486995 | R23: =+R13/R$15 -> 0.099716325 | S23: =+S13/S$15 -> 0.030628731 | T23: =+T13/T$15 -> 0.044876491 | U23: =+U13/U$15 -> 0.13448382 | V23: =+V13/V$15 -> 0.1590706 | ... AB23: =+AB13/AB$15 -> 0.063029661 | AF23: =+AF13/AF$15 -> 0.1 | AG23: =+AG13/AG$15 -> 0.095077215 | AJ23: =+AJ13/AJ$15 -> 0.1 | AK23: =+AK13/AK$15 -> -0.035214296 | AL23: =+AL13/AL$15 -> 0.028767901 | AM23: =+AM13/AM$15 -> 0.059576596
B24: Others | H24: =+H14/H$15 -> -0.00060883639 | I24: =+I14/I$15 -> -0.00095546895 | J24: =+J14/J$15 -> -0.0014727541 | K24: =+K14/K$15 -> 0.072035863 | L24: =+L14/L$15 -> 0.083209107 | M24: =+M14/M$15 -> #DIV/0! | S24: =+S14/S$15 -> -0.00059885095 | T24: =+T14/T$15 -> -0.00061844776 | U24: =+U14/U$15 -> -0.000917236 | V24: =+V14/V$15 -> -0.00098907447 | W24: =+W14/W$15 -> 0.0095976375 | X24: =+X14/X$15 -> -0.012486228 | Y24: =+Y14/Y$15 -> 0.016295832 | Z24: =+Z14/Z$15 -> 0.12629652 | ... AB24: =+AB14/AB$15 -> 0.16260593 | AK24: =+AK14/AK$15 -> -0.0011662374 | AL24: =+AL14/AL$15 -> 0 | AM24: =+AM14/AM$15 -> -0.0011828204
B25: Total | E25: =+SUM(E19:E23) -> 1 | F25: =+SUM(F19:F23) -> 1 | G25: =+SUM(G19:G23) -> 1 | H25: =+SUM(H19:H24) -> 1 | I25: =+SUM(I19:I24) -> 1 | J25: =+SUM(J19:J24) -> 1 | K25: =+SUM(K19:K24) -> 1 | L25: =+SUM(L19:L24) -> 1 | M25: =+SUM(M19:M24) -> #DIV/0! | O25: =+SUM(O19:O23) -> 1 | P25: =+SUM(P19:P23) -> 1 | Q25: =+SUM(Q19:Q23) -> 1 | R25: =+SUM(R19:R23) -> 1 | S25: =+SUM(S19:S24) -> 1 | T25: =+SUM(T19:T24) -> 1 | U25: =+SUM(U19:U24) -> 1 | V25: =+SUM(V19:V24) -> 1 | W25: =+SUM(W19:W24) -> 1 | X25: =+SUM(X19:X24) -> 1 | Y25: =+SUM(Y19:Y24) -> 1 | Z25: =+SUM(Z19:Z24) -> 1 | ... AB25: =+SUM(AB19:AB24) -> 1 | AF25: =+SUM(AF19:AF23) -> 1 | AG25: =+SUM(AG19:AG23) -> 1 | AJ25: =+SUM(AJ19:AJ23) -> 1 | AK25: =+SUM(AK19:AK24) -> 0.99883376 | AL25: =+SUM(AL19:AL24) -> 1 | AM25: =+SUM(AM19:AM24) -> 1
B27: Revenue (YoY % Growth)
B28: Czech Republic | F28: =F9/E9-1 -> -0.031612254 | G28: =G9/F9-1 -> 0.11358364 | H28: =H9/G9-1 -> 0.087900041 | I28: =I9/H9-1 -> 0.080527189 | J28: =J9/I9-1 -> 0.14644421 | K28: =K9/J9-1 -> 0.10602995 | L28: =L9/K9-1 -> 0.055616539 | Q28: =Q9/O9-1 -> 0.13952191 | R28: =R9/P9-1 -> 0.08971967 | S28: =S9/Q9-1 -> 0.11744489 | T28: =T9/R9-1 -> 0.059475655 | U28: =U9/S9-1 -> 0.02250535 | V28: =V9/T9-1 -> 0.13940288 | W28: =W9/U9-1 -> 0.30346748 | X28: =X9/V9-1 -> 0.0034571403 | ... AB28: =AB9/Z9-1 -> 0.06491612
B29: Romania | F29: =F10/E10-1 -> 0.093245272 | G29: =G10/F10-1 -> 0.29992311 | H29: =H10/G10-1 -> 0.30485023 | I29: =I10/H10-1 -> 0.38791303 | J29: =J10/I10-1 -> 0.1792838 | K29: =K10/J10-1 -> 0.20375865 | L29: =L10/K10-1 -> 0.17255546 | Q29: =Q10/O10-1 -> 0.44858604 | R29: =R10/P10-1 -> 0.18038147 | S29: =S10/Q10-1 -> 0.29644437 | T29: =T10/R10-1 -> 0.3131453 | U29: =U10/S10-1 -> 0.3282593 | V29: =V10/T10-1 -> 0.4460319 | W29: =W10/U10-1 -> 0.19788579 | X29: =X10/V10-1 -> 0.16263649 | ... AB29: =AB10/Z10-1 -> 0.15408805
B30: Hungary | F30: =F11/E11-1 -> 1.4538114 | G30: =G11/F11-1 -> 0.24327942 | H30: =H11/G11-1 -> 0.30284407 | I30: =I11/H11-1 -> 0.66057225 | J30: =J11/I11-1 -> 0.17566559 | K30: =K11/J11-1 -> 0.08994709 | L30: =L11/K11-1 -> 0.26375405 | Q30: =Q11/O11-1 -> 0.31937314 | R30: =R11/P11-1 -> 0.18977964 | S30: =S11/Q11-1 -> 0.20643047 | T30: =T11/R11-1 -> 0.37801373 | U30: =U11/S11-1 -> 0.9372772 | V30: =V11/T11-1 -> 0.47169921 | W30: =W11/U11-1 -> 0.27053669 | X30: =X11/V11-1 -> 0.090422391 | ... AB30: =AB11/Z11-1 -> 0.26129032
B31: Slovakia | F31: =F12/E12-1 -> #DIV/0! | G31: =G12/F12-1 -> #DIV/0! | H31: =H12/G12-1 -> #DIV/0! | I31: =I12/H12-1 -> 0.49083378 | J31: =J12/I12-1 -> 0.16915628 | K31: =K12/J12-1 -> 0.25882353 | L31: =L12/K12-1 -> 0.2411215 | Q31: =Q12/O12-1 -> #DIV/0! | R31: =R12/P12-1 -> #DIV/0! | S31: =S12/Q12-1 -> #DIV/0! | T31: =T12/R12-1 -> #DIV/0! | U31: =U12/S12-1 -> 0.34879348 | V31: =V12/T12-1 -> 0.6468715 | W31: =W12/U12-1 -> 0.18494424 | X31: =X12/V12-1 -> 0.15495166 | ... AB31: =AB12/Z12-1 -> 0.21942446
B32: Netherland, Germany and Poland | F32: =F13/E13-1 -> -0.033248082 | G32: =G13/F13-1 -> 0.33155363 | H32: =H13/G13-1 -> -0.55264964 | I32: =I13/H13-1 -> 4.3876776 | J32: =J13/I13-1 -> 0.44782003 | K32: =K13/J13-1 -> -0.068322981 | L32: =L13/K13-1 -> 0.12 | Q32: =Q13/O13-1 -> 0.32635566 | R32: =R13/P13-1 -> 0.33640082 | S32: =S13/Q13-1 -> -0.63099354 | T32: =T13/R13-1 -> -0.48014189 | U32: =U13/S13-1 -> 4.7930754 | V32: =V13/T13-1 -> 4.121354 | W32: =W13/U13-1 -> 0.28322318 | X32: =X13/V13-1 -> 0.5701335 | ... AB32: =AB13/Z13-1 -> -0.11524164
B33: Others | F33: =F14/E14-1 -> #DIV/0! | G33: =G14/F14-1 -> #DIV/0! | H33: =H14/G14-1 -> #DIV/0! | I33: =I14/H14-1 -> 1.1708543 | J33: =J14/I14-1 -> 0.85185185 | K33: =K14/J14-1 -> -59.25 | L33: =L14/K14-1 -> 0.31759657 | Q33: =Q14/O14-1 -> #DIV/0! | R33: =R14/P14-1 -> #DIV/0! | S33: =S14/Q14-1 -> #DIV/0! | T33: =T14/R14-1 -> #DIV/0! | U33: =U14/S14-1 -> 1.0208333 | V33: =V14/T14-1 -> 1.3106796 | W33: =W14/U14-1 -> -14.402062 | X33: =X14/V14-1 -> 13.285714 | ... AB33: =AB14/Z14-1 -> 0.48309179
B34: Total | F34: =F15/E15-1 -> 0.032905307 | G34: =G15/F15-1 -> 0.17047834 | H34: =H15/G15-1 -> 0.1645497 | I34: =I15/H15-1 -> 0.38329463 | J34: =J15/I15-1 -> 0.20141374 | K34: =K15/J15-1 -> 0.19090574 | L34: =L15/K15-1 -> 0.14067089 | Q34: =Q15/O15-1 -> 0.21256541 | R34: =R15/P15-1 -> 0.13324216 | S34: =S15/Q15-1 -> 0.1744963 | T34: =T15/R15-1 -> 0.15513355 | U34: =U15/S15-1 -> 0.3193747 | V34: =V15/T15-1 -> 0.44482005 | W34: =W15/U15-1 -> 0.28082078 | X34: =X15/V15-1 -> 0.13161755 | ... AB34: =AB15/Z15-1 -> 0.1519219
B37: Net valuation result on IP
B38: Czech Republic | E38: 153.382 | F38: 257.983 | G38: 62.577 | H38: 733.943 | I38: 394.372 | J38: 260.2 | K38: 340.7 | L38: 297.6 | O38: 69.839 | P38: =+F38-O38 -> 188.144 | Q38: -6.35 | R38: =+G38-Q38 -> 68.927 | S38: 74.964 | T38: =+H38-S38 -> 658.979 | U38: 341.868 | V38: =+I38-U38 -> 52.504 | W38: 120.5 | X38: =+J38-W38 -> 139.7 | Y38: 224.8 | Z38: =+K38-Y38 -> 115.9 | AA38: 166.8 | AB38: =+L38-AA38 -> 130.8
B39: Romania | E39: 40.41 | F39: 67.064 | G39: 22.681 | H39: 110.458 | I39: 67.238 | J39: 149.6 | K39: 207.8 | L39: 226.3 | O39: 46.687 | P39: =+F39-O39 -> 20.377 | Q39: 20.721 | R39: =+G39-Q39 -> 1.96 | S39: 13.324 | T39: =+H39-S39 -> 97.134 | U39: 44.768 | V39: =+I39-U39 -> 22.47 | W39: 106.5 | X39: =+J39-W39 -> 43.1 | Y39: 99.8 | Z39: =+K39-Y39 -> 108 | AA39: 68.9 | AB39: =+L39-AA39 -> 157.4
B40: Hungary | E40: 20.498 | F40: 48.525 | G40: 53.092 | H40: 123.31 | I40: 46.434 | J40: 3.4 | K40: 69.9 | L40: 53.6 | O40: 22.415 | P40: =+F40-O40 -> 26.11 | Q40: 19.417 | R40: =+G40-Q40 -> 33.675 | S40: 41.654 | T40: =+H40-S40 -> 81.656 | U40: 33.285 | V40: =+I40-U40 -> 13.149 | W40: 18.6 | X40: =+J40-W40 -> -15.2 | Y40: 4.7 | Z40: =+K40-Y40 -> 65.2 | AA40: 30.5 | AB40: =+L40-AA40 -> 23.1
B41: Slovakia | H41: 100.271 | I41: 18.412 | J41: 105.3 | K41: 116.8 | L41: 124.6 | S41: 11.622 | T41: =+H41-S41 -> 88.649 | U41: 43.336 | V41: =+I41-U41 -> -24.924 | W41: 44.9 | X41: =+J41-W41 -> 60.4 | Y41: 13.5 | Z41: =+K41-Y41 -> 103.3 | AA41: 54.3 | AB41: =+L41-AA41 -> 70.3
B42: Netherland, Germany and Poland | E42: 23.728 | F42: =27.106+6.097 -> 33.203 | G42: =5.037+8.775 -> 13.812 | H42: =43.835-8.36-2.886 -> 32.589 | I42: =186.05+14.761-29.97 -> 170.841 | J42: =17.8+123.4+219 -> 360.2 | K42: =-4+121.8+57.3+31.2 -> 206.3 | L42: =-0.9+242.8+92.8+103.1 -> 437.8 | O42: 6.302 | P42: =+F42-O42 -> 26.901 | Q42: -3.828 | R42: =+G42-Q42 -> 17.64 | S42: 4.179 | T42: =+H42-S42 -> 28.41 | U42: =22.09-39.269+52.938 -> 35.759 | V42: =+I42-U42 -> 135.082 | W42: =9.7+22.2+94.8 -> 126.7 | X42: =+J42-W42 -> 233.5 | Y42: =-6.6+37.1+55.4+7.9 -> 93.8 | Z42: =+K42-Y42 -> 112.5 | AA42: =-3.2+182+42.1+56.6 -> 277.5 | AB42: =+L42-AA42 -> 160.3
B43: Others | H43: 0 | I43: 0 | J43: 0 | K43: 0 | L43: 0 | S43: 0 | T43: =+H43-S43 -> 0 | U43: 0 | V43: =+I43-U43 -> 0 | X43: =+J43-W43 -> 0 | Z43: =+K43-Y43 -> 0 | AB43: =+L43-AA43 -> 0
B44: Total | C44: =+SUM(C38:C42) -> 0 | D44: =+SUM(D38:D42) -> 0 | E44: =+SUM(E38:E42) -> 238.018 | F44: =+SUM(F38:F42) -> 406.775 | G44: =+SUM(G38:G42) -> 152.162 | H44: =+SUM(H38:H43) -> 1100.571 | I44: =+SUM(I38:I43) -> 697.297 | J44: =+SUM(J38:J43) -> 878.7 | K44: =+SUM(K38:K43) -> 941.5 | L44: =+SUM(L38:L43) -> 1139.9 | M44: =+SUM(M38:M43) -> 0 | O44: =+SUM(O38:O42) -> 145.243 | P44: =+SUM(P38:P42) -> 261.532 | Q44: =+SUM(Q38:Q42) -> 29.96 | R44: =+SUM(R38:R42) -> 122.202 | S44: =+SUM(S38:S43) -> 145.743 | T44: =+SUM(T38:T43) -> 954.828 | U44: =+SUM(U38:U43) -> 499.016 | V44: =+SUM(V38:V43) -> 198.281 | W44: =+SUM(W38:W43) -> 417.2 | X44: =+SUM(X38:X43) -> 461.5 | Y44: =+SUM(Y38:Y43) -> 436.6 | Z44: =+SUM(Z38:Z43) -> 504.9 | ... AB44: =+SUM(AB38:AB43) -> 541.9
