Workbook
Name IQ_CH: 110000
Name IQ_CQ: 5000
Name IQ_CY: 10000
Name IQ_DAILY: 500000
Name IQ_FH: 100000
Name IQ_FQ: 500
Name IQ_FY: 1000
Name IQ_LTM: 2000
Name IQ_MONTH: 15000
Name IQ_NTM: 6000
Name IQ_WEEK: 50000
Name IQ_YTD: 3000

Sheet Capitalization
A2: 2Q26
J3: Exchange rate as at end | K3: =[1]Sheet1!$A$201 -> 60.295
J4: LTM Average exchange rate | K4: =AVERAGE(Model!$AS$200:$AU$200) -> 58.079667
B6: Debt Breakdown as on 30-Jun-2026 | C6: Php (in million) | D6: USD (mn) | E6: Leverage (PHP) | F6: Leverage (USD) | J6: =B6 -> Debt Breakdown as on 30-Jun-2026 | K6: =C6 -> Php (in million) | L6: =D6 -> USD (mn) | M6: =E6 -> Leverage (PHP) | N6: =F6 -> Leverage (USD)
A7: =SUM(C8:C10)/C17 -> 0.56260655 | B7: Term Loans: | J7: Total debt (company reported) | K7: 261670 | L7: =K7/K3 -> 4339.8292
B8: Peso | C8: 202864.66 | D8: =C8/$K3 -> 3364.5354 | J8: Perpetuals | K8: =C18 -> 35702.8 | L8: =K8/K3 -> 592.13533
B9: Dollar | C9: 14854.689 | D9: =C9/$K3 -> 246.36685 | J9: Total Debt (including perpetuals) | K9: =K7+K8 -> 297372.8 | L9: =L7+L8 -> 4931.9645 | M9: =K9/K12 -> 13.099351 | N9: =L9/L12 -> 13.099351
B10: Yen | C10: 7434.15 | D10: =C10/$K3 -> 123.29629 | J10: Cash and Short-Term Investments | K10: =C20 -> 19700.518 | L10: =K10/K3 -> 326.73552
A11: =SUM(C12:C13)/C17 -> 0.091246512 | B11: Retail bonds | J11: Net debt | K11: =K9-K10 -> 277672.28 | L11: =L9-L10 -> 4605.229 | M11: =K11/K12 -> 12.231538 | N11: =L11/L12 -> 12.231538
B12: Peso | C12: 0 | D12: =C12/$K3 -> 0 | J12: LTM Adjusted EBITDA | K12: =C24 -> 22701.339 | L12: =K12/K3 -> 376.5045
B13: Dollar | C13: 36516.588 | D13: =C13/$K3 -> 605.63211
B14: Total Debt (excluding lease liabilities) | C14: =+C8+C9+C12+C13+C10 -> 261670.09 | D14: =+D8+D9+D12+D13 -> 4216.5344
A15: =SUM(C15:C16)/C17 -> 0.34614693 | B15: Current portion of lease liabilities | C15: 8335.832 | D15: =C15/$K3 -> 138.2508 | J15: Company reported
B16: Non-current portion of lease liabilities | C16: 130191.16 | D16: =C16/$K3 -> 2159.2364 | J16: Gross debt to EBITDA | K16: 2.68
B17: Total Debt (including lease liabilities) | C17: =C14+C15+C16 -> 400197.08 | D17: =D14+D15+D16 -> 6514.0216 | J17: Net debt to EBITDA | K17: 2.48
B18: Perpetuals | C18: =[1]Sheet1!A$119 -> 35702.8 | D18: =C18/$K3 -> 592.13533
B19: Total debt (including perpetuals & lease liabilities) | C19: =C17+C18 -> 435899.88 | D19: =D17+D18 -> 7106.1569 | E19: =C19/C24 -> 19.201505 | F19: =D19/D24 -> 18.180567
B20: Cash and Short-Term Investments | C20: =[1]Sheet1!A$122 -> 19700.518 | D20: =C20/$K3 -> 326.73552
B21: Net debt | C21: =C19-C20 -> 416199.36 | D21: =D19-D20 -> 6779.4214 | E21: =C21/C24 -> 18.333692 | F21: =D21/D24 -> 17.344639
B22: Equity | C22: =[1]Sheet1!A$127 -> 177784.86 | D22: =C22/$K3 -> 2948.5839
B23: Total Capitalisation | C23: =C21+C22 -> 593984.23 | D23: =C23/$K3 -> 9851.3016
B24: LTM Adjusted EBITDA | C24: =[1]Sheet1!A$87 -> 22701.339 | D24: =C24/$K4 -> 390.86552
B25: check | C25: =C19-[1]Sheet1!A$120 -> 0
B28: Liquidity Table at end-2Q26 | C28: =C6 -> Php (in million) | D28: =D6 -> USD (mn)
B29: Cash on hand and in banks | C29: 5014.411 | D29: =C29/$K$3 -> 83.164624
B30: Short-term money market placements | C30: 14686.107 | D30: =C30/$K$3 -> 243.57089
B31: Total | C31: =SUM(C29:C30) -> 19700.518 | D31: =SUM(D29:D30) -> 326.73552
B32: check | C32: =C31-C20 -> 0
B35: Globe’s short term credit facilities at end-2Q26 | C35: =C6 -> Php (in million) | D35: =D6 -> USD (mn)
B36: Uncommitted credit facilty
B37: Peso | C37: 85249 | D37: =C37/$K3 -> 1413.8652
B38: Dollar | C38: =+D38*$K3 -> 1205.9 | D38: 20
B39: Committed
B40: Peso | C40: 3000 | D40: =C40/$K3 -> 49.755369
B41: Dollar | C41: =+D41*$K3 -> 3014.75 | D41: 50
B42: Cash and Short-Term Investments | C42: =C31 -> 19700.518 | D42: =C42/$K3 -> 326.73552
B43: Total Liquidity | C43: =+C37+C38+C41+C42 -> 109170.17 | D43: =+D37+D38+D41+D42 -> 1810.6007
B46: Debt maturity 2Q26 | C46: =C6 -> Php (in million) | D46: =D6 -> USD (mn)
B47: 2026 | C47: 20238.5 | D47: =C47/$K3 -> 335.65801
B48: 2027 | C48: 24226.6 | D48: =C48/$K3 -> 401.80114
...

Sheet Model
B2: Globe Telecom Philippines | C2: Annual | D2: Annual | E2: Annual | F2: Annual | G2: Annual | H2: Annual | I2: Annual | J2: Annual | K2: Annual | L2: Annual | O2: Quarter | P2: Quarter | Q2: Quarter | R2: Quarter | S2: Quarter | T2: Quarter | U2: Quarter | V2: Quarter | W2: Quarter | X2: Quarter | Y2: Quarter | Z2: Quarter | AA2: Quarter | AB2: Quarter | AC2: Quarter | AD2: Quarter | AE2: Quarter | AF2: Quarter | AG2: Quarter | AH2: Quarter | AI2: Quarter | AJ2: Quarter | AK2: Quarter | AL2: Quarter | AM2: Quarter | AN2: Quarter | AO2: Quarter | AP2: Quarter | AQ2: Quarter | AR2: Quarter | AS2: Quarter | AT2: Quarter | AU2: Quarter
B3: (PHP millions) | C3: 42735 | D3: 43100 | E3: 43465 | F3: 43830 | G3: 44196 | H3: 44561 | I3: 44926 | J3: 45291 | K3: 45657 | L3: 46022 | O3: 43190 | P3: 43281 | Q3: 43373 | R3: 43465 | S3: 43555 | T3: 43646 | U3: 43738 | V3: 43830 | W3: 43921 | X3: 44012 | Y3: 44104 | Z3: 44196 | AA3: 44286 | AB3: 44377 | AC3: 44469 | AD3: 44561 | AE3: 44651 | AF3: 44742 | AG3: 44834 | AH3: 44926 | AI3: 45016 | AJ3: 45107 | AK3: 45199 | AL3: 45291 | AM3: 45382 | AN3: 45473 | AO3: 45565 | AP3: 45657 | AQ3: 45747 | AR3: 45838 | AS3: 45930 | AT3: 46022 | AU3: 46112
C4: Act | D4: Act | E4: Act | F4: Act | G4: Act | H4: Act | I4: Act | J4: Act | K4: Act | L4: Act | O4: Act | P4: Act | Q4: Act | R4: Act | S4: Act | T4: Act | U4: Act | V4: Act | W4: Act | X4: Act | Y4: Act | Z4: Act | AA4: Act | AB4: Act | AC4: Act | AD4: Act | AE4: Act | AF4: Act | AG4: Act | AH4: Act | AI4: Act | AJ4: Act | AK4: Act | AL4: Act | AM4: Act | AN4: Act | AO4: Act | AP4: Act | AQ4: Act | AR4: Act | AS4: Act | AT4: Act | AU4: Act
C5: FY 16 | D5: FY 17 | E5: FY 18 | F5: FY 19 | G5: FY 20 | H5: FY 21 | I5: FY 22 | J5: FY 23 | K5: FY 24 | L5: FY 25 | O5: Q1 18 | P5: Q2 18 | Q5: Q3 18 | R5: Q4 18 | S5: Q1 19 | T5: Q2 19 | U5: Q3 19 | V5: Q4 19 | W5: Q1 20 | X5: Q2 20 | Y5: Q3 20 | Z5: Q4 20 | AA5: Q1 21 | AB5: Q2 21 | AC5: Q3 21 | AD5: Q4 21 | AE5: Q1 22 | AF5: Q2 22 | AG5: Q3 22 | AH5: Q4 22 | AI5: Q1 23 | AJ5: Q2 23 | AK5: Q3 23 | AL5: Q4 23 | AM5: Q1 24 | AN5: Q2 24 | AO5: Q3 24 | AP5: Q4 24 | AQ5: Q1 25 | AR5: Q2 24 | AS5: Q3 24 | AT5: Q4 25 | AU5: Q1 26
B6: INCOME STATEMENT
B7: Service revenues | C7: 120588 | D7: 127905.85 | E7: 132875.31 | F7: 149009.96 | G7: 146388.13 | H7: 152262.83 | I7: 157979.33 | J7: =162333.484 -> 162333.48 | K7: 165016.29 | L7: 165077.66 | O7: 31942.191 | P7: 32803.989 | Q7: 33197.531 | R7: =E7-Q7-P7-O7 -> 34931.599 | S7: 36003.039 | T7: 36875.674 | U7: 37736.247 | V7: =F7-U7-T7-S7 -> 38395.003 | W7: 36881.974 | X7: 35540.807 | Y7: 36681.453 | Z7: =G7-Y7-X7-W7 -> 37283.9 | AA7: 37813.235 | AB7: 37849.072 | AC7: 38433.322 | AD7: =H7-AC7-AB7-AA7 -> 38167.204 | AE7: 39155.08 | AF7: 39725.035 | AG7: 39075.122 | AH7: =I7-AG7-AF7-AE7 -> 40024.098 | AI7: 39981.702 | AJ7: 40419.291 | AK7: 40661.107 | AL7: =J7-AK7-AJ7-AI7 -> 41271.384 | AM7: 41148.386 | AN7: 41077.304 | AO7: 41783.727 | AP7: =K7-AO7-AN7-AM7 -> 41006.872 | AQ7: 39853.267 | AR7: =80188.239-AQ7 -> 40334.972 | AS7: 41488.212 | AT7: =L7-AS7-AR7-AQ7 -> 43401.207 | AU7: 41964.725
B8: % growth | D8: =D7/C7-1 -> 0.060684727 | E8: =E7/D7-1 -> 0.03885246 | F8: =F7/E7-1 -> 0.12142702 | G8: =G7/F7-1 -> -0.017594991 | H8: =H7/G7-1 -> 0.040130978 | I8: =I7/H7-1 -> 0.037543647 | J8: =J7/I7-1 -> 0.02756151 | K8: =K7/J7-1 -> 0.016526504 | L8: =L7/K7-1 -> 0.00037189662 | S8: =S7/O7-1 -> 0.12713117 | T8: =T7/P7-1 -> 0.12412164 | U8: =U7/Q7-1 -> 0.13671848 | V8: =V7/R7-1 -> 0.099148167 | W8: =W7/S7-1 -> 0.0244128 | X8: =X7/T7-1 -> -0.036199121 | Y8: =Y7/U7-1 -> -0.027951746 | Z8: =Z7/V7-1 -> -0.02893874 | ... AU8: =AU7/AQ7-1 -> 0.052980801
B9: Non-service revenues | C9: 6193.657 | D9: 7374.878 | E9: 18297.496 | F9: 17650.374 | G9: 14131.408 | H9: 16233.625 | I9: 17061.388 | J9: 17830.971 | K9: 15569.771 | L9: 13162.186 | O9: 4995.435 | P9: 4704.35 | Q9: 3959.257 | R9: =E9-Q9-P9-O9 -> 4638.454 | S9: 4633.028 | T9: 4009.277 | U9: 4160.65 | V9: =F9-U9-T9-S9 -> 4847.419 | W9: 4309.378 | X9: 2081.971 | Y9: 4097.424 | Z9: =G9-Y9-X9-W9 -> 3642.635 | AA9: 5033.852 | AB9: 3713.592 | AC9: 3310.988 | AD9: =H9-AC9-AB9-AA9 -> 4175.193 | AE9: 4401.796 | AF9: 4039.956 | AG9: 3800.15 | AH9: =I9-AG9-AF9-AE9 -> 4819.486 | AI9: 5048.606 | AJ9: 4074.679 | AK9: 3607.018 | AL9: =J9-AK9-AJ9-AI9 -> 5100.668 | AM9: 4159.236 | AN9: 3240.327 | AO9: 3335.212 | AP9: =K9-AO9-AN9-AM9 -> 4834.996 | AQ9: 3902.414 | AR9: =7037.464-AQ9 -> 3135.05 | AS9: 2876.52 | AT9: =L9-AS9-AR9-AQ9 -> 3248.202 | AU9: 3741.727
B10: Total revenue | C10: =C7+C9 -> 126781.66 | D10: =D7+D9 -> 135280.73 | E10: =E7+E9 -> 151172.81 | F10: =F7+F9 -> 166660.34 | G10: =G7+G9 -> 160519.54 | H10: =H7+H9 -> 168496.46 | I10: =I7+I9 -> 175040.72 | J10: =J7+J9 -> 180164.45 | ... L10: =L7+L9 -> 178239.84 | O10: =O7+O9 -> 36937.626 | P10: =P7+P9 -> 37508.339 | Q10: =Q7+Q9 -> 37156.788 | R10: =R7+R9 -> 39570.053 | S10: =S7+S9 -> 40636.067 | T10: =T7+T9 -> 40884.951 | U10: =U7+U9 -> 41896.897 | V10: =V7+V9 -> 43242.422 | ... AU10: =AU7+AU9 -> 45706.452
B11: % growth | D11: =D10/C10-1 -> 0.06703707 | E11: =E10/D10-1 -> 0.11747479 | F11: =F10/E10-1 -> 0.10244919 | G11: =G10/F10-1 -> -0.036846169 | H11: =H10/G10-1 -> 0.049694361 | I11: =I10/H10-1 -> 0.038839184 | J11: =J10/I10-1 -> 0.029271657 | K11: =K10/J10-1 -> 0.002340112 | L11: =L10/K10-1 -> -0.012992232 | S11: =S10/O10-1 -> 0.10012666 | T11: =T10/P10-1 -> 0.090022968 | U11: =U10/Q10-1 -> 0.12757047 | V11: =V10/R10-1 -> 0.092806775 | W11: =W10/S10-1 -> 0.013664831 | X11: =X10/T10-1 -> -0.079789089 | Y11: =Y10/U10-1 -> -0.026685031 | Z11: =Z10/V10-1 -> -0.053555904 | ... AU11: =AU10/AQ10-1 -> 0.044583262
B12: Equity in net losses of associates and joint ventures | C12: -855.198 | D12: -846.177 | E12: -1249.603 | F12: -2554.782 | G12: -2367.44 | H12: 881.535 | I12: 1083.202 | J12: 2214.761 | K12: 3897.012 | L12: 6392.043 | O12: -263.842 | P12: -259.013 | Q12: -383.395 | R12: =E12-Q12-P12-O12 -> -343.353 | S12: -516.798 | T12: -730.719 | U12: -622.099 | V12: =F12-U12-T12-S12 -> -685.166 | W12: -708.21 | X12: -514.086 | Y12: -425.918 | Z12: =G12-Y12-X12-W12 -> -719.226 | AA12: 660.512 | AB12: -6.75 | AC12: 135.618 | AD12: =H12-AC12-AB12-AA12 -> 92.155 | AE12: 377.394 | AF12: 315.962 | AG12: 190.047 | AH12: =I12-AG12-AF12-AE12 -> 199.799 | AI12: 303.596 | AJ12: 573.703 | AK12: 636.607 | AL12: =J12-AK12-AJ12-AI12 -> 700.855 | AM12: 1215.928 | AN12: 1226.21 | AO12: 1221.621 | AP12: =K12-AO12-AN12-AM12 -> 233.253 | AQ12: 1816.376 | AR12: =3851.558-AQ12 -> 2035.182 | AS12: 1530.854 | AT12: =L12-AS12-AR12-AQ12 -> 1009.631 | AU12: 1950.344
B13: Gain on sale of controlling interest on data center business | F13: 0 | G13: 0 | H13: 0 | I13: 10511.945 | J13: 0 | K13: 0 | L13: 0 | AA13: 0 | AB13: 0 | AC13: 0 | AD13: =H13-AC13-AB13-AA13 -> 0 | AE13: 10511.945 | AF13: 0 | AG13: 0 | AH13: =I13-AG13-AF13-AE13 -> 0 | AI13: 0 | AJ13: 0 | AK13: 0 | AL13: =J13-AK13-AJ13-AI13 -> 0 | AM13: 0 | AN13: 0 | AO13: 0 | AP13: =K13-AO13-AN13-AM13 -> 0 | AQ13: 0 | AR13: =0-AQ13 -> 0 | AS13: 0 | AT13: =L13-AS13-AR13-AQ13 -> 0 | AU13: 0
B14: Gain on sale and leaseback of telecom towers - net | F14: 0 | G14: 0 | H14: 0 | I14: 8260.927 | J14: 7258.378 | K14: 3482.083 | L14: 380.717 | AA14: 0 | AB14: 0 | AC14: 0 | AD14: =H14-AC14-AB14-AA14 -> 0 | AE14: 0 | AF14: 0 | AG14: 1868.707 | AH14: =I14-AG14-AF14-AE14 -> 6392.22 | AI14: 2852.897 | AJ14: 2979.72 | AK14: 188.858 | AL14: =J14-AK14-AJ14-AI14 -> 1236.903 | AM14: 1315.171 | AN14: 2172.044 | AO14: 140.596 | AP14: =K14-AO14-AN14-AM14 -> -145.728 | AQ14: 300.166 | AR14: =300.583-AQ14 -> 0.417 | AS14: 80.134 | AT14: =L14-AS14-AR14-AQ14 -> 0 | AU14: 0
B15: Interest income | C15: 151.589 | D15: 139.581 | E15: 391.03 | F15: 500.437 | G15: 194.938 | H15: 149.508 | I15: 340.109 | J15: 677.57 | K15: 918.338 | L15: 821.815 | O15: 56.262 | P15: 84.428 | Q15: 82.239 | R15: =E15-Q15-P15-O15 -> 168.101 | S15: 195.676 | T15: 143.895 | U15: 96.995 | V15: =F15-U15-T15-S15 -> 63.871 | W15: 73.329 | X15: 89.663 | Y15: 10.036 | Z15: =G15-Y15-X15-W15 -> 21.91 | AA15: 15.448 | AB15: 33.381 | AC15: 46.848 | AD15: =H15-AC15-AB15-AA15 -> 53.831 | AE15: 49.42 | AF15: 46.478 | AG15: 71.375 | AH15: =I15-AG15-AF15-AE15 -> 172.836 | AI15: 112.774 | AJ15: 171.778 | AK15: 182.324 | AL15: =J15-AK15-AJ15-AI15 -> 210.694 | AM15: 202.125 | AN15: 167.351 | AO15: 256.258 | AP15: =K15-AO15-AN15-AM15 -> 292.604 | AQ15: 166.624 | AR15: =325.205-AQ15 -> 158.581 | AS15: 217.16 | AT15: =L15-AS15-AR15-AQ15 -> 279.45 | AU15: 208.695
B16: Gain on disposal of property and equipment – net | C16: 101.232 | D16: 38.455 | E16: 73.088 | F16: 43.012 | G16: 33.244 | H16: 152.565 | I16: 321.354 | J16: 371.655 | K16: 206.5 | L16: 283.559 | O16: 9.806 | P16: 10.502 | Q16: 47.774 | R16: =E16-Q16-P16-O16 -> 5.006 | S16: 17.351 | T16: 5.92 | U16: 16.62 | V16: =F16-U16-T16-S16 -> 3.121 | W16: 42.064 | X16: 8.427 | Y16: -0.08 | Z16: =G16-Y16-X16-W16 -> -17.167 | AA16: 53.19 | AB16: 32.934 | AC16: 23.922 | AD16: =H16-AC16-AB16-AA16 -> 42.519 | AE16: 10.751 | AF16: 101.382 | AG16: 73.562 | AH16: =I16-AG16-AF16-AE16 -> 135.659 | AI16: 34.901 | AJ16: 167.707 | AK16: 88.755 | AL16: =J16-AK16-AJ16-AI16 -> 80.292 | AM16: 141.217 | AN16: 264.084 | AO16: -163.993 | AP16: =K16-AO16-AN16-AM16 -> -34.808 | AQ16: 32.769 | AR16: =33.773-AQ16 -> 1.004 | AS16: 96.911 | AT16: =L16-AS16-AR16-AQ16 -> 152.875 | AU16: 15.329
B17: Other income – net | C17: 983.186 | D17: =1889.901+701.653 -> 2591.554 | E17: 695.405 | F17: 1047.007 | G17: 3817.211 | H17: 4656.647 | I17: 2474.814 | J17: 959.898 | K17: 1734.944 | L17: 3870.814 | O17: 947.901 | P17: 223.995 | Q17: 230.162 | R17: =E17-Q17-P17-O17 -> -706.653 | S17: 124.404 | T17: 172.925 | U17: 369.572 | V17: =F17-U17-T17-S17 -> 380.106 | W17: 396.263 | X17: 1105.173 | Y17: -29.766 | Z17: =G17-Y17-X17-W17 -> 2345.541 | AA17: 15.273 | AB17: 47.586 | AC17: -54.266 | AD17: =H17-AC17-AB17-AA17 -> 4648.054 | AE17: =10731.97-AE13 -> 220.025 | AF17: 481.528 | AG17: 1116.062 | AH17: =I17-AG17-AF17-AE17 -> 657.199 | AI17: 79.701 | AJ17: 221.229 | AK17: -16.262 | AL17: =J17-AK17-AJ17-AI17 -> 675.23 | AM17: 194.023 | AN17: 530.68 | AO17: 501.046 | AP17: =K17-AO17-AN17-AM17 -> 509.195 | AQ17: 2727.091 | AR17: =2850.649-AQ17 -> 123.558 | AS17: 365.146 | AT17: =L17-AS17-AR17-AQ17 -> 655.019 | AU17: 1079.458
B18: Cost of inventories sold | C18: -11914.114 | D18: -13013.437 | E18: -18645.314 | F18: -18554.814 | G18: -16406.196 | H18: =-17307.774 -> -17307.774 | I18: -17691.677 | J18: -18217.044 | K18: -16428.713 | L18: =-13487.058 -> -13487.058 | O18: -4745.987 | P18: -4665.072 | Q18: -4222.212 | R18: =E18-Q18-P18-O18 -> -5012.043 | S18: -4615.626 | T18: -4497.012 | U18: -4142.913 | V18: =F18-U18-T18-S18 -> -5299.263 | W18: -4530.397 | X18: -2449.531 | Y18: -5167.546 | Z18: =G18-Y18-X18-W18 -> -4258.722 | AA18: -5457.519 | AB18: -4100.946 | AC18: -3661.397 | AD18: =H18-AC18-AB18-AA18 -> -4087.912 | AE18: -4735.168 | AF18: -4164.008 | AG18: -3973.387 | AH18: =I18-AG18-AF18-AE18 -> -4819.114 | AI18: -5353.226 | AJ18: -4199.18 | AK18: -3778.17 | AL18: =J18-AK18-AJ18-AI18 -> -4886.468 | AM18: -4166.309 | AN18: -3486.354 | AO18: -3856.457 | AP18: =K18-AO18-AN18-AM18 -> -4919.593 | AQ18: -3921.606 | AR18: =-7118.954-AQ18 -> -3197.348 | AS18: -2973.152 | AT18: =L18-AS18-AR18-AQ18 -> -3394.952 | AU18: -3858.726
B19: General, selling and administrative expenses | C19: -52471.053 | D19: -56608.922 | E19: -57742.131 | F19: -64471.409 | G19: -64913.355 | H19: -71366.092 | I19: -74227.306 | J19: -74681.05 | K19: -72836.753 | L19: -72207.939 | O19: -13429.954 | P19: -13056.455 | Q19: -13988.066 | R19: =E19-Q19-P19-O19 -> -17267.656 | S19: -14295.58 | T19: -15568.88 | U19: -16742.046 | V19: =F19-U19-T19-S19 -> -17864.903 | W19: -15178.125 | X19: -14771.669 | Y19: -16515.615 | Z19: =G19-Y19-X19-W19 -> -18447.946 | AA19: -17377.103 | AB19: -17392.453 | AC19: -17301.232 | AD19: =H19-AC19-AB19-AA19 -> -19295.304 | AE19: -17787.777 | AF19: -17557.402 | AG19: -18064.688 | AH19: =I19-AG19-AF19-AE19 -> -20817.439 | AI19: -17605.23 | AJ19: -19001.16 | AK19: -18859.526 | AL19: =J19-AK19-AJ19-AI19 -> -19215.134 | AM19: -18407.255 | AN19: -18104.775 | AO19: -18743.558 | AP19: =K19-AO19-AN19-AM19 -> -17581.165 | AQ19: -17579.632 | AR19: =-35262.304-AQ19 -> -17682.672 | AS19: -18130.298 | AT19: =L19-AS19-AR19-AQ19 -> -18815.337 | AU19: -18532.047
B20: Interconnect costs | C20: -9623.127 | D20: -7852.336 | E20: -5677.375 | F20: -3982.873 | G20: -1007.234 | H20: -1182.381 | I20: -1362.309 | J20: -1367.052 | K20: -1619.788 | L20: -1911.763 | O20: -1800.006 | P20: -1711.156 | Q20: -1435.963 | R20: =E20-Q20-P20-O20 -> -730.25 | S20: -806.821 | T20: -944.464 | U20: -1064.175 | V20: =F20-U20-T20-S20 -> -1167.413 | W20: -303.573 | X20: -241.851 | Y20: -274.817 | Z20: =G20-Y20-X20-W20 -> -186.993 | AA20: -284.058 | AB20: -290.496 | AC20: -271.367 | AD20: =H20-AC20-AB20-AA20 -> -336.46 | AE20: -323.916 | AF20: -320.193 | AG20: -308.656 | AH20: =I20-AG20-AF20-AE20 -> -409.544 | AI20: -360.992 | AJ20: -343.597 | AK20: -308.478 | AL20: =J20-AK20-AJ20-AI20 -> -353.985 | AM20: -363.299 | AN20: -407.952 | AO20: -415.507 | AP20: =K20-AO20-AN20-AM20 -> -433.03 | AQ20: -441.894 | AR20: =-850.558-AQ20 -> -408.664 | AS20: -522.68 | AT20: =L20-AS20-AR20-AQ20 -> -538.525 | AU20: -508.791
B21: Depreciation and amortisation | C21: -23848.646 | D21: -27512.689 | E21: -30421.721 | F21: -34143.541 | G21: -35412.038 | H21: -41132.992 | I21: -45653.296 | J21: -47356.043 | K21: -50473.04 | L21: -53871.127 | O21: -7285.383 | P21: -7287.645 | Q21: -7741.981 | R21: =E21-Q21-P21-O21 -> -8106.712 | S21: -7995.932 | T21: -8457.483 | U21: -8545.086 | V21: =F21-U21-T21-S21 -> -9145.04 | W21: -8639.488 | X21: -8881.131 | Y21: -9057.167 | Z21: =G21-Y21-X21-W21 -> -8834.252 | AA21: -9173.234 | AB21: -9375.231 | AC21: -10652.961 | AD21: =H21-AC21-AB21-AA21 -> -11931.566 | AE21: -11049.426 | AF21: -11253.333 | AG21: -10991.014 | AH21: =I21-AG21-AF21-AE21 -> -12359.523 | AI21: -11154.876 | AJ21: -11735.062 | AK21: -11604.508 | AL21: =J21-AK21-AJ21-AI21 -> -12861.597 | AM21: -12299.948 | AN21: -12460.789 | AO21: -12540.699 | AP21: =K21-AO21-AN21-AM21 -> -13171.604 | AQ21: -13441.415 | AR21: =-26429.849-AQ21 -> -12988.434 | AS21: -13551.984 | AT21: =L21-AS21-AR21-AQ21 -> -13889.294 | AU21: -14360.804
B22: Impairment and other losses | C22: -3271.301 | D22: -5423.366 | E22: -4787.644 | F22: -4913.137 | G22: -10207.599 | H22: -5566.939 | I22: -4906.747 | J22: -5463.979 | K22: -4691.29 | L22: -3827.345 | O22: -1011.67 | P22: -1655.97 | Q22: -1160.599 | R22: =E22-Q22-P22-O22 -> -959.405 | S22: -1149.529 | T22: -1346.856 | U22: -1292.858 | V22: =F22-U22-T22-S22 -> -1123.894 | W22: -1051.101 | X22: -2844.799 | Y22: -1126.858 | Z22: =G22-Y22-X22-W22 -> -5184.841 | AA22: -1605.51 | AB22: -851.574 | AC22: -1100.286 | AD22: =H22-AC22-AB22-AA22 -> -2009.569 | AE22: -1480.383 | AF22: -1456.959 | AG22: -1423.111 | AH22: =I22-AG22-AF22-AE22 -> -546.294 | AI22: -1330.008 | AJ22: -1200.515 | AK22: -1160.954 | AL22: =J22-AK22-AJ22-AI22 -> -1772.502 | AM22: -1198.969 | AN22: -1035.493 | AO22: -730.566 | AP22: =K22-AO22-AN22-AM22 -> -1726.262 | AQ22: -1199.368 | AR22: =-2235.924-AQ22 -> -1036.556 | AS22: -901.66 | AT22: =L22-AS22-AR22-AQ22 -> -689.761 | AU22: -791.38
B23: Operating profit | C23: =C10+SUM(C12:C22) -> 26034.228 | D23: =D10+SUM(D12:D22) -> 26793.394 | E23: =E10+SUM(E12:E22) -> 33808.541 | F23: =F10+SUM(F12:F22) -> 39630.237 | G23: =G10+SUM(G12:G22) -> 34251.073 | H23: =H10+SUM(H12:H22) -> 37780.535 | I23: =I10+SUM(I12:I22) -> 54191.739 | J23: =J10+SUM(J12:J22) -> 44561.549 | ... L23: =L10+SUM(L12:L22) -> 44683.56 | O23: =O10+SUM(O12:O22) -> 9414.753 | P23: =P10+SUM(P12:P22) -> 9191.953 | Q23: =Q10+SUM(Q12:Q22) -> 8584.747 | R23: =R10+SUM(R12:R22) -> 6617.088 | S23: =S10+SUM(S12:S22) -> 11593.212 | T23: =T10+SUM(T12:T22) -> 9662.277 | U23: =U10+SUM(U12:U22) -> 9970.907 | V23: =V10+SUM(V12:V22) -> 8403.841 | ... AU23: =AU10+SUM(AU12:AU22) -> 10908.53
B24: % margin | C24: =C23/C10 -> 0.20534696 | D24: =D23/D10 -> 0.19805773 | E24: =E23/E10 -> 0.22364168 | F24: =F23/F10 -> 0.23779045 | G24: =G23/G10 -> 0.21337634 | H24: =H23/H10 -> 0.22422154 | I24: =I23/I10 -> 0.30959504 | J24: =J23/J10 -> 0.24733818 | ... L24: =L23/L10 -> 0.25069344 | O24: =O23/O10 -> 0.25488246 | P24: =P23/P10 -> 0.24506425 | Q24: =Q23/Q10 -> 0.23104115 | R24: =R23/R10 -> 0.16722464 | S24: =S23/S10 -> 0.28529365 | T24: =T23/T10 -> 0.23632845 | U24: =U23/U10 -> 0.23798677 | V24: =V23/V10 -> 0.19434251 | ... AU24: =AU23/AU10 -> 0.23866499
B25: Finance costs | C25: -4096.826 | D25: -5251.692 | E25: -6195.225 | F25: -6802.861 | G25: -7111.41 | H25: -8740.763 | I25: -10091.289 | J25: -12145.879 | K25: -14444.27 | L25: -16456.49 | O25: -2373.005 | P25: -1533.206 | Q25: -1550.943 | R25: =E25-Q25-P25-O25 -> -738.071 | S25: -1797.252 | T25: -1725.179 | U25: -1670.25 | V25: =F25-U25-T25-S25 -> -1610.18 | W25: -1655.9 | X25: -1690.463 | Y25: -1830.308 | Z25: =G25-Y25-X25-W25 -> -1934.739 | AA25: -1873.403 | AB25: -2026.395 | AC25: -2357.964 | AD25: =H25-AC25-AB25-AA25 -> -2483.001 | AE25: -2422.935 | AF25: -2161.804 | AG25: -2542.719 | AH25: =I25-AG25-AF25-AE25 -> -2963.831 | AI25: -2841.469 | AJ25: -2862.297 | AK25: -3156.529 | AL25: =J25-AK25-AJ25-AI25 -> -3285.584 | AM25: -3279.731 | AN25: -3437.259 | AO25: -3794.046 | AP25: =K25-AO25-AN25-AM25 -> -3933.234 | AQ25: -3956.892 | AR25: =-7959.65-AQ25 -> -4002.758 | AS25: -4145.716 | AT25: =L25-AS25-AR25-AQ25 -> -4351.124 | AU25: -4381.943
B26: Profit before tax | C26: =C23+C25 -> 21937.402 | D26: =D23+D25 -> 21541.702 | E26: =E23+E25 -> 27613.316 | F26: =F23+F25 -> 32827.376 | G26: =G23+G25 -> 27139.663 | H26: =H23+H25 -> 29039.772 | I26: =I23+I25 -> 44100.45 | J26: =J23+J25 -> 32415.67 | ... L26: =L23+L25 -> 28227.07 | O26: =O23+O25 -> 7041.748 | P26: =P23+P25 -> 7658.747 | Q26: =Q23+Q25 -> 7033.804 | R26: =R23+R25 -> 5879.017 | S26: =S23+S25 -> 9795.96 | T26: =T23+T25 -> 7937.098 | U26: =U23+U25 -> 8300.657 | V26: =V23+V25 -> 6793.661 | ... AU26: =AU23+AU25 -> 6526.587
B27: Current tax | C27: -5556.965 | D27: -6005.42 | E27: -7259.985 | F27: -8488.595 | G27: -8139.602 | H27: -4903.568 | I27: -9696.533 | J27: -7853.664 | K27: -6919.731 | L27: -5593.063 | O27: -1850.957 | P27: -1705.047 | Q27: -2054.897 | R27: =E27-Q27-P27-O27 -> -1649.084 | S27: -2062.55 | T27: -2100.331 | U27: -2486.62 | V27: =F27-U27-T27-S27 -> -1839.094 | W27: -2162.421 | X27: -2687.981 | Y27: -1807.762 | Z27: =G27-Y27-X27-W27 -> -1481.438 | AA27: -1036.841 | AB27: -1438.294 | AC27: -1606.394 | AD27: =H27-AC27-AB27-AA27 -> -822.039 | AE27: -2155.144 | AF27: -650.376 | AG27: -2121.041 | AH27: =I27-AG27-AF27-AE27 -> -4769.972 | AI27: -2393.583 | AJ27: -2897.977 | AK27: -1095.112 | AL27: =J27-AK27-AJ27-AI27 -> -1466.992 | AM27: -1804.15 | AN27: -2089.572 | AO27: -1002.599 | AP27: =K27-AO27-AN27-AM27 -> -2023.41 | AQ27: -857.727 | AR27: =-1873.471-AQ27 -> -1015.744 | AS27: -831.584 | AT27: =L27-AS27-AR27-AQ27 -> -2888.008 | AU27: -936.854
B28: Deferred tax | C28: -491.938 | D28: -452.069 | E28: -1727.388 | F28: -2055.024 | G28: -377.016 | H28: -412.347 | I28: 200.132 | J28: =16.004 -> 16.004 | K28: 874.417 | L28: 628.053 | O28: -511.025 | P28: -668.439 | Q28: -161.029 | R28: =E28-Q28-P28-O28 -> -386.895 | S28: -1003.628 | T28: -520.038 | U28: -176.775 | V28: =F28-U28-T28-S28 -> -354.583 | W28: -879.212 | X28: 155.644 | Y28: -159.719 | Z28: =G28-Y28-X28-W28 -> 506.271 | AA28: 552.668 | AB28: -492.631 | AC28: -24.115 | AD28: =H28-AC28-AB28-AA28 -> -448.269 | AE28: -1109.61 | AF28: -1126.932 | AG28: 47.736 | AH28: =I28-AG28-AF28-AE28 -> 2388.938 | AI28: -102.465 | AJ28: 734.58 | AK28: -396.358 | AL28: =J28-AK28-AJ28-AI28 -> -219.753 | AM28: -60.491 | AN28: 85.144 | AO28: 28.429 | AP28: =K28-AO28-AN28-AM28 -> 821.335 | AQ28: -424.809 | AR28: =-419.935-AQ28 -> 4.874 | AS28: -343.86 | AT28: =L28-AS28-AR28-AQ28 -> 1391.848 | AU28: -35.99
B29: Net profit/loss | C29: =C26+C28+C27 -> 15888.499 | D29: =D26+D28+D27 -> 15084.213 | E29: =E26+E28+E27 -> 18625.943 | F29: =F26+F28+F27 -> 22283.757 | G29: =G26+G28+G27 -> 18623.045 | H29: =H26+H28+H27 -> 23723.857 | I29: =I26+I28+I27 -> 34604.049 | J29: =J26+J28+J27 -> 24578.01 | ... L29: =L26+L28+L27 -> 23262.06 | O29: =O26+O28+O27 -> 4679.766 | P29: =P26+P28+P27 -> 5285.261 | Q29: =Q26+Q28+Q27 -> 4817.878 | R29: =R26+R28+R27 -> 3843.038 | S29: =S26+S28+S27 -> 6729.782 | T29: =T26+T28+T27 -> 5316.729 | U29: =U26+U28+U27 -> 5637.262 | V29: =V26+V28+V27 -> 4599.984 | ... AU29: =AU26+AU28+AU27 -> 5553.743
B30: % margin | C30: =C29/C10 -> 0.12532175 | D30: =D29/D10 -> 0.11150304 | E30: =E29/E10 -> 0.12320961 | F30: =F29/F10 -> 0.13370762 | G30: =G29/G10 -> 0.11601731 | H30: =H29/H10 -> 0.14079736 | I30: =I29/I10 -> 0.19769142 | J30: =J29/J10 -> 0.13641986 | ... L30: =L29/L10 -> 0.13050988 | O30: =O29/O10 -> 0.12669374 | P30: =P29/P10 -> 0.14090896 | Q30: =Q29/Q10 -> 0.12966347 | R30: =R29/R10 -> 0.09711986 | S30: =S29/S10 -> 0.16561106 | T30: =T29/T10 -> 0.13004122 | U30: =U29/U10 -> 0.13455082 | V30: =V29/V10 -> 0.10637665 | ... AU30: =AU29/AU10 -> 0.12150895
B32: Marginal tax rate | C32: =C27/C26 -> -0.25331008 | D32: =D27/D26 -> -0.27878113 | E32: =E27/E26 -> -0.26291609 | F32: =F27/F26 -> -0.25858281 | G32: =G27/G26 -> -0.29991537 | H32: =H27/H26 -> -0.16885697 | I32: =I27/I26 -> -0.21987379 | J32: =J27/J26 -> -0.24227986 | ... L32: =L27/L26 -> -0.19814536 | O32: =O27/O26 -> -0.26285476 | P32: =P27/P26 -> -0.22262741 | Q32: =Q27/Q26 -> -0.2921459 | R32: =R27/R26 -> -0.28050336 | S32: =S27/S26 -> -0.21055108 | T32: =T27/T26 -> -0.26462203 | U32: =U27/U26 -> -0.29956906 | V32: =V27/V26 -> -0.27070735 | ... AU32: =AU27/AU26 -> -0.14354424
B33: Defered tax rate | C33: =C28/C26 -> -0.022424624 | D33: =D28/D26 -> -0.020985761 | E33: =E28/E26 -> -0.062556341 | F33: =F28/F26 -> -0.062600922 | G33: =G28/G26 -> -0.013891698 | H33: =H28/H26 -> -0.014199388 | I33: =I28/I26 -> 0.0045380943 | J33: =J28/J26 -> 0.00049371184 | ... L33: =L28/L26 -> 0.022250025 | O33: =O28/O26 -> -0.072570759 | P33: =P28/P26 -> -0.087277854 | Q33: =Q28/Q26 -> -0.022893586 | R33: =R28/R26 -> -0.065809471 | S33: =S28/S26 -> -0.10245326 | T33: =T28/T26 -> -0.065519917 | U33: =U28/U26 -> -0.021296507 | V33: =V28/V26 -> -0.052193214 | ... AU33: =AU28/AU26 -> -0.0055143676
B35: As % of Net sales unless stated otherwise
B36: =B18 -> Cost of inventories sold | C36: =-C18/C7 -> 0.09880016 | D36: =-D18/D7 -> 0.10174231 | E36: =-E18/E7 -> 0.14032189 | F36: =-F18/F7 -> 0.12452063 | G36: =-G18/G7 -> 0.11207326 | H36: =-H18/H7 -> 0.11367038 | I36: =-I18/I7 -> 0.11198729 | J36: =-J18/J7 -> 0.11221988 | ... L36: =-L18/L7 -> 0.081701292 | O36: =-O18/O7 -> 0.14858051 | P36: =-P18/P7 -> 0.14221051 | Q36: =-Q18/Q7 -> 0.12718452 | R36: =-R18/R7 -> 0.14348164 | S36: =-S18/S7 -> 0.12820101 | T36: =-T18/T7 -> 0.12195064 | U36: =-U18/U7 -> 0.10978604 | V36: =-V18/V7 -> 0.1380196 | ... AU36: =-AU18/AU7 -> 0.091951657
B37: =B19 -> General, selling and administrative expenses | C37: =-C19/C7 -> 0.43512664 | D37: =-D19/D7 -> 0.44258273 | E37: =-E19/E7 -> 0.43455877 | F37: =-F19/F7 -> 0.43266509 | G37: =-G19/G7 -> 0.44343317 | H37: =-H19/H7 -> 0.4687033 | I37: =-I19/I7 -> 0.46985453 | J37: =-J19/J7 -> 0.46004711 | ... L37: =-L19/L7 -> 0.437418 | O37: =-O19/O7 -> 0.42044561 | P37: =-P19/P7 -> 0.39801425 | Q37: =-Q19/Q7 -> 0.42135862 | R37: =-R19/R7 -> 0.49432767 | S37: =-S19/S7 -> 0.39706593 | T37: =-T19/T7 -> 0.4221992 | U37: =-U19/U7 -> 0.44365954 | V37: =-V19/V7 -> 0.4652924 | ... AU37: =-AU19/AU7 -> 0.44161011
B38: =B20 -> Interconnect costs | C38: =-C20/C7 -> 0.079801695 | D38: =-D20/D7 -> 0.06139153 | E38: =-E20/E7 -> 0.042727088 | F38: =-F20/F7 -> 0.026728904 | G38: =-G20/G7 -> 0.0068805713 | H38: =-H20/H7 -> 0.0077653947 | I38: =-I20/I7 -> 0.0086233367 | J38: =-J20/J7 -> 0.0084212571 | ... L38: =-L20/L7 -> 0.011580992 | O38: =-O20/O7 -> 0.056351989 | P38: =-P20/P7 -> 0.052163046 | Q38: =-Q20/Q7 -> 0.043255114 | R38: =-R20/R7 -> 0.020905141 | S38: =-S20/S7 -> 0.022409803 | T38: =-T20/T7 -> 0.025612115 | U38: =-U20/U7 -> 0.02820034 | V38: =-V20/V7 -> 0.030405337 | ... AU38: =-AU20/AU7 -> 0.012124254
B39: =B23 -> Operating profit | C39: =C23/C7 -> 0.21589401 | D39: =D23/D7 -> 0.20947747 | E39: =E23/E7 -> 0.2544381 | F39: =F23/F7 -> 0.26595696 | G39: =G23/G7 -> 0.23397438 | H39: =H23/H7 -> 0.2481271 | I39: =I23/I7 -> 0.34303056 | J39: =J23/J7 -> 0.27450621 | ... L39: =L23/L7 -> 0.27068206 | O39: =O23/O7 -> 0.29474349 | P39: =P23/P7 -> 0.28020839 | Q39: =Q23/Q7 -> 0.25859595 | R39: =R23/R7 -> 0.18942986 | S39: =S23/S7 -> 0.32200648 | T39: =T23/T7 -> 0.26202306 | U39: =U23/U7 -> 0.26422625 | V39: =V23/V7 -> 0.21887851 | ... AU39: =AU23/AU7 -> 0.25994523
B40: PBT | C40: =C26/C7 -> 0.18192027 | D40: =D26/D7 -> 0.16841842 | E40: =E26/E7 -> 0.20781375 | F40: =F26/F7 -> 0.22030323 | G40: =G26/G7 -> 0.18539524 | H40: =H26/H7 -> 0.19072134 | I40: =I26/I7 -> 0.27915328 | J40: =J26/J7 -> 0.19968567 | ... L40: =L26/L7 -> 0.17099267 | O40: =O26/O7 -> 0.22045288 | P40: =P26/P7 -> 0.23346999 | Q40: =Q26/Q7 -> 0.21187732 | R40: =R26/R7 -> 0.16830083 | S40: =S26/S7 -> 0.27208703 | T40: =T26/T7 -> 0.2152394 | U40: =U26/U7 -> 0.21996509 | V40: =V26/V7 -> 0.17694128 | ... AU40: =AU26/AU7 -> 0.15552555
B41: Income Tax Expense as a % PBT | C41: =-(C28+C27)/C26 -> 0.2757347 | D41: =-(D28+D27)/D26 -> 0.29976689 | E41: =-(E28+E27)/E26 -> 0.32547243 | F41: =-(F28+F27)/F26 -> 0.32118373 | G41: =-(G28+G27)/G26 -> 0.31380707 | H41: =-(H28+H27)/H26 -> 0.18305636 | I41: =-(I28+I27)/I26 -> 0.21533569 | J41: =-(J28+J27)/J26 -> 0.24178615 | ... L41: =-(L28+L27)/L26 -> 0.17589534 | O41: =-(O28+O27)/O26 -> 0.33542552 | P41: =-(P28+P27)/P26 -> 0.30990526 | Q41: =-(Q28+Q27)/Q26 -> 0.31503949 | R41: =-(R28+R27)/R26 -> 0.34631283 | S41: =-(S28+S27)/S26 -> 0.31300434 | T41: =-(T28+T27)/T26 -> 0.33014195 | U41: =-(U28+U27)/U26 -> 0.32086557 | V41: =-(V28+V27)/V26 -> 0.32290057 | ... AU41: =-(AU28+AU27)/AU26 -> 0.14905861
B42: Finance costs as % of debt | C42: =-C25/C120 -> 0.040471036 | D42: =-D25/D120 -> 0.039928105 | E42: =-E25/E120 -> 0.04178005 | F42: =-F25/F120 -> 0.048756818 | G42: =-G25/G120 -> 0.042000611 | H42: =-H25/H120 -> 0.038014405 | I42: =-I25/I120 -> 0.03043887 | J42: =-J25/J120 -> 0.031714412 | ... L42: =-L25/L120 -> 0.038184639 | R42: =-SUM(O25:R25)/R120 -> 0.04178005 | S42: =-SUM(P25:S25)/S120 -> 0.039649674 | T42: =-SUM(Q25:T25)/T120 -> 0.042916506 | U42: =-SUM(R25:U25)/U120 -> 0.043841899 | V42: =-SUM(S25:V25)/V120 -> 0.048756818 | W42: =-SUM(T25:W25)/W120 -> 0.044854294 | X42: =-SUM(U25:X25)/X120 -> 0.042992165 | Y42: =-SUM(V25:Y25)/Y120 -> 0.040411863 | ... AU42: =-SUM(AR25:AU25)/AU120 -> 0.039027822
B43: Working capital/sales | C43: =C62/C10 -> -0.091285222 | D43: =D62/D10 -> -0.022931862 | E43: =E62/E10 -> -0.05209814 | F43: =F62/F10 -> -0.010603663 | G43: =G62/G10 -> -0.058039052 | H43: =H62/H10 -> -0.059711837 | I43: =I62/I10 -> -0.08333819 | J43: =J62/J10 -> -0.025916028 | ... L43: =L62/L10 -> -0.045282703 | R43: =R99/R84 -> -0.20315754 | S43: =S99/S84 -> -0.19512668 | T43: =T99/T84 -> -0.20456439 | U43: =U99/U84 -> -0.23055836 | V43: =V99/V84 -> -0.18676785 | W43: =W99/W84 -> -0.17499025 | X43: =X99/X84 -> -0.16964495 | Y43: =Y99/Y84 -> -0.20600656 | ... AU43: =AU99/AU84 -> -0.2951051
...

Sheet KPI
B2: Globe Telecom Philippines | C2: Annual | D2: Annual | E2: Annual | F2: Annual | G2: Annual | H2: Annual | I2: Annual | J2: Annual | K2: Annual | L2: Annual | M2: LTM | O2: Quarterly | P2: Quarterly | Q2: Quarterly | R2: Quarterly | S2: Quarterly | T2: Quarterly | U2: Quarterly | V2: Quarterly | W2: Quarterly | X2: Quarterly | Y2: Quarterly | Z2: Quarterly | AA2: Quarterly | AB2: Quarterly | AC2: Quarterly | AD2: Quarterly | AE2: Quarterly | AF2: Quarterly | AG2: Quarterly | AH2: Quarterly | AI2: Quarterly | AJ2: Quarterly | AK2: Quarterly | AL2: Quarterly | AM2: Quarterly | AN2: Quarterly | AO2: Quarterly | AP2: Quarterly | AQ2: Quarterly | AR2: Quarterly | AS2: Quarterly | AT2: Quarterly | AU2: Quarterly
B3: (PHP millions) | C3: 42735 | D3: =EDATE(C3,12) -> 43100 | E3: =EDATE(D3,12) -> 43465 | F3: =EDATE(E3,12) -> 43830 | G3: =EDATE(F3,12) -> 44196 | H3: =EDATE(G3,12) -> 44561 | I3: =EDATE(H3,12) -> 44926 | J3: =EDATE(I3,12) -> 45291 | K3: =EDATE(J3,12) -> 45657 | L3: =EDATE(K3,12) -> 46022 | M3: =AV3 -> 0 | O3: 43160 | P3: 43252 | Q3: 43344 | R3: 43435 | S3: 43525 | T3: 43617 | U3: 43709 | V3: 43800 | W3: 43891 | X3: 43983 | Y3: 44075 | Z3: 44166 | AA3: 44256 | AB3: 44348 | AC3: 44440 | AD3: 44531 | AE3: 44621 | AF3: 44713 | AG3: 44805 | AH3: 44896 | AI3: 44986 | AJ3: 45078 | AK3: 45170 | AL3: 45261 | AM3: 45352 | AN3: 45444 | AO3: 45536 | AP3: 45627 | AQ3: 45717 | AR3: 45809 | AS3: 45901 | AT3: 45992 | AU3: 46082
C4: Act | D4: Act | E4: Act | F4: Act | G4: Act | H4: Act | I4: Act | J4: Act | K4: Act | L4: Act | M4: Act | O4: Act | P4: Act | Q4: Act | R4: Act | S4: Act | T4: Act | U4: Act | V4: Act | W4: Act | X4: Act | Y4: Act | Z4: Act | AA4: Act | AB4: Act | AC4: Act | AD4: Act | AE4: Act | AF4: Act | AG4: Act | AH4: Act | AI4: Act | AJ4: Act | AK4: Act | AL4: Act | AM4: Act | AN4: Act | AO4: Act | AP4: Act | AQ4: Act | AR4: Act | AS4: Act | AT4: Act | AU4: Act
C5: FY | D5: FY | E5: FY | F5: FY | G5: FY | H5: FY | I5: FY | J5: FY | K5: FY | L5: FY | M5: LTM | O5: Q1 | P5: Q2 | Q5: Q3 | R5: Q4 | S5: Q1 | T5: Q2 | U5: Q3 | V5: Q4 | W5: Q1 | X5: Q2 | Y5: Q3 | Z5: Q4 | AA5: Q1 | AB5: Q2 | AC5: Q3 | AD5: Q4 | AE5: Q1 | AF5: Q2 | AG5: Q3 | AH5: Q4 | AI5: Q1 | AJ5: Q2 | AK5: Q3 | AL5: Q4 | AM5: Q1 | AN5: Q2 | AO5: Q3 | AP5: Q4 | AQ5: Q1 | AR5: Q2 | AS5: Q3 | AT5: Q4 | AU5: Q1
B8: Revenue by business segment
B9: Mobile Communications | C9: =+C11+C12+C13+C14+C15+C16 -> 97925.564 | D9: =+D11+D12+D13+D14+D15+D16 -> 105586.15 | E9: =+E11+E12+E13+E14+E15+E16 -> 117436.27 | F9: =+F11+F12+F13+F14+F15+F16 -> 129024.24 | G9: =+G11+G12+G13+G14+G15+G16 -> 115082.19 | H9: =+H11+H12+H13+H14+H15+H16 -> 119592.24 | I9: =+I11+I12+I13+I14+I15+I16 -> 124084.84 | J9: =+J11+J12+J13+J14+J15+J16 -> 129833.26 | ... M9: =+M11+M12+M13+M14+M15+M16 -> 99557.581 | O9: =+O11+O12+O13+O14+O15+O16 -> 29108.214 | P9: =+P11+P12+P13+P14+P15+P16 -> 29416.691 | Q9: =+Q11+Q12+Q13+Q14+Q15+Q16 -> 28523.406 | R9: =+R11+R12+R13+R14+R15+R16 -> 30387.962 | S9: =+S11+S12+S13+S14+S15+S16 -> 31417.808 | T9: =+T11+T12+T13+T14+T15+T16 -> 31660.231 | U9: =+U11+U12+U13+U14+U15+U16 -> 32415.748 | V9: =+V11+V12+V13+V14+V15+V16 -> 33530.45 | ... AU9: =+AU11+AU12+AU13+AU14+AU15+AU16 -> 33705.482
B10: Service revenues: | R10: =+E10-SUM(O10:Q10) -> 0
B11: Data | C11: 34991.091 | D11: 43058.894 | E11: 50960.555 | F11: 71801.472 | G11: 71953.848 | H11: 77812.713 | I11: 83758.035 | J11: 90894.707 | K11: 97368.837 | L11: 101166.06 | M11: =SUM(AS11:AV11) -> 79118.406 | O11: 11481.915 | P11: =23416.783-O11 -> 11934.868 | Q11: =36166.39-P11-O11 -> 12749.607 | R11: =+E11-SUM(O11:Q11) -> 14794.165 | S11: 16487.975 | T11: =34036.778-S11 -> 17548.803 | U11: =52218.535-T11-S11 -> 18181.757 | V11: =+F11-SUM(S11:U11) -> 19582.937 | W11: 18470.828 | X11: =35847.804-W11 -> 17376.976 | Y11: =53401.309-X11-W11 -> 17553.505 | Z11: =+G11-SUM(W11:Y11) -> 18552.539 | AA11: 19204.087 | AB11: =38632.568-AA11 -> 19428.481 | AC11: =57915.33-AB11-AA11 -> 19282.762 | AD11: =+H11-SUM(AA11:AC11) -> 19897.383 | AE11: 20841.338 | AF11: =41836.71-AE11 -> 20995.372 | AG11: =62546.552-AF11-AE11 -> 20709.842 | AH11: =+I11-SUM(AE11:AG11) -> 21211.483 | AI11: 21657.313 | AJ11: =44036.306-AI11 -> 22378.993 | AK11: =67046.878-AJ11-AI11 -> 23010.572 | AL11: =+J11-SUM(AI11:AK11) -> 23847.829 | AM11: 23831.211 | AN11: =48010.98-AM11 -> 24179.769 | AO11: =72859.051-AN11-AM11 -> 24848.071 | AP11: =+K11-SUM(AM11:AO11) -> 24509.786 | AQ11: 24124.789 | AR11: =48831.557-AQ11 -> 24706.768 | AS11: =73996.839-AR11-AQ11 -> 25165.282 | AT11: =+L11-SUM(AQ11:AS11) -> 27169.222 | AU11: 26783.902
B12: Voice | C12: 34065.3 | D12: 32274.474 | E12: 28407.83 | F12: 24275.585 | G12: 20129.875 | H12: 17228.714 | I12: 14916.566 | J12: 13505.925 | K12: 12652.83 | L12: 10882.048 | M12: =SUM(AS12:AV12) -> 7784.986 | O12: 7324.831 | P12: =14760.032-O12 -> 7435.201 | Q12: =21753.542-P12-O12 -> 6993.51 | R12: =+E12-SUM(O12:Q12) -> 6654.288 | S12: 6197.795 | T12: =12316.334-S12 -> 6118.539 | U12: =18495.762-T12-S12 -> 6179.428 | V12: =+F12-SUM(S12:U12) -> 5779.823 | W12: 5288.667 | X12: =10206.875-W12 -> 4918.208 | Y12: =15306.266-X12-W12 -> 5099.391 | Z12: =+G12-SUM(W12:Y12) -> 4823.609 | AA12: 4711.361 | AB12: =9112.982-AA12 -> 4401.621 | AC12: =13281.404-AB12-AA12 -> 4168.422 | AD12: =+H12-SUM(AA12:AC12) -> 3947.31 | AE12: 3899.23 | AF12: =7769.43-AE12 -> 3870.2 | AG12: =11389.308-AF12-AE12 -> 3619.878 | AH12: =+I12-SUM(AE12:AG12) -> 3527.258 | AI12: 3427.074 | AJ12: =6793.917-AI12 -> 3366.843 | AK12: =10168.49-AJ12-AI12 -> 3374.573 | AL12: =+J12-SUM(AI12:AK12) -> 3337.435 | AM12: 3355.937 | AN12: =6635.061-AM12 -> 3279.124 | AO12: =9642.449-AN12-AM12 -> 3007.388 | AP12: =+K12-SUM(AM12:AO12) -> 3010.381 | AQ12: 2776.253 | AR12: =5534.864-AQ12 -> 2758.611 | AS12: =8283.253-AR12-AQ12 -> 2748.389 | AT12: =+L12-SUM(AQ12:AS12) -> 2598.795 | AU12: 2437.802
B13: SMS | C13: 23198.924 | D13: 23149.293 | E13: 20162.343 | F13: 15690.309 | G13: 11029.64 | H13: 9350.815 | I13: 8845.422 | J13: 7975.319 | K13: 6691.721 | L13: 4801.389 | M13: =SUM(AS13:AV13) -> 2838.023 | O13: 5402.15 | P13: =10837.592-O13 -> 5435.442 | Q13: =15772.38-P13-O13 -> 4934.788 | R13: =+E13-SUM(O13:Q13) -> 4389.963 | S13: 4196.915 | T13: =8283.258-S13 -> 4086.343 | U13: =12285.502-T13-S13 -> 4002.244 | V13: =+F13-SUM(S13:U13) -> 3404.807 | W13: 3033.833 | X13: =5777.977-W13 -> 2744.144 | Y13: =8602.79-X13-W13 -> 2824.813 | Z13: =+G13-SUM(W13:Y13) -> 2426.85 | AA13: 2400.977 | AB13: =4826.972-AA13 -> 2425.995 | AC13: =7167.415-AB13-AA13 -> 2340.443 | AD13: =+H13-SUM(AA13:AC13) -> 2183.4 | AE13: 2148.86 | AF13: =4440.455-AE13 -> 2291.595 | AG13: =6650.753-AF13-AE13 -> 2210.298 | AH13: =+I13-SUM(AE13:AG13) -> 2194.669 | AI13: 2007.807 | AJ13: =3992.439-AI13 -> 1984.632 | AK13: =5964.287-AJ13-AI13 -> 1971.848 | AL13: =+J13-SUM(AI13:AK13) -> 2011.032 | AM13: 1939.027 | AN13: =3745.909-AM13 -> 1806.882 | AO13: =5204.629-AN13-AM13 -> 1458.72 | AP13: =+K13-SUM(AM13:AO13) -> 1487.092 | AQ13: 1393.051 | AR13: =2706.677-AQ13 -> 1313.626 | AS13: =3892.904-AR13-AQ13 -> 1186.227 | AT13: =+L13-SUM(AQ13:AS13) -> 908.485 | AU13: 743.311
B14: Broadband | C14: 0 | D14: 0 | E14: 0 | F14: 0 | G14: 0 | H14: 0 | I14: 0 | J14: 0 | K14: 0 | L14: 0 | M14: =SUM(AS14:AV14) -> 0 | O14: 0 | P14: =0-O14 -> 0 | Q14: =0-P14-O14 -> 0 | R14: =+E14-SUM(O14:Q14) -> 0 | S14: 0 | T14: =0-S14 -> 0 | U14: =0-T14-S14 -> 0 | V14: =+F14-SUM(S14:U14) -> 0 | W14: 0 | X14: =0-W14 -> 0 | Y14: =0-X14-W14 -> 0 | Z14: =+G14-SUM(W14:Y14) -> 0 | AA14: 0 | AB14: =0-AA14 -> 0 | AC14: =0-AB14-AA14 -> 0 | AD14: =+H14-SUM(AA14:AC14) -> 0 | AE14: 0 | AF14: =0-AE14 -> 0 | AG14: =0-AF14-AE14 -> 0 | AH14: =+I14-SUM(AE14:AG14) -> 0 | AI14: 0 | AJ14: =0-AI14 -> 0 | AK14: =0-AJ14-AI14 -> 0 | AL14: =+J14-SUM(AI14:AK14) -> 0 | AM14: 0 | AN14: =0-AM14 -> 0 | AO14: =0-AN14-AM14 -> 0 | AP14: =+K14-SUM(AM14:AO14) -> 0 | AQ14: 0 | AR14: =0-AQ14 -> 0 | AS14: =0-AR14-AQ14 -> 0 | AT14: =+L14-SUM(AQ14:AS14) -> 0 | AU14: 0
B15: Other | C15: 0 | D15: 0 | E15: 0 | F15: 0 | G15: 0 | H15: 0 | I15: 0 | J15: 0 | K15: 0 | L15: 0 | M15: =SUM(AS15:AV15) -> 0 | O15: 0 | P15: =0-O15 -> 0 | Q15: =0-P15-O15 -> 0 | R15: =+E15-SUM(O15:Q15) -> 0 | S15: 0 | T15: =0-S15 -> 0 | U15: =0-T15-S15 -> 0 | V15: =+F15-SUM(S15:U15) -> 0 | W15: 0 | X15: =0-W15 -> 0 | Y15: =0-X15-W15 -> 0 | Z15: =+G15-SUM(W15:Y15) -> 0 | AA15: 0 | AB15: =0-AA15 -> 0 | AC15: =0-AB15-AA15 -> 0 | AD15: =+H15-SUM(AA15:AC15) -> 0 | AE15: 0 | AF15: =0-AE15 -> 0 | AG15: =0-AF15-AE15 -> 0 | AH15: =+I15-SUM(AE15:AG15) -> 0 | AI15: 0 | AJ15: =0-AI15 -> 0 | AK15: =0-AJ15-AI15 -> 0 | AL15: =+J15-SUM(AI15:AK15) -> 0 | AM15: 0 | AN15: =0-AM15 -> 0 | AO15: =0-AN15-AM15 -> 0 | AP15: =+K15-SUM(AM15:AO15) -> 0 | AQ15: 0 | AR15: =0-AQ15 -> 0 | AS15: =0-AR15-AQ15 -> 0 | AT15: =+L15-SUM(AQ15:AS15) -> 0 | AU15: 0
B16: Nonservice revenues | C16: 5670.249 | D16: 7103.49 | E16: 17905.545 | F16: 17256.871 | G16: 11968.825 | H16: 15199.998 | I16: 16564.819 | J16: 17457.309 | K16: 15201.455 | L16: 13050.019 | M16: =SUM(AS16:AV16) -> 9816.166 | O16: 4899.318 | P16: =9510.498-O16 -> 4611.18 | Q16: =13355.999-P16-O16 -> 3845.501 | R16: =+E16-SUM(O16:Q16) -> 4549.546 | S16: 4535.123 | T16: =8441.669-S16 -> 3906.546 | U16: =12493.988-T16-S16 -> 4052.319 | V16: =+F16-SUM(S16:U16) -> 4762.883 | W16: 3962.999 | X16: =5475.12-W16 -> 1512.121 | Y16: =8768.036-X16-W16 -> 3292.916 | Z16: =+G16-SUM(W16:Y16) -> 3200.789 | AA16: 4736.78 | AB16: =8212.069-AA16 -> 3475.289 | AC16: =11252.254-AB16-AA16 -> 3040.185 | AD16: =+H16-SUM(AA16:AC16) -> 3947.744 | AE16: 4257.865 | AF16: =8161.795-AE16 -> 3903.93 | AG16: =11842.183-AF16-AE16 -> 3680.388 | AH16: =+I16-SUM(AE16:AG16) -> 4722.636 | AI16: 4945.223 | AJ16: =8907.502-AI16 -> 3962.279 | AK16: =12417.537-AJ16-AI16 -> 3510.035 | AL16: =+J16-SUM(AI16:AK16) -> 5039.772 | AM16: 4058.38 | AN16: =7221.077-AM16 -> 3162.697 | AO16: =10457.109-AN16-AM16 -> 3236.032 | AP16: =+K16-SUM(AM16:AO16) -> 4744.346 | AQ16: 3867.523 | AR16: =6974.32-AQ16 -> 3106.797 | AS16: =9818.645-AR16-AQ16 -> 2844.325 | AT16: =+L16-SUM(AQ16:AS16) -> 3231.374 | AU16: 3740.467
B17: Wireline Communications | C17: =+C19+C20+C21+C22+C23+C24 -> 28856.096 | D17: =+D19+D20+D21+D22+D23+D24 -> 29694.58 | E17: =+E19+E20+E21+E22+E23+E24 -> 33736.533 | F17: =+F19+F20+F21+F22+F23+F24 -> 37636.1 | G17: =+G19+G20+G21+G22+G23+G24 -> 44029.614 | H17: =+H19+H20+H22+H21+H23+H24 -> 46806.11 | I17: =+I19+I20+I22+I21+I23+I24 -> 46670.826 | J17: =+J19+J20+J22+J21+J23+J24 -> 45289.363 | K17: =+K19+K20+K22+K21+K23+K24 -> 45940.536 | L17: =+L19+L20+L22+L21+L23+L24 -> 45931.731 | M17: =+M19+M20+M21+M22+M23+M24 -> 35590.46 | O17: =+O19+O20+O21+O22+O23+O24 -> 7829.412 | P17: =+P19+P20+P21+P22+P23+P24 -> 8091.648 | Q17: =+Q19+Q20+Q21+Q22+Q23+Q24 -> 8633.382 | R17: =+R19+R20+R21+R22+R23+R24 -> 9182.091 | S17: =+S19+S20+S21+S22+S23+S24 -> 9151.808 | T17: =+T19+T20+T21+T22+T23+T24 -> 9291.171 | U17: =+U19+U20+U21+U22+U23+U24 -> 9481.149 | V17: =+V19+V20+V21+V22+V23+V24 -> 9711.972 | ... AU17: =+AU19+AU20+AU21+AU22+AU23+AU24 -> 11635.923
B18: Service revenues:
B19: Data | C19: 9873.417 | D19: 10287.868 | E19: 11761.929 | F19: 12827.652 | G19: 12539.234 | H19: 14170.1 | I19: 17198.099 | J19: 18319.203 | K19: 20379.506 | L19: 20670.497 | M19: =SUM(AS19:AV19) -> 16179.258 | O19: 2666.57 | P19: =5492.761-O19 -> 2826.191 | Q19: =8437.238-P19-O19 -> 2944.477 | R19: =+E19-SUM(O19:Q19) -> 3324.691 | S19: 3136.219 | T19: =6294.489-S19 -> 3158.27 | U19: =9481.169-T19-S19 -> 3186.68 | V19: =+F19-SUM(S19:U19) -> 3346.483 | W19: 3250.423 | X19: =6199.21-W19 -> 2948.787 | Y19: =9276.673-X19-W19 -> 3077.463 | Z19: =+G19-SUM(W19:Y19) -> 3262.561 | AA19: 3322.683 | AB19: =6729.309-AA19 -> 3406.626 | AC19: =10388.197-AB19-AA19 -> 3658.888 | AD19: =+H19-SUM(AA19:AC19) -> 3781.903 | AE19: 3921.731 | AF19: =8151.542-AE19 -> 4229.811 | AG19: =12534.178-AF19-AE19 -> 4382.636 | AH19: =+I19-SUM(AE19:AG19) -> 4663.921 | AI19: 4504.629 | AJ19: =9071.921-AI19 -> 4567.292 | AK19: =13559.353-AJ19-AI19 -> 4487.432 | AL19: =+J19-SUM(AI19:AK19) -> 4759.85 | AM19: 4955.858 | AN19: =9789.005-AM19 -> 4833.147 | AO19: =15480.071-AN19-AM19 -> 5691.066 | AP19: =+K19-SUM(AM19:AO19) -> 4899.435 | AQ19: 4857.516 | AR19: =9626.663-AQ19 -> 4769.147 | AS19: =14995.089-AR19-AQ19 -> 5368.426 | AT19: =+L19-SUM(AQ19:AS19) -> 5675.408 | AU19: 5135.424
B20: Voice | C20: 3779.82 | D20: 3490.35 | E20: 2977.017 | F20: 2668.413 | G20: 2620.106 | H20: 2280.357 | I20: 1989.174 | J20: 1595.674 | K20: 1500.199 | L20: 1251.135 | M20: =SUM(AS20:AV20) -> 946.79 | O20: 768.976 | P20: =1511.88-O20 -> 742.904 | Q20: =2261.083-P20-O20 -> 749.203 | R20: =+E20-SUM(O20:Q20) -> 715.934 | S20: 710.33 | T20: =1393.641-S20 -> 683.311 | U20: =2062.378-T20-S20 -> 668.737 | V20: =+F20-SUM(S20:U20) -> 606.035 | W20: 696.624 | X20: =1301.319-W20 -> 604.695 | Y20: =2032.9-X20-W20 -> 731.581 | Z20: =+G20-SUM(W20:Y20) -> 587.206 | AA20: 599.086 | AB20: =1176.849-AA20 -> 577.763 | AC20: =1741.904-AB20-AA20 -> 565.055 | AD20: =+H20-SUM(AA20:AC20) -> 538.453 | AE20: 527.423 | AF20: =1012.515-AE20 -> 485.092 | AG20: =1516.42-AF20-AE20 -> 503.905 | AH20: =+I20-SUM(AE20:AG20) -> 472.754 | AI20: 426.474 | AJ20: =856.725-AI20 -> 430.251 | AK20: =1248.665-AJ20-AI20 -> 391.94 | AL20: =+J20-SUM(AI20:AK20) -> 347.009 | AM20: 382.954 | AN20: =762.961-AM20 -> 380.007 | AO20: =1129.99-AN20-AM20 -> 367.029 | AP20: =+K20-SUM(AM20:AO20) -> 370.209 | AQ20: 320.534 | AR20: =626.115-AQ20 -> 305.581 | AS20: =942.868-AR20-AQ20 -> 316.753 | AT20: =+L20-SUM(AQ20:AS20) -> 308.267 | AU20: 321.77
B21: SMS | C21: 0 | D21: 0 | E21: 0 | F21: 0 | G21: 0 | M21: =SUM(AS21:AV21) -> 0 | O21: 0 | P21: =0-O21 -> 0 | Q21: =0-P21-O21 -> 0 | R21: =+E21-SUM(O21:Q21) -> 0 | S21: 0 | T21: =0-S21 -> 0 | U21: =0-T21-S21 -> 0 | V21: =+F21-SUM(S21:U21) -> 0 | W21: 0 | X21: =0-W21 -> 0 | Y21: =0-X21-W21 -> 0 | Z21: =+G21-SUM(W21:Y21) -> 0 | AA21: 0 | AB21: =0-AA21 -> 0 | AC21: =0-AB21-AA21 -> 0 | AD21: =+H21-SUM(AA21:AC21) -> 0 | AE21: 0 | AF21: =0-AE21 -> 0 | AG21: =0-AF21-AE21 -> 0 | AH21: =+I21-SUM(AE21:AG21) -> 0 | AI21: 0 | AJ21: =0-AI21 -> 0 | AK21: =0-AJ21-AI21 -> 0 | AL21: =+J21-SUM(AI21:AK21) -> 0 | AM21: 0 | AN21: =0-AM21 -> 0 | AO21: =0-AN21-AM21 -> 0 | AP21: =+K21-SUM(AM21:AO21) -> 0 | AQ21: 0 | AR21: =0-AQ21 -> 0 | AS21: =0-AR21-AQ21 -> 0 | AT21: =+L21-SUM(AQ21:AS21) -> 0 | AU21: 0
B22: Broadband | C22: 14679.451 | D22: 15644.974 | E22: 18605.636 | F22: 21746.532 | G22: 26798.31 | H22: 29391.454 | I22: 27093.52 | J22: 25111.748 | K22: 23785.396 | L22: 23980.12 | M22: =SUM(AS22:AV22) -> 18449.65 | O22: 4297.749 | P22: =8727.132-O22 -> 4429.383 | Q22: =13553.078-P22-O22 -> 4825.946 | R22: =+E22-SUM(O22:Q22) -> 5052.558 | S22: 5207.354 | T22: =10554.213-S22 -> 5346.859 | U22: =16071.614-T22-S22 -> 5517.401 | V22: =+F22-SUM(S22:U22) -> 5674.918 | W22: 5779.956 | X22: =12512.794-W22 -> 6732.838 | Y22: =19548.475-X22-W22 -> 7035.681 | Z22: =+G22-SUM(W22:Y22) -> 7249.835 | AA22: 7350.644 | AB22: =14531.856-AA22 -> 7181.212 | AC22: =22397.312-AB22-AA22 -> 7865.456 | AD22: =+H22-SUM(AA22:AC22) -> 6994.142 | AE22: 7025.776 | AF22: =13794.756-AE22 -> 6768.98 | AG22: =20475.986-AF22-AE22 -> 6681.23 | AH22: =+I22-SUM(AE22:AG22) -> 6617.534 | AI22: 6531.853 | AJ22: =12809.116-AI22 -> 6277.263 | AK22: =18993.848-AJ22-AI22 -> 6184.732 | AL22: =+J22-SUM(AI22:AK22) -> 6117.9 | AM22: 6116.796 | AN22: =12100.164-AM22 -> 5983.368 | AO22: =17886.868-AN22-AM22 -> 5786.704 | AP22: =+K22-SUM(AM22:AO22) -> 5898.528 | AQ22: 5813.032 | AR22: =11708.118-AQ22 -> 5895.086 | AS22: =17840.249-AR22-AQ22 -> 6132.131 | AT22: =+L22-SUM(AQ22:AS22) -> 6139.871 | AU22: 6177.648
B23: Other | C23: 0 | D23: 0 | E23: 0 | F23: 0 | G23: 0 | H23: 0 | I23: 0 | J23: 0 | K23: 0 | L23: 0 | M23: =SUM(AS23:AV23) -> 0 | O23: 0 | P23: =0-O23 -> 0 | Q23: =0-P23-O23 -> 0 | R23: =+E23-SUM(O23:Q23) -> 0 | S23: 0 | T23: =0-S23 -> 0 | U23: =0-T23-S23 -> 0 | V23: =+F23-SUM(S23:U23) -> 0 | W23: 0 | X23: =0-W23 -> 0 | Y23: =0-X23-W23 -> 0 | Z23: =+G23-SUM(W23:Y23) -> 0 | AA23: 0 | AB23: =0-AA23 -> 0 | AC23: =0-AB23-AA23 -> 0 | AD23: =+H23-SUM(AA23:AC23) -> 0 | AE23: 0 | AF23: =0-AE23 -> 0 | AG23: =0-AF23-AE23 -> 0 | AH23: =+I23-SUM(AE23:AG23) -> 0 | AI23: 0 | AJ23: =0-AI23 -> 0 | AK23: =0-AJ23-AI23 -> 0 | AL23: =+J23-SUM(AI23:AK23) -> 0 | AM23: 0 | AN23: =0-AM23 -> 0 | AO23: =0-AN23-AM23 -> 0 | AP23: =+K23-SUM(AM23:AO23) -> 0 | AQ23: 0 | AR23: =0-AQ23 -> 0 | AS23: =0-AR23-AQ23 -> 0 | AT23: =+L23-SUM(AQ23:AS23) -> 0 | AU23: 0
B24: Nonservice revenues | C24: 523.408 | D24: 271.388 | E24: 391.951 | F24: 393.503 | G24: 2071.964 | H24: 964.199 | I24: 390.033 | J24: 262.738 | K24: 275.435 | L24: 29.979 | M24: =SUM(AS24:AV24) -> 14.762 | O24: 96.117 | P24: =189.287-O24 -> 93.17 | Q24: =303.043-P24-O24 -> 113.756 | R24: =+E24-SUM(O24:Q24) -> 88.908 | S24: 97.905 | T24: =200.636-S24 -> 102.731 | U24: =308.967-T24-S24 -> 108.331 | V24: =+F24-SUM(S24:U24) -> 84.536 | W24: 343.044 | X24: =912.351-W24 -> 569.307 | Y24: =1716.859-X24-W24 -> 804.508 | Z24: =+G24-SUM(W24:Y24) -> 355.105 | AA24: 273.236 | AB24: =494.409-AA24 -> 221.173 | AC24: =736.749-AB24-AA24 -> 242.34 | AD24: =+H24-SUM(AA24:AC24) -> 227.45 | AE24: 116.913 | AF24: =232.579-AE24 -> 115.666 | AG24: =323.618-AF24-AE24 -> 91.039 | AH24: =+I24-SUM(AE24:AG24) -> 66.415 | AI24: 65.408 | AJ24: =152.147-AI24 -> 86.739 | AK24: =226.762-AJ24-AI24 -> 74.615 | AL24: =+J24-SUM(AI24:AK24) -> 35.976 | AM24: 66.759 | AN24: =128.222-AM24 -> 61.463 | AO24: =195.765-AN24-AM24 -> 67.543 | AP24: =+K24-SUM(AM24:AO24) -> 79.67 | AQ24: 8.889 | AR24: =16.298-AQ24 -> 7.409 | AS24: =28.422-AR24-AQ24 -> 12.124 | AT24: =+L24-SUM(AQ24:AS24) -> 1.557 | AU24: 1.081
B25: Other | C25: =+C26+C27 -> 0 | D25: =+D26+D27 -> 0 | E25: =+E26+E27 -> 0 | F25: =+F26+F27 -> 0 | G25: =+G26+G27 -> 1407.74 | H25: =+H26+H27 -> 2098.108 | I25: =+I26+I27 -> 4285.055 | J25: =+J26+J27 -> 5041.832 | ... M25: =+M26+M27 -> 1572.552 | O25: =+O26+O27 -> 0 | P25: =+P26+P27 -> 0 | Q25: =+Q26+Q27 -> 0 | R25: =+R26+R27 -> 0 | S25: =+S26+S27 -> 66.451 | T25: =+T26+T27 -> -66.451 | U25: =+U26+U27 -> 0 | V25: =+V26+V27 -> 0 | ... AU25: =+AU26+AU27 -> 365.047
B26: Service revenues: | C26: 0 | D26: 0 | E26: 0 | F26: 0 | G26: 1317.121 | H26: 2028.68 | I26: 4178.519 | J26: 4930.908 | K26: 2637.8 | L26: 2326.408 | M26: =SUM(AS26:AV26) -> 1537.031 | O26: 0 | P26: =0-O26 -> 0 | Q26: =0-P26-O26 -> 0 | R26: =+E26-SUM(O26:Q26) -> 0 | S26: 66.451 | T26: =0-S26 -> -66.451 | U26: =0-T26-S26 -> 0 | V26: =+F26-SUM(S26:U26) -> 0 | W26: 361.643 | X26: =576.802-W26 -> 215.159 | Y26: =935.821-X26-W26 -> 359.019 | Z26: =+G26-SUM(W26:Y26) -> 381.3 | AA26: 224.397 | AB26: =858.523-AA26 -> 634.126 | AC26: =1410.819-AB26-AA26 -> 552.296 | AD26: =+H26-SUM(AA26:AC26) -> 617.861 | AE26: 790.722 | AF26: =1874.707-AE26 -> 1083.985 | AG26: =2842.04-AF26-AE26 -> 967.333 | AH26: =+I26-SUM(AE26:AG26) -> 1336.479 | AI26: 1426.552 | AJ26: =2840.569-AI26 -> 1414.017 | AK26: =4080.579-AJ26-AI26 -> 1240.01 | AL26: =+J26-SUM(AI26:AK26) -> 850.329 | AM26: 566.603 | AN26: =1181.61-AM26 -> 615.007 | AO26: =1806.359-AN26-AM26 -> 624.749 | AP26: =+K26-SUM(AM26:AO26) -> 831.441 | AQ26: 568.092 | AR26: =1154.245-AQ26 -> 586.153 | AS26: =1725.249-AR26-AQ26 -> 571.004 | AT26: =+L26-SUM(AQ26:AS26) -> 601.159 | AU26: 364.868
B27: Nonservice revenues | C27: 0 | D27: 0 | E27: 0 | F27: 0 | G27: 90.619 | H27: 69.428 | I27: 106.536 | J27: 110.924 | K27: 92.881 | L27: 82.188 | M27: =SUM(AS27:AV27) -> 35.521 | O27: 0 | P27: =0-O27 -> 0 | Q27: =0-P27-O27 -> 0 | R27: =+E27-SUM(O27:Q27) -> 0 | S27: 0 | T27: =0-S27 -> 0 | U27: =0-T27-S27 -> 0 | V27: =+F27-SUM(S27:U27) -> 0 | W27: 3.335 | X27: =3.878-W27 -> 0.543 | Y27: =3.878-X27-W27 -> 0 | Z27: =+G27-SUM(W27:Y27) -> 86.741 | AA27: 23.836 | AB27: =40.966-AA27 -> 17.13 | AC27: =69.429-AB27-AA27 -> 28.463 | AD27: =+H27-SUM(AA27:AC27) -> -0.001 | AE27: 27.018 | AF27: =47.378-AE27 -> 20.36 | AG27: =76.101-AF27-AE27 -> 28.723 | AH27: =+I27-SUM(AE27:AG27) -> 30.435 | AI27: 37.975 | AJ27: =63.636-AI27 -> 25.661 | AK27: =86.004-AJ27-AI27 -> 22.368 | AL27: =+J27-SUM(AI27:AK27) -> 24.92 | AM27: 34.097 | AN27: =50.264-AM27 -> 16.167 | AO27: =81.901-AN27-AM27 -> 31.637 | AP27: =+K27-SUM(AM27:AO27) -> 10.98 | AQ27: 26.002 | AR27: =46.846-AQ27 -> 20.844 | AS27: =66.917-AR27-AQ27 -> 20.071 | AT27: =+L27-SUM(AQ27:AS27) -> 15.271 | AU27: 0.179
B28: Total | C28: =+C9+C17+C25 -> 126781.66 | D28: =+D9+D17+D25 -> 135280.73 | E28: =+E9+E17+E25 -> 151172.81 | F28: =+F9+F17+F25 -> 166660.34 | G28: =+G9+G17+G25 -> 160519.54 | H28: =+H9+H17+H25 -> 168496.46 | I28: =+I9+I17+I25 -> 175040.72 | J28: =+J9+J17+J25 -> 180164.46 | ... M28: =+M9+M17+M25 -> 136720.59 | O28: =+O9+O17+O25 -> 36937.626 | P28: =+P9+P17+P25 -> 37508.339 | Q28: =+Q9+Q17+Q25 -> 37156.788 | R28: =+R9+R17+R25 -> 39570.053 | S28: =+S9+S17+S25 -> 40636.067 | T28: =+T9+T17+T25 -> 40884.951 | U28: =+U9+U17+U25 -> 41896.897 | V28: =+V9+V17+V25 -> 43242.422 | ... AU28: =+AU9+AU17+AU25 -> 45706.452
B29: Check | C29: =+C28-Model!C10 -> 0 | D29: =+D28-Model!D10 -> 0 | E29: =+E28-Model!E10 -> 0 | F29: =+F28-Model!F10 -> 0 | G29: =+G28-Model!G10 -> 0 | H29: =+H28-Model!H10 -> 0 | I29: =+I28-Model!I10 -> 0 | J29: =+J28-Model!J10 -> 0 | ... M29: =+M28-Model!M10 -> 136720.59 | O29: =+O28-Model!O10 -> 0 | P29: =+P28-Model!P10 -> 0 | Q29: =+Q28-Model!Q10 -> 0 | R29: =+R28-Model!R10 -> 0 | S29: =+S28-Model!S10 -> 0 | T29: =+T28-Model!T10 -> 0 | U29: =+U28-Model!U10 -> 0 | V29: =+V28-Model!V10 -> 0 | ... AU29: =+AU28-Model!AU10 -> 0
B31: % of Revenue by business segment
B32: =+B9 -> Mobile Communications | C32: =+C9/C$28 -> 0.77239534 | D32: =+D9/D$28 -> 0.7804966 | E32: =+E9/E$28 -> 0.77683464 | F32: =+F9/F$28 -> 0.77417482 | G32: =+G9/G$28 -> 0.71693569 | H32: =+H9/H$28 -> 0.70976115 | I32: =+I9/I$28 -> 0.70889128 | J32: =+J9/J$28 -> 0.72063749 | ... M32: =+M9/M$28 -> 0.72818278 | O32: =+O9/O$28 -> 0.78803695 | P32: =+P9/P$28 -> 0.78427069 | Q32: =+Q9/Q$28 -> 0.76764994 | R32: =+R9/R$28 -> 0.76795353 | S32: =+S9/S$28 -> 0.77315081 | T32: =+T9/T$28 -> 0.77437371 | U32: =+U9/U$28 -> 0.77370284 | V32: =+V9/V$28 -> 0.77540638 | ... AU32: =+AU9/AU$28 -> 0.73743379
B33: =+B17 -> Wireline Communications | C33: =+C17/C$28 -> 0.22760466 | D33: =+D17/D$28 -> 0.2195034 | E33: =+E17/E$28 -> 0.22316536 | F33: =+F17/F$28 -> 0.22582518 | G33: =+G17/G$28 -> 0.27429442 | H33: =+H17/H$28 -> 0.27778691 | I33: =+I17/I$28 -> 0.26662839 | J33: =+J17/J$28 -> 0.2513779 | ... M33: =+M17/M$28 -> 0.26031528 | O33: =+O17/O$28 -> 0.21196305 | P33: =+P17/P$28 -> 0.21572931 | Q33: =+Q17/Q$28 -> 0.23235006 | R33: =+R17/R$28 -> 0.23204647 | S33: =+S17/S$28 -> 0.22521392 | T33: =+T17/T$28 -> 0.22725161 | U33: =+U17/U$28 -> 0.22629716 | V33: =+V17/V$28 -> 0.22459362 | ... AU33: =+AU17/AU$28 -> 0.25457944
B34: =+B25 -> Other | C34: =+C25/C$28 -> 0 | D34: =+D25/D$28 -> 0 | E34: =+E25/E$28 -> 0 | F34: =+F25/F$28 -> 0 | G34: =+G25/G$28 -> 0.0087698979 | H34: =+H25/H$28 -> 0.012451941 | I34: =+I25/I$28 -> 0.024480332 | J34: =+J25/J$28 -> 0.02798461 | ... M34: =+M25/M$28 -> 0.01150194 | O34: =+O25/O$28 -> 0 | P34: =+P25/P$28 -> 0 | Q34: =+Q25/Q$28 -> 0 | R34: =+R25/R$28 -> 0 | S34: =+S25/S$28 -> 0.0016352714 | T34: =+T25/T$28 -> -0.0016253169 | U34: =+U25/U$28 -> 0 | V34: =+V25/V$28 -> 0 | ... AU34: =+AU25/AU$28 -> 0.0079867718
B35: Total | C35: =+C32+C33+C34 -> 1 | D35: =+D32+D33+D34 -> 1 | E35: =+E32+E33+E34 -> 1 | F35: =+F32+F33+F34 -> 1 | G35: =+G32+G33+G34 -> 1 | H35: =+H32+H33+H34 -> 1 | I35: =+I32+I33+I34 -> 1 | J35: =+J32+J33+J34 -> 1 | ... M35: =+M32+M33+M34 -> 1 | O35: =+O32+O33+O34 -> 1 | P35: =+P32+P33+P34 -> 1 | Q35: =+Q32+Q33+Q34 -> 1 | R35: =+R32+R33+R34 -> 1 | S35: =+S32+S33+S34 -> 1 | T35: =+T32+T33+T34 -> 1 | U35: =+U32+U33+U34 -> 1 | V35: =+V32+V33+V34 -> 1 | ... AU35: =+AU32+AU33+AU34 -> 1
B37: EBITDA by business segment
B38: =+B9 -> Mobile Communications | C38: 41260.57 | D38: 46412.954 | E38: 54813.431 | F38: 63935.268 | G38: 60240.7 | H38: 59309.36 | I38: 61719.758 | J38: 65524.818 | K38: 69890.996 | L38: 70461.477 | M38: =SUM(AS38:AV38) -> 53941.614 | O38: 13579.419 | P38: =27789.635-O38 -> 14210.216 | Q38: =41332.447-P38-O38 -> 13542.812 | R38: =+E38-SUM(O38:Q38) -> 13480.984 | S38: 16660.983 | T38: =32159.321-S38 -> 15498.338 | U38: =48552.366-T38-S38 -> 16393.045 | V38: =+F38-SUM(S38:U38) -> 15382.902 | W38: 16589.83 | X38: =31252.085-W38 -> 14662.255 | Y38: =45350.726-X38-W38 -> 14098.641 | Z38: =+G38-SUM(W38:Y38) -> 14889.974 | AA38: 14522.764 | AB38: =29535.182-AA38 -> 15012.418 | AC38: =44459.084-AB38-AA38 -> 14923.902 | AD38: =+H38-SUM(AA38:AC38) -> 14850.276 | AE38: 15862.442 | AF38: =32215.336-AE38 -> 16352.894 | AG38: =47440.573-AF38-AE38 -> 15225.237 | AH38: =+I38-SUM(AE38:AG38) -> 14279.185 | AI38: 16292.543 | AJ38: =31923.786-AI38 -> 15631.243 | AK38: =48253.42-AJ38-AI38 -> 16329.634 | AL38: =+J38-SUM(AI38:AK38) -> 17271.398 | AM38: 17299.439 | AN38: =34366.037-AM38 -> 17066.598 | AO38: =52118.708-AN38-AM38 -> 17752.671 | AP38: =+K38-SUM(AM38:AO38) -> 17772.288 | AQ38: 17017.295 | AR38: =34333.017-AQ38 -> 17315.722 | AS38: =51992.777-AR38-AQ38 -> 17659.76 | AT38: =+L38-SUM(AQ38:AS38) -> 18468.7 | AU38: 17813.154
B39: =+B17 -> Wireline Communications | C39: 8717.826 | D39: 6912.717 | E39: 10313.684 | F39: 12096.165 | G39: 12656.74 | H39: 15186.191 | I39: 14899.935 | J39: 14476.633 | K39: 16917.109 | L39: 17243.441 | M39: =SUM(AS39:AV39) -> 13883.33 | O39: 2500.26 | P39: =5029.46-O39 -> 2529.2 | Q39: =7962.486-P39-O39 -> 2933.026 | R39: =+E39-SUM(O39:Q39) -> 2351.198 | S39: 3249.885 | T39: =6422.383-S39 -> 3172.498 | U39: =9304.352-T39-S39 -> 2881.969 | V39: =+F39-SUM(S39:U39) -> 2791.813 | W39: 3700.407 | X39: =6815.261-W39 -> 3114.854 | Y39: =10384.365-X39-W39 -> 3569.104 | Z39: =+G39-SUM(W39:Y39) -> 2272.375 | AA39: 3723.78 | AB39: =7708.406-AA39 -> 3984.626 | AC39: =12157.581-AB39-AA39 -> 4449.175 | AD39: =+H39-SUM(AA39:AC39) -> 3028.61 | AE39: 3161.736 | AF39: =7231.738-AE39 -> 4070.002 | AG39: =10773.869-AF39-AE39 -> 3542.131 | AH39: =+I39-SUM(AE39:AG39) -> 4126.066 | AI39: 3975.913 | AJ39: =7696.001-AI39 -> 3720.088 | AK39: =11202.875-AJ39-AI39 -> 3506.874 | AL39: =+J39-SUM(AI39:AK39) -> 3273.758 | AM39: 4017.31 | AN39: =8419.744-AM39 -> 4402.434 | AO39: =12223.931-AN39-AM39 -> 3804.187 | AP39: =+K39-SUM(AM39:AO39) -> 4693.178 | AQ39: 3747.474 | AR39: =7871.053-AQ39 -> 4123.579 | AS39: =12286.115-AR39-AQ39 -> 4415.062 | AT39: =+L39-SUM(AQ39:AS39) -> 4957.326 | AU39: 4510.942
B40: =+B25 -> Other | C40: 0 | D40: 0 | E40: 0 | F40: 0 | G40: 614.915 | H40: 426.33 | I40: 2472.326 | J40: 1425.295 | K40: 5.571 | L40: -80.602 | M40: =SUM(AS40:AV40) -> -166.519 | O40: 0 | P40: 0 | Q40: 0 | R40: =+E40-SUM(O40:Q40) -> 0 | S40: 8.485 | T40: =0-S40 -> -8.485 | U40: 0 | V40: =+F40-SUM(S40:U40) -> 0 | W40: 185.441 | X40: =320.207-W40 -> 134.766 | Y40: =519.427-X40-W40 -> 199.22 | Z40: =+G40-SUM(W40:Y40) -> 95.488 | AA40: 41.386 | AB40: =128.816-AA40 -> 87.43 | AC40: =298.435-AB40-AA40 -> 169.619 | AD40: =+H40-SUM(AA40:AC40) -> 127.895 | AE40: 656.162 | AF40: =1098.649-AE40 -> 442.487 | AG40: =2103.096-AF40-AE40 -> 1004.447 | AH40: =+I40-SUM(AE40:AG40) -> 369.23 | AI40: 259.644 | AJ40: =873.288-AI40 -> 613.644 | AK40: =1240.144-AJ40-AI40 -> 366.856 | AL40: =+J40-SUM(AI40:AK40) -> 185.151 | AM40: 34.043 | AN40: =177.779-AM40 -> 143.736 | AO40: =522.019-AN40-AM40 -> 344.24 | AP40: =+K40-SUM(AM40:AO40) -> -516.448 | AQ40: -2.055 | AR40: =-64.313-AQ40 -> -62.258 | AS40: =-93.44-AR40-AQ40 -> -29.127 | AT40: =+L40-SUM(AQ40:AS40) -> 12.838 | AU40: -150.23
B41: Total | C41: =+C38+C39+C40 -> 49978.396 | D41: =+D38+D39+D40 -> 53325.671 | E41: =+E38+E39+E40 -> 65127.115 | F41: =+F38+F39+F40 -> 76031.433 | G41: =+G38+G39+G40 -> 73512.355 | H41: =+H38+H39+H40 -> 74921.881 | I41: =+I38+I39+I40 -> 79092.019 | J41: =+J38+J39+J40 -> 81426.746 | ... M41: =+M38+M39+M40 -> 67658.425 | O41: =+O38+O39+O40 -> 16079.679 | P41: =+P38+P39+P40 -> 16739.416 | Q41: =+Q38+Q39+Q40 -> 16475.838 | R41: =+R38+R39+R40 -> 15832.182 | S41: =+S38+S39+S40 -> 19919.353 | T41: =+T38+T39+T40 -> 18662.351 | U41: =+U38+U39+U40 -> 19275.014 | V41: =+V38+V39+V40 -> 18174.715 | ... AU41: =+AU38+AU39+AU40 -> 22173.866
B42: Check | C42: =+C41-Model!C56 -> 0 | D42: =+D41-Model!D56 -> 0 | E42: =+E41-Model!E56 -> 0 | F42: =+F41-Model!F56 -> 0 | G42: =+G41-Model!G56 -> 0 | H42: =+H41-Model!H56 -> 0 | I42: =+I41-Model!I56 -> 0 | J42: =+J41-Model!J56 -> 0 | ... M42: =+M41-Model!M56 -> 67658.425 | O42: =+O41-Model!O56 -> 0 | P42: =+P41-Model!P56 -> 0 | Q42: =+Q41-Model!Q56 -> 0 | R42: =+R41-Model!R56 -> 0 | S42: =+S41-Model!S56 -> 0 | T42: =+T41-Model!T56 -> 0 | U42: =+U41-Model!U56 -> 0 | V42: =+V41-Model!V56 -> 0 | ... AU42: =+AU41-Model!AU56 -> 0
B44: % margin
