Workbook
Name \A: #REF!
Name \A: #REF!
Name \B: #REF!
Name \B: #REF!
Name \C: #REF!
Name \C: #REF!
Name \L: #REF!
Name \M: #REF!
Name \P: #REF!
Name \Y: #REF!
Name _01_30_04: MonthlyOpStats
Name _01_30_04: MonthlyOpStats
Name _1_30_01: MonthlyOpStats
Name _1_30_01: MonthlyOpStats
Name _1_30_02: MonthlyOpStats
Name _1_30_02: MonthlyOpStats
Name _1_31_01: MonthlyOpStats
Name _1_31_01: MonthlyOpStats
Name _1_31_02: MonthlyOpStats
Name _1_31_02: MonthlyOpStats
Name _12_31_05: MonthlyOpStats
Name _12_31_05: MonthlyOpStats
Name _A: #REF!
Name _A: #REF!
Name _A___0: #REF!
Name _A___0: #REF!
Name _B: #REF!
Name _B: #REF!
Name _B___0: #REF!
Name _C: #REF!
Name _C___0: #REF!
Name _ent1: [1]Inputs!$J$17
Name _ent10: [1]Inputs!$J$476
Name _ent11: [1]Inputs!$J$527
Name _ent12: [1]Inputs!$J$578
Name _ent13: [1]Inputs!$J$629
Name _ent14: [1]Inputs!$J$680
Name _ent15: [1]Inputs!$J$731
Name _ent2: [1]Inputs!$J$68
Name _ent3: [1]Inputs!$J$119
Name _ent4: [1]Inputs!$J$170
Name _ent5: [1]Inputs!$J$221
Name _ent6: [1]Inputs!$J$272
Name _ent7: [1]Inputs!$J$323
Name _ent8: [1]Inputs!$J$374
Name _ent9: [1]Inputs!$J$425
Name _eps1: [1]Inputs!$P$42
Name _eps10: [1]Inputs!$P$501
Name _eps11: [1]Inputs!$P$552
Name _eps12: [1]Inputs!$P$603
Name _eps13: [1]Inputs!$P$654
Name _eps14: [1]Inputs!$P$705
Name _eps15: [1]Inputs!$P$756
Name _eps2: [1]Inputs!$P$93
Name _eps3: [1]Inputs!$P$144
Name _eps4: [1]Inputs!$P$195
Name _eps5: [1]Inputs!$P$246
Name _eps6: [1]Inputs!$P$297
Name _eps7: [1]Inputs!$P$348
Name _eps8: [1]Inputs!$P$399

Sheet Capitalisation
A2: 2Q26
B4: in billions
B5: Debt Maturity Profile at 30-Jun-2026 (from BBG) | C5: KRW bn
B6: 2026 | C6: 4061.3983
B7: 2027 | C7: 13694.293
B8: 2028 | C8: 12476.347
B9: 2029 | C9: 10764.291
B10: 2030 | C10: 4714.5643
B11: 2031 & thereafter | C11: =63085.00401-SUM(C6:C10) -> 17374.111
B12: Total | C12: =SUM(C6:C11) -> 63085.004
A20: 1Q26 | I20: Exchange rate as at end | J20: =Model!$K$203 -> 0.0006636713
I21: LTM Average exchange rate | J21: =Model!$K$204 -> 0.00070219616
B23: Debt Breakdown as on 31-Mar-2026 | C23: KRW mn | D23: Leverage | E23: USD mn | F23: Leverage | I23: Company reported | J23: =C23 -> KRW mn
I24: Total borrowings | J24: 19317665
B25: Current | C25: =SUM(C26:C29) -> 5890940 | E25: =SUM(E26:E28) -> 3909.6478 | I25: Cash and cash equivalents, and others | J25: -54329761
B26: Short-term borrowings | C26: 2522307 | E26: =C26*J20 -> 1673.9828 | I26: Net debt | J26: =SUM(J24:J25) -> -35012096
B27: Current portion of long-term borrowings | C27: 1716223 | E27: =C27*J20 -> 1139.0079 | I27: Net debt / EBITDA | J27: =J26/C46 -> -0.38196958
B28: Current portion of debentures | C28: 1652410 | E28: =C28*J20 -> 1096.6571
B31: Non-current | C31: =SUM(C32:C33) -> 13426725 | E31: =SUM(E32:E33) -> 8910.932
B32: Long-term borrowings | C32: 2675856 | E32: =C32*J20 -> 1775.8888
B33: Debentures | C33: 10750869 | E33: =C33*J20 -> 7135.0432
B35: Lease Obligations | C35: =SUM(C36:C37) -> 2514751 | E35: =SUM(E36:E37) -> 1668.9681
B36: Short-term | C36: =Model!$AG$107 -> 526303 | E36: =C36*J20 -> 349.29219
B37: Long-term | C37: =Model!$AG$108 -> 1988448 | E37: =C37*J20 -> 1319.6759
B39: Total Loans & Borrowings | C39: =C31+C25+C35 -> 21832416 | D39: =C39/C46 -> 0.23818394 | E39: =E31+E25+E35 -> 14489.548 | F39: =E39/E46 -> 0.22511636
B40: Cash and Cash Equivalents | C40: =Model!AG$115 -> 21166904 | E40: =C40*J20 -> 14047.867
B41: Short-term financial instruments | C41: =Model!AG$116 -> 18220075 | E41: =C41*J20 -> 12092.141
B42: Short-term investment assets | C42: =Model!AG$117 -> 14942782 | E42: =C42*J20 -> 9917.0955
B43: Net debt | C43: =C39-C40-C41-C42 -> -32497345 | D43: =C43/C46 -> -0.35453454 | E43: =E39-E40-E41-E42 -> -21567.555 | F43: =E43/E46 -> -0.33508357
B44: Equity | C44: =Model!AG$121 -> 164379799 | E44: =C44*J20 -> 109094.15
B45: Total Capitalisation | C45: =C43+C44 -> 131882454 | E45: =E43+E44 -> 87526.599
B46: LTM Adjusted EBITDA | C46: =Model!$AG$82 -> 91662000 | E46: =C46*J21 -> 64364.705
B47: check | C47: =+C39-Model!AG$114 -> 0
B50: Cash Breakdown as on 31-Mar-2026 | C50: =C23 -> KRW mn | D50: =E23 -> USD mn
B51: Cash and Cash Equivalents | C51: =C40 -> 21166904 | D51: =C51*J20 -> 14047.867
B52: Short-term financial instruments | C52: =C41 -> 18220075 | D52: =C52*J20 -> 12092.141
B53: Short-term investment assets | C53: =C42 -> 14942782 | D53: =C53*J20 -> 9917.0955
B54: Total | C54: =SUM(C51:C53) -> 54329761 | D54: =SUM(D51:D53) -> 36057.103
B57: Debt Maturity Profile at 31-Mar-2026 (from BBG) | C57: =C50 -> KRW mn | D57: =D50 -> USD mn
B58: 2026 | C58: 4303773.9 | D58: =C58*J20 -> 2856.2912
...

Sheet Model
B2: SK Hynix Inc. | C2: Annual | D2: Annual | E2: Annual | F2: Annual | G2: Annual | H2: Annual | I2: Annual | J2: Annual | K2: LTM | M2: Quarters | N2: Quarters | O2: Quarters | P2: Quarters | Q2: Quarters | R2: Quarters | S2: Quarters | T2: Quarters | U2: Quarters | V2: Quarters | W2: Quarters | X2: Quarters | Y2: Quarters | Z2: Quarters | AA2: Quarters | AB2: Quarters | AC2: Quarters | AD2: Quarters | AE2: Quarters | AF2: Quarters | AG2: Quarters | AN2: s
B3: (KRW millions) | C3: 43465 | D3: 43830 | E3: 44196 | F3: 44561 | G3: 44926 | H3: 45291 | I3: 45657 | J3: 46022 | K3: =AG3 -> 46112 | M3: 44286 | N3: 44377 | O3: 44469 | P3: 44561 | Q3: 44651 | R3: 44742 | S3: 44834 | T3: 44926 | U3: 45016 | V3: 45107 | W3: 45199 | X3: 45291 | Y3: 45382 | Z3: 45473 | AA3: 45565 | AB3: 45657 | AC3: 45747 | AD3: 45838 | AE3: 45930 | AF3: 46022 | AG3: 46112
C4: Act | D4: Act | E4: Act | F4: Act | G4: Act | H4: Act | I4: Act | J4: Act | K4: Act | M4: Act | N4: Act | O4: Act | P4: Act | Q4: Act | R4: Act | S4: Act | T4: Act | U4: Act | V4: Act | W4: Act | X4: Act | Y4: Act | Z4: Act | AA4: Act | AB4: Act | AC4: Act | AD4: Act | AE4: Act | AF4: Act | AG4: Act
C5: FY | D5: FY | E5: FY | F5: FY | G5: FY | H5: FY | I5: FY | J5: FY | K5: LTM | M5: 1Q | N5: 2Q | O5: 3Q | P5: 4Q | Q5: 1Q | R5: 2Q | S5: 3Q | T5: 4Q | U5: 1Q | V5: 2Q | W5: 3Q | X5: 4Q | Y5: 1Q | Z5: 2Q | AA5: 3Q | AB5: 4Q | AC5: 1Q | AD5: 2Q | AE5: 3Q | AF5: 4Q | AG5: 1Q
B6: INCOME STATEMENT
B7: Revenue | C7: 40445066 | D7: 26990733 | E7: 31900418 | F7: 42997792 | G7: 44621568 | H7: 32765719 | I7: 66192960 | J7: 97146675 | K7: =SUM(AD7:AG7) -> 132083821 | M7: 8494188 | N7: 10321671 | O7: 11805324 | P7: =F7-SUM(M7:O7) -> 12376609 | Q7: 12155653 | R7: 13811001 | S7: 10982883 | T7: =G7-SUM(Q7:S7) -> 7672031 | U7: 5088111 | V7: 7305933 | W7: 9066171 | X7: =H7-SUM(U7:W7) -> 11305504 | Y7: 12429598 | Z7: 16423258 | AA7: 17573069 | AB7: =I7-SUM(Y7:AA7) -> 19767035 | AC7: 17639141 | AD7: 22231952 | AE7: 24448929 | AF7: =J7-SUM(AC7:AE7) -> 32826653 | AG7: 52576287
B8: % of growth | D8: =(D7/C7)-1 -> -0.33265697 | E8: =(E7/D7)-1 -> 0.18190262 | F8: =(F7/E7)-1 -> 0.3478755 | G8: =(G7/F7)-1 -> 0.037764172 | H8: =(H7/G7)-1 -> -0.26569772 | I8: =(I7/H7)-1 -> 1.0201895 | J8: =(J7/I7)-1 -> 0.46762851 | Q8: =(Q7/M7)-1 -> 0.43105533 | R8: =(R7/N7)-1 -> 0.33805863 | S8: =(S7/O7)-1 -> -0.069666957 | T8: =(T7/P7)-1 -> -0.3801185 | U8: =(U7/Q7)-1 -> -0.58142018 | V8: =(V7/R7)-1 -> -0.47100627 | W8: =(W7/S7)-1 -> -0.17451811 | X8: =(X7/T7)-1 -> 0.47359989 | ... AG8: =(AG7/AC7)-1 -> 1.9806603
B9: Cost of sales | C9: -15180838 | D9: -18818814 | E9: -21089789 | F9: -24045600 | G9: -28993713 | H9: -33299167 | I9: -34364814 | J9: -38455885 | K9: =SUM(AD9:AG9) -> -41815608 | M9: -5765640 | N9: -5982227 | O9: -5974270 | P9: =F9-SUM(M9:O9) -> -6323463 | Q9: -6754457 | R9: -7473340 | S9: -7117303 | T9: =G9-SUM(Q9:S9) -> -7648613 | U9: -6733410 | V9: -8483761 | W9: -9002045 | X9: =H9-SUM(U9:W9) -> -9079951 | Y9: -7634953 | Z9: -8926794 | AA9: -8401685 | AB9: =I9-SUM(Y9:AA9) -> -9401382 | AC9: -7537150 | AD9: -10248628 | AE9: =-10419829 -> -10419829 | AF9: =J9-SUM(AC9:AE9) -> -10250278 | AG9: -10896873
B10: Gross Profit | C10: =C7+C9 -> 25264228 | D10: =D7+D9 -> 8171919 | E10: =E7+E9 -> 10810629 | F10: =F7+F9 -> 18952192 | G10: =G7+G9 -> 15627855 | H10: =H7+H9 -> -533448 | I10: =I7+I9 -> 31828146 | J10: =J7+J9 -> 58690790 | K10: =K7+K9 -> 90268213 | M10: =M7+M9 -> 2728548 | N10: =N7+N9 -> 4339444 | O10: =O7+O9 -> 5831054 | P10: =P7+P9 -> 6053146 | Q10: =Q7+Q9 -> 5401196 | R10: =R7+R9 -> 6337661 | S10: =S7+S9 -> 3865580 | T10: =T7+T9 -> 23418 | ... AG10: =AG7+AG9 -> 41679414
B11: Gross Profit margin | C11: =C10/C7 -> 0.62465538 | D11: =D10/D7 -> 0.30276758 | E11: =E10/E7 -> 0.33888675 | F11: =F10/F7 -> 0.44077128 | G11: =G10/G7 -> 0.35023097 | H11: =H10/H7 -> -0.016280674 | I11: =I10/I7 -> 0.48083884 | J11: =J10/J7 -> 0.60414615 | K11: =K10/K7 -> 0.68341612 | M11: =M10/M7 -> 0.32122529 | N11: =N10/N7 -> 0.42042069 | O11: =O10/O7 -> 0.49393426 | P11: =P10/P7 -> 0.48907952 | Q11: =Q10/Q7 -> 0.44433615 | R11: =R10/R7 -> 0.45888499 | S11: =S10/S7 -> 0.35196405 | T11: =T10/T7 -> 0.003052386 | ... AG11: =AG10/AG7 -> 0.79274168
B12: Operating expenses:
B13: Selling and administrative expenses | C13: -4420478 | D13: -5452740 | E13: -5798005 | F13: -6541852 | G13: -8818438 | H13: -7196865 | I13: -8360827 | J13: -11484471 | K13: =SUM(AD13:AG13) -> -12892115 | M13: -1404127 | N13: -1644870 | O13: -1659233 | P13: =F13-SUM(M13:O13) -> -1833622 | Q13: -2537299 | R13: -2140435 | S13: -2205057 | T13: =G13-SUM(Q13:S13) -> -1935647 | U13: -1757003 | V13: -1704256 | W13: -1856087 | X13: =H13-SUM(U13:W13) -> -1879519 | Y13: -1908616 | Z13: -2027928 | AA13: -2141426 | AB13: =I13-SUM(Y13:AA13) -> -2282857 | AC13: -2661487 | AD13: -2770473 | AE13: -2645710 | AF13: =J13-SUM(AC13:AE13) -> -3406801 | AG13: -4069131
B14: Operating profit | C14: =C10+SUM(C13:C13) -> 20843750 | D14: =D10+SUM(D13:D13) -> 2719179 | E14: =E10+SUM(E13:E13) -> 5012624 | F14: =F10+SUM(F13:F13) -> 12410340 | G14: =G10+SUM(G13:G13) -> 6809417 | H14: =H10+SUM(H13:H13) -> -7730313 | I14: =I10+SUM(I13:I13) -> 23467319 | J14: =J10+SUM(J13:J13) -> 47206319 | K14: =K10+SUM(K13:K13) -> 77376098 | M14: =M10+SUM(M13:M13) -> 1324421 | N14: =N10+SUM(N13:N13) -> 2694574 | O14: =O10+SUM(O13:O13) -> 4171821 | P14: =P10+SUM(P13:P13) -> 4219524 | Q14: =Q10+SUM(Q13:Q13) -> 2863897 | R14: =R10+SUM(R13:R13) -> 4197226 | S14: =S10+SUM(S13:S13) -> 1660523 | T14: =T10+SUM(T13:T13) -> -1912229 | ... AG14: =AG10+SUM(AG13:AG13) -> 37610283
B15: Finance income | C15: 1691955 | D15: 1247640 | E15: 3327905 | F15: 2377516 | G15: 3714278 | H15: 2261801 | I15: 4855082 | J15: 16373480 | K15: =SUM(AD15:AG15) -> 30742471 | M15: 597565 | N15: 216373 | O15: 649820 | P15: =F15-SUM(M15:O15) -> 913758 | Q15: 657956 | R15: 1425304 | S15: 2095629 | T15: =G15-SUM(Q15:S15) -> -464611 | U15: 1073308 | V15: =447027 -> 447027 | W15: 668230 | X15: =H15-SUM(U15:W15) -> 73236 | Y15: 1117553 | Z15: 915411 | AA15: 1594457 | AB15: =I15-SUM(Y15:AA15) -> 1227661 | AC15: 2687359 | AD15: 1719380 | AE15: =4490315 -> 4490315 | AF15: =J15-SUM(AC15:AE15) -> 7476426 | AG15: 17056350
B16: Finance expenses | C16: -1142134 | D16: -1531417 | E16: -1980411 | F16: -1469860 | G16: -5091553 | H16: -6093167 | I16: -5707997 | J16: -12504998 | K16: =SUM(AD16:AG16) -> -14763877 | M16: -589521 | N16: -216686 | O16: -274108 | P16: =F16-SUM(M16:O16) -> -389545 | Q16: -737321 | R16: -1814401 | S16: -2064165 | T16: =G16-SUM(Q16:S16) -> -475666 | U16: -1202394 | V16: -1312018 | W16: -1141653 | X16: =H16-SUM(U16:W16) -> -2437102 | Y16: -1625139 | Z16: -1312751 | AA16: -1778636 | AB16: =I16-SUM(Y16:AA16) -> -991471 | AC16: -764604 | AD16: -2172268 | AE16: -1092286 | AF16: =J16-SUM(AC16:AE16) -> -8475840 | AG16: -3023483
B17: Share of profit of equity-accounted investees | C17: 13007 | D17: 22633 | E17: -36279 | F17: 162280 | G17: 131186 | H17: 15061 | I17: -38245 | J17: -564553 | K17: =SUM(AD17:AG17) -> -550222 | M17: 17479 | N17: 125458 | O17: 41493 | P17: =F17-SUM(M17:O17) -> -22150 | Q17: 31967 | R17: 60752 | S17: 26526 | T17: =G17-SUM(Q17:S17) -> 11941 | U17: 2745 | V17: 10102 | W17: 6011 | X17: =H17-SUM(U17:W17) -> -3797 | Y17: 6161 | Z17: 782 | AA17: 6798 | AB17: =I17-SUM(Y17:AA17) -> -51986 | AC17: -41109 | AD17: 17312 | AE17: -23221 | AF17: =J17-SUM(AC17:AE17) -> -517535 | AG17: -26778
B18: Other income | C18: 112810 | D18: 88179 | E18: 84773 | F18: 116135 | G18: 241371 | H18: 623867 | I18: 1476579 | J18: 333277 | K18: =SUM(AD18:AG18) -> 269357 | M18: 16927 | N18: 31826 | O18: 29869 | P18: =F18-SUM(M18:O18) -> 37513 | Q18: 26111 | R18: 158041 | S18: 30097 | T18: =G18-SUM(Q18:S18) -> 27122 | U18: 18891 | V18: 7210 | W18: 234157 | X18: =H18-SUM(U18:W18) -> 363609 | Y18: 27478 | Z18: 16781 | AA18: 57239 | AB18: =I18-SUM(Y18:AA18) -> 1375081 | AC18: 78943 | AD18: 29879 | AE18: =54827 -> 54827 | AF18: =J18-SUM(AC18:AE18) -> 169628 | AG18: 15023
B19: Other expenses | C19: -178358 | D19: -113575 | E19: -171575 | F19: -180424 | G19: -1801919 | H19: -735065 | I19: -167388 | J19: -377973 | K19: =SUM(AD19:AG19) -> -290646 | M19: -16279 | N19: -50437 | O19: -20260 | P19: =F19-SUM(M19:O19) -> -93448 | Q19: -64078 | R19: -55586 | S19: -60401 | T19: =G19-SUM(Q19:S19) -> -1621854 | U19: -15431 | V19: -58444 | W19: -444441 | X19: =H19-SUM(U19:W19) -> -216749 | Y19: -39507 | Z19: -36572 | AA19: -30643 | AB19: =I19-SUM(Y19:AA19) -> -60666 | AC19: -101864 | AD19: -84571 | AE19: -22597 | AF19: =J19-SUM(AC19:AE19) -> -168941 | AG19: -14537
B20: Profit before tax | C20: =C14+SUM(C15:C19) -> 21341030 | D20: =D14+SUM(D15:D19) -> 2432639 | E20: =E14+SUM(E15:E19) -> 6237037 | F20: =F14+SUM(F15:F19) -> 13415987 | G20: =G14+SUM(G15:G19) -> 4002780 | H20: =H14+SUM(H15:H19) -> -11657816 | I20: =I14+SUM(I15:I19) -> 23885350 | J20: =J14+SUM(J15:J19) -> 50465552 | K20: =K14+SUM(K15:K19) -> 92783181 | M20: =M14+SUM(M15:M19) -> 1350592 | N20: =N14+SUM(N15:N19) -> 2801108 | O20: =O14+SUM(O15:O19) -> 4598635 | P20: =P14+SUM(P15:P19) -> 4665652 | Q20: =Q14+SUM(Q15:Q19) -> 2778532 | R20: =R14+SUM(R15:R19) -> 3971336 | S20: =S14+SUM(S15:S19) -> 1688209 | T20: =T14+SUM(T15:T19) -> -4435297 | ... AG20: =AG14+SUM(AG15:AG19) -> 51616858
B21: Income tax expense (benefit) | C21: -5801046 | D21: -423561 | E21: -1478123 | F21: -3799799 | G21: -1761111 | H21: 2520269 | I21: -4088448 | J21: -7517650 | K21: =SUM(AD21:AG21) -> -17597565 | M21: -357952 | N21: -812684 | O21: -1283383 | P21: =F21-SUM(M21:O21) -> -1345780 | Q21: -791322 | R21: -1089906 | S21: -580592 | T21: =G21-SUM(Q21:S21) -> 700709 | U21: 939692 | V21: 800300 | W21: 284958 | X21: =H21-SUM(U21:W21) -> 495319 | Y21: -455536 | Z21: -932184 | AA21: -1125800 | AB21: =I21-SUM(Y21:AA21) -> -1574928 | AC21: -1191034 | AD21: -1726367 | AE21: -2192890 | AF21: =J21-SUM(AC21:AE21) -> -2407359 | AG21: -11270949
B22: Net profit/loss | C22: =+C20+C21 -> 15539984 | D22: =+D20+D21 -> 2009078 | E22: =+E20+E21 -> 4758914 | F22: =+F20+F21 -> 9616188 | G22: =+G20+G21 -> 2241669 | H22: =+H20+H21 -> -9137547 | I22: =+I20+I21 -> 19796902 | J22: =+J20+J21 -> 42947902 | K22: =+K20+K21 -> 75185616 | M22: =+M20+M21 -> 992640 | N22: =+N20+N21 -> 1988424 | O22: =+O20+O21 -> 3315252 | P22: =+P20+P21 -> 3319872 | Q22: =+Q20+Q21 -> 1987210 | R22: =+R20+R21 -> 2881430 | S22: =+S20+S21 -> 1107617 | T22: =+T20+T21 -> -3734588 | ... AG22: =+AG20+AG21 -> 40345909
B23: % margin | C23: =+C22/C7 -> 0.38422447 | D23: =+D22/D7 -> 0.074435844 | E23: =+E22/E7 -> 0.1491803 | F23: =+F22/F7 -> 0.22364376 | G23: =+G22/G7 -> 0.050237343 | H23: =+H22/H7 -> -0.27887522 | I23: =+I22/I7 -> 0.29907866 | J23: =+J22/J7 -> 0.44209338 | K23: =+K22/K7 -> 0.56922654 | M23: =+M22/M7 -> 0.11686108 | N23: =+N22/N7 -> 0.19264555 | O23: =+O22/O7 -> 0.28082685 | P23: =+P22/P7 -> 0.26823761 | Q23: =+Q22/Q7 -> 0.16348032 | R23: =+R22/R7 -> 0.20863296 | S23: =+S22/S7 -> 0.10084939 | T23: =+T22/T7 -> -0.48677958 | ... AG23: =+AG22/AG7 -> 0.76737844
B24: Non-controlling interest | C24: 127 | D24: -3103 | E24: -3812 | F24: -13872 | G24: -12109 | H24: 25119 | I24: -8221 | J24: -28615 | K24: =SUM(AD24:AG24) -> -43234 | M24: -2194 | N24: -3909 | O24: -4429 | P24: =F24-SUM(M24:O24) -> -3340 | Q24: -4084 | R24: -5282 | S24: 4088 | T24: =G24-SUM(Q24:S24) -> -6831 | U24: 5082 | V24: -3274 | W24: 966 | X24: =H24-SUM(U24:W24) -> 22345 | Y24: 2212 | Z24: 276 | AA24: -4697 | AB24: =I24-SUM(Y24:AA24) -> -6012 | AC24: -1114 | AD24: 1012 | AE24: -2343 | AF24: =J24-SUM(AC24:AE24) -> -26170 | AG24: -15733
B25: Net profit/loss | C25: =+C22+C24 -> 15540111 | D25: =+D22+D24 -> 2005975 | E25: =+E22+E24 -> 4755102 | F25: =+F22+F24 -> 9602316 | G25: =+G22+G24 -> 2229560 | H25: =+H22+H24 -> -9112428 | I25: =+I22+I24 -> 19788681 | J25: =+J22+J24 -> 42919287 | K25: =+K22+K24 -> 75142382 | M25: =+M22+M24 -> 990446 | N25: =+N22+N24 -> 1984515 | O25: =+O22+O24 -> 3310823 | P25: =+P22+P24 -> 3316532 | Q25: =+Q22+Q24 -> 1983126 | R25: =+R22+R24 -> 2876148 | S25: =+S22+S24 -> 1111705 | T25: =+T22+T24 -> -3741419 | ... AG25: =+AG22+AG24 -> 40330176
B27: As % of sales unless stated otherwise
B28: =B13 -> Selling and administrative expenses | C28: =-C13/C7 -> 0.10929585 | D28: =-D13/D7 -> 0.20202267 | E28: =-E13/E7 -> 0.18175326 | F28: =-F13/F7 -> 0.15214391 | G28: =-G13/G7 -> 0.19762726 | H28: =-H13/H7 -> 0.21964618 | I28: =-I13/I7 -> 0.12630991 | J28: =-J13/J7 -> 0.11821785 | K28: =-K13/K7 -> 0.097605558 | M28: =-M13/M7 -> 0.16530444 | N28: =-N13/N7 -> 0.15936082 | O28: =-O13/O7 -> 0.14054955 | P28: =-P13/P7 -> 0.14815221 | Q28: =-Q13/Q7 -> 0.20873408 | R28: =-R13/R7 -> 0.15498044 | S28: =-S13/S7 -> 0.20077215 | T28: =-T13/T7 -> 0.25229916 | ... AG28: =-AG13/AG7 -> 0.077394796
B29: Finance expenses as % of debt | C29: =-C16/C104 -> 0.21623393 | D29: =-D16/D104 -> 0.14552346 | E29: =-E16/E104 -> 0.17601075 | F29: =-F16/F104 -> 0.083401948 | G29: =-G16/G104 -> 0.22142382 | H29: =-H16/H104 -> 0.20676789 | I29: =-I16/I104 -> 0.25163394 | J29: =-J16/J104 -> 0.56207531 | K29: =-K16/K104 -> 0.7642682 | P29: {=-SUM(M16:P16/P104)} -> 0.083401948 | Q29: {=-SUM(N16:Q16/Q104)} -> 0.089306215 | R29: {=-SUM(O16:R16/R104)} -> 0.16589404 | S29: {=-SUM(P16:S16/S104)} -> 0.22729778 | T29: {=-SUM(Q16:T16/T104)} -> 0.22142382 | U29: {=-SUM(R16:U16/U104)} -> 0.19322171 | V29: {=-SUM(S16:V16/V104)} -> 0.16406412 | W29: {=-SUM(T16:W16/W104)} -> 0.13092244 | ... AG29: {=-SUM(AD16:AG16/AG104)} -> 0.7642682
B30: Finance income as % of cash and cash equivalents | C30: =C15/C115 -> 0.72018955 | D30: =D15/D115 -> 0.54102434 | E30: =E15/E115 -> 1.1182518 | F30: =F15/F115 -> 0.47005229 | G30: =G15/G115 -> 0.74628748 | H30: =H15/H115 -> 0.2981024 | I30: =I15/I115 -> 0.4332915 | J30: =J15/J115 -> 1.0971413 | K30: =K15/K115 -> 1.4523839 | P30: =SUM(M15:P15)/P115 -> 0.47005229 | Q30: =SUM(N15:Q15)/Q115 -> 0.489268 | R30: =SUM(O15:R15)/R115 -> 0.80215304 | S30: =SUM(P15:S15)/S115 -> 1.0791297 | T30: =SUM(Q15:T15)/T115 -> 0.74628748 | U30: =SUM(R15:U15)/U115 -> 0.84368007 | V30: =SUM(S15:V15)/V115 -> 0.52167723 | W30: =SUM(T15:W15)/W115 -> 0.24204998 | ... AG30: =SUM(AD15:AG15)/AG115 -> 1.4523839
B31: Other income | C31: =C18/C7 -> 0.0027892154 | D31: =D18/D7 -> 0.0032670102 | E31: =E18/E7 -> 0.002657426 | F31: =F18/F7 -> 0.0027009526 | G31: =G18/G7 -> 0.00540929 | H31: =H18/H7 -> 0.019040235 | I31: =I18/I7 -> 0.022307191 | J31: =J18/J7 -> 0.0034306578 | K31: =K18/K7 -> 0.0020392884 | M31: =M18/M7 -> 0.0019927744 | N31: =N18/N7 -> 0.0030834155 | O31: =O18/O7 -> 0.0025301296 | P31: =P18/P7 -> 0.0030309594 | Q31: =Q18/Q7 -> 0.0021480541 | R31: =R18/R7 -> 0.011443124 | S31: =S18/S7 -> 0.0027403552 | T31: =T18/T7 -> 0.0035351786 | ... AG31: =AG18/AG7 -> 0.00028573718
B32: Other expenses | C32: =-C19/C7 -> 0.0044098828 | D32: =-D19/D7 -> 0.0042079257 | E32: =-E19/E7 -> 0.0053784562 | F32: =-F19/F7 -> 0.0041961224 | G32: =-G19/G7 -> 0.040382243 | H32: =-H19/H7 -> 0.022433965 | I32: =-I19/I7 -> 0.0025287886 | J32: =-J19/J7 -> 0.0038907456 | K32: =-K19/K7 -> 0.0022004663 | M32: =-M19/M7 -> 0.0019164869 | N32: =-N19/N7 -> 0.004886515 | O32: =-O19/O7 -> 0.0017161748 | P32: =-P19/P7 -> 0.0075503718 | Q32: =-Q19/Q7 -> 0.0052714568 | R32: =-R19/R7 -> 0.0040247626 | S32: =-S19/S7 -> 0.0054995578 | T32: =-T19/T7 -> 0.21139826 | ... AG32: =-AG19/AG7 -> 0.00027649347
B33: Tax % of PBT | C33: =-C21/C20 -> 0.27182596 | D33: =-D21/D20 -> 0.17411585 | E33: =-E21/E20 -> 0.23699122 | F33: =-F21/F20 -> 0.28322918 | G33: =-G21/G20 -> 0.43997197 | H33: =-H21/H20 -> 0.21618706 | I33: =-I21/I20 -> 0.17116969 | J33: =-J21/J20 -> 0.14896597 | K33: =-K21/K20 -> 0.18966331 | M33: =-M21/M20 -> 0.26503341 | N33: =-N21/N20 -> 0.29012948 | O33: =-O21/O20 -> 0.27907912 | P33: =-P21/P20 -> 0.28844414 | Q33: =-Q21/Q20 -> 0.28479859 | R33: =-R21/R20 -> 0.27444316 | S33: =-S21/S20 -> 0.34391003 | T33: =-T21/T20 -> 0.15798469 | ... AG33: =-AG21/AG20 -> 0.21835791
B35: Working capital /sales | C35: =C55/C7 -> -0.056146923 | D35: =D55/D7 -> 0.040180902 | E35: =E55/E7 -> -0.048812903 | F35: =F55/F7 -> -0.079545038 | G35: =G55/G7 -> -0.060713398 | H35: =H55/H7 -> 0.021783041 | I35: =I55/I7 -> -0.070344384 | J35: =J55/J7 -> -0.059494707 | K35: =K55/K7 -> -0.17292883 | M35: =M55/M7 -> -0.014361231 | N35: =N55/N7 -> -0.12383247 | O35: =O55/O7 -> -0.087092993 | P35: =P55/P7 -> -0.080147559 | Q35: =Q55/Q7 -> -0.02581153 | R35: =R55/R7 -> -0.12330707 | S35: =S55/S7 -> -0.14631914 | T35: =T55/T7 -> 0.11921602 | ... AG35: =AG55/AG7 -> -0.3089093
B36: Capex/sales | C36: =-C59/C7 -> 0.39323442 | D36: =-D59/D7 -> 0.51374685 | E36: =-E59/E7 -> 0.31377561 | F36: =-F59/F7 -> 0.28854261 | G36: =-G59/G7 -> 0.41877827 | H36: =-H59/H7 -> 0.20708573 | I36: =-I59/I7 -> 0.24018276 | J36: =-J59/J7 -> 0.28178109 | K36: =-K59/K7 -> 0.2178813 | M36: =-M59/M7 -> 0.46905767 | N36: =-N59/N7 -> 0.28091614 | O36: =-O59/O7 -> 0.23609356 | P36: =-P59/P7 -> 0.22104164 | Q36: =-Q59/Q7 -> 0.42881588 | R36: =-R59/R7 -> 0.33045534 | S36: =-S59/S7 -> 0.43538969 | T36: =-T59/T7 -> 0.53809128 | ... AG36: =-AG59/AG7 -> 0.1453642
B38: EBITDA | C38: =C3 -> 43465 | D38: =D3 -> 43830 | E38: =E3 -> 44196 | F38: =F3 -> 44561 | G38: =G3 -> 44926 | H38: =H3 -> 45291 | I38: =I3 -> 45657 | J38: =J3 -> 46022 | K38: =K2 -> LTM | M38: =M3 -> 44286 | N38: =N3 -> 44377 | O38: =O3 -> 44469 | P38: =P3 -> 44561 | Q38: =Q3 -> 44651 | R38: =R3 -> 44742 | S38: =S3 -> 44834 | T38: =T3 -> 44926 | ... AG38: =AG3 -> 46112
B39: Operating profit | C39: =C14 -> 20843750 | D39: =D14 -> 2719179 | E39: =E14 -> 5012624 | F39: =F14 -> 12410340 | G39: =G14 -> 6809417 | H39: =H14 -> -7730313 | I39: =I14 -> 23467319 | J39: =J14 -> 47206319 | K39: =K14 -> 77376098 | M39: =M14 -> 1324421 | N39: =N14 -> 2694574 | O39: =O14 -> 4171821 | P39: =P14 -> 4219524 | Q39: =Q14 -> 2863897 | R39: =R14 -> 4197226 | S39: =S14 -> 1660523 | T39: =T14 -> -1912229 | ... AG39: =AG14 -> 37610283
B40: Depreciation, depletion & amortization | C40: 6309070 | D40: 8605492 | E40: 9764776 | F40: 10646887 | G40: 14135292 | H40: 13619161 | I40: 12544767 | J40: 13889639 | K40: =SUM(AD40:AG40) -> 14281476 | M40: 2532934 | N40: 2614665 | O40: 2708159 | P40: =F40-SUM(M40:O40) -> 2791129 | Q40: 3391643 | R40: 3478314 | S40: 3552718 | T40: =G40-SUM(Q40:S40) -> 3712617 | U40: 3556847 | V40: 3493623 | W40: 3332583 | X40: =H40-SUM(U40:W40) -> 3236108 | Y40: 3186882 | Z40: 3122193 | AA40: 3070447 | AB40: =I40-SUM(Y40:AA40) -> 3165245 | AC40: 3333928 | AD40: 3442889 | AE40: 3549343 | AF40: =J40-SUM(AC40:AE40) -> 3563479 | AG40: 3725765
B41: EBITDA | C41: =SUM(C39:C40) -> 27152820 | D41: =SUM(D39:D40) -> 11324671 | E41: =SUM(E39:E40) -> 14777400 | F41: =SUM(F39:F40) -> 23057227 | G41: =SUM(G39:G40) -> 20944709 | H41: =SUM(H39:H40) -> 5888848 | I41: =SUM(I39:I40) -> 36012086 | J41: =SUM(J39:J40) -> 61095958 | K41: =SUM(K39:K40) -> 91657574 | M41: =SUM(M39:M40) -> 3857355 | N41: =SUM(N39:N40) -> 5309239 | O41: =SUM(O39:O40) -> 6879980 | P41: =SUM(P39:P40) -> 7010653 | Q41: =SUM(Q39:Q40) -> 6255540 | R41: =SUM(R39:R40) -> 7675540 | S41: =SUM(S39:S40) -> 5213241 | T41: =SUM(T39:T40) -> 1800388 | ... AG41: =SUM(AG39:AG40) -> 41336048
B42: % growth | D42: =+D41/C41-1 -> -0.58292837 | E42: =+E41/D41-1 -> 0.30488559 | F42: =+F41/E41-1 -> 0.56030337 | G42: =+G41/F41-1 -> -0.091620645 | H42: =+H41/G41-1 -> -0.71883839 | I42: =+I41/H41-1 -> 5.1153023 | J42: =+J41/I41-1 -> 0.69654038 | Q42: =Q41/M41-1 -> 0.62171747 | R42: =R41/N41-1 -> 0.44569495 | S42: =S41/O41-1 -> -0.24225928 | T42: =T41/P41-1 -> -0.74319254 | U42: =U41/Q41-1 -> -0.9752947 | V42: =V41/R41-1 -> -0.92032626 | W42: =W41/S41-1 -> -0.70447904 | X42: =X41/T41-1 -> 0.98965001 | ... AG42: =AG41/AC41-1 -> 2.8364944
B43: % margin | C43: =+C41/C7 -> 0.67135062 | D43: =+D41/D7 -> 0.41957627 | E43: =+E41/E7 -> 0.46323531 | F43: =+F41/F7 -> 0.53624212 | G43: =+G41/G7 -> 0.46938532 | H43: =+H41/H7 -> 0.17972589 | I43: =+I41/I7 -> 0.54404707 | J43: =+J41/J7 -> 0.62890426 | K43: =+K41/K7 -> 0.69393491 | M43: =+M41/M7 -> 0.45411698 | N43: =+N41/N7 -> 0.51437786 | O43: =+O41/O7 -> 0.58278621 | P43: =+P41/P7 -> 0.56644377 | Q43: =+Q41/Q7 -> 0.51461982 | R43: =+R41/R7 -> 0.55575552 | S43: =+S41/S7 -> 0.47466963 | T43: =+T41/T7 -> 0.23466902 | ... AG43: =+AG41/AG7 -> 0.78621086
B45: Adjustment | C45: =C46-C41 -> 107180 | D45: =D46-D41 -> -73671 | E45: =E46-E41 -> 25600 | F45: =F46-F41 -> -227 | G45: =G46-G41 -> 3291 | H45: =H46-H41 -> 152 | I45: =I46-I41 -> 914 | J45: =J46-J41 -> -958 | K45: =K46-K41 -> 4426 | M45: =M46-M41 -> -355 | N45: =N46-N41 -> -239 | O45: =O46-O41 -> 20 | P45: =P46-P41 -> 347 | Q45: =Q46-Q41 -> 460 | R45: =R46-R41 -> -3540 | S45: =S46-S41 -> 6759 | T45: =T46-T41 -> -388 | ... AG45: =AG46-AG41 -> -48
...

Sheet KPIs
B2: SK Hynix Inc. | C2: Annual | D2: Annual | E2: Annual | F2: Annual | G2: Annual | H2: Annual | I2: Annual | J2: Annual | K2: LTM | M2: Quarters | N2: Quarters | O2: Quarters | P2: Quarters | Q2: Quarters | R2: Quarters | S2: Quarters | T2: Quarters | U2: Quarters | V2: Quarters | W2: Quarters | X2: Quarters | Y2: Quarters | Z2: Quarters | AA2: Quarters | AB2: Quarters | AC2: Quarters | AD2: Quarters | AE2: Quarters | AF2: Quarters | AG2: Quarters
B3: (KRW millions) | C3: 43465 | D3: 43830 | E3: 44196 | F3: 44561 | G3: 44926 | H3: 45291 | I3: 45657 | J3: 46022 | K3: =AG3 -> 46112 | M3: 44286 | N3: 44377 | O3: 44469 | P3: 44561 | Q3: 44651 | R3: 44742 | S3: 44834 | T3: 44926 | U3: 45016 | V3: 45107 | W3: 45199 | X3: 45291 | Y3: 45382 | Z3: 45473 | AA3: 45565 | AB3: 45657 | AC3: 45747 | AD3: 45838 | AE3: 45930 | AF3: 46022 | AG3: 46112
C4: Act | D4: Act | E4: Act | F4: Act | G4: Act | H4: Act | I4: Act | J4: Act | K4: Act | M4: Act | N4: Act | O4: Act | P4: Act | Q4: Act | R4: Act | S4: Act | T4: Act | U4: Act | V4: Act | W4: Act | X4: Act | Y4: Act | Z4: Act | AA4: Act | AB4: Act | AC4: Act | AD4: Act | AE4: Act | AF4: Act | AG4: Act
C5: FY | D5: FY | E5: FY | F5: FY | G5: FY | H5: FY | I5: FY | J5: FY | K5: FY | M5: 1Q | N5: 2Q | O5: 3Q | P5: 4Q | Q5: 1Q | R5: 2Q | S5: 3Q | T5: 4Q | U5: 1Q | V5: 2Q | W5: 3Q | X5: 4Q | Y5: 1Q | Z5: 2Q | AA5: 3Q | AB5: 4Q | AC5: 1Q | AD5: 2Q | AE5: 3Q | AF5: 4Q | AG5: 1Q
B7: Revenue by type
B8: Sale of goods | C8: 40388846 | D8: 26922416 | E8: 31837538 | F8: 42932963 | G8: 44540140 | H8: 32680033 | I8: 66100890 | J8: 97024278 | K8: =SUM(AD8:AG8) -> 131961631 | M8: 8479145 | N8: 10303146 | O8: 11789903 | P8: =F8-SUM(M8:O8) -> 12360769 | Q8: 12139578 | R8: 13789311 | S8: 10962408 | T8: =G8-SUM(Q8:S8) -> 7648843 | U8: 5073063 | V8: 7255332 | W8: 9047470 | X8: =H8-SUM(U8:W8) -> 11304168 | Y8: 12408716 | Z8: 16402538 | AA8: 17552396 | AB8: =I8-SUM(Y8:AA8) -> 19737240 | AC8: 17608044 | AD8: 22201681 | AE8: 24417726 | AF8: =J8-SUM(AC8:AE8) -> 32796827 | AG8: 52545397
B9: Providing services | C9: 56220 | D9: 68317 | E9: 62880 | F9: 64829 | G9: 81428 | H9: 85686 | I9: 92070 | J9: 122397 | K9: =SUM(AD9:AG9) -> 122190 | M9: 15043 | N9: 18525 | O9: 15421 | P9: =F9-SUM(M9:O9) -> 15840 | Q9: 16075 | R9: 21690 | S9: 20475 | T9: =G9-SUM(Q9:S9) -> 23188 | U9: 15048 | V9: 50601 | W9: 18701 | X9: =H9-SUM(U9:W9) -> 1336 | Y9: 20882 | Z9: 20720 | AA9: 20673 | AB9: =I9-SUM(Y9:AA9) -> 29795 | AC9: 31097 | AD9: 30271 | AE9: 31203 | AF9: =J9-SUM(AC9:AE9) -> 29826 | AG9: 30890
B10: Net Revenue | C10: =SUM(C8:C9) -> 40445066 | D10: =SUM(D8:D9) -> 26990733 | E10: =SUM(E8:E9) -> 31900418 | F10: =SUM(F8:F9) -> 42997792 | G10: =SUM(G8:G9) -> 44621568 | H10: =SUM(H8:H9) -> 32765719 | I10: =SUM(I8:I9) -> 66192960 | J10: =SUM(J8:J9) -> 97146675 | K10: =SUM(K8:K9) -> 132083821 | M10: =SUM(M8:M9) -> 8494188 | N10: =SUM(N8:N9) -> 10321671 | O10: =SUM(O8:O9) -> 11805324 | P10: =SUM(P8:P9) -> 12376609 | Q10: =SUM(Q8:Q9) -> 12155653 | R10: =SUM(R8:R9) -> 13811001 | S10: =SUM(S8:S9) -> 10982883 | T10: =SUM(T8:T9) -> 7672031 | ... AG10: =SUM(AG8:AG9) -> 52576287
B11: check | C11: =C10-Model!C7 -> 0 | D11: =D10-Model!D7 -> 0 | E11: =E10-Model!E7 -> 0 | F11: =F10-Model!F7 -> 0 | G11: =G10-Model!G7 -> 0 | H11: =H10-Model!H7 -> 0 | I11: =I10-Model!I7 -> 0 | J11: =J10-Model!J7 -> 0 | K11: =K10-Model!K7 -> 0 | M11: =M10-Model!M7 -> 0 | N11: =N10-Model!N7 -> 0 | O11: =O10-Model!O7 -> 0 | P11: =P10-Model!P7 -> 0 | Q11: =Q10-Model!Q7 -> 0 | R11: =R10-Model!R7 -> 0 | S11: =S10-Model!S7 -> 0 | T11: =T10-Model!T7 -> 0 | ... AG11: =AG10-Model!AG7 -> 0
B13: Revenue by type (% Share)
B14: Sale of goods | C14: =C8/C$10 -> 0.99860997 | D14: =D8/D$10 -> 0.99746887 | E14: =E8/E$10 -> 0.99802887 | F14: =F8/F$10 -> 0.99849227 | G14: =G8/G$10 -> 0.99817514 | H14: =H8/H$10 -> 0.99738489 | I14: =I8/I$10 -> 0.99860907 | J14: =J8/J$10 -> 0.99874008 | K14: =K8/K$10 -> 0.99907491 | M14: =M8/M$10 -> 0.99822902 | N14: =N8/N$10 -> 0.99820523 | O14: =O8/O$10 -> 0.99869372 | P14: =P8/P$10 -> 0.99872017 | Q14: =Q8/Q$10 -> 0.99867757 | R14: =R8/R$10 -> 0.99842951 | S14: =S8/S$10 -> 0.99813574 | T14: =T8/T$10 -> 0.99697759 | ... AG14: =AG8/AG$10 -> 0.99941247
B15: Providing services | C15: =C9/C$10 -> 0.0013900336 | D15: =D9/D$10 -> 0.002531128 | E15: =E9/E$10 -> 0.001971134 | F15: =F9/F$10 -> 0.0015077286 | G15: =G9/G$10 -> 0.0018248574 | H15: =H9/H$10 -> 0.0026151112 | I15: =I9/I$10 -> 0.0013909334 | J15: =J9/J$10 -> 0.0012599196 | K15: =K9/K$10 -> 0.00092509438 | M15: =M9/M$10 -> 0.0017709756 | N15: =N9/N$10 -> 0.0017947675 | O15: =O9/O$10 -> 0.001306275 | P15: =P9/P$10 -> 0.0012798336 | Q15: =Q9/Q$10 -> 0.00132243 | R15: =R9/R$10 -> 0.0015704872 | S15: =S9/S$10 -> 0.0018642646 | T15: =T9/T$10 -> 0.003022407 | ... AG15: =AG9/AG$10 -> 0.00058752722
B16: Net Revenue | C16: =SUM(C14:C15) -> 1 | D16: =SUM(D14:D15) -> 1 | E16: =SUM(E14:E15) -> 1 | F16: =SUM(F14:F15) -> 1 | G16: =SUM(G14:G15) -> 1 | H16: =SUM(H14:H15) -> 1 | I16: =SUM(I14:I15) -> 1 | J16: =SUM(J14:J15) -> 1 | K16: =SUM(K14:K15) -> 1 | M16: =SUM(M14:M15) -> 1 | N16: =SUM(N14:N15) -> 1 | O16: =SUM(O14:O15) -> 1 | P16: =SUM(P14:P15) -> 1 | Q16: =SUM(Q14:Q15) -> 1 | R16: =SUM(R14:R15) -> 1 | S16: =SUM(S14:S15) -> 1 | T16: =SUM(T14:T15) -> 1 | ... AG16: =SUM(AG14:AG15) -> 1
B18: Revenue by type (% YoY Growth)
B19: Sale of goods | D19: =D8/C8-1 -> -0.33341953 | E19: =E8/D8-1 -> 0.18256616 | F19: =F8/E8-1 -> 0.34850135 | G19: =G8/F8-1 -> 0.03743457 | H19: =H8/G8-1 -> -0.26627907 | I19: =I8/H8-1 -> 1.022669 | J19: =J8/I8-1 -> 0.46782105 | Q19: =Q8/M8-1 -> 0.43169836 | R19: =R8/N8-1 -> 0.33835927 | S19: =S8/O8-1 -> -0.070186752 | T19: =T8/P8-1 -> -0.38120007 | U19: =U8/Q8-1 -> -0.58210549 | V19: =V8/R8-1 -> -0.47384376 | W19: =W8/S8-1 -> -0.17468224 | X19: =X8/T8-1 -> 0.47789254 | ... AG19: =AG8/AC8-1 -> 1.98417
B20: Providing services | D20: =D9/C9-1 -> 0.21517254 | E20: =E9/D9-1 -> -0.079584876 | F20: =F9/E9-1 -> 0.030995547 | G20: =G9/F9-1 -> 0.25604282 | H20: =H9/G9-1 -> 0.052291595 | I20: =I9/H9-1 -> 0.074504587 | J20: =J9/I9-1 -> 0.32939068 | Q20: =Q9/M9-1 -> 0.068603337 | R20: =R9/N9-1 -> 0.1708502 | S20: =S9/O9-1 -> 0.32773491 | T20: =T9/P9-1 -> 0.46388889 | U20: =U9/Q9-1 -> -0.063888025 | V20: =V9/R9-1 -> 1.3329184 | W20: =W9/S9-1 -> -0.086642247 | X20: =X9/T9-1 -> -0.94238399 | ... AG20: =AG9/AC9-1 -> -0.0066565907
B21: Net Revenue | D21: =D10/C10-1 -> -0.33265697 | E21: =E10/D10-1 -> 0.18190262 | F21: =F10/E10-1 -> 0.3478755 | G21: =G10/F10-1 -> 0.037764172 | H21: =H10/G10-1 -> -0.26569772 | I21: =I10/H10-1 -> 1.0201895 | J21: =J10/I10-1 -> 0.46762851 | Q21: =Q10/M10-1 -> 0.43105533 | R21: =R10/N10-1 -> 0.33805863 | S21: =S10/O10-1 -> -0.069666957 | T21: =T10/P10-1 -> -0.3801185 | U21: =U10/Q10-1 -> -0.58142018 | V21: =V10/R10-1 -> -0.47100627 | W21: =W10/S10-1 -> -0.17451811 | X21: =X10/T10-1 -> 0.47359989 | ... AG21: =AG10/AC10-1 -> 1.9806603
B25: Revenue by Products
B26: DRAM | C26: 32370936 | D26: 20292687 | E26: 22536404 | F26: 30599711 | G26: 28168802 | H26: 20768662 | I26: 44731664 | J26: 74904134 | K26: =SUM(AD26:AG26) -> 101525900 | M26: 6062469 | N26: 7505783 | O26: 8312960 | P26: =F26-SUM(M26:O26) -> 8718499 | Q26: 7857576 | R26: 8781735 | S26: 6954326 | T26: =G26-SUM(Q26:S26) -> 4575165 | U26: 2918692 | V26: 4414132 | W26: 6085615 | X26: =H26-SUM(U26:W26) -> 7350223 | Y26: 7493448 | Z26: 10700356 | AA26: 12048412 | AB26: =I26-SUM(Y26:AA26) -> 14489448 | AC26: 14036870 | AD26: 17123990 | AE26: 19083916 | AF26: =J26-SUM(AC26:AE26) -> 24659358 | AG26: 40658636
B27: NAND Flash | C27: 7420857 | D27: 5139563 | E27: 7471242 | F27: 10529447 | G27: 14183923 | H27: 9653061 | I27: 19274112 | J27: 20690084 | K27: =SUM(AD27:AG27) -> 29035484 | M27: 2007523 | N27: 2305681 | O27: 3044004 | P27: =F27-SUM(M27:O27) -> 3172239 | Q27: 3913395 | R27: 4517859 | S27: 3388185 | T27: =G27-SUM(Q27:S27) -> 2364484 | U27: 1688034 | V27: 2240211 | W27: 2426210 | X27: =H27-SUM(U27:W27) -> 3298606 | Y27: 4407213 | Z27: 5184707 | AA27: 4980518 | AB27: =I27-SUM(Y27:AA27) -> 4701674 | AC27: 3228835 | AD27: 4727806 | AE27: 4989186 | AF27: =J27-SUM(AC27:AE27) -> 7744257 | AG27: 11574235
B28: Others | C28: 653273 | D28: 1558483 | E28: 1892772 | F28: 1868634 | G28: 2268843 | H28: 2343996 | I28: 2187184 | J28: 1552457 | K28: =SUM(AD28:AG28) -> 1522437 | M28: 424196 | N28: 510207 | O28: 448360 | P28: =F28-SUM(M28:O28) -> 485871 | Q28: 384682 | R28: 511407 | S28: 640372 | T28: =G28-SUM(Q28:S28) -> 732382 | U28: 481385 | V28: 651590 | W28: 554346 | X28: =H28-SUM(U28:W28) -> 656675 | Y28: 528937 | Z28: 538195 | AA28: 544139 | AB28: =I28-SUM(Y28:AA28) -> 575913 | AC28: 373436 | AD28: 380156 | AE28: 375827 | AF28: =J28-SUM(AC28:AE28) -> 423038 | AG28: 343416
B29: Net Revenue | C29: =SUM(C26:C28) -> 40445066 | D29: =SUM(D26:D28) -> 26990733 | E29: =SUM(E26:E28) -> 31900418 | F29: =SUM(F26:F28) -> 42997792 | G29: =SUM(G26:G28) -> 44621568 | H29: =SUM(H26:H28) -> 32765719 | I29: =SUM(I26:I28) -> 66192960 | J29: =SUM(J26:J28) -> 97146675 | K29: =SUM(K26:K28) -> 132083821 | M29: =SUM(M26:M28) -> 8494188 | N29: =SUM(N26:N28) -> 10321671 | O29: =SUM(O26:O28) -> 11805324 | P29: =SUM(P26:P28) -> 12376609 | Q29: =SUM(Q26:Q28) -> 12155653 | R29: =SUM(R26:R28) -> 13811001 | S29: =SUM(S26:S28) -> 10982883 | T29: =SUM(T26:T28) -> 7672031 | ... AG29: =SUM(AG26:AG28) -> 52576287
B30: check | C30: =C29-Model!C7 -> 0 | D30: =D29-Model!D7 -> 0 | E30: =E29-Model!E7 -> 0 | F30: =F29-Model!F7 -> 0 | G30: =G29-Model!G7 -> 0 | H30: =H29-Model!H7 -> 0 | I30: =I29-Model!I7 -> 0 | J30: =J29-Model!J7 -> 0 | K30: =K29-Model!K7 -> 0 | M30: =M29-Model!M7 -> 0 | N30: =N29-Model!N7 -> 0 | O30: =O29-Model!O7 -> 0 | P30: =P29-Model!P7 -> 0 | Q30: =Q29-Model!Q7 -> 0 | R30: =R29-Model!R7 -> 0 | S30: =S29-Model!S7 -> 0 | T30: =T29-Model!T7 -> 0 | ... AG30: =AG29-Model!AG7 -> 0
B32: Revenue by Products (% Share)
B33: DRAM | C33: =C26/C$29 -> 0.80036799 | D33: =D26/D$29 -> 0.75183905 | E33: =E26/E$29 -> 0.70646109 | F33: =F26/F$29 -> 0.71165773 | G33: =G26/G$29 -> 0.63128221 | H33: =H26/H$29 -> 0.63385339 | I33: =I26/I$29 -> 0.67577676 | J33: =J26/J$29 -> 0.77104166 | K33: =K26/K$29 -> 0.76864751 | M33: =M26/M$29 -> 0.71371966 | N33: =N26/N$29 -> 0.72718681 | O33: =O26/O$29 -> 0.70417042 | P33: =P26/P$29 -> 0.70443358 | Q33: =Q26/Q$29 -> 0.64641332 | R33: =R26/R$29 -> 0.63585073 | S33: =S26/S$29 -> 0.63319677 | T33: =T26/T$29 -> 0.59634339 | ... AG33: =AG26/AG$29 -> 0.7733265
B34: NAND Flash | C34: =C27/C$29 -> 0.18347991 | D34: =D27/D$29 -> 0.19041954 | E34: =E27/E$29 -> 0.23420514 | F34: =F27/F$29 -> 0.24488343 | G34: =G27/G$29 -> 0.31787146 | H34: =H27/H$29 -> 0.29460855 | I34: =I27/I$29 -> 0.29118069 | J34: =J27/J$29 -> 0.21297779 | K34: =K27/K$29 -> 0.2198262 | M34: =M27/M$29 -> 0.23634078 | N34: =N27/N$29 -> 0.22338253 | O34: =O27/O$29 -> 0.2578501 | P34: =P27/P$29 -> 0.25630922 | Q34: =Q27/Q$29 -> 0.32194034 | R34: =R27/R$29 -> 0.32712032 | S34: =S27/S$29 -> 0.30849687 | T34: =T27/T$29 -> 0.30819531 | ... AG34: =AG27/AG$29 -> 0.22014173
B35: Others | C35: =C28/C$29 -> 0.016152106 | D35: =D28/D$29 -> 0.057741411 | E35: =E28/E$29 -> 0.059333768 | F35: =F28/F$29 -> 0.043458836 | G35: =G28/G$29 -> 0.050846331 | H35: =H28/H$29 -> 0.071538061 | I35: =I28/I$29 -> 0.033042547 | J35: =J28/J$29 -> 0.015980547 | K35: =K28/K$29 -> 0.011526294 | M35: =M28/M$29 -> 0.049939559 | N35: =N28/N$29 -> 0.049430659 | O35: =O28/O$29 -> 0.037979474 | P35: =P28/P$29 -> 0.039257199 | Q35: =Q28/Q$29 -> 0.031646346 | R35: =R28/R$29 -> 0.03702896 | S35: =S28/S$29 -> 0.058306366 | T35: =T28/T$29 -> 0.095461293 | ... AG35: =AG28/AG$29 -> 0.0065317659
B36: Net Revenue | C36: =SUM(C33:C35) -> 1 | D36: =SUM(D33:D35) -> 1 | E36: =SUM(E33:E35) -> 1 | F36: =SUM(F33:F35) -> 1 | G36: =SUM(G33:G35) -> 1 | H36: =SUM(H33:H35) -> 1 | I36: =SUM(I33:I35) -> 1 | J36: =SUM(J33:J35) -> 1 | K36: =SUM(K33:K35) -> 1 | M36: =SUM(M33:M35) -> 1 | N36: =SUM(N33:N35) -> 1 | O36: =SUM(O33:O35) -> 1 | P36: =SUM(P33:P35) -> 1 | Q36: =SUM(Q33:Q35) -> 1 | R36: =SUM(R33:R35) -> 1 | S36: =SUM(S33:S35) -> 1 | T36: =SUM(T33:T35) -> 1 | ... AG36: =SUM(AG33:AG35) -> 1
B38: Revenue by Products (% YoY Growth)
B39: DRAM | D39: =D26/C26-1 -> -0.37312017 | E39: =E26/D26-1 -> 0.11056776 | F39: =F26/E26-1 -> 0.35779031 | G39: =G26/F26-1 -> -0.079442221 | H39: =H26/G26-1 -> -0.26270695 | I39: =I26/H26-1 -> 1.1538058 | J39: =J26/I26-1 -> 0.67452152 | Q39: =Q26/M26-1 -> 0.29610164 | R39: =R26/N26-1 -> 0.16999586 | S39: =S26/O26-1 -> -0.16343565 | T39: =T26/P26-1 -> -0.47523479 | U39: =U26/Q26-1 -> -0.62855059 | V39: =V26/R26-1 -> -0.49735081 | W39: =W26/S26-1 -> -0.12491663 | X39: =X26/T26-1 -> 0.60654818 | ... AG39: =AG26/AC26-1 -> 1.89656
B40: NAND Flash | D40: =D27/C27-1 -> -0.30741652 | E40: =E27/D27-1 -> 0.45367262 | F40: =F27/E27-1 -> 0.4093302 | G40: =G27/F27-1 -> 0.34707198 | H40: =H27/G27-1 -> -0.31943645 | I40: =I27/H27-1 -> 0.99668395 | J40: =J27/I27-1 -> 0.073464967 | Q40: =Q27/M27-1 -> 0.94936496 | R40: =R27/N27-1 -> 0.95944669 | S40: =S27/O27-1 -> 0.11306851 | T40: =T27/P27-1 -> -0.25463245 | U40: =U27/Q27-1 -> -0.56865228 | V40: =V27/R27-1 -> -0.50414322 | W40: =W27/S27-1 -> -0.28392045 | X40: =X27/T27-1 -> 0.39506379 | ... AG40: =AG27/AC27-1 -> 2.5846474
B41: Others | D41: =D28/C28-1 -> 1.3856535 | E41: =E28/D28-1 -> 0.2144964 | F41: =F28/E28-1 -> -0.012752725 | G41: =G28/F28-1 -> 0.21417196 | H41: =H28/G28-1 -> 0.033123931 | I41: =I28/H28-1 -> -0.066899432 | J41: =J28/I28-1 -> -0.29020284 | Q41: =Q28/M28-1 -> -0.093150336 | R41: =R28/N28-1 -> 0.0023519865 | S41: =S28/O28-1 -> 0.42825408 | T41: =T28/P28-1 -> 0.50735895 | U41: =U28/Q28-1 -> 0.25138426 | V41: =V28/R28-1 -> 0.2741124 | W41: =W28/S28-1 -> -0.13433754 | X41: =X28/T28-1 -> -0.10337092 | ... AG41: =AG28/AC28-1 -> -0.080388607
B42: Net Revenue | D42: =D29/C29-1 -> -0.33265697 | E42: =E29/D29-1 -> 0.18190262 | F42: =F29/E29-1 -> 0.3478755 | G42: =G29/F29-1 -> 0.037764172 | H42: =H29/G29-1 -> -0.26569772 | I42: =I29/H29-1 -> 1.0201895 | J42: =J29/I29-1 -> 0.46762851 | Q42: =Q29/M29-1 -> 0.43105533 | R42: =R29/N29-1 -> 0.33805863 | S42: =S29/O29-1 -> -0.069666957 | T42: =T29/P29-1 -> -0.3801185 | U42: =U29/Q29-1 -> -0.58142018 | V42: =V29/R29-1 -> -0.47100627 | W42: =W29/S29-1 -> -0.17451811 | X42: =X29/T29-1 -> 0.47359989 | ... AG42: =AG29/AC29-1 -> 1.9806603
B46: Revenue by Geography
B47: Korea | C47: 840491 | D47: 1446997 | E47: 1452006 | F47: 1461982 | G47: 1225765 | H47: 2033857 | I47: 1904112 | J47: 1932342 | K47: =SUM(AD47:AG47) -> 1668489 | M47: 321150 | N47: 398880 | O47: 344933 | P47: =F47-SUM(M47:O47) -> 397019 | Q47: 253540 | R47: 292987 | S47: 397823 | T47: =G47-SUM(Q47:S47) -> 281415 | U47: 394307 | V47: 467047 | W47: 600930 | X47: =H47-SUM(U47:W47) -> 571573 | Y47: 485931 | Z47: 481626 | AA47: 375675 | AB47: =I47-SUM(Y47:AA47) -> 560880 | AC47: 442620 | AD47: 408005 | AE47: 472452 | AF47: =J47-SUM(AC47:AE47) -> 609265 | AG47: 178767
B48: U.S.A. | C48: 14278161 | D48: 8141151 | E48: 12686108 | F48: 17144323 | G48: 23960980 | H48: 15390229 | I48: 41961072 | J48: 66885115 | K48: =SUM(AD48:AG48) -> 88089740 | M48: 3197159 | N48: 3888759 | O48: 4601148 | P48: =F48-SUM(M48:O48) -> 5457257 | Q48: 5992764 | R48: 7087906 | S48: 6167748 | T48: =G48-SUM(Q48:S48) -> 4712562 | U48: 2290112 | V48: 3150488 | W48: 4268604 | X48: =H48-SUM(U48:W48) -> 5681025 | Y48: 6312614 | Z48: 9666130 | AA48: 11327116 | AB48: =I48-SUM(Y48:AA48) -> 14655212 | AC48: 12794533 | AD48: 15039907 | AE48: 17345742 | AF48: =J48-SUM(AC48:AE48) -> 21704933 | AG48: 33999158
B49: China | C49: 15785993 | D49: 12570278 | E49: 12217634 | F49: 15730223 | G49: 12210470 | H49: 10110084 | I49: 15533563 | J49: 19136237 | K49: =SUM(AD49:AG49) -> 29238463 | M49: 3234700 | N49: 3891709 | O49: 4456709 | P49: =F49-SUM(M49:O49) -> 4147105 | Q49: 3818525 | R49: 4206358 | S49: 2753335 | T49: =G49-SUM(Q49:S49) -> 1432252 | U49: 1546079 | V49: 2362645 | W49: 2738825 | X49: =H49-SUM(U49:W49) -> 3462535 | Y49: 4091101 | Z49: 4515011 | AA49: 4156213 | AB49: =I49-SUM(Y49:AA49) -> 2771238 | AC49: 2694352 | AD49: 4670650 | AE49: 4383924 | AF49: =J49-SUM(AC49:AE49) -> 7387311 | AG49: 12796578
B50: Asia ( Excl Korea and China) | C50: =4609601+2950067 -> 7559668 | D50: =2301314+1444188 -> 3745502 | E50: =2416321+1905650 -> 4321971 | F50: =4033614+2989315 -> 7022929 | G50: =5615384 -> 5615384 | H50: 4296937 | I50: 5381439 | J50: 7215598 | K50: =SUM(AD50:AG50) -> 10430593 | M50: 1410774 | N50: 1744920 | O50: 1992788 | P50: =F50-SUM(M50:O50) -> 1874447 | Q50: 1647717 | R50: 1822087 | S50: 1219391 | T50: =G50-SUM(Q50:S50) -> 926189 | U50: 711623 | V50: 1119770 | W50: 1228031 | X50: =H50-SUM(U50:W50) -> 1237513 | Y50: 1170251 | Z50: 1378600 | AA50: 1374216 | AB50: =I50-SUM(Y50:AA50) -> 1458372 | AC50: 1258292 | AD50: 1739197 | AE50: 1777843 | AF50: =J50-SUM(AC50:AE50) -> 2440266 | AG50: 4473287
B51: Europe | C51: 1980753 | D51: 1086805 | E51: 1222699 | F51: 1638335 | G51: 1608969 | H51: 934612 | I51: 1412774 | J51: 1977383 | K51: =SUM(AD51:AG51) -> 2656536 | M51: 330405 | N51: 397403 | O51: 409746 | P51: =F51-SUM(M51:O51) -> 500781 | Q51: 443107 | R51: 401663 | S51: 444586 | T51: =G51-SUM(Q51:S51) -> 319613 | U51: 145990 | V51: 205983 | W51: 229781 | X51: =H51-SUM(U51:W51) -> 352858 | Y51: 369701 | Z51: 381891 | AA51: 339849 | AB51: =I51-SUM(Y51:AA51) -> 321333 | AC51: 449344 | AD51: 374193 | AE51: 468968 | AF51: =J51-SUM(AC51:AE51) -> 684878 | AG51: 1128497
B52: Net cost of revenues | C52: =SUM(C47:C51) -> 40445066 | D52: =SUM(D47:D51) -> 26990733 | E52: =SUM(E47:E51) -> 31900418 | F52: =SUM(F47:F51) -> 42997792 | G52: =SUM(G47:G51) -> 44621568 | H52: =SUM(H47:H51) -> 32765719 | I52: =SUM(I47:I51) -> 66192960 | J52: =SUM(J47:J51) -> 97146675 | K52: =SUM(K47:K51) -> 132083821 | M52: =SUM(M47:M51) -> 8494188 | N52: =SUM(N47:N51) -> 10321671 | O52: =SUM(O47:O51) -> 11805324 | P52: =SUM(P47:P51) -> 12376609 | Q52: =SUM(Q47:Q51) -> 12155653 | R52: =SUM(R47:R51) -> 13811001 | S52: =SUM(S47:S51) -> 10982883 | T52: =SUM(T47:T51) -> 7672031 | ... AG52: =SUM(AG47:AG51) -> 52576287
...

Sheet Earnings Release
B2: SK Hynix Inc. | C2: Quarters | D2: Quarters | E2: Quarters | F2: Quarters | G2: Quarters | H2: Quarters | I2: Quarters | J2: Quarters | K2: Quarters | L2: Quarters
B3: (KRW billions) | C3: 45382 | D3: 45473 | E3: 45565 | F3: 45657 | G3: 45747 | H3: 45838 | I3: 45930 | J3: 46022 | K3: 46112 | L3: 46203
C4: Act | D4: Act | E4: Act | F4: Act | G4: Act | H4: Act | I4: Act | J4: Act | K4: Act | L4: Act
C5: 1Q | D5: 2Q | E5: 3Q | F5: 4Q | G5: 1Q | H5: 2Q | I5: 3Q | J5: 4Q | K5: 1Q | L5: 2Q
B6: INCOME STATEMENT
B8: Revenue | C8: 12430 | D8: 16423 | E8: 17573 | F8: 19767 | G8: 17639 | H8: 22232 | I8: 24449 | J8: 32827 | K8: 52576 | L8: 79319
B9: Cost of goods sold | C9: -7635 | D9: -8927 | E9: -8402 | F9: -9401 | G9: -7537 | H9: -10249 | I9: -10420 | J9: -10250 | K9: -10897 | L9: -13327
B10: Gross Profit | C10: 4795 | D10: 7496 | E10: 9171 | F10: 10366 | G10: 10102 | H10: 11983 | I10: 14029 | J10: 22576 | K10: 41679 | L10: 65991
B11: SG&A Expense | C11: -1909 | D11: -2028 | E11: -2141 | F11: -2283 | G11: -2661 | H11: -2770 | I11: -2646 | J11: -3407 | K11: -4069 | L11: -5449
B12: Operating Profit | C12: 2886 | D12: 5469 | E12: 7030 | F12: 8083 | G12: 7441 | H12: 9213 | I12: 11383 | J12: 19170 | K12: 37610 | L12: 60543
B13: Net Financial Profit/Loss | C13: -322 | D13: -275 | E13: -233 | F13: -170 | G13: -152 | H13: -129 | I13: -103 | J13: -46 | K13: 22 | L13: 150
B14: Net F/X Transaction & Translation P/L | C14: -215 | D14: -159 | E14: 18 | F14: 625 | G14: 122 | H14: -613 | I14: 209 | J14: -166 | K14: 1573 | L14: 1147
B15: Net Income(Expense) From Jointly Controlled Entities & Associates | C15: 6 | D15: 1 | E15: 7 | F15: -27 | G15: -41 | H15: 17 | I15: -23 | J15: -47 | K15: -27 | L15: -20
B16: Others | C16: 17 | D16: 17 | E16: 57 | F16: 1071 | G16: 1930 | H16: 234 | I16: 3324 | J16: -1258 | K16: 12438 | L16: 60889
B18: EBITDA | C18: 6073 | D18: 8591 | E18: 10100 | F18: 11249 | G18: 10769 | H18: 12645 | I18: 14949 | J18: 22732 | K18: 41336 | L18: 64563
B20: Income Before Tax | C20: 2373 | D20: 5052 | E20: 6879 | F20: 9581 | G20: 9299 | H20: 8723 | I20: 14790 | J20: 17653 | K20: 51617 | L20: 122708
B21: Tax Expense/Benefit | C21: -456 | D21: -932 | E21: -1126 | F21: -1575 | G21: -1191 | H21: -1726 | I21: -2193 | J21: -2407 | K21: -11271 | L21: -28786
B22: Net Profit | C22: 1917 | D22: 4120 | E22: 5753 | F22: 8006 | G22: 8108 | H22: 6996 | I22: 12598 | J22: 15246 | K22: 40346 | L22: 93923
B24: CASH FLOW STATEMENT
B26: Beginning Cash Balance | C26: 8921 | D26: 10319 | E26: 9688 | F26: 10858 | G26: 14156 | H26: 14311 | I26: 16962 | J26: 27854 | K26: 34942 | L26: 54330
B28: CF from Operating Activities | C28: 5385 | D28: 5697 | E28: 7804 | F28: 11081 | G28: 9075 | H28: 9208 | I28: 14368 | J28: 20939 | K28: 26430 | L28: 65710
B29: Net Profit (Loss) | C29: 1917 | D29: 4120 | E29: 5753 | F29: 8006 | G29: 8108 | H29: 6996 | I29: 12598 | J29: 15246 | K29: 40346 | L29: 93923
B30: D&A | C30: 3194 | D30: 3132 | E30: 3082 | F30: 3173 | G30: 3346 | H30: 3454 | I30: 3560 | J30: 3571 | K30: 3729 | L30: 4030
B31: Changes in Working Capital, etc. | C31: 274 | D31: -1554 | E31: -1032 | F31: -99 | G31: -2378 | H31: -1243 | I31: -1789 | J31: 2122 | K31: -17645 | L31: -32243
B33: CF from Investing Activities | C33: -3226 | D33: -2207 | E33: -3688 | F33: -7469 | G33: -9470 | H33: -4329 | I33: -5154 | J33: -12258 | K33: -7228 | L33: -28747
B34: Acquisition of PP&E | C34: -3103 | D34: -2079 | E34: -3516 | F34: -7248 | G34: -6284 | H34: -4332 | I34: -5033 | J34: -11871 | K34: -7657 | L34: -10671
B36: CF from Financing Activities | C36: -913 | D36: -4120 | E36: -2741 | F36: -930 | G36: 509 | H36: -1780 | I36: 1375 | J36: -1549 | K36: -2951 | L36: -4666
B37: Changes in Debt | C37: -783 | D37: -3601 | E37: -2401 | F37: -591 | G37: 645 | H37: -484 | I37: 1757 | J37: -1151 | K37: -2754 | L37: -3032
B38: Repayment of Lease Liability | C38: -161 | D38: -149 | E38: -149 | F38: -143 | G38: -152 | H38: -150 | I38: -145 | J38: -150 | K38: -148 | L38: -139
B39: Dividend Payout | C39: 0 | D39: -413 | E39: -207 | F39: -207 | G39: 0 | H39: -1159 | I39: -259 | J39: -263 | K39: 0 | L39: -1594
B40: Effect of F/X rate changes on Cash & Equivalents | C40: 151 | D40: -1 | E40: -205 | F40: 617 | G40: 41 | H40: -447 | I40: 303 | J40: -45 | K40: 3138 | L40: 1332
B42: Net Changes in Cash | C42: 1398 | D42: -631 | E42: 1170 | F42: 3298 | G42: 155 | H42: 2651 | I42: 10892 | J42: 7088 | K42: 19388 | L42: 33628
B43: Ending Cash Balance | C43: =C26+C42 -> 10319 | D43: =D26+D42 -> 9688 | E43: 10858 | F43: =F26+F42 -> 14156 | G43: =G26+G42 -> 14311 | H43: =H26+H42 -> 16962 | I43: 27854 | J43: =J26+J42 -> 34942 | K43: =K26+K42 -> 54330 | L43: =L26+L42 -> 87958
B45: BALANCE SHEET STATEMENT
B47: Current Assets | C47: 33026 | D47: 35684 | E47: 37078 | F47: 42279 | G47: 41228 | H47: 45203 | I47: 57140 | J47: 69458 | K47: 106506 | L47: 156156
B48: Cash & Cash Equivalents | C48: 10319 | D48: 9688 | E48: 10858 | F48: 14156 | G48: 14311 | H48: 16962 | I48: 27854 | J48: 34942 | K48: 54330 | L48: 87958
B49: Accounts Receivables | C49: 7179 | D49: 10224 | E49: 10471 | F49: 13019 | G49: 10629 | H49: 13125 | I49: 14312 | J49: 18199 | K49: 33808 | L49: 47821
B50: Inventories | C50: 13845 | D50: 13355 | E50: 13354 | F50: 13314 | G50: 14551 | H50: 13408 | I50: 13156 | J50: 14289 | K50: 15974 | L50: 17986
B52: Non-Current Assets | C52: 70171 | D52: 69941 | E52: 71289 | F52: 77576 | G52: 82757 | H52: 83885 | I52: 91295 | J52: 106650 | K52: 116323 | L52: 192706
B53: Property, Plant & Equipment | C53: 53164 | D53: 53232 | E53: 54634 | F53: 60157 | G53: 63015 | H53: 64473 | I53: 68145 | J53: 77503 | K53: 82052 | L53: 88889
...
