Workbook
Name \A: #REF!
Name \B: #REF!
Name \C: #REF!
Name \L: #REF!
Name \M: #REF!
Name \P: #REF!
Name \Y: #REF!
Name _01_30_04: MonthlyOpStats
Name _01_30_04: MonthlyOpStats
Name _1_30_01: MonthlyOpStats
Name _1_30_01: MonthlyOpStats
Name _1_30_02: MonthlyOpStats
Name _1_30_02: MonthlyOpStats
Name _1_31_01: MonthlyOpStats
Name _1_31_01: MonthlyOpStats
Name _1_31_02: MonthlyOpStats
Name _1_31_02: MonthlyOpStats
Name _12_31_05: MonthlyOpStats
Name _12_31_05: MonthlyOpStats
Name _A: #REF!
Name _A___0: #REF!
Name _B: #REF!
Name _B___0: #REF!
Name _C: #REF!
Name _C___0: #REF!
Name _ent1: [1]Inputs!$J$17
Name _ent10: [1]Inputs!$J$476
Name _ent11: [1]Inputs!$J$527
Name _ent12: [1]Inputs!$J$578
Name _ent13: [1]Inputs!$J$629
Name _ent14: [1]Inputs!$J$680
Name _ent15: [1]Inputs!$J$731
Name _ent2: [1]Inputs!$J$68
Name _ent3: [1]Inputs!$J$119
Name _ent4: [1]Inputs!$J$170
Name _ent5: [1]Inputs!$J$221
Name _ent6: [1]Inputs!$J$272
Name _ent7: [1]Inputs!$J$323
Name _ent8: [1]Inputs!$J$374
Name _ent9: [1]Inputs!$J$425
Name _eps1: [1]Inputs!$P$42
Name _eps10: [1]Inputs!$P$501
Name _eps11: [1]Inputs!$P$552
Name _eps12: [1]Inputs!$P$603
Name _eps13: [1]Inputs!$P$654
Name _eps14: [1]Inputs!$P$705
Name _eps15: [1]Inputs!$P$756
Name _eps2: [1]Inputs!$P$93
Name _eps3: [1]Inputs!$P$144
Name _eps4: [1]Inputs!$P$195
Name _eps5: [1]Inputs!$P$246
Name _eps6: [1]Inputs!$P$297
Name _eps7: [1]Inputs!$P$348
Name _eps8: [1]Inputs!$P$399
Name _eps9: [1]Inputs!$P$450
Name _fye1: [1]Inputs!$E$12
Name _fye10: [1]Inputs!$E$471
Name _fye11: [1]Inputs!$E$522
Name _fye12: [1]Inputs!$E$573
Name _fye13: [1]Inputs!$E$624

Sheet Capitalisation
A2: 4Q26 | J2: Exchange rate as at end 4Q26 | K2: =Model!$AE$207 -> 0.010696903
J3: Average Exchange rate of 4Q26 | K3: =Model!$AE$208 -> 0.011317886
B5: Debt Breakdown as on 31-Mar-2026 | C5: INR mn | D5: Leverage | E5: USD mn | F5: Leverage | J5: Company Reported | K5: INR mn
B6: Loans | C6: =SUM(C7:C10) -> 322770 | E6: =SUM(E7:E10) -> 3452.6395 | J6: Gross Debt | K6: 220450
B7: Current | C7: =Model!$AE$107 -> 65110 | E7: =C7*$K2 -> 696.47537 | J7: Cash and cash equivalent | K7: 67200
B8: Non current | C8: =Model!$AE$108 -> 155350 | E8: =C8*$K2 -> 1661.7639 | J8: Net debt | K8: 153250
B9: Receivable factoring | C9: =Model!$AE$119 -> 102310 | E9: =C9*$K2 -> 1094.4002 | J9: Net debt / EBITDA | K9: 1.6x
B10: 50% of Hybrid | C10: =Model!$AE$126/2 -> 0 | E10: =C10*$K2 -> 0
B12: Operating lease liabilities | C12: =SUM(C13:C14) -> 15300 | E12: =SUM(E13:E14) -> 163.66262
B13: Current | C13: =Model!AE112 -> 5090 | E13: =C13*$K2 -> 54.447238
B14: Non current | C14: =Model!AE113 -> 10210 | E14: =C14*$K2 -> 109.21538
B15: Total Loans & Borrowings | C15: =C12+C6 -> 338070 | D15: =C15/C21 -> 3.52597 | E15: =E12+E6 -> 3616.3021 | F15: =E15/E21 -> 3.3325093
B16: Cash and Cash Equivalents | C16: =Model!$AE$121 -> 60860 | E16: =C16*$K2 -> 651.01353
B17: Investments | C17: =Model!$AE$122 -> 6340 | E17: =C17*$K2 -> 67.818367
B18: Net debt | C18: =C15-C16-C17 -> 270870 | D18: =C18/C21 -> 2.8250939 | E18: =E15-E16-E17 -> 2897.4702 | F18: =E18/E21 -> 2.6700884
B19: Equity | C19: =Model!$AE$127 -> 346960 | E19: =C19*$K2 -> 3711.3976
B20: Total Capitalisation | C20: =C18+C19 -> 617830 | E20: =C20*$K2 -> 6608.8677
B21: LTM Adjusted EBITDA | C21: =Model!$AE$85 -> 95880 | E21: =C21*$K3 -> 1085.1589
B22: check | C22: =+C15-Model!$AE$120 -> 0
B25: LT Debt Maturity Breakdown at 4Q26 (from BBG) | C25: INR mn | D25: USD mn
B26: 2026 | C26: 47138.68 | D26: =C26*$K$2 -> 504.2379
B27: 2027 | C27: 52138.68 | D27: =C27*$K$2 -> 557.72242
B28: 2028 | C28: 28358.21 | D28: =C28*$K$2 -> 303.34503
B29: 2029 | C29: 66094.15 | D29: =C29*$K$2 -> 707.00273
B30: 2030 | C30: 48338.68 | D30: =C30*$K$2 -> 517.07418
B31: 2031 | C31: 145 | D31: =C31*$K$2 -> 1.551051
B32: 2032 | C32: 1690 | D32: =C32*$K$2 -> 18.077766
B33: Total | C33: =SUM(C26:C32) -> 243903.4 | D33: =SUM(D26:D32) -> 2609.0111
A40: 3Q26 | J40: Exchange rate as at end 3Q26 | K40: =Model!$J$207 -> 0.010696903
J41: Average Exchange rate of 3Q26 | K41: =Model!$J$208 -> 0.011317886
B43: Debt Breakdown as on 31-Dec-2025 | C43: INR mn | D43: Leverage | E43: USD mn | F43: Leverage | J43: Company Reported | K43: INR mn
B44: Loans | C44: =SUM(C45:C48) -> 339650 | E44: =SUM(E45:E48) -> 3633.2032 | J44: Gross Debt | K44: 284640
B45: Current | C45: =Model!$AD$107 -> 175070 | E45: =C45*$K40 -> 1872.7069 | J45: Cash and cash equivalent | K45: 51470
B46: Non current | C46: =Model!$AD$108 -> 109570 | E46: =C46*$K40 -> 1172.0597 | J46: Net debt | K46: 233170
B47: Receivable factoring | C47: =Model!$AD$119 -> 55010 | E47: =C47*$K40 -> 588.43665 | J47: Net debt / EBITDA | K47: 2.5x
B48: 50% of Hybrid | C48: =Model!$AD$126/2 -> 0 | E48: =C48*$K40 -> 0
B49: Operating lease liabilities | C49: =SUM(C50:C51) -> 0 | E49: =SUM(E50:E51) -> 0
B50: Current
B51: Non current
B52: Total Loans & Borrowings | C52: =C49+C44 -> 339650 | D52: =C52/C58 -> 3.7006973 | E52: =E49+E44 -> 3633.2032 | F52: =E52/E58 -> 3.4976499
...

Sheet Model
B2: UPL Ltd | C2: Annual | D2: Annual | E2: Annual | F2: Annual | G2: Annual | H2: Annual | I2: Annual | J2: LTM | L2: Quarters | M2: Quarters | N2: Quarters | O2: Quarters | P2: Quarters | Q2: Quarters | R2: Quarters | S2: Quarters | T2: Quarters | U2: Quarters | V2: Quarters | W2: Quarters | X2: Quarters | Y2: Quarters | Z2: Quarters | AA2: Quarters | AB2: Quarters | AC2: Quarters | AD2: Quarters | AE2: Quarters
B3: (INR million) | C3: 43921 | D3: 44286 | E3: 44651 | F3: 45016 | G3: 45382 | H3: 45747 | I3: 46112 | J3: =AE3 -> 46112 | L3: 44377 | M3: 44469 | N3: 44561 | O3: 44651 | P3: 44742 | Q3: 44834 | R3: 44926 | S3: 45016 | T3: 45107 | U3: 45199 | V3: 45291 | W3: 45382 | X3: 45473 | Y3: 45565 | Z3: 45657 | AA3: 45747 | AB3: 45838 | AC3: 45930 | AD3: 46022 | AE3: 46112
C4: Act | D4: Act | E4: Act | F4: Act | G4: Act | H4: Act | I4: Act | J4: Act | L4: Act | M4: Act | N4: Act | O4: Act | P4: Act | Q4: Act | R4: Act | S4: Act | T4: Act | U4: Act | V4: Act | W4: Act | X4: Act | Y4: Act | Z4: Act | AA4: Act | AB4: Act | AC4: Act | AD4: Act | AE4: Act
C5: FY | D5: FY | E5: FY | F5: FY | G5: FY | H5: FY | I5: FY | J5: LTM | L5: 1Q | M5: 2Q | N5: 3Q | O5: 4Q | P5: 1Q | Q5: 2Q | R5: 3Q | S5: 4Q | T5: 1Q | U5: 2Q | V5: 3Q | W5: 4Q | X5: 1Q | Y5: 2Q | Z5: 3Q | AA5: 4Q | AB5: 1Q | AC5: 2Q | AD5: 3Q | AE5: 4Q
B6: INCOME STATEMENT
B7: Revenue from Operations | C7: 357560 | D7: 386940 | E7: 462400 | F7: 535760 | G7: 430980 | H7: 466370 | I7: 518390 | J7: =SUM(AB7:AE7) -> 518390 | L7: 85150 | M7: 105670 | N7: 112970 | O7: =E7-SUM(L7:N7) -> 158610 | P7: 108210 | Q7: 125070 | R7: 136790 | S7: =F7-SUM(P7:R7) -> 165690 | T7: 89630 | U7: 101700 | V7: 98870 | W7: =G7-SUM(T7:V7) -> 140780 | X7: 90670 | Y7: 110900 | Z7: 109070 | AA7: =H7-SUM(X7:Z7) -> 155730 | AB7: 92160 | AC7: 120190 | AD7: 122690 | AE7: =I7-SUM(AB7:AD7) -> 183350
B8: Other income | C8: 1040 | D8: 2580 | E8: 2810 | F8: 4770 | G8: 4830 | H8: 4860 | I8: 6630 | J8: =SUM(AB8:AE8) -> 6630 | L8: 480 | M8: 470 | N8: 700 | O8: =E8-SUM(L8:N8) -> 1160 | P8: 730 | Q8: 780 | R8: 1150 | S8: =F8-SUM(P8:R8) -> 2110 | T8: 1010 | U8: 1050 | V8: 1510 | W8: =G8-SUM(T8:V8) -> 1260 | X8: 980 | Y8: 1110 | Z8: 1700 | AA8: =H8-SUM(X8:Z8) -> 1070 | AB8: 1430 | AC8: 2500 | AD8: 920 | AE8: =I8-SUM(AB8:AD8) -> 1780
B9: % of growth | D9: =(D7/C7)-1 -> 0.082168028 | E9: =(E7/D7)-1 -> 0.19501732 | F9: =(F7/E7)-1 -> 0.15865052 | G9: =(G7/F7)-1 -> -0.19557264 | H9: =(H7/G7)-1 -> 0.082115179 | I9: =(I7/H7)-1 -> 0.11154234
B10: Cost of revenue | C10: -187430 | D10: -190960 | E10: -220720 | F10: -272810 | G10: -244940 | H10: -242230 | I10: =-239280-38080+18450 -> -258910 | J10: =SUM(AB10:AE10) -> -258910 | L10: -37030 | M10: -52210 | N10: -51540 | O10: =E10-SUM(L10:N10) -> -79940 | P10: -49190 | Q10: -57810 | R10: -66220 | S10: =F10-SUM(P10:R10) -> -99590 | T10: -39300 | U10: -52320 | V10: -63230 | W10: =G10-SUM(T10:V10) -> -90090 | X10: -45200 | Y10: -58230 | Z10: -53290 | AA10: =H10-SUM(X10:Z10) -> -85510 | AB10: -41690 | AC10: -57530 | AD10: -58460 | AE10: =I10-SUM(AB10:AD10) -> -101230
B11: Gross Profit | C11: =C7+C8+C10 -> 171170 | D11: =D7+D8+D10 -> 198560 | E11: =E7+E8+E10 -> 244490 | F11: =F7+F8+F10 -> 267720 | G11: =G7+G8+G10 -> 190870 | H11: =H7+H8+H10 -> 229000 | I11: =I7+I8+I10 -> 266110 | J11: =J7+J8+J10 -> 266110 | L11: =L7+L8+L10 -> 48600 | M11: =M7+M8+M10 -> 53930 | N11: =N7+N8+N10 -> 62130 | O11: =O7+O8+O10 -> 79830 | P11: =P7+P8+P10 -> 59750 | Q11: =Q7+Q8+Q10 -> 68040 | R11: =R7+R8+R10 -> 71720 | S11: =S7+S8+S10 -> 68210 | ... AE11: =AE7+AE8+AE10 -> 83900
B12: Gross Profit margin | C12: =C11/C7 -> 0.47871686 | D12: =D11/D7 -> 0.51315449 | E12: =E11/E7 -> 0.52874135 | F12: =F11/F7 -> 0.49970136 | G12: =G11/G7 -> 0.44287438 | H12: =H11/H7 -> 0.49102644 | I12: =I11/I7 -> 0.51333938 | J12: =J11/J7 -> 0.51333938 | L12: =L11/L7 -> 0.57075749 | M12: =M11/M7 -> 0.51036245 | N12: =N11/N7 -> 0.54996902 | O12: =O11/O7 -> 0.50331001 | P12: =P11/P7 -> 0.55216708 | Q12: =Q11/Q7 -> 0.54401535 | R12: =R11/R7 -> 0.52430733 | S12: =S11/S7 -> 0.4116724 | ... AE12: =AE11/AE7 -> 0.45759476
B13: Operating expenses:
B14: Employee benefit expense | C14: -33910 | D14: -37120 | E14: -46220 | F14: -50560 | G14: -46820 | H14: -53090 | I14: -58070 | J14: =SUM(AB14:AE14) -> -58070 | L14: -10300 | M14: -10790 | N14: -11660 | O14: =E14-SUM(L14:N14) -> -13470 | P14: -12440 | Q14: -12330 | R14: -13210 | S14: =F14-SUM(P14:R14) -> -12580 | T14: -12400 | U14: -12510 | V14: -11550 | W14: =G14-SUM(T14:V14) -> -10360 | X14: -13370 | Y14: -13370 | Z14: -11840 | AA14: =H14-SUM(X14:Z14) -> -14510 | AB14: -13220 | AC14: -14660 | AD14: -13790 | AE14: =I14-SUM(AB14:AD14) -> -16400
B15: Impairment loss/(writeback) on trade receivables | C15: -490 | D15: -800 | E15: 150 | F15: -1230 | G15: -910 | H15: -2400 | I15: -7500 | J15: =SUM(AB15:AE15) -> -7500 | L15: 370 | M15: -580 | N15: 250 | O15: =E15-SUM(L15:N15) -> 110 | P15: -330 | Q15: -500 | R15: -80 | S15: =F15-SUM(P15:R15) -> -320 | T15: -630 | U15: -380 | V15: -140 | W15: =G15-SUM(T15:V15) -> 240 | X15: -870 | Y15: -1520 | Z15: 190 | AA15: =H15-SUM(X15:Z15) -> -200 | AB15: -1920 | AC15: -1140 | AD15: -650 | AE15: =I15-SUM(AB15:AD15) -> -3790
B16: Depreciation and Amortisation expense | C16: -20120 | D16: -21730 | E16: -23590 | F16: -25470 | G16: -27630 | H16: -27500 | I16: -32440 | J16: =SUM(AB16:AE16) -> -32440 | L16: -5510 | M16: -5660 | N16: -6000 | O16: =E16-SUM(L16:N16) -> -6420 | P16: -5880 | Q16: -6080 | R16: -6240 | S16: =F16-SUM(P16:R16) -> -7270 | T16: -6360 | U16: -6570 | V16: -6760 | W16: =G16-SUM(T16:V16) -> -7940 | X16: -6600 | Y16: -6970 | Z16: -6880 | AA16: =H16-SUM(X16:Z16) -> -7050 | AB16: -7310 | AC16: -7710 | AD16: -8270 | AE16: =I16-SUM(AB16:AD16) -> -9150
B17: Exchange difference on trade receivables and trade payables | C17: -3310 | D17: -2070 | E17: -6360 | F17: -9640 | G17: -9760 | H17: -5200 | I17: -3160 | J17: =SUM(AB17:AE17) -> -3160 | L17: -890 | M17: -1140 | N17: -2210 | O17: =E17-SUM(L17:N17) -> -2120 | P17: -1970 | Q17: -3240 | R17: -1500 | S17: =F17-SUM(P17:R17) -> -2930 | T17: -3190 | U17: -2500 | V17: -3230 | W17: =G17-SUM(T17:V17) -> -840 | X17: -450 | Y17: -2230 | Z17: -2060 | AA17: =H17-SUM(X17:Z17) -> -460 | AB17: 930 | AC17: -2040 | AD17: -1160 | AE17: =I17-SUM(AB17:AD17) -> -890
B18: Operating profit | C18: =C11+SUM(C14:C17) -> 113340 | D18: =D11+SUM(D14:D17) -> 136840 | E18: =E11+SUM(E14:E17) -> 168470 | F18: =F11+SUM(F14:F17) -> 180820 | G18: =G11+SUM(G14:G17) -> 105750 | H18: =H11+SUM(H14:H17) -> 140810 | I18: =I11+SUM(I14:I17) -> 164940 | J18: =J11+SUM(J14:J17) -> 164940 | L18: =L11+SUM(L14:L17) -> 32270 | M18: =M11+SUM(M14:M17) -> 35760 | N18: =N11+SUM(N14:N17) -> 42510 | O18: =O11+SUM(O14:O17) -> 57930 | P18: =P11+SUM(P14:P17) -> 39130 | Q18: =Q11+SUM(Q14:Q17) -> 45890 | R18: =R11+SUM(R14:R17) -> 50690 | S18: =S11+SUM(S14:S17) -> 45110 | ... AE18: =AE11+SUM(AE14:AE17) -> 53670
B19: Finance cost | C19: -14810 | D19: -20600 | E19: -22950 | F19: -29630 | G19: -38520 | H19: -36270 | I19: -34010 | J19: =SUM(AB19:AE19) -> -34010 | L19: -6070 | M19: -3590 | N19: -5290 | O19: =E19-SUM(L19:N19) -> -8000 | P19: -5190 | Q19: -6440 | R19: -8940 | S19: =F19-SUM(P19:R19) -> -9060 | T19: -7000 | U19: -8710 | V19: -11910 | W19: =G19-SUM(T19:V19) -> -10900 | X19: -9130 | Y19: -10700 | Z19: -7300 | AA19: =H19-SUM(X19:Z19) -> -9140 | AB19: -10070 | AC19: -7840 | AD19: -7740 | AE19: =I19-SUM(AB19:AD19) -> -8360
B20: Other Expenses | C20: -64690 | D20: -72470 | E20: -93960 | F20: -99560 | G20: -83160 | H20: -87450 | I20: -98030 | J20: =SUM(AB20:AE20) -> -98030 | L20: -19560 | M20: -21640 | N20: -23370 | O20: =E20-SUM(L20:N20) -> -29390 | P20: -22820 | Q20: -26750 | R20: -26940 | S20: =F20-SUM(P20:R20) -> -23050 | T20: -21380 | U20: -20740 | V20: -19790 | W20: =G20-SUM(T20:V20) -> -21250 | X20: -19770 | Y20: -22030 | Z20: -22510 | AA20: =H20-SUM(X20:Z20) -> -23140 | AB20: -22300 | AC20: -24810 | AD20: -25460 | AE20: =I20-SUM(AB20:AD20) -> -25460
B21: Share of profit/loss from Associates/ JV | C21: 30 | D21: 420 | E21: 1340 | F21: 1570 | G21: -2420 | H21: -4720 | I21: -1940 | J21: =SUM(AB21:AE21) -> -1940 | L21: -40 | M21: 100 | N21: 140 | O21: =E21-SUM(L21:N21) -> 1140 | P21: 300 | Q21: -270 | R21: 340 | S21: =F21-SUM(P21:R21) -> 1200 | T21: -570 | U21: -2040 | V21: -260 | W21: =G21-SUM(T21:V21) -> 450 | X21: -320 | Y21: -1350 | Z21: -2780 | AA21: =H21-SUM(X21:Z21) -> -270 | AB21: 180 | AC21: -540 | AD21: -810 | AE21: =I21-SUM(AB21:AD21) -> -770
B22: Exceptional items | C22: -6230 | D22: -2380 | E22: -3240 | F22: -1700 | G22: -2520 | H22: -4080 | I22: 610 | J22: =SUM(AB22:AE22) -> 610 | L22: -630 | M22: -400 | N22: -530 | O22: =E22-SUM(L22:N22) -> -1680 | P22: -780 | Q22: -430 | R22: -200 | S22: =F22-SUM(P22:R22) -> -290 | T22: -430 | U22: -870 | V22: -170 | W22: =G22-SUM(T22:V22) -> -1050 | X22: -490 | Y22: -80 | Z22: -760 | AA22: =H22-SUM(X22:Z22) -> -2750 | AB22: -90 | AC22: =(((142)/10)*10)*10 -> 1420 | AD22: -560 | AE22: =I22-SUM(AB22:AD22) -> -160
B23: Profit / (Loss) before tax | C23: =C18+SUM(C19:C22) -> 27640 | D23: =D18+SUM(D19:D22) -> 41810 | E23: =E18+SUM(E19:E22) -> 49660 | F23: =F18+SUM(F19:F22) -> 51500 | G23: =G18+SUM(G19:G22) -> -20870 | H23: =H18+SUM(H19:H22) -> 8290 | I23: =I18+SUM(I19:I22) -> 31570 | J23: =J18+SUM(J19:J22) -> 31570 | L23: =L18+SUM(L19:L22) -> 5970 | M23: =M18+SUM(M19:M22) -> 10230 | N23: =N18+SUM(N19:N22) -> 13460 | O23: =O18+SUM(O19:O22) -> 20000 | P23: =P18+SUM(P19:P22) -> 10640 | Q23: =Q18+SUM(Q19:Q22) -> 12000 | R23: =R18+SUM(R19:R22) -> 14950 | S23: =S18+SUM(S19:S22) -> 13910 | ... AE23: =AE18+SUM(AE19:AE22) -> 18920
B24: Tax expenses | C24: -5860 | D24: -6860 | E24: -5290 | F24: -7360 | G24: 2090 | H24: =(-295+286)*10 -> -90 | I24: =-(1243-306)*10 -> -9370 | J24: =SUM(AB24:AE24) -> -9370 | L24: 1520 | M24: -2490 | N24: -1670 | O24: =E24-SUM(L24:N24) -> -2650 | P24: -590 | Q24: -2310 | R24: -1350 | S24: =F24-SUM(P24:R24) -> -3110 | T24: 1640 | U24: 960 | V24: 590 | W24: =G24-SUM(T24:V24) -> -1100 | X24: -720 | Y24: -1380 | Z24: 4990 | AA24: =H24-SUM(X24:Z24) -> -2980 | AB24: 140 | AC24: -1720 | AD24: -1810 | AE24: =I24-SUM(AB24:AD24) -> -5980
B25: Net profit/ (Loss) | C25: =+C23+C24 -> 21780 | D25: =+D23+D24 -> 34950 | E25: =+E23+E24 -> 44370 | F25: =+F23+F24 -> 44140 | G25: =+G23+G24 -> -18780 | H25: =+H23+H24 -> 8200 | I25: =+I23+I24 -> 22200 | J25: =+J23+J24 -> 22200 | L25: =+L23+L24 -> 7490 | M25: =+M23+M24 -> 7740 | N25: =+N23+N24 -> 11790 | O25: =+O23+O24 -> 17350 | P25: =+P23+P24 -> 10050 | Q25: =+Q23+Q24 -> 9690 | R25: =+R23+R24 -> 13600 | S25: =+S23+S24 -> 10800 | ... AE25: =+AE23+AE24 -> 12940
B26: % margin | C26: =+C25/C7 -> 0.060912854 | D26: =+D25/D7 -> 0.090324081 | E26: =+E25/E7 -> 0.095955882 | F26: =+F25/F7 -> 0.082387636 | G26: =+G25/G7 -> -0.043575108 | H26: =+H25/H7 -> 0.017582606 | I26: =+I25/I7 -> 0.0428249 | J26: =+J25/J7 -> 0.0428249 | L26: =+L25/L7 -> 0.087962419 | M26: =+M25/M7 -> 0.073246901 | N26: =+N25/N7 -> 0.10436399 | O26: =+O25/O7 -> 0.10938781 | P26: =+P25/P7 -> 0.092874965 | Q26: =+Q25/Q7 -> 0.077476613 | R26: =+R25/R7 -> 0.099422472 | S26: =+S25/S7 -> 0.065181966 | ... AE26: =+AE25/AE7 -> 0.070575402
B27: Non-controlling interest | C27: 0 | D27: 0 | E27: -8110 | F27: -8440 | G27: 6780 | H27: 770 | I27: -2980 | J27: =SUM(AB27:AE27) -> -2980 | L27: 0 | M27: 0 | N27: -2430 | O27: =E27-SUM(L27:N27) -> -5680 | P27: 0 | Q27: -1550 | R27: -2730 | S27: =F27-SUM(P27:R27) -> -4160 | T27: 640 | U27: 1040 | V27: 3900 | W27: 1200 | X27: 1430 | Y27: 1420 | Z27: -250 | AA27: =H27-SUM(X27:Z27) -> -1830 | AB27: 880 | AC27: -590 | AD27: -940 | AE27: =I27-SUM(AB27:AD27) -> -2330
B28: Net profit/loss | C28: =+C25+SUM(C27:C27) -> 21780 | D28: =+D25+SUM(D27:D27) -> 34950 | E28: =+E25+SUM(E27:E27) -> 36260 | F28: =+F25+SUM(F27:F27) -> 35700 | G28: =+G25+SUM(G27:G27) -> -12000 | H28: =+H25+SUM(H27:H27) -> 8970 | I28: =+I25+SUM(I27:I27) -> 19220 | J28: =+J25+SUM(J27:J27) -> 19220 | L28: =+L25+SUM(L27:L27) -> 7490 | M28: =+M25+SUM(M27:M27) -> 7740 | N28: =+N25+SUM(N27:N27) -> 9360 | O28: =+O25+SUM(O27:O27) -> 11670 | P28: =+P25+SUM(P27:P27) -> 10050 | Q28: =+Q25+SUM(Q27:Q27) -> 8140 | R28: =+R25+SUM(R27:R27) -> 10870 | S28: =+S25+SUM(S27:S27) -> 6640 | ... AE28: =+AE25+SUM(AE27:AE27) -> 10610
B30: As % of Revenues unless stated otherwise
B31: =B14 -> Employee benefit expense | C31: =-C14/C7 -> 0.09483723 | D31: =-D14/D7 -> 0.095932186 | E31: =-E14/E7 -> 0.099956747 | F31: =-F14/F7 -> 0.094370614 | G31: =-G14/G7 -> 0.10863613 | H31: =-H14/H7 -> 0.11383665 | I31: =-I14/I7 -> 0.11201991 | J31: =-J14/J7 -> 0.11201991 | L31: =-L14/L7 -> 0.12096301 | M31: =-M14/M7 -> 0.10211034 | N31: =-N14/N7 -> 0.10321324 | O31: =-O14/O7 -> 0.084925288 | P31: =-P14/P7 -> 0.11496165 | Q31: =-Q14/Q7 -> 0.098584793 | R31: =-R14/R7 -> 0.096571387 | S31: =-S14/S7 -> 0.07592492 | ... AE31: =-AE14/AE7 -> 0.089446414
B32: =B15 -> Impairment loss/(writeback) on trade receivables | C32: =-C15/C7 -> 0.0013703994 | D32: =-D15/D7 -> 0.002067504 | E32: =-E15/E7 -> -0.00032439446 | F32: =-F15/F7 -> 0.0022958041 | G32: =-G15/G7 -> 0.0021114669 | H32: =-H15/H7 -> 0.0051461286 | I32: =-I15/I7 -> 0.014467872 | J32: =-J15/J7 -> 0.014467872 | L32: =-L15/L7 -> -0.004345273 | M32: =-M15/M7 -> 0.0054887858 | N32: =-N15/N7 -> -0.0022129769 | O32: =-O15/O7 -> -0.000693525 | P32: =-P15/P7 -> 0.0030496257 | Q32: =-Q15/Q7 -> 0.0039977613 | R32: =-R15/R7 -> 0.00058483807 | S32: =-S15/S7 -> 0.0019313175 | ... AE32: =-AE15/AE7 -> 0.020670848
B33: =B16 -> Depreciation and Amortisation expense | C33: =-C16/C7 -> 0.056270276 | D33: =-D16/D7 -> 0.056158578 | E33: =-E16/E7 -> 0.051016436 | F33: =-F16/F7 -> 0.047539943 | G33: =-G16/G7 -> 0.064109703 | H33: =-H16/H7 -> 0.058966057 | I33: =-I16/I7 -> 0.062578368 | J33: =-J16/J7 -> 0.062578368 | L33: =-L16/L7 -> 0.064709336 | M33: =-M16/M7 -> 0.053562979 | N33: =-N16/N7 -> 0.053111446 | O33: =-O16/O7 -> 0.040476641 | P33: =-P16/P7 -> 0.054338786 | Q33: =-Q16/Q7 -> 0.048612777 | R33: =-R16/R7 -> 0.04561737 | S33: =-S16/S7 -> 0.04387712 | ... AE33: =-AE16/AE7 -> 0.049904554
B34: =B17 -> Exchange difference on trade receivables and trade payables | C34: =-C17/C7 -> 0.0092571876 | D34: =-D17/D7 -> 0.0053496666 | E34: =-E17/E7 -> 0.013754325 | F34: =-F17/F7 -> 0.017993131 | G34: =-G17/G7 -> 0.022646062 | H34: =-H17/H7 -> 0.011149945 | I34: =-I17/I7 -> 0.0060957966 | J34: =-J17/J7 -> 0.0060957966 | L34: =-L17/L7 -> 0.010452143 | M34: =-M17/M7 -> 0.010788303 | N34: =-N17/N7 -> 0.019562716 | O34: =-O17/O7 -> 0.013366118 | P34: =-P17/P7 -> 0.018205341 | Q34: =-Q17/Q7 -> 0.025905493 | R34: =-R17/R7 -> 0.010965714 | S34: =-S17/S7 -> 0.017683626 | ... AE34: =-AE17/AE7 -> 0.0048541042
B35: Finance cost as % of debt | C35: =-C19/C109 -> 0.051658586 | D35: =-D19/D109 -> 0.086667508 | E35: =-E19/E109 -> 0.088726514 | F35: =-F19/F109 -> 0.12883169 | G35: =-G19/G109 -> 0.13545256 | H35: =-H19/H109 -> 0.15294763 | I35: =-I19/I109 -> 0.15426835 | J35: =-J19/J109 -> 0.15426835 | O35: =-SUM(L19:O19)/O109 -> 0.088726514 | Q35: =-SUM(N19:Q19)/Q109 -> 0.076561492 | S35: =-SUM(P19:S19)/S109 -> 0.12883169 | U35: =-SUM(R19:U19)/U109 -> 0.099339895 | W35: =-SUM(T19:W19)/W109 -> 0.13545256 | Y35: =-SUM(V19:Y19)/Y109 -> 0.13390698 | AA35: =-SUM(X19:AA19)/AA109 -> 0.15294763 | AC35: =-SUM(Z19:AC19)/AC109 -> 0.12026469 | AD35: =-SUM(AA19:AD19)/AD109 -> 0.12222456 | AE35: =-SUM(AB19:AE19)/AE109 -> 0.15426835
B36: Tax % of PBT | C36: =-C24/C23 -> 0.21201158 | D36: =-D24/D23 -> 0.16407558 | E36: =-E24/E23 -> 0.10652437 | F36: =-F24/F23 -> 0.14291262 | G36: =-G24/G23 -> 0.10014375 | H36: =-H24/H23 -> 0.010856454 | I36: =-I24/I23 -> 0.29680076 | J36: =-J24/J23 -> 0.29680076 | L36: =L24/L23 -> 0.25460637 | M36: =-M24/M23 -> 0.24340176 | N36: =-N24/N23 -> 0.12407132 | O36: =-O24/O23 -> 0.1325 | P36: =-P24/P23 -> 0.055451128 | Q36: =-Q24/Q23 -> 0.1925 | R36: =-R24/R23 -> 0.090301003 | S36: =-S24/S23 -> 0.22358016 | T36: =-T24/T23 -> 2.6451613 | ... AE36: =-AE24/AE23 -> 0.31606765
B38: Working capital /sales | C38: =C59/C7 -> 0.085300369 | D38: =-D59/D7 -> 0.0055305732 | E38: =-E59/E7 -> 0.038213668 | F38: =-F59/F7 -> 0.025552486 | G38: =-G59/G7 -> 0.029490928 | H38: =-H59/H7 -> -0.077620773 | I38: =-I59/I7 -> 0.022627751 | J38: =-J59/J7 -> 0.022627751 | L38: =L59/L7 -> 0 | M38: =M59/M7 -> -0.53279076 | N38: =N59/N7 -> 0 | O38: =O59/O7 -> 0.24355337 | P38: =P59/P7 -> 0 | Q38: =Q59/Q7 -> -0.68761494 | R38: =R59/R7 -> 0 | S38: =S59/S7 -> 0.43641741 | ... AE38: =AE59/AE7 -> 0.38821925
B39: Capex/sales | C39: =-C63/C7 -> 0.039993288 | D39: =-D63/D7 -> 0.040368016 | E39: =-E63/E7 -> 0.041068339 | F39: =-F63/F7 -> 0.029882783 | G39: =-G63/G7 -> 0.025940879 | H39: =-H63/H7 -> 0.0079979415 | I39: =-I63/I7 -> 0.031115569 | J39: =-J63/J7 -> 0.031115569 | L39: =-L63/L7 -> 0 | M39: =-M63/M7 -> 0.071354216 | N39: =-N63/N7 -> 0 | O39: =-O63/O7 -> 0.072189648 | P39: =-P63/P7 -> 0 | Q39: =-Q63/Q7 -> 0.077956344 | R39: =-R63/R7 -> 0 | S39: =-S63/S7 -> 0.037781399 | ... AE39: =-AE63/AE7 -> 0.044668666
B41: EBITDA | C41: =C3 -> 43921 | D41: =D3 -> 44286 | E41: =E3 -> 44651 | F41: =F3 -> 45016 | G41: =G3 -> 45382 | H41: =H3 -> 45747 | I41: =I3 -> 46112 | J41: =J2 -> LTM | L41: =L3 -> 44377 | M41: =M3 -> 44469 | N41: =N3 -> 44561 | O41: =O3 -> 44651 | P41: =P3 -> 44742 | Q41: =Q3 -> 44834 | R41: =R3 -> 44926 | S41: =S3 -> 45016 | ... AE41: =AE3 -> 46112
B42: Operating profit | C42: =C18 -> 113340 | D42: =D18 -> 136840 | E42: =E18 -> 168470 | F42: =F18 -> 180820 | G42: =G18 -> 105750 | H42: =H18 -> 140810 | I42: =I18 -> 164940 | J42: =J18 -> 164940 | L42: =L18 -> 32270 | M42: =M18 -> 35760 | N42: =N18 -> 42510 | O42: =O18 -> 57930 | P42: =P18 -> 39130 | Q42: =Q18 -> 45890 | R42: =R18 -> 50690 | S42: =S18 -> 45110 | ... AE42: =AE18 -> 53670
B43: Depreciation & amortization | C43: =-C16 -> 20120 | D43: =-D16 -> 21730 | E43: =-E16 -> 23590 | F43: =-F16 -> 25470 | G43: =-G16 -> 27630 | H43: =-H16 -> 27500 | I43: =-I16 -> 32440 | J43: =SUM(AB43:AE43) -> 32440 | L43: =-L16 -> 5510 | M43: =-M16 -> 5660 | N43: =-N16 -> 6000 | O43: =E43-SUM(L43:N43) -> 6420 | P43: =-P16 -> 5880 | Q43: =-Q16 -> 6080 | R43: =-R16 -> 6240 | S43: =F43-SUM(P43:R43) -> 7270 | T43: =-T16 -> 6360 | U43: =-U16 -> 6570 | V43: =-V16 -> 6760 | W43: =G43-SUM(T43:V43) -> 7940 | X43: =-X16 -> 6600 | Y43: =-Y16 -> 6970 | Z43: =-Z16 -> 6880 | AA43: =H43-SUM(X43:Z43) -> 7050 | AB43: =-AB16 -> 7310 | AC43: =-AC16 -> 7710 | AD43: =-AD16 -> 8270 | AE43: =-AE16 -> 9150
B44: EBITDA | C44: =SUM(C42:C43) -> 133460 | D44: =SUM(D42:D43) -> 158570 | E44: =SUM(E42:E43) -> 192060 | F44: =SUM(F42:F43) -> 206290 | G44: =SUM(G42:G43) -> 133380 | H44: =SUM(H42:H43) -> 168310 | I44: =SUM(I42:I43) -> 197380 | J44: =SUM(J42:J43) -> 197380 | L44: =SUM(L42:L43) -> 37780 | M44: =SUM(M42:M43) -> 41420 | N44: =SUM(N42:N43) -> 48510 | O44: =SUM(O42:O43) -> 64350 | P44: =SUM(P42:P43) -> 45010 | Q44: =SUM(Q42:Q43) -> 51970 | R44: =SUM(R42:R43) -> 56930 | S44: =SUM(S42:S43) -> 52380 | ... AE44: =SUM(AE42:AE43) -> 62820
...

Sheet KPIs
B2: UPL Ltd | C2: Annual | D2: Annual | E2: Annual | F2: Annual | G2: Annual | H2: Annual | I2: Annual | J2: LTM | L2: Quarters | M2: Quarters | N2: Quarters | O2: Quarters | P2: Quarters | Q2: Quarters | R2: Quarters | S2: Quarters | T2: Quarters | U2: Quarters | V2: Quarters | W2: Quarters | X2: Quarters | Y2: Quarters | Z2: Quarters | AA2: Quarters | AB2: Quarters | AC2: Quarters | AD2: Quarters | AE2: Quarters
B3: (INR million) | C3: 43921 | D3: 44286 | E3: 44651 | F3: 45016 | G3: 45382 | H3: 45747 | I3: 46112 | J3: =AE3 -> 46112 | L3: 44377 | M3: 44469 | N3: 44561 | O3: 44651 | P3: 44742 | Q3: 44834 | R3: 44926 | S3: 45016 | T3: 45107 | U3: 45199 | V3: 45291 | W3: 45382 | X3: 45473 | Y3: 45565 | Z3: 45657 | AA3: 45747 | AB3: 45838 | AC3: 45930 | AD3: 46022 | AE3: 46112
C4: Act | D4: Act | E4: Act | F4: Act | G4: Act | H4: Act | I4: Act | J4: Act | L4: Act | M4: Act | N4: Act | O4: Act | P4: Act | Q4: Act | R4: Act | S4: Act | T4: Act | U4: Act | V4: Act | W4: Act | X4: Act | Y4: Act | Z4: Act | AA4: Act | AB4: Act | AC4: Act | AD4: Act | AE4: Act
C5: FY | D5: FY | E5: FY | F5: FY | G5: FY | H5: FY | I5: FY | J5: LTM | L5: 1Q | M5: 2Q | N5: 3Q | O5: 4Q | P5: 1Q | Q5: 2Q | R5: 3Q | S5: 4Q | T5: 1Q | U5: 2Q | V5: 3Q | W5: 4Q | X5: 1Q | Y5: 2Q | Z5: 3Q | AA5: 4Q | AB5: 1Q | AC5: 2Q | AD5: 3Q | AE5: 4Q
B7: Revenue breakup by region
B8: Latin America | C8: 137640 | D8: 148630 | E8: 180400 | F8: 219750 | G8: 172540 | H8: 176000 | I8: 193580 | J8: =SUM(AB8:AE8) -> 193580 | L8: 25070 | M8: 50880 | N8: 46830 | O8: =E8-SUM(L8:N8) -> 57620 | P8: 34640 | Q8: 60920 | R8: 59740 | S8: =F8-SUM(P8:R8) -> 64450 | T8: 29650 | U8: 50330 | V8: 42870 | W8: =G8-SUM(T8:V8) -> 49690 | X8: 26590 | Y8: 50430 | Z8: 48150 | AA8: =H8-SUM(X8:Z8) -> 50830 | AB8: 24010 | AC8: 56930 | AD8: 51370 | AE8: =I8-SUM(AB8:AD8) -> 61270
B9: North America | C9: 56350 | D9: 56910 | E9: 78100 | F9: 87350 | G9: 38930 | H9: 60700 | I9: 71820 | J9: =SUM(AB9:AE9) -> 71820 | L9: 12210 | M9: 9580 | N9: 21170 | O9: =E9-SUM(L9:N9) -> 35140 | P9: 17960 | Q9: 11850 | R9: 27450 | S9: =F9-SUM(P9:R9) -> 30090 | T9: 8700 | U9: 12630 | V9: 9900 | W9: =G9-SUM(T9:V9) -> 7700 | X9: 12350 | Y9: 5580 | Z9: 15710 | AA9: =H9-SUM(X9:Z9) -> 27060 | AB9: 13370 | AC9: 9070 | AD9: 16170 | AE9: =I9-SUM(AB9:AD9) -> 33210
B10: Europe | C10: 57140 | D10: 64220 | E10: 68900 | F10: 73240 | G10: 66090 | H10: 71900 | I10: 81670 | J10: =SUM(AB10:AE10) -> 81670 | L10: 15220 | M10: 13360 | N10: 14060 | O10: =E10-SUM(L10:N10) -> 26260 | P10: 17280 | Q10: 13540 | R10: 14440 | S10: =F10-SUM(P10:R10) -> 27980 | T10: 12590 | U10: 5070 | V10: 10060 | W10: =G10-SUM(T10:V10) -> 38370 | X10: 14250 | Y10: 13680 | Z10: 12850 | AA10: =H10-SUM(X10:Z10) -> 31120 | AB10: 15350 | AC10: 13710 | AD10: 15540 | AE10: =I10-SUM(AB10:AD10) -> 37070
B11: India | C11: 38280 | D11: 46770 | E11: 56900 | F11: 65390 | G11: 55030 | H11: 59500 | I11: 63430 | J11: =SUM(AB11:AE11) -> 63430 | L11: 19140 | M11: 14830 | N11: 9070 | O11: =E11-SUM(L11:N11) -> 13860 | P11: 20670 | Q11: 18080 | R11: 10750 | S11: =F11-SUM(P11:R11) -> 15890 | T11: 20540 | U11: 13870 | V11: 8600 | W11: =G11-SUM(T11:V11) -> 12020 | X11: 18720 | Y11: 15710 | Z11: 11050 | AA11: =H11-SUM(X11:Z11) -> 14020 | AB11: 22620 | AC11: 16600 | AD11: 11480 | AE11: =I11-SUM(AB11:AD11) -> 12730
B12: Rest of World | C12: 68150 | D12: 70440 | E12: 78100 | F12: 90020 | G12: 98400 | H12: 98300 | I12: 107890 | J12: =SUM(AB12:AE12) -> 107890 | L12: 13500 | M12: 17020 | N12: 21850 | O12: =E12-SUM(L12:N12) -> 25730 | P12: 17650 | Q12: 20670 | R12: 24410 | S12: =F12-SUM(P12:R12) -> 27290 | T12: 18140 | U12: 19800 | V12: 27440 | W12: =G12-SUM(T12:V12) -> 33020 | X12: 18760 | Y12: 25500 | Z12: 21310 | AA12: =H12-SUM(X12:Z12) -> 32730 | AB12: 16810 | AC12: 23880 | AD12: 28140 | AE12: =I12-SUM(AB12:AD12) -> 39060
B13: Total | C13: =SUM(C7:C12) -> 357560 | D13: =SUM(D7:D12) -> 386970 | E13: =SUM(E7:E12) -> 462400 | F13: =SUM(F7:F12) -> 535750 | G13: =SUM(G7:G12) -> 430990 | H13: =SUM(H7:H12) -> 466400 | I13: =SUM(I7:I12) -> 518390 | J13: =SUM(J8:J12) -> 518390 | L13: =SUM(L7:L12) -> 85140 | M13: =SUM(M7:M12) -> 105670 | N13: =SUM(N7:N12) -> 112980 | O13: =SUM(O7:O12) -> 158610 | P13: =SUM(P7:P12) -> 108200 | Q13: =SUM(Q7:Q12) -> 125060 | R13: =SUM(R7:R12) -> 136790 | S13: =SUM(S7:S12) -> 165700 | ... AE13: =SUM(AE7:AE12) -> 183340
B14: Check | C14: =C13-Model!C7 -> 0 | D14: =D13-Model!D7 -> 30 | E14: =E13-Model!E7 -> 0 | F14: =F13-Model!F7 -> -10 | G14: =G13-Model!G7 -> 10 | H14: =H13-Model!H7 -> 30 | I14: =I13-Model!I7 -> 0 | L14: =L13-Model!L7 -> -10 | M14: =M13-Model!M7 -> 0 | N14: =N13-Model!N7 -> 10 | O14: =O13-Model!O7 -> 0 | P14: =P13-Model!P7 -> -10 | Q14: =Q13-Model!Q7 -> -10 | R14: =R13-Model!R7 -> 0 | S14: =S13-Model!S7 -> 10 | ... AE14: =AE13-Model!AE7 -> -10
B16: Revenue contribution by region (%)
B17: Latin America | C17: =C8/C$13 -> 0.38494239 | D17: =D8/D$13 -> 0.38408662 | E17: =E8/E$13 -> 0.39013841 | F17: =F8/F$13 -> 0.41017266 | G17: =G8/G$13 -> 0.40033411 | H17: =H8/H$13 -> 0.37735849 | I17: =I8/I$13 -> 0.37342541 | J17: =J8/J$13 -> 0.37342541 | L17: =L8/L$13 -> 0.29445619 | M17: =M8/M$13 -> 0.48149901 | N17: =N8/N$13 -> 0.41449814 | O17: =O8/O$13 -> 0.363281 | P17: =P8/P$13 -> 0.32014787 | Q17: =Q8/Q$13 -> 0.48712618 | R17: =R8/R$13 -> 0.43672783 | S17: =S8/S$13 -> 0.38895594 | ... AE17: =AE8/AE$13 -> 0.33418785
B18: North America | C18: =C9/C$13 -> 0.15759593 | D18: =D9/D$13 -> 0.14706566 | E18: =E9/E$13 -> 0.16890138 | F18: =F9/F$13 -> 0.16304246 | G18: =G9/G$13 -> 0.090326922 | H18: =H9/H$13 -> 0.1301458 | I18: =I9/I$13 -> 0.13854434 | J18: =J9/J$13 -> 0.13854434 | L18: =L9/L$13 -> 0.14341085 | M18: =M9/M$13 -> 0.090659601 | N18: =N9/N$13 -> 0.1873783 | O18: =O9/O$13 -> 0.22154971 | P18: =P9/P$13 -> 0.16598891 | Q18: =Q9/Q$13 -> 0.094754518 | R18: =R9/R$13 -> 0.20067256 | S18: =S9/S$13 -> 0.18159324 | ... AE18: =AE9/AE$13 -> 0.18113887
B19: Europe | C19: =C10/C$13 -> 0.15980535 | D19: =D10/D$13 -> 0.16595602 | E19: =E10/E$13 -> 0.14900519 | F19: =F10/F$13 -> 0.13670555 | G19: =G10/G$13 -> 0.15334463 | H19: =H10/H$13 -> 0.15415952 | I19: =I10/I$13 -> 0.15754548 | J19: =J10/J$13 -> 0.15754548 | L19: =L10/L$13 -> 0.17876439 | M19: =M10/M$13 -> 0.12643134 | N19: =N10/N$13 -> 0.1244468 | O19: =O10/O$13 -> 0.16556333 | P19: =P10/P$13 -> 0.15970425 | Q19: =Q10/Q$13 -> 0.10826803 | R19: =R10/R$13 -> 0.10556327 | S19: =S10/S$13 -> 0.16885938 | ... AE19: =AE10/AE$13 -> 0.20219265
B20: India | C20: =C11/C$13 -> 0.10705896 | D20: =D11/D$13 -> 0.12086208 | E20: =E11/E$13 -> 0.12305363 | F20: =F11/F$13 -> 0.1220532 | G20: =G11/G$13 -> 0.12768278 | H20: =H11/H$13 -> 0.1275729 | I20: =I11/I$13 -> 0.12235961 | J20: =J11/J$13 -> 0.12235961 | L20: =L11/L$13 -> 0.2248062 | M20: =M11/M$13 -> 0.14034258 | N20: =N11/N$13 -> 0.080279696 | O20: =O11/O$13 -> 0.08738415 | P20: =P11/P$13 -> 0.19103512 | Q20: =Q11/Q$13 -> 0.14457061 | R20: =R11/R$13 -> 0.078587616 | S20: =S11/S$13 -> 0.095896198 | ... AE20: =AE11/AE$13 -> 0.069433839
B21: Rest of World | C21: =C12/C$13 -> 0.19059738 | D21: =D12/D$13 -> 0.18202961 | E21: =E12/E$13 -> 0.16890138 | F21: =F12/F$13 -> 0.16802613 | G21: =G12/G$13 -> 0.22831156 | H21: =H12/H$13 -> 0.21076329 | I21: =I12/I$13 -> 0.20812516 | J21: =J12/J$13 -> 0.20812516 | L21: =L12/L$13 -> 0.15856237 | M21: =M12/M$13 -> 0.16106747 | N21: =N12/N$13 -> 0.19339706 | O21: =O12/O$13 -> 0.1622218 | P21: =P12/P$13 -> 0.16312384 | Q21: =Q12/Q$13 -> 0.16528067 | R21: =R12/R$13 -> 0.17844872 | S21: =S12/S$13 -> 0.16469523 | ... AE21: =AE12/AE$13 -> 0.2130468
B23: Revenue growth by region (%)
B24: Latin America | C24: 0.24 | D24: 0.08 | E24: 0.21 | F24: 0.22 | G24: -0.21 | H24: 0.02 | I24: 0.1 | L24: 0.24 | M24: 0.2 | N24: 0.22 | O24: 0.21 | P24: 0.38 | Q24: 0.2 | R24: 0.28 | S24: 0.12 | T24: -0.14 | U24: -0.17 | V24: -0.28 | W24: -0.23 | X24: -0.1 | Y24: 0 | Z24: 0.12 | AA24: 0.02 | AB24: -0.1 | AC24: 0.13 | AD24: 0.07 | AE24: 0.21
B25: North America | C25: 0.13 | D25: 0.01 | E25: 0.37 | F25: 0.12 | G25: -0.55 | H25: 0.56 | I25: 0.18 | L25: 0.19 | M25: 0.24 | N25: 0.57 | O25: 0.38 | P25: 0.47 | Q25: 0.24 | R25: 0.3 | S25: -0.14 | T25: -0.52 | U25: -0.07 | V25: -0.64 | W25: -0.49 | X25: 0.42 | Y25: 0.1 | Z25: 0.59 | AA25: 0.77 | AB25: 0.08 | AC25: 0.63 | AD25: 0.03 | AE25: 0.23
B26: Europe | C26: -0.07 | D26: 0.12 | E26: 0.07 | F26: 0.07 | G26: -0.1 | H26: 0.09 | I26: 0.14 | L26: -0.11 | M26: 0.31 | N26: 0.26 | O26: 0.02 | P26: 0.13 | Q26: 0.01 | R26: 0.03 | S26: 0.07 | T26: -0.27 | U26: -0.57 | V26: -0.3 | W26: 0.1 | X26: 0.13 | Y26: 0.08 | Z26: 0.28 | AA26: 0.09 | AB26: 0.08 | AC26: 0 | AD26: 0.21 | AE26: 0.19
B27: India | C27: 0.11 | D27: 0.22 | E27: 0.11 | F27: 0.13 | G27: -0.16 | H27: 0.08 | I27: 0.07 | L27: 0.27 | M27: 0.05 | N27: 0 | O27: 0.63 | P27: 0.08 | Q27: 0.22 | R27: 0.19 | S27: 0.15 | T27: -0.01 | U27: -0.23 | V27: -0.2 | W27: -0.24 | X27: -0.09 | Y27: 0.13 | Z27: 0.28 | AA27: 0.17 | AB27: 0.21 | AC27: 0.06 | AD27: 0.04 | AE27: -0.09
B28: Rest of World | C28: 0.12 | D28: 0.03 | E28: 0.22 | F28: 0.1 | G28: 0.09 | H28: 0 | I28: 0.1 | L28: -0.14 | M28: 0.13 | N28: 0.15 | O28: 0.25 | P28: 0.31 | Q28: 0.21 | R28: 0.12 | S28: 0.06 | T28: 0.03 | U28: -0.04 | V28: 0.12 | W28: 0.21 | X28: 0.03 | Y28: 0.29 | Z28: -0.22 | AA28: -0.01 | AB28: -0.1 | AC28: -0.06 | AD28: 0.32 | AE28: 0.19
C30: Annual | D30: Annual | E30: Annual | F30: Annual | G30: Annual | H30: Annual | I30: Annual | J30: LTM | L30: Quarters | M30: Quarters | N30: Quarters | O30: Quarters | P30: Quarters | Q30: Quarters | R30: Quarters | S30: Quarters | T30: Quarters | U30: Quarters | V30: Quarters | W30: Quarters | X30: Quarters | Y30: Quarters | Z30: Quarters | AA30: Quarters | AB30: Quarters | AC30: Quarters | AD30: Quarters | AE30: Quarters
B31: =Model!B30 -> As % of Revenues unless stated otherwise | C31: 43921 | D31: 44286 | E31: 44651 | F31: 45016 | G31: 45382 | H31: =H3 -> 45747 | I31: =I3 -> 46112 | J31: =AE31 -> 46112 | L31: 44377 | M31: 44469 | N31: 44561 | O31: 44651 | P31: 44742 | Q31: 44834 | R31: 44926 | S31: 45016 | T31: 45107 | U31: 45199 | V31: 45291 | W31: 45382 | X31: 45473 | Y31: =Y3 -> 45565 | Z31: =Z3 -> 45657 | AA31: =AA3 -> 45747 | AB31: 45838 | AC31: =AC3 -> 45930 | AD31: =AD3 -> 46022 | AE31: =AE3 -> 46112
B32: Volume yoy | E32: 0.08 | F32: 0.002 | G32: -0.06 | H32: 0.13 | I32: 0.08 | L32: 0.06 | M32: 0.15 | N32: 0.11 | O32: 0.03 | P32: 0.06 | Q32: -0.07 | R32: 0.01 | S32: 0.01 | T32: -0.09 | U32: -0.07 | V32: -0.05 | W32: -0.02 | X32: -0.09 | Y32: 0.16 | Z32: 0.09 | AA32: 0.11 | AB32: -0.01 | AC32: 0.07 | AD32: 0.08
B33: Price yoy | E33: 0.1 | F33: 0.1 | G33: -0.17 | H33: -0.03 | I33: -0.03 | L33: 0.02 | M33: 0.03 | N33: 0.13 | O33: 0.19 | P33: 0.18 | Q33: 0.21 | R33: 0.13 | S33: -0.03 | T33: -0.1 | U33: -0.15 | V33: -0.24 | W33: -0.15 | X33: -0.1 | Y33: -0.07 | Z33: 0.05 | AA33: 0.01 | AB33: 0.01 | AC33: -0.02 | AD33: 0.03
B34: Revenue | E34: =E13 -> 462400 | F34: =F13 -> 535750 | G34: =G13 -> 430990 | H34: =H13 -> 466400 | I34: =I13 -> 518390 | J34: =SUM(AB34:AE34) -> 518390 | L34: =L13 -> 85140 | M34: =M13 -> 105670 | N34: =N13 -> 112980 | O34: =O13 -> 158610 | P34: =P13 -> 108200 | Q34: =Q13 -> 125060 | R34: =R13 -> 136790 | S34: =S13 -> 165700 | ... AE34: =AE13 -> 183340
B35: Revenue yoy | E35: =Model!E9 -> 0.19501732 | F35: =Model!F9 -> 0.15865052 | G35: =Model!G9 -> -0.19557264 | H35: =Model!H9 -> 0.082115179 | I35: =Model!I9 -> 0.11154234 | J35: =I35 -> 0.11154234 | L35: 0.09 | M35: 0.18 | N35: 0.24 | O35: 0.24 | P35: =P13/L13-1 -> 0.27084802 | Q35: =Q13/M13-1 -> 0.18349579 | R35: =R13/N13-1 -> 0.21074526 | S35: =S13/O13-1 -> 0.044700839 | T35: =T13/P13-1 -> -0.17171904 | U35: =U13/Q13-1 -> -0.18679034 | V35: =V13/R13-1 -> -0.27721325 | W35: =W13/S13-1 -> -0.15027158 | ... AE35: =AE13/AA13-1 -> 0.17706728
B37: EBITDA | E37: =Model!E49 -> 101650 | F37: =Model!F49 -> 111780 | G37: =Model!G49 -> 55150 | H37: =Model!H49 -> 81200 | I37: =Model!I49 -> 95880 | J37: =SUM(AB37:AE37) -> 95880 | L37: =Model!L49 -> 18620 | M37: =Model!M49 -> 20450 | N37: =Model!N49 -> 26660 | O37: =Model!O49 -> 35920 | P37: =Model!P49 -> 23420 | Q37: =Model!Q49 -> 27680 | R37: =Model!R49 -> 30350 | S37: =Model!S49 -> 30330 | ... AE37: =Model!AE49 -> 36460
B38: EBITDA yoy | E38: =Model!E50 -> 0.18763874 | F38: =Model!F50 -> 0.099655681 | G38: =Model!G50 -> -0.50662015 | H38: =Model!H50 -> 0.47234814 | I38: =Model!I50 -> 0.18078818 | J38: =I38 -> 0.18078818 | L38: 0.09 | M38: 0.13 | N38: 0.21 | O38: 0.26 | P38: =P37/L37-1 -> 0.25778733 | Q38: =Q37/M37-1 -> 0.35354523 | R38: =R37/N37-1 -> 0.1384096 | S38: =S37/O37-1 -> -0.15562361 | T38: =T37/P37-1 -> -0.31981213 | U38: =U37/Q37-1 -> -0.43171965 | V38: =V37/R37-1 -> -0.86293245 | W38: =W37/S37-1 -> -0.36267722 | ... AE38: =AE37/AA37-1 -> 0.12669963
B39: EBITDA margin | E39: =Model!E51 -> 0.21983131 | F39: =Model!F51 -> 0.2086382 | G39: =Model!G51 -> 0.12796417 | H39: =Model!H51 -> 0.17411068 | I39: =Model!I51 -> 0.18495727 | J39: =I39 -> 0.18495727 | L39: =Model!L51 -> 0.21867293 | M39: =Model!M51 -> 0.19352702 | N39: =Model!N51 -> 0.23599186 | O39: =Model!O51 -> 0.22646744 | P39: =Model!P51 -> 0.21643101 | Q39: =Model!Q51 -> 0.22131606 | R39: =Model!R51 -> 0.22187294 | S39: =Model!S51 -> 0.18305269 | ... AE39: =Model!AE51 -> 0.19885465
C81: 43921 | D81: 44286 | E81: 44651 | F81: 45016 | G81: 45382 | H81: 45747 | I81: 46112 | J81: =J3 -> 46112 | L81: 44377 | M81: 44469 | N81: 44561 | O81: 44651 | P81: 44742 | Q81: 44834 | R81: 44926 | S81: 45016 | T81: 45107 | U81: 45199 | V81: 45291 | W81: 45382 | X81: 45473 | Y81: =Y3 -> 45565 | Z81: =Z3 -> 45657 | AA81: =AA3 -> 45747 | AB81: 45838 | AC81: =AC3 -> 45930 | AD81: =AD3 -> 46022 | AE81: =AE3 -> 46112
B82: EBITDA | E82: =E37 -> 101650 | F82: =F37 -> 111780 | G82: =G37 -> 55150 | H82: =H37 -> 81200 | I82: =I37 -> 95880 | J82: =J37 -> 95880 | L82: =L37 -> 18620 | M82: =M37 -> 20450 | N82: =N37 -> 26660 | O82: =O37 -> 35920 | P82: =P37 -> 23420 | Q82: =Q37 -> 27680 | R82: =R37 -> 30350 | S82: =S37 -> 30330 | ... AE82: =AE37 -> 36460
B83: EBITDA margin | E83: =E39 -> 0.21983131 | F83: =F39 -> 0.2086382 | G83: =G39 -> 0.12796417 | H83: =H39 -> 0.17411068 | I83: =I39 -> 0.18495727 | J83: =J39 -> 0.18495727 | L83: =L39 -> 0.21867293 | M83: =M39 -> 0.19352702 | N83: =N39 -> 0.23599186 | O83: =O39 -> 0.22646744 | P83: =P39 -> 0.21643101 | Q83: =Q39 -> 0.22131606 | R83: =R39 -> 0.22187294 | S83: =S39 -> 0.18305269 | ... AE83: =AE39 -> 0.19885465

Sheet Detailed Debt information
A3: FY25 | B3: Below details published only on Annual basis by company
B6: All values in INR Millions, recorded at amortised cost
B7: Particulars | C7: Effective Interest Date | D7: Maturity | E7: FY23 | F7: FY24 | G7: FY25
E8: 45016 | F8: 45382 | G8: 45747
B9: A) Non-current borrowings
B10: 1) Debentures
B11: i) Unsecured Redeemable non-convertible debentures (NCDs) | C11: 10.40% to 10.470% | D11: 2021-2023 | E11: 0 | F11: 0 | G11: 0
B13: 2) Bonds (Unsecured)
B14: i) 4.50% Senior Notes (Note 1) | C14: 0.045 | D14: 8th March 2028 | E14: 22540 | F14: 22910 | G14: 23510
B15: ii) 4.625% Senior Notes (Note 2) | C15: 0.04625 | D15: 16th June 2030 | E15: 36370 | F15: 36980 | G15: 37970
B16: Total Bonds | E16: =SUM(E14:E15) -> 58910 | F16: =SUM(F14:F15) -> 59890 | G16: =SUM(G14:G15) -> 61480
B18: 3) Term Loans
B19: i) From Bank
B20: a) Foreign currency loan (Unsecured) | C20: SOFR + 1.25% and 1.40% | D20: Sep 2025 and Sep 2027 | E20: 61170 | F20: 95200 | G20: 76620
B21: b) Sustainability linked Foreign currency loan (Unsecured) | C21: SOFR + 1.27%, 1.46%, 1.65% | D21: January 2024/March 2026/Dec 2026 | E21: 97720 | F21: 82780 | G21: 85120
B22: ii) From others (Unsecured) | C22: 0.02 | D22: 1st January 2023 | E22: 0 | F22: 2230 | G22: 1980
B23: Total Term Loans | E23: =SUM(E20:E22) -> 158890 | F23: =SUM(F20:F22) -> 180210 | G23: =SUM(G20:G22) -> 163720
B25: Total Non-Current Borrowings | E25: =E23+E16+E11 -> 217800 | F25: =F23+F16+F11 -> 240100 | G25: =G23+G16+G11 -> 225200
B28: B) Current borrowings
B29: 1) Loan from banks
B30: i) Secured | C30: Euribor +1.30% to 8.0% | D30: On demand | E30: 830 | F30: 1950 | G30: 0
B31: ii) Unsecured | G31: 530
B32: a) Working capital loan repayable on demand from banks: | C32: 3.45% to 13% | D32: On demand | E32: 6730 | F32: 37380 | G32: 9130
B33: b) Interest accrued and not due on borrowings | C33: NA | D33: NA | E33: 1130 | F33: 1950 | G33: 1780
B34: c) Commercial paper | C34: 0.084 | D34: Within 90 days | E34: 3500 | F34: 3000 | G34: 500
B35: Total Loans from banks | E35: =SUM(E30:E34) -> 12190 | F35: =SUM(F30:F34) -> 44280 | G35: =SUM(G30:G34) -> 11940
B37: 2) Discounted trade receivables (Unsecured) | C37: 5.00% - 9.90% | D37: 2021-22 | E37: 0 | F37: 0 | G37: 0
B39: 3) Current maturities of non current borrowings | C39: NA | D39: NA | E39: 16360 | F39: 0 | G39: 42570
B41: Total Current Borrowings | E41: =E35+E37+E39 -> 28550 | F41: =F35+F37+F39 -> 44280 | G41: =G35+G37+G39 -> 54510
B44: Total Non current borrowings | E44: =E25 -> 217800 | F44: =F25 -> 240100 | G44: =G25 -> 225200
B45: Less current portion | E45: =E39 -> 16360 | F45: =F39 -> 0 | G45: =G39 -> 42570
B46: Net Non Current Borrowings | E46: =E44-E45 -> 201440 | F46: =F44-F45 -> 240100 | G46: =G44-G45 -> 182630
B47: Secured Portion | E47: 0 | F47: 2230 | G47: 1980
B48: Unsecured Portion | E48: 201440 | F48: 237870 | G48: 223220
B49: Net Current Borrowings | E49: =E41 -> 28550 | F49: =F41 -> 44280 | G49: =G41 -> 54510
B50: Secured Portion | E50: 830 | F50: 1950 | G50: =G35 -> 11940
B51: Unsecured Portion | E51: 27720 | F51: 42330 | G51: =G39 -> 42570
B52: Total Borrowings | E52: =E46+E49 -> 229990 | F52: =F46+F49 -> 284380 | G52: =G46+G49 -> 237140
B53: Check | E53: =E52-Model!F109 -> 0 | F53: =F52-Model!G109 -> 0 | G53: =G52-Model!H109 -> 0
B57: Note 1
...
