Workbook
Name \A: #REF!
Name \B: #REF!
Name \C: #REF!
Name \L: #REF!
Name \M: #REF!
Name \P: #REF!
Name \Y: #REF!
Name _01_30_04: MonthlyOpStats
Name _1_30_01: MonthlyOpStats
Name _1_30_02: MonthlyOpStats
Name _1_31_01: MonthlyOpStats
Name _1_31_02: MonthlyOpStats
Name _12_31_05: MonthlyOpStats
Name _A: #REF!
Name _A___0: #REF!
Name _B: #REF!
Name _B___0: #REF!
Name _C: #REF!
Name _C___0: #REF!
Name _ent1: [1]Inputs!$J$17
Name _ent10: [1]Inputs!$J$476
Name _ent11: [1]Inputs!$J$527
Name _ent12: [1]Inputs!$J$578
Name _ent13: [1]Inputs!$J$629
Name _ent14: [1]Inputs!$J$680
Name _ent15: [1]Inputs!$J$731
Name _ent2: [1]Inputs!$J$68
Name _ent3: [1]Inputs!$J$119
Name _ent4: [1]Inputs!$J$170
Name _ent5: [1]Inputs!$J$221
Name _ent6: [1]Inputs!$J$272
Name _ent7: [1]Inputs!$J$323
Name _ent8: [1]Inputs!$J$374
Name _ent9: [1]Inputs!$J$425
Name _eps1: [1]Inputs!$P$42
Name _eps10: [1]Inputs!$P$501
Name _eps11: [1]Inputs!$P$552
Name _eps12: [1]Inputs!$P$603
Name _eps13: [1]Inputs!$P$654
Name _eps14: [1]Inputs!$P$705
Name _eps15: [1]Inputs!$P$756
Name _eps2: [1]Inputs!$P$93
Name _eps3: [1]Inputs!$P$144
Name _eps4: [1]Inputs!$P$195
Name _eps5: [1]Inputs!$P$246
Name _eps6: [1]Inputs!$P$297
Name _eps7: [1]Inputs!$P$348
Name _eps8: [1]Inputs!$P$399
Name _eps9: [1]Inputs!$P$450
Name _fye1: [1]Inputs!$E$12
Name _fye10: [1]Inputs!$E$471
Name _fye11: [1]Inputs!$E$522
Name _fye12: [1]Inputs!$E$573
Name _fye13: [1]Inputs!$E$624
Name _fye14: [1]Inputs!$E$675
Name _fye15: [1]Inputs!$E$726
Name _fye2: [1]Inputs!$E$63
Name _fye3: [1]Inputs!$E$114
Name _fye4: [1]Inputs!$E$165
Name _fye5: [1]Inputs!$E$216

Sheet Capitalisation
A3: 1Q26
B5: Debt Breakdown as on 31-Mar-2026 | C5: USD mn | D5: Leverage | H5: Company Reported | I5: USD mn | J5: Leverage
B6: Long-term debt - Including current portion | C6: =SUM(C7:C16) -> 1175.6845
B7: Series B Senior Note 60,000,000 5.31% (2) September 2027 | C7: 60
B8: Series B Senior Note 45,000,000 5.85% (2) May 2028 | C8: 45
B9: MetLife 10-year 118,000,000 4.75% (1) December 2027 | C9: 0
B10: Series RC Senior Note 70,000,000 5.18% (3) June 2029 | C10: 70
B11: Series RD Senior Note 15,000,000 5.28% (4) June 2031 | C11: 15
B12: Vesta ESG Global bond 35/8 05/31 350,000,000 3.63% (5) May 2031 | C12: 350
B13: Facility – Tranche I 75,000,000 SOFR + 130 bp (6) December 2027 | C13: 75
B14: Facility – Tranche II 75,000,000 SOFR + 150 bp (6) December 2029 | C14: 75
B15: Senior Notes 2033 500,000,000 5.50% (7) January 2033 | C15: 500
B16: (Less) Direct Issuance Costs | C16: -14.315517
B18: Operating lease liabilities | C18: =Model!$AP$121 -> 1.383273
B20: Total Loans & Borrowings | C20: =C6+C18 -> 1177.0678 | D20: =C20/C25 -> 4.9470288
B21: Cash and Cash Equivalents | C21: =Model!$AP$127 -> 206.14451
B22: Net debt exc Short term inv | C22: =C20-C21 -> 970.92324 | D22: =C22/C25 -> 4.0806361
B23: Equity | C23: =Model!$AP$131 -> 2858.6722
B24: Total Capitalisation | C24: =C22+C23 -> 3829.5954
B25: LTM Adjusted EBITDA | C25: =Model!$AP$98 -> 237.93429
B26: check | C26: =C20-Model!$AP$126 -> 0
B29: Liquidity at 1Q26 | C29: USD mn
B30: Cash and cash equivalents | C30: 206.12475
B31: Restricted cash - Current | C31: 0.019765
B32: Restricted cash - Non Current | C32: 0
B33: Total Liquidity | C33: =+C30+C31+C32 -> 206.14451
B34: check | C34: =C33-C21 -> 0
B37: Debt maturity at 1Q26 | C37: USD mn
B38: 2027 | C38: =60+75 -> 135
B39: 2028 | C39: =45 -> 45
B40: 2029 | C40: =70+75 -> 145
B41: 2030 and later | C41: =15+350+500 -> 865
B42: (Less) Direct Issuance Costs | C42: =C16 -> -14.315517
B43: Total long-term debt | C43: =SUM(C38:C42) -> 1175.6845
B44: check | C44: =C43-C6 -> 0
B47: Lease maturity at 1Q26 | C47: USD mn
B48: Not later than 1 year | C48: 0.719902
B49: Later than 1 year and not later than 5 years | C49: 0.77466
B50: (Less) future finance cost | C50: -0.111289
B51: Total long-term debt | C51: =SUM(C48:C50) -> 1.383273
...

Sheet Model
B2: Corporación Inmobiliaria Vesta | C2: Annual | D2: Annual | E2: Annual | F2: Annual | G2: Annual | H2: Annual | I2: Annual | J2: Annual | K2: Annual | L2: LTM | N2: Quarters | O2: Quarters | P2: Quarters | Q2: Quarters | R2: Quarters | S2: Quarters | T2: Quarters | U2: Quarters | V2: Quarters | W2: Quarters | X2: Quarters | Y2: Quarters | Z2: Quarters | AA2: Quarters | AB2: Quarters | AC2: Quarters | AD2: Quarters | AE2: Quarters | AF2: Quarters | AG2: Quarters | AH2: Quarters | AI2: Quarters | AJ2: Quarters | AK2: Quarters | AL2: Quarters | AM2: Quarters | AN2: Quarters | AO2: Quarters | AP2: Quarters
B3: (USD million) | C3: 43100 | D3: 43465 | E3: 43830 | F3: 44196 | G3: 44561 | H3: 44926 | I3: 45291 | J3: 45657 | K3: 46022 | L3: =AP3 -> 46112 | N3: 43555 | O3: 43646 | P3: 43738 | Q3: 43830 | R3: 43921 | S3: 44012 | T3: 44104 | U3: 44196 | V3: 44286 | W3: 44377 | X3: 44469 | Y3: 44561 | Z3: 44651 | AA3: 44742 | AB3: 44834 | AC3: 44926 | AD3: 45016 | AE3: 45107 | AF3: 45199 | AG3: 45291 | AH3: 45382 | AI3: 45473 | AJ3: 45565 | AK3: 45657 | AL3: 45747 | AM3: 45838 | AN3: 45930 | AO3: 46022 | AP3: 46112
C4: Act | D4: Act | E4: Act | F4: Act | G4: Act | H4: Act | I4: Act | J4: Act | K4: Act | L4: Act | N4: Act | O4: Act | P4: Act | Q4: Act | R4: Act | S4: Act | T4: Act | U4: Act | V4: Act | W4: Act | X4: Act | Y4: Act | Z4: Act | AA4: Act | AB4: Act | AC4: Act | AD4: Act | AE4: Act | AF4: Act | AG4: Act | AH4: Act | AI4: Act | AJ4: Act | AK4: Act | AL4: Act | AM4: Act | AN4: Act | AO4: Act | AP4: Act
C5: FY | D5: FY | E5: FY | F5: FY | G5: FY | H5: FY | I5: FY | J5: FY | K5: FY | L5: LTM | N5: 1Q | O5: 2Q | P5: 3Q | Q5: 4Q | R5: 1Q | S5: 2Q | T5: 3Q | U5: 4Q | V5: 1Q | W5: 2Q | X5: 3Q | Y5: 4Q | Z5: 1Q | AA5: 2Q | AB5: 3Q | AC5: 4Q | AD5: 1Q | AE5: 2Q | AF5: 3Q | AG5: 4Q | AH5: 1Q | AI5: 2Q | AJ5: 3Q | AK5: 4Q | AL5: 1Q | AM5: 2Q | AN5: 3Q | AO5: 4Q | AP5: 1Q
B6: INCOME STATEMENT | AF6: Restated
B7: Rental Income | C7: =109.427282 -> 109.42728 | D7: 132.66927 | E7: 144.2924 | F7: 149.53589 | G7: 160.69839 | H7: 178.02546 | I7: 213.4483 | J7: 251.9505 | K7: 283.19337 | L7: =SUM(AM7:AP7) -> 292.90351 | N7: 36.290385 | O7: 35.928051 | P7: 35.825569 | Q7: =E7-SUM(N7:P7) -> 36.248397 | R7: 37.695133 | S7: 36.538805 | T7: 37.457861 | U7: =F7-SUM(R7:T7) -> 37.844088 | V7: 38.352404 | W7: 39.756847 | X7: 41.00213 | Y7: =G7-SUM(V7:X7) -> 41.587004 | Z7: 41.988045 | AA7: 41.340864 | AB7: 45.508043 | AC7: =H7-SUM(Z7:AB7) -> 49.188509 | AD7: 49.610889 | AE7: 48.693742 | AF7: 51.613071 | AG7: =I7-SUM(AD7:AF7) -> 63.530594 | AH7: 60.176393 | AI7: 57.668018 | AJ7: 58.377122 | AK7: =J7-SUM(AH7:AJ7) -> 75.728971 | AL7: 67.03901 | AM7: 62.2 | AN7: 72.420925 | AO7: =K7-SUM(AL7:AN7) -> 81.533435 | AP7: 76.749154
B8: Management Fees | C8: 0 | D8: 0 | E8: 0.072677 | F8: 0.319446 | G8: 0.087973 | H8: 0 | I8: 1.019316 | J8: 0.376618 | K8: 0.031437 | L8: =SUM(AM8:AP8) -> 0.006789 | N8: 0 | O8: 0.010681 | P8: 0 | Q8: =E8-SUM(N8:P8) -> 0.061996 | R8: 0.017667 | S8: 0.112015 | T8: 0.019768 | U8: =F8-SUM(R8:T8) -> 0.169996 | V8: 0.041387 | W8: 0.039083 | X8: 0.007502 | Y8: =G8-SUM(V8:X8) -> 1e-06 | Z8: 0 | AA8: 1.756358 | AB8: 0 | AC8: =H8-SUM(Z8:AB8) -> -1.756358 | AD8: 0.327618 | AE8: 3.23069 | AF8: =3.073078+0.330703+0.639933 -> 4.043714 | AG8: =I8-SUM(AD8:AF8) -> -6.582706 | AH8: 0.413263 | AI8: =3.309085+2.037764 -> 5.346849 | AJ8: =2.701432+2.611647 -> 5.313079 | AK8: =J8-SUM(AH8:AJ8) -> -10.696573 | AL8: 0.024648 | AM8: =3.2+1.9 -> 5.1 | AN8: =6789/10^6 -> 0.006789 | AO8: =K8-SUM(AL8:AN8) -> -5.1 | AP8: 0
B9: Total Revenue | C9: =SUM(C7:C8) -> 109.42728 | D9: =SUM(D7:D8) -> 132.66927 | E9: =SUM(E7:E8) -> 144.36508 | F9: =SUM(F7:F8) -> 149.85533 | G9: =SUM(G7:G8) -> 160.78636 | H9: =SUM(H7:H8) -> 178.02546 | I9: =SUM(I7:I8) -> 214.46761 | J9: =SUM(J7:J8) -> 252.32712 | ... L9: =SUM(L7:L8) -> 292.9103 | N9: =SUM(N7:N8) -> 36.290385 | O9: =SUM(O7:O8) -> 35.938732 | P9: =SUM(P7:P8) -> 35.825569 | Q9: =SUM(Q7:Q8) -> 36.310393 | R9: =SUM(R7:R8) -> 37.7128 | S9: =SUM(S7:S8) -> 36.65082 | T9: =SUM(T7:T8) -> 37.477629 | U9: =SUM(U7:U8) -> 38.014084 | ... AP9: =SUM(AP7:AP8) -> 76.749154
B10: % of growth | D10: =(D7/C7)-1 -> 0.21239661 | E10: =(E7/D7)-1 -> 0.087609861 | F10: =(F7/E7)-1 -> 0.036339301 | G10: =(G7/F7)-1 -> 0.07464762 | H10: =(H7/G7)-1 -> 0.10782359 | I10: =(I7/H7)-1 -> 0.19897623 | J10: =(J7/I7)-1 -> 0.18038189 | K10: =(K7/J7)-1 -> 0.12400398 | R10: =(R7/N7)-1 -> 0.038708545 | S10: =(S7/O7)-1 -> 0.016999364 | T10: =(T7/P7)-1 -> 0.045562207 | U10: =(U7/Q7)-1 -> 0.044021009 | V10: =(V7/R7)-1 -> 0.017436495 | W10: =(W7/S7)-1 -> 0.088071901 | X10: =(X7/T7)-1 -> 0.094620165 | Y10: =(Y7/U7)-1 -> 0.098903586 | ... AP10: =(AP7/AL7)-1 -> 0.14484319
B11: COR - Related to Properties that generated rental income | C11: -4.106403 | D11: -4.848618 | E11: -7.26649 | F11: -8.925518 | G11: =-8543961/10^6 -> -8.543961 | H11: =-8940789/10^6 -> -8.940789 | I11: =-13476324/10^6 -> -13.476324 | J11: -21.24416 | K11: -24.104475 | L11: =SUM(AM11:AP11) -> -25.829283 | N11: -1.338009 | O11: -1.689009 | P11: -1.708186 | Q11: =E11-SUM(N11:P11) -> -2.531286 | R11: -2.275524 | S11: -2.589607 | T11: -2.004441 | U11: =F11-SUM(R11:T11) -> -2.055946 | V11: -1.173883 | W11: -2.252464 | X11: -2.473727 | Y11: =G11-SUM(V11:X11) -> -2.643887 | Z11: -1.603949 | AA11: -2.444505 | AB11: -2.342554 | AC11: =H11-SUM(Z11:AB11) -> -2.549781 | AD11: -2.238569 | AE11: -3.390747 | AF11: -3.924533 | AG11: =I11-SUM(AD11:AF11) -> -3.922475 | AH11: -3.786225 | AI11: -5.014314 | AJ11: -5.412651 | AK11: =J11-SUM(AH11:AJ11) -> -7.03097 | AL11: -4.445843 | AM11: -5.6 | AN11: -7.226843 | AO11: =K11-SUM(AL11:AN11) -> -6.831789 | AP11: -6.170651
B12: COR - Related to Properties that did not generate rental income | C12: -0.886688 | D12: -0.828082 | E12: -0.874128 | F12: -1.229137 | G12: =-2182796/10^6 -> -2.182796 | H12: =-2482605/10^6 -> -2.482605 | I12: =-4763398/10^6 -> -4.763398 | J12: -3.348273 | K12: -4.171323 | L12: =SUM(AM12:AP12) -> -4.670426 | N12: -0.222134 | O12: -0.09285 | P12: -0.105084 | Q12: =E12-SUM(N12:P12) -> -0.45406 | R12: -0.242162 | S12: -0.285434 | T12: -0.287292 | U12: =F12-SUM(R12:T12) -> -0.414249 | V12: -0.27204 | W12: -0.358192 | X12: -0.353652 | Y12: =G12-SUM(V12:X12) -> -1.198912 | Z12: -0.514839 | AA12: -0.169774 | AB12: -0.591547 | AC12: =H12-SUM(Z12:AB12) -> -1.206445 | AD12: -0.666089 | AE12: -0.977976 | AF12: -1.400458 | AG12: =I12-SUM(AD12:AF12) -> -1.718875 | AH12: -0.71703 | AI12: -1.178181 | AJ12: -1.067008 | AK12: =J12-SUM(AH12:AJ12) -> -0.386054 | AL12: -0.758698 | AM12: -0.92 | AN12: -1.008863 | AO12: =K12-SUM(AL12:AN12) -> -1.483762 | AP12: -1.257801
B13: Gross Profit | C13: =C9+C11+C12 -> 104.43419 | D13: =D9+D11+D12 -> 126.99257 | E13: =E9+E11+E12 -> 136.22446 | F13: =F9+F11+F12 -> 139.70068 | G13: =G9+G11+G12 -> 150.0596 | H13: =H9+H11+H12 -> 166.60207 | I13: =I9+I11+I12 -> 196.22789 | J13: =J9+J11+J12 -> 227.73469 | ... L13: =L9+L11+L12 -> 262.41059 | N13: =N9+N11+N12 -> 34.730242 | O13: =O9+O11+O12 -> 34.156873 | P13: =P9+P11+P12 -> 34.012299 | Q13: =Q9+Q11+Q12 -> 33.325047 | R13: =R9+R11+R12 -> 35.195114 | S13: =S9+S11+S12 -> 33.775779 | T13: =T9+T11+T12 -> 35.185896 | U13: =U9+U11+U12 -> 35.543889 | ... AP13: =AP9+AP11+AP12 -> 69.320702
B14: Gross Profit margin | C14: =C13/C7 -> 0.95437069 | D14: =D13/D7 -> 0.95721164 | E14: =E13/E7 -> 0.94408617 | F14: =F13/F7 -> 0.93422844 | G14: =G13/G7 -> 0.93379657 | H14: =H13/H7 -> 0.93583281 | I14: =I13/I7 -> 0.91932282 | J14: =J13/J7 -> 0.90388662 | ... L14: =L13/L7 -> 0.89589432 | N14: =N13/N7 -> 0.95700947 | O14: =O13/O7 -> 0.95070209 | P14: =P13/P7 -> 0.94938615 | Q14: =Q13/Q7 -> 0.9193523 | R14: =R13/R7 -> 0.93367794 | S14: =S13/S7 -> 0.92438105 | T14: =T13/T7 -> 0.93934611 | U14: =U13/U7 -> 0.93921907 | ... AP14: =AP13/AP7 -> 0.90321128
B15: Operating expenses:
B16: Administration Expenses | C16: -13.911938 | D16: -16.094364 | E16: -17.630342 | F16: -17.184479 | G16: =-19799701/10^6 -> -19.799701 | H16: =-(16300021+6650487)/10^6 -> -22.950508 | I16: =-(22139991+8001831)/10^6 -> -30.141822 | J16: =-23.779729-8.982488 -> -32.762217 | K16: =(-24137274-9630465)/1000000 -> -33.767739 | L16: =SUM(AM16:AP16) -> -34.783625 | N16: -4.313463 | O16: -4.597505 | P16: -4.462334 | Q16: =E16-SUM(N16:P16) -> -4.25704 | R16: -4.67189 | S16: -3.962524 | T16: -4.004564 | U16: =F16-SUM(R16:T16) -> -4.545501 | V16: -4.933187 | W16: -4.928192 | X16: -5.144429 | Y16: =G16-SUM(V16:X16) -> -4.793893 | Z16: -6.113201 | AA16: -5.738825 | AB16: -5.529993 | AC16: =H16-SUM(Z16:AB16) -> -5.568489 | AD16: =-5.04415-2.792918 -> -7.837068 | AE16: -6.437817 | AF16: -7.054483 | AG16: =I16-SUM(AD16:AF16) -> -8.812454 | AH16: =-6.082243-2.146913 -> -8.229156 | AI16: -9.047505 | AJ16: -7.00599 | AK16: =J16-SUM(AH16:AJ16) -> -8.479566 | AL16: =(-8924602+636653)/1000000 -> -8.287949 | AM16: -8.3 | AN16: -8.326405 | AO16: =K16-SUM(AL16:AN16) -> -8.853385 | AP16: =(-9775131+471296)/1000000 -> -9.303835
B17: Depreciation | C17: -0.356727 | D17: -0.573177 | E17: -1.494778 | F17: -1.477413 | G17: =-1601216/10^6 -> -1.601216 | H17: =-1463920/10^6 -> -1.46392 | I17: =-1578073/10^6 -> -1.578073 | J17: -1.416026 | K17: -1.724637 | L17: =SUM(AM17:AP17) -> -1.55928 | N17: -0.337236 | O17: -0.337236 | P17: -0.403047 | Q17: =E17-SUM(N17:P17) -> -0.417259 | R17: -0.492342 | S17: -0.299754 | T17: -0.323789 | U17: =F17-SUM(R17:T17) -> -0.361528 | V17: -0.388299 | W17: -0.396139 | X17: -0.390724 | Y17: =G17-SUM(V17:X17) -> -0.426054 | Z17: -0.349123 | AA17: -0.330449 | AB17: -0.405601 | AC17: =H17-SUM(Z17:AB17) -> -0.378747 | AD17: -0.368875 | AE17: -0.376117 | AF17: -0.265962 | AG17: =I17-SUM(AD17:AF17) -> -0.567119 | AH17: -0.327639 | AI17: -0.146099 | AJ17: -0.425616 | AK17: =J17-SUM(AH17:AJ17) -> -0.516672 | AL17: -0.636653 | AM17: -0.1 | AN17: 0 | AO17: =K17-SUM(AL17:AN17) -> -0.987984 | AP17: -0.471296
B18: Total operating expenses | C18: =C16+C17 -> -14.268665 | D18: =D16+D17 -> -16.667541 | E18: =E16+E17 -> -19.12512 | F18: =F16+F17 -> -18.661892 | G18: =G16+G17 -> -21.400917 | H18: =H16+H17 -> -24.414428 | I18: =I16+I17 -> -31.719895 | J18: =J16+J17 -> -34.178243 | ... L18: =L16+L17 -> -36.342905 | N18: =N16+N17 -> -4.650699 | O18: =O16+O17 -> -4.934741 | P18: =P16+P17 -> -4.865381 | Q18: =Q16+Q17 -> -4.674299 | R18: =R16+R17 -> -5.164232 | S18: =S16+S17 -> -4.262278 | T18: =T16+T17 -> -4.328353 | U18: =U16+U17 -> -4.907029 | ... AP18: =AP16+AP17 -> -9.775131
B19: Operating profit | C19: =C13+C18 -> 90.165526 | D19: =D13+D18 -> 110.32502 | E19: =E13+E18 -> 117.09934 | F19: =F13+F18 -> 121.03879 | G19: =G13+G18 -> 128.65868 | H19: =H13+H18 -> 142.18764 | I19: =I13+I18 -> 164.50799 | J19: =J13+J18 -> 193.55645 | ... L19: =L13+L18 -> 226.06769 | N19: =N13+N18 -> 30.079543 | O19: =O13+O18 -> 29.222132 | P19: =P13+P18 -> 29.146918 | Q19: =Q13+Q18 -> 28.650748 | R19: =R13+R18 -> 30.030882 | S19: =S13+S18 -> 29.513501 | T19: =T13+T18 -> 30.857543 | U19: =U13+U18 -> 30.63686 | ... AP19: =AP13+AP18 -> 59.545571
B20: % margin | C20: =+C19/C7 -> 0.82397666 | D20: =+D19/D7 -> 0.83157937 | E20: =+E19/E7 -> 0.81154198 | F20: =+F19/F7 -> 0.80942969 | G20: =+G19/G7 -> 0.80062213 | H20: =+H19/H7 -> 0.79869272 | I20: =+I19/I7 -> 0.7707159 | J20: =+J19/J7 -> 0.76823203 | ... L20: =+L19/L7 -> 0.77181624 | N20: =+N19/N7 -> 0.82885709 | O20: =+O19/O7 -> 0.81335144 | P20: =+P19/P7 -> 0.81357865 | Q20: =+Q19/Q7 -> 0.79040041 | R20: =+R19/R7 -> 0.79667797 | S20: =+S19/S7 -> 0.80773033 | T20: =+T19/T7 -> 0.82379352 | U20: =+U19/U7 -> 0.80955472 | ... AP20: =+AP19/AP7 -> 0.77584661
B21: Other income (expenses):
B22: Interest income | C22: 0.055171 | D22: 0.434427 | E22: 0.070394 | F22: 0.311959 | G22: =76871/10^6 -> 0.076871 | H22: =2640687/10^6 -> 2.640687 | I22: =9414027/10^6 -> 9.414027 | J22: 15.185565 | K22: 5.27266 | L22: =SUM(AM22:AP22) -> 6.336389 | N22: 0.014307 | O22: 0.016533 | P22: 0.022073 | Q22: =E22-SUM(N22:P22) -> 0.017481 | R22: 0.009967 | S22: 0.204945 | T22: 0.081746 | U22: =F22-SUM(R22:T22) -> 0.015301 | V22: 0.016572 | W22: 0.012215 | X22: 0.024167 | Y22: =G22-SUM(V22:X22) -> 0.023917 | Z22: 0.037774 | AA22: 0.132774 | AB22: 1.375039 | AC22: =H22-SUM(Z22:AB22) -> 1.0951 | AD22: 0.566836 | AE22: 0.5378 | AF22: 4.423263 | AG22: =I22-SUM(AD22:AF22) -> 3.886128 | AH22: 5.068364 | AI22: 4.06199 | AJ22: 4.010121 | AK22: =J22-SUM(AH22:AJ22) -> 2.04509 | AL22: 1.025445 | AM22: 0.4 | AN22: 0.651746 | AO22: =K22-SUM(AL22:AN22) -> 3.195469 | AP22: 2.089174
B23: Other income - net | C23: 0.449193 | D23: 0.47624 | E23: 1.051904 | F23: 0.007852 | G23: =27795/10^6 -> 0.027795 | H23: =956862/10^6 -> 0.956862 | I23: =(5138158-3037113)/10^6 -> 2.101045 | J23: =4.307956-5.152385 -> -0.844429 | K23: =(6818185-3523537)/1000000 -> 3.294648 | L23: =SUM(AM23:AP23) -> 4.296107 | N23: -0.207438 | O23: 0 | P23: 0.445761 | Q23: =E23-SUM(N23:P23) -> 0.813581 | R23: 0.079917 | S23: 0.098649 | T23: -0.202364 | U23: =F23-SUM(R23:T23) -> 0.03165 | V23: 0.093629 | W23: -0.014122 | X23: 0.116322 | Y23: =G23-SUM(V23:X23) -> -0.168034 | Z23: 0.025695 | AA23: 0.354909 | AB23: 0.257563 | AC23: =H23-SUM(Z23:AB23) -> 0.318695 | AD23: =0.256351-0.330286 -> -0.073935 | AE23: 0.808513 | AF23: =1.707806+0.222955 -> 1.930761 | AG23: =I23-SUM(AD23:AF23) -> -0.564294 | AH23: =0.895669-1.110553 -> -0.214884 | AI23: =1.140107-2.305118 -> -1.165011 | AJ23: =0.358488+0.114849 -> 0.473337 | AK23: =J23-SUM(AH23:AJ23) -> 0.062129 | AL23: =(1563173-518562)/1000000 -> 1.044611 | AM23: 0 | AN23: =(1196412-623458)/1000000 -> 0.572954 | AO23: =K23-SUM(AL23:AN23) -> 1.677083 | AP23: =3.636548-1.590478 -> 2.04607
B24: Transaction costs on debt issuance | C24: -0.395559 | D24: -0.139062 | E24: 0 | F24: 0 | G24: 0 | H24: 0 | I24: 0 | J24: 0 | K24: 0 | L24: =SUM(AM24:AP24) -> 0 | N24: 0 | O24: 0 | P24: 0 | Q24: =E24-SUM(N24:P24) -> 0 | R24: 0 | S24: 0 | T24: 0 | U24: =F24-SUM(R24:T24) -> 0 | V24: 0 | W24: 0 | X24: 0 | Y24: =G24-SUM(V24:X24) -> 0 | Z24: -10.40765 | AA24: 0 | AB24: 0 | AC24: =H24-SUM(Z24:AB24) -> 10.40765 | AD24: 0 | AE24: 0 | AF24: 0 | AG24: =I24-SUM(AD24:AF24) -> 0 | AH24: 0 | AI24: 0 | AJ24: 0 | AK24: =J24-SUM(AH24:AJ24) -> 0 | AL24: 0 | AM24: 0 | AN24: 0 | AO24: =K24-SUM(AL24:AN24) -> 0 | AP24: 0
B25: Interest expense | C25: -19.668274 | D25: -35.156825 | E25: -39.161931 | F25: -39.052739 | G25: =-50263493/10^6 -> -50.263493 | H25: =-46396156/10^6 -> -46.396156 | I25: =-46306975/10^6 -> -46.306975 | J25: -44.26139 | K25: -56.226952 | L25: =SUM(AM25:AP25) -> -64.896665 | N25: -9.181172 | O25: -11.210785 | P25: -9.102284 | Q25: =E25-SUM(N25:P25) -> -9.66769 | R25: -9.295627 | S25: -10.191399 | T25: -9.933891 | U25: =F25-SUM(R25:T25) -> -9.631822 | V25: -11.045969 | W25: -16.440226 | X25: -11.651279 | Y25: =G25-SUM(V25:X25) -> -11.126019 | Z25: 0 | AA25: -11.927469 | AB25: -11.783272 | AC25: =H25-SUM(Z25:AB25) -> -22.685415 | AD25: -11.580977 | AE25: -11.771653 | AF25: -11.395892 | AG25: =I25-SUM(AD25:AF25) -> -11.558453 | AH25: -10.212525 | AI25: -12.251664 | AJ25: -11.22982 | AK25: =J25-SUM(AH25:AJ25) -> -10.567381 | AL25: -10.285252 | AM25: -11.9 | AN25: -12.289994 | AO25: =K25-SUM(AL25:AN25) -> -21.751706 | AP25: -18.954965
B26: Exchange gain (loss)- net | C26: 2.897256 | D26: -0.719007 | E26: 2.15693 | F26: -0.171566 | G26: =-1109567/10^6 -> -1.109567 | H26: =1939848/10^6 -> 1.939848 | I26: =8906782/10^6 -> 8.906782 | J26: -10.837867 | K26: 10.097353 | L26: =SUM(AM26:AP26) -> 9.94163 | N26: 1.240277 | O26: 0.690787 | P26: -1.468717 | Q26: =E26-SUM(N26:P26) -> 1.694583 | R26: -9.104508 | S26: 1.73479 | T26: 7.666205 | U26: =F26-SUM(R26:T26) -> -0.468053 | V26: 0.500146 | W26: -0.254524 | X26: -0.476894 | Y26: =G26-SUM(V26:X26) -> -0.878295 | Z26: -0.800455 | AA26: 1.252495 | AB26: -0.754543 | AC26: =H26-SUM(Z26:AB26) -> 2.242351 | AD26: 4.602489 | AE26: 3.74076 | AF26: -2.149238 | AG26: =I26-SUM(AD26:AF26) -> 2.712771 | AH26: 0.854082 | AI26: -6.523491 | AJ26: -4.305296 | AK26: =J26-SUM(AH26:AJ26) -> -0.863162 | AL26: -0.096271 | AM26: 6.3 | AN26: 2.429486 | AO26: =K26-SUM(AL26:AN26) -> 1.464138 | AP26: -0.251994
B27: Gain on sale of investment property | C27: 0 | D27: 0 | E27: 17.920717 | F27: 0 | G27: =13992675/10^6 -> 13.992675 | H27: =5027826/10^6 -> 5.027826 | I27: =-461600/10^6 -> -0.4616 | J27: 2.617233 | K27: -0.009945 | L27: =SUM(AM27:AP27) -> -0.009945 | N27: 0 | O27: 16.017448 | P27: 0 | Q27: =E27-SUM(N27:P27) -> 1.903269 | R27: 0 | S27: 0 | T27: 0 | U27: =F27-SUM(R27:T27) -> 0 | V27: 4.299598 | W27: 4.25929 | X27: 0 | Y27: =G27-SUM(V27:X27) -> 5.433787 | Z27: 0.567754 | AA27: 4.460072 | AB27: 0 | AC27: =H27-SUM(Z27:AB27) -> 0 | AD27: 0 | AE27: 0 | AF27: 0 | AG27: =I27-SUM(AD27:AF27) -> -0.4616 | AH27: 0.25 | AI27: 0 | AJ27: 0 | AK27: =J27-SUM(AH27:AJ27) -> 2.367233 | AL27: 0 | AM27: -0.4 | AN27: 0.4 | AO27: =K27-SUM(AL27:AN27) -> -0.009945 | AP27: 0
B28: Share of results of associates | K28: 0.011538 | L28: =SUM(AM28:AP28) -> 0.04923 | AN28: -0.008711 | AO28: =K28-SUM(AL28:AN28) -> 0.020249 | AP28: 0.037692
B29: Gain on revaluation of investment property | C29: 84.058105 | D29: 52.822802 | E29: 86.062112 | F29: 45.370264 | G29: =164649959/10^6 -> 164.64996 | H29: =185491518/10^6 -> 185.49152 | I29: =243459821/10^6 -> 243.45982 | J29: 270.74766 | K29: 52.075064 | L29: =SUM(AM29:AP29) -> 121.54895 | N29: 11.954926 | O29: 32.442363 | P29: 13.944263 | Q29: =E29-SUM(N29:P29) -> 27.72056 | R29: 13.899686 | S29: 14.282625 | T29: 4.215727 | U29: =F29-SUM(R29:T29) -> 12.972226 | V29: -3.716929 | W29: 90.996712 | X29: 26.610777 | Y29: =G29-SUM(V29:X29) -> 50.759399 | Z29: 38.195915 | AA29: 38.599306 | AB29: 62.985726 | AC29: =H29-SUM(Z29:AB29) -> 45.710571 | AD29: 10.759462 | AE29: 73.628123 | AF29: 95.162184 | AG29: =I29-SUM(AD29:AF29) -> 63.910052 | AH29: 107.32603 | AI29: 100.0795 | AJ29: 23.969004 | AK29: =J29-SUM(AH29:AJ29) -> 39.373132 | AL29: -16.038206 | AM29: 7.8 | AN29: 4.792273 | AO29: =K29-SUM(AL29:AN29) -> 55.520997 | AP29: 53.435678
B30: Profit before tax | C30: =C19+SUM(C22:C29) -> 157.56142 | D30: =D19+SUM(D22:D29) -> 128.0436 | E30: =E19+SUM(E22:E29) -> 185.19947 | F30: =F19+SUM(F22:F29) -> 127.50456 | G30: =G19+SUM(G22:G29) -> 256.03292 | H30: =H19+SUM(H22:H29) -> 291.84822 | I30: =I19+SUM(I22:I29) -> 381.62109 | J30: =J19+SUM(J22:J29) -> 426.16322 | ... L30: =L19+SUM(L22:L29) -> 303.33338 | N30: =N19+SUM(N22:N29) -> 33.900443 | O30: =O19+SUM(O22:O29) -> 67.178478 | P30: =P19+SUM(P22:P29) -> 32.988014 | Q30: =Q19+SUM(Q22:Q29) -> 51.132532 | R30: =R19+SUM(R22:R29) -> 25.620317 | S30: =S19+SUM(S22:S29) -> 35.643111 | T30: =T19+SUM(T22:T29) -> 32.684966 | U30: =U19+SUM(U22:U29) -> 33.556162 | ... AP30: =AP19+SUM(AP22:AP29) -> 97.947226
B31: Current income tax expense | C31: -31.531237 | D31: -21.892031 | E31: -37.670744 | F31: -26.15048 | G31: =-50262466/10^6 -> -50.262466 | H31: =-41981391/10^6 -> -41.981391 | I31: =-91953099/10^6 -> -91.953099 | J31: -31.892785 | K31: -56.138103 | L31: =SUM(AM31:AP31) -> -39.439241 | N31: -11.167037 | O31: -12.273515 | P31: -6.39751 | Q31: =E31-SUM(N31:P31) -> -7.832682 | R31: -1.851778 | S31: -3.21361 | T31: -6.63117 | U31: =F31-SUM(R31:T31) -> -14.453922 | V31: -5.521844 | W31: -13.492846 | X31: -6.671784 | Y31: =G31-SUM(V31:X31) -> -24.575992 | Z31: -9.13698 | AA31: -12.346817 | AB31: -6.534278 | AC31: =H31-SUM(Z31:AB31) -> -13.963316 | AD31: -20.749621 | AE31: -21.475691 | AF31: -31.57051 | AG31: =I31-SUM(AD31:AF31) -> -18.157277 | AH31: -25.733091 | AI31: -22.526023 | AJ31: -10.712706 | AK31: =J31-SUM(AH31:AJ31) -> 27.079035 | AL31: -13.663554 | AM31: -26.8 | AN31: -27.446316 | AO31: =K31-SUM(AL31:AN31) -> 11.771767 | AP31: 3.035308
B32: Deferred income tax | C32: 0 | D32: -13.091239 | E32: -12.918014 | F32: -34.397994 | G32: =-31828085/10^6 -> -31.828085 | H32: =-6242079/10^6 -> -6.242079 | I32: =26969516/10^6 -> 26.969516 | J32: -170.92409 | K32: 64.069427 | L32: =SUM(AM32:AP32) -> 64.069427 | N32: -0.797586 | O32: -5.571251 | P32: -14.178535 | Q32: =E32-SUM(N32:P32) -> 7.629358 | R32: -48.187278 | S32: -13.36146 | T32: 10.588101 | U32: =F32-SUM(R32:T32) -> 16.562643 | V32: -1.939495 | W32: 11.477473 | X32: -35.832671 | Y32: =G32-SUM(V32:X32) -> -5.533392 | Z32: -2.502225 | AA32: -1.340663 | AB32: -20.210106 | AC32: =H32-SUM(Z32:AB32) -> 17.810915 | AD32: 32.974505 | AE32: 9.4986 | AF32: -23.193789 | AG32: =I32-SUM(AD32:AF32) -> 7.6902 | AH32: 0 | AI32: 0 | AJ32: 0 | AK32: =J32-SUM(AH32:AJ32) -> -170.92409 | AL32: 0 | AM32: 0 | AN32: 0 | AO32: =K32-SUM(AL32:AN32) -> 64.069427 | AP32: 0
B33: Net profit/loss | C33: =+C30+C31+C32 -> 126.03018 | D33: =+D30+D31+D32 -> 93.06033 | E33: =+E30+E31+E32 -> 134.61071 | F33: =+F30+F31+F32 -> 66.956082 | G33: =+G30+G31+G32 -> 173.94237 | H33: =+H30+H31+H32 -> 243.62475 | I33: =+I30+I31+I32 -> 316.63751 | J33: =+J30+J31+J32 -> 223.34635 | ... L33: =+L30+L31+L32 -> 327.96357 | N33: =+N30+N31+N32 -> 21.93582 | O33: =+O30+O31+O32 -> 49.333712 | P33: =+P30+P31+P32 -> 12.411969 | Q33: =+Q30+Q31+Q32 -> 50.929208 | R33: =+R30+R31+R32 -> -24.418739 | S33: =+S30+S31+S32 -> 19.068041 | T33: =+T30+T31+T32 -> 36.641897 | U33: =+U30+U31+U32 -> 35.664883 | ... AP33: =+AP30+AP31+AP32 -> 100.98253
B34: % margin | C34: =+C33/C7 -> 1.1517254 | D34: =+D33/D7 -> 0.70144603 | E34: =+E33/E7 -> 0.93290227 | F34: =+F33/F7 -> 0.44775929 | G34: =+G33/G7 -> 1.0824152 | H34: =+H33/H7 -> 1.3684826 | I34: =+I33/I7 -> 1.4834389 | J34: =+J33/J7 -> 0.88646914 | ... L34: =+L33/L7 -> 1.1196983 | N34: =+N33/N7 -> 0.60445267 | O34: =+O33/O7 -> 1.3731252 | P34: =+P33/P7 -> 0.3464556 | Q34: =+Q33/Q7 -> 1.4050058 | R34: =+R33/R7 -> -0.64779554 | S34: =+S33/S7 -> 0.52185727 | T34: =+T33/T7 -> 0.97821648 | U34: =+U33/U7 -> 0.94241624 | ... AP34: =+AP33/AP7 -> 1.3157478
B36: As % of sales unless stated otherwise
B37: =B11 -> COR - Related to Properties that generated rental income | C37: =-C11/C9 -> 0.037526318 | D37: =-D11/D9 -> 0.036546656 | E37: =-E11/E9 -> 0.050334125 | F37: =-F11/F9 -> 0.059560897 | G37: =-G11/G9 -> 0.053138594 | H37: =-H11/H9 -> 0.050221968 | I37: =-I11/I9 -> 0.062836173 | J37: =-J11/J9 -> 0.084192931 | ... L37: =-L11/L9 -> 0.088181545 | N37: =-N11/N9 -> 0.036869518 | O37: =-O11/O9 -> 0.0469969 | P37: =-P11/P9 -> 0.047680638 | Q37: =-Q11/Q9 -> 0.069712437 | R37: =-R11/R9 -> 0.060338241 | S37: =-S11/S9 -> 0.070656182 | T37: =-T11/T9 -> 0.053483666 | U37: =-U11/U9 -> 0.054083797 | ... AP37: =-AP11/AP9 -> 0.080400248
B38: =B12 -> COR - Related to Properties that did not generate rental income | C38: =-C12/C9 -> 0.0081029884 | D38: =-D12/D9 -> 0.0062417018 | E38: =-E12/E9 -> 0.0060549823 | F38: =-F12/F9 -> 0.0082021572 | G38: =-G12/G9 -> 0.013575754 | H38: =-H12/H9 -> 0.013945224 | I38: =-I12/I9 -> 0.022210337 | J38: =-J12/J9 -> 0.013269572 | ... L38: =-L12/L9 -> 0.015944902 | N38: =-N12/N9 -> 0.0061210152 | O38: =-O12/O9 -> 0.0025835636 | P38: =-P12/P9 -> 0.0029332123 | Q38: =-Q12/Q9 -> 0.01250496 | R38: =-R12/R9 -> 0.0064212151 | S38: =-S12/S9 -> 0.0077879294 | T38: =-T12/T9 -> 0.007665693 | U38: =-U12/U9 -> 0.010897251 | ... AP38: =-AP12/AP9 -> 0.016388467
B39: =B16 -> Administration Expenses | C39: =-C16/C9 -> 0.12713409 | D39: =-D16/D9 -> 0.12131192 | E39: =-E16/E9 -> 0.12212331 | F39: =-F16/F9 -> 0.11467379 | G39: =-G16/G9 -> 0.12314292 | H39: =-H16/H9 -> 0.128917 | I39: =-I16/I9 -> 0.14054254 | J39: =-J16/J9 -> 0.12984025 | ... L39: =-L16/L9 -> 0.1187518 | N39: =-N16/N9 -> 0.11885966 | O39: =-O16/O9 -> 0.12792619 | P39: =-P16/P9 -> 0.12455724 | Q39: =-Q16/Q9 -> 0.11724026 | R39: =-R16/R9 -> 0.12388075 | S39: =-S16/S9 -> 0.10811556 | T39: =-T16/T9 -> 0.10685212 | U39: =-U16/U9 -> 0.11957413 | ... AP39: =-AP16/AP9 -> 0.12122394
B40: =B17 -> Depreciation | C40: =-C17/C9 -> 0.0032599457 | D40: =-D17/D9 -> 0.004320345 | E40: =-E17/E9 -> 0.010354152 | F40: =-F17/F9 -> 0.0098589284 | G40: =-G17/G9 -> 0.0099586558 | H40: =-H17/H9 -> 0.0082230934 | I40: =-I17/I9 -> 0.0073580947 | J40: =-J17/J9 -> 0.005611866 | ... L40: =-L17/L9 -> 0.0053234044 | N40: =-N17/N9 -> 0.0092927093 | O40: =-O17/O9 -> 0.0093836366 | P40: =-P17/P9 -> 0.011250261 | Q40: =-Q17/Q9 -> 0.011491448 | R40: =-R17/R9 -> 0.013055037 | S40: =-S17/S9 -> 0.0081786438 | T40: =-T17/T9 -> 0.0086395273 | U40: =-U17/U9 -> 0.0095103699 | ... AP40: =-AP17/AP9 -> 0.0061407322
B41: =B22 -> Interest income | C41: =C22/C9 -> 0.00050417957 | D41: =D22/D9 -> 0.0032745112 | E41: =E22/E9 -> 0.000487611 | F41: =F22/F9 -> 0.0020817344 | G41: =G22/G9 -> 0.00047809404 | H41: =H22/H9 -> 0.014833198 | I41: =I22/I9 -> 0.043894866 | J41: =J22/J9 -> 0.060182056 | ... L41: =L22/L9 -> 0.021632523 | N41: =N22/N9 -> 0.00039423666 | O41: =O22/O9 -> 0.00046003292 | P41: =P22/P9 -> 0.0006161242 | Q41: =Q22/Q9 -> 0.00048143241 | R41: =R22/R9 -> 0.00026428693 | S41: =S22/S9 -> 0.0055918258 | T41: =T22/T9 -> 0.0021811945 | U41: =U22/U9 -> 0.00040250871 | ... AP41: =AP22/AP9 -> 0.027220808
B42: =B23 -> Other income - net | C42: =C23/C9 -> 0.0041049452 | D42: =D23/D9 -> 0.0035896784 | E42: =E23/E9 -> 0.0072864159 | F42: =F23/F9 -> 5.2397201e-05 | G42: =G23/G9 -> 0.00017286914 | H42: =H23/H9 -> 0.0053748604 | I42: =I23/I9 -> 0.0097965608 | J42: =J23/J9 -> -0.0033465645 | ... L42: =L23/L9 -> 0.014666971 | N42: =N23/N9 -> -0.0057160595 | O42: =O23/O9 -> 0 | P42: =P23/P9 -> 0.012442538 | Q42: =Q23/Q9 -> 0.022406285 | R42: =R23/R9 -> 0.0021190948 | S42: =S23/S9 -> 0.0026915905 | T42: =T23/T9 -> -0.0053995945 | U42: =U23/U9 -> 0.00083258615 | ... AP42: =AP23/AP9 -> 0.026659186
...

Sheet EBITDA
B2: Corporación Inmobiliaria Vesta | C2: Annual | D2: Annual | F2: Quarters | G2: Quarters | H2: Quarters | I2: Quarters | J2: Quarters | K2: Quarters | L2: Quarters | M2: Quarters | N2: Quarters
B3: (USD million) | C3: 45657 | D3: 46022 | F3: 45382 | G3: 45473 | H3: 45565 | I3: 45657 | J3: 45747 | K3: 45838 | L3: 45930 | M3: 46022 | N3: 46112
C4: Act | D4: Act | F4: Act | G4: Act | H4: Act | I4: Act | J4: Act | K4: Act | L4: Act | M4: Act | N4: Act
F5: 1Q | G5: 2Q | H5: 3Q | I5: 4Q | J5: 1Q | K5: 2Q | L5: 3Q | M5: 4Q | N5: 1Q
B8: Total revenues | C8: 252.3 | D8: 283.2 | F8: 60.589657 | G8: 63 | H8: 63.7 | I8: 65.2 | J8: 67.063658 | K8: 67.3 | L8: 72.4 | M8: 76.4 | N8: 76.749154
B10: Property operating costs:
B11: Related to properties that generate rental income | C11: =SUM(C12:C13) -> -21.2 | D11: =SUM(D12:D13) -> -24.1 | F11: =SUM(F12:F13) -> -3.786225 | G11: =SUM(G12:G13) -> -5.3 | H11: =SUM(H12:H13) -> -5.7 | I11: =SUM(I12:I13) -> -6.3 | J11: =SUM(J12:J13) -> -4.445843 | K11: =SUM(K12:K13) -> -5.6 | L11: =SUM(L12:L13) -> -7.2 | M11: =SUM(M12:M13) -> -6.8 | N11: =SUM(N12:N13) -> -6.170651
B12: Costs related to properties | C12: -13.2 | D12: -14.2 | F12: -2.365872 | G12: -3.3 | H12: -3.5 | I12: -4 | J12: -2.779184 | K12: -3.6 | L12: -3.9 | M12: -4 | N12: -3.633335
B13: Costs related to energy | C13: -8 | D13: -9.9 | F13: -1.420353 | G13: -2 | H13: -2.2 | I13: -2.3 | J13: -1.666659 | K13: -2 | L13: -3.3 | M13: -2.8 | N13: -2.537316
B14: Related to properties that did not generate rental income | C14: -3.3 | D14: -4.2 | F14: -0.71703 | G14: -0.85 | H14: -0.81 | I14: -1.11 | J14: -0.758699 | K14: -0.92 | L14: -1.01 | M14: -1.48 | N14: -1.257801
B16: Adjusted NOI | C16: 231.5 | D16: =(SUM(D8,D11,D14)) -> 254.9 | F16: =(SUM(F8,F11,F14)) -> 56.086402 | G16: =(SUM(G8,G11,G14)) -> 56.85 | H16: 57.6 | I16: 59.3 | J16: =(SUM(J8,J11,J14)) -> 61.859116 | K16: =(SUM(K8,K11,K14)) -> 60.78 | L16: 66.1 | M16: 69.4 | N16: 70.406117
B18: General and administrative expenses | C18: -32.8 | D18: -33.8 | F18: -8.229156 | G18: -9 | H18: -7 | I18: -8.5 | J18: -8.287949 | K18: -8.287949 | L18: -7.8 | M18: -9.3 | N18: -9.303835
B19: Stock-based compensation expenses | C19: 9 | D19: 9.6 | F19: 2.146913 | G19: 2.7 | H19: 2.1 | I19: 2 | J19: 2.196456 | K19: 2.4 | L19: 2.5 | M19: 2.5 | N19: 2.248176
B20: Depreciation | C20: -1.4 | D20: -1.7 | F20: -0.327639 | G20: -0.1 | H20: -0.4 | I20: -0.5 | J20: -0.636653 | K20: -0.1 | L20: -0.5 | M20: -0.5 | N20: -0.471296
B21: EBITDA | C21: 204.4 | D21: 231.1 | F21: 50.578089 | G21: =SUM(G18:G20)+G16-0.1 -> 50.35 | H21: 51.9 | I21: 51.7 | J21: 55.258372 | K21: =SUM(K18:K20)+K16+0.2 -> 54.992051 | L21: 59.7 | M21: 61.1 | N21: 62.092657

Sheet KPIs
B2: Corporación Inmobiliaria Vesta | C2: Annual | D2: Annual | E2: Annual | F2: Annual | G2: Annual | H2: Annual | I2: Annual | J2: Annual | K2: Annual | L2: LTM | N2: Quarters | O2: Quarters | P2: Quarters | Q2: Quarters | R2: Quarters | S2: Quarters | T2: Quarters | U2: Quarters | V2: Quarters | W2: Quarters | X2: Quarters | Y2: Quarters | Z2: Quarters | AA2: Quarters | AB2: Quarters | AC2: Quarters | AD2: Quarters | AE2: Quarters | AF2: Quarters | AG2: Quarters | AH2: Quarters | AI2: Quarters | AJ2: Quarters | AK2: Quarters | AL2: Quarters | AM2: Quarters | AN2: Quarters | AO2: Quarters | AP2: Quarters
B3: (USD million) | C3: 43100 | D3: 43465 | E3: 43830 | F3: 44196 | G3: 44561 | H3: 44926 | I3: 45291 | J3: 45657 | K3: 46022 | L3: =AP3 -> 46112 | N3: 43555 | O3: 43646 | P3: 43738 | Q3: 43830 | R3: 43921 | S3: 44012 | T3: 44104 | U3: 44196 | V3: 44286 | W3: 44377 | X3: 44469 | Y3: 44561 | Z3: 44651 | AA3: 44742 | AB3: 44834 | AC3: 44926 | AD3: 45016 | AE3: 45107 | AF3: 45199 | AG3: 45291 | AH3: 45382 | AI3: 45473 | AJ3: 45565 | AK3: 45657 | AL3: 45747 | AM3: 45838 | AN3: 45930 | AO3: 46022 | AP3: 46112
C4: Act | D4: Act | E4: Act | F4: Act | G4: Act | H4: Act | I4: Act | J4: Act | K4: Act | L4: Act | N4: Act | O4: Act | P4: Act | Q4: Act | R4: Act | S4: Act | T4: Act | U4: Act | V4: Act | W4: Act | X4: Act | Y4: Act | Z4: Act | AA4: Act | AB4: Act | AC4: Act | AD4: Act | AE4: Act | AF4: Act | AG4: Act | AH4: Act | AI4: Act | AJ4: Act | AK4: Act | AL4: Act | AM4: Act | AN4: Act | AO4: Act | AP4: Act
C5: FY | D5: FY | E5: FY | F5: FY | G5: FY | H5: FY | I5: FY | J5: FY | K5: FY | L5: FY | N5: 1Q | O5: 2Q | P5: 3Q | Q5: 4Q | R5: 1Q | S5: 2Q | T5: 3Q | U5: 4Q | V5: 1Q | W5: 2Q | X5: 3Q | Y5: 4Q | Z5: 1Q | AA5: 2Q | AB5: 3Q | AC5: 4Q | AD5: 1Q | AE5: 2Q | AF5: 3Q | AG5: 4Q | AH5: 1Q | AI5: 2Q | AJ5: 3Q | AK5: 4Q | AL5: 1Q | AM5: 2Q | AN5: 3Q | AO5: 4Q | AP5: 1Q
B7: North Region
B8: Number of operating buildings | C8: 63 | D8: 66 | E8: 69 | F8: 70 | G8: 72 | H8: 78 | I8: 85 | J8: 88 | K8: 91 | L8: =AP8 -> 89 | N8: 66 | O8: 68 | P8: 68 | Q8: =E8 -> 69 | R8: 69 | S8: 70 | T8: 70 | U8: =F8 -> 70 | V8: 71 | W8: 71 | X8: 71 | Y8: =G8 -> 72 | Z8: 73 | AA8: 74 | AB8: 74 | AC8: =H8 -> 78 | AD8: 78 | AE8: 79 | AF8: 86 | AG8: =I8 -> 85 | AH8: 85 | AI8: 86 | AJ8: 88 | AK8: =J8 -> 88 | AL8: 89 | AM8: 91 | AN8: 92 | AO8: =K8 -> 91 | AP8: 89
B9: Number of buildings under development | C9: 0 | D9: 2 | E9: 2 | F9: 1 | G9: 5 | H9: 8 | I9: 3 | J9: 4 | K9: 0 | L9: =AP9 -> 1 | N9: 5 | O9: 2 | P9: 4 | Q9: =E9 -> 2 | R9: 2 | S9: 0 | T9: 1 | U9: =F9 -> 1 | V9: 3 | W9: 4 | X9: 4 | Y9: =G9 -> 5 | Z9: 7 | AA9: 6 | AB9: 8 | AC9: =H9 -> 8 | AD9: 8 | AE9: 7 | AF9: 3 | AG9: =I9 -> 3 | AH9: 6 | AI9: 6 | AJ9: 4 | AK9: =J9 -> 4 | AL9: 3 | AM9: 1 | AN9: 0 | AO9: =K9 -> 0 | AP9: 1
B10: Total Buildings | C10: =SUM(C8:C9) -> 63 | D10: =SUM(D8:D9) -> 68 | E10: =SUM(E8:E9) -> 71 | F10: =SUM(F8:F9) -> 71 | G10: =SUM(G8:G9) -> 77 | H10: =SUM(H8:H9) -> 86 | I10: =SUM(I8:I9) -> 88 | J10: =SUM(J8:J9) -> 92 | ... L10: =SUM(L8:L9) -> 90 | N10: =SUM(N8:N9) -> 71 | O10: =SUM(O8:O9) -> 70 | P10: =SUM(P8:P9) -> 72 | Q10: =SUM(Q8:Q9) -> 71 | R10: =SUM(R8:R9) -> 71 | S10: =SUM(S8:S9) -> 70 | T10: =SUM(T8:T9) -> 71 | U10: =SUM(U8:U9) -> 71 | ... AP10: =SUM(AP8:AP9) -> 90
B12: Operating portfolio (sf) | C12: 6875440 | D12: 7996798 | E12: 8852290 | F12: 9078485 | G12: 9303139 | H12: 10352575 | I12: 12070580 | J12: 12786657 | K12: 14283183 | L12: =AP12 -> 14283187 | N12: 8212054 | O12: 8631873 | P12: 8631873 | Q12: =E12 -> 8852290 | R12: 8852385 | S12: 9074369 | T12: 9074369 | U12: =F12 -> 9078485 | V12: 9361517 | W12: 9360915 | X12: 9303139 | Y12: =G12 -> 9303139 | Z12: 9509958 | AA12: 9628555 | AB12: 9628555 | AC12: =H12 -> 10352575 | AD12: 10352575 | AE12: 10657963 | AF12: 12384129 | AG12: =I12 -> 12070580 | AH12: 12070580 | AI12: 12281380 | AJ12: 12786659 | AK12: =J12 -> 12786657 | AL12: 13263621 | AM12: 13628161 | AN12: 14282993 | AO12: =K12 -> 14283183 | AP12: 14283187
B13: Development portfolio (sf) | C13: 1121413 | D13: 419673 | E13: 221984 | F13: 603239 | G13: 957623 | H13: 2026077 | I13: 716079 | J13: 1619288 | K13: 0 | L13: =AP13 -> 375625 | N13: 639874 | O13: 220201 | P13: 442185 | Q13: =E13 -> 221984 | R13: 221984 | S13: 0 | T13: 283032 | U13: =F13 -> 603239 | V13: 625891 | W13: 735112 | X13: 892299 | Y13: =G13 -> 957623 | Z13: 1410492 | AA13: 1291895 | AB13: 1821284 | AC13: =H13 -> 2026077 | AD13: 2026077 | AE13: 1728660 | AF13: 791879 | AG13: =I13 -> 716079 | AH13: 1666458 | AI13: 2105824 | AJ13: 1600545 | AK13: =J13 -> 1619288 | AL13: 1142324 | AM13: 730762 | AN13: 0 | AO13: =K13 -> 0 | AP13: 375625
B14: Total GLA (sf) | C14: =SUM(C12:C13) -> 7996853 | D14: =SUM(D12:D13) -> 8416471 | E14: =SUM(E12:E13) -> 9074274 | F14: =SUM(F12:F13) -> 9681724 | G14: =SUM(G12:G13) -> 10260762 | H14: =SUM(H12:H13) -> 12378652 | I14: =SUM(I12:I13) -> 12786659 | J14: =SUM(J12:J13) -> 14405945 | ... L14: =SUM(L12:L13) -> 14658812 | N14: =SUM(N12:N13) -> 8851928 | O14: =SUM(O12:O13) -> 8852074 | P14: =SUM(P12:P13) -> 9074058 | Q14: =SUM(Q12:Q13) -> 9074274 | R14: =SUM(R12:R13) -> 9074369 | S14: =SUM(S12:S13) -> 9074369 | T14: =SUM(T12:T13) -> 9357401 | U14: =SUM(U12:U13) -> 9681724 | ... AP14: =SUM(AP12:AP13) -> 14658812
B16: Development portfolio Total Expected Investment ($ 000's) | C16: 62861 | D16: 20778 | E16: 11050 | F16: 30778 | G16: 51234 | H16: 127072 | I16: 57715 | J16: 134868 | K16: 0 | L16: =AP16 -> 32379 | N16: 32773 | O16: 11995 | P16: 23044 | Q16: =E16 -> 11050 | R16: 11049 | S16: 0 | T16: 12934 | U16: =F16 -> 30778 | V16: 35760 | W16: 41441 | X16: 48065 | Y16: =G16 -> 51234 | Z16: 79303 | AA16: 73622 | AB16: 108199 | AC16: =H16 -> 127072 | AD16: 127072 | AE16: 112376 | AF16: 60105 | AG16: =I16 -> 57715 | AH16: 130701 | AI16: 175779 | AJ16: 134714 | AK16: =J16 -> 134868 | AL16: 90135 | AM16: 57180 | AN16: 0 | AO16: =K16 -> 0 | AP16: 32379
B17: Land (acres) | C17: 72 | D17: 53.63 | E17: 118.63 | F17: 107.17 | G17: 108.24 | H17: 153.64 | I17: 100.83 | J17: 88.32 | K17: 539.48 | L17: =AP17 -> 523.61 | N17: 53.63 | O17: 43.33 | P17: 31.18 | Q17: =E17 -> 118.63 | R17: 118.63 | S17: 118.63 | T17: 107.17 | U17: =F17 -> 107.17 | V17: 178.73 | W17: 152.67 | X17: 141.99 | Y17: =G17 -> 108.24 | Z17: 257.1 | AA17: 216.59 | AB17: 194.3 | AC17: =H17 -> 153.64 | AD17: 141.24 | AE17: 141.24 | AF17: 100.83 | AG17: =I17 -> 100.83 | AH17: 56.24 | AI17: 0 | AJ17: 88.32 | AK17: =J17 -> 88.32 | AL17: 185.6 | AM17: 209.57 | AN17: 209.57 | AO17: =K17 -> 539.48 | AP17: 523.61
B18: Land Book Value ($ 000's) | C18: 23909 | D18: 17208 | E18: 30107 | F18: 26275 | G18: 20050 | H18: 44258 | I18: 33.22 | J18: 10272 | K18: 163880 | L18: =AP18 -> 160243 | N18: 17208 | O18: 13966 | P18: 11503 | Q18: =E18 -> 30107 | R18: 30107 | S18: 30107 | T18: 26275 | U18: =F18 -> 26275 | V18: 42328 | W18: 30552 | X18: 26984 | Y18: =G18 -> 20050 | Z18: 70452 | AA18: 58645 | AB18: 51610 | AC18: =H18 -> 44258 | AD18: 45415 | AE18: 45420 | AF18: 32660 | AG18: =I18 -> 33.22 | AH18: 18203 | AI18: 0 | AJ18: 10298 | AK18: =J18 -> 10272 | AL18: 36754 | AM18: 48358 | AN18: 48358 | AO18: =K18 -> 163880 | AP18: 160243
B20: Bajio Region
B21: Number of operating buildings | C21: 76 | D21: 84 | E21: 83 | F21: 84 | G21: 83 | H21: 88 | I21: 92 | J21: 98 | K21: 102 | L21: =AP21 -> 101 | N21: 87 | O21: 82 | P21: 82 | Q21: =E21 -> 83 | R21: 83 | S21: 83 | T21: 83 | U21: =F21 -> 84 | V21: 84 | W21: 84 | X21: 84 | Y21: =G21 -> 83 | Z21: 83 | AA21: 85 | AB21: 86 | AC21: =H21 -> 88 | AD21: 88 | AE21: 89 | AF21: 91 | AG21: =I21 -> 92 | AH21: 92 | AI21: 93 | AJ21: 96 | AK21: =J21 -> 98 | AL21: 99 | AM21: 99 | AN21: 102 | AO21: =K21 -> 102 | AP21: 101
B22: Number of buildings under development | C22: 0 | D22: 3 | E22: 1 | F22: 2 | G22: 3 | H22: 6 | I22: 6 | J22: 5 | K22: 3 | L22: =AP22 -> 3 | N22: 2 | O22: 2 | P22: 1 | Q22: =E22 -> 1 | R22: 3 | S22: 4 | T22: 5 | U22: =F22 -> 2 | V22: 2 | W22: 2 | X22: 3 | Y22: =G22 -> 3 | Z22: 5 | AA22: 3 | AB22: 5 | AC22: =H22 -> 6 | AD22: 6 | AE22: 4 | AF22: 6 | AG22: =I22 -> 6 | AH22: 5 | AI22: 7 | AJ22: 3 | AK22: =J22 -> 5 | AL22: 3 | AM22: 3 | AN22: 1 | AO22: =K22 -> 3 | AP22: 3
B23: Total Buildings | C23: =SUM(C21:C22) -> 76 | D23: =SUM(D21:D22) -> 87 | E23: =SUM(E21:E22) -> 84 | F23: =SUM(F21:F22) -> 86 | G23: =SUM(G21:G22) -> 86 | H23: =SUM(H21:H22) -> 94 | I23: =SUM(I21:I22) -> 98 | J23: =SUM(J21:J22) -> 103 | ... L23: =SUM(L21:L22) -> 104 | N23: =SUM(N21:N22) -> 89 | O23: =SUM(O21:O22) -> 84 | P23: =SUM(P21:P22) -> 83 | Q23: =SUM(Q21:Q22) -> 84 | R23: =SUM(R21:R22) -> 86 | S23: =SUM(S21:S22) -> 87 | T23: =SUM(T21:T22) -> 88 | U23: =SUM(U21:U22) -> 86 | ... AP23: =SUM(AP21:AP22) -> 104
B25: Operating portfolio (sf) | C25: 12722893 | D25: 14748046 | E25: 14445698 | F25: 15182807 | G25: 14771316 | H25: 16183191 | I25: 18027608 | J25: 19193885 | K25: 20093889 | L25: =AP25 -> 20093885 | N25: 15081603 | O25: 14136412 | P25: 14210107 | Q25: =E25 -> 14445698 | R25: 14447822 | S25: 14447822 | T25: 14447822 | U25: =F25 -> 15182807 | V25: 15227219 | W25: 15231132 | X25: 15231131 | Y25: =G25 -> 14771316 | Z25: 14849602 | AA25: 15451284 | AB25: 15630160 | AC25: =H25 -> 16183191 | AD25: 16183191 | AE25: 16769047 | AF25: 17341893 | AG25: =I25 -> 18027608 | AH25: 17963025 | AI25: 18255502 | AJ25: 19033534 | AK25: =J25 -> 19193885 | AL25: 19533041 | AM25: 19533041 | AN25: 20093889 | AO25: =K25 -> 20093889 | AP25: 20093885
B26: Development portfolio (sf) | C26: 1209136 | D26: 622080 | E26: 405509 | F26: 449921 | G26: 678842 | H26: 1839413 | I26: 1155265 | J26: 900007 | K26: 771844 | L26: =AP26 -> 777226 | N26: 309285 | O26: 309285 | P26: 235591 | Q26: =E26 -> 405509 | R26: 1065584 | S26: 1157593 | T26: 1202005 | U26: =F26 -> 449921 | V26: 631475 | W26: 631475 | X26: 904808 | Y26: =G26 -> 678842 | Z26: 1287347 | AA26: 686791 | AB26: 1333873 | AC26: =H26 -> 1839413 | AD26: 1839413 | AE26: 1520283 | AF26: 1489514 | AG26: =I26 -> 1155265 | AH26: 1236423 | AI26: 1248766 | AJ26: 470727 | AK26: =J26 -> 900007 | AL26: 560851 | AM26: 560851 | AN26: 376016 | AO26: =K26 -> 771844 | AP26: 777226
B27: Total GLA (sf) | C27: =SUM(C25:C26) -> 13932029 | D27: =SUM(D25:D26) -> 15370126 | E27: =SUM(E25:E26) -> 14851207 | F27: =SUM(F25:F26) -> 15632728 | G27: =SUM(G25:G26) -> 15450158 | H27: =SUM(H25:H26) -> 18022604 | I27: =SUM(I25:I26) -> 19182873 | J27: =SUM(J25:J26) -> 20093892 | ... L27: =SUM(L25:L26) -> 20871111 | N27: =SUM(N25:N26) -> 15390888 | O27: =SUM(O25:O26) -> 14445697 | P27: =SUM(P25:P26) -> 14445698 | Q27: =SUM(Q25:Q26) -> 14851207 | R27: =SUM(R25:R26) -> 15513406 | S27: =SUM(S25:S26) -> 15605415 | T27: =SUM(T25:T26) -> 15649827 | U27: =SUM(U25:U26) -> 15632728 | ... AP27: =SUM(AP25:AP26) -> 20871111
B29: Development portfolio Total Expected Investment ($ 000's) | C29: 48006 | D29: 25458 | E29: 19397 | F29: 21540 | G29: 37038 | H29: 114612 | I29: 70.141 | J29: 54435 | K29: 59042 | L29: =AP29 -> 62613 | N29: 12193 | O29: 12193 | P29: 9319 | Q29: =E29 -> 19397 | R29: 58207 | S29: 61233 | T29: 63375 | U29: =F29 -> 21540 | V29: 33082 | W29: 33082 | X29: 50723 | Y29: =G29 -> 37038 | Z29: 71352 | AA29: 37861 | AB29: 80693 | AC29: =H29 -> 114612 | AD29: 114612 | AE29: 93237 | AF29: 91855 | AG29: =I29 -> 70.141 | AH29: 74588 | AI29: 76130 | AJ29: 28981 | AK29: =J29 -> 54435 | AL29: 33776 | AM29: 33776 | AN29: 29188 | AO29: =K29 -> 59042 | AP29: 62613
B30: Land (acres) | C30: 684 | D30: 778.17 | E30: 861.46 | F30: 791.38 | G30: 785.29 | H30: 693.65 | I30: 605.97 | J30: 569.56 | K30: 672.09 | L30: =AP30 -> 672.09 | N30: 786.7 | O30: 786.7 | P30: 861.46 | Q30: =E30 -> 861.46 | R30: 833.41 | S30: 833.41 | T30: 833.41 | U30: =F30 -> 791.38 | V30: 769.76 | W30: 705 | X30: 793.88 | Y30: =G30 -> 785.29 | Z30: 751.94 | AA30: 751.94 | AB30: 731.54 | AC30: =H30 -> 693.65 | AD30: 669.42 | AE30: 660.06 | AF30: 632.19 | AG30: =I30 -> 605.97 | AH30: 594.31 | AI30: 579.45 | AJ30: 579.45 | AK30: =J30 -> 569.56 | AL30: 569.56 | AM30: 697.96 | AN30: 682.11 | AO30: =K30 -> 672.09 | AP30: 672.09
B31: Land Book Value | C31: 62216 | D31: 73807 | E31: 106160 | F31: 95999 | G31: 113305 | H31: 96895 | I31: 104370 | J31: 104050 | K31: 133160 | L31: =AP31 -> 133160 | N31: 75233 | O31: 75386 | P31: 96264 | Q31: =E31 -> 106160 | R31: 98327 | S31: 98327 | T31: 98327 | U31: =F31 -> 95999 | V31: 94801 | W31: 100075 | X31: 115704 | Y31: =G31 -> 113305 | Z31: 107331 | AA31: 107330 | AB31: 104550 | AC31: =H31 -> 96895 | AD31: 112740 | AE31: 110410 | AF31: 106650 | AG31: =I31 -> 104370 | AH31: 101423 | AI31: 99798 | AJ31: 99798 | AK31: =J31 -> 104050 | AL31: 104050 | AM31: 137266 | AN31: 131530 | AO31: =K31 -> 133160 | AP31: 133160
B33: Central Region
B34: Number of operating buildings | C34: 34 | D34: 34 | E34: 32 | F34: 34 | G34: 34 | H34: 36 | I34: 36 | J34: 39 | K34: 41 | L34: =AP34 -> 41 | N34: 34 | O34: 32 | P34: 32 | Q34: =E34 -> 32 | R34: 32 | S34: 33 | T34: 33 | U34: =F34 -> 34 | V34: 34 | W34: 34 | X34: 34 | Y34: =G34 -> 34 | Z34: 34 | AA34: 34 | AB34: 34 | AC34: =H34 -> 36 | AD34: 36 | AE34: 36 | AF34: 37 | AG34: =I34 -> 36 | AH34: 37 | AI34: 37 | AJ34: 37 | AK34: =J34 -> 39 | AL34: 40 | AM34: 41 | AN34: 41 | AO34: =K34 -> 41 | AP34: 41
B35: Number of buildings under development | C35: 0 | D35: 0 | E35: 1 | F35: 1 | G35: 0 | H35: 0 | I35: 3 | J35: 2 | K35: 0 | L35: =AP35 -> 2 | N35: 0 | O35: 0 | P35: 1 | Q35: =E35 -> 1 | R35: 2 | S35: 2 | T35: 2 | U35: =F35 -> 1 | V35: 0 | W35: 0 | X35: 0 | Y35: =G35 -> 0 | Z35: 0 | AA35: 0 | AB35: 0 | AC35: =H35 -> 0 | AD35: 0 | AE35: 0 | AF35: 3 | AG35: =I35 -> 3 | AH35: 3 | AI35: 4 | AJ35: 4 | AK35: =J35 -> 2 | AL35: 1 | AM35: 0 | AN35: 0 | AO35: =K35 -> 0 | AP35: 2
B36: Total Buildings | C36: =SUM(C34:C35) -> 34 | D36: =SUM(D34:D35) -> 34 | E36: =SUM(E34:E35) -> 33 | F36: =SUM(F34:F35) -> 35 | G36: =SUM(G34:G35) -> 34 | H36: =SUM(H34:H35) -> 36 | I36: =SUM(I34:I35) -> 39 | J36: =SUM(J34:J35) -> 41 | ... L36: =SUM(L34:L35) -> 43 | N36: =SUM(N34:N35) -> 34 | O36: =SUM(O34:O35) -> 32 | P36: =SUM(P34:P35) -> 33 | Q36: =SUM(Q34:Q35) -> 33 | R36: =SUM(R34:R35) -> 34 | S36: =SUM(S34:S35) -> 35 | T36: =SUM(T34:T35) -> 35 | U36: =SUM(U34:U35) -> 35 | ... AP36: =SUM(AP34:AP35) -> 43
B38: Operating portfolio (sf) | C38: 7122837 | D38: 7122733 | E38: 6494060 | F38: 6959744 | G38: 7007291 | H38: 7178604 | I38: 7179938 | J38: 8319422 | K38: 8576950 | L38: =AP38 -> 8576950 | N38: 7122733 | O38: 6494060 | P38: 6494060 | Q38: =E38 -> 6494060 | R38: 6494214 | S38: 6629396 | T38: 6629396 | U38: =F38 -> 6959744 | V38: 7003125 | W38: 7003125 | X38: 7007291 | Y38: =G38 -> 7007291 | Z38: 7007291 | AA38: 7008211 | AB38: 7008211 | AC38: =H38 -> 7178604 | AD38: 7178604 | AE38: 7179701 | AF38: 7179938 | AG38: =I38 -> 7179938 | AH38: 7256310 | AI38: 7256310 | AJ38: 7256310 | AK38: =J38 -> 8319422 | AL38: 8405555 | AM38: 8756841 | AN38: 8576840 | AO38: =K38 -> 8576950 | AP38: 8576950
B39: Development portfolio (sf) | C39: 0 | D39: 0 | E39: 135182 | F39: 43381 | G39: 0 | H39: 0 | I39: 1230308 | J39: 257419 | K39: 0 | L39: =AP39 -> 400458 | N39: 0 | O39: 0 | P39: 135182 | Q39: =E39 -> 135182 | R39: 474675 | S39: 382874 | T39: 382874 | U39: =F39 -> 43381 | V39: 0 | W39: 0 | X39: 0 | Y39: =G39 -> 0 | Z39: 0 | AA39: 0 | AB39: 0 | AC39: =H39 -> 0 | AD39: 0 | AE39: 0 | AF39: 1230308 | AG39: =I39 -> 1230308 | AH39: 1230308 | AI39: 1320532 | AJ39: 1320532 | AK39: =J39 -> 257419 | AL39: 171286 | AM39: 0 | AN39: 0 | AO39: =K39 -> 0 | AP39: 400458
B40: Total GLA (sf) | C40: =SUM(C38:C39) -> 7122837 | D40: =SUM(D38:D39) -> 7122733 | E40: =SUM(E38:E39) -> 6629242 | F40: =SUM(F38:F39) -> 7003125 | G40: =SUM(G38:G39) -> 7007291 | H40: =SUM(H38:H39) -> 7178604 | I40: =SUM(I38:I39) -> 8410246 | J40: =SUM(J38:J39) -> 8576841 | ... L40: =SUM(L38:L39) -> 8977408 | N40: =SUM(N38:N39) -> 7122733 | O40: =SUM(O38:O39) -> 6494060 | P40: =SUM(P38:P39) -> 6629242 | Q40: =SUM(Q38:Q39) -> 6629242 | R40: =SUM(R38:R39) -> 6968889 | S40: =SUM(S38:S39) -> 7012270 | T40: =SUM(T38:T39) -> 7012270 | U40: =SUM(U38:U39) -> 7003125 | ... AP40: =SUM(AP38:AP39) -> 8977408
B42: Development portfolio Total Expected Investment ($ 000's) | C42: 0 | D42: 0 | E42: 6358 | F42: 2550 | G42: 0 | H42: 0 | I42: 82.909 | J42: 24755 | K42: 0 | L42: =AP42 -> 51736 | N42: 0 | O42: 0 | P42: 6358 | Q42: =E42 -> 6358 | R42: 24314 | S42: 20506 | T42: 20506 | U42: =F42 -> 2550 | V42: 0 | W42: 0 | X42: 0 | Y42: =G42 -> 0 | Z42: 0 | AA42: 0 | AB42: 0 | AC42: =H42 -> 0 | AD42: 0 | AE42: 0 | AF42: 82909 | AG42: =I42 -> 82.909 | AH42: 82909 | AI42: 87071 | AJ42: 165249 | AK42: =J42 -> 24755 | AL42: 18650 | AM42: 0 | AN42: 0 | AO42: =K42 -> 0 | AP42: 51736
B43: Land (acres) | C43: 28 | D43: 28.08 | E43: 28.08 | F43: 7.63 | G43: 2.12 | H43: 62.47 | I43: 2.12 | J43: 0 | K43: 18.73 | L43: =AP43 -> 0 | N43: 28.08 | O43: 28.08 | P43: 28.08 | Q43: =E43 -> 28.08 | R43: 7.63 | S43: 7.63 | T43: 7.63 | U43: =F43 -> 7.63 | V43: 7.63 | W43: 2.12 | X43: 2.12 | Y43: =G43 -> 2.12 | Z43: 2.12 | AA43: 2.12 | AB43: 10.78 | AC43: =H43 -> 62.47 | AD43: 62.47 | AE43: 62.47 | AF43: 2.12 | AG43: =I43 -> 2.12 | AH43: 2.12 | AI43: 0 | AJ43: 0 | AK43: =J43 -> 0 | AL43: 18.73 | AM43: 18.73 | AN43: 18.73 | AO43: =K43 -> 18.73 | AP43: 0
B44: Land Book Value | C44: 1508 | D44: 1508 | E44: 6712 | F44: 1824 | G44: 508 | H44: 50129 | I44: 790 | J44: 0 | K44: 18610 | L44: =AP44 -> 0 | N44: 1508 | O44: 1508 | P44: 1508 | Q44: =E44 -> 6712 | R44: 1824 | S44: 1824 | T44: 1824 | U44: =F44 -> 1824 | V44: 1824 | W44: 508 | X44: 508 | Y44: =G44 -> 508 | Z44: 508 | AA44: 508 | AB44: 17919 | AC44: =H44 -> 50129 | AD44: 50750 | AE44: 50750 | AF44: 790 | AG44: =I44 -> 790 | AH44: 790 | AI44: 0 | AJ44: 0 | AK44: =J44 -> 0 | AL44: 18887 | AM44: 18887 | AN44: 18887 | AO44: =K44 -> 18610 | AP44: 0
B46: Total
B47: Number of operating buildings | C47: =SUM(C8,C21,C34) -> 173 | D47: =SUM(D8,D21,D34) -> 184 | E47: =SUM(E8,E21,E34) -> 184 | F47: =SUM(F8,F21,F34) -> 188 | G47: =SUM(G8,G21,G34) -> 189 | H47: =SUM(H8,H21,H34) -> 202 | I47: =SUM(I8,I21,I34) -> 213 | J47: =SUM(J8,J21,J34) -> 225 | ... L47: =SUM(L8,L21,L34) -> 231 | N47: =SUM(N8,N21,N34) -> 187 | O47: =SUM(O8,O21,O34) -> 182 | P47: =SUM(P8,P21,P34) -> 182 | Q47: =SUM(Q8,Q21,Q34) -> 184 | R47: =SUM(R8,R21,R34) -> 184 | S47: =SUM(S8,S21,S34) -> 186 | T47: =SUM(T8,T21,T34) -> 186 | U47: =SUM(U8,U21,U34) -> 188 | ... AP47: =SUM(AP8,AP21,AP34) -> 231
B48: Number of buildings under development | C48: =SUM(C9,C22,C35) -> 0 | D48: =SUM(D9,D22,D35) -> 5 | E48: =SUM(E9,E22,E35) -> 4 | F48: =SUM(F9,F22,F35) -> 4 | G48: =SUM(G9,G22,G35) -> 8 | H48: =SUM(H9,H22,H35) -> 14 | I48: =SUM(I9,I22,I35) -> 12 | J48: =SUM(J9,J22,J35) -> 11 | ... L48: =SUM(L9,L22,L35) -> 6 | N48: =SUM(N9,N22,N35) -> 7 | O48: =SUM(O9,O22,O35) -> 4 | P48: =SUM(P9,P22,P35) -> 6 | Q48: =SUM(Q9,Q22,Q35) -> 4 | R48: =SUM(R9,R22,R35) -> 7 | S48: =SUM(S9,S22,S35) -> 6 | T48: =SUM(T9,T22,T35) -> 8 | U48: =SUM(U9,U22,U35) -> 4 | ... AP48: =SUM(AP9,AP22,AP35) -> 6
B49: Total Buildings | C49: =SUM(C47:C48) -> 173 | D49: =SUM(D47:D48) -> 189 | E49: =SUM(E47:E48) -> 188 | F49: =SUM(F47:F48) -> 192 | G49: =SUM(G47:G48) -> 197 | H49: =SUM(H47:H48) -> 216 | I49: =SUM(I47:I48) -> 225 | J49: =SUM(J47:J48) -> 236 | ... L49: =SUM(L47:L48) -> 237 | N49: =SUM(N47:N48) -> 194 | O49: =SUM(O47:O48) -> 186 | P49: =SUM(P47:P48) -> 188 | Q49: =SUM(Q47:Q48) -> 188 | R49: =SUM(R47:R48) -> 191 | S49: =SUM(S47:S48) -> 192 | T49: =SUM(T47:T48) -> 194 | U49: =SUM(U47:U48) -> 192 | ... AP49: =SUM(AP47:AP48) -> 237
B51: Operating portfolio (sf) | C51: =SUM(C12,C25,C38) -> 26721170 | D51: =SUM(D12,D25,D38) -> 29867577 | E51: =SUM(E12,E25,E38) -> 29792048 | F51: =SUM(F12,F25,F38) -> 31221036 | G51: =SUM(G12,G25,G38) -> 31081746 | H51: =SUM(H12,H25,H38) -> 33714370 | I51: =SUM(I12,I25,I38) -> 37278126 | J51: =SUM(J12,J25,J38) -> 40299964 | K51: =SUM(K12,K25,K38) -> 42954022 | L51: =AN51 -> 42953722 | N51: =SUM(N12,N25,N38) -> 30416390 | O51: =SUM(O12,O25,O38) -> 29262345 | P51: =SUM(P12,P25,P38) -> 29336040 | Q51: =SUM(Q12,Q25,Q38) -> 29792048 | R51: =SUM(R12,R25,R38) -> 29794421 | S51: =SUM(S12,S25,S38) -> 30151587 | T51: =SUM(T12,T25,T38) -> 30151587 | U51: =SUM(U12,U25,U38) -> 31221036 | ... AP51: =SUM(AP12,AP25,AP38) -> 42954022
B52: Development portfolio (sf) | C52: =SUM(C13,C26,C39) -> 2330549 | D52: =SUM(D13,D26,D39) -> 1041753 | E52: =SUM(E13,E26,E39) -> 762675 | F52: =SUM(F13,F26,F39) -> 1096541 | G52: =SUM(G13,G26,G39) -> 1636465 | H52: =SUM(H13,H26,H39) -> 3865490 | I52: =SUM(I13,I26,I39) -> 3101652 | J52: =SUM(J13,J26,J39) -> 2776714 | K52: =SUM(K13,K26,K39) -> 771844 | L52: =AN52 -> 376016 | N52: =SUM(N13,N26,N39) -> 949159 | O52: =SUM(O13,O26,O39) -> 529486 | P52: =SUM(P13,P26,P39) -> 812958 | Q52: =SUM(Q13,Q26,Q39) -> 762675 | R52: =SUM(R13,R26,R39) -> 1762243 | S52: =SUM(S13,S26,S39) -> 1540467 | T52: =SUM(T13,T26,T39) -> 1867911 | U52: =SUM(U13,U26,U39) -> 1096541 | ... AP52: =SUM(AP13,AP26,AP39) -> 1553309
...
